Workbook

Sheet RESUMO
A1: RESUMO CONSOLIDADO — REGIÃO 1 — RODOVIAS NÃO PAVIMENTADAS | M1: Valores dos gráficos — troca 0 por N/D para a fatia não aparecer. Não editar.
A2: Todos os números vêm das abas dos trechos por referência direta. Não digite nada aqui. A coluna CONFERÊNCIA acusa qualquer trecho em que a soma das marcações não fecha com a extensão. | M2: =IF(D17=0,NA(),D17) -> 441.31857 | N2: =IF(E17=0,NA(),E17) -> 134.3602 | O2: =IF(F17=0,NA(),F17) -> 1 | P2: =IF(G17=0,NA(),G17) -> #N/A | Q2: =IF(H17=0,NA(),H17) -> 420.31288 | R2: =IF(I17=0,NA(),I17) -> 84.076208 | S2: =IF(J17=0,NA(),J17) -> 72.289675
A4: Nº TRECHO | B4: TRECHO | C4: EXTENSÃO (KM) | D4: CONDIÇÃO DA PLATAFORMA | H4: DRENAGEM SUPERFICIAL | K4: CONFERÊNCIA
D5: BOM | E5: REG. (ATÉ 10 IRR./KM) | F5: RUIM (+ 10 IRR./KM) | G5: PÉSSIMA (ATOLEIRO/PTO. CRÍTICO) | H5: LIMPA | I5: OBSTRUÍDA | J5: AUSENTE
A6: 228 | B6: RODOVIA TO-296 - TRECHO SÃO SALVADOR DO TOCANTINS - PARANÃ | C6: ='228'!I30 -> 12.317348 | D6: ='228'!F27 -> 0 | E6: ='228'!G27 -> 12.317348 | F6: ='228'!H27 -> 0 | G6: ='228'!I27 -> 0 | H6: ='228'!J27 -> 9.3173481 | I6: ='228'!K27 -> 3 | J6: ='228'!L27 -> 0 | K6: =IF(SUM(D6:G6)=0,"— não preenchido",IF(ROUND(SUM(D6:G6)-C6,3)=0,"OK","ERRO — dif. de "&ROUND(SUM(D6:G6)-C6,3)&" km")) -> OK
A7: 229 | B7: RODOVIA TO-296 - TRECHO JAÚ DO TOCANTINS - SÃO SALVADOR DO TOCANTINS | C7: ='229'!I102 -> 81.717854 | D7: ='229'!F99 -> 81.717854 | E7: ='229'!G99 -> 0 | F7: ='229'!H99 -> 0 | G7: ='229'!I99 -> 0 | H7: ='229'!J99 -> 81.717854 | I7: ='229'!K99 -> 0 | J7: ='229'!L99 -> 0 | K7: =IF(SUM(D7:G7)=0,"— não preenchido",IF(ROUND(SUM(D7:G7)-C7,3)=0,"OK","ERRO — dif. de "&ROUND(SUM(D7:G7)-C7,3)&" km")) -> OK
A8: 231 | B8: RODOVIA TO-365 - TRECHO IPUEIRAS - SILVANÓPOLIS | C8: ='231'!I58 -> 34.254616 | D8: ='231'!F55 -> 34.254616 | E8: ='231'!G55 -> 0 | F8: ='231'!H55 -> 0 | G8: ='231'!I55 -> 0 | H8: ='231'!J55 -> 34.254616 | I8: ='231'!K55 -> 0 | J8: ='231'!L55 -> 0 | K8: =IF(SUM(D8:G8)=0,"— não preenchido",IF(ROUND(SUM(D8:G8)-C8,3)=0,"OK","ERRO — dif. de "&ROUND(SUM(D8:G8)-C8,3)&" km")) -> OK
A9: 232 | B9: RODOVIA TO-373 - TRECHO ENTR. TO-365 (BALSA) - SÃO MIGUEL - LAGOA DO ROMÃO -ENTR. TO-280 | C9: ='232'!I109 -> 87.831045 | D9: ='232'!F106 -> 87.831045 | E9: ='232'!G106 -> 0 | F9: ='232'!H106 -> 0 | G9: ='232'!I106 -> 0 | H9: ='232'!J106 -> 20.945342 | I9: ='232'!K106 -> 0 | J9: ='232'!L106 -> 66.885703 | K9: =IF(SUM(D9:G9)=0,"— não preenchido",IF(ROUND(SUM(D9:G9)-C9,3)=0,"OK","ERRO — dif. de "&ROUND(SUM(D9:G9)-C9,3)&" km")) -> OK
A10: 236 | B10: RODOVIA TO-458 - TRECHO ENTR. TO-365 (IPUEIRAS) - ENTR. BR-010 | C10: ='236'!I55 -> 33.96664 | D10: ='236'!F52 -> 6 | E10: ='236'!G52 -> 26.96664 | F10: ='236'!H52 -> 1 | G10: ='236'!I52 -> 0 | H10: ='236'!J52 -> 33.96664 | I10: ='236'!K52 -> 0 | J10: ='236'!L52 -> 0 | K10: =IF(SUM(D10:G10)=0,"— não preenchido",IF(ROUND(SUM(D10:G10)-C10,3)=0,"OK","ERRO — dif. de "&ROUND(SUM(D10:G10)-C10,3)&" km")) -> OK
A11: 237 | B11: RODOVIA TO-479 - TRECHO PEIXE - POVOADO LAGOA DO ROMÃO (ENTR. TO-373) | C11: ='237'!I44 -> 26.043993 | D11: ='237'!F41 -> 26.043993 | E11: ='237'!G41 -> 0 | F11: ='237'!H41 -> 0 | G11: ='237'!I41 -> 0 | H11: ='237'!J41 -> 26.043993 | I11: ='237'!K41 -> 0 | J11: ='237'!L41 -> 0 | K11: =IF(SUM(D11:G11)=0,"— não preenchido",IF(ROUND(SUM(D11:G11)-C11,3)=0,"OK","ERRO — dif. de "&ROUND(SUM(D11:G11)-C11,3)&" km")) -> OK
A12: 238 | B12: RODOVIA TO-482 - TRECHO: ENTR. TO-280 (SÃO VALÉRIO DE NATIVIDADE) / ENTR. TO-458 | C12: ='238'!I94 -> 73.554481 | D12: ='238'!F91 -> 73.554481 | E12: ='238'!G91 -> 0 | F12: ='238'!H91 -> 0 | G12: ='238'!I91 -> 0 | H12: ='238'!J91 -> 73.554481 | I12: ='238'!K91 -> 0 | J12: ='238'!L91 -> 0 | K12: =IF(SUM(D12:G12)=0,"— não preenchido",IF(ROUND(SUM(D12:G12)-C12,3)=0,"OK","ERRO — dif. de "&ROUND(SUM(D12:G12)-C12,3)&" km")) -> OK
A13: 239 | B13: RODOVIA TO-486 - TRECHO SANTA ROSA DO TOCANTINS - ENTR. TO-280 (NATIVIDADE) | C13: ='239'!I81 -> 63.930071 | D13: ='239'!F78 -> 63.930071 | E13: ='239'!G78 -> 0 | F13: ='239'!H78 -> 0 | G13: ='239'!I78 -> 0 | H13: ='239'!J78 -> 63.930071 | I13: ='239'!K78 -> 0 | J13: ='239'!L78 -> 0 | K13: =IF(SUM(D13:G13)=0,"— não preenchido",IF(ROUND(SUM(D13:G13)-C13,3)=0,"OK","ERRO — dif. de "&ROUND(SUM(D13:G13)-C13,3)&" km")) -> OK
A14: 240 | B14: RODOVIA TO-490 - TRECHO SÃO VALÉRIO DE NATIVIDADE - ENTR. BR-242 | C14: ='240'!I100 -> 81.076208 | D14: ='240'!F97 -> 0 | E14: ='240'!G97 -> 81.076208 | F14: ='240'!H97 -> 0 | G14: ='240'!I97 -> 0 | H14: ='240'!J97 -> 0 | I14: ='240'!K97 -> 81.076208 | J14: ='240'!L97 -> 0 | K14: =IF(SUM(D14:G14)=0,"— não preenchido",IF(ROUND(SUM(D14:G14)-C14,3)=0,"OK","ERRO — dif. de "&ROUND(SUM(D14:G14)-C14,3)&" km")) -> OK
A15: 241 | B15: RODOVIA TO-491 - TRECHO ENTR. BR-242 - ENTR. TO-296 (POVOADO RETIRO) | C15: ='241'!I78 -> 60.310113 | D15: ='241'!F75 -> 46.310113 | E15: ='241'!G75 -> 14 | F15: ='241'!H75 -> 0 | G15: ='241'!I75 -> 0 | H15: ='241'!J75 -> 60.310113 | I15: ='241'!K75 -> 0 | J15: ='241'!L75 -> 0 | K15: =IF(SUM(D15:G15)=0,"— não preenchido",IF(ROUND(SUM(D15:G15)-C15,3)=0,"OK","ERRO — dif. de "&ROUND(SUM(D15:G15)-C15,3)&" km")) -> OK
A16: 242 | B16: RODOVIA TO-495 - TRECHO DIVISA TO-GO - LOURENÇO BORGES - ENTR. TO-296 | C16: ='242'!I41 -> 21.676393 | D16: ='242'!F38 -> 21.676393 | E16: ='242'!G38 -> 0 | F16: ='242'!H38 -> 0 | G16: ='242'!I38 -> 0 | H16: ='242'!J38 -> 16.27242 | I16: ='242'!K38 -> 0 | J16: ='242'!L38 -> 5.4039722 | K16: =IF(SUM(D16:G16)=0,"— não preenchido",IF(ROUND(SUM(D16:G16)-C16,3)=0,"OK","ERRO — dif. de "&ROUND(SUM(D16:G16)-C16,3)&" km")) -> OK
B17: TOTAL PERCORRIDO NO MÊS | C17: =SUM(C6:C16) -> 576.67876 | D17: =SUM(D6:D16) -> 441.31857 | E17: =SUM(E6:E16) -> 134.3602 | F17: =SUM(F6:F16) -> 1 | G17: =SUM(G6:G16) -> 0 | H17: =SUM(H6:H16) -> 420.31288 | I17: =SUM(I6:I16) -> 84.076208 | J17: =SUM(J6:J16) -> 72.289675
B18: % DA EXTENSÃO DA MALHA (576.68 km) | D18: =SUM(D17:G17)/576.68 -> 0.99999785 | H18: (soma do grupo 'CONDIÇÃO DA PLATAFORMA' dividida pela malha)

Sheet 228
A1: PROGRAMA DE MANUTENÇÃO RODOVIÁRIA — FICHA DE INSPEÇÃO — RODOVIAS NÃO PAVIMENTADAS | P1: Valores dos gráficos — troca 0 por N/D para a fatia não aparecer. Não editar.
A2: REGIÃO: 12 — PEIXE | D2: MÊS / ANO: | F2: 46235 | G2: DATA: | J2: TÉCNICO: | K2: ENG. THIAGO BORGES TORQUATO | P2: =IF(F27=0,NA(),F27) -> #N/A | Q2: =IF(G27=0,NA(),G27) -> 12.317348 | R2: =IF(H27=0,NA(),H27) -> #N/A | S2: =IF(I27=0,NA(),I27) -> #N/A | T2: =IF(J27=0,NA(),J27) -> 9.3173481 | U2: =IF(K27=0,NA(),K27) -> 3 | V2: =IF(L27=0,NA(),L27) -> #N/A
A3: TRECHO 228 — RODOVIA TO-296 - TRECHO SÃO SALVADOR DO TOCANTINS - PARANÃ | K3: EXTENSÃO: 12,317 km · 1 S.R.E.
A4: COMO PREENCHER: uma X em UMA coluna de cada grupo, por linha. Se houver mais de um defeito no mesmo km, marque o PREDOMINANTE e escreva o resto em OBSERVAÇÕES. A quilometragem é contada de 0 até o fim de CADA S.R.E. (não é o marco da rodovia).
A6: S.R.E. | B6: SENT. | C6: INÍCIO (KM) | D6: FIM (KM) | E6: EXT. (KM) | F6: CONDIÇÃO DA PLATAFORMA | J6: DRENAGEM SUPERFICIAL | M6: OBSERVAÇÕES | N6: CONFERÊNCIA (só na tela)
F7: BOM | G7: REG. (ATÉ 10 IRR./KM) | H7: RUIM (+ 10 IRR./KM) | I7: PÉSSIMA (ATOLEIRO/PTO. CRÍTICO) | J7: LIMPA | K7: OBSTRUÍDA | L7: AUSENTE
A8: S.R.E. ACESSO02 | ENTR. TO-387 - UHE SÃO SALVADOR (código antigo: ACESSO) | LEN · Outros · 12.317 km · início: -12.729837, -48.234105
A9: ACESSO02 | B9: C | C9: 0 | D9: 1 | E9: =D9-C9 -> 1 | G9: x | J9: x | N9: =IF(COUNTA(F9:L9)=0,"— não preenchido",IF(COUNTIF(F9:I9,"X")<>1,"FALTA/DUPLA: CONDIÇÃO DA PLATAFORMA",IF(COUNTIF(J9:L9,"X")<>1,"FALTA/DUPLA: DRENAGEM SUPERFICIAL","OK"))) -> OK
A10: ACESSO02 | B10: C | C10: 1 | D10: 2 | E10: =D10-C10 -> 1 | G10: x | K10: x | N10: =IF(COUNTA(F10:L10)=0,"— não preenchido",IF(COUNTIF(F10:I10,"X")<>1,"FALTA/DUPLA: CONDIÇÃO DA PLATAFORMA",IF(COUNTIF(J10:L10,"X")<>1,"FALTA/DUPLA: DRENAGEM SUPERFICIAL","OK"))) -> OK
A11: ACESSO02 | B11: C | C11: 2 | D11: 3 | E11: =D11-C11 -> 1 | G11: x | K11: x | N11: =IF(COUNTA(F11:L11)=0,"— não preenchido",IF(COUNTIF(F11:I11,"X")<>1,"FALTA/DUPLA: CONDIÇÃO DA PLATAFORMA",IF(COUNTIF(J11:L11,"X")<>1,"FALTA/DUPLA: DRENAGEM SUPERFICIAL","OK"))) -> OK
A12: ACESSO02 | B12: C | C12: 3 | D12: 4 | E12: =D12-C12 -> 1 | G12: x | K12: x | N12: =IF(COUNTA(F12:L12)=0,"— não preenchido",IF(COUNTIF(F12:I12,"X")<>1,"FALTA/DUPLA: CONDIÇÃO DA PLATAFORMA",IF(COUNTIF(J12:L12,"X")<>1,"FALTA/DUPLA: DRENAGEM SUPERFICIAL","OK"))) -> OK
A13: ACESSO02 | B13: C | C13: 4 | D13: 5 | E13: =D13-C13 -> 1 | G13: x | J13: x | N13: =IF(COUNTA(F13:L13)=0,"— não preenchido",IF(COUNTIF(F13:I13,"X")<>1,"FALTA/DUPLA: CONDIÇÃO DA PLATAFORMA",IF(COUNTIF(J13:L13,"X")<>1,"FALTA/DUPLA: DRENAGEM SUPERFICIAL","OK"))) -> OK
A14: ACESSO02 | B14: C | C14: 5 | D14: 6 | E14: =D14-C14 -> 1 | G14: x | J14: x | N14: =IF(COUNTA(F14:L14)=0,"— não preenchido",IF(COUNTIF(F14:I14,"X")<>1,"FALTA/DUPLA: CONDIÇÃO DA PLATAFORMA",IF(COUNTIF(J14:L14,"X")<>1,"FALTA/DUPLA: DRENAGEM SUPERFICIAL","OK"))) -> OK
A15: ACESSO02 | B15: C | C15: 6 | D15: 7 | E15: =D15-C15 -> 1 | G15: x | J15: x | N15: =IF(COUNTA(F15:L15)=0,"— não preenchido",IF(COUNTIF(F15:I15,"X")<>1,"FALTA/DUPLA: CONDIÇÃO DA PLATAFORMA",IF(COUNTIF(J15:L15,"X")<>1,"FALTA/DUPLA: DRENAGEM SUPERFICIAL","OK"))) -> OK
A16: ACESSO02 | B16: C | C16: 7 | D16: 8 | E16: =D16-C16 -> 1 | G16: x | J16: x | N16: =IF(COUNTA(F16:L16)=0,"— não preenchido",IF(COUNTIF(F16:I16,"X")<>1,"FALTA/DUPLA: CONDIÇÃO DA PLATAFORMA",IF(COUNTIF(J16:L16,"X")<>1,"FALTA/DUPLA: DRENAGEM SUPERFICIAL","OK"))) -> OK
A17: ACESSO02 | B17: C | C17: 8 | D17: 9 | E17: =D17-C17 -> 1 | G17: x | J17: x | N17: =IF(COUNTA(F17:L17)=0,"— não preenchido",IF(COUNTIF(F17:I17,"X")<>1,"FALTA/DUPLA: CONDIÇÃO DA PLATAFORMA",IF(COUNTIF(J17:L17,"X")<>1,"FALTA/DUPLA: DRENAGEM SUPERFICIAL","OK"))) -> OK
A18: ACESSO02 | B18: C | C18: 9 | D18: 10 | E18: =D18-C18 -> 1 | G18: x | J18: x | N18: =IF(COUNTA(F18:L18)=0,"— não preenchido",IF(COUNTIF(F18:I18,"X")<>1,"FALTA/DUPLA: CONDIÇÃO DA PLATAFORMA",IF(COUNTIF(J18:L18,"X")<>1,"FALTA/DUPLA: DRENAGEM SUPERFICIAL","OK"))) -> OK
A19: ACESSO02 | B19: C | C19: 10 | D19: 11 | E19: =D19-C19 -> 1 | G19: x | J19: x | N19: =IF(COUNTA(F19:L19)=0,"— não preenchido",IF(COUNTIF(F19:I19,"X")<>1,"FALTA/DUPLA: CONDIÇÃO DA PLATAFORMA",IF(COUNTIF(J19:L19,"X")<>1,"FALTA/DUPLA: DRENAGEM SUPERFICIAL","OK"))) -> OK
A20: ACESSO02 | B20: C | C20: 11 | D20: 12 | E20: =D20-C20 -> 1 | G20: x | J20: x | N20: =IF(COUNTA(F20:L20)=0,"— não preenchido",IF(COUNTIF(F20:I20,"X")<>1,"FALTA/DUPLA: CONDIÇÃO DA PLATAFORMA",IF(COUNTIF(J20:L20,"X")<>1,"FALTA/DUPLA: DRENAGEM SUPERFICIAL","OK"))) -> OK
A21: ACESSO02 | B21: C | C21: 12 | D21: 12.317348 | E21: =D21-C21 -> 0.31734807 | G21: x | J21: x | N21: =IF(COUNTA(F21:L21)=0,"— não preenchido",IF(COUNTIF(F21:I21,"X")<>1,"FALTA/DUPLA: CONDIÇÃO DA PLATAFORMA",IF(COUNTIF(J21:L21,"X")<>1,"FALTA/DUPLA: DRENAGEM SUPERFICIAL","OK"))) -> OK
A23: ____________________________________________ | G23: ____________________________________________
A24: TÉCNICO RESPONSÁVEL PELA INSPEÇÃO | G24: VISTO DA SUPERVISÃO
A26: RESUMO DO TRECHO — KM LANÇADO POR ITEM
A27: KM LANÇADO | F27: =SUMIF(F$9:F$21,"X",$E$9:$E$21) -> 0 | G27: =SUMIF(G$9:G$21,"X",$E$9:$E$21) -> 12.317348 | H27: =SUMIF(H$9:H$21,"X",$E$9:$E$21) -> 0 | I27: =SUMIF(I$9:I$21,"X",$E$9:$E$21) -> 0 | J27: =SUMIF(J$9:J$21,"X",$E$9:$E$21) -> 9.3173481 | K27: =SUMIF(K$9:K$21,"X",$E$9:$E$21) -> 3 | L27: =SUMIF(L$9:L$21,"X",$E$9:$E$21) -> 0
A28: % DA EXTENSÃO | F28: =IF($I30=0,0,F27/$I30) -> 0 | G28: =IF($I30=0,0,G27/$I30) -> 1 | H28: =IF($I30=0,0,H27/$I30) -> 0 | I28: =IF($I30=0,0,I27/$I30) -> 0 | J28: =IF($I30=0,0,J27/$I30) -> 0.75644108 | K28: =IF($I30=0,0,K27/$I30) -> 0.24355892 | L28: =IF($I30=0,0,L27/$I30) -> 0
A29: CONFERÊNCIA POR GRUPO | F29: =IF(SUM(F27:I27)=0,"— não preenchido",IF(ROUND(SUM(F27:I27)-$I30,3)=0,"OK — "&ROUND(SUM(F27:I27),3)&" km","ERRO — dif. de "&ROUND(SUM(F27:I27)-$I30,3)&" km")) -> OK — 12,317 km | J29: =IF(SUM(J27:L27)=0,"— não preenchido",IF(ROUND(SUM(J27:L27)-$I30,3)=0,"OK — "&ROUND(SUM(J27:L27),3)&" km","ERRO — dif. de "&ROUND(SUM(J27:L27)-$I30,3)&" km")) -> OK — 12,317 km
A30: EXTENSÃO TOTAL DO TRECHO | I30: =SUM(E9:E21) -> 12.317348 | M30: =COUNTIF(N9:N21,"OK")&" de "&COUNT($E$9:$E$21)&" linhas conferidas" -> 13 de 13 linhas conferidas
A32: LEGENDA
A33: REGULAR | E33: Até 10 irregularidades por km
A34: RUIM | E34: Mais de 10 irregularidades por km
A35: PÉSSIMA | E35: Atoleiro ou ponto crítico
A36: SIT. | E36: LEN = leito natural · EOP = em obras de pavimentação
A37: FAIXA AZUL | E37: Cabeçalho de cada S.R.E.: descrição, situação, jurisdição, extensão e coordenada de início.
A38: INÍCIO / FIM (KM) | E38: Contados de 0 até o fim de CADA S.R.E. Não é o marco quilométrico da rodovia.
A39: SENT. | E39: C = crescente · D = decrescente
A40: FAIXA CINZA | E40: Segmento fora do escopo do contrato: você passa por ele, mas não preenche.
A41: CÉLULA VERMELHA | E41: Mais de uma X no mesmo grupo. Apague uma delas.
A42: CONFERÊNCIA | E42: Só na tela, não sai impresso. Fica OK com uma X em cada grupo.

Sheet 229
A1: PROGRAMA DE MANUTENÇÃO RODOVIÁRIA — FICHA DE INSPEÇÃO — RODOVIAS NÃO PAVIMENTADAS | P1: Valores dos gráficos — troca 0 por N/D para a fatia não aparecer. Não editar.
A2: REGIÃO: 12 — PEIXE | D2: MÊS / ANO: | F2: 46235 | G2: DATA: | J2: TÉCNICO: | K2: ENG. THIAGO BORGES TORQUATO | P2: =IF(F99=0,NA(),F99) -> 81.717854 | Q2: =IF(G99=0,NA(),G99) -> #N/A | R2: =IF(H99=0,NA(),H99) -> #N/A | S2: =IF(I99=0,NA(),I99) -> #N/A | T2: =IF(J99=0,NA(),J99) -> 81.717854 | U2: =IF(K99=0,NA(),K99) -> #N/A | V2: =IF(L99=0,NA(),L99) -> #N/A
A3: TRECHO 229 — RODOVIA TO-296 - TRECHO JAÚ DO TOCANTINS - SÃO SALVADOR DO TOCANTINS | K3: EXTENSÃO: 81,718 km · 3 S.R.E.
A4: COMO PREENCHER: uma X em UMA coluna de cada grupo, por linha. Se houver mais de um defeito no mesmo km, marque o PREDOMINANTE e escreva o resto em OBSERVAÇÕES. A quilometragem é contada de 0 até o fim de CADA S.R.E. (não é o marco da rodovia).
A6: S.R.E. | B6: SENT. | C6: INÍCIO (KM) | D6: FIM (KM) | E6: EXT. (KM) | F6: CONDIÇÃO DA PLATAFORMA | J6: DRENAGEM SUPERFICIAL | M6: OBSERVAÇÕES | N6: CONFERÊNCIA (só na tela)
F7: BOM | G7: REG. (ATÉ 10 IRR./KM) | H7: RUIM (+ 10 IRR./KM) | I7: PÉSSIMA (ATOLEIRO/PTO. CRÍTICO) | J7: LIMPA | K7: OBSTRUÍDA | L7: AUSENTE
A8: S.R.E. 296ETO0240 | ENTR. TO-387 - RETIRO | EOP · Estadual · 22.432 km · início: -12.613204, -48.284007
A9: 296ETO0240 | B9: C | C9: 0 | D9: 1 | E9: =D9-C9 -> 1 | F9: X | J9: X | N9: =IF(COUNTA(F9:L9)=0,"— não preenchido",IF(COUNTIF(F9:I9,"X")<>1,"FALTA/DUPLA: CONDIÇÃO DA PLATAFORMA",IF(COUNTIF(J9:L9,"X")<>1,"FALTA/DUPLA: DRENAGEM SUPERFICIAL","OK"))) -> OK
A10: 296ETO0240 | B10: C | C10: 1 | D10: 2 | E10: =D10-C10 -> 1 | F10: X | J10: X | N10: =IF(COUNTA(F10:L10)=0,"— não preenchido",IF(COUNTIF(F10:I10,"X")<>1,"FALTA/DUPLA: CONDIÇÃO DA PLATAFORMA",IF(COUNTIF(J10:L10,"X")<>1,"FALTA/DUPLA: DRENAGEM SUPERFICIAL","OK"))) -> OK
A11: 296ETO0240 | B11: C | C11: 2 | D11: 3 | E11: =D11-C11 -> 1 | F11: X | J11: X | N11: =IF(COUNTA(F11:L11)=0,"— não preenchido",IF(COUNTIF(F11:I11,"X")<>1,"FALTA/DUPLA: CONDIÇÃO DA PLATAFORMA",IF(COUNTIF(J11:L11,"X")<>1,"FALTA/DUPLA: DRENAGEM SUPERFICIAL","OK"))) -> OK
A12: 296ETO0240 | B12: C | C12: 3 | D12: 4 | E12: =D12-C12 -> 1 | F12: X | J12: X | N12: =IF(COUNTA(F12:L12)=0,"— não preenchido",IF(COUNTIF(F12:I12,"X")<>1,"FALTA/DUPLA: CONDIÇÃO DA PLATAFORMA",IF(COUNTIF(J12:L12,"X")<>1,"FALTA/DUPLA: DRENAGEM SUPERFICIAL","OK"))) -> OK
A13: 296ETO0240 | B13: C | C13: 4 | D13: 5 | E13: =D13-C13 -> 1 | F13: X | J13: X | N13: =IF(COUNTA(F13:L13)=0,"— não preenchido",IF(COUNTIF(F13:I13,"X")<>1,"FALTA/DUPLA: CONDIÇÃO DA PLATAFORMA",IF(COUNTIF(J13:L13,"X")<>1,"FALTA/DUPLA: DRENAGEM SUPERFICIAL","OK"))) -> OK
A14: 296ETO0240 | B14: C | C14: 5 | D14: 6 | E14: =D14-C14 -> 1 | F14: X | J14: X | N14: =IF(COUNTA(F14:L14)=0,"— não preenchido",IF(COUNTIF(F14:I14,"X")<>1,"FALTA/DUPLA: CONDIÇÃO DA PLATAFORMA",IF(COUNTIF(J14:L14,"X")<>1,"FALTA/DUPLA: DRENAGEM SUPERFICIAL","OK"))) -> OK
A15: 296ETO0240 | B15: C | C15: 6 | D15: 7 | E15: =D15-C15 -> 1 | F15: X | J15: X | N15: =IF(COUNTA(F15:L15)=0,"— não preenchido",IF(COUNTIF(F15:I15,"X")<>1,"FALTA/DUPLA: CONDIÇÃO DA PLATAFORMA",IF(COUNTIF(J15:L15,"X")<>1,"FALTA/DUPLA: DRENAGEM SUPERFICIAL","OK"))) -> OK
A16: 296ETO0240 | B16: C | C16: 7 | D16: 8 | E16: =D16-C16 -> 1 | F16: X | J16: X | N16: =IF(COUNTA(F16:L16)=0,"— não preenchido",IF(COUNTIF(F16:I16,"X")<>1,"FALTA/DUPLA: CONDIÇÃO DA PLATAFORMA",IF(COUNTIF(J16:L16,"X")<>1,"FALTA/DUPLA: DRENAGEM SUPERFICIAL","OK"))) -> OK
A17: 296ETO0240 | B17: C | C17: 8 | D17: 9 | E17: =D17-C17 -> 1 | F17: X | J17: X | N17: =IF(COUNTA(F17:L17)=0,"— não preenchido",IF(COUNTIF(F17:I17,"X")<>1,"FALTA/DUPLA: CONDIÇÃO DA PLATAFORMA",IF(COUNTIF(J17:L17,"X")<>1,"FALTA/DUPLA: DRENAGEM SUPERFICIAL","OK"))) -> OK
A18: 296ETO0240 | B18: C | C18: 9 | D18: 10 | E18: =D18-C18 -> 1 | F18: X | J18: X | N18: =IF(COUNTA(F18:L18)=0,"— não preenchido",IF(COUNTIF(F18:I18,"X")<>1,"FALTA/DUPLA: CONDIÇÃO DA PLATAFORMA",IF(COUNTIF(J18:L18,"X")<>1,"FALTA/DUPLA: DRENAGEM SUPERFICIAL","OK"))) -> OK
A19: 296ETO0240 | B19: C | C19: 10 | D19: 11 | E19: =D19-C19 -> 1 | F19: X | J19: X | N19: =IF(COUNTA(F19:L19)=0,"— não preenchido",IF(COUNTIF(F19:I19,"X")<>1,"FALTA/DUPLA: CONDIÇÃO DA PLATAFORMA",IF(COUNTIF(J19:L19,"X")<>1,"FALTA/DUPLA: DRENAGEM SUPERFICIAL","OK"))) -> OK
A20: 296ETO0240 | B20: C | C20: 11 | D20: 12 | E20: =D20-C20 -> 1 | F20: X | J20: X | N20: =IF(COUNTA(F20:L20)=0,"— não preenchido",IF(COUNTIF(F20:I20,"X")<>1,"FALTA/DUPLA: CONDIÇÃO DA PLATAFORMA",IF(COUNTIF(J20:L20,"X")<>1,"FALTA/DUPLA: DRENAGEM SUPERFICIAL","OK"))) -> OK
... A31: 296ETO0240 | B31: C | C31: 22 | D31: 22.432307 | E31: =D31-C31 -> 0.43230674 | F31: X | J31: X | N31: =IF(COUNTA(F31:L31)=0,"— não preenchido",IF(COUNTIF(F31:I31,"X")<>1,"FALTA/DUPLA: CONDIÇÃO DA PLATAFORMA",IF(COUNTIF(J31:L31,"X")<>1,"FALTA/DUPLA: DRENAGEM SUPERFICIAL","OK"))) -> OK
A32: S.R.E. 296ETO0250 | RETIRO - ENTR. TO-491 | EOP · Estadual · 7.658 km · início: -12.610954, -48.286
A33: 296ETO0250 | B33: C | C33: 0 | D33: 1 | E33: =D33-C33 -> 1 | F33: X | J33: X | N33: =IF(COUNTA(F33:L33)=0,"— não preenchido",IF(COUNTIF(F33:I33,"X")<>1,"FALTA/DUPLA: CONDIÇÃO DA PLATAFORMA",IF(COUNTIF(J33:L33,"X")<>1,"FALTA/DUPLA: DRENAGEM SUPERFICIAL","OK"))) -> OK
A34: 296ETO0250 | B34: C | C34: 1 | D34: 2 | E34: =D34-C34 -> 1 | F34: X | J34: X | N34: =IF(COUNTA(F34:L34)=0,"— não preenchido",IF(COUNTIF(F34:I34,"X")<>1,"FALTA/DUPLA: CONDIÇÃO DA PLATAFORMA",IF(COUNTIF(J34:L34,"X")<>1,"FALTA/DUPLA: DRENAGEM SUPERFICIAL","OK"))) -> OK
A35: 296ETO0250 | B35: C | C35: 2 | D35: 3 | E35: =D35-C35 -> 1 | F35: X | J35: X | N35: =IF(COUNTA(F35:L35)=0,"— não preenchido",IF(COUNTIF(F35:I35,"X")<>1,"FALTA/DUPLA: CONDIÇÃO DA PLATAFORMA",IF(COUNTIF(J35:L35,"X")<>1,"FALTA/DUPLA: DRENAGEM SUPERFICIAL","OK"))) -> OK
A36: 296ETO0250 | B36: C | C36: 3 | D36: 4 | E36: =D36-C36 -> 1 | F36: X | J36: X | N36: =IF(COUNTA(F36:L36)=0,"— não preenchido",IF(COUNTIF(F36:I36,"X")<>1,"FALTA/DUPLA: CONDIÇÃO DA PLATAFORMA",IF(COUNTIF(J36:L36,"X")<>1,"FALTA/DUPLA: DRENAGEM SUPERFICIAL","OK"))) -> OK
A37: 296ETO0250 | B37: C | C37: 4 | D37: 5 | E37: =D37-C37 -> 1 | F37: X | J37: X | N37: =IF(COUNTA(F37:L37)=0,"— não preenchido",IF(COUNTIF(F37:I37,"X")<>1,"FALTA/DUPLA: CONDIÇÃO DA PLATAFORMA",IF(COUNTIF(J37:L37,"X")<>1,"FALTA/DUPLA: DRENAGEM SUPERFICIAL","OK"))) -> OK
A38: 296ETO0250 | B38: C | C38: 5 | D38: 6 | E38: =D38-C38 -> 1 | F38: X | J38: X | N38: =IF(COUNTA(F38:L38)=0,"— não preenchido",IF(COUNTIF(F38:I38,"X")<>1,"FALTA/DUPLA: CONDIÇÃO DA PLATAFORMA",IF(COUNTIF(J38:L38,"X")<>1,"FALTA/DUPLA: DRENAGEM SUPERFICIAL","OK"))) -> OK
A39: 296ETO0250 | B39: C | C39: 6 | D39: 7 | E39: =D39-C39 -> 1 | F39: X | J39: X | N39: =IF(COUNTA(F39:L39)=0,"— não preenchido",IF(COUNTIF(F39:I39,"X")<>1,"FALTA/DUPLA: CONDIÇÃO DA PLATAFORMA",IF(COUNTIF(J39:L39,"X")<>1,"FALTA/DUPLA: DRENAGEM SUPERFICIAL","OK"))) -> OK
A40: 296ETO0250 | B40: C | C40: 7 | D40: 7.6576128 | E40: =D40-C40 -> 0.65761278 | F40: X | J40: X | N40: =IF(COUNTA(F40:L40)=0,"— não preenchido",IF(COUNTIF(F40:I40,"X")<>1,"FALTA/DUPLA: CONDIÇÃO DA PLATAFORMA",IF(COUNTIF(J40:L40,"X")<>1,"FALTA/DUPLA: DRENAGEM SUPERFICIAL","OK"))) -> OK
A41: S.R.E. 296ETO0260 | ENTR. TO-491 - JAÚ DO TOCANTINS *TRECHO URBANO* | EOP · Estadual · 51.628 km · início: -12.570387, -48.319684
A42: 296ETO0260 | B42: C | C42: 0 | D42: 1 | E42: =D42-C42 -> 1 | F42: X | J42: X | N42: =IF(COUNTA(F42:L42)=0,"— não preenchido",IF(COUNTIF(F42:I42,"X")<>1,"FALTA/DUPLA: CONDIÇÃO DA PLATAFORMA",IF(COUNTIF(J42:L42,"X")<>1,"FALTA/DUPLA: DRENAGEM SUPERFICIAL","OK"))) -> OK
A43: 296ETO0260 | B43: C | C43: 1 | D43: 2 | E43: =D43-C43 -> 1 | F43: X | J43: X | N43: =IF(COUNTA(F43:L43)=0,"— não preenchido",IF(COUNTIF(F43:I43,"X")<>1,"FALTA/DUPLA: CONDIÇÃO DA PLATAFORMA",IF(COUNTIF(J43:L43,"X")<>1,"FALTA/DUPLA: DRENAGEM SUPERFICIAL","OK"))) -> OK
A44: 296ETO0260 | B44: C | C44: 2 | D44: 3 | E44: =D44-C44 -> 1 | F44: X | J44: X | N44: =IF(COUNTA(F44:L44)=0,"— não preenchido",IF(COUNTIF(F44:I44,"X")<>1,"FALTA/DUPLA: CONDIÇÃO DA PLATAFORMA",IF(COUNTIF(J44:L44,"X")<>1,"FALTA/DUPLA: DRENAGEM SUPERFICIAL","OK"))) -> OK
A45: 296ETO0260 | B45: C | C45: 3 | D45: 4 | E45: =D45-C45 -> 1 | F45: X | J45: X | N45: =IF(COUNTA(F45:L45)=0,"— não preenchido",IF(COUNTIF(F45:I45,"X")<>1,"FALTA/DUPLA: CONDIÇÃO DA PLATAFORMA",IF(COUNTIF(J45:L45,"X")<>1,"FALTA/DUPLA: DRENAGEM SUPERFICIAL","OK"))) -> OK
A46: 296ETO0260 | B46: C | C46: 4 | D46: 5 | E46: =D46-C46 -> 1 | F46: X | J46: X | N46: =IF(COUNTA(F46:L46)=0,"— não preenchido",IF(COUNTIF(F46:I46,"X")<>1,"FALTA/DUPLA: CONDIÇÃO DA PLATAFORMA",IF(COUNTIF(J46:L46,"X")<>1,"FALTA/DUPLA: DRENAGEM SUPERFICIAL","OK"))) -> OK
A47: 296ETO0260 | B47: C | C47: 5 | D47: 6 | E47: =D47-C47 -> 1 | F47: X | J47: X | N47: =IF(COUNTA(F47:L47)=0,"— não preenchido",IF(COUNTIF(F47:I47,"X")<>1,"FALTA/DUPLA: CONDIÇÃO DA PLATAFORMA",IF(COUNTIF(J47:L47,"X")<>1,"FALTA/DUPLA: DRENAGEM SUPERFICIAL","OK"))) -> OK
A48: 296ETO0260 | B48: C | C48: 6 | D48: 7 | E48: =D48-C48 -> 1 | F48: X | J48: X | N48: =IF(COUNTA(F48:L48)=0,"— não preenchido",IF(COUNTIF(F48:I48,"X")<>1,"FALTA/DUPLA: CONDIÇÃO DA PLATAFORMA",IF(COUNTIF(J48:L48,"X")<>1,"FALTA/DUPLA: DRENAGEM SUPERFICIAL","OK"))) -> OK
A49: 296ETO0260 | B49: C | C49: 7 | D49: 8 | E49: =D49-C49 -> 1 | F49: X | J49: X | N49: =IF(COUNTA(F49:L49)=0,"— não preenchido",IF(COUNTIF(F49:I49,"X")<>1,"FALTA/DUPLA: CONDIÇÃO DA PLATAFORMA",IF(COUNTIF(J49:L49,"X")<>1,"FALTA/DUPLA: DRENAGEM SUPERFICIAL","OK"))) -> OK
A50: 296ETO0260 | B50: C | C50: 8 | D50: 9 | E50: =D50-C50 -> 1 | F50: X | J50: X | N50: =IF(COUNTA(F50:L50)=0,"— não preenchido",IF(COUNTIF(F50:I50,"X")<>1,"FALTA/DUPLA: CONDIÇÃO DA PLATAFORMA",IF(COUNTIF(J50:L50,"X")<>1,"FALTA/DUPLA: DRENAGEM SUPERFICIAL","OK"))) -> OK
A51: 296ETO0260 | B51: C | C51: 9 | D51: 10 | E51: =D51-C51 -> 1 | F51: X | J51: X | N51: =IF(COUNTA(F51:L51)=0,"— não preenchido",IF(COUNTIF(F51:I51,"X")<>1,"FALTA/DUPLA: CONDIÇÃO DA PLATAFORMA",IF(COUNTIF(J51:L51,"X")<>1,"FALTA/DUPLA: DRENAGEM SUPERFICIAL","OK"))) -> OK
...

Sheet 231
A1: PROGRAMA DE MANUTENÇÃO RODOVIÁRIA — FICHA DE INSPEÇÃO — RODOVIAS NÃO PAVIMENTADAS | P1: Valores dos gráficos — troca 0 por N/D para a fatia não aparecer. Não editar.
A2: REGIÃO: 12 — PEIXE | D2: MÊS / ANO: | F2: 46235 | G2: DATA: | J2: TÉCNICO: | K2: ENG. THIAGO BORGES TORQUATO | P2: =IF(F55=0,NA(),F55) -> 34.254616 | Q2: =IF(G55=0,NA(),G55) -> #N/A | R2: =IF(H55=0,NA(),H55) -> #N/A | S2: =IF(I55=0,NA(),I55) -> #N/A | T2: =IF(J55=0,NA(),J55) -> 34.254616 | U2: =IF(K55=0,NA(),K55) -> #N/A | V2: =IF(L55=0,NA(),L55) -> #N/A
A3: TRECHO 231 — RODOVIA TO-365 - TRECHO IPUEIRAS - SILVANÓPOLIS | K3: EXTENSÃO: 34,255 km · 4 S.R.E.
A4: COMO PREENCHER: uma X em UMA coluna de cada grupo, por linha. Se houver mais de um defeito no mesmo km, marque o PREDOMINANTE e escreva o resto em OBSERVAÇÕES. A quilometragem é contada de 0 até o fim de CADA S.R.E. (não é o marco da rodovia).
A6: S.R.E. | B6: SENT. | C6: INÍCIO (KM) | D6: FIM (KM) | E6: EXT. (KM) | F6: CONDIÇÃO DA PLATAFORMA | J6: DRENAGEM SUPERFICIAL | M6: OBSERVAÇÕES | N6: CONFERÊNCIA (só na tela)
F7: BOM | G7: REG. (ATÉ 10 IRR./KM) | H7: RUIM (+ 10 IRR./KM) | I7: PÉSSIMA (ATOLEIRO/PTO. CRÍTICO) | J7: LIMPA | K7: OBSTRUÍDA | L7: AUSENTE
A8: S.R.E. 365ETO0170 | ENTR- TO-050-BR-010 (SILVANÓPOLIS) - SURUBIM | LEN · Estadual · 21.354 km · início: -11.15112, -48.182983
A9: 365ETO0170 | B9: C | C9: 0 | D9: 1 | E9: =D9-C9 -> 1 | F9: X | J9: X | N9: =IF(COUNTA(F9:L9)=0,"— não preenchido",IF(COUNTIF(F9:I9,"X")<>1,"FALTA/DUPLA: CONDIÇÃO DA PLATAFORMA",IF(COUNTIF(J9:L9,"X")<>1,"FALTA/DUPLA: DRENAGEM SUPERFICIAL","OK"))) -> OK
A10: 365ETO0170 | B10: C | C10: 1 | D10: 2 | E10: =D10-C10 -> 1 | F10: X | J10: X | N10: =IF(COUNTA(F10:L10)=0,"— não preenchido",IF(COUNTIF(F10:I10,"X")<>1,"FALTA/DUPLA: CONDIÇÃO DA PLATAFORMA",IF(COUNTIF(J10:L10,"X")<>1,"FALTA/DUPLA: DRENAGEM SUPERFICIAL","OK"))) -> OK
A11: 365ETO0170 | B11: C | C11: 2 | D11: 3 | E11: =D11-C11 -> 1 | F11: X | J11: X | N11: =IF(COUNTA(F11:L11)=0,"— não preenchido",IF(COUNTIF(F11:I11,"X")<>1,"FALTA/DUPLA: CONDIÇÃO DA PLATAFORMA",IF(COUNTIF(J11:L11,"X")<>1,"FALTA/DUPLA: DRENAGEM SUPERFICIAL","OK"))) -> OK
A12: 365ETO0170 | B12: C | C12: 3 | D12: 4 | E12: =D12-C12 -> 1 | F12: X | J12: X | N12: =IF(COUNTA(F12:L12)=0,"— não preenchido",IF(COUNTIF(F12:I12,"X")<>1,"FALTA/DUPLA: CONDIÇÃO DA PLATAFORMA",IF(COUNTIF(J12:L12,"X")<>1,"FALTA/DUPLA: DRENAGEM SUPERFICIAL","OK"))) -> OK
A13: 365ETO0170 | B13: C | C13: 4 | D13: 5 | E13: =D13-C13 -> 1 | F13: X | J13: X | N13: =IF(COUNTA(F13:L13)=0,"— não preenchido",IF(COUNTIF(F13:I13,"X")<>1,"FALTA/DUPLA: CONDIÇÃO DA PLATAFORMA",IF(COUNTIF(J13:L13,"X")<>1,"FALTA/DUPLA: DRENAGEM SUPERFICIAL","OK"))) -> OK
A14: 365ETO0170 | B14: C | C14: 5 | D14: 6 | E14: =D14-C14 -> 1 | F14: X | J14: X | N14: =IF(COUNTA(F14:L14)=0,"— não preenchido",IF(COUNTIF(F14:I14,"X")<>1,"FALTA/DUPLA: CONDIÇÃO DA PLATAFORMA",IF(COUNTIF(J14:L14,"X")<>1,"FALTA/DUPLA: DRENAGEM SUPERFICIAL","OK"))) -> OK
A15: 365ETO0170 | B15: C | C15: 6 | D15: 7 | E15: =D15-C15 -> 1 | F15: X | J15: X | N15: =IF(COUNTA(F15:L15)=0,"— não preenchido",IF(COUNTIF(F15:I15,"X")<>1,"FALTA/DUPLA: CONDIÇÃO DA PLATAFORMA",IF(COUNTIF(J15:L15,"X")<>1,"FALTA/DUPLA: DRENAGEM SUPERFICIAL","OK"))) -> OK
A16: 365ETO0170 | B16: C | C16: 7 | D16: 8 | E16: =D16-C16 -> 1 | F16: X | J16: X | N16: =IF(COUNTA(F16:L16)=0,"— não preenchido",IF(COUNTIF(F16:I16,"X")<>1,"FALTA/DUPLA: CONDIÇÃO DA PLATAFORMA",IF(COUNTIF(J16:L16,"X")<>1,"FALTA/DUPLA: DRENAGEM SUPERFICIAL","OK"))) -> OK
A17: 365ETO0170 | B17: C | C17: 8 | D17: 9 | E17: =D17-C17 -> 1 | F17: X | J17: X | N17: =IF(COUNTA(F17:L17)=0,"— não preenchido",IF(COUNTIF(F17:I17,"X")<>1,"FALTA/DUPLA: CONDIÇÃO DA PLATAFORMA",IF(COUNTIF(J17:L17,"X")<>1,"FALTA/DUPLA: DRENAGEM SUPERFICIAL","OK"))) -> OK
A18: 365ETO0170 | B18: C | C18: 9 | D18: 10 | E18: =D18-C18 -> 1 | F18: X | J18: X | N18: =IF(COUNTA(F18:L18)=0,"— não preenchido",IF(COUNTIF(F18:I18,"X")<>1,"FALTA/DUPLA: CONDIÇÃO DA PLATAFORMA",IF(COUNTIF(J18:L18,"X")<>1,"FALTA/DUPLA: DRENAGEM SUPERFICIAL","OK"))) -> OK
A19: 365ETO0170 | B19: C | C19: 10 | D19: 11 | E19: =D19-C19 -> 1 | F19: X | J19: X | N19: =IF(COUNTA(F19:L19)=0,"— não preenchido",IF(COUNTIF(F19:I19,"X")<>1,"FALTA/DUPLA: CONDIÇÃO DA PLATAFORMA",IF(COUNTIF(J19:L19,"X")<>1,"FALTA/DUPLA: DRENAGEM SUPERFICIAL","OK"))) -> OK
A20: 365ETO0170 | B20: C | C20: 11 | D20: 12 | E20: =D20-C20 -> 1 | F20: X | J20: X | N20: =IF(COUNTA(F20:L20)=0,"— não preenchido",IF(COUNTIF(F20:I20,"X")<>1,"FALTA/DUPLA: CONDIÇÃO DA PLATAFORMA",IF(COUNTIF(J20:L20,"X")<>1,"FALTA/DUPLA: DRENAGEM SUPERFICIAL","OK"))) -> OK
... A30: 365ETO0170 | B30: C | C30: 21 | D30: 21.354216 | E30: =D30-C30 -> 0.35421556 | F30: X | J30: X | N30: =IF(COUNTA(F30:L30)=0,"— não preenchido",IF(COUNTIF(F30:I30,"X")<>1,"FALTA/DUPLA: CONDIÇÃO DA PLATAFORMA",IF(COUNTIF(J30:L30,"X")<>1,"FALTA/DUPLA: DRENAGEM SUPERFICIAL","OK"))) -> OK
A31: S.R.E. 365ETO0180 | SURUBIM - ENTR. TO-458 | LEN · Estadual · 6.239 km · início: -11.246862, -48.34366
A32: 365ETO0180 | B32: C | C32: 0 | D32: 1 | E32: =D32-C32 -> 1 | F32: X | J32: X | N32: =IF(COUNTA(F32:L32)=0,"— não preenchido",IF(COUNTIF(F32:I32,"X")<>1,"FALTA/DUPLA: CONDIÇÃO DA PLATAFORMA",IF(COUNTIF(J32:L32,"X")<>1,"FALTA/DUPLA: DRENAGEM SUPERFICIAL","OK"))) -> OK
A33: 365ETO0180 | B33: C | C33: 1 | D33: 2 | E33: =D33-C33 -> 1 | F33: X | J33: X | N33: =IF(COUNTA(F33:L33)=0,"— não preenchido",IF(COUNTIF(F33:I33,"X")<>1,"FALTA/DUPLA: CONDIÇÃO DA PLATAFORMA",IF(COUNTIF(J33:L33,"X")<>1,"FALTA/DUPLA: DRENAGEM SUPERFICIAL","OK"))) -> OK
A34: 365ETO0180 | B34: C | C34: 2 | D34: 3 | E34: =D34-C34 -> 1 | F34: X | J34: X | N34: =IF(COUNTA(F34:L34)=0,"— não preenchido",IF(COUNTIF(F34:I34,"X")<>1,"FALTA/DUPLA: CONDIÇÃO DA PLATAFORMA",IF(COUNTIF(J34:L34,"X")<>1,"FALTA/DUPLA: DRENAGEM SUPERFICIAL","OK"))) -> OK
A35: 365ETO0180 | B35: C | C35: 3 | D35: 4 | E35: =D35-C35 -> 1 | F35: X | J35: X | N35: =IF(COUNTA(F35:L35)=0,"— não preenchido",IF(COUNTIF(F35:I35,"X")<>1,"FALTA/DUPLA: CONDIÇÃO DA PLATAFORMA",IF(COUNTIF(J35:L35,"X")<>1,"FALTA/DUPLA: DRENAGEM SUPERFICIAL","OK"))) -> OK
A36: 365ETO0180 | B36: C | C36: 4 | D36: 5 | E36: =D36-C36 -> 1 | F36: X | J36: X | N36: =IF(COUNTA(F36:L36)=0,"— não preenchido",IF(COUNTIF(F36:I36,"X")<>1,"FALTA/DUPLA: CONDIÇÃO DA PLATAFORMA",IF(COUNTIF(J36:L36,"X")<>1,"FALTA/DUPLA: DRENAGEM SUPERFICIAL","OK"))) -> OK
A37: 365ETO0180 | B37: C | C37: 5 | D37: 6 | E37: =D37-C37 -> 1 | F37: X | J37: X | N37: =IF(COUNTA(F37:L37)=0,"— não preenchido",IF(COUNTIF(F37:I37,"X")<>1,"FALTA/DUPLA: CONDIÇÃO DA PLATAFORMA",IF(COUNTIF(J37:L37,"X")<>1,"FALTA/DUPLA: DRENAGEM SUPERFICIAL","OK"))) -> OK
A38: 365ETO0180 | B38: C | C38: 6 | D38: 6.2394458 | E38: =D38-C38 -> 0.23944584 | F38: X | J38: X | N38: =IF(COUNTA(F38:L38)=0,"— não preenchido",IF(COUNTIF(F38:I38,"X")<>1,"FALTA/DUPLA: CONDIÇÃO DA PLATAFORMA",IF(COUNTIF(J38:L38,"X")<>1,"FALTA/DUPLA: DRENAGEM SUPERFICIAL","OK"))) -> OK
A39: S.R.E. 365ETO0190 | ENTR. TO-458 - IPUEIRAS *TRECHO URBANO* | LEN · Estadual · 5.330 km · início: -11.259612, -48.398791
A40: 365ETO0190 | B40: C | C40: 0 | D40: 1 | E40: =D40-C40 -> 1 | F40: X | J40: X | N40: =IF(COUNTA(F40:L40)=0,"— não preenchido",IF(COUNTIF(F40:I40,"X")<>1,"FALTA/DUPLA: CONDIÇÃO DA PLATAFORMA",IF(COUNTIF(J40:L40,"X")<>1,"FALTA/DUPLA: DRENAGEM SUPERFICIAL","OK"))) -> OK
A41: 365ETO0190 | B41: C | C41: 1 | D41: 2 | E41: =D41-C41 -> 1 | F41: X | J41: X | N41: =IF(COUNTA(F41:L41)=0,"— não preenchido",IF(COUNTIF(F41:I41,"X")<>1,"FALTA/DUPLA: CONDIÇÃO DA PLATAFORMA",IF(COUNTIF(J41:L41,"X")<>1,"FALTA/DUPLA: DRENAGEM SUPERFICIAL","OK"))) -> OK
A42: 365ETO0190 | B42: C | C42: 2 | D42: 3 | E42: =D42-C42 -> 1 | F42: X | J42: X | N42: =IF(COUNTA(F42:L42)=0,"— não preenchido",IF(COUNTIF(F42:I42,"X")<>1,"FALTA/DUPLA: CONDIÇÃO DA PLATAFORMA",IF(COUNTIF(J42:L42,"X")<>1,"FALTA/DUPLA: DRENAGEM SUPERFICIAL","OK"))) -> OK
A43: 365ETO0190 | B43: C | C43: 3 | D43: 4 | E43: =D43-C43 -> 1 | F43: X | J43: X | N43: =IF(COUNTA(F43:L43)=0,"— não preenchido",IF(COUNTIF(F43:I43,"X")<>1,"FALTA/DUPLA: CONDIÇÃO DA PLATAFORMA",IF(COUNTIF(J43:L43,"X")<>1,"FALTA/DUPLA: DRENAGEM SUPERFICIAL","OK"))) -> OK
A44: 365ETO0190 | B44: C | C44: 4 | D44: 5 | E44: =D44-C44 -> 1 | F44: X | J44: X | N44: =IF(COUNTA(F44:L44)=0,"— não preenchido",IF(COUNTIF(F44:I44,"X")<>1,"FALTA/DUPLA: CONDIÇÃO DA PLATAFORMA",IF(COUNTIF(J44:L44,"X")<>1,"FALTA/DUPLA: DRENAGEM SUPERFICIAL","OK"))) -> OK
A45: 365ETO0190 | B45: C | C45: 5 | D45: 5.3298942 | E45: =D45-C45 -> 0.32989419 | F45: X | J45: X | N45: =IF(COUNTA(F45:L45)=0,"— não preenchido",IF(COUNTIF(F45:I45,"X")<>1,"FALTA/DUPLA: CONDIÇÃO DA PLATAFORMA",IF(COUNTIF(J45:L45,"X")<>1,"FALTA/DUPLA: DRENAGEM SUPERFICIAL","OK"))) -> OK
A46: ▲ AQUI HÁ 1.125 km FORA DO ESCOPO DO CONTRATO (perímetro urbano de jurisdição municipal). Você passa por ele, mas NÃO preenche.
A47: S.R.E. 365ETO0210 | ENTR. TO-458 (IPUEIRAS *TRECHO URBANO*) - RIO TOCANTINS( BALSA) | LEN · Estadual · 1.331 km · início: -11.240851, -48.448866
A48: 365ETO0210 | B48: C | C48: 0 | D48: 1 | E48: =D48-C48 -> 1 | F48: X | J48: X | N48: =IF(COUNTA(F48:L48)=0,"— não preenchido",IF(COUNTIF(F48:I48,"X")<>1,"FALTA/DUPLA: CONDIÇÃO DA PLATAFORMA",IF(COUNTIF(J48:L48,"X")<>1,"FALTA/DUPLA: DRENAGEM SUPERFICIAL","OK"))) -> OK
A49: 365ETO0210 | B49: C | C49: 1 | D49: 1.3310602 | E49: =D49-C49 -> 0.33106017 | F49: X | J49: X | N49: =IF(COUNTA(F49:L49)=0,"— não preenchido",IF(COUNTIF(F49:I49,"X")<>1,"FALTA/DUPLA: CONDIÇÃO DA PLATAFORMA",IF(COUNTIF(J49:L49,"X")<>1,"FALTA/DUPLA: DRENAGEM SUPERFICIAL","OK"))) -> OK
A51: ____________________________________________ | G51: ____________________________________________
...

Sheet 232
A1: PROGRAMA DE MANUTENÇÃO RODOVIÁRIA — FICHA DE INSPEÇÃO — RODOVIAS NÃO PAVIMENTADAS | P1: Valores dos gráficos — troca 0 por N/D para a fatia não aparecer. Não editar.
A2: REGIÃO: 12 — PEIXE | D2: MÊS / ANO: | F2: 46235 | G2: DATA: | J2: TÉCNICO: | K2: ENG. THIAGO BORGES TORQUATO | P2: =IF(F106=0,NA(),F106) -> 87.831045 | Q2: =IF(G106=0,NA(),G106) -> #N/A | R2: =IF(H106=0,NA(),H106) -> #N/A | S2: =IF(I106=0,NA(),I106) -> #N/A | T2: =IF(J106=0,NA(),J106) -> 20.945342 | U2: =IF(K106=0,NA(),K106) -> #N/A | V2: =IF(L106=0,NA(),L106) -> 66.885703
A3: TRECHO 232 — RODOVIA TO-373 - TRECHO ENTR. TO-365 (BALSA) - SÃO MIGUEL - LAGOA DO ROMÃO -ENTR. TO-280 | K3: EXTENSÃO: 87,831 km · 4 S.R.E.
A4: COMO PREENCHER: uma X em UMA coluna de cada grupo, por linha. Se houver mais de um defeito no mesmo km, marque o PREDOMINANTE e escreva o resto em OBSERVAÇÕES. A quilometragem é contada de 0 até o fim de CADA S.R.E. (não é o marco da rodovia).
A6: S.R.E. | B6: SENT. | C6: INÍCIO (KM) | D6: FIM (KM) | E6: EXT. (KM) | F6: CONDIÇÃO DA PLATAFORMA | J6: DRENAGEM SUPERFICIAL | M6: OBSERVAÇÕES | N6: CONFERÊNCIA (só na tela)
F7: BOM | G7: REG. (ATÉ 10 IRR./KM) | H7: RUIM (+ 10 IRR./KM) | I7: PÉSSIMA (ATOLEIRO/PTO. CRÍTICO) | J7: LIMPA | K7: OBSTRUÍDA | L7: AUSENTE
A8: S.R.E. 373ETO0120 | RIO TOCANTINS (BALSA) - SÃO MIGUEL | LEN · Estadual · 25.933 km · início: -11.428717, -48.58823
A9: 373ETO0120 | B9: C | C9: 0 | D9: 1 | E9: =D9-C9 -> 1 | F9: X | L9: X | N9: =IF(COUNTA(F9:L9)=0,"— não preenchido",IF(COUNTIF(F9:I9,"X")<>1,"FALTA/DUPLA: CONDIÇÃO DA PLATAFORMA",IF(COUNTIF(J9:L9,"X")<>1,"FALTA/DUPLA: DRENAGEM SUPERFICIAL","OK"))) -> OK
A10: 373ETO0120 | B10: C | C10: 1 | D10: 2 | E10: =D10-C10 -> 1 | F10: X | L10: X | N10: =IF(COUNTA(F10:L10)=0,"— não preenchido",IF(COUNTIF(F10:I10,"X")<>1,"FALTA/DUPLA: CONDIÇÃO DA PLATAFORMA",IF(COUNTIF(J10:L10,"X")<>1,"FALTA/DUPLA: DRENAGEM SUPERFICIAL","OK"))) -> OK
A11: 373ETO0120 | B11: C | C11: 2 | D11: 3 | E11: =D11-C11 -> 1 | F11: X | L11: X | N11: =IF(COUNTA(F11:L11)=0,"— não preenchido",IF(COUNTIF(F11:I11,"X")<>1,"FALTA/DUPLA: CONDIÇÃO DA PLATAFORMA",IF(COUNTIF(J11:L11,"X")<>1,"FALTA/DUPLA: DRENAGEM SUPERFICIAL","OK"))) -> OK
A12: 373ETO0120 | B12: C | C12: 3 | D12: 4 | E12: =D12-C12 -> 1 | F12: X | L12: X | N12: =IF(COUNTA(F12:L12)=0,"— não preenchido",IF(COUNTIF(F12:I12,"X")<>1,"FALTA/DUPLA: CONDIÇÃO DA PLATAFORMA",IF(COUNTIF(J12:L12,"X")<>1,"FALTA/DUPLA: DRENAGEM SUPERFICIAL","OK"))) -> OK
A13: 373ETO0120 | B13: C | C13: 4 | D13: 5 | E13: =D13-C13 -> 1 | F13: X | L13: X | N13: =IF(COUNTA(F13:L13)=0,"— não preenchido",IF(COUNTIF(F13:I13,"X")<>1,"FALTA/DUPLA: CONDIÇÃO DA PLATAFORMA",IF(COUNTIF(J13:L13,"X")<>1,"FALTA/DUPLA: DRENAGEM SUPERFICIAL","OK"))) -> OK
A14: 373ETO0120 | B14: C | C14: 5 | D14: 6 | E14: =D14-C14 -> 1 | F14: X | L14: X | N14: =IF(COUNTA(F14:L14)=0,"— não preenchido",IF(COUNTIF(F14:I14,"X")<>1,"FALTA/DUPLA: CONDIÇÃO DA PLATAFORMA",IF(COUNTIF(J14:L14,"X")<>1,"FALTA/DUPLA: DRENAGEM SUPERFICIAL","OK"))) -> OK
A15: 373ETO0120 | B15: C | C15: 6 | D15: 7 | E15: =D15-C15 -> 1 | F15: X | L15: X | N15: =IF(COUNTA(F15:L15)=0,"— não preenchido",IF(COUNTIF(F15:I15,"X")<>1,"FALTA/DUPLA: CONDIÇÃO DA PLATAFORMA",IF(COUNTIF(J15:L15,"X")<>1,"FALTA/DUPLA: DRENAGEM SUPERFICIAL","OK"))) -> OK
A16: 373ETO0120 | B16: C | C16: 7 | D16: 8 | E16: =D16-C16 -> 1 | F16: X | L16: X | N16: =IF(COUNTA(F16:L16)=0,"— não preenchido",IF(COUNTIF(F16:I16,"X")<>1,"FALTA/DUPLA: CONDIÇÃO DA PLATAFORMA",IF(COUNTIF(J16:L16,"X")<>1,"FALTA/DUPLA: DRENAGEM SUPERFICIAL","OK"))) -> OK
A17: 373ETO0120 | B17: C | C17: 8 | D17: 9 | E17: =D17-C17 -> 1 | F17: X | L17: X | N17: =IF(COUNTA(F17:L17)=0,"— não preenchido",IF(COUNTIF(F17:I17,"X")<>1,"FALTA/DUPLA: CONDIÇÃO DA PLATAFORMA",IF(COUNTIF(J17:L17,"X")<>1,"FALTA/DUPLA: DRENAGEM SUPERFICIAL","OK"))) -> OK
A18: 373ETO0120 | B18: C | C18: 9 | D18: 10 | E18: =D18-C18 -> 1 | F18: X | L18: X | N18: =IF(COUNTA(F18:L18)=0,"— não preenchido",IF(COUNTIF(F18:I18,"X")<>1,"FALTA/DUPLA: CONDIÇÃO DA PLATAFORMA",IF(COUNTIF(J18:L18,"X")<>1,"FALTA/DUPLA: DRENAGEM SUPERFICIAL","OK"))) -> OK
A19: 373ETO0120 | B19: C | C19: 10 | D19: 11 | E19: =D19-C19 -> 1 | F19: X | L19: X | N19: =IF(COUNTA(F19:L19)=0,"— não preenchido",IF(COUNTIF(F19:I19,"X")<>1,"FALTA/DUPLA: CONDIÇÃO DA PLATAFORMA",IF(COUNTIF(J19:L19,"X")<>1,"FALTA/DUPLA: DRENAGEM SUPERFICIAL","OK"))) -> OK
A20: 373ETO0120 | B20: C | C20: 11 | D20: 12 | E20: =D20-C20 -> 1 | F20: X | L20: X | N20: =IF(COUNTA(F20:L20)=0,"— não preenchido",IF(COUNTIF(F20:I20,"X")<>1,"FALTA/DUPLA: CONDIÇÃO DA PLATAFORMA",IF(COUNTIF(J20:L20,"X")<>1,"FALTA/DUPLA: DRENAGEM SUPERFICIAL","OK"))) -> OK
... A34: 373ETO0120 | B34: C | C34: 25 | D34: 25.932627 | E34: =D34-C34 -> 0.93262673 | F34: X | L34: X | N34: =IF(COUNTA(F34:L34)=0,"— não preenchido",IF(COUNTIF(F34:I34,"X")<>1,"FALTA/DUPLA: CONDIÇÃO DA PLATAFORMA",IF(COUNTIF(J34:L34,"X")<>1,"FALTA/DUPLA: DRENAGEM SUPERFICIAL","OK"))) -> OK
A35: S.R.E. 373ETO0130 | SÃO MIGUEL - LAGOA DO ROMÃO | LEN · Estadual · 39.401 km · início: -11.59937, -48.527765
A36: 373ETO0130 | B36: C | C36: 0 | D36: 1 | E36: =D36-C36 -> 1 | F36: X | L36: X | N36: =IF(COUNTA(F36:L36)=0,"— não preenchido",IF(COUNTIF(F36:I36,"X")<>1,"FALTA/DUPLA: CONDIÇÃO DA PLATAFORMA",IF(COUNTIF(J36:L36,"X")<>1,"FALTA/DUPLA: DRENAGEM SUPERFICIAL","OK"))) -> OK
A37: 373ETO0130 | B37: C | C37: 1 | D37: 2 | E37: =D37-C37 -> 1 | F37: X | L37: X | N37: =IF(COUNTA(F37:L37)=0,"— não preenchido",IF(COUNTIF(F37:I37,"X")<>1,"FALTA/DUPLA: CONDIÇÃO DA PLATAFORMA",IF(COUNTIF(J37:L37,"X")<>1,"FALTA/DUPLA: DRENAGEM SUPERFICIAL","OK"))) -> OK
A38: 373ETO0130 | B38: C | C38: 2 | D38: 3 | E38: =D38-C38 -> 1 | F38: X | L38: X | N38: =IF(COUNTA(F38:L38)=0,"— não preenchido",IF(COUNTIF(F38:I38,"X")<>1,"FALTA/DUPLA: CONDIÇÃO DA PLATAFORMA",IF(COUNTIF(J38:L38,"X")<>1,"FALTA/DUPLA: DRENAGEM SUPERFICIAL","OK"))) -> OK
A39: 373ETO0130 | B39: C | C39: 3 | D39: 4 | E39: =D39-C39 -> 1 | F39: X | L39: X | N39: =IF(COUNTA(F39:L39)=0,"— não preenchido",IF(COUNTIF(F39:I39,"X")<>1,"FALTA/DUPLA: CONDIÇÃO DA PLATAFORMA",IF(COUNTIF(J39:L39,"X")<>1,"FALTA/DUPLA: DRENAGEM SUPERFICIAL","OK"))) -> OK
A40: 373ETO0130 | B40: C | C40: 4 | D40: 5 | E40: =D40-C40 -> 1 | F40: X | L40: X | N40: =IF(COUNTA(F40:L40)=0,"— não preenchido",IF(COUNTIF(F40:I40,"X")<>1,"FALTA/DUPLA: CONDIÇÃO DA PLATAFORMA",IF(COUNTIF(J40:L40,"X")<>1,"FALTA/DUPLA: DRENAGEM SUPERFICIAL","OK"))) -> OK
A41: 373ETO0130 | B41: C | C41: 5 | D41: 6 | E41: =D41-C41 -> 1 | F41: X | L41: X | N41: =IF(COUNTA(F41:L41)=0,"— não preenchido",IF(COUNTIF(F41:I41,"X")<>1,"FALTA/DUPLA: CONDIÇÃO DA PLATAFORMA",IF(COUNTIF(J41:L41,"X")<>1,"FALTA/DUPLA: DRENAGEM SUPERFICIAL","OK"))) -> OK
A42: 373ETO0130 | B42: C | C42: 6 | D42: 7 | E42: =D42-C42 -> 1 | F42: X | L42: X | N42: =IF(COUNTA(F42:L42)=0,"— não preenchido",IF(COUNTIF(F42:I42,"X")<>1,"FALTA/DUPLA: CONDIÇÃO DA PLATAFORMA",IF(COUNTIF(J42:L42,"X")<>1,"FALTA/DUPLA: DRENAGEM SUPERFICIAL","OK"))) -> OK
A43: 373ETO0130 | B43: C | C43: 7 | D43: 8 | E43: =D43-C43 -> 1 | F43: X | L43: X | N43: =IF(COUNTA(F43:L43)=0,"— não preenchido",IF(COUNTIF(F43:I43,"X")<>1,"FALTA/DUPLA: CONDIÇÃO DA PLATAFORMA",IF(COUNTIF(J43:L43,"X")<>1,"FALTA/DUPLA: DRENAGEM SUPERFICIAL","OK"))) -> OK
A44: 373ETO0130 | B44: C | C44: 8 | D44: 9 | E44: =D44-C44 -> 1 | F44: X | L44: X | N44: =IF(COUNTA(F44:L44)=0,"— não preenchido",IF(COUNTIF(F44:I44,"X")<>1,"FALTA/DUPLA: CONDIÇÃO DA PLATAFORMA",IF(COUNTIF(J44:L44,"X")<>1,"FALTA/DUPLA: DRENAGEM SUPERFICIAL","OK"))) -> OK
A45: 373ETO0130 | B45: C | C45: 9 | D45: 10 | E45: =D45-C45 -> 1 | F45: X | L45: X | N45: =IF(COUNTA(F45:L45)=0,"— não preenchido",IF(COUNTIF(F45:I45,"X")<>1,"FALTA/DUPLA: CONDIÇÃO DA PLATAFORMA",IF(COUNTIF(J45:L45,"X")<>1,"FALTA/DUPLA: DRENAGEM SUPERFICIAL","OK"))) -> OK
A46: 373ETO0130 | B46: C | C46: 10 | D46: 11 | E46: =D46-C46 -> 1 | F46: X | L46: X | N46: =IF(COUNTA(F46:L46)=0,"— não preenchido",IF(COUNTIF(F46:I46,"X")<>1,"FALTA/DUPLA: CONDIÇÃO DA PLATAFORMA",IF(COUNTIF(J46:L46,"X")<>1,"FALTA/DUPLA: DRENAGEM SUPERFICIAL","OK"))) -> OK
A47: 373ETO0130 | B47: C | C47: 11 | D47: 12 | E47: =D47-C47 -> 1 | F47: X | L47: X | N47: =IF(COUNTA(F47:L47)=0,"— não preenchido",IF(COUNTIF(F47:I47,"X")<>1,"FALTA/DUPLA: CONDIÇÃO DA PLATAFORMA",IF(COUNTIF(J47:L47,"X")<>1,"FALTA/DUPLA: DRENAGEM SUPERFICIAL","OK"))) -> OK
... A75: 373ETO0130 | B75: C | C75: 39 | D75: 39.401208 | E75: =D75-C75 -> 0.40120784 | F75: X | L75: X | N75: =IF(COUNTA(F75:L75)=0,"— não preenchido",IF(COUNTIF(F75:I75,"X")<>1,"FALTA/DUPLA: CONDIÇÃO DA PLATAFORMA",IF(COUNTIF(J75:L75,"X")<>1,"FALTA/DUPLA: DRENAGEM SUPERFICIAL","OK"))) -> OK
A76: S.R.E. 373ETO0140 | LAGOA DO ROMÃO - ENTR. TO-479 | LEN · Estadual · 1.552 km · início: -11.842096, -48.39303
A77: 373ETO0140 | B77: C | C77: 0 | D77: 1 | E77: =D77-C77 -> 1 | F77: X | L77: X | N77: =IF(COUNTA(F77:L77)=0,"— não preenchido",IF(COUNTIF(F77:I77,"X")<>1,"FALTA/DUPLA: CONDIÇÃO DA PLATAFORMA",IF(COUNTIF(J77:L77,"X")<>1,"FALTA/DUPLA: DRENAGEM SUPERFICIAL","OK"))) -> OK
A78: 373ETO0140 | B78: C | C78: 1 | D78: 1.5518686 | E78: =D78-C78 -> 0.55186857 | F78: X | L78: X | N78: =IF(COUNTA(F78:L78)=0,"— não preenchido",IF(COUNTIF(F78:I78,"X")<>1,"FALTA/DUPLA: CONDIÇÃO DA PLATAFORMA",IF(COUNTIF(J78:L78,"X")<>1,"FALTA/DUPLA: DRENAGEM SUPERFICIAL","OK"))) -> OK
A79: S.R.E. 373ETO0150 | ENTR.TO- 479 - ENTR. TO-280 | LEN · Estadual · 20.945 km · início: -11.853915, -48.395878
A80: 373ETO0150 | B80: C | C80: 0 | D80: 1 | E80: =D80-C80 -> 1 | F80: X | J80: X | N80: =IF(COUNTA(F80:L80)=0,"— não preenchido",IF(COUNTIF(F80:I80,"X")<>1,"FALTA/DUPLA: CONDIÇÃO DA PLATAFORMA",IF(COUNTIF(J80:L80,"X")<>1,"FALTA/DUPLA: DRENAGEM SUPERFICIAL","OK"))) -> OK
A81: 373ETO0150 | B81: C | C81: 1 | D81: 2 | E81: =D81-C81 -> 1 | F81: X | J81: X | N81: =IF(COUNTA(F81:L81)=0,"— não preenchido",IF(COUNTIF(F81:I81,"X")<>1,"FALTA/DUPLA: CONDIÇÃO DA PLATAFORMA",IF(COUNTIF(J81:L81,"X")<>1,"FALTA/DUPLA: DRENAGEM SUPERFICIAL","OK"))) -> OK
...

Sheet 236
A1: PROGRAMA DE MANUTENÇÃO RODOVIÁRIA — FICHA DE INSPEÇÃO — RODOVIAS NÃO PAVIMENTADAS | P1: Valores dos gráficos — troca 0 por N/D para a fatia não aparecer. Não editar.
A2: REGIÃO: 12 — PEIXE | D2: MÊS / ANO: | F2: 46235 | G2: DATA: | J2: TÉCNICO: | K2: ENG. THIAGO BORGES TORQUATO | P2: =IF(F52=0,NA(),F52) -> 6 | Q2: =IF(G52=0,NA(),G52) -> 26.96664 | R2: =IF(H52=0,NA(),H52) -> 1 | S2: =IF(I52=0,NA(),I52) -> #N/A | T2: =IF(J52=0,NA(),J52) -> 33.96664 | U2: =IF(K52=0,NA(),K52) -> #N/A | V2: =IF(L52=0,NA(),L52) -> #N/A
A3: TRECHO 236 — RODOVIA TO-458 - TRECHO ENTR. TO-365 (IPUEIRAS) - ENTR. BR-010 | K3: EXTENSÃO: 33,967 km · 3 S.R.E.
A4: COMO PREENCHER: uma X em UMA coluna de cada grupo, por linha. Se houver mais de um defeito no mesmo km, marque o PREDOMINANTE e escreva o resto em OBSERVAÇÕES. A quilometragem é contada de 0 até o fim de CADA S.R.E. (não é o marco da rodovia).
A6: S.R.E. | B6: SENT. | C6: INÍCIO (KM) | D6: FIM (KM) | E6: EXT. (KM) | F6: CONDIÇÃO DA PLATAFORMA | J6: DRENAGEM SUPERFICIAL | M6: OBSERVAÇÕES | N6: CONFERÊNCIA (só na tela)
F7: BOM | G7: REG. (ATÉ 10 IRR./KM) | H7: RUIM (+ 10 IRR./KM) | I7: PÉSSIMA (ATOLEIRO/PTO. CRÍTICO) | J7: LIMPA | K7: OBSTRUÍDA | L7: AUSENTE
A8: S.R.E. 458ETO0050 | ENTR. TO-365 - MORRO DE SÃO JOÃO | LEN · Estadual · 9.478 km · início: -11.259612, -48.398791
A9: 458ETO0050 | B9: C | C9: 0 | D9: 1 | E9: =D9-C9 -> 1 | F9: X | J9: X | N9: =IF(COUNTA(F9:L9)=0,"— não preenchido",IF(COUNTIF(F9:I9,"X")<>1,"FALTA/DUPLA: CONDIÇÃO DA PLATAFORMA",IF(COUNTIF(J9:L9,"X")<>1,"FALTA/DUPLA: DRENAGEM SUPERFICIAL","OK"))) -> OK
A10: 458ETO0050 | B10: C | C10: 1 | D10: 2 | E10: =D10-C10 -> 1 | F10: X | J10: X | N10: =IF(COUNTA(F10:L10)=0,"— não preenchido",IF(COUNTIF(F10:I10,"X")<>1,"FALTA/DUPLA: CONDIÇÃO DA PLATAFORMA",IF(COUNTIF(J10:L10,"X")<>1,"FALTA/DUPLA: DRENAGEM SUPERFICIAL","OK"))) -> OK
A11: 458ETO0050 | B11: C | C11: 2 | D11: 3 | E11: =D11-C11 -> 1 | F11: X | J11: X | N11: =IF(COUNTA(F11:L11)=0,"— não preenchido",IF(COUNTIF(F11:I11,"X")<>1,"FALTA/DUPLA: CONDIÇÃO DA PLATAFORMA",IF(COUNTIF(J11:L11,"X")<>1,"FALTA/DUPLA: DRENAGEM SUPERFICIAL","OK"))) -> OK
A12: 458ETO0050 | B12: C | C12: 3 | D12: 4 | E12: =D12-C12 -> 1 | F12: X | J12: X | N12: =IF(COUNTA(F12:L12)=0,"— não preenchido",IF(COUNTIF(F12:I12,"X")<>1,"FALTA/DUPLA: CONDIÇÃO DA PLATAFORMA",IF(COUNTIF(J12:L12,"X")<>1,"FALTA/DUPLA: DRENAGEM SUPERFICIAL","OK"))) -> OK
A13: 458ETO0050 | B13: C | C13: 4 | D13: 5 | E13: =D13-C13 -> 1 | F13: X | J13: X | N13: =IF(COUNTA(F13:L13)=0,"— não preenchido",IF(COUNTIF(F13:I13,"X")<>1,"FALTA/DUPLA: CONDIÇÃO DA PLATAFORMA",IF(COUNTIF(J13:L13,"X")<>1,"FALTA/DUPLA: DRENAGEM SUPERFICIAL","OK"))) -> OK
A14: 458ETO0050 | B14: C | C14: 5 | D14: 6 | E14: =D14-C14 -> 1 | F14: X | J14: X | N14: =IF(COUNTA(F14:L14)=0,"— não preenchido",IF(COUNTIF(F14:I14,"X")<>1,"FALTA/DUPLA: CONDIÇÃO DA PLATAFORMA",IF(COUNTIF(J14:L14,"X")<>1,"FALTA/DUPLA: DRENAGEM SUPERFICIAL","OK"))) -> OK
A15: 458ETO0050 | B15: C | C15: 6 | D15: 7 | E15: =D15-C15 -> 1 | G15: X | J15: X | N15: =IF(COUNTA(F15:L15)=0,"— não preenchido",IF(COUNTIF(F15:I15,"X")<>1,"FALTA/DUPLA: CONDIÇÃO DA PLATAFORMA",IF(COUNTIF(J15:L15,"X")<>1,"FALTA/DUPLA: DRENAGEM SUPERFICIAL","OK"))) -> OK
A16: 458ETO0050 | B16: C | C16: 7 | D16: 8 | E16: =D16-C16 -> 1 | G16: X | J16: X | N16: =IF(COUNTA(F16:L16)=0,"— não preenchido",IF(COUNTIF(F16:I16,"X")<>1,"FALTA/DUPLA: CONDIÇÃO DA PLATAFORMA",IF(COUNTIF(J16:L16,"X")<>1,"FALTA/DUPLA: DRENAGEM SUPERFICIAL","OK"))) -> OK
A17: 458ETO0050 | B17: C | C17: 8 | D17: 9 | E17: =D17-C17 -> 1 | G17: X | J17: X | N17: =IF(COUNTA(F17:L17)=0,"— não preenchido",IF(COUNTIF(F17:I17,"X")<>1,"FALTA/DUPLA: CONDIÇÃO DA PLATAFORMA",IF(COUNTIF(J17:L17,"X")<>1,"FALTA/DUPLA: DRENAGEM SUPERFICIAL","OK"))) -> OK
A18: 458ETO0050 | B18: C | C18: 9 | D18: 9.4784748 | E18: =D18-C18 -> 0.4784748 | G18: X | J18: X | N18: =IF(COUNTA(F18:L18)=0,"— não preenchido",IF(COUNTIF(F18:I18,"X")<>1,"FALTA/DUPLA: CONDIÇÃO DA PLATAFORMA",IF(COUNTIF(J18:L18,"X")<>1,"FALTA/DUPLA: DRENAGEM SUPERFICIAL","OK"))) -> OK
A19: S.R.E. 458ETO0060 | MORRO DE SÃO JOÃO - ENTR. TO-482 | LEN · Estadual · 21.461 km · início: -11.39927, -48.20139
A20: 458ETO0060 | B20: C | C20: 0 | D20: 1 | E20: =D20-C20 -> 1 | G20: X | J20: X | N20: =IF(COUNTA(F20:L20)=0,"— não preenchido",IF(COUNTIF(F20:I20,"X")<>1,"FALTA/DUPLA: CONDIÇÃO DA PLATAFORMA",IF(COUNTIF(J20:L20,"X")<>1,"FALTA/DUPLA: DRENAGEM SUPERFICIAL","OK"))) -> OK
A21: 458ETO0060 | B21: C | C21: 1 | D21: 2 | E21: =D21-C21 -> 1 | G21: X | J21: X | N21: =IF(COUNTA(F21:L21)=0,"— não preenchido",IF(COUNTIF(F21:I21,"X")<>1,"FALTA/DUPLA: CONDIÇÃO DA PLATAFORMA",IF(COUNTIF(J21:L21,"X")<>1,"FALTA/DUPLA: DRENAGEM SUPERFICIAL","OK"))) -> OK
A22: 458ETO0060 | B22: C | C22: 2 | D22: 3 | E22: =D22-C22 -> 1 | G22: X | J22: X | N22: =IF(COUNTA(F22:L22)=0,"— não preenchido",IF(COUNTIF(F22:I22,"X")<>1,"FALTA/DUPLA: CONDIÇÃO DA PLATAFORMA",IF(COUNTIF(J22:L22,"X")<>1,"FALTA/DUPLA: DRENAGEM SUPERFICIAL","OK"))) -> OK
A23: 458ETO0060 | B23: C | C23: 3 | D23: 4 | E23: =D23-C23 -> 1 | G23: X | J23: X | N23: =IF(COUNTA(F23:L23)=0,"— não preenchido",IF(COUNTIF(F23:I23,"X")<>1,"FALTA/DUPLA: CONDIÇÃO DA PLATAFORMA",IF(COUNTIF(J23:L23,"X")<>1,"FALTA/DUPLA: DRENAGEM SUPERFICIAL","OK"))) -> OK
A24: 458ETO0060 | B24: C | C24: 4 | D24: 5 | E24: =D24-C24 -> 1 | G24: X | J24: X | N24: =IF(COUNTA(F24:L24)=0,"— não preenchido",IF(COUNTIF(F24:I24,"X")<>1,"FALTA/DUPLA: CONDIÇÃO DA PLATAFORMA",IF(COUNTIF(J24:L24,"X")<>1,"FALTA/DUPLA: DRENAGEM SUPERFICIAL","OK"))) -> OK
A25: 458ETO0060 | B25: C | C25: 5 | D25: 6 | E25: =D25-C25 -> 1 | G25: X | J25: X | N25: =IF(COUNTA(F25:L25)=0,"— não preenchido",IF(COUNTIF(F25:I25,"X")<>1,"FALTA/DUPLA: CONDIÇÃO DA PLATAFORMA",IF(COUNTIF(J25:L25,"X")<>1,"FALTA/DUPLA: DRENAGEM SUPERFICIAL","OK"))) -> OK
A26: 458ETO0060 | B26: C | C26: 6 | D26: 7 | E26: =D26-C26 -> 1 | G26: X | J26: X | N26: =IF(COUNTA(F26:L26)=0,"— não preenchido",IF(COUNTIF(F26:I26,"X")<>1,"FALTA/DUPLA: CONDIÇÃO DA PLATAFORMA",IF(COUNTIF(J26:L26,"X")<>1,"FALTA/DUPLA: DRENAGEM SUPERFICIAL","OK"))) -> OK
A27: 458ETO0060 | B27: C | C27: 7 | D27: 8 | E27: =D27-C27 -> 1 | G27: X | J27: X | N27: =IF(COUNTA(F27:L27)=0,"— não preenchido",IF(COUNTIF(F27:I27,"X")<>1,"FALTA/DUPLA: CONDIÇÃO DA PLATAFORMA",IF(COUNTIF(J27:L27,"X")<>1,"FALTA/DUPLA: DRENAGEM SUPERFICIAL","OK"))) -> OK
A28: 458ETO0060 | B28: C | C28: 8 | D28: 9 | E28: =D28-C28 -> 1 | G28: X | J28: X | N28: =IF(COUNTA(F28:L28)=0,"— não preenchido",IF(COUNTIF(F28:I28,"X")<>1,"FALTA/DUPLA: CONDIÇÃO DA PLATAFORMA",IF(COUNTIF(J28:L28,"X")<>1,"FALTA/DUPLA: DRENAGEM SUPERFICIAL","OK"))) -> OK
A29: 458ETO0060 | B29: C | C29: 9 | D29: 10 | E29: =D29-C29 -> 1 | G29: X | J29: X | N29: =IF(COUNTA(F29:L29)=0,"— não preenchido",IF(COUNTIF(F29:I29,"X")<>1,"FALTA/DUPLA: CONDIÇÃO DA PLATAFORMA",IF(COUNTIF(J29:L29,"X")<>1,"FALTA/DUPLA: DRENAGEM SUPERFICIAL","OK"))) -> OK
A30: 458ETO0060 | B30: C | C30: 10 | D30: 11 | E30: =D30-C30 -> 1 | G30: X | J30: X | N30: =IF(COUNTA(F30:L30)=0,"— não preenchido",IF(COUNTIF(F30:I30,"X")<>1,"FALTA/DUPLA: CONDIÇÃO DA PLATAFORMA",IF(COUNTIF(J30:L30,"X")<>1,"FALTA/DUPLA: DRENAGEM SUPERFICIAL","OK"))) -> OK
A31: 458ETO0060 | B31: C | C31: 11 | D31: 12 | E31: =D31-C31 -> 1 | G31: X | J31: X | N31: =IF(COUNTA(F31:L31)=0,"— não preenchido",IF(COUNTIF(F31:I31,"X")<>1,"FALTA/DUPLA: CONDIÇÃO DA PLATAFORMA",IF(COUNTIF(J31:L31,"X")<>1,"FALTA/DUPLA: DRENAGEM SUPERFICIAL","OK"))) -> OK
... A41: 458ETO0060 | B41: C | C41: 21 | D41: 21.460758 | E41: =D41-C41 -> 0.46075812 | G41: X | J41: X | N41: =IF(COUNTA(F41:L41)=0,"— não preenchido",IF(COUNTIF(F41:I41,"X")<>1,"FALTA/DUPLA: CONDIÇÃO DA PLATAFORMA",IF(COUNTIF(J41:L41,"X")<>1,"FALTA/DUPLA: DRENAGEM SUPERFICIAL","OK"))) -> OK
A42: S.R.E. 458ETO0070 | ENTR. TO-482 - ENTR. TO-050-BR-010 | LEN · Estadual · 3.027 km · início: -11.399238, -48.201314
A43: 458ETO0070 | B43: C | C43: 0 | D43: 1 | E43: =D43-C43 -> 1 | G43: X | J43: X | N43: =IF(COUNTA(F43:L43)=0,"— não preenchido",IF(COUNTIF(F43:I43,"X")<>1,"FALTA/DUPLA: CONDIÇÃO DA PLATAFORMA",IF(COUNTIF(J43:L43,"X")<>1,"FALTA/DUPLA: DRENAGEM SUPERFICIAL","OK"))) -> OK
A44: 458ETO0070 | B44: C | C44: 1 | D44: 2 | E44: =D44-C44 -> 1 | H44: X | J44: X | N44: =IF(COUNTA(F44:L44)=0,"— não preenchido",IF(COUNTIF(F44:I44,"X")<>1,"FALTA/DUPLA: CONDIÇÃO DA PLATAFORMA",IF(COUNTIF(J44:L44,"X")<>1,"FALTA/DUPLA: DRENAGEM SUPERFICIAL","OK"))) -> OK
A45: 458ETO0070 | B45: C | C45: 2 | D45: 3 | E45: =D45-C45 -> 1 | G45: X | J45: X | N45: =IF(COUNTA(F45:L45)=0,"— não preenchido",IF(COUNTIF(F45:I45,"X")<>1,"FALTA/DUPLA: CONDIÇÃO DA PLATAFORMA",IF(COUNTIF(J45:L45,"X")<>1,"FALTA/DUPLA: DRENAGEM SUPERFICIAL","OK"))) -> OK
A46: 458ETO0070 | B46: C | C46: 3 | D46: 3.0274067 | E46: =D46-C46 -> 0.027406718 | G46: X | J46: X | N46: =IF(COUNTA(F46:L46)=0,"— não preenchido",IF(COUNTIF(F46:I46,"X")<>1,"FALTA/DUPLA: CONDIÇÃO DA PLATAFORMA",IF(COUNTIF(J46:L46,"X")<>1,"FALTA/DUPLA: DRENAGEM SUPERFICIAL","OK"))) -> OK
A48: ____________________________________________ | G48: ____________________________________________
A49: TÉCNICO RESPONSÁVEL PELA INSPEÇÃO | G49: VISTO DA SUPERVISÃO
A51: RESUMO DO TRECHO — KM LANÇADO POR ITEM
A52: KM LANÇADO | F52: =SUMIF(F$9:F$46,"X",$E$9:$E$46) -> 6 | G52: =SUMIF(G$9:G$46,"X",$E$9:$E$46) -> 26.96664 | H52: =SUMIF(H$9:H$46,"X",$E$9:$E$46) -> 1 | I52: =SUMIF(I$9:I$46,"X",$E$9:$E$46) -> 0 | J52: =SUMIF(J$9:J$46,"X",$E$9:$E$46) -> 33.96664 | K52: =SUMIF(K$9:K$46,"X",$E$9:$E$46) -> 0 | L52: =SUMIF(L$9:L$46,"X",$E$9:$E$46) -> 0
...

Sheet 237
A1: PROGRAMA DE MANUTENÇÃO RODOVIÁRIA — FICHA DE INSPEÇÃO — RODOVIAS NÃO PAVIMENTADAS | P1: Valores dos gráficos — troca 0 por N/D para a fatia não aparecer. Não editar.
A2: REGIÃO: 12 — PEIXE | D2: MÊS / ANO: | F2: 46235 | G2: DATA: | J2: TÉCNICO: | K2: ENG. THIAGO BORGES TORQUATO | P2: =IF(F41=0,NA(),F41) -> 26.043993 | Q2: =IF(G41=0,NA(),G41) -> #N/A | R2: =IF(H41=0,NA(),H41) -> #N/A | S2: =IF(I41=0,NA(),I41) -> #N/A | T2: =IF(J41=0,NA(),J41) -> 26.043993 | U2: =IF(K41=0,NA(),K41) -> #N/A | V2: =IF(L41=0,NA(),L41) -> #N/A
A3: TRECHO 237 — RODOVIA TO-479 - TRECHO PEIXE - POVOADO LAGOA DO ROMÃO (ENTR. TO-373) | K3: EXTENSÃO: 26,044 km · 1 S.R.E.
A4: COMO PREENCHER: uma X em UMA coluna de cada grupo, por linha. Se houver mais de um defeito no mesmo km, marque o PREDOMINANTE e escreva o resto em OBSERVAÇÕES. A quilometragem é contada de 0 até o fim de CADA S.R.E. (não é o marco da rodovia).
A6: S.R.E. | B6: SENT. | C6: INÍCIO (KM) | D6: FIM (KM) | E6: EXT. (KM) | F6: CONDIÇÃO DA PLATAFORMA | J6: DRENAGEM SUPERFICIAL | M6: OBSERVAÇÕES | N6: CONFERÊNCIA (só na tela)
F7: BOM | G7: REG. (ATÉ 10 IRR./KM) | H7: RUIM (+ 10 IRR./KM) | I7: PÉSSIMA (ATOLEIRO/PTO. CRÍTICO) | J7: LIMPA | K7: OBSTRUÍDA | L7: AUSENTE
A8: S.R.E. 479ETO0010 | ENTROC. TO-373 - PEIXE (RIO TOCANTINS) | LEN · Estadual · 26.044 km · início: -11.853915, -48.395878
A9: 479ETO0010 | B9: C | C9: 0 | D9: 1 | E9: =D9-C9 -> 1 | F9: X | J9: X | N9: =IF(COUNTA(F9:L9)=0,"— não preenchido",IF(COUNTIF(F9:I9,"X")<>1,"FALTA/DUPLA: CONDIÇÃO DA PLATAFORMA",IF(COUNTIF(J9:L9,"X")<>1,"FALTA/DUPLA: DRENAGEM SUPERFICIAL","OK"))) -> OK
A10: 479ETO0010 | B10: C | C10: 1 | D10: 2 | E10: =D10-C10 -> 1 | F10: X | J10: X | N10: =IF(COUNTA(F10:L10)=0,"— não preenchido",IF(COUNTIF(F10:I10,"X")<>1,"FALTA/DUPLA: CONDIÇÃO DA PLATAFORMA",IF(COUNTIF(J10:L10,"X")<>1,"FALTA/DUPLA: DRENAGEM SUPERFICIAL","OK"))) -> OK
A11: 479ETO0010 | B11: C | C11: 2 | D11: 3 | E11: =D11-C11 -> 1 | F11: X | J11: X | N11: =IF(COUNTA(F11:L11)=0,"— não preenchido",IF(COUNTIF(F11:I11,"X")<>1,"FALTA/DUPLA: CONDIÇÃO DA PLATAFORMA",IF(COUNTIF(J11:L11,"X")<>1,"FALTA/DUPLA: DRENAGEM SUPERFICIAL","OK"))) -> OK
A12: 479ETO0010 | B12: C | C12: 3 | D12: 4 | E12: =D12-C12 -> 1 | F12: X | J12: X | N12: =IF(COUNTA(F12:L12)=0,"— não preenchido",IF(COUNTIF(F12:I12,"X")<>1,"FALTA/DUPLA: CONDIÇÃO DA PLATAFORMA",IF(COUNTIF(J12:L12,"X")<>1,"FALTA/DUPLA: DRENAGEM SUPERFICIAL","OK"))) -> OK
A13: 479ETO0010 | B13: C | C13: 4 | D13: 5 | E13: =D13-C13 -> 1 | F13: X | J13: X | N13: =IF(COUNTA(F13:L13)=0,"— não preenchido",IF(COUNTIF(F13:I13,"X")<>1,"FALTA/DUPLA: CONDIÇÃO DA PLATAFORMA",IF(COUNTIF(J13:L13,"X")<>1,"FALTA/DUPLA: DRENAGEM SUPERFICIAL","OK"))) -> OK
A14: 479ETO0010 | B14: C | C14: 5 | D14: 6 | E14: =D14-C14 -> 1 | F14: X | J14: X | N14: =IF(COUNTA(F14:L14)=0,"— não preenchido",IF(COUNTIF(F14:I14,"X")<>1,"FALTA/DUPLA: CONDIÇÃO DA PLATAFORMA",IF(COUNTIF(J14:L14,"X")<>1,"FALTA/DUPLA: DRENAGEM SUPERFICIAL","OK"))) -> OK
A15: 479ETO0010 | B15: C | C15: 6 | D15: 7 | E15: =D15-C15 -> 1 | F15: X | J15: X | N15: =IF(COUNTA(F15:L15)=0,"— não preenchido",IF(COUNTIF(F15:I15,"X")<>1,"FALTA/DUPLA: CONDIÇÃO DA PLATAFORMA",IF(COUNTIF(J15:L15,"X")<>1,"FALTA/DUPLA: DRENAGEM SUPERFICIAL","OK"))) -> OK
A16: 479ETO0010 | B16: C | C16: 7 | D16: 8 | E16: =D16-C16 -> 1 | F16: X | J16: X | N16: =IF(COUNTA(F16:L16)=0,"— não preenchido",IF(COUNTIF(F16:I16,"X")<>1,"FALTA/DUPLA: CONDIÇÃO DA PLATAFORMA",IF(COUNTIF(J16:L16,"X")<>1,"FALTA/DUPLA: DRENAGEM SUPERFICIAL","OK"))) -> OK
A17: 479ETO0010 | B17: C | C17: 8 | D17: 9 | E17: =D17-C17 -> 1 | F17: X | J17: X | N17: =IF(COUNTA(F17:L17)=0,"— não preenchido",IF(COUNTIF(F17:I17,"X")<>1,"FALTA/DUPLA: CONDIÇÃO DA PLATAFORMA",IF(COUNTIF(J17:L17,"X")<>1,"FALTA/DUPLA: DRENAGEM SUPERFICIAL","OK"))) -> OK
A18: 479ETO0010 | B18: C | C18: 9 | D18: 10 | E18: =D18-C18 -> 1 | F18: X | J18: X | N18: =IF(COUNTA(F18:L18)=0,"— não preenchido",IF(COUNTIF(F18:I18,"X")<>1,"FALTA/DUPLA: CONDIÇÃO DA PLATAFORMA",IF(COUNTIF(J18:L18,"X")<>1,"FALTA/DUPLA: DRENAGEM SUPERFICIAL","OK"))) -> OK
A19: 479ETO0010 | B19: C | C19: 10 | D19: 11 | E19: =D19-C19 -> 1 | F19: X | J19: X | N19: =IF(COUNTA(F19:L19)=0,"— não preenchido",IF(COUNTIF(F19:I19,"X")<>1,"FALTA/DUPLA: CONDIÇÃO DA PLATAFORMA",IF(COUNTIF(J19:L19,"X")<>1,"FALTA/DUPLA: DRENAGEM SUPERFICIAL","OK"))) -> OK
A20: 479ETO0010 | B20: C | C20: 11 | D20: 12 | E20: =D20-C20 -> 1 | F20: X | J20: X | N20: =IF(COUNTA(F20:L20)=0,"— não preenchido",IF(COUNTIF(F20:I20,"X")<>1,"FALTA/DUPLA: CONDIÇÃO DA PLATAFORMA",IF(COUNTIF(J20:L20,"X")<>1,"FALTA/DUPLA: DRENAGEM SUPERFICIAL","OK"))) -> OK
... A35: 479ETO0010 | B35: C | C35: 26 | D35: 26.043993 | E35: =D35-C35 -> 0.043992978 | F35: X | J35: X | N35: =IF(COUNTA(F35:L35)=0,"— não preenchido",IF(COUNTIF(F35:I35,"X")<>1,"FALTA/DUPLA: CONDIÇÃO DA PLATAFORMA",IF(COUNTIF(J35:L35,"X")<>1,"FALTA/DUPLA: DRENAGEM SUPERFICIAL","OK"))) -> OK
A37: ____________________________________________ | G37: ____________________________________________
A38: TÉCNICO RESPONSÁVEL PELA INSPEÇÃO | G38: VISTO DA SUPERVISÃO
A40: RESUMO DO TRECHO — KM LANÇADO POR ITEM
A41: KM LANÇADO | F41: =SUMIF(F$9:F$35,"X",$E$9:$E$35) -> 26.043993 | G41: =SUMIF(G$9:G$35,"X",$E$9:$E$35) -> 0 | H41: =SUMIF(H$9:H$35,"X",$E$9:$E$35) -> 0 | I41: =SUMIF(I$9:I$35,"X",$E$9:$E$35) -> 0 | J41: =SUMIF(J$9:J$35,"X",$E$9:$E$35) -> 26.043993 | K41: =SUMIF(K$9:K$35,"X",$E$9:$E$35) -> 0 | L41: =SUMIF(L$9:L$35,"X",$E$9:$E$35) -> 0
A42: % DA EXTENSÃO | F42: =IF($I44=0,0,F41/$I44) -> 1 | G42: =IF($I44=0,0,G41/$I44) -> 0 | H42: =IF($I44=0,0,H41/$I44) -> 0 | I42: =IF($I44=0,0,I41/$I44) -> 0 | J42: =IF($I44=0,0,J41/$I44) -> 1 | K42: =IF($I44=0,0,K41/$I44) -> 0 | L42: =IF($I44=0,0,L41/$I44) -> 0
A43: CONFERÊNCIA POR GRUPO | F43: =IF(SUM(F41:I41)=0,"— não preenchido",IF(ROUND(SUM(F41:I41)-$I44,3)=0,"OK — "&ROUND(SUM(F41:I41),3)&" km","ERRO — dif. de "&ROUND(SUM(F41:I41)-$I44,3)&" km")) -> OK — 26,044 km | J43: =IF(SUM(J41:L41)=0,"— não preenchido",IF(ROUND(SUM(J41:L41)-$I44,3)=0,"OK — "&ROUND(SUM(J41:L41),3)&" km","ERRO — dif. de "&ROUND(SUM(J41:L41)-$I44,3)&" km")) -> OK — 26,044 km
A44: EXTENSÃO TOTAL DO TRECHO | I44: =SUM(E9:E35) -> 26.043993 | M44: =COUNTIF(N9:N35,"OK")&" de "&COUNT($E$9:$E$35)&" linhas conferidas" -> 27 de 27 linhas conferidas
A46: LEGENDA
A47: REGULAR | E47: Até 10 irregularidades por km
A48: RUIM | E48: Mais de 10 irregularidades por km
A49: PÉSSIMA | E49: Atoleiro ou ponto crítico
A50: SIT. | E50: LEN = leito natural · EOP = em obras de pavimentação
A51: FAIXA AZUL | E51: Cabeçalho de cada S.R.E.: descrição, situação, jurisdição, extensão e coordenada de início.
A52: INÍCIO / FIM (KM) | E52: Contados de 0 até o fim de CADA S.R.E. Não é o marco quilométrico da rodovia.
A53: SENT. | E53: C = crescente · D = decrescente
A54: FAIXA CINZA | E54: Segmento fora do escopo do contrato: você passa por ele, mas não preenche.
A55: CÉLULA VERMELHA | E55: Mais de uma X no mesmo grupo. Apague uma delas.
A56: CONFERÊNCIA | E56: Só na tela, não sai impresso. Fica OK com uma X em cada grupo.

Sheet 238
A1: PROGRAMA DE MANUTENÇÃO RODOVIÁRIA — FICHA DE INSPEÇÃO — RODOVIAS NÃO PAVIMENTADAS | P1: Valores dos gráficos — troca 0 por N/D para a fatia não aparecer. Não editar.
A2: REGIÃO: 12 — PEIXE | D2: MÊS / ANO: | F2: 46235 | G2: DATA: | J2: TÉCNICO: | K2: ENG. THIAGO BORGES TORQUATO | P2: =IF(F91=0,NA(),F91) -> 73.554481 | Q2: =IF(G91=0,NA(),G91) -> #N/A | R2: =IF(H91=0,NA(),H91) -> #N/A | S2: =IF(I91=0,NA(),I91) -> #N/A | T2: =IF(J91=0,NA(),J91) -> 73.554481 | U2: =IF(K91=0,NA(),K91) -> #N/A | V2: =IF(L91=0,NA(),L91) -> #N/A
A3: TRECHO 238 — RODOVIA TO-482 - TRECHO: ENTR. TO-280 (SÃO VALÉRIO DE NATIVIDADE) / ENTR. TO-458 | K3: EXTENSÃO: 73,554 km · 3 S.R.E.
