Workbook

Sheet RESUMO
A1: RESUMO CONSOLIDADO — REGIÃO 1 — RODOVIAS NÃO PAVIMENTADAS | M1: Valores dos gráficos — troca 0 por N/D para a fatia não aparecer. Não editar.
A2: Todos os números vêm das abas dos trechos por referência direta. Não digite nada aqui. A coluna CONFERÊNCIA acusa qualquer trecho em que a soma das marcações não fecha com a extensão. | M2: =IF(D17=0,NA(),D17) -> 112.73775 | N2: =IF(E17=0,NA(),E17) -> 178.2525 | O2: =IF(F17=0,NA(),F17) -> 237.98815 | P2: =IF(G17=0,NA(),G17) -> 13 | Q2: =IF(H17=0,NA(),H17) -> 238.60706 | R2: =IF(I17=0,NA(),I17) -> 222.97457 | S2: =IF(J17=0,NA(),J17) -> 80.396771
A4: Nº TRECHO | B4: TRECHO | C4: EXTENSÃO (KM) | D4: CONDIÇÃO DA PLATAFORMA | H4: DRENAGEM SUPERFICIAL | K4: CONFERÊNCIA
D5: BOM | E5: REG. (ATÉ 10 IRR./KM) | F5: RUIM (+ 10 IRR./KM) | G5: PÉSSIMA (ATOLEIRO/PTO. CRÍTICO) | H5: LIMPA | I5: OBSTRUÍDA | J5: AUSENTE
A6: 207 | B6: RODOVIA TO-181 - TRECHO ENTR. TO-255 - ENTR. TO-481 (CAPAO DO COCO) | C6: ='207'!I83 -> 65.901646 | D6: ='207'!F80 -> 0 | E6: ='207'!G80 -> 30 | F6: ='207'!H80 -> 35.901646 | G6: ='207'!I80 -> 0 | H6: ='207'!J80 -> 30 | I6: ='207'!K80 -> 35.901646 | J6: ='207'!L80 -> 0 | K6: =IF(SUM(D6:G6)=0,"— não preenchido",IF(ROUND(SUM(D6:G6)-C6,3)=0,"OK","ERRO — dif. de "&ROUND(SUM(D6:G6)-C6,3)&" km")) -> OK
A7: 208 | B7: RODOVIA TO-181 - TRECHO ENTR. TO-481 (CAPAO DO COCO) - FAZENDA COBRAPE | C7: ='208'!I59 -> 41.632983 | D7: ='208'!F56 -> 41.632983 | E7: ='208'!G56 -> 0 | F7: ='208'!H56 -> 0 | G7: ='208'!I56 -> 0 | H7: ='208'!J56 -> 0 | I7: ='208'!K56 -> 0 | J7: ='208'!L56 -> 41.632983 | K7: =IF(SUM(D7:G7)=0,"— não preenchido",IF(ROUND(SUM(D7:G7)-C7,3)=0,"OK","ERRO — dif. de "&ROUND(SUM(D7:G7)-C7,3)&" km")) -> OK
A8: 211 | B8: RODOVIA TO-181 - TRECHO FUNDAÇÃO BRADESCO - ENTR. TO-070 | C8: ='211'!I59 -> 41.818855 | D8: ='211'!F56 -> 0 | E8: ='211'!G56 -> 30 | F8: ='211'!H56 -> 11.818855 | G8: ='211'!I56 -> 0 | H8: ='211'!J56 -> 0 | I8: ='211'!K56 -> 41.818855 | J8: ='211'!L56 -> 0 | K8: =IF(SUM(D8:G8)=0,"— não preenchido",IF(ROUND(SUM(D8:G8)-C8,3)=0,"OK","ERRO — dif. de "&ROUND(SUM(D8:G8)-C8,3)&" km")) -> OK
A9: 213 | B9: RODOVIA TO-181 - TRECHO ARAGUAÇU - DIVISA TO-GO | C9: ='213'!I58 -> 40.379495 | D9: ='213'!F55 -> 0 | E9: ='213'!G55 -> 0 | F9: ='213'!H55 -> 27.379495 | G9: ='213'!I55 -> 13 | H9: ='213'!J55 -> 0 | I9: ='213'!K55 -> 40.379495 | J9: ='213'!L55 -> 0 | K9: =IF(SUM(D9:G9)=0,"— não preenchido",IF(ROUND(SUM(D9:G9)-C9,3)=0,"OK","ERRO — dif. de "&ROUND(SUM(D9:G9)-C9,3)&" km")) -> OK
A10: 214 | B10: RODOVIA TO-362 - TRECHO SANTA RITA DO TOCANTINS - BREJINHO DE NAZARÉ | C10: ='214'!I63 -> 45.214542 | D10: ='214'!F60 -> 0 | E10: ='214'!G60 -> 15 | F10: ='214'!H60 -> 30.214542 | G10: ='214'!I60 -> 0 | H10: ='214'!J60 -> 45.214542 | I10: ='214'!K60 -> 0 | J10: ='214'!L60 -> 0 | K10: =IF(SUM(D10:G10)=0,"— não preenchido",IF(ROUND(SUM(D10:G10)-C10,3)=0,"OK","ERRO — dif. de "&ROUND(SUM(D10:G10)-C10,3)&" km")) -> OK
A11: 215 | B11: RODOVIA TO-362 - TRECHO BREJINHO DE NAZARÉ - ENTR. TO-365 (ACESSO BALSA) | C11: ='215'!I54 -> 36.281095 | D11: ='215'!F51 -> 0 | E11: ='215'!G51 -> 11 | F11: ='215'!H51 -> 25.281095 | G11: ='215'!I51 -> 0 | H11: ='215'!J51 -> 0 | I11: ='215'!K51 -> 33 | J11: ='215'!L51 -> 3.2810952 | K11: =IF(SUM(D11:G11)=0,"— não preenchido",IF(ROUND(SUM(D11:G11)-C11,3)=0,"OK","ERRO — dif. de "&ROUND(SUM(D11:G11)-C11,3)&" km")) -> OK
A12: 216 | B12: RODOVIA TO-365 - TRECHO RIO TOCANTINS (BALSA) - TREVO DA PRAIA - ENTR. BR-153 | C12: ='216'!I110 -> 89.379777 | D12: ='216'!F107 -> 0 | E12: ='216'!G107 -> 0 | F12: ='216'!H107 -> 89.379777 | G12: ='216'!I107 -> 0 | H12: ='216'!J107 -> 88.379777 | I12: ='216'!K107 -> 0 | J12: ='216'!L107 -> 1 | K12: =IF(SUM(D12:G12)=0,"— não preenchido",IF(ROUND(SUM(D12:G12)-C12,3)=0,"OK","ERRO — dif. de "&ROUND(SUM(D12:G12)-C12,3)&" km")) -> OK
A13: 217 | B13: RODOVIA TO-373 - TRECHO ENTR. TO-365 - RIO TOCANTINS (BALSA) | C13: ='217'!I20 -> 2.3779246 | D13: ='217'!F17 -> 0 | E13: ='217'!G17 -> 2.3779246 | F13: ='217'!H17 -> 0 | G13: ='217'!I17 -> 0 | H13: ='217'!J17 -> 0 | I13: ='217'!K17 -> 0 | J13: ='217'!L17 -> 2.3779246 | K13: =IF(SUM(D13:G13)=0,"— não preenchido",IF(ROUND(SUM(D13:G13)-C13,3)=0,"OK","ERRO — dif. de "&ROUND(SUM(D13:G13)-C13,3)&" km")) -> OK
A14: 221 | B14: RODOVIA TO-481 - TRECHO DUERÉ - ENTR. TO-181 (CAPAO DO COCO) | C14: ='221'!I95 -> 77.104768 | D14: ='221'!F92 -> 71.104768 | E14: ='221'!G92 -> 6 | F14: ='221'!H92 -> 0 | G14: ='221'!I92 -> 0 | H14: ='221'!J92 -> 37 | I14: ='221'!K92 -> 8 | J14: ='221'!L92 -> 32.104768 | K14: =IF(SUM(D14:G14)=0,"— não preenchido",IF(ROUND(SUM(D14:G14)-C14,3)=0,"OK","ERRO — dif. de "&ROUND(SUM(D14:G14)-C14,3)&" km")) -> OK
A15: 222 | B15: RODOVIA TO-483 - TRECHO SUCUPIRA - FIGUEIRÓPOLIS | C15: ='222'!I56 -> 38.012738 | D15: ='222'!F53 -> 0 | E15: ='222'!G53 -> 20 | F15: ='222'!H53 -> 18.012738 | G15: ='222'!I53 -> 0 | H15: ='222'!J53 -> 38.012738 | I15: ='222'!K53 -> 0 | J15: ='222'!L53 -> 0 | K15: =IF(SUM(D15:G15)=0,"— não preenchido",IF(ROUND(SUM(D15:G15)-C15,3)=0,"OK","ERRO — dif. de "&ROUND(SUM(D15:G15)-C15,3)&" km")) -> OK
A16: 223 | B16: RODOVIA TO-484 - TRECHO FIGUEIRÓPOLIS - KM 64 (RIO FORMOSO) | C16: ='223'!I81 -> 63.874574 | D16: ='223'!F78 -> 0 | E16: ='223'!G78 -> 63.874574 | F16: ='223'!H78 -> 0 | G16: ='223'!I78 -> 0 | H16: ='223'!J78 -> 0 | I16: ='223'!K78 -> 63.874574 | J16: ='223'!L78 -> 0 | K16: =IF(SUM(D16:G16)=0,"— não preenchido",IF(ROUND(SUM(D16:G16)-C16,3)=0,"OK","ERRO — dif. de "&ROUND(SUM(D16:G16)-C16,3)&" km")) -> OK
B17: TOTAL PERCORRIDO NO MÊS | C17: =SUM(C6:C16) -> 541.9784 | D17: =SUM(D6:D16) -> 112.73775 | E17: =SUM(E6:E16) -> 178.2525 | F17: =SUM(F6:F16) -> 237.98815 | G17: =SUM(G6:G16) -> 13 | H17: =SUM(H6:H16) -> 238.60706 | I17: =SUM(I6:I16) -> 222.97457 | J17: =SUM(J6:J16) -> 80.396771
B18: % DA EXTENSÃO DA MALHA (541.98 km) | D18: =SUM(D17:G17)/541.98 -> 0.99999705 | H18: (soma do grupo 'CONDIÇÃO DA PLATAFORMA' dividida pela malha)

Sheet 207
A1: PROGRAMA DE MANUTENÇÃO RODOVIÁRIA — FICHA DE INSPEÇÃO — RODOVIAS NÃO PAVIMENTADAS | P1: Valores dos gráficos — troca 0 por N/D para a fatia não aparecer. Não editar.
A2: REGIÃO: 11 — GURUPI | D2: MÊS / ANO: | F2: 46235 | G2: DATA: | J2: TÉCNICO: | K2: ENG. THIAGO BORGES TORQUATO | P2: =IF(F80=0,NA(),F80) -> #N/A | Q2: =IF(G80=0,NA(),G80) -> 30 | R2: =IF(H80=0,NA(),H80) -> 35.901646 | S2: =IF(I80=0,NA(),I80) -> #N/A | T2: =IF(J80=0,NA(),J80) -> 30 | U2: =IF(K80=0,NA(),K80) -> 35.901646 | V2: =IF(L80=0,NA(),L80) -> #N/A
A3: TRECHO 207 — RODOVIA TO-181 - TRECHO ENTR. TO-255 - ENTR. TO-481 (CAPAO DO COCO) | K3: EXTENSÃO: 65,902 km · 1 S.R.E.
A4: COMO PREENCHER: uma X em UMA coluna de cada grupo, por linha. Se houver mais de um defeito no mesmo km, marque o PREDOMINANTE e escreva o resto em OBSERVAÇÕES. A quilometragem é contada de 0 até o fim de CADA S.R.E. (não é o marco da rodovia).
A6: S.R.E. | B6: SENT. | C6: INÍCIO (KM) | D6: FIM (KM) | E6: EXT. (KM) | F6: CONDIÇÃO DA PLATAFORMA | J6: DRENAGEM SUPERFICIAL | M6: OBSERVAÇÕES | N6: CONFERÊNCIA (só na tela)
F7: BOM | G7: REG. (ATÉ 10 IRR./KM) | H7: RUIM (+ 10 IRR./KM) | I7: PÉSSIMA (ATOLEIRO/PTO. CRÍTICO) | J7: LIMPA | K7: OBSTRUÍDA | L7: AUSENTE
A8: S.R.E. 181ETO0070 | ENTR. TO-255 - ENTR. TO-481 (CAPAO DO COCO) | LEN · Estadual · 65.902 km · início: -11.186191, -49.873813
A9: 181ETO0070 | B9: C | C9: 0 | D9: 1 | E9: =D9-C9 -> 1 | G9: X | J9: X | N9: =IF(COUNTA(F9:L9)=0,"— não preenchido",IF(COUNTIF(F9:I9,"X")<>1,"FALTA/DUPLA: CONDIÇÃO DA PLATAFORMA",IF(COUNTIF(J9:L9,"X")<>1,"FALTA/DUPLA: DRENAGEM SUPERFICIAL","OK"))) -> OK
A10: 181ETO0070 | B10: C | C10: 1 | D10: 2 | E10: =D10-C10 -> 1 | G10: X | J10: X | N10: =IF(COUNTA(F10:L10)=0,"— não preenchido",IF(COUNTIF(F10:I10,"X")<>1,"FALTA/DUPLA: CONDIÇÃO DA PLATAFORMA",IF(COUNTIF(J10:L10,"X")<>1,"FALTA/DUPLA: DRENAGEM SUPERFICIAL","OK"))) -> OK
A11: 181ETO0070 | B11: C | C11: 2 | D11: 3 | E11: =D11-C11 -> 1 | G11: X | J11: X | N11: =IF(COUNTA(F11:L11)=0,"— não preenchido",IF(COUNTIF(F11:I11,"X")<>1,"FALTA/DUPLA: CONDIÇÃO DA PLATAFORMA",IF(COUNTIF(J11:L11,"X")<>1,"FALTA/DUPLA: DRENAGEM SUPERFICIAL","OK"))) -> OK
A12: 181ETO0070 | B12: C | C12: 3 | D12: 4 | E12: =D12-C12 -> 1 | G12: X | J12: X | N12: =IF(COUNTA(F12:L12)=0,"— não preenchido",IF(COUNTIF(F12:I12,"X")<>1,"FALTA/DUPLA: CONDIÇÃO DA PLATAFORMA",IF(COUNTIF(J12:L12,"X")<>1,"FALTA/DUPLA: DRENAGEM SUPERFICIAL","OK"))) -> OK
A13: 181ETO0070 | B13: C | C13: 4 | D13: 5 | E13: =D13-C13 -> 1 | G13: X | J13: X | N13: =IF(COUNTA(F13:L13)=0,"— não preenchido",IF(COUNTIF(F13:I13,"X")<>1,"FALTA/DUPLA: CONDIÇÃO DA PLATAFORMA",IF(COUNTIF(J13:L13,"X")<>1,"FALTA/DUPLA: DRENAGEM SUPERFICIAL","OK"))) -> OK
A14: 181ETO0070 | B14: C | C14: 5 | D14: 6 | E14: =D14-C14 -> 1 | G14: X | J14: X | N14: =IF(COUNTA(F14:L14)=0,"— não preenchido",IF(COUNTIF(F14:I14,"X")<>1,"FALTA/DUPLA: CONDIÇÃO DA PLATAFORMA",IF(COUNTIF(J14:L14,"X")<>1,"FALTA/DUPLA: DRENAGEM SUPERFICIAL","OK"))) -> OK
A15: 181ETO0070 | B15: C | C15: 6 | D15: 7 | E15: =D15-C15 -> 1 | G15: X | J15: X | N15: =IF(COUNTA(F15:L15)=0,"— não preenchido",IF(COUNTIF(F15:I15,"X")<>1,"FALTA/DUPLA: CONDIÇÃO DA PLATAFORMA",IF(COUNTIF(J15:L15,"X")<>1,"FALTA/DUPLA: DRENAGEM SUPERFICIAL","OK"))) -> OK
A16: 181ETO0070 | B16: C | C16: 7 | D16: 8 | E16: =D16-C16 -> 1 | G16: X | J16: X | N16: =IF(COUNTA(F16:L16)=0,"— não preenchido",IF(COUNTIF(F16:I16,"X")<>1,"FALTA/DUPLA: CONDIÇÃO DA PLATAFORMA",IF(COUNTIF(J16:L16,"X")<>1,"FALTA/DUPLA: DRENAGEM SUPERFICIAL","OK"))) -> OK
A17: 181ETO0070 | B17: C | C17: 8 | D17: 9 | E17: =D17-C17 -> 1 | G17: X | J17: X | N17: =IF(COUNTA(F17:L17)=0,"— não preenchido",IF(COUNTIF(F17:I17,"X")<>1,"FALTA/DUPLA: CONDIÇÃO DA PLATAFORMA",IF(COUNTIF(J17:L17,"X")<>1,"FALTA/DUPLA: DRENAGEM SUPERFICIAL","OK"))) -> OK
A18: 181ETO0070 | B18: C | C18: 9 | D18: 10 | E18: =D18-C18 -> 1 | G18: X | J18: X | N18: =IF(COUNTA(F18:L18)=0,"— não preenchido",IF(COUNTIF(F18:I18,"X")<>1,"FALTA/DUPLA: CONDIÇÃO DA PLATAFORMA",IF(COUNTIF(J18:L18,"X")<>1,"FALTA/DUPLA: DRENAGEM SUPERFICIAL","OK"))) -> OK
A19: 181ETO0070 | B19: C | C19: 10 | D19: 11 | E19: =D19-C19 -> 1 | G19: X | J19: X | N19: =IF(COUNTA(F19:L19)=0,"— não preenchido",IF(COUNTIF(F19:I19,"X")<>1,"FALTA/DUPLA: CONDIÇÃO DA PLATAFORMA",IF(COUNTIF(J19:L19,"X")<>1,"FALTA/DUPLA: DRENAGEM SUPERFICIAL","OK"))) -> OK
A20: 181ETO0070 | B20: C | C20: 11 | D20: 12 | E20: =D20-C20 -> 1 | G20: X | J20: X | N20: =IF(COUNTA(F20:L20)=0,"— não preenchido",IF(COUNTIF(F20:I20,"X")<>1,"FALTA/DUPLA: CONDIÇÃO DA PLATAFORMA",IF(COUNTIF(J20:L20,"X")<>1,"FALTA/DUPLA: DRENAGEM SUPERFICIAL","OK"))) -> OK
... A38: 181ETO0070 | B38: C | C38: 29 | D38: 30 | E38: =D38-C38 -> 1 | G38: X | J38: X | N38: =IF(COUNTA(F38:L38)=0,"— não preenchido",IF(COUNTIF(F38:I38,"X")<>1,"FALTA/DUPLA: CONDIÇÃO DA PLATAFORMA",IF(COUNTIF(J38:L38,"X")<>1,"FALTA/DUPLA: DRENAGEM SUPERFICIAL","OK"))) -> OK
A39: 181ETO0070 | B39: C | C39: 30 | D39: 31 | E39: =D39-C39 -> 1 | H39: X | K39: X | N39: =IF(COUNTA(F39:L39)=0,"— não preenchido",IF(COUNTIF(F39:I39,"X")<>1,"FALTA/DUPLA: CONDIÇÃO DA PLATAFORMA",IF(COUNTIF(J39:L39,"X")<>1,"FALTA/DUPLA: DRENAGEM SUPERFICIAL","OK"))) -> OK
A40: 181ETO0070 | B40: C | C40: 31 | D40: 32 | E40: =D40-C40 -> 1 | H40: X | K40: X | N40: =IF(COUNTA(F40:L40)=0,"— não preenchido",IF(COUNTIF(F40:I40,"X")<>1,"FALTA/DUPLA: CONDIÇÃO DA PLATAFORMA",IF(COUNTIF(J40:L40,"X")<>1,"FALTA/DUPLA: DRENAGEM SUPERFICIAL","OK"))) -> OK
A41: 181ETO0070 | B41: C | C41: 32 | D41: 33 | E41: =D41-C41 -> 1 | H41: X | K41: X | N41: =IF(COUNTA(F41:L41)=0,"— não preenchido",IF(COUNTIF(F41:I41,"X")<>1,"FALTA/DUPLA: CONDIÇÃO DA PLATAFORMA",IF(COUNTIF(J41:L41,"X")<>1,"FALTA/DUPLA: DRENAGEM SUPERFICIAL","OK"))) -> OK
A42: 181ETO0070 | B42: C | C42: 33 | D42: 34 | E42: =D42-C42 -> 1 | H42: X | K42: X | N42: =IF(COUNTA(F42:L42)=0,"— não preenchido",IF(COUNTIF(F42:I42,"X")<>1,"FALTA/DUPLA: CONDIÇÃO DA PLATAFORMA",IF(COUNTIF(J42:L42,"X")<>1,"FALTA/DUPLA: DRENAGEM SUPERFICIAL","OK"))) -> OK
A43: 181ETO0070 | B43: C | C43: 34 | D43: 35 | E43: =D43-C43 -> 1 | H43: X | K43: X | N43: =IF(COUNTA(F43:L43)=0,"— não preenchido",IF(COUNTIF(F43:I43,"X")<>1,"FALTA/DUPLA: CONDIÇÃO DA PLATAFORMA",IF(COUNTIF(J43:L43,"X")<>1,"FALTA/DUPLA: DRENAGEM SUPERFICIAL","OK"))) -> OK
A44: 181ETO0070 | B44: C | C44: 35 | D44: 36 | E44: =D44-C44 -> 1 | H44: X | K44: X | N44: =IF(COUNTA(F44:L44)=0,"— não preenchido",IF(COUNTIF(F44:I44,"X")<>1,"FALTA/DUPLA: CONDIÇÃO DA PLATAFORMA",IF(COUNTIF(J44:L44,"X")<>1,"FALTA/DUPLA: DRENAGEM SUPERFICIAL","OK"))) -> OK
A45: 181ETO0070 | B45: C | C45: 36 | D45: 37 | E45: =D45-C45 -> 1 | H45: X | K45: X | N45: =IF(COUNTA(F45:L45)=0,"— não preenchido",IF(COUNTIF(F45:I45,"X")<>1,"FALTA/DUPLA: CONDIÇÃO DA PLATAFORMA",IF(COUNTIF(J45:L45,"X")<>1,"FALTA/DUPLA: DRENAGEM SUPERFICIAL","OK"))) -> OK
A46: 181ETO0070 | B46: C | C46: 37 | D46: 38 | E46: =D46-C46 -> 1 | H46: X | K46: X | N46: =IF(COUNTA(F46:L46)=0,"— não preenchido",IF(COUNTIF(F46:I46,"X")<>1,"FALTA/DUPLA: CONDIÇÃO DA PLATAFORMA",IF(COUNTIF(J46:L46,"X")<>1,"FALTA/DUPLA: DRENAGEM SUPERFICIAL","OK"))) -> OK
A47: 181ETO0070 | B47: C | C47: 38 | D47: 39 | E47: =D47-C47 -> 1 | H47: X | K47: X | N47: =IF(COUNTA(F47:L47)=0,"— não preenchido",IF(COUNTIF(F47:I47,"X")<>1,"FALTA/DUPLA: CONDIÇÃO DA PLATAFORMA",IF(COUNTIF(J47:L47,"X")<>1,"FALTA/DUPLA: DRENAGEM SUPERFICIAL","OK"))) -> OK
A48: 181ETO0070 | B48: C | C48: 39 | D48: 40 | E48: =D48-C48 -> 1 | H48: X | K48: X | N48: =IF(COUNTA(F48:L48)=0,"— não preenchido",IF(COUNTIF(F48:I48,"X")<>1,"FALTA/DUPLA: CONDIÇÃO DA PLATAFORMA",IF(COUNTIF(J48:L48,"X")<>1,"FALTA/DUPLA: DRENAGEM SUPERFICIAL","OK"))) -> OK
A49: 181ETO0070 | B49: C | C49: 40 | D49: 41 | E49: =D49-C49 -> 1 | H49: X | K49: X | N49: =IF(COUNTA(F49:L49)=0,"— não preenchido",IF(COUNTIF(F49:I49,"X")<>1,"FALTA/DUPLA: CONDIÇÃO DA PLATAFORMA",IF(COUNTIF(J49:L49,"X")<>1,"FALTA/DUPLA: DRENAGEM SUPERFICIAL","OK"))) -> OK
A50: 181ETO0070 | B50: C | C50: 41 | D50: 42 | E50: =D50-C50 -> 1 | H50: X | K50: X | N50: =IF(COUNTA(F50:L50)=0,"— não preenchido",IF(COUNTIF(F50:I50,"X")<>1,"FALTA/DUPLA: CONDIÇÃO DA PLATAFORMA",IF(COUNTIF(J50:L50,"X")<>1,"FALTA/DUPLA: DRENAGEM SUPERFICIAL","OK"))) -> OK
... A74: 181ETO0070 | B74: C | C74: 65 | D74: 65.901646 | E74: =D74-C74 -> 0.90164623 | H74: X | K74: X | N74: =IF(COUNTA(F74:L74)=0,"— não preenchido",IF(COUNTIF(F74:I74,"X")<>1,"FALTA/DUPLA: CONDIÇÃO DA PLATAFORMA",IF(COUNTIF(J74:L74,"X")<>1,"FALTA/DUPLA: DRENAGEM SUPERFICIAL","OK"))) -> OK
A76: ____________________________________________ | G76: ____________________________________________
A77: TÉCNICO RESPONSÁVEL PELA INSPEÇÃO | G77: VISTO DA SUPERVISÃO
A79: RESUMO DO TRECHO — KM LANÇADO POR ITEM
A80: KM LANÇADO | F80: =SUMIF(F$9:F$74,"X",$E$9:$E$74) -> 0 | G80: =SUMIF(G$9:G$74,"X",$E$9:$E$74) -> 30 | H80: =SUMIF(H$9:H$74,"X",$E$9:$E$74) -> 35.901646 | I80: =SUMIF(I$9:I$74,"X",$E$9:$E$74) -> 0 | J80: =SUMIF(J$9:J$74,"X",$E$9:$E$74) -> 30 | K80: =SUMIF(K$9:K$74,"X",$E$9:$E$74) -> 35.901646 | L80: =SUMIF(L$9:L$74,"X",$E$9:$E$74) -> 0
A81: % DA EXTENSÃO | F81: =IF($I83=0,0,F80/$I83) -> 0 | G81: =IF($I83=0,0,G80/$I83) -> 0.45522383 | H81: =IF($I83=0,0,H80/$I83) -> 0.54477617 | I81: =IF($I83=0,0,I80/$I83) -> 0 | J81: =IF($I83=0,0,J80/$I83) -> 0.45522383 | K81: =IF($I83=0,0,K80/$I83) -> 0.54477617 | L81: =IF($I83=0,0,L80/$I83) -> 0
A82: CONFERÊNCIA POR GRUPO | F82: =IF(SUM(F80:I80)=0,"— não preenchido",IF(ROUND(SUM(F80:I80)-$I83,3)=0,"OK — "&ROUND(SUM(F80:I80),3)&" km","ERRO — dif. de "&ROUND(SUM(F80:I80)-$I83,3)&" km")) -> OK — 65,902 km | J82: =IF(SUM(J80:L80)=0,"— não preenchido",IF(ROUND(SUM(J80:L80)-$I83,3)=0,"OK — "&ROUND(SUM(J80:L80),3)&" km","ERRO — dif. de "&ROUND(SUM(J80:L80)-$I83,3)&" km")) -> OK — 65,902 km
A83: EXTENSÃO TOTAL DO TRECHO | I83: =SUM(E9:E74) -> 65.901646 | M83: =COUNTIF(N9:N74,"OK")&" de "&COUNT($E$9:$E$74)&" linhas conferidas" -> 66 de 66 linhas conferidas
...

Sheet 208
A1: PROGRAMA DE MANUTENÇÃO RODOVIÁRIA — FICHA DE INSPEÇÃO — RODOVIAS NÃO PAVIMENTADAS | P1: Valores dos gráficos — troca 0 por N/D para a fatia não aparecer. Não editar.
A2: REGIÃO: 11 — GURUPI | D2: MÊS / ANO: | F2: 46235 | G2: DATA: | J2: TÉCNICO: | K2: ENG. THIAGO BORGES TORQUATO | P2: =IF(F56=0,NA(),F56) -> 41.632983 | Q2: =IF(G56=0,NA(),G56) -> #N/A | R2: =IF(H56=0,NA(),H56) -> #N/A | S2: =IF(I56=0,NA(),I56) -> #N/A | T2: =IF(J56=0,NA(),J56) -> #N/A | U2: =IF(K56=0,NA(),K56) -> #N/A | V2: =IF(L56=0,NA(),L56) -> 41.632983
A3: TRECHO 208 — RODOVIA TO-181 - TRECHO ENTR. TO-481 (CAPAO DO COCO) - FAZENDA COBRAPE | K3: EXTENSÃO: 41,633 km · 1 S.R.E.
A4: COMO PREENCHER: uma X em UMA coluna de cada grupo, por linha. Se houver mais de um defeito no mesmo km, marque o PREDOMINANTE e escreva o resto em OBSERVAÇÕES. A quilometragem é contada de 0 até o fim de CADA S.R.E. (não é o marco da rodovia).
A6: S.R.E. | B6: SENT. | C6: INÍCIO (KM) | D6: FIM (KM) | E6: EXT. (KM) | F6: CONDIÇÃO DA PLATAFORMA | J6: DRENAGEM SUPERFICIAL | M6: OBSERVAÇÕES | N6: CONFERÊNCIA (só na tela)
F7: BOM | G7: REG. (ATÉ 10 IRR./KM) | H7: RUIM (+ 10 IRR./KM) | I7: PÉSSIMA (ATOLEIRO/PTO. CRÍTICO) | J7: LIMPA | K7: OBSTRUÍDA | L7: AUSENTE
A8: S.R.E. 181ETO0090 | ENTR. TO-481 (CAPAO DO COCO) - INICIO PAVIMENTAÇÃO (FAZ. COBRAPE) | LEN · Estadual · 41.633 km · início: -11.186191, -49.873813
A9: 181ETO0090 | B9: C | C9: 0 | D9: 1 | E9: =D9-C9 -> 1 | F9: X | L9: X | N9: =IF(COUNTA(F9:L9)=0,"— não preenchido",IF(COUNTIF(F9:I9,"X")<>1,"FALTA/DUPLA: CONDIÇÃO DA PLATAFORMA",IF(COUNTIF(J9:L9,"X")<>1,"FALTA/DUPLA: DRENAGEM SUPERFICIAL","OK"))) -> OK
A10: 181ETO0090 | B10: C | C10: 1 | D10: 2 | E10: =D10-C10 -> 1 | F10: X | L10: X | N10: =IF(COUNTA(F10:L10)=0,"— não preenchido",IF(COUNTIF(F10:I10,"X")<>1,"FALTA/DUPLA: CONDIÇÃO DA PLATAFORMA",IF(COUNTIF(J10:L10,"X")<>1,"FALTA/DUPLA: DRENAGEM SUPERFICIAL","OK"))) -> OK
A11: 181ETO0090 | B11: C | C11: 2 | D11: 3 | E11: =D11-C11 -> 1 | F11: X | L11: X | N11: =IF(COUNTA(F11:L11)=0,"— não preenchido",IF(COUNTIF(F11:I11,"X")<>1,"FALTA/DUPLA: CONDIÇÃO DA PLATAFORMA",IF(COUNTIF(J11:L11,"X")<>1,"FALTA/DUPLA: DRENAGEM SUPERFICIAL","OK"))) -> OK
A12: 181ETO0090 | B12: C | C12: 3 | D12: 4 | E12: =D12-C12 -> 1 | F12: X | L12: X | N12: =IF(COUNTA(F12:L12)=0,"— não preenchido",IF(COUNTIF(F12:I12,"X")<>1,"FALTA/DUPLA: CONDIÇÃO DA PLATAFORMA",IF(COUNTIF(J12:L12,"X")<>1,"FALTA/DUPLA: DRENAGEM SUPERFICIAL","OK"))) -> OK
A13: 181ETO0090 | B13: C | C13: 4 | D13: 5 | E13: =D13-C13 -> 1 | F13: X | L13: X | N13: =IF(COUNTA(F13:L13)=0,"— não preenchido",IF(COUNTIF(F13:I13,"X")<>1,"FALTA/DUPLA: CONDIÇÃO DA PLATAFORMA",IF(COUNTIF(J13:L13,"X")<>1,"FALTA/DUPLA: DRENAGEM SUPERFICIAL","OK"))) -> OK
A14: 181ETO0090 | B14: C | C14: 5 | D14: 6 | E14: =D14-C14 -> 1 | F14: X | L14: X | N14: =IF(COUNTA(F14:L14)=0,"— não preenchido",IF(COUNTIF(F14:I14,"X")<>1,"FALTA/DUPLA: CONDIÇÃO DA PLATAFORMA",IF(COUNTIF(J14:L14,"X")<>1,"FALTA/DUPLA: DRENAGEM SUPERFICIAL","OK"))) -> OK
A15: 181ETO0090 | B15: C | C15: 6 | D15: 7 | E15: =D15-C15 -> 1 | F15: X | L15: X | N15: =IF(COUNTA(F15:L15)=0,"— não preenchido",IF(COUNTIF(F15:I15,"X")<>1,"FALTA/DUPLA: CONDIÇÃO DA PLATAFORMA",IF(COUNTIF(J15:L15,"X")<>1,"FALTA/DUPLA: DRENAGEM SUPERFICIAL","OK"))) -> OK
A16: 181ETO0090 | B16: C | C16: 7 | D16: 8 | E16: =D16-C16 -> 1 | F16: X | L16: X | N16: =IF(COUNTA(F16:L16)=0,"— não preenchido",IF(COUNTIF(F16:I16,"X")<>1,"FALTA/DUPLA: CONDIÇÃO DA PLATAFORMA",IF(COUNTIF(J16:L16,"X")<>1,"FALTA/DUPLA: DRENAGEM SUPERFICIAL","OK"))) -> OK
A17: 181ETO0090 | B17: C | C17: 8 | D17: 9 | E17: =D17-C17 -> 1 | F17: X | L17: X | N17: =IF(COUNTA(F17:L17)=0,"— não preenchido",IF(COUNTIF(F17:I17,"X")<>1,"FALTA/DUPLA: CONDIÇÃO DA PLATAFORMA",IF(COUNTIF(J17:L17,"X")<>1,"FALTA/DUPLA: DRENAGEM SUPERFICIAL","OK"))) -> OK
A18: 181ETO0090 | B18: C | C18: 9 | D18: 10 | E18: =D18-C18 -> 1 | F18: X | L18: X | N18: =IF(COUNTA(F18:L18)=0,"— não preenchido",IF(COUNTIF(F18:I18,"X")<>1,"FALTA/DUPLA: CONDIÇÃO DA PLATAFORMA",IF(COUNTIF(J18:L18,"X")<>1,"FALTA/DUPLA: DRENAGEM SUPERFICIAL","OK"))) -> OK
A19: 181ETO0090 | B19: C | C19: 10 | D19: 11 | E19: =D19-C19 -> 1 | F19: X | L19: X | N19: =IF(COUNTA(F19:L19)=0,"— não preenchido",IF(COUNTIF(F19:I19,"X")<>1,"FALTA/DUPLA: CONDIÇÃO DA PLATAFORMA",IF(COUNTIF(J19:L19,"X")<>1,"FALTA/DUPLA: DRENAGEM SUPERFICIAL","OK"))) -> OK
A20: 181ETO0090 | B20: C | C20: 11 | D20: 12 | E20: =D20-C20 -> 1 | F20: X | L20: X | N20: =IF(COUNTA(F20:L20)=0,"— não preenchido",IF(COUNTIF(F20:I20,"X")<>1,"FALTA/DUPLA: CONDIÇÃO DA PLATAFORMA",IF(COUNTIF(J20:L20,"X")<>1,"FALTA/DUPLA: DRENAGEM SUPERFICIAL","OK"))) -> OK
... A50: 181ETO0090 | B50: C | C50: 41 | D50: 41.632983 | E50: =D50-C50 -> 0.63298326 | F50: X | L50: X | N50: =IF(COUNTA(F50:L50)=0,"— não preenchido",IF(COUNTIF(F50:I50,"X")<>1,"FALTA/DUPLA: CONDIÇÃO DA PLATAFORMA",IF(COUNTIF(J50:L50,"X")<>1,"FALTA/DUPLA: DRENAGEM SUPERFICIAL","OK"))) -> OK
A52: ____________________________________________ | G52: ____________________________________________
A53: TÉCNICO RESPONSÁVEL PELA INSPEÇÃO | G53: VISTO DA SUPERVISÃO
A55: RESUMO DO TRECHO — KM LANÇADO POR ITEM
A56: KM LANÇADO | F56: =SUMIF(F$9:F$50,"X",$E$9:$E$50) -> 41.632983 | G56: =SUMIF(G$9:G$50,"X",$E$9:$E$50) -> 0 | H56: =SUMIF(H$9:H$50,"X",$E$9:$E$50) -> 0 | I56: =SUMIF(I$9:I$50,"X",$E$9:$E$50) -> 0 | J56: =SUMIF(J$9:J$50,"X",$E$9:$E$50) -> 0 | K56: =SUMIF(K$9:K$50,"X",$E$9:$E$50) -> 0 | L56: =SUMIF(L$9:L$50,"X",$E$9:$E$50) -> 41.632983
A57: % DA EXTENSÃO | F57: =IF($I59=0,0,F56/$I59) -> 1 | G57: =IF($I59=0,0,G56/$I59) -> 0 | H57: =IF($I59=0,0,H56/$I59) -> 0 | I57: =IF($I59=0,0,I56/$I59) -> 0 | J57: =IF($I59=0,0,J56/$I59) -> 0 | K57: =IF($I59=0,0,K56/$I59) -> 0 | L57: =IF($I59=0,0,L56/$I59) -> 1
A58: CONFERÊNCIA POR GRUPO | F58: =IF(SUM(F56:I56)=0,"— não preenchido",IF(ROUND(SUM(F56:I56)-$I59,3)=0,"OK — "&ROUND(SUM(F56:I56),3)&" km","ERRO — dif. de "&ROUND(SUM(F56:I56)-$I59,3)&" km")) -> OK — 41,633 km | J58: =IF(SUM(J56:L56)=0,"— não preenchido",IF(ROUND(SUM(J56:L56)-$I59,3)=0,"OK — "&ROUND(SUM(J56:L56),3)&" km","ERRO — dif. de "&ROUND(SUM(J56:L56)-$I59,3)&" km")) -> OK — 41,633 km
A59: EXTENSÃO TOTAL DO TRECHO | I59: =SUM(E9:E50) -> 41.632983 | M59: =COUNTIF(N9:N50,"OK")&" de "&COUNT($E$9:$E$50)&" linhas conferidas" -> 42 de 42 linhas conferidas
A61: LEGENDA
A62: REGULAR | E62: Até 10 irregularidades por km
A63: RUIM | E63: Mais de 10 irregularidades por km
A64: PÉSSIMA | E64: Atoleiro ou ponto crítico
A65: SIT. | E65: LEN = leito natural · EOP = em obras de pavimentação
A66: FAIXA AZUL | E66: Cabeçalho de cada S.R.E.: descrição, situação, jurisdição, extensão e coordenada de início.
A67: INÍCIO / FIM (KM) | E67: Contados de 0 até o fim de CADA S.R.E. Não é o marco quilométrico da rodovia.
A68: SENT. | E68: C = crescente · D = decrescente
A69: FAIXA CINZA | E69: Segmento fora do escopo do contrato: você passa por ele, mas não preenche.
A70: CÉLULA VERMELHA | E70: Mais de uma X no mesmo grupo. Apague uma delas.
A71: CONFERÊNCIA | E71: Só na tela, não sai impresso. Fica OK com uma X em cada grupo.

Sheet 211
A1: PROGRAMA DE MANUTENÇÃO RODOVIÁRIA — FICHA DE INSPEÇÃO — RODOVIAS NÃO PAVIMENTADAS | P1: Valores dos gráficos — troca 0 por N/D para a fatia não aparecer. Não editar.
A2: REGIÃO: 11 — GURUPI | D2: MÊS / ANO: | F2: 46235 | G2: DATA: | J2: TÉCNICO: | K2: ENG. THIAGO BORGES TORQUATO | P2: =IF(F56=0,NA(),F56) -> #N/A | Q2: =IF(G56=0,NA(),G56) -> 30 | R2: =IF(H56=0,NA(),H56) -> 11.818855 | S2: =IF(I56=0,NA(),I56) -> #N/A | T2: =IF(J56=0,NA(),J56) -> #N/A | U2: =IF(K56=0,NA(),K56) -> 41.818855 | V2: =IF(L56=0,NA(),L56) -> #N/A
A3: TRECHO 211 — RODOVIA TO-181 - TRECHO FUNDAÇÃO BRADESCO - ENTR. TO-070 | K3: EXTENSÃO: 41,819 km · 1 S.R.E.
A4: COMO PREENCHER: uma X em UMA coluna de cada grupo, por linha. Se houver mais de um defeito no mesmo km, marque o PREDOMINANTE e escreva o resto em OBSERVAÇÕES. A quilometragem é contada de 0 até o fim de CADA S.R.E. (não é o marco da rodovia).
A6: S.R.E. | B6: SENT. | C6: INÍCIO (KM) | D6: FIM (KM) | E6: EXT. (KM) | F6: CONDIÇÃO DA PLATAFORMA | J6: DRENAGEM SUPERFICIAL | M6: OBSERVAÇÕES | N6: CONFERÊNCIA (só na tela)
F7: BOM | G7: REG. (ATÉ 10 IRR./KM) | H7: RUIM (+ 10 IRR./KM) | I7: PÉSSIMA (ATOLEIRO/PTO. CRÍTICO) | J7: LIMPA | K7: OBSTRUÍDA | L7: AUSENTE
A8: S.R.E. 181ETO0150 | FIM PAVIMENTAÇÃO - ENTR. TO-070 | LEN · Estadual · 41.819 km · início: -11.979505, -49.896445
A9: 181ETO0150 | B9: C | C9: 0 | D9: 1 | E9: =D9-C9 -> 1 | G9: X | K9: X | N9: =IF(COUNTA(F9:L9)=0,"— não preenchido",IF(COUNTIF(F9:I9,"X")<>1,"FALTA/DUPLA: CONDIÇÃO DA PLATAFORMA",IF(COUNTIF(J9:L9,"X")<>1,"FALTA/DUPLA: DRENAGEM SUPERFICIAL","OK"))) -> OK
A10: 181ETO0150 | B10: C | C10: 1 | D10: 2 | E10: =D10-C10 -> 1 | G10: X | K10: X | N10: =IF(COUNTA(F10:L10)=0,"— não preenchido",IF(COUNTIF(F10:I10,"X")<>1,"FALTA/DUPLA: CONDIÇÃO DA PLATAFORMA",IF(COUNTIF(J10:L10,"X")<>1,"FALTA/DUPLA: DRENAGEM SUPERFICIAL","OK"))) -> OK
A11: 181ETO0150 | B11: C | C11: 2 | D11: 3 | E11: =D11-C11 -> 1 | G11: X | K11: X | N11: =IF(COUNTA(F11:L11)=0,"— não preenchido",IF(COUNTIF(F11:I11,"X")<>1,"FALTA/DUPLA: CONDIÇÃO DA PLATAFORMA",IF(COUNTIF(J11:L11,"X")<>1,"FALTA/DUPLA: DRENAGEM SUPERFICIAL","OK"))) -> OK
A12: 181ETO0150 | B12: C | C12: 3 | D12: 4 | E12: =D12-C12 -> 1 | G12: X | K12: X | N12: =IF(COUNTA(F12:L12)=0,"— não preenchido",IF(COUNTIF(F12:I12,"X")<>1,"FALTA/DUPLA: CONDIÇÃO DA PLATAFORMA",IF(COUNTIF(J12:L12,"X")<>1,"FALTA/DUPLA: DRENAGEM SUPERFICIAL","OK"))) -> OK
A13: 181ETO0150 | B13: C | C13: 4 | D13: 5 | E13: =D13-C13 -> 1 | G13: X | K13: X | N13: =IF(COUNTA(F13:L13)=0,"— não preenchido",IF(COUNTIF(F13:I13,"X")<>1,"FALTA/DUPLA: CONDIÇÃO DA PLATAFORMA",IF(COUNTIF(J13:L13,"X")<>1,"FALTA/DUPLA: DRENAGEM SUPERFICIAL","OK"))) -> OK
A14: 181ETO0150 | B14: C | C14: 5 | D14: 6 | E14: =D14-C14 -> 1 | G14: X | K14: X | N14: =IF(COUNTA(F14:L14)=0,"— não preenchido",IF(COUNTIF(F14:I14,"X")<>1,"FALTA/DUPLA: CONDIÇÃO DA PLATAFORMA",IF(COUNTIF(J14:L14,"X")<>1,"FALTA/DUPLA: DRENAGEM SUPERFICIAL","OK"))) -> OK
A15: 181ETO0150 | B15: C | C15: 6 | D15: 7 | E15: =D15-C15 -> 1 | G15: X | K15: X | N15: =IF(COUNTA(F15:L15)=0,"— não preenchido",IF(COUNTIF(F15:I15,"X")<>1,"FALTA/DUPLA: CONDIÇÃO DA PLATAFORMA",IF(COUNTIF(J15:L15,"X")<>1,"FALTA/DUPLA: DRENAGEM SUPERFICIAL","OK"))) -> OK
A16: 181ETO0150 | B16: C | C16: 7 | D16: 8 | E16: =D16-C16 -> 1 | G16: X | K16: X | N16: =IF(COUNTA(F16:L16)=0,"— não preenchido",IF(COUNTIF(F16:I16,"X")<>1,"FALTA/DUPLA: CONDIÇÃO DA PLATAFORMA",IF(COUNTIF(J16:L16,"X")<>1,"FALTA/DUPLA: DRENAGEM SUPERFICIAL","OK"))) -> OK
A17: 181ETO0150 | B17: C | C17: 8 | D17: 9 | E17: =D17-C17 -> 1 | G17: X | K17: X | N17: =IF(COUNTA(F17:L17)=0,"— não preenchido",IF(COUNTIF(F17:I17,"X")<>1,"FALTA/DUPLA: CONDIÇÃO DA PLATAFORMA",IF(COUNTIF(J17:L17,"X")<>1,"FALTA/DUPLA: DRENAGEM SUPERFICIAL","OK"))) -> OK
A18: 181ETO0150 | B18: C | C18: 9 | D18: 10 | E18: =D18-C18 -> 1 | G18: X | K18: X | N18: =IF(COUNTA(F18:L18)=0,"— não preenchido",IF(COUNTIF(F18:I18,"X")<>1,"FALTA/DUPLA: CONDIÇÃO DA PLATAFORMA",IF(COUNTIF(J18:L18,"X")<>1,"FALTA/DUPLA: DRENAGEM SUPERFICIAL","OK"))) -> OK
A19: 181ETO0150 | B19: C | C19: 10 | D19: 11 | E19: =D19-C19 -> 1 | G19: X | K19: X | N19: =IF(COUNTA(F19:L19)=0,"— não preenchido",IF(COUNTIF(F19:I19,"X")<>1,"FALTA/DUPLA: CONDIÇÃO DA PLATAFORMA",IF(COUNTIF(J19:L19,"X")<>1,"FALTA/DUPLA: DRENAGEM SUPERFICIAL","OK"))) -> OK
A20: 181ETO0150 | B20: C | C20: 11 | D20: 12 | E20: =D20-C20 -> 1 | G20: X | K20: X | N20: =IF(COUNTA(F20:L20)=0,"— não preenchido",IF(COUNTIF(F20:I20,"X")<>1,"FALTA/DUPLA: CONDIÇÃO DA PLATAFORMA",IF(COUNTIF(J20:L20,"X")<>1,"FALTA/DUPLA: DRENAGEM SUPERFICIAL","OK"))) -> OK
... A38: 181ETO0150 | B38: C | C38: 29 | D38: 30 | E38: =D38-C38 -> 1 | G38: X | K38: X | N38: =IF(COUNTA(F38:L38)=0,"— não preenchido",IF(COUNTIF(F38:I38,"X")<>1,"FALTA/DUPLA: CONDIÇÃO DA PLATAFORMA",IF(COUNTIF(J38:L38,"X")<>1,"FALTA/DUPLA: DRENAGEM SUPERFICIAL","OK"))) -> OK
A39: 181ETO0150 | B39: C | C39: 30 | D39: 31 | E39: =D39-C39 -> 1 | H39: X | K39: X | N39: =IF(COUNTA(F39:L39)=0,"— não preenchido",IF(COUNTIF(F39:I39,"X")<>1,"FALTA/DUPLA: CONDIÇÃO DA PLATAFORMA",IF(COUNTIF(J39:L39,"X")<>1,"FALTA/DUPLA: DRENAGEM SUPERFICIAL","OK"))) -> OK
A40: 181ETO0150 | B40: C | C40: 31 | D40: 32 | E40: =D40-C40 -> 1 | H40: X | K40: X | N40: =IF(COUNTA(F40:L40)=0,"— não preenchido",IF(COUNTIF(F40:I40,"X")<>1,"FALTA/DUPLA: CONDIÇÃO DA PLATAFORMA",IF(COUNTIF(J40:L40,"X")<>1,"FALTA/DUPLA: DRENAGEM SUPERFICIAL","OK"))) -> OK
A41: 181ETO0150 | B41: C | C41: 32 | D41: 33 | E41: =D41-C41 -> 1 | H41: X | K41: X | N41: =IF(COUNTA(F41:L41)=0,"— não preenchido",IF(COUNTIF(F41:I41,"X")<>1,"FALTA/DUPLA: CONDIÇÃO DA PLATAFORMA",IF(COUNTIF(J41:L41,"X")<>1,"FALTA/DUPLA: DRENAGEM SUPERFICIAL","OK"))) -> OK
A42: 181ETO0150 | B42: C | C42: 33 | D42: 34 | E42: =D42-C42 -> 1 | H42: X | K42: X | N42: =IF(COUNTA(F42:L42)=0,"— não preenchido",IF(COUNTIF(F42:I42,"X")<>1,"FALTA/DUPLA: CONDIÇÃO DA PLATAFORMA",IF(COUNTIF(J42:L42,"X")<>1,"FALTA/DUPLA: DRENAGEM SUPERFICIAL","OK"))) -> OK
A43: 181ETO0150 | B43: C | C43: 34 | D43: 35 | E43: =D43-C43 -> 1 | H43: X | K43: X | N43: =IF(COUNTA(F43:L43)=0,"— não preenchido",IF(COUNTIF(F43:I43,"X")<>1,"FALTA/DUPLA: CONDIÇÃO DA PLATAFORMA",IF(COUNTIF(J43:L43,"X")<>1,"FALTA/DUPLA: DRENAGEM SUPERFICIAL","OK"))) -> OK
A44: 181ETO0150 | B44: C | C44: 35 | D44: 36 | E44: =D44-C44 -> 1 | H44: X | K44: X | N44: =IF(COUNTA(F44:L44)=0,"— não preenchido",IF(COUNTIF(F44:I44,"X")<>1,"FALTA/DUPLA: CONDIÇÃO DA PLATAFORMA",IF(COUNTIF(J44:L44,"X")<>1,"FALTA/DUPLA: DRENAGEM SUPERFICIAL","OK"))) -> OK
A45: 181ETO0150 | B45: C | C45: 36 | D45: 37 | E45: =D45-C45 -> 1 | H45: X | K45: X | N45: =IF(COUNTA(F45:L45)=0,"— não preenchido",IF(COUNTIF(F45:I45,"X")<>1,"FALTA/DUPLA: CONDIÇÃO DA PLATAFORMA",IF(COUNTIF(J45:L45,"X")<>1,"FALTA/DUPLA: DRENAGEM SUPERFICIAL","OK"))) -> OK
A46: 181ETO0150 | B46: C | C46: 37 | D46: 38 | E46: =D46-C46 -> 1 | H46: X | K46: X | N46: =IF(COUNTA(F46:L46)=0,"— não preenchido",IF(COUNTIF(F46:I46,"X")<>1,"FALTA/DUPLA: CONDIÇÃO DA PLATAFORMA",IF(COUNTIF(J46:L46,"X")<>1,"FALTA/DUPLA: DRENAGEM SUPERFICIAL","OK"))) -> OK
A47: 181ETO0150 | B47: C | C47: 38 | D47: 39 | E47: =D47-C47 -> 1 | H47: X | K47: X | N47: =IF(COUNTA(F47:L47)=0,"— não preenchido",IF(COUNTIF(F47:I47,"X")<>1,"FALTA/DUPLA: CONDIÇÃO DA PLATAFORMA",IF(COUNTIF(J47:L47,"X")<>1,"FALTA/DUPLA: DRENAGEM SUPERFICIAL","OK"))) -> OK
A48: 181ETO0150 | B48: C | C48: 39 | D48: 40 | E48: =D48-C48 -> 1 | H48: X | K48: X | N48: =IF(COUNTA(F48:L48)=0,"— não preenchido",IF(COUNTIF(F48:I48,"X")<>1,"FALTA/DUPLA: CONDIÇÃO DA PLATAFORMA",IF(COUNTIF(J48:L48,"X")<>1,"FALTA/DUPLA: DRENAGEM SUPERFICIAL","OK"))) -> OK
A49: 181ETO0150 | B49: C | C49: 40 | D49: 41 | E49: =D49-C49 -> 1 | H49: X | K49: X | N49: =IF(COUNTA(F49:L49)=0,"— não preenchido",IF(COUNTIF(F49:I49,"X")<>1,"FALTA/DUPLA: CONDIÇÃO DA PLATAFORMA",IF(COUNTIF(J49:L49,"X")<>1,"FALTA/DUPLA: DRENAGEM SUPERFICIAL","OK"))) -> OK
A50: 181ETO0150 | B50: C | C50: 41 | D50: 41.818855 | E50: =D50-C50 -> 0.8188554 | H50: X | K50: X | N50: =IF(COUNTA(F50:L50)=0,"— não preenchido",IF(COUNTIF(F50:I50,"X")<>1,"FALTA/DUPLA: CONDIÇÃO DA PLATAFORMA",IF(COUNTIF(J50:L50,"X")<>1,"FALTA/DUPLA: DRENAGEM SUPERFICIAL","OK"))) -> OK
A52: ____________________________________________ | G52: ____________________________________________
A53: TÉCNICO RESPONSÁVEL PELA INSPEÇÃO | G53: VISTO DA SUPERVISÃO
A55: RESUMO DO TRECHO — KM LANÇADO POR ITEM
A56: KM LANÇADO | F56: =SUMIF(F$9:F$50,"X",$E$9:$E$50) -> 0 | G56: =SUMIF(G$9:G$50,"X",$E$9:$E$50) -> 30 | H56: =SUMIF(H$9:H$50,"X",$E$9:$E$50) -> 11.818855 | I56: =SUMIF(I$9:I$50,"X",$E$9:$E$50) -> 0 | J56: =SUMIF(J$9:J$50,"X",$E$9:$E$50) -> 0 | K56: =SUMIF(K$9:K$50,"X",$E$9:$E$50) -> 41.818855 | L56: =SUMIF(L$9:L$50,"X",$E$9:$E$50) -> 0
A57: % DA EXTENSÃO | F57: =IF($I59=0,0,F56/$I59) -> 0 | G57: =IF($I59=0,0,G56/$I59) -> 0.71737975 | H57: =IF($I59=0,0,H56/$I59) -> 0.28262025 | I57: =IF($I59=0,0,I56/$I59) -> 0 | J57: =IF($I59=0,0,J56/$I59) -> 0 | K57: =IF($I59=0,0,K56/$I59) -> 1 | L57: =IF($I59=0,0,L56/$I59) -> 0
A58: CONFERÊNCIA POR GRUPO | F58: =IF(SUM(F56:I56)=0,"— não preenchido",IF(ROUND(SUM(F56:I56)-$I59,3)=0,"OK — "&ROUND(SUM(F56:I56),3)&" km","ERRO — dif. de "&ROUND(SUM(F56:I56)-$I59,3)&" km")) -> OK — 41,819 km | J58: =IF(SUM(J56:L56)=0,"— não preenchido",IF(ROUND(SUM(J56:L56)-$I59,3)=0,"OK — "&ROUND(SUM(J56:L56),3)&" km","ERRO — dif. de "&ROUND(SUM(J56:L56)-$I59,3)&" km")) -> OK — 41,819 km
A59: EXTENSÃO TOTAL DO TRECHO | I59: =SUM(E9:E50) -> 41.818855 | M59: =COUNTIF(N9:N50,"OK")&" de "&COUNT($E$9:$E$50)&" linhas conferidas" -> 42 de 42 linhas conferidas
A61: LEGENDA
...

Sheet 213
A1: PROGRAMA DE MANUTENÇÃO RODOVIÁRIA — FICHA DE INSPEÇÃO — RODOVIAS NÃO PAVIMENTADAS | P1: Valores dos gráficos — troca 0 por N/D para a fatia não aparecer. Não editar.
A2: REGIÃO: 11 — GURUPI | D2: MÊS / ANO: | F2: 46235 | G2: DATA: | J2: TÉCNICO: | K2: ENG. THIAGO BORGES TORQUATO | P2: =IF(F55=0,NA(),F55) -> #N/A | Q2: =IF(G55=0,NA(),G55) -> #N/A | R2: =IF(H55=0,NA(),H55) -> 27.379495 | S2: =IF(I55=0,NA(),I55) -> 13 | T2: =IF(J55=0,NA(),J55) -> #N/A | U2: =IF(K55=0,NA(),K55) -> 40.379495 | V2: =IF(L55=0,NA(),L55) -> #N/A
A3: TRECHO 213 — RODOVIA TO-181 - TRECHO ARAGUAÇU - DIVISA TO-GO | K3: EXTENSÃO: 40,379 km · 1 S.R.E.
A4: COMO PREENCHER: uma X em UMA coluna de cada grupo, por linha. Se houver mais de um defeito no mesmo km, marque o PREDOMINANTE e escreva o resto em OBSERVAÇÕES. A quilometragem é contada de 0 até o fim de CADA S.R.E. (não é o marco da rodovia).
A6: S.R.E. | B6: SENT. | C6: INÍCIO (KM) | D6: FIM (KM) | E6: EXT. (KM) | F6: CONDIÇÃO DA PLATAFORMA | J6: DRENAGEM SUPERFICIAL | M6: OBSERVAÇÕES | N6: CONFERÊNCIA (só na tela)
F7: BOM | G7: REG. (ATÉ 10 IRR./KM) | H7: RUIM (+ 10 IRR./KM) | I7: PÉSSIMA (ATOLEIRO/PTO. CRÍTICO) | J7: LIMPA | K7: OBSTRUÍDA | L7: AUSENTE
A8: S.R.E. 181ETO0230 | ARAGUAÇU *TRECHO URBANO* - DIV TO-GO | LEN · Estadual · 40.379 km · início: -12.946693, -49.8179
A9: 181ETO0230 | B9: C | C9: 0 | D9: 1 | E9: =D9-C9 -> 1 | I9: X | K9: X | N9: =IF(COUNTA(F9:L9)=0,"— não preenchido",IF(COUNTIF(F9:I9,"X")<>1,"FALTA/DUPLA: CONDIÇÃO DA PLATAFORMA",IF(COUNTIF(J9:L9,"X")<>1,"FALTA/DUPLA: DRENAGEM SUPERFICIAL","OK"))) -> OK
A10: 181ETO0230 | B10: C | C10: 1 | D10: 2 | E10: =D10-C10 -> 1 | I10: X | K10: X | N10: =IF(COUNTA(F10:L10)=0,"— não preenchido",IF(COUNTIF(F10:I10,"X")<>1,"FALTA/DUPLA: CONDIÇÃO DA PLATAFORMA",IF(COUNTIF(J10:L10,"X")<>1,"FALTA/DUPLA: DRENAGEM SUPERFICIAL","OK"))) -> OK
A11: 181ETO0230 | B11: C | C11: 2 | D11: 3 | E11: =D11-C11 -> 1 | I11: X | K11: X | N11: =IF(COUNTA(F11:L11)=0,"— não preenchido",IF(COUNTIF(F11:I11,"X")<>1,"FALTA/DUPLA: CONDIÇÃO DA PLATAFORMA",IF(COUNTIF(J11:L11,"X")<>1,"FALTA/DUPLA: DRENAGEM SUPERFICIAL","OK"))) -> OK
A12: 181ETO0230 | B12: C | C12: 3 | D12: 4 | E12: =D12-C12 -> 1 | I12: X | K12: X | N12: =IF(COUNTA(F12:L12)=0,"— não preenchido",IF(COUNTIF(F12:I12,"X")<>1,"FALTA/DUPLA: CONDIÇÃO DA PLATAFORMA",IF(COUNTIF(J12:L12,"X")<>1,"FALTA/DUPLA: DRENAGEM SUPERFICIAL","OK"))) -> OK
A13: 181ETO0230 | B13: C | C13: 4 | D13: 5 | E13: =D13-C13 -> 1 | I13: X | K13: X | N13: =IF(COUNTA(F13:L13)=0,"— não preenchido",IF(COUNTIF(F13:I13,"X")<>1,"FALTA/DUPLA: CONDIÇÃO DA PLATAFORMA",IF(COUNTIF(J13:L13,"X")<>1,"FALTA/DUPLA: DRENAGEM SUPERFICIAL","OK"))) -> OK
A14: 181ETO0230 | B14: C | C14: 5 | D14: 6 | E14: =D14-C14 -> 1 | I14: X | K14: X | N14: =IF(COUNTA(F14:L14)=0,"— não preenchido",IF(COUNTIF(F14:I14,"X")<>1,"FALTA/DUPLA: CONDIÇÃO DA PLATAFORMA",IF(COUNTIF(J14:L14,"X")<>1,"FALTA/DUPLA: DRENAGEM SUPERFICIAL","OK"))) -> OK
A15: 181ETO0230 | B15: C | C15: 6 | D15: 7 | E15: =D15-C15 -> 1 | I15: X | K15: X | N15: =IF(COUNTA(F15:L15)=0,"— não preenchido",IF(COUNTIF(F15:I15,"X")<>1,"FALTA/DUPLA: CONDIÇÃO DA PLATAFORMA",IF(COUNTIF(J15:L15,"X")<>1,"FALTA/DUPLA: DRENAGEM SUPERFICIAL","OK"))) -> OK
A16: 181ETO0230 | B16: C | C16: 7 | D16: 8 | E16: =D16-C16 -> 1 | I16: X | K16: X | N16: =IF(COUNTA(F16:L16)=0,"— não preenchido",IF(COUNTIF(F16:I16,"X")<>1,"FALTA/DUPLA: CONDIÇÃO DA PLATAFORMA",IF(COUNTIF(J16:L16,"X")<>1,"FALTA/DUPLA: DRENAGEM SUPERFICIAL","OK"))) -> OK
A17: 181ETO0230 | B17: C | C17: 8 | D17: 9 | E17: =D17-C17 -> 1 | I17: X | K17: X | N17: =IF(COUNTA(F17:L17)=0,"— não preenchido",IF(COUNTIF(F17:I17,"X")<>1,"FALTA/DUPLA: CONDIÇÃO DA PLATAFORMA",IF(COUNTIF(J17:L17,"X")<>1,"FALTA/DUPLA: DRENAGEM SUPERFICIAL","OK"))) -> OK
A18: 181ETO0230 | B18: C | C18: 9 | D18: 10 | E18: =D18-C18 -> 1 | I18: X | K18: X | N18: =IF(COUNTA(F18:L18)=0,"— não preenchido",IF(COUNTIF(F18:I18,"X")<>1,"FALTA/DUPLA: CONDIÇÃO DA PLATAFORMA",IF(COUNTIF(J18:L18,"X")<>1,"FALTA/DUPLA: DRENAGEM SUPERFICIAL","OK"))) -> OK
A19: 181ETO0230 | B19: C | C19: 10 | D19: 11 | E19: =D19-C19 -> 1 | I19: X | K19: X | N19: =IF(COUNTA(F19:L19)=0,"— não preenchido",IF(COUNTIF(F19:I19,"X")<>1,"FALTA/DUPLA: CONDIÇÃO DA PLATAFORMA",IF(COUNTIF(J19:L19,"X")<>1,"FALTA/DUPLA: DRENAGEM SUPERFICIAL","OK"))) -> OK
A20: 181ETO0230 | B20: C | C20: 11 | D20: 12 | E20: =D20-C20 -> 1 | I20: X | K20: X | N20: =IF(COUNTA(F20:L20)=0,"— não preenchido",IF(COUNTIF(F20:I20,"X")<>1,"FALTA/DUPLA: CONDIÇÃO DA PLATAFORMA",IF(COUNTIF(J20:L20,"X")<>1,"FALTA/DUPLA: DRENAGEM SUPERFICIAL","OK"))) -> OK
A21: 181ETO0230 | B21: C | C21: 12 | D21: 13 | E21: =D21-C21 -> 1 | I21: X | K21: X | N21: =IF(COUNTA(F21:L21)=0,"— não preenchido",IF(COUNTIF(F21:I21,"X")<>1,"FALTA/DUPLA: CONDIÇÃO DA PLATAFORMA",IF(COUNTIF(J21:L21,"X")<>1,"FALTA/DUPLA: DRENAGEM SUPERFICIAL","OK"))) -> OK
A22: 181ETO0230 | B22: C | C22: 13 | D22: 14 | E22: =D22-C22 -> 1 | H22: X | K22: X | N22: =IF(COUNTA(F22:L22)=0,"— não preenchido",IF(COUNTIF(F22:I22,"X")<>1,"FALTA/DUPLA: CONDIÇÃO DA PLATAFORMA",IF(COUNTIF(J22:L22,"X")<>1,"FALTA/DUPLA: DRENAGEM SUPERFICIAL","OK"))) -> OK
A23: 181ETO0230 | B23: C | C23: 14 | D23: 15 | E23: =D23-C23 -> 1 | H23: X | K23: X | N23: =IF(COUNTA(F23:L23)=0,"— não preenchido",IF(COUNTIF(F23:I23,"X")<>1,"FALTA/DUPLA: CONDIÇÃO DA PLATAFORMA",IF(COUNTIF(J23:L23,"X")<>1,"FALTA/DUPLA: DRENAGEM SUPERFICIAL","OK"))) -> OK
A24: 181ETO0230 | B24: C | C24: 15 | D24: 16 | E24: =D24-C24 -> 1 | H24: X | K24: X | N24: =IF(COUNTA(F24:L24)=0,"— não preenchido",IF(COUNTIF(F24:I24,"X")<>1,"FALTA/DUPLA: CONDIÇÃO DA PLATAFORMA",IF(COUNTIF(J24:L24,"X")<>1,"FALTA/DUPLA: DRENAGEM SUPERFICIAL","OK"))) -> OK
A25: 181ETO0230 | B25: C | C25: 16 | D25: 17 | E25: =D25-C25 -> 1 | H25: X | K25: X | N25: =IF(COUNTA(F25:L25)=0,"— não preenchido",IF(COUNTIF(F25:I25,"X")<>1,"FALTA/DUPLA: CONDIÇÃO DA PLATAFORMA",IF(COUNTIF(J25:L25,"X")<>1,"FALTA/DUPLA: DRENAGEM SUPERFICIAL","OK"))) -> OK
A26: 181ETO0230 | B26: C | C26: 17 | D26: 18 | E26: =D26-C26 -> 1 | H26: X | K26: X | N26: =IF(COUNTA(F26:L26)=0,"— não preenchido",IF(COUNTIF(F26:I26,"X")<>1,"FALTA/DUPLA: CONDIÇÃO DA PLATAFORMA",IF(COUNTIF(J26:L26,"X")<>1,"FALTA/DUPLA: DRENAGEM SUPERFICIAL","OK"))) -> OK
A27: 181ETO0230 | B27: C | C27: 18 | D27: 19 | E27: =D27-C27 -> 1 | H27: X | K27: X | N27: =IF(COUNTA(F27:L27)=0,"— não preenchido",IF(COUNTIF(F27:I27,"X")<>1,"FALTA/DUPLA: CONDIÇÃO DA PLATAFORMA",IF(COUNTIF(J27:L27,"X")<>1,"FALTA/DUPLA: DRENAGEM SUPERFICIAL","OK"))) -> OK
A28: 181ETO0230 | B28: C | C28: 19 | D28: 20 | E28: =D28-C28 -> 1 | H28: X | K28: X | N28: =IF(COUNTA(F28:L28)=0,"— não preenchido",IF(COUNTIF(F28:I28,"X")<>1,"FALTA/DUPLA: CONDIÇÃO DA PLATAFORMA",IF(COUNTIF(J28:L28,"X")<>1,"FALTA/DUPLA: DRENAGEM SUPERFICIAL","OK"))) -> OK
A29: 181ETO0230 | B29: C | C29: 20 | D29: 21 | E29: =D29-C29 -> 1 | H29: X | K29: X | N29: =IF(COUNTA(F29:L29)=0,"— não preenchido",IF(COUNTIF(F29:I29,"X")<>1,"FALTA/DUPLA: CONDIÇÃO DA PLATAFORMA",IF(COUNTIF(J29:L29,"X")<>1,"FALTA/DUPLA: DRENAGEM SUPERFICIAL","OK"))) -> OK
A30: 181ETO0230 | B30: C | C30: 21 | D30: 22 | E30: =D30-C30 -> 1 | H30: X | K30: X | N30: =IF(COUNTA(F30:L30)=0,"— não preenchido",IF(COUNTIF(F30:I30,"X")<>1,"FALTA/DUPLA: CONDIÇÃO DA PLATAFORMA",IF(COUNTIF(J30:L30,"X")<>1,"FALTA/DUPLA: DRENAGEM SUPERFICIAL","OK"))) -> OK
A31: 181ETO0230 | B31: C | C31: 22 | D31: 23 | E31: =D31-C31 -> 1 | H31: X | K31: X | N31: =IF(COUNTA(F31:L31)=0,"— não preenchido",IF(COUNTIF(F31:I31,"X")<>1,"FALTA/DUPLA: CONDIÇÃO DA PLATAFORMA",IF(COUNTIF(J31:L31,"X")<>1,"FALTA/DUPLA: DRENAGEM SUPERFICIAL","OK"))) -> OK
A32: 181ETO0230 | B32: C | C32: 23 | D32: 24 | E32: =D32-C32 -> 1 | H32: X | K32: X | N32: =IF(COUNTA(F32:L32)=0,"— não preenchido",IF(COUNTIF(F32:I32,"X")<>1,"FALTA/DUPLA: CONDIÇÃO DA PLATAFORMA",IF(COUNTIF(J32:L32,"X")<>1,"FALTA/DUPLA: DRENAGEM SUPERFICIAL","OK"))) -> OK
A33: 181ETO0230 | B33: C | C33: 24 | D33: 25 | E33: =D33-C33 -> 1 | H33: X | K33: X | N33: =IF(COUNTA(F33:L33)=0,"— não preenchido",IF(COUNTIF(F33:I33,"X")<>1,"FALTA/DUPLA: CONDIÇÃO DA PLATAFORMA",IF(COUNTIF(J33:L33,"X")<>1,"FALTA/DUPLA: DRENAGEM SUPERFICIAL","OK"))) -> OK
... A49: 181ETO0230 | B49: C | C49: 40 | D49: 40.379495 | E49: =D49-C49 -> 0.37949493 | H49: X | K49: X | N49: =IF(COUNTA(F49:L49)=0,"— não preenchido",IF(COUNTIF(F49:I49,"X")<>1,"FALTA/DUPLA: CONDIÇÃO DA PLATAFORMA",IF(COUNTIF(J49:L49,"X")<>1,"FALTA/DUPLA: DRENAGEM SUPERFICIAL","OK"))) -> OK
A51: ____________________________________________ | G51: ____________________________________________
A52: TÉCNICO RESPONSÁVEL PELA INSPEÇÃO | G52: VISTO DA SUPERVISÃO
A54: RESUMO DO TRECHO — KM LANÇADO POR ITEM
A55: KM LANÇADO | F55: =SUMIF(F$9:F$49,"X",$E$9:$E$49) -> 0 | G55: =SUMIF(G$9:G$49,"X",$E$9:$E$49) -> 0 | H55: =SUMIF(H$9:H$49,"X",$E$9:$E$49) -> 27.379495 | I55: =SUMIF(I$9:I$49,"X",$E$9:$E$49) -> 13 | J55: =SUMIF(J$9:J$49,"X",$E$9:$E$49) -> 0 | K55: =SUMIF(K$9:K$49,"X",$E$9:$E$49) -> 40.379495 | L55: =SUMIF(L$9:L$49,"X",$E$9:$E$49) -> 0
A56: % DA EXTENSÃO | F56: =IF($I58=0,0,F55/$I58) -> 0 | G56: =IF($I58=0,0,G55/$I58) -> 0 | H56: =IF($I58=0,0,H55/$I58) -> 0.67805442 | I56: =IF($I58=0,0,I55/$I58) -> 0.32194558 | J56: =IF($I58=0,0,J55/$I58) -> 0 | K56: =IF($I58=0,0,K55/$I58) -> 1 | L56: =IF($I58=0,0,L55/$I58) -> 0
A57: CONFERÊNCIA POR GRUPO | F57: =IF(SUM(F55:I55)=0,"— não preenchido",IF(ROUND(SUM(F55:I55)-$I58,3)=0,"OK — "&ROUND(SUM(F55:I55),3)&" km","ERRO — dif. de "&ROUND(SUM(F55:I55)-$I58,3)&" km")) -> OK — 40,379 km | J57: =IF(SUM(J55:L55)=0,"— não preenchido",IF(ROUND(SUM(J55:L55)-$I58,3)=0,"OK — "&ROUND(SUM(J55:L55),3)&" km","ERRO — dif. de "&ROUND(SUM(J55:L55)-$I58,3)&" km")) -> OK — 40,379 km
A58: EXTENSÃO TOTAL DO TRECHO | I58: =SUM(E9:E49) -> 40.379495 | M58: =COUNTIF(N9:N49,"OK")&" de "&COUNT($E$9:$E$49)&" linhas conferidas" -> 41 de 41 linhas conferidas
...

Sheet 214
A1: PROGRAMA DE MANUTENÇÃO RODOVIÁRIA — FICHA DE INSPEÇÃO — RODOVIAS NÃO PAVIMENTADAS | P1: Valores dos gráficos — troca 0 por N/D para a fatia não aparecer. Não editar.
A2: REGIÃO: 11 — GURUPI | D2: MÊS / ANO: | F2: 46235 | G2: DATA: | J2: TÉCNICO: | K2: ENG. THIAGO BORGES TORQUATO | P2: =IF(F60=0,NA(),F60) -> #N/A | Q2: =IF(G60=0,NA(),G60) -> 15 | R2: =IF(H60=0,NA(),H60) -> 30.214542 | S2: =IF(I60=0,NA(),I60) -> #N/A | T2: =IF(J60=0,NA(),J60) -> 45.214542 | U2: =IF(K60=0,NA(),K60) -> #N/A | V2: =IF(L60=0,NA(),L60) -> #N/A
A3: TRECHO 214 — RODOVIA TO-362 - TRECHO SANTA RITA DO TOCANTINS - BREJINHO DE NAZARÉ | K3: EXTENSÃO: 45,215 km · 1 S.R.E.
A4: COMO PREENCHER: uma X em UMA coluna de cada grupo, por linha. Se houver mais de um defeito no mesmo km, marque o PREDOMINANTE e escreva o resto em OBSERVAÇÕES. A quilometragem é contada de 0 até o fim de CADA S.R.E. (não é o marco da rodovia).
A6: S.R.E. | B6: SENT. | C6: INÍCIO (KM) | D6: FIM (KM) | E6: EXT. (KM) | F6: CONDIÇÃO DA PLATAFORMA | J6: DRENAGEM SUPERFICIAL | M6: OBSERVAÇÕES | N6: CONFERÊNCIA (só na tela)
F7: BOM | G7: REG. (ATÉ 10 IRR./KM) | H7: RUIM (+ 10 IRR./KM) | I7: PÉSSIMA (ATOLEIRO/PTO. CRÍTICO) | J7: LIMPA | K7: OBSTRUÍDA | L7: AUSENTE
A8: S.R.E. 362ETO0100 | ENTR. BR-153 (STA RITA DO TO) - ENTR. TO-070 (BREJINHO DE NAZARÉ) | LEN · Estadual · 45.215 km · início: -10.864649, -48.905564
A9: 362ETO0100 | B9: C | C9: 0 | D9: 1 | E9: =D9-C9 -> 1 | G9: X | J9: X | N9: =IF(COUNTA(F9:L9)=0,"— não preenchido",IF(COUNTIF(F9:I9,"X")<>1,"FALTA/DUPLA: CONDIÇÃO DA PLATAFORMA",IF(COUNTIF(J9:L9,"X")<>1,"FALTA/DUPLA: DRENAGEM SUPERFICIAL","OK"))) -> OK
A10: 362ETO0100 | B10: C | C10: 1 | D10: 2 | E10: =D10-C10 -> 1 | G10: X | J10: X | N10: =IF(COUNTA(F10:L10)=0,"— não preenchido",IF(COUNTIF(F10:I10,"X")<>1,"FALTA/DUPLA: CONDIÇÃO DA PLATAFORMA",IF(COUNTIF(J10:L10,"X")<>1,"FALTA/DUPLA: DRENAGEM SUPERFICIAL","OK"))) -> OK
A11: 362ETO0100 | B11: C | C11: 2 | D11: 3 | E11: =D11-C11 -> 1 | G11: X | J11: X | N11: =IF(COUNTA(F11:L11)=0,"— não preenchido",IF(COUNTIF(F11:I11,"X")<>1,"FALTA/DUPLA: CONDIÇÃO DA PLATAFORMA",IF(COUNTIF(J11:L11,"X")<>1,"FALTA/DUPLA: DRENAGEM SUPERFICIAL","OK"))) -> OK
A12: 362ETO0100 | B12: C | C12: 3 | D12: 4 | E12: =D12-C12 -> 1 | G12: X | J12: X | N12: =IF(COUNTA(F12:L12)=0,"— não preenchido",IF(COUNTIF(F12:I12,"X")<>1,"FALTA/DUPLA: CONDIÇÃO DA PLATAFORMA",IF(COUNTIF(J12:L12,"X")<>1,"FALTA/DUPLA: DRENAGEM SUPERFICIAL","OK"))) -> OK
A13: 362ETO0100 | B13: C | C13: 4 | D13: 5 | E13: =D13-C13 -> 1 | G13: X | J13: X | N13: =IF(COUNTA(F13:L13)=0,"— não preenchido",IF(COUNTIF(F13:I13,"X")<>1,"FALTA/DUPLA: CONDIÇÃO DA PLATAFORMA",IF(COUNTIF(J13:L13,"X")<>1,"FALTA/DUPLA: DRENAGEM SUPERFICIAL","OK"))) -> OK
A14: 362ETO0100 | B14: C | C14: 5 | D14: 6 | E14: =D14-C14 -> 1 | G14: X | J14: X | N14: =IF(COUNTA(F14:L14)=0,"— não preenchido",IF(COUNTIF(F14:I14,"X")<>1,"FALTA/DUPLA: CONDIÇÃO DA PLATAFORMA",IF(COUNTIF(J14:L14,"X")<>1,"FALTA/DUPLA: DRENAGEM SUPERFICIAL","OK"))) -> OK
A15: 362ETO0100 | B15: C | C15: 6 | D15: 7 | E15: =D15-C15 -> 1 | G15: X | J15: X | N15: =IF(COUNTA(F15:L15)=0,"— não preenchido",IF(COUNTIF(F15:I15,"X")<>1,"FALTA/DUPLA: CONDIÇÃO DA PLATAFORMA",IF(COUNTIF(J15:L15,"X")<>1,"FALTA/DUPLA: DRENAGEM SUPERFICIAL","OK"))) -> OK
A16: 362ETO0100 | B16: C | C16: 7 | D16: 8 | E16: =D16-C16 -> 1 | G16: X | J16: X | N16: =IF(COUNTA(F16:L16)=0,"— não preenchido",IF(COUNTIF(F16:I16,"X")<>1,"FALTA/DUPLA: CONDIÇÃO DA PLATAFORMA",IF(COUNTIF(J16:L16,"X")<>1,"FALTA/DUPLA: DRENAGEM SUPERFICIAL","OK"))) -> OK
A17: 362ETO0100 | B17: C | C17: 8 | D17: 9 | E17: =D17-C17 -> 1 | G17: X | J17: X | N17: =IF(COUNTA(F17:L17)=0,"— não preenchido",IF(COUNTIF(F17:I17,"X")<>1,"FALTA/DUPLA: CONDIÇÃO DA PLATAFORMA",IF(COUNTIF(J17:L17,"X")<>1,"FALTA/DUPLA: DRENAGEM SUPERFICIAL","OK"))) -> OK
A18: 362ETO0100 | B18: C | C18: 9 | D18: 10 | E18: =D18-C18 -> 1 | G18: X | J18: X | N18: =IF(COUNTA(F18:L18)=0,"— não preenchido",IF(COUNTIF(F18:I18,"X")<>1,"FALTA/DUPLA: CONDIÇÃO DA PLATAFORMA",IF(COUNTIF(J18:L18,"X")<>1,"FALTA/DUPLA: DRENAGEM SUPERFICIAL","OK"))) -> OK
A19: 362ETO0100 | B19: C | C19: 10 | D19: 11 | E19: =D19-C19 -> 1 | G19: X | J19: X | N19: =IF(COUNTA(F19:L19)=0,"— não preenchido",IF(COUNTIF(F19:I19,"X")<>1,"FALTA/DUPLA: CONDIÇÃO DA PLATAFORMA",IF(COUNTIF(J19:L19,"X")<>1,"FALTA/DUPLA: DRENAGEM SUPERFICIAL","OK"))) -> OK
A20: 362ETO0100 | B20: C | C20: 11 | D20: 12 | E20: =D20-C20 -> 1 | G20: X | J20: X | N20: =IF(COUNTA(F20:L20)=0,"— não preenchido",IF(COUNTIF(F20:I20,"X")<>1,"FALTA/DUPLA: CONDIÇÃO DA PLATAFORMA",IF(COUNTIF(J20:L20,"X")<>1,"FALTA/DUPLA: DRENAGEM SUPERFICIAL","OK"))) -> OK
... A23: 362ETO0100 | B23: C | C23: 14 | D23: 15 | E23: =D23-C23 -> 1 | G23: X | J23: X | N23: =IF(COUNTA(F23:L23)=0,"— não preenchido",IF(COUNTIF(F23:I23,"X")<>1,"FALTA/DUPLA: CONDIÇÃO DA PLATAFORMA",IF(COUNTIF(J23:L23,"X")<>1,"FALTA/DUPLA: DRENAGEM SUPERFICIAL","OK"))) -> OK
A24: 362ETO0100 | B24: C | C24: 15 | D24: 16 | E24: =D24-C24 -> 1 | H24: X | J24: X | N24: =IF(COUNTA(F24:L24)=0,"— não preenchido",IF(COUNTIF(F24:I24,"X")<>1,"FALTA/DUPLA: CONDIÇÃO DA PLATAFORMA",IF(COUNTIF(J24:L24,"X")<>1,"FALTA/DUPLA: DRENAGEM SUPERFICIAL","OK"))) -> OK
A25: 362ETO0100 | B25: C | C25: 16 | D25: 17 | E25: =D25-C25 -> 1 | H25: X | J25: X | N25: =IF(COUNTA(F25:L25)=0,"— não preenchido",IF(COUNTIF(F25:I25,"X")<>1,"FALTA/DUPLA: CONDIÇÃO DA PLATAFORMA",IF(COUNTIF(J25:L25,"X")<>1,"FALTA/DUPLA: DRENAGEM SUPERFICIAL","OK"))) -> OK
A26: 362ETO0100 | B26: C | C26: 17 | D26: 18 | E26: =D26-C26 -> 1 | H26: X | J26: X | N26: =IF(COUNTA(F26:L26)=0,"— não preenchido",IF(COUNTIF(F26:I26,"X")<>1,"FALTA/DUPLA: CONDIÇÃO DA PLATAFORMA",IF(COUNTIF(J26:L26,"X")<>1,"FALTA/DUPLA: DRENAGEM SUPERFICIAL","OK"))) -> OK
A27: 362ETO0100 | B27: C | C27: 18 | D27: 19 | E27: =D27-C27 -> 1 | H27: X | J27: X | N27: =IF(COUNTA(F27:L27)=0,"— não preenchido",IF(COUNTIF(F27:I27,"X")<>1,"FALTA/DUPLA: CONDIÇÃO DA PLATAFORMA",IF(COUNTIF(J27:L27,"X")<>1,"FALTA/DUPLA: DRENAGEM SUPERFICIAL","OK"))) -> OK
A28: 362ETO0100 | B28: C | C28: 19 | D28: 20 | E28: =D28-C28 -> 1 | H28: X | J28: X | N28: =IF(COUNTA(F28:L28)=0,"— não preenchido",IF(COUNTIF(F28:I28,"X")<>1,"FALTA/DUPLA: CONDIÇÃO DA PLATAFORMA",IF(COUNTIF(J28:L28,"X")<>1,"FALTA/DUPLA: DRENAGEM SUPERFICIAL","OK"))) -> OK
A29: 362ETO0100 | B29: C | C29: 20 | D29: 21 | E29: =D29-C29 -> 1 | H29: X | J29: X | N29: =IF(COUNTA(F29:L29)=0,"— não preenchido",IF(COUNTIF(F29:I29,"X")<>1,"FALTA/DUPLA: CONDIÇÃO DA PLATAFORMA",IF(COUNTIF(J29:L29,"X")<>1,"FALTA/DUPLA: DRENAGEM SUPERFICIAL","OK"))) -> OK
A30: 362ETO0100 | B30: C | C30: 21 | D30: 22 | E30: =D30-C30 -> 1 | H30: X | J30: X | N30: =IF(COUNTA(F30:L30)=0,"— não preenchido",IF(COUNTIF(F30:I30,"X")<>1,"FALTA/DUPLA: CONDIÇÃO DA PLATAFORMA",IF(COUNTIF(J30:L30,"X")<>1,"FALTA/DUPLA: DRENAGEM SUPERFICIAL","OK"))) -> OK
A31: 362ETO0100 | B31: C | C31: 22 | D31: 23 | E31: =D31-C31 -> 1 | H31: X | J31: X | N31: =IF(COUNTA(F31:L31)=0,"— não preenchido",IF(COUNTIF(F31:I31,"X")<>1,"FALTA/DUPLA: CONDIÇÃO DA PLATAFORMA",IF(COUNTIF(J31:L31,"X")<>1,"FALTA/DUPLA: DRENAGEM SUPERFICIAL","OK"))) -> OK
A32: 362ETO0100 | B32: C | C32: 23 | D32: 24 | E32: =D32-C32 -> 1 | H32: X | J32: X | N32: =IF(COUNTA(F32:L32)=0,"— não preenchido",IF(COUNTIF(F32:I32,"X")<>1,"FALTA/DUPLA: CONDIÇÃO DA PLATAFORMA",IF(COUNTIF(J32:L32,"X")<>1,"FALTA/DUPLA: DRENAGEM SUPERFICIAL","OK"))) -> OK
A33: 362ETO0100 | B33: C | C33: 24 | D33: 25 | E33: =D33-C33 -> 1 | H33: X | J33: X | N33: =IF(COUNTA(F33:L33)=0,"— não preenchido",IF(COUNTIF(F33:I33,"X")<>1,"FALTA/DUPLA: CONDIÇÃO DA PLATAFORMA",IF(COUNTIF(J33:L33,"X")<>1,"FALTA/DUPLA: DRENAGEM SUPERFICIAL","OK"))) -> OK
A34: 362ETO0100 | B34: C | C34: 25 | D34: 26 | E34: =D34-C34 -> 1 | H34: X | J34: X | N34: =IF(COUNTA(F34:L34)=0,"— não preenchido",IF(COUNTIF(F34:I34,"X")<>1,"FALTA/DUPLA: CONDIÇÃO DA PLATAFORMA",IF(COUNTIF(J34:L34,"X")<>1,"FALTA/DUPLA: DRENAGEM SUPERFICIAL","OK"))) -> OK
A35: 362ETO0100 | B35: C | C35: 26 | D35: 27 | E35: =D35-C35 -> 1 | H35: X | J35: X | N35: =IF(COUNTA(F35:L35)=0,"— não preenchido",IF(COUNTIF(F35:I35,"X")<>1,"FALTA/DUPLA: CONDIÇÃO DA PLATAFORMA",IF(COUNTIF(J35:L35,"X")<>1,"FALTA/DUPLA: DRENAGEM SUPERFICIAL","OK"))) -> OK
... A54: 362ETO0100 | B54: C | C54: 45 | D54: 45.214542 | E54: =D54-C54 -> 0.21454243 | H54: X | J54: X | N54: =IF(COUNTA(F54:L54)=0,"— não preenchido",IF(COUNTIF(F54:I54,"X")<>1,"FALTA/DUPLA: CONDIÇÃO DA PLATAFORMA",IF(COUNTIF(J54:L54,"X")<>1,"FALTA/DUPLA: DRENAGEM SUPERFICIAL","OK"))) -> OK
A56: ____________________________________________ | G56: ____________________________________________
A57: TÉCNICO RESPONSÁVEL PELA INSPEÇÃO | G57: VISTO DA SUPERVISÃO
A59: RESUMO DO TRECHO — KM LANÇADO POR ITEM
A60: KM LANÇADO | F60: =SUMIF(F$9:F$54,"X",$E$9:$E$54) -> 0 | G60: =SUMIF(G$9:G$54,"X",$E$9:$E$54) -> 15 | H60: =SUMIF(H$9:H$54,"X",$E$9:$E$54) -> 30.214542 | I60: =SUMIF(I$9:I$54,"X",$E$9:$E$54) -> 0 | J60: =SUMIF(J$9:J$54,"X",$E$9:$E$54) -> 45.214542 | K60: =SUMIF(K$9:K$54,"X",$E$9:$E$54) -> 0 | L60: =SUMIF(L$9:L$54,"X",$E$9:$E$54) -> 0
A61: % DA EXTENSÃO | F61: =IF($I63=0,0,F60/$I63) -> 0 | G61: =IF($I63=0,0,G60/$I63) -> 0.33175167 | H61: =IF($I63=0,0,H60/$I63) -> 0.66824833 | I61: =IF($I63=0,0,I60/$I63) -> 0 | J61: =IF($I63=0,0,J60/$I63) -> 1 | K61: =IF($I63=0,0,K60/$I63) -> 0 | L61: =IF($I63=0,0,L60/$I63) -> 0
A62: CONFERÊNCIA POR GRUPO | F62: =IF(SUM(F60:I60)=0,"— não preenchido",IF(ROUND(SUM(F60:I60)-$I63,3)=0,"OK — "&ROUND(SUM(F60:I60),3)&" km","ERRO — dif. de "&ROUND(SUM(F60:I60)-$I63,3)&" km")) -> OK — 45,215 km | J62: =IF(SUM(J60:L60)=0,"— não preenchido",IF(ROUND(SUM(J60:L60)-$I63,3)=0,"OK — "&ROUND(SUM(J60:L60),3)&" km","ERRO — dif. de "&ROUND(SUM(J60:L60)-$I63,3)&" km")) -> OK — 45,215 km
A63: EXTENSÃO TOTAL DO TRECHO | I63: =SUM(E9:E54) -> 45.214542 | M63: =COUNTIF(N9:N54,"OK")&" de "&COUNT($E$9:$E$54)&" linhas conferidas" -> 46 de 46 linhas conferidas
...

Sheet 215
A1: PROGRAMA DE MANUTENÇÃO RODOVIÁRIA — FICHA DE INSPEÇÃO — RODOVIAS NÃO PAVIMENTADAS | P1: Valores dos gráficos — troca 0 por N/D para a fatia não aparecer. Não editar.
A2: REGIÃO: 11 — GURUPI | D2: MÊS / ANO: | F2: 46235 | G2: DATA: | J2: TÉCNICO: | K2: ENG. THIAGO BORGES TORQUATO | P2: =IF(F51=0,NA(),F51) -> #N/A | Q2: =IF(G51=0,NA(),G51) -> 11 | R2: =IF(H51=0,NA(),H51) -> 25.281095 | S2: =IF(I51=0,NA(),I51) -> #N/A | T2: =IF(J51=0,NA(),J51) -> #N/A | U2: =IF(K51=0,NA(),K51) -> 33 | V2: =IF(L51=0,NA(),L51) -> 3.2810952
A3: TRECHO 215 — RODOVIA TO-362 - TRECHO BREJINHO DE NAZARÉ - ENTR. TO-365 (ACESSO BALSA) | K3: EXTENSÃO: 36,281 km · 1 S.R.E.
A4: COMO PREENCHER: uma X em UMA coluna de cada grupo, por linha. Se houver mais de um defeito no mesmo km, marque o PREDOMINANTE e escreva o resto em OBSERVAÇÕES. A quilometragem é contada de 0 até o fim de CADA S.R.E. (não é o marco da rodovia).
A6: S.R.E. | B6: SENT. | C6: INÍCIO (KM) | D6: FIM (KM) | E6: EXT. (KM) | F6: CONDIÇÃO DA PLATAFORMA | J6: DRENAGEM SUPERFICIAL | M6: OBSERVAÇÕES | N6: CONFERÊNCIA (só na tela)
F7: BOM | G7: REG. (ATÉ 10 IRR./KM) | H7: RUIM (+ 10 IRR./KM) | I7: PÉSSIMA (ATOLEIRO/PTO. CRÍTICO) | J7: LIMPA | K7: OBSTRUÍDA | L7: AUSENTE
A8: S.R.E. 362ETO0120 | BREJINHO DE NAZARÉ *TRECHO URBANO* - ENTR. TO-365 | LEN · Estadual · 36.281 km · início: -11.265538, -48.471305
A9: 362ETO0120 | B9: C | C9: 0 | D9: 1 | E9: =D9-C9 -> 1 | G9: X | K9: X | N9: =IF(COUNTA(F9:L9)=0,"— não preenchido",IF(COUNTIF(F9:I9,"X")<>1,"FALTA/DUPLA: CONDIÇÃO DA PLATAFORMA",IF(COUNTIF(J9:L9,"X")<>1,"FALTA/DUPLA: DRENAGEM SUPERFICIAL","OK"))) -> OK
A10: 362ETO0120 | B10: C | C10: 1 | D10: 2 | E10: =D10-C10 -> 1 | G10: X | K10: X | N10: =IF(COUNTA(F10:L10)=0,"— não preenchido",IF(COUNTIF(F10:I10,"X")<>1,"FALTA/DUPLA: CONDIÇÃO DA PLATAFORMA",IF(COUNTIF(J10:L10,"X")<>1,"FALTA/DUPLA: DRENAGEM SUPERFICIAL","OK"))) -> OK
A11: 362ETO0120 | B11: C | C11: 2 | D11: 3 | E11: =D11-C11 -> 1 | G11: X | K11: X | N11: =IF(COUNTA(F11:L11)=0,"— não preenchido",IF(COUNTIF(F11:I11,"X")<>1,"FALTA/DUPLA: CONDIÇÃO DA PLATAFORMA",IF(COUNTIF(J11:L11,"X")<>1,"FALTA/DUPLA: DRENAGEM SUPERFICIAL","OK"))) -> OK
A12: 362ETO0120 | B12: C | C12: 3 | D12: 4 | E12: =D12-C12 -> 1 | G12: X | K12: X | N12: =IF(COUNTA(F12:L12)=0,"— não preenchido",IF(COUNTIF(F12:I12,"X")<>1,"FALTA/DUPLA: CONDIÇÃO DA PLATAFORMA",IF(COUNTIF(J12:L12,"X")<>1,"FALTA/DUPLA: DRENAGEM SUPERFICIAL","OK"))) -> OK
A13: 362ETO0120 | B13: C | C13: 4 | D13: 5 | E13: =D13-C13 -> 1 | G13: X | K13: X | N13: =IF(COUNTA(F13:L13)=0,"— não preenchido",IF(COUNTIF(F13:I13,"X")<>1,"FALTA/DUPLA: CONDIÇÃO DA PLATAFORMA",IF(COUNTIF(J13:L13,"X")<>1,"FALTA/DUPLA: DRENAGEM SUPERFICIAL","OK"))) -> OK
A14: 362ETO0120 | B14: C | C14: 5 | D14: 6 | E14: =D14-C14 -> 1 | G14: X | K14: X | N14: =IF(COUNTA(F14:L14)=0,"— não preenchido",IF(COUNTIF(F14:I14,"X")<>1,"FALTA/DUPLA: CONDIÇÃO DA PLATAFORMA",IF(COUNTIF(J14:L14,"X")<>1,"FALTA/DUPLA: DRENAGEM SUPERFICIAL","OK"))) -> OK
A15: 362ETO0120 | B15: C | C15: 6 | D15: 7 | E15: =D15-C15 -> 1 | G15: X | K15: X | N15: =IF(COUNTA(F15:L15)=0,"— não preenchido",IF(COUNTIF(F15:I15,"X")<>1,"FALTA/DUPLA: CONDIÇÃO DA PLATAFORMA",IF(COUNTIF(J15:L15,"X")<>1,"FALTA/DUPLA: DRENAGEM SUPERFICIAL","OK"))) -> OK
A16: 362ETO0120 | B16: C | C16: 7 | D16: 8 | E16: =D16-C16 -> 1 | G16: X | K16: X | N16: =IF(COUNTA(F16:L16)=0,"— não preenchido",IF(COUNTIF(F16:I16,"X")<>1,"FALTA/DUPLA: CONDIÇÃO DA PLATAFORMA",IF(COUNTIF(J16:L16,"X")<>1,"FALTA/DUPLA: DRENAGEM SUPERFICIAL","OK"))) -> OK
A17: 362ETO0120 | B17: C | C17: 8 | D17: 9 | E17: =D17-C17 -> 1 | G17: X | K17: X | N17: =IF(COUNTA(F17:L17)=0,"— não preenchido",IF(COUNTIF(F17:I17,"X")<>1,"FALTA/DUPLA: CONDIÇÃO DA PLATAFORMA",IF(COUNTIF(J17:L17,"X")<>1,"FALTA/DUPLA: DRENAGEM SUPERFICIAL","OK"))) -> OK
A18: 362ETO0120 | B18: C | C18: 9 | D18: 10 | E18: =D18-C18 -> 1 | G18: X | K18: X | N18: =IF(COUNTA(F18:L18)=0,"— não preenchido",IF(COUNTIF(F18:I18,"X")<>1,"FALTA/DUPLA: CONDIÇÃO DA PLATAFORMA",IF(COUNTIF(J18:L18,"X")<>1,"FALTA/DUPLA: DRENAGEM SUPERFICIAL","OK"))) -> OK
A19: 362ETO0120 | B19: C | C19: 10 | D19: 11 | E19: =D19-C19 -> 1 | G19: X | K19: X | N19: =IF(COUNTA(F19:L19)=0,"— não preenchido",IF(COUNTIF(F19:I19,"X")<>1,"FALTA/DUPLA: CONDIÇÃO DA PLATAFORMA",IF(COUNTIF(J19:L19,"X")<>1,"FALTA/DUPLA: DRENAGEM SUPERFICIAL","OK"))) -> OK
A20: 362ETO0120 | B20: C | C20: 11 | D20: 12 | E20: =D20-C20 -> 1 | H20: X | K20: X | N20: =IF(COUNTA(F20:L20)=0,"— não preenchido",IF(COUNTIF(F20:I20,"X")<>1,"FALTA/DUPLA: CONDIÇÃO DA PLATAFORMA",IF(COUNTIF(J20:L20,"X")<>1,"FALTA/DUPLA: DRENAGEM SUPERFICIAL","OK"))) -> OK
A21: 362ETO0120 | B21: C | C21: 12 | D21: 13 | E21: =D21-C21 -> 1 | H21: X | K21: X | N21: =IF(COUNTA(F21:L21)=0,"— não preenchido",IF(COUNTIF(F21:I21,"X")<>1,"FALTA/DUPLA: CONDIÇÃO DA PLATAFORMA",IF(COUNTIF(J21:L21,"X")<>1,"FALTA/DUPLA: DRENAGEM SUPERFICIAL","OK"))) -> OK
A22: 362ETO0120 | B22: C | C22: 13 | D22: 14 | E22: =D22-C22 -> 1 | H22: X | K22: X | N22: =IF(COUNTA(F22:L22)=0,"— não preenchido",IF(COUNTIF(F22:I22,"X")<>1,"FALTA/DUPLA: CONDIÇÃO DA PLATAFORMA",IF(COUNTIF(J22:L22,"X")<>1,"FALTA/DUPLA: DRENAGEM SUPERFICIAL","OK"))) -> OK
A23: 362ETO0120 | B23: C | C23: 14 | D23: 15 | E23: =D23-C23 -> 1 | H23: X | K23: X | N23: =IF(COUNTA(F23:L23)=0,"— não preenchido",IF(COUNTIF(F23:I23,"X")<>1,"FALTA/DUPLA: CONDIÇÃO DA PLATAFORMA",IF(COUNTIF(J23:L23,"X")<>1,"FALTA/DUPLA: DRENAGEM SUPERFICIAL","OK"))) -> OK
A24: 362ETO0120 | B24: C | C24: 15 | D24: 16 | E24: =D24-C24 -> 1 | H24: X | K24: X | N24: =IF(COUNTA(F24:L24)=0,"— não preenchido",IF(COUNTIF(F24:I24,"X")<>1,"FALTA/DUPLA: CONDIÇÃO DA PLATAFORMA",IF(COUNTIF(J24:L24,"X")<>1,"FALTA/DUPLA: DRENAGEM SUPERFICIAL","OK"))) -> OK
A25: 362ETO0120 | B25: C | C25: 16 | D25: 17 | E25: =D25-C25 -> 1 | H25: X | K25: X | N25: =IF(COUNTA(F25:L25)=0,"— não preenchido",IF(COUNTIF(F25:I25,"X")<>1,"FALTA/DUPLA: CONDIÇÃO DA PLATAFORMA",IF(COUNTIF(J25:L25,"X")<>1,"FALTA/DUPLA: DRENAGEM SUPERFICIAL","OK"))) -> OK
A26: 362ETO0120 | B26: C | C26: 17 | D26: 18 | E26: =D26-C26 -> 1 | H26: X | K26: X | N26: =IF(COUNTA(F26:L26)=0,"— não preenchido",IF(COUNTIF(F26:I26,"X")<>1,"FALTA/DUPLA: CONDIÇÃO DA PLATAFORMA",IF(COUNTIF(J26:L26,"X")<>1,"FALTA/DUPLA: DRENAGEM SUPERFICIAL","OK"))) -> OK
A27: 362ETO0120 | B27: C | C27: 18 | D27: 19 | E27: =D27-C27 -> 1 | H27: X | K27: X | N27: =IF(COUNTA(F27:L27)=0,"— não preenchido",IF(COUNTIF(F27:I27,"X")<>1,"FALTA/DUPLA: CONDIÇÃO DA PLATAFORMA",IF(COUNTIF(J27:L27,"X")<>1,"FALTA/DUPLA: DRENAGEM SUPERFICIAL","OK"))) -> OK
A28: 362ETO0120 | B28: C | C28: 19 | D28: 20 | E28: =D28-C28 -> 1 | H28: X | K28: X | N28: =IF(COUNTA(F28:L28)=0,"— não preenchido",IF(COUNTIF(F28:I28,"X")<>1,"FALTA/DUPLA: CONDIÇÃO DA PLATAFORMA",IF(COUNTIF(J28:L28,"X")<>1,"FALTA/DUPLA: DRENAGEM SUPERFICIAL","OK"))) -> OK
A29: 362ETO0120 | B29: C | C29: 20 | D29: 21 | E29: =D29-C29 -> 1 | H29: X | K29: X | N29: =IF(COUNTA(F29:L29)=0,"— não preenchido",IF(COUNTIF(F29:I29,"X")<>1,"FALTA/DUPLA: CONDIÇÃO DA PLATAFORMA",IF(COUNTIF(J29:L29,"X")<>1,"FALTA/DUPLA: DRENAGEM SUPERFICIAL","OK"))) -> OK
A30: 362ETO0120 | B30: C | C30: 21 | D30: 22 | E30: =D30-C30 -> 1 | H30: X | K30: X | N30: =IF(COUNTA(F30:L30)=0,"— não preenchido",IF(COUNTIF(F30:I30,"X")<>1,"FALTA/DUPLA: CONDIÇÃO DA PLATAFORMA",IF(COUNTIF(J30:L30,"X")<>1,"FALTA/DUPLA: DRENAGEM SUPERFICIAL","OK"))) -> OK
A31: 362ETO0120 | B31: C | C31: 22 | D31: 23 | E31: =D31-C31 -> 1 | H31: X | K31: X | N31: =IF(COUNTA(F31:L31)=0,"— não preenchido",IF(COUNTIF(F31:I31,"X")<>1,"FALTA/DUPLA: CONDIÇÃO DA PLATAFORMA",IF(COUNTIF(J31:L31,"X")<>1,"FALTA/DUPLA: DRENAGEM SUPERFICIAL","OK"))) -> OK
