Workbook

Sheet Trechos
A1: RELAÇÃO DE SEGMENTOS PAVIMENTADOS R.11
A2: LOTE | B2: N. | C2: TRECHO | D2: S.R.E | E2: SUBTRECHOS | F2: EXT. (KM) | G2: TIPO | H2: 45839 | I2: 45870
A3: 11 | B3: 202 | C3: RODOVIA TO-070 - TRECHO SANDOLÂNDIA - FORMOSO DO ARAGUAIA | D3: 181ETO0171 | E3: PERÍMETRO URBANO DE SANDOLÂNDIA | F3: 1.1468163 | G3: PSU
A4: 11 | B4: 202 | C4: RODOVIA TO-070 - TRECHO SANDOLÂNDIA - FORMOSO DO ARAGUAIA | D4: 070ETO0230 | E4: ENTR. BR-242 (FORMOSO DO ARAGUAIA ) - DORILÂNDIA | F4: 59.748298 | G4: PPS
A5: 11 | B5: 202 | C5: RODOVIA TO-070 - TRECHO SANDOLÂNDIA - FORMOSO DO ARAGUAIA | D5: 070ETO0240 | E5: DORILÂNDIA - ENTR. TO-181 | F5: 9.4908128 | G5: PPS
A6: 11 | B6: 202 | C6: RODOVIA TO-070 - TRECHO SANDOLÂNDIA - FORMOSO DO ARAGUAIA | D6: 070ETO0250 | E6: ENTR. TO-181 - SANDOLÂNDIA *TRECHO URBANO* | F6: 32.011004 | G6: PPS
A7: 11 | B7: 203 | C7: RODOVIA TO-373 - TRECHO ALVORADA - ARAGUAÇU | D7: 373ETO0221 | E7: ALVORADA *TRECHO URBANO* | F7: 0.99985589 | G7: PSU
A8: 11 | B8: 204 | C8: RODOVIA TO-070 - TRECHO ALIANÇA DO TOCANTINS - BREJINHO DE NAZARÉ | D8: 070ETO0120 | E8: BREJINHO DE NAZARÉ *TRECHO URBANO* - ALIANCA *TRECHO URBANO* | F8: 58.755349 | G8: PPS
A9: 11 | B9: 204 | C9: RODOVIA TO-070 - TRECHO ALIANÇA DO TOCANTINS - BREJINHO DE NAZARÉ | D9: 070ETO0121 | E9: ALIANCA *TRECHO URBANO* | F9: 0.99026288 | G9: PPS
A10: 11 | B10: 205 | C10: RODOVIA TO-070 - TRECHO DUERÉ - ALIANÇA DO TOCANTINS | D10: 070ETO0140 | E10: ENTR. BR-153 (B) - ENTR. TO-164 | F10: 26.907003 | G10: PPS
A11: 11 | B11: 205 | C11: RODOVIA TO-070 - TRECHO DUERÉ - ALIANÇA DO TOCANTINS | D11: 070ETO0150 | E11: ENTR. TO-164 - ENTR. TO-374 | F11: 16.263875 | G11: PPS
A12: 11 | B12: 205 | C12: RODOVIA TO-070 - TRECHO DUERÉ - ALIANÇA DO TOCANTINS | D12: 070ETO0160 | E12: ENTR. TO-374 - DUERÉ *TRECHO URBANO* | F12: 3.6652384 | G12: PPS
A13: 11 | B13: 206 | C13: RODOVIA TO-070 - TRECHO FORMOSO DO ARAGUAIA - DUERÉ | D13: 070ETO0170 | E13: DUERÉ *TRECHO URBANO* - ENTR.TO-374 | F13: 0.41866269 | G13: PPS
A14: 11 | B14: 206 | C14: RODOVIA TO-070 - TRECHO FORMOSO DO ARAGUAIA - DUERÉ | D14: 070ETO0200 | E14: ENTR. TO-374 (DUERE) - FORMOSO DO ARAGUAIA *TRECHO URBANO* | F14: 61.372322 | G14: PPS
... A20: 11 | B20: 212 | C20: RODOVIA TO-181 - TRECHO ARAGUAÇU - SANDOLÂNDIA | D20: 181ETO0200 | E20: SANDOLANDIA *TRECHO URBANO* - ENTR. TO-373 (ARAGUAÇU *TRECHO URBANO*) | F20: 48.649724 | G20: PPS
A21: 11 | B21: 214 | C21: RODOVIA TO-362 - TRECHO SANTA RITA DO TOCANTINS - BREJINHO DE NAZARÉ | D21: 362ETO0110 | E21: ENTR. TO-070 - BREJINHO DE NAZARÉ *TRECHO URBANO* | F21: 0.37470222 | G21: PSU | H21: PPS
A22: 11 | B22: 218 | C22: RODOVIA TO-373 - TRECHO ALVORADA - ARAGUAÇU - DIVISA TO-GO | D22: 373ETO0240 | E22: ALVORADA *TRECHO URBANO* - ENTR. TO-181 (ARAGUAÇU *TRECHO URBANO*) | F22: 95.248502 | G22: PPS
A23: 11 | B23: 218 | C23: RODOVIA TO-373 - TRECHO ALVORADA - ARAGUAÇU - DIVISA TO-GO | D23: 373ETO0250 | E23: ENTR. TO-181 (ARAGUAÇU *TRECHO URBANO*) - ARAGUAÇU (ACESSO SUL) | F23: 6.1686928 | G23: PPS
A24: 11 | B24: 218 | C24: RODOVIA TO-373 - TRECHO ALVORADA - ARAGUAÇU - DIVISA TO-GO | D24: 373ETO0260 | E24: ARAGUAÇU (ACESSO SUL) - DIV TO-GO | F24: 10.891949 | G24: PPS
A25: 11 | B25: 219 | C25: RODOVIA TO-374 - TRECHO DUERÉ - GURUPI | D25: 374ETO0200 | E25: ENTR. TO-070 - GURUPI *TRECHO URBANO* | F25: 50.300052 | G25: PPS
A26: 11 | B26: 220 | C26: RODOVIA TO-460/483 - TRECHO BR-242 (VILA QUIXABA) - SUCUPIRA | D26: 460ETO0010 | E26: BR-242 (VILA QUIXABA) - SUCUPIRA *TRECHO URBANO* | F26: 14.041142 | G26: PPS
A27: 11 | B27: 220 | C27: RODOVIA TO-460/483 - TRECHO BR-242 (VILA QUIXABA) - SUCUPIRA | D27: 483ETO0010 | E27: SUCUPIRA *TRECHO URBANO* - FIM PAVIMENTAÇÃO | F27: 0.98012925 | G27: PPS
F28: =SUM(F3:F27) -> 563.39531

Sheet 202
A1: PROGRAMA DE MANUTENÇÃO RODOVIÁRIA
D2: RODOVIAS PAVIMENTADAS | I2: DATA: | J2: 46204 | N2: TÉCNICO RESP. | O2: ENG. THIAGO TORQUATO
A3: FICHA DE INSPEÇÃO: | B3: =TT!C4 -> RODOVIA TO-070 - TRECHO SANDOLÂNDIA - FORMOSO DO ARAGUAIA | Q3: REGIÃO: | S3: 11
A5: S.R.E. | B5: SENTIDO | C5: INÍCIO (KM) | D5: FIM (KM) | E5: CONDIÇÃO DO PAVIMENTO | J5: VEGETAÇÃO | L5: ELEM. DE DRENAGEM | O5: SIN. HOR. | R5: SIN. VERTICAL | U5: OBSERV.
E6: BOM | F6: REM. I. | G6: REM. L | H6: BUR. I | I6: BUR. L | J6: ADEQ. | K6: INADED. | L6: LIMPOS | M6: SUJOS | N6: DAN. | O6: BOM | P6: REG. | Q6: INEXIST. | R6: BOM | S6: POUCAS | T6: INEXIST.
A7: 070ETO0230 | B7: D | C7: 0 | D7: 1 | F7: X | K7: X | M7: X | P7: X | S7: X
C8: =D7 -> 1 | D8: 1.3 | G8: X | I8: X | K8: X | M8: X | P8: X | S8: X
C9: =D8 -> 1.3 | D9: 1.8 | F9: X | K9: X | M9: X | P9: X | S9: X
C10: =D9 -> 1.8 | D10: 2.7 | G10: X | K10: X | M10: X | P10: X | S10: X
C11: =D10 -> 2.7 | D11: 4.4 | F11: X | K11: X | M11: X | P11: X | S11: X
C12: =D11 -> 4.4 | D12: 5 | G12: X | I12: X | K12: X | M12: X | P12: X | S12: X
C13: =D12 -> 5 | D13: 5.3 | F13: X | I13: X | K13: X | M13: X | P13: X | S13: X
C14: =D13 -> 5.3 | D14: 5.4 | G14: X | I14: X | K14: X | M14: X | P14: X | S14: X
C15: =D14 -> 5.4 | D15: 6.7 | F15: X | K15: X | M15: X | P15: X | S15: X
C16: =D15 -> 6.7 | D16: 7.1 | G16: X | K16: X | M16: X | P16: X | S16: X
C17: =D16 -> 7.1 | D17: 11 | F17: X | K17: X | M17: X | P17: X | S17: X
C18: =D17 -> 11 | D18: 11.1 | H18: X | K18: X | M18: X | P18: X | S18: X
C19: =D18 -> 11.1 | D19: 17.3 | F19: X | K19: X | M19: X | P19: X | S19: X
C20: =D19 -> 17.3 | D20: 17.4 | H20: X | K20: X | M20: X | P20: X | S20: X
C21: =D20 -> 17.4 | D21: 21.9 | F21: X | I21: X | K21: X | M21: X | P21: X | S21: X
C22: =D21 -> 21.9 | D22: 22.1 | G22: X | I22: X | K22: X | M22: X | P22: X | S22: X
C23: =D22 -> 22.1 | D23: 33 | F23: X | K23: X | M23: X | P23: X | S23: X
C24: =D23 -> 33 | D24: 33.7 | G24: X | I24: X | K24: X | M24: X | P24: X | S24: X
C25: =D24 -> 33.7 | D25: 33.8 | H25: X | I25: X | K25: X | M25: X | P25: X | S25: X
C26: =D25 -> 33.8 | D26: 55.7 | F26: X | K26: X | M26: X | P26: X | S26: X
C27: =D26 -> 55.7 | D27: 56 | H27: X | I27: X | K27: X | M27: X | P27: X | S27: X
C28: =D27 -> 56 | D28: 56.4 | G28: X | K28: X | M28: X | P28: X | S28: X
C29: =D28 -> 56.4 | D29: 59.75 | F29: X | K29: X | M29: X | P29: X | S29: X
A30: 070ETO0240 | B30: D | C30: 0 | D30: 9.49 | F30: X | K30: X | M30: X | P30: X | S30: X
A31: 070ETO0250 | B31: D | C31: 0 | D31: 2.5 | K31: X | M31: X | P31: X | S31: X
C32: =D31 -> 2.5 | D32: 2.6 | H32: X | K32: X | M32: X | P32: X | S32: X
C33: =D32 -> 2.6 | D33: 3 | F33: X | K33: X | M33: X | P33: X | S33: X
C34: =D33 -> 3 | D34: 5.3 | G34: X | K34: X | M34: X | P34: X | S34: X
C35: =D34 -> 5.3 | D35: 6.7 | F35: X | K35: X | M35: X | P35: X | S35: X
C36: =D35 -> 6.7 | D36: 7.5 | G36: X | K36: X | M36: X | P36: X | S36: X
C37: =D36 -> 7.5 | D37: 8.7 | F37: X | J37: X | M37: X | P37: X | S37: X
C38: =D37 -> 8.7 | D38: 11.3 | G38: X | J38: X | M38: X | P38: X | S38: X
C39: =D38 -> 11.3 | D39: 11.4 | H39: X | J39: X | M39: X | P39: X | S39: X
C40: =D39 -> 11.4 | D40: 11.9 | F40: X | J40: X | M40: X | P40: X | S40: X
C41: =D40 -> 11.9 | D41: 15.3 | G41: X | H41: X | J41: X | M41: X | P41: X | S41: X
...

Sheet 203
A1: PROGRAMA DE MANUTENÇÃO RODOVIÁRIA
D2: RODOVIAS PAVIMENTADAS | I2: DATA: | J2: ='202'!J2 -> 46204 | N2: TÉCNICO RESP. | O2: ='202'!O2 -> ENG. THIAGO TORQUATO
A3: FICHA DE INSPEÇÃO: | B3: =TT!C5 -> RODOVIA TO-373 - TRECHO ALVORADA - ARAGUAÇU | Q3: REGIÃO: | S3: 11
A5: S.R.E. | B5: SENTIDO | C5: INÍCIO (KM) | D5: FIM (KM) | E5: CONDIÇÃO DO PAVIMENTO | J5: VEGETAÇÃO | L5: ELEM. DE DRENAGEM | O5: SIN. HOR. | R5: SIN. VERTICAL | U5: OBSERV.
E6: BOM | F6: REM. I. | G6: REM. L | H6: BUR. I | I6: BUR. L | J6: ADEQ. | K6: INADED. | L6: LIMPOS | M6: SUJOS | N6: DAN. | O6: BOM | P6: REG. | Q6: INEXIST. | R6: BOM | S6: POUCAS | T6: INEXIST.
A7: 373ETO0221 | B7: C | C7: 0 | D7: 1.15 | G7: X | J7: X | L7: X | P7: X | S7: X
A32: LEGENDA | B32: CONDIÇÃO DO PAVIMENTO
A33: REM. I | B33: REMENDOS ISOLADOS | E33: ATÉ 10 REMENDOS/KM | I33: BUR. I | J33: BURACOS ISOLADOS | M33: ATÉ 5 BURACOS/KM
A34: REM. L | B34: REMENDOS AO LONGO | E34: MAIS DE 10 REMENDOS/KM | I34: BUR. L | J34: BURACOS AO LONGO | M34: MAIS DE 5 BURACOS/KM
E39: =IF(E7="X",(D7-C7),"0") -> 0 | F39: =IF(F7="X",(D7-C7),"0") -> 0 | G39: =IF(G7="X",(D7-C7),"0") -> 1.15 | H39: =IF(H7="X",(D7-C7),"0") -> 0 | I39: =IF(I7="X",(D7-C7),"0") -> 0 | J39: =IF(J7="X",(D7-C7),"0") -> 1.15 | K39: =IF(K7="X",(D7-C7),"0") -> 0 | L39: =IF(L7="X",(D7-C7),"0") -> 1.15 | M39: =IF(M7="X",(D7-C7),"0") -> 0 | N39: =IF(N7="X",(D7-C7),"0") -> 0 | O39: =IF(O7="X",(D7-C7),"0") -> 0 | P39: =IF(P7="X",(D7-C7),"0") -> 1.15 | Q39: =IF(Q7="X",(D7-C7),"0") -> 0 | R39: =IF(R7="X",(D7-C7),"0") -> 0 | S39: =IF(S7="X",(D7-C7),"0") -> 1.15 | T39: =IF(T7="X",(D7-C7),"0") -> 0
E40: =IF(E8="X",(D8-C8),"0") -> 0 | F40: =IF(F8="X",(D8-C8),"0") -> 0 | G40: =IF(G8="X",(D8-C8),"0") -> 0 | H40: =IF(H8="X",(D8-C8),"0") -> 0 | I40: =IF(I8="X",(D8-C8),"0") -> 0 | J40: =IF(J8="X",(D8-C8),"0") -> 0 | K40: =IF(K8="X",(D8-C8),"0") -> 0 | L40: =IF(L8="X",(D8-C8),"0") -> 0 | M40: =IF(M8="X",(D8-C8),"0") -> 0 | N40: =IF(N8="X",(D8-C8),"0") -> 0 | O40: =IF(O8="X",(D8-C8),"0") -> 0 | P40: =IF(P8="X",(D8-C8),"0") -> 0 | Q40: =IF(Q8="X",(D8-C8),"0") -> 0 | R40: =IF(R8="X",(D8-C8),"0") -> 0 | S40: =IF(S8="X",(D8-C8),"0") -> 0 | T40: =IF(T8="X",(D8-C8),"0") -> 0
E41: =IF(E9="X",(D9-C9),"0") -> 0 | F41: =IF(F9="X",(D9-C9),"0") -> 0 | G41: =IF(G9="X",(D9-C9),"0") -> 0 | H41: =IF(H9="X",(D9-C9),"0") -> 0 | I41: =IF(I9="X",(D9-C9),"0") -> 0 | J41: =IF(J9="X",(D9-C9),"0") -> 0 | K41: =IF(K9="X",(D9-C9),"0") -> 0 | L41: =IF(L9="X",(D9-C9),"0") -> 0 | M41: =IF(M9="X",(D9-C9),"0") -> 0 | N41: =IF(N9="X",(D9-C9),"0") -> 0 | O41: =IF(O9="X",(D9-C9),"0") -> 0 | P41: =IF(P9="X",(D9-C9),"0") -> 0 | Q41: =IF(Q9="X",(D9-C9),"0") -> 0 | R41: =IF(R9="X",(D9-C9),"0") -> 0 | S41: =IF(S9="X",(D9-C9),"0") -> 0 | T41: =IF(T9="X",(D9-C9),"0") -> 0
E42: =IF(E10="X",(D10-C10),"0") -> 0 | F42: =IF(F10="X",(D10-C10),"0") -> 0 | G42: =IF(G10="X",(D10-C10),"0") -> 0 | H42: =IF(H10="X",(D10-C10),"0") -> 0 | I42: =IF(I10="X",(D10-C10),"0") -> 0 | J42: =IF(J10="X",(D10-C10),"0") -> 0 | K42: =IF(K10="X",(D10-C10),"0") -> 0 | L42: =IF(L10="X",(D10-C10),"0") -> 0 | M42: =IF(M10="X",(D10-C10),"0") -> 0 | N42: =IF(N10="X",(D10-C10),"0") -> 0 | O42: =IF(O10="X",(D10-C10),"0") -> 0 | P42: =IF(P10="X",(D10-C10),"0") -> 0 | Q42: =IF(Q10="X",(D10-C10),"0") -> 0 | R42: =IF(R10="X",(D10-C10),"0") -> 0 | S42: =IF(S10="X",(D10-C10),"0") -> 0 | T42: =IF(T10="X",(D10-C10),"0") -> 0
E43: =IF(E11="X",(D11-C11),"0") -> 0 | F43: =IF(F11="X",(D11-C11),"0") -> 0 | G43: =IF(G11="X",(D11-C11),"0") -> 0 | H43: =IF(H11="X",(D11-C11),"0") -> 0 | I43: =IF(I11="X",(D11-C11),"0") -> 0 | J43: =IF(J11="X",(D11-C11),"0") -> 0 | K43: =IF(K11="X",(D11-C11),"0") -> 0 | L43: =IF(L11="X",(D11-C11),"0") -> 0 | M43: =IF(M11="X",(D11-C11),"0") -> 0 | N43: =IF(N11="X",(D11-C11),"0") -> 0 | O43: =IF(O11="X",(D11-C11),"0") -> 0 | P43: =IF(P11="X",(D11-C11),"0") -> 0 | Q43: =IF(Q11="X",(D11-C11),"0") -> 0 | R43: =IF(R11="X",(D11-C11),"0") -> 0 | S43: =IF(S11="X",(D11-C11),"0") -> 0 | T43: =IF(T11="X",(D11-C11),"0") -> 0
E44: =IF(E12="X",(D12-C12),"0") -> 0 | F44: =IF(F12="X",(D12-C12),"0") -> 0 | G44: =IF(G12="X",(D12-C12),"0") -> 0 | H44: =IF(H12="X",(D12-C12),"0") -> 0 | I44: =IF(I12="X",(D12-C12),"0") -> 0 | J44: =IF(J12="X",(D12-C12),"0") -> 0 | K44: =IF(K12="X",(D12-C12),"0") -> 0 | L44: =IF(L12="X",(D12-C12),"0") -> 0 | M44: =IF(M12="X",(D12-C12),"0") -> 0 | N44: =IF(N12="X",(D12-C12),"0") -> 0 | O44: =IF(O12="X",(D12-C12),"0") -> 0 | P44: =IF(P12="X",(D12-C12),"0") -> 0 | Q44: =IF(Q12="X",(D12-C12),"0") -> 0 | R44: =IF(R12="X",(D12-C12),"0") -> 0 | S44: =IF(S12="X",(D12-C12),"0") -> 0 | T44: =IF(T12="X",(D12-C12),"0") -> 0
E45: =IF(E13="X",(D13-C13),"0") -> 0 | F45: =IF(F13="X",(D13-C13),"0") -> 0 | G45: =IF(G13="X",(D13-C13),"0") -> 0 | H45: =IF(H13="X",(D13-C13),"0") -> 0 | I45: =IF(I13="X",(D13-C13),"0") -> 0 | J45: =IF(J13="X",(D13-C13),"0") -> 0 | K45: =IF(K13="X",(D13-C13),"0") -> 0 | L45: =IF(L13="X",(D13-C13),"0") -> 0 | M45: =IF(M13="X",(D13-C13),"0") -> 0 | N45: =IF(N13="X",(D13-C13),"0") -> 0 | O45: =IF(O13="X",(D13-C13),"0") -> 0 | P45: =IF(P13="X",(D13-C13),"0") -> 0 | Q45: =IF(Q13="X",(D13-C13),"0") -> 0 | R45: =IF(R13="X",(D13-C13),"0") -> 0 | S45: =IF(S13="X",(D13-C13),"0") -> 0 | T45: =IF(T13="X",(D13-C13),"0") -> 0
E46: =IF(E14="X",(D14-C14),"0") -> 0 | F46: =IF(F14="X",(D14-C14),"0") -> 0 | G46: =IF(G14="X",(D14-C14),"0") -> 0 | H46: =IF(H14="X",(D14-C14),"0") -> 0 | I46: =IF(I14="X",(D14-C14),"0") -> 0 | J46: =IF(J14="X",(D14-C14),"0") -> 0 | K46: =IF(K14="X",(D14-C14),"0") -> 0 | L46: =IF(L14="X",(D14-C14),"0") -> 0 | M46: =IF(M14="X",(D14-C14),"0") -> 0 | N46: =IF(N14="X",(D14-C14),"0") -> 0 | O46: =IF(O14="X",(D14-C14),"0") -> 0 | P46: =IF(P14="X",(D14-C14),"0") -> 0 | Q46: =IF(Q14="X",(D14-C14),"0") -> 0 | R46: =IF(R14="X",(D14-C14),"0") -> 0 | S46: =IF(S14="X",(D14-C14),"0") -> 0 | T46: =IF(T14="X",(D14-C14),"0") -> 0
E47: =IF(E15="X",(D15-C15),"0") -> 0 | F47: =IF(F15="X",(D15-C15),"0") -> 0 | G47: =IF(G15="X",(D15-C15),"0") -> 0 | H47: =IF(H15="X",(D15-C15),"0") -> 0 | I47: =IF(I15="X",(D15-C15),"0") -> 0 | J47: =IF(J15="X",(D15-C15),"0") -> 0 | K47: =IF(K15="X",(D15-C15),"0") -> 0 | L47: =IF(L15="X",(D15-C15),"0") -> 0 | M47: =IF(M15="X",(D15-C15),"0") -> 0 | N47: =IF(N15="X",(D15-C15),"0") -> 0 | O47: =IF(O15="X",(D15-C15),"0") -> 0 | P47: =IF(P15="X",(D15-C15),"0") -> 0 | Q47: =IF(Q15="X",(D15-C15),"0") -> 0 | R47: =IF(R15="X",(D15-C15),"0") -> 0 | S47: =IF(S15="X",(D15-C15),"0") -> 0 | T47: =IF(T15="X",(D15-C15),"0") -> 0
E48: =IF(E16="X",(D16-C16),"0") -> 0 | F48: =IF(F16="X",(D16-C16),"0") -> 0 | G48: =IF(G16="X",(D16-C16),"0") -> 0 | H48: =IF(H16="X",(D16-C16),"0") -> 0 | I48: =IF(I16="X",(D16-C16),"0") -> 0 | J48: =IF(J16="X",(D16-C16),"0") -> 0 | K48: =IF(K16="X",(D16-C16),"0") -> 0 | L48: =IF(L16="X",(D16-C16),"0") -> 0 | M48: =IF(M16="X",(D16-C16),"0") -> 0 | N48: =IF(N16="X",(D16-C16),"0") -> 0 | O48: =IF(O16="X",(D16-C16),"0") -> 0 | P48: =IF(P16="X",(D16-C16),"0") -> 0 | Q48: =IF(Q16="X",(D16-C16),"0") -> 0 | R48: =IF(R16="X",(D16-C16),"0") -> 0 | S48: =IF(S16="X",(D16-C16),"0") -> 0 | T48: =IF(T16="X",(D16-C16),"0") -> 0
E49: =IF(E17="X",(D17-C17),"0") -> 0 | F49: =IF(F17="X",(D17-C17),"0") -> 0 | G49: =IF(G17="X",(D17-C17),"0") -> 0 | H49: =IF(H17="X",(D17-C17),"0") -> 0 | I49: =IF(I17="X",(D17-C17),"0") -> 0 | J49: =IF(J17="X",(D17-C17),"0") -> 0 | K49: =IF(K17="X",(D17-C17),"0") -> 0 | L49: =IF(L17="X",(D17-C17),"0") -> 0 | M49: =IF(M17="X",(D17-C17),"0") -> 0 | N49: =IF(N17="X",(D17-C17),"0") -> 0 | O49: =IF(O17="X",(D17-C17),"0") -> 0 | P49: =IF(P17="X",(D17-C17),"0") -> 0 | Q49: =IF(Q17="X",(D17-C17),"0") -> 0 | R49: =IF(R17="X",(D17-C17),"0") -> 0 | S49: =IF(S17="X",(D17-C17),"0") -> 0 | T49: =IF(T17="X",(D17-C17),"0") -> 0
E50: =IF(E18="X",(D18-C18),"0") -> 0 | F50: =IF(F18="X",(D18-C18),"0") -> 0 | G50: =IF(G18="X",(D18-C18),"0") -> 0 | H50: =IF(H18="X",(D18-C18),"0") -> 0 | I50: =IF(I18="X",(D18-C18),"0") -> 0 | J50: =IF(J18="X",(D18-C18),"0") -> 0 | K50: =IF(K18="X",(D18-C18),"0") -> 0 | L50: =IF(L18="X",(D18-C18),"0") -> 0 | M50: =IF(M18="X",(D18-C18),"0") -> 0 | N50: =IF(N18="X",(D18-C18),"0") -> 0 | O50: =IF(O18="X",(D18-C18),"0") -> 0 | P50: =IF(P18="X",(D18-C18),"0") -> 0 | Q50: =IF(Q18="X",(D18-C18),"0") -> 0 | R50: =IF(R18="X",(D18-C18),"0") -> 0 | S50: =IF(S18="X",(D18-C18),"0") -> 0 | T50: =IF(T18="X",(D18-C18),"0") -> 0
... E62: =IF(E30="X",(D30-C30),"0") -> 0 | F62: =IF(F30="X",(D30-C30),"0") -> 0 | G62: =IF(G30="X",(D30-C30),"0") -> 0 | H62: =IF(H30="X",(D30-C30),"0") -> 0 | I62: =IF(I30="X",(D30-C30),"0") -> 0 | J62: =IF(J30="X",(D30-C30),"0") -> 0 | K62: =IF(K30="X",(D30-C30),"0") -> 0 | L62: =IF(L30="X",(D30-C30),"0") -> 0 | M62: =IF(M30="X",(D30-C30),"0") -> 0 | N62: =IF(N30="X",(D30-C30),"0") -> 0 | O62: =IF(O30="X",(D30-C30),"0") -> 0 | P62: =IF(P30="X",(D30-C30),"0") -> 0 | Q62: =IF(Q30="X",(D30-C30),"0") -> 0 | R62: =IF(R30="X",(D30-C30),"0") -> 0 | S62: =IF(S30="X",(D30-C30),"0") -> 0 | T62: =IF(T30="X",(D30-C30),"0") -> 0
E128: =SUM(E39:E126) -> 0 | F128: =SUM(F39:F126) -> 0 | G128: =SUM(G39:G126) -> 1.15 | H128: =SUM(H39:H126) -> 0 | I128: =SUM(I39:I126) -> 0 | J128: =SUM(J39:J126) -> 1.15 | K128: =SUM(K39:K126) -> 0 | L128: =SUM(L39:L126) -> 1.15 | ... T128: =SUM(T39:T126) -> 0

Sheet 204
A1: PROGRAMA DE MANUTENÇÃO RODOVIÁRIA
D2: RODOVIAS PAVIMENTADAS | I2: DATA: | J2: ='202'!J2 -> 46204 | N2: TÉCNICO RESP. | O2: ='202'!O2 -> ENG. THIAGO TORQUATO
A3: FICHA DE INSPEÇÃO: | B3: =TT!C6 -> RODOVIA TO-070 - TRECHO ALIANÇA DO TOCANTINS - BREJINHO DE NAZARÉ | Q3: REGIÃO: | S3: 11
A5: S.R.E. | B5: SENTIDO | C5: INÍCIO (KM) | D5: FIM (KM) | E5: CONDIÇÃO DO PAVIMENTO | J5: VEGETAÇÃO | L5: ELEM. DE DRENAGEM | O5: SIN. HOR. | R5: SIN. VERTICAL | U5: OBSERV.
E6: BOM | F6: REM. I. | G6: REM. L | H6: BUR. I | I6: BUR. L | J6: ADEQ. | K6: INADED. | L6: LIMPOS | M6: SUJOS | N6: DAN. | O6: BOM | P6: REG. | Q6: INEXIST. | R6: BOM | S6: POUCAS | T6: INEXIST.
A7: 070ETO0120 | B7: C | C7: 0 | D7: 57.8 | F7: X | J7: X | M7: X | P7: X | S7: X
C8: =D7 -> 57.8 | D8: 57.8 | J8: X | M8: X | P8: X | S8: X
C9: =D8 -> 57.8 | D9: 58.76 | G9: X | J9: X | M9: X | P9: X | S9: X
A10: 070ETO0121 | B10: C | C10: 0 | D10: 0.99 | G10: X | J10: X | L10: X | Q10: X | S10: X
A32: LEGENDA | B32: CONDIÇÃO DO PAVIMENTO
A33: REM. I | B33: REMENDOS ISOLADOS | E33: ATÉ 10 REMENDOS/KM | I33: BUR. I | J33: BURACOS ISOLADOS | M33: ATÉ 5 BURACOS/KM
A34: REM. L | B34: REMENDOS AO LONGO | E34: MAIS DE 10 REMENDOS/KM | I34: BUR. L | J34: BURACOS AO LONGO | M34: MAIS DE 5 BURACOS/KM
E39: =IF(E7="X",(D7-C7),"0") -> 0 | F39: =IF(F7="X",(D7-C7),"0") -> 57.8 | G39: =IF(G7="X",(D7-C7),"0") -> 0 | H39: =IF(H7="X",(D7-C7),"0") -> 0 | I39: =IF(I7="X",(D7-C7),"0") -> 0 | J39: =IF(J7="X",(D7-C7),"0") -> 57.8 | K39: =IF(K7="X",(D7-C7),"0") -> 0 | L39: =IF(L7="X",(D7-C7),"0") -> 0 | M39: =IF(M7="X",(D7-C7),"0") -> 57.8 | N39: =IF(N7="X",(D7-C7),"0") -> 0 | O39: =IF(O7="X",(D7-C7),"0") -> 0 | P39: =IF(P7="X",(D7-C7),"0") -> 57.8 | Q39: =IF(Q7="X",(D7-C7),"0") -> 0 | R39: =IF(R7="X",(D7-C7),"0") -> 0 | S39: =IF(S7="X",(D7-C7),"0") -> 57.8 | T39: =IF(T7="X",(D7-C7),"0") -> 0
E40: =IF(E8="X",(D8-C8),"0") -> 0 | F40: =IF(F8="X",(D8-C8),"0") -> 0 | G40: =IF(G8="X",(D8-C8),"0") -> 0 | H40: =IF(H8="X",(D8-C8),"0") -> 0 | I40: =IF(I8="X",(D8-C8),"0") -> 0 | J40: =IF(J8="X",(D8-C8),"0") -> 0 | K40: =IF(K8="X",(D8-C8),"0") -> 0 | L40: =IF(L8="X",(D8-C8),"0") -> 0 | M40: =IF(M8="X",(D8-C8),"0") -> 0 | N40: =IF(N8="X",(D8-C8),"0") -> 0 | O40: =IF(O8="X",(D8-C8),"0") -> 0 | P40: =IF(P8="X",(D8-C8),"0") -> 0 | Q40: =IF(Q8="X",(D8-C8),"0") -> 0 | R40: =IF(R8="X",(D8-C8),"0") -> 0 | S40: =IF(S8="X",(D8-C8),"0") -> 0 | T40: =IF(T8="X",(D8-C8),"0") -> 0
E41: =IF(E9="X",(D9-C9),"0") -> 0 | F41: =IF(F9="X",(D9-C9),"0") -> 0 | G41: =IF(G9="X",(D9-C9),"0") -> 0.96 | H41: =IF(H9="X",(D9-C9),"0") -> 0 | I41: =IF(I9="X",(D9-C9),"0") -> 0 | J41: =IF(J9="X",(D9-C9),"0") -> 0.96 | K41: =IF(K9="X",(D9-C9),"0") -> 0 | L41: =IF(L9="X",(D9-C9),"0") -> 0 | M41: =IF(M9="X",(D9-C9),"0") -> 0.96 | N41: =IF(N9="X",(D9-C9),"0") -> 0 | O41: =IF(O9="X",(D9-C9),"0") -> 0 | P41: =IF(P9="X",(D9-C9),"0") -> 0.96 | Q41: =IF(Q9="X",(D9-C9),"0") -> 0 | R41: =IF(R9="X",(D9-C9),"0") -> 0 | S41: =IF(S9="X",(D9-C9),"0") -> 0.96 | T41: =IF(T9="X",(D9-C9),"0") -> 0
E42: =IF(E10="X",(D10-C10),"0") -> 0 | F42: =IF(F10="X",(D10-C10),"0") -> 0 | G42: =IF(G10="X",(D10-C10),"0") -> 0.99 | H42: =IF(H10="X",(D10-C10),"0") -> 0 | I42: =IF(I10="X",(D10-C10),"0") -> 0 | J42: =IF(J10="X",(D10-C10),"0") -> 0.99 | K42: =IF(K10="X",(D10-C10),"0") -> 0 | L42: =IF(L10="X",(D10-C10),"0") -> 0.99 | M42: =IF(M10="X",(D10-C10),"0") -> 0 | N42: =IF(N10="X",(D10-C10),"0") -> 0 | O42: =IF(O10="X",(D10-C10),"0") -> 0 | P42: =IF(P10="X",(D10-C10),"0") -> 0 | Q42: =IF(Q10="X",(D10-C10),"0") -> 0.99 | R42: =IF(R10="X",(D10-C10),"0") -> 0 | S42: =IF(S10="X",(D10-C10),"0") -> 0.99 | T42: =IF(T10="X",(D10-C10),"0") -> 0
E43: =IF(E11="X",(D11-C11),"0") -> 0 | F43: =IF(F11="X",(D11-C11),"0") -> 0 | G43: =IF(G11="X",(D11-C11),"0") -> 0 | H43: =IF(H11="X",(D11-C11),"0") -> 0 | I43: =IF(I11="X",(D11-C11),"0") -> 0 | J43: =IF(J11="X",(D11-C11),"0") -> 0 | K43: =IF(K11="X",(D11-C11),"0") -> 0 | L43: =IF(L11="X",(D11-C11),"0") -> 0 | M43: =IF(M11="X",(D11-C11),"0") -> 0 | N43: =IF(N11="X",(D11-C11),"0") -> 0 | O43: =IF(O11="X",(D11-C11),"0") -> 0 | P43: =IF(P11="X",(D11-C11),"0") -> 0 | Q43: =IF(Q11="X",(D11-C11),"0") -> 0 | R43: =IF(R11="X",(D11-C11),"0") -> 0 | S43: =IF(S11="X",(D11-C11),"0") -> 0 | T43: =IF(T11="X",(D11-C11),"0") -> 0
E44: =IF(E12="X",(D12-C12),"0") -> 0 | F44: =IF(F12="X",(D12-C12),"0") -> 0 | G44: =IF(G12="X",(D12-C12),"0") -> 0 | H44: =IF(H12="X",(D12-C12),"0") -> 0 | I44: =IF(I12="X",(D12-C12),"0") -> 0 | J44: =IF(J12="X",(D12-C12),"0") -> 0 | K44: =IF(K12="X",(D12-C12),"0") -> 0 | L44: =IF(L12="X",(D12-C12),"0") -> 0 | M44: =IF(M12="X",(D12-C12),"0") -> 0 | N44: =IF(N12="X",(D12-C12),"0") -> 0 | O44: =IF(O12="X",(D12-C12),"0") -> 0 | P44: =IF(P12="X",(D12-C12),"0") -> 0 | Q44: =IF(Q12="X",(D12-C12),"0") -> 0 | R44: =IF(R12="X",(D12-C12),"0") -> 0 | S44: =IF(S12="X",(D12-C12),"0") -> 0 | T44: =IF(T12="X",(D12-C12),"0") -> 0
E45: =IF(E13="X",(D13-C13),"0") -> 0 | F45: =IF(F13="X",(D13-C13),"0") -> 0 | G45: =IF(G13="X",(D13-C13),"0") -> 0 | H45: =IF(H13="X",(D13-C13),"0") -> 0 | I45: =IF(I13="X",(D13-C13),"0") -> 0 | J45: =IF(J13="X",(D13-C13),"0") -> 0 | K45: =IF(K13="X",(D13-C13),"0") -> 0 | L45: =IF(L13="X",(D13-C13),"0") -> 0 | M45: =IF(M13="X",(D13-C13),"0") -> 0 | N45: =IF(N13="X",(D13-C13),"0") -> 0 | O45: =IF(O13="X",(D13-C13),"0") -> 0 | P45: =IF(P13="X",(D13-C13),"0") -> 0 | Q45: =IF(Q13="X",(D13-C13),"0") -> 0 | R45: =IF(R13="X",(D13-C13),"0") -> 0 | S45: =IF(S13="X",(D13-C13),"0") -> 0 | T45: =IF(T13="X",(D13-C13),"0") -> 0
E46: =IF(E14="X",(D14-C14),"0") -> 0 | F46: =IF(F14="X",(D14-C14),"0") -> 0 | G46: =IF(G14="X",(D14-C14),"0") -> 0 | H46: =IF(H14="X",(D14-C14),"0") -> 0 | I46: =IF(I14="X",(D14-C14),"0") -> 0 | J46: =IF(J14="X",(D14-C14),"0") -> 0 | K46: =IF(K14="X",(D14-C14),"0") -> 0 | L46: =IF(L14="X",(D14-C14),"0") -> 0 | M46: =IF(M14="X",(D14-C14),"0") -> 0 | N46: =IF(N14="X",(D14-C14),"0") -> 0 | O46: =IF(O14="X",(D14-C14),"0") -> 0 | P46: =IF(P14="X",(D14-C14),"0") -> 0 | Q46: =IF(Q14="X",(D14-C14),"0") -> 0 | R46: =IF(R14="X",(D14-C14),"0") -> 0 | S46: =IF(S14="X",(D14-C14),"0") -> 0 | T46: =IF(T14="X",(D14-C14),"0") -> 0
E47: =IF(E15="X",(D15-C15),"0") -> 0 | F47: =IF(F15="X",(D15-C15),"0") -> 0 | G47: =IF(G15="X",(D15-C15),"0") -> 0 | H47: =IF(H15="X",(D15-C15),"0") -> 0 | I47: =IF(I15="X",(D15-C15),"0") -> 0 | J47: =IF(J15="X",(D15-C15),"0") -> 0 | K47: =IF(K15="X",(D15-C15),"0") -> 0 | L47: =IF(L15="X",(D15-C15),"0") -> 0 | M47: =IF(M15="X",(D15-C15),"0") -> 0 | N47: =IF(N15="X",(D15-C15),"0") -> 0 | O47: =IF(O15="X",(D15-C15),"0") -> 0 | P47: =IF(P15="X",(D15-C15),"0") -> 0 | Q47: =IF(Q15="X",(D15-C15),"0") -> 0 | R47: =IF(R15="X",(D15-C15),"0") -> 0 | S47: =IF(S15="X",(D15-C15),"0") -> 0 | T47: =IF(T15="X",(D15-C15),"0") -> 0
E48: =IF(E16="X",(D16-C16),"0") -> 0 | F48: =IF(F16="X",(D16-C16),"0") -> 0 | G48: =IF(G16="X",(D16-C16),"0") -> 0 | H48: =IF(H16="X",(D16-C16),"0") -> 0 | I48: =IF(I16="X",(D16-C16),"0") -> 0 | J48: =IF(J16="X",(D16-C16),"0") -> 0 | K48: =IF(K16="X",(D16-C16),"0") -> 0 | L48: =IF(L16="X",(D16-C16),"0") -> 0 | M48: =IF(M16="X",(D16-C16),"0") -> 0 | N48: =IF(N16="X",(D16-C16),"0") -> 0 | O48: =IF(O16="X",(D16-C16),"0") -> 0 | P48: =IF(P16="X",(D16-C16),"0") -> 0 | Q48: =IF(Q16="X",(D16-C16),"0") -> 0 | R48: =IF(R16="X",(D16-C16),"0") -> 0 | S48: =IF(S16="X",(D16-C16),"0") -> 0 | T48: =IF(T16="X",(D16-C16),"0") -> 0
E49: =IF(E17="X",(D17-C17),"0") -> 0 | F49: =IF(F17="X",(D17-C17),"0") -> 0 | G49: =IF(G17="X",(D17-C17),"0") -> 0 | H49: =IF(H17="X",(D17-C17),"0") -> 0 | I49: =IF(I17="X",(D17-C17),"0") -> 0 | J49: =IF(J17="X",(D17-C17),"0") -> 0 | K49: =IF(K17="X",(D17-C17),"0") -> 0 | L49: =IF(L17="X",(D17-C17),"0") -> 0 | M49: =IF(M17="X",(D17-C17),"0") -> 0 | N49: =IF(N17="X",(D17-C17),"0") -> 0 | O49: =IF(O17="X",(D17-C17),"0") -> 0 | P49: =IF(P17="X",(D17-C17),"0") -> 0 | Q49: =IF(Q17="X",(D17-C17),"0") -> 0 | R49: =IF(R17="X",(D17-C17),"0") -> 0 | S49: =IF(S17="X",(D17-C17),"0") -> 0 | T49: =IF(T17="X",(D17-C17),"0") -> 0
E50: =IF(E18="X",(D18-C18),"0") -> 0 | F50: =IF(F18="X",(D18-C18),"0") -> 0 | G50: =IF(G18="X",(D18-C18),"0") -> 0 | H50: =IF(H18="X",(D18-C18),"0") -> 0 | I50: =IF(I18="X",(D18-C18),"0") -> 0 | J50: =IF(J18="X",(D18-C18),"0") -> 0 | K50: =IF(K18="X",(D18-C18),"0") -> 0 | L50: =IF(L18="X",(D18-C18),"0") -> 0 | M50: =IF(M18="X",(D18-C18),"0") -> 0 | N50: =IF(N18="X",(D18-C18),"0") -> 0 | O50: =IF(O18="X",(D18-C18),"0") -> 0 | P50: =IF(P18="X",(D18-C18),"0") -> 0 | Q50: =IF(Q18="X",(D18-C18),"0") -> 0 | R50: =IF(R18="X",(D18-C18),"0") -> 0 | S50: =IF(S18="X",(D18-C18),"0") -> 0 | T50: =IF(T18="X",(D18-C18),"0") -> 0
... E59: =IF(E27="X",(D27-C27),"0") -> 0 | F59: =IF(F27="X",(D27-C27),"0") -> 0 | G59: =IF(G27="X",(D27-C27),"0") -> 0 | H59: =IF(H27="X",(D27-C27),"0") -> 0 | I59: =IF(I27="X",(D27-C27),"0") -> 0 | J59: =IF(J27="X",(D27-C27),"0") -> 0 | K59: =IF(K27="X",(D27-C27),"0") -> 0 | L59: =IF(L27="X",(D27-C27),"0") -> 0 | M59: =IF(M27="X",(D27-C27),"0") -> 0 | N59: =IF(N27="X",(D27-C27),"0") -> 0 | O59: =IF(O27="X",(D27-C27),"0") -> 0 | P59: =IF(P27="X",(D27-C27),"0") -> 0 | Q59: =IF(Q27="X",(D27-C27),"0") -> 0 | R59: =IF(R27="X",(D27-C27),"0") -> 0 | S59: =IF(S27="X",(D27-C27),"0") -> 0 | T59: =IF(T27="X",(D27-C27),"0") -> 0
E61: =SUM(E39:E60) -> 0 | F61: =SUM(F39:F60) -> 57.8 | G61: =SUM(G39:G60) -> 1.95 | H61: =SUM(H39:H60) -> 0 | I61: =SUM(I39:I60) -> 0 | J61: =SUM(J39:J60) -> 59.75 | K61: =SUM(K39:K60) -> 0 | L61: =SUM(L39:L60) -> 0.99 | ... T61: =SUM(T39:T60) -> 0

Sheet 205
A1: PROGRAMA DE MANUTENÇÃO RODOVIÁRIA
D2: RODOVIAS PAVIMENTADAS | I2: DATA: | J2: ='202'!J2 -> 46204 | N2: TÉCNICO RESP. | O2: ='202'!O2 -> ENG. THIAGO TORQUATO
A3: FICHA DE INSPEÇÃO: | B3: =TT!C7 -> RODOVIA TO-070 - TRECHO DUERÉ - ALIANÇA DO TOCANTINS | Q3: REGIÃO: | S3: 11
A5: S.R.E. | B5: SENTIDO | C5: INÍCIO (KM) | D5: FIM (KM) | E5: CONDIÇÃO DO PAVIMENTO | J5: VEGETAÇÃO | L5: ELEM. DE DRENAGEM | O5: SIN. HOR. | R5: SIN. VERTICAL | U5: OBSERV.
E6: BOM | F6: REM. I. | G6: REM. L | H6: BUR. I | I6: BUR. L | J6: ADEQ. | K6: INADED. | L6: LIMPOS | M6: SUJOS | N6: DAN. | O6: BOM | P6: REG. | Q6: INEXIST. | R6: BOM | S6: POUCAS | T6: INEXIST.
A7: 070ETO0140 | B7: C | C7: 0 | D7: 4.3 | E7: X | J7: X | M7: X | O7: X | S7: X
C8: =D7 -> 4.3 | D8: 4.3 | F8: X | J8: X | M8: X | O8: X | S8: X
C9: =D8 -> 4.3 | D9: 7 | E9: X | J9: X | M9: X | O9: X | S9: X
C10: =D9 -> 7 | D10: 16 | G10: X | J10: X | M10: X | O10: X | S10: X
C11: =D10 -> 16 | D11: 26.91 | E11: X | J11: X | M11: X | O11: X | S11: X
A12: 070ETO0150 | B12: C | C12: 0 | D12: 1 | F12: X | J12: X | M12: X | O12: X | S12: X
C13: =D12 -> 1 | D13: 3.1 | E13: X | J13: X | M13: X | O13: X | S13: X
C14: =D13 -> 3.1 | D14: 9 | F14: X | J14: X | M14: X | O14: X | S14: X
C15: =D14 -> 9 | D15: 10 | G15: X | J15: X | M15: X | O15: X | S15: X
C16: =D15 -> 10 | D16: 12 | F16: X | J16: X | M16: X | O16: X | S16: X
C17: =D16 -> 12 | D17: 16.26 | E17: X | J17: X | M17: X | O17: X | S17: X
A18: 070ETO0160 | B18: C | C18: 0 | D18: 3.67 | E18: X | J18: X | M18: X | O18: X | S18: X
A32: LEGENDA | B32: CONDIÇÃO DO PAVIMENTO
A33: REM. I | B33: REMENDOS ISOLADOS | E33: ATÉ 10 REMENDOS/KM | I33: BUR. I | J33: BURACOS ISOLADOS | M33: ATÉ 5 BURACOS/KM
A34: REM. L | B34: REMENDOS AO LONGO | E34: MAIS DE 10 REMENDOS/KM | I34: BUR. L | J34: BURACOS AO LONGO | M34: MAIS DE 5 BURACOS/KM
E39: =IF(E7="X",(D7-C7),"0") -> 4.3 | F39: =IF(F7="X",(D7-C7),"0") -> 0 | G39: =IF(G7="X",(D7-C7),"0") -> 0 | H39: =IF(H7="X",(D7-C7),"0") -> 0 | I39: =IF(I7="X",(D7-C7),"0") -> 0 | J39: =IF(J7="X",(D7-C7),"0") -> 4.3 | K39: =IF(K7="X",(D7-C7),"0") -> 0 | L39: =IF(L7="X",(D7-C7),"0") -> 0 | M39: =IF(M7="X",(D7-C7),"0") -> 4.3 | N39: =IF(N7="X",(D7-C7),"0") -> 0 | O39: =IF(O7="X",(D7-C7),"0") -> 4.3 | P39: =IF(P7="X",(D7-C7),"0") -> 0 | Q39: =IF(Q7="X",(D7-C7),"0") -> 0 | R39: =IF(R7="X",(D7-C7),"0") -> 0 | S39: =IF(S7="X",(D7-C7),"0") -> 4.3 | T39: =IF(T7="X",(D7-C7),"0") -> 0
E40: =IF(E8="X",(D8-C8),"0") -> 0 | F40: =IF(F8="X",(D8-C8),"0") -> 0 | G40: =IF(G8="X",(D8-C8),"0") -> 0 | H40: =IF(H8="X",(D8-C8),"0") -> 0 | I40: =IF(I8="X",(D8-C8),"0") -> 0 | J40: =IF(J8="X",(D8-C8),"0") -> 0 | K40: =IF(K8="X",(D8-C8),"0") -> 0 | L40: =IF(L8="X",(D8-C8),"0") -> 0 | M40: =IF(M8="X",(D8-C8),"0") -> 0 | N40: =IF(N8="X",(D8-C8),"0") -> 0 | O40: =IF(O8="X",(D8-C8),"0") -> 0 | P40: =IF(P8="X",(D8-C8),"0") -> 0 | Q40: =IF(Q8="X",(D8-C8),"0") -> 0 | R40: =IF(R8="X",(D8-C8),"0") -> 0 | S40: =IF(S8="X",(D8-C8),"0") -> 0 | T40: =IF(T8="X",(D8-C8),"0") -> 0
E41: =IF(E9="X",(D9-C9),"0") -> 2.7 | F41: =IF(F9="X",(D9-C9),"0") -> 0 | G41: =IF(G9="X",(D9-C9),"0") -> 0 | H41: =IF(H9="X",(D9-C9),"0") -> 0 | I41: =IF(I9="X",(D9-C9),"0") -> 0 | J41: =IF(J9="X",(D9-C9),"0") -> 2.7 | K41: =IF(K9="X",(D9-C9),"0") -> 0 | L41: =IF(L9="X",(D9-C9),"0") -> 0 | M41: =IF(M9="X",(D9-C9),"0") -> 2.7 | N41: =IF(N9="X",(D9-C9),"0") -> 0 | O41: =IF(O9="X",(D9-C9),"0") -> 2.7 | P41: =IF(P9="X",(D9-C9),"0") -> 0 | Q41: =IF(Q9="X",(D9-C9),"0") -> 0 | R41: =IF(R9="X",(D9-C9),"0") -> 0 | S41: =IF(S9="X",(D9-C9),"0") -> 2.7 | T41: =IF(T9="X",(D9-C9),"0") -> 0
E42: =IF(E10="X",(D10-C10),"0") -> 0 | F42: =IF(F10="X",(D10-C10),"0") -> 0 | G42: =IF(G10="X",(D10-C10),"0") -> 9 | H42: =IF(H10="X",(D10-C10),"0") -> 0 | I42: =IF(I10="X",(D10-C10),"0") -> 0 | J42: =IF(J10="X",(D10-C10),"0") -> 9 | K42: =IF(K10="X",(D10-C10),"0") -> 0 | L42: =IF(L10="X",(D10-C10),"0") -> 0 | M42: =IF(M10="X",(D10-C10),"0") -> 9 | N42: =IF(N10="X",(D10-C10),"0") -> 0 | O42: =IF(O10="X",(D10-C10),"0") -> 9 | P42: =IF(P10="X",(D10-C10),"0") -> 0 | Q42: =IF(Q10="X",(D10-C10),"0") -> 0 | R42: =IF(R10="X",(D10-C10),"0") -> 0 | S42: =IF(S10="X",(D10-C10),"0") -> 9 | T42: =IF(T10="X",(D10-C10),"0") -> 0
E43: =IF(E11="X",(D11-C11),"0") -> 10.91 | F43: =IF(F11="X",(D11-C11),"0") -> 0 | G43: =IF(G11="X",(D11-C11),"0") -> 0 | H43: =IF(H11="X",(D11-C11),"0") -> 0 | I43: =IF(I11="X",(D11-C11),"0") -> 0 | J43: =IF(J11="X",(D11-C11),"0") -> 10.91 | K43: =IF(K11="X",(D11-C11),"0") -> 0 | L43: =IF(L11="X",(D11-C11),"0") -> 0 | M43: =IF(M11="X",(D11-C11),"0") -> 10.91 | N43: =IF(N11="X",(D11-C11),"0") -> 0 | O43: =IF(O11="X",(D11-C11),"0") -> 10.91 | P43: =IF(P11="X",(D11-C11),"0") -> 0 | Q43: =IF(Q11="X",(D11-C11),"0") -> 0 | R43: =IF(R11="X",(D11-C11),"0") -> 0 | S43: =IF(S11="X",(D11-C11),"0") -> 10.91 | T43: =IF(T11="X",(D11-C11),"0") -> 0
E44: =IF(E12="X",(D12-C12),"0") -> 0 | F44: =IF(F12="X",(D12-C12),"0") -> 1 | G44: =IF(G12="X",(D12-C12),"0") -> 0 | H44: =IF(H12="X",(D12-C12),"0") -> 0 | I44: =IF(I12="X",(D12-C12),"0") -> 0 | J44: =IF(J12="X",(D12-C12),"0") -> 1 | K44: =IF(K12="X",(D12-C12),"0") -> 0 | L44: =IF(L12="X",(D12-C12),"0") -> 0 | M44: =IF(M12="X",(D12-C12),"0") -> 1 | N44: =IF(N12="X",(D12-C12),"0") -> 0 | O44: =IF(O12="X",(D12-C12),"0") -> 1 | P44: =IF(P12="X",(D12-C12),"0") -> 0 | Q44: =IF(Q12="X",(D12-C12),"0") -> 0 | R44: =IF(R12="X",(D12-C12),"0") -> 0 | S44: =IF(S12="X",(D12-C12),"0") -> 1 | T44: =IF(T12="X",(D12-C12),"0") -> 0
E45: =IF(E13="X",(D13-C13),"0") -> 2.1 | F45: =IF(F13="X",(D13-C13),"0") -> 0 | G45: =IF(G13="X",(D13-C13),"0") -> 0 | H45: =IF(H13="X",(D13-C13),"0") -> 0 | I45: =IF(I13="X",(D13-C13),"0") -> 0 | J45: =IF(J13="X",(D13-C13),"0") -> 2.1 | K45: =IF(K13="X",(D13-C13),"0") -> 0 | L45: =IF(L13="X",(D13-C13),"0") -> 0 | M45: =IF(M13="X",(D13-C13),"0") -> 2.1 | N45: =IF(N13="X",(D13-C13),"0") -> 0 | O45: =IF(O13="X",(D13-C13),"0") -> 2.1 | P45: =IF(P13="X",(D13-C13),"0") -> 0 | Q45: =IF(Q13="X",(D13-C13),"0") -> 0 | R45: =IF(R13="X",(D13-C13),"0") -> 0 | S45: =IF(S13="X",(D13-C13),"0") -> 2.1 | T45: =IF(T13="X",(D13-C13),"0") -> 0
E46: =IF(E14="X",(D14-C14),"0") -> 0 | F46: =IF(F14="X",(D14-C14),"0") -> 5.9 | G46: =IF(G14="X",(D14-C14),"0") -> 0 | H46: =IF(H14="X",(D14-C14),"0") -> 0 | I46: =IF(I14="X",(D14-C14),"0") -> 0 | J46: =IF(J14="X",(D14-C14),"0") -> 5.9 | K46: =IF(K14="X",(D14-C14),"0") -> 0 | L46: =IF(L14="X",(D14-C14),"0") -> 0 | M46: =IF(M14="X",(D14-C14),"0") -> 5.9 | N46: =IF(N14="X",(D14-C14),"0") -> 0 | O46: =IF(O14="X",(D14-C14),"0") -> 5.9 | P46: =IF(P14="X",(D14-C14),"0") -> 0 | Q46: =IF(Q14="X",(D14-C14),"0") -> 0 | R46: =IF(R14="X",(D14-C14),"0") -> 0 | S46: =IF(S14="X",(D14-C14),"0") -> 5.9 | T46: =IF(T14="X",(D14-C14),"0") -> 0
E47: =IF(E15="X",(D15-C15),"0") -> 0 | F47: =IF(F15="X",(D15-C15),"0") -> 0 | G47: =IF(G15="X",(D15-C15),"0") -> 1 | H47: =IF(H15="X",(D15-C15),"0") -> 0 | I47: =IF(I15="X",(D15-C15),"0") -> 0 | J47: =IF(J15="X",(D15-C15),"0") -> 1 | K47: =IF(K15="X",(D15-C15),"0") -> 0 | L47: =IF(L15="X",(D15-C15),"0") -> 0 | M47: =IF(M15="X",(D15-C15),"0") -> 1 | N47: =IF(N15="X",(D15-C15),"0") -> 0 | O47: =IF(O15="X",(D15-C15),"0") -> 1 | P47: =IF(P15="X",(D15-C15),"0") -> 0 | Q47: =IF(Q15="X",(D15-C15),"0") -> 0 | R47: =IF(R15="X",(D15-C15),"0") -> 0 | S47: =IF(S15="X",(D15-C15),"0") -> 1 | T47: =IF(T15="X",(D15-C15),"0") -> 0
E48: =IF(E16="X",(D16-C16),"0") -> 0 | F48: =IF(F16="X",(D16-C16),"0") -> 2 | G48: =IF(G16="X",(D16-C16),"0") -> 0 | H48: =IF(H16="X",(D16-C16),"0") -> 0 | I48: =IF(I16="X",(D16-C16),"0") -> 0 | J48: =IF(J16="X",(D16-C16),"0") -> 2 | K48: =IF(K16="X",(D16-C16),"0") -> 0 | L48: =IF(L16="X",(D16-C16),"0") -> 0 | M48: =IF(M16="X",(D16-C16),"0") -> 2 | N48: =IF(N16="X",(D16-C16),"0") -> 0 | O48: =IF(O16="X",(D16-C16),"0") -> 2 | P48: =IF(P16="X",(D16-C16),"0") -> 0 | Q48: =IF(Q16="X",(D16-C16),"0") -> 0 | R48: =IF(R16="X",(D16-C16),"0") -> 0 | S48: =IF(S16="X",(D16-C16),"0") -> 2 | T48: =IF(T16="X",(D16-C16),"0") -> 0
E49: =IF(E17="X",(D17-C17),"0") -> 4.26 | F49: =IF(F17="X",(D17-C17),"0") -> 0 | G49: =IF(G17="X",(D17-C17),"0") -> 0 | H49: =IF(H17="X",(D17-C17),"0") -> 0 | I49: =IF(I17="X",(D17-C17),"0") -> 0 | J49: =IF(J17="X",(D17-C17),"0") -> 4.26 | K49: =IF(K17="X",(D17-C17),"0") -> 0 | L49: =IF(L17="X",(D17-C17),"0") -> 0 | M49: =IF(M17="X",(D17-C17),"0") -> 4.26 | N49: =IF(N17="X",(D17-C17),"0") -> 0 | O49: =IF(O17="X",(D17-C17),"0") -> 4.26 | P49: =IF(P17="X",(D17-C17),"0") -> 0 | Q49: =IF(Q17="X",(D17-C17),"0") -> 0 | R49: =IF(R17="X",(D17-C17),"0") -> 0 | S49: =IF(S17="X",(D17-C17),"0") -> 4.26 | T49: =IF(T17="X",(D17-C17),"0") -> 0
E50: =IF(E18="X",(D18-C18),"0") -> 3.67 | F50: =IF(F18="X",(D18-C18),"0") -> 0 | G50: =IF(G18="X",(D18-C18),"0") -> 0 | H50: =IF(H18="X",(D18-C18),"0") -> 0 | I50: =IF(I18="X",(D18-C18),"0") -> 0 | J50: =IF(J18="X",(D18-C18),"0") -> 3.67 | K50: =IF(K18="X",(D18-C18),"0") -> 0 | L50: =IF(L18="X",(D18-C18),"0") -> 0 | M50: =IF(M18="X",(D18-C18),"0") -> 3.67 | N50: =IF(N18="X",(D18-C18),"0") -> 0 | O50: =IF(O18="X",(D18-C18),"0") -> 3.67 | P50: =IF(P18="X",(D18-C18),"0") -> 0 | Q50: =IF(Q18="X",(D18-C18),"0") -> 0 | R50: =IF(R18="X",(D18-C18),"0") -> 0 | S50: =IF(S18="X",(D18-C18),"0") -> 3.67 | T50: =IF(T18="X",(D18-C18),"0") -> 0
... E59: =IF(E27="X",(D27-C27),"0") -> 0 | F59: =IF(F27="X",(D27-C27),"0") -> 0 | G59: =IF(G27="X",(D27-C27),"0") -> 0 | H59: =IF(H27="X",(D27-C27),"0") -> 0 | I59: =IF(I27="X",(D27-C27),"0") -> 0 | J59: =IF(J27="X",(D27-C27),"0") -> 0 | K59: =IF(K27="X",(D27-C27),"0") -> 0 | L59: =IF(L27="X",(D27-C27),"0") -> 0 | M59: =IF(M27="X",(D27-C27),"0") -> 0 | N59: =IF(N27="X",(D27-C27),"0") -> 0 | O59: =IF(O27="X",(D27-C27),"0") -> 0 | P59: =IF(P27="X",(D27-C27),"0") -> 0 | Q59: =IF(Q27="X",(D27-C27),"0") -> 0 | R59: =IF(R27="X",(D27-C27),"0") -> 0 | S59: =IF(S27="X",(D27-C27),"0") -> 0 | T59: =IF(T27="X",(D27-C27),"0") -> 0
E84: =SUM(E39:E83) -> 27.94 | F84: =SUM(F39:F83) -> 8.9 | G84: =SUM(G39:G83) -> 10 | H84: =SUM(H39:H83) -> 0 | I84: =SUM(I39:I83) -> 0 | J84: =SUM(J39:J83) -> 46.84 | K84: =SUM(K39:K83) -> 0 | L84: =SUM(L39:L83) -> 0 | ... T84: =SUM(T39:T83) -> 0

Sheet 206
A1: PROGRAMA DE MANUTENÇÃO RODOVIÁRIA
D2: RODOVIAS PAVIMENTADAS | I2: DATA: | J2: ='202'!J2 -> 46204 | N2: TÉCNICO RESP. | O2: ='202'!O2 -> ENG. THIAGO TORQUATO
A3: FICHA DE INSPEÇÃO: | B3: =TT!C8 -> RODOVIA TO-070 - TRECHO FORMOSO DO ARAGUAIA - DUERÉ | Q3: REGIÃO: | S3: 11
A5: S.R.E. | B5: SENTIDO | C5: INÍCIO (KM) | D5: FIM (KM) | E5: CONDIÇÃO DO PAVIMENTO | J5: VEGETAÇÃO | L5: ELEM. DE DRENAGEM | O5: SIN. HOR. | R5: SIN. VERTICAL | U5: OBSERV.
E6: BOM | F6: REM. I. | G6: REM. L | H6: BUR. I | I6: BUR. L | J6: ADEQ. | K6: INADED. | L6: LIMPOS | M6: SUJOS | N6: DAN. | O6: BOM | P6: REG. | Q6: INEXIST. | R6: BOM | S6: POUCAS | T6: INEXIST.
A7: 070ETO0170 | B7: C | C7: 0 | D7: 0.42 | F7: X | J7: X | M7: X | O7: X | S7: X
A8: 070ETO0201 | B8: D | C8: 0 | D8: 3.13 | G8: X | H8: X | J8: X | M8: X | Q8: X | T8: X
A9: 070ETO0200 | B9: D | C9: 0 | D9: 1 | E9: X | J9: X | M9: X
C10: =D9 -> 1 | D10: 4.1 | F10: X | J10: X | M10: X | P10: X | S10: X
C11: =D10 -> 4.1 | D11: 7.4 | E11: X | J11: X | M11: X | P11: X | S11: X
C12: =D11 -> 7.4 | D12: 18 | F12: X | J12: X | M12: X | P12: X | S12: X
C13: =D12 -> 18 | D13: 20 | E13: X | G13: X | J13: X | M13: X | P13: X | S13: X
C14: =D13 -> 20 | D14: 23.3 | G14: X | H14: X | J14: X | M14: X | P14: X | S14: X
C15: =D14 -> 23.3 | D15: 29 | F15: X | J15: X | M15: X | P15: X | S15: X
C16: =D15 -> 29 | D16: 37 | F16: X | J16: X | M16: X | P16: X | S16: X
C17: =D16 -> 37 | D17: 39 | G17: X | J17: X | M17: X | P17: X | S17: X
C18: =D17 -> 39 | D18: 41.8 | F18: X | J18: X | M18: X | P18: X | S18: X
C19: =D18 -> 41.8 | D19: 43.3 | G19: X | J19: X | M19: X | P19: X | S19: X
C20: =D19 -> 43.3 | D20: 48 | F20: X | J20: X | M20: X | P20: X | S20: X
C21: =D20 -> 48 | D21: 49 | G21: X | H21: X | J21: X | M21: X | P21: X | S21: X
C22: =D21 -> 49 | D22: 61.37 | F22: X | H22: X | J22: X | M22: X | P22: X | S22: X
A54: LEGENDA | B54: CONDIÇÃO DO PAVIMENTO
A55: REM. I | B55: REMENDOS ISOLADOS | E55: ATÉ 10 REMENDOS/KM | I55: BUR. I | J55: BURACOS ISOLADOS | M55: ATÉ 5 BURACOS/KM
A56: REM. L | B56: REMENDOS AO LONGO | E56: MAIS DE 10 REMENDOS/KM | I56: BUR. L | J56: BURACOS AO LONGO | M56: MAIS DE 5 BURACOS/KM
E61: =IF(E7="X",(D7-C7),"0") -> 0 | F61: =IF(F7="X",(D7-C7),"0") -> 0.42 | G61: =IF(G7="X",(D7-C7),"0") -> 0 | H61: =IF(H7="X",(D7-C7),"0") -> 0 | I61: =IF(I7="X",(D7-C7),"0") -> 0 | J61: =IF(J7="X",(D7-C7),"0") -> 0.42 | K61: =IF(K7="X",(D7-C7),"0") -> 0 | L61: =IF(L7="X",(D7-C7),"0") -> 0 | M61: =IF(M7="X",(D7-C7),"0") -> 0.42 | N61: =IF(N7="X",(D7-C7),"0") -> 0 | O61: =IF(O7="X",(D7-C7),"0") -> 0.42 | P61: =IF(P7="X",(D7-C7),"0") -> 0 | Q61: =IF(Q7="X",(D7-C7),"0") -> 0 | R61: =IF(R7="X",(D7-C7),"0") -> 0 | S61: =IF(S7="X",(D7-C7),"0") -> 0.42 | T61: =IF(T7="X",(D7-C7),"0") -> 0
E62: =IF(E8="X",(D8-C8),"0") -> 0 | F62: =IF(F8="X",(D8-C8),"0") -> 0 | G62: =IF(G8="X",(D8-C8),"0") -> 3.13 | H62: =IF(H8="X",(D8-C8),"0") -> 3.13 | I62: =IF(I8="X",(D8-C8),"0") -> 0 | J62: =IF(J8="X",(D8-C8),"0") -> 3.13 | K62: =IF(K8="X",(D8-C8),"0") -> 0 | L62: =IF(L8="X",(D8-C8),"0") -> 0 | M62: =IF(M8="X",(D8-C8),"0") -> 3.13 | N62: =IF(N8="X",(D8-C8),"0") -> 0 | O62: =IF(O8="X",(D8-C8),"0") -> 0 | P62: =IF(P8="X",(D8-C8),"0") -> 0 | Q62: =IF(Q8="X",(D8-C8),"0") -> 3.13 | R62: =IF(R8="X",(D8-C8),"0") -> 0 | S62: =IF(S8="X",(D8-C8),"0") -> 0 | T62: =IF(T8="X",(D8-C8),"0") -> 3.13
E63: =IF(E9="X",(D9-C9),"0") -> 1 | F63: =IF(F9="X",(D9-C9),"0") -> 0 | G63: =IF(G9="X",(D9-C9),"0") -> 0 | H63: =IF(H9="X",(D9-C9),"0") -> 0 | I63: =IF(I9="X",(D9-C9),"0") -> 0 | J63: =IF(J9="X",(D9-C9),"0") -> 1 | K63: =IF(K9="X",(D9-C9),"0") -> 0 | L63: =IF(L9="X",(D9-C9),"0") -> 0 | M63: =IF(M9="X",(D9-C9),"0") -> 1 | N63: =IF(N9="X",(D9-C9),"0") -> 0 | O63: =IF(O9="X",(D9-C9),"0") -> 0 | P63: =IF(P9="X",(D9-C9),"0") -> 0 | Q63: =IF(Q9="X",(D9-C9),"0") -> 0 | R63: =IF(R9="X",(D9-C9),"0") -> 0 | S63: =IF(S9="X",(D9-C9),"0") -> 0 | T63: =IF(T9="X",(D9-C9),"0") -> 0
E64: =IF(E10="X",(D10-C10),"0") -> 0 | F64: =IF(F10="X",(D10-C10),"0") -> 3.1 | G64: =IF(G10="X",(D10-C10),"0") -> 0 | H64: =IF(H10="X",(D10-C10),"0") -> 0 | I64: =IF(I10="X",(D10-C10),"0") -> 0 | J64: =IF(J10="X",(D10-C10),"0") -> 3.1 | K64: =IF(K10="X",(D10-C10),"0") -> 0 | L64: =IF(L10="X",(D10-C10),"0") -> 0 | M64: =IF(M10="X",(D10-C10),"0") -> 3.1 | N64: =IF(N10="X",(D10-C10),"0") -> 0 | O64: =IF(O10="X",(D10-C10),"0") -> 0 | P64: =IF(P10="X",(D10-C10),"0") -> 3.1 | Q64: =IF(Q10="X",(D10-C10),"0") -> 0 | R64: =IF(R10="X",(D10-C10),"0") -> 0 | S64: =IF(S10="X",(D10-C10),"0") -> 3.1 | T64: =IF(T10="X",(D10-C10),"0") -> 0
E65: =IF(E11="X",(D11-C11),"0") -> 3.3 | F65: =IF(F11="X",(D11-C11),"0") -> 0 | G65: =IF(G11="X",(D11-C11),"0") -> 0 | H65: =IF(H11="X",(D11-C11),"0") -> 0 | I65: =IF(I11="X",(D11-C11),"0") -> 0 | J65: =IF(J11="X",(D11-C11),"0") -> 3.3 | K65: =IF(K11="X",(D11-C11),"0") -> 0 | L65: =IF(L11="X",(D11-C11),"0") -> 0 | M65: =IF(M11="X",(D11-C11),"0") -> 3.3 | N65: =IF(N11="X",(D11-C11),"0") -> 0 | O65: =IF(O11="X",(D11-C11),"0") -> 0 | P65: =IF(P11="X",(D11-C11),"0") -> 3.3 | Q65: =IF(Q11="X",(D11-C11),"0") -> 0 | R65: =IF(R11="X",(D11-C11),"0") -> 0 | S65: =IF(S11="X",(D11-C11),"0") -> 3.3 | T65: =IF(T11="X",(D11-C11),"0") -> 0
E66: =IF(E12="X",(D12-C12),"0") -> 0 | F66: =IF(F12="X",(D12-C12),"0") -> 10.6 | G66: =IF(G12="X",(D12-C12),"0") -> 0 | H66: =IF(H12="X",(D12-C12),"0") -> 0 | I66: =IF(I12="X",(D12-C12),"0") -> 0 | J66: =IF(J12="X",(D12-C12),"0") -> 10.6 | K66: =IF(K12="X",(D12-C12),"0") -> 0 | L66: =IF(L12="X",(D12-C12),"0") -> 0 | M66: =IF(M12="X",(D12-C12),"0") -> 10.6 | N66: =IF(N12="X",(D12-C12),"0") -> 0 | O66: =IF(O12="X",(D12-C12),"0") -> 0 | P66: =IF(P12="X",(D12-C12),"0") -> 10.6 | Q66: =IF(Q12="X",(D12-C12),"0") -> 0 | R66: =IF(R12="X",(D12-C12),"0") -> 0 | S66: =IF(S12="X",(D12-C12),"0") -> 10.6 | T66: =IF(T12="X",(D12-C12),"0") -> 0
E67: =IF(E13="X",(D13-C13),"0") -> 2 | F67: =IF(F13="X",(D13-C13),"0") -> 0 | G67: =IF(G13="X",(D13-C13),"0") -> 2 | H67: =IF(H13="X",(D13-C13),"0") -> 0 | I67: =IF(I13="X",(D13-C13),"0") -> 0 | J67: =IF(J13="X",(D13-C13),"0") -> 2 | K67: =IF(K13="X",(D13-C13),"0") -> 0 | L67: =IF(L13="X",(D13-C13),"0") -> 0 | M67: =IF(M13="X",(D13-C13),"0") -> 2 | N67: =IF(N13="X",(D13-C13),"0") -> 0 | O67: =IF(O13="X",(D13-C13),"0") -> 0 | P67: =IF(P13="X",(D13-C13),"0") -> 2 | Q67: =IF(Q13="X",(D13-C13),"0") -> 0 | R67: =IF(R13="X",(D13-C13),"0") -> 0 | S67: =IF(S13="X",(D13-C13),"0") -> 2 | T67: =IF(T13="X",(D13-C13),"0") -> 0
E68: =IF(E14="X",(D14-C14),"0") -> 0 | F68: =IF(F14="X",(D14-C14),"0") -> 0 | G68: =IF(G14="X",(D14-C14),"0") -> 3.3 | H68: =IF(H14="X",(D14-C14),"0") -> 3.3 | I68: =IF(I14="X",(D14-C14),"0") -> 0 | J68: =IF(J14="X",(D14-C14),"0") -> 3.3 | K68: =IF(K14="X",(D14-C14),"0") -> 0 | L68: =IF(L14="X",(D14-C14),"0") -> 0 | M68: =IF(M14="X",(D14-C14),"0") -> 3.3 | N68: =IF(N14="X",(D14-C14),"0") -> 0 | O68: =IF(O14="X",(D14-C14),"0") -> 0 | P68: =IF(P14="X",(D14-C14),"0") -> 3.3 | Q68: =IF(Q14="X",(D14-C14),"0") -> 0 | R68: =IF(R14="X",(D14-C14),"0") -> 0 | S68: =IF(S14="X",(D14-C14),"0") -> 3.3 | T68: =IF(T14="X",(D14-C14),"0") -> 0
E69: =IF(E15="X",(D15-C15),"0") -> 0 | F69: =IF(F15="X",(D15-C15),"0") -> 5.7 | G69: =IF(G15="X",(D15-C15),"0") -> 0 | H69: =IF(H15="X",(D15-C15),"0") -> 0 | I69: =IF(I15="X",(D15-C15),"0") -> 0 | J69: =IF(J15="X",(D15-C15),"0") -> 5.7 | K69: =IF(K15="X",(D15-C15),"0") -> 0 | L69: =IF(L15="X",(D15-C15),"0") -> 0 | M69: =IF(M15="X",(D15-C15),"0") -> 5.7 | N69: =IF(N15="X",(D15-C15),"0") -> 0 | O69: =IF(O15="X",(D15-C15),"0") -> 0 | P69: =IF(P15="X",(D15-C15),"0") -> 5.7 | Q69: =IF(Q15="X",(D15-C15),"0") -> 0 | R69: =IF(R15="X",(D15-C15),"0") -> 0 | S69: =IF(S15="X",(D15-C15),"0") -> 5.7 | T69: =IF(T15="X",(D15-C15),"0") -> 0
E70: =IF(E16="X",(D16-C16),"0") -> 0 | F70: =IF(F16="X",(D16-C16),"0") -> 8 | G70: =IF(G16="X",(D16-C16),"0") -> 0 | H70: =IF(H16="X",(D16-C16),"0") -> 0 | I70: =IF(I16="X",(D16-C16),"0") -> 0 | J70: =IF(J16="X",(D16-C16),"0") -> 8 | K70: =IF(K16="X",(D16-C16),"0") -> 0 | L70: =IF(L16="X",(D16-C16),"0") -> 0 | M70: =IF(M16="X",(D16-C16),"0") -> 8 | N70: =IF(N16="X",(D16-C16),"0") -> 0 | O70: =IF(O16="X",(D16-C16),"0") -> 0 | P70: =IF(P16="X",(D16-C16),"0") -> 8 | Q70: =IF(Q16="X",(D16-C16),"0") -> 0 | R70: =IF(R16="X",(D16-C16),"0") -> 0 | S70: =IF(S16="X",(D16-C16),"0") -> 8 | T70: =IF(T16="X",(D16-C16),"0") -> 0
E71: =IF(E17="X",(D17-C17),"0") -> 0 | F71: =IF(F17="X",(D17-C17),"0") -> 0 | G71: =IF(G17="X",(D17-C17),"0") -> 2 | H71: =IF(H17="X",(D17-C17),"0") -> 0 | I71: =IF(I17="X",(D17-C17),"0") -> 0 | J71: =IF(J17="X",(D17-C17),"0") -> 2 | K71: =IF(K17="X",(D17-C17),"0") -> 0 | L71: =IF(L17="X",(D17-C17),"0") -> 0 | M71: =IF(M17="X",(D17-C17),"0") -> 2 | N71: =IF(N17="X",(D17-C17),"0") -> 0 | O71: =IF(O17="X",(D17-C17),"0") -> 0 | P71: =IF(P17="X",(D17-C17),"0") -> 2 | Q71: =IF(Q17="X",(D17-C17),"0") -> 0 | R71: =IF(R17="X",(D17-C17),"0") -> 0 | S71: =IF(S17="X",(D17-C17),"0") -> 2 | T71: =IF(T17="X",(D17-C17),"0") -> 0
E72: =IF(E18="X",(D18-C18),"0") -> 0 | F72: =IF(F18="X",(D18-C18),"0") -> 2.8 | G72: =IF(G18="X",(D18-C18),"0") -> 0 | H72: =IF(H18="X",(D18-C18),"0") -> 0 | I72: =IF(I18="X",(D18-C18),"0") -> 0 | J72: =IF(J18="X",(D18-C18),"0") -> 2.8 | K72: =IF(K18="X",(D18-C18),"0") -> 0 | L72: =IF(L18="X",(D18-C18),"0") -> 0 | M72: =IF(M18="X",(D18-C18),"0") -> 2.8 | N72: =IF(N18="X",(D18-C18),"0") -> 0 | O72: =IF(O18="X",(D18-C18),"0") -> 0 | P72: =IF(P18="X",(D18-C18),"0") -> 2.8 | Q72: =IF(Q18="X",(D18-C18),"0") -> 0 | R72: =IF(R18="X",(D18-C18),"0") -> 0 | S72: =IF(S18="X",(D18-C18),"0") -> 2.8 | T72: =IF(T18="X",(D18-C18),"0") -> 0
... E112: =IF(E58="X",(D58-C58),"0") -> 0 | F112: =IF(F58="X",(D58-C58),"0") -> 0 | G112: =IF(G58="X",(D58-C58),"0") -> 0 | H112: =IF(H58="X",(D58-C58),"0") -> 0 | I112: =IF(I58="X",(D58-C58),"0") -> 0 | J112: =IF(J58="X",(D58-C58),"0") -> 0 | K112: =IF(K58="X",(D58-C58),"0") -> 0 | L112: =IF(L58="X",(D58-C58),"0") -> 0 | M112: =IF(M58="X",(D58-C58),"0") -> 0 | N112: =IF(N58="X",(D58-C58),"0") -> 0 | O112: =IF(O58="X",(D58-C58),"0") -> 0 | P112: =IF(P58="X",(D58-C58),"0") -> 0 | Q112: =IF(Q58="X",(D58-C58),"0") -> 0 | R112: =IF(R58="X",(D58-C58),"0") -> 0 | S112: =IF(S58="X",(D58-C58),"0") -> 0 | T112: =IF(T58="X",(D58-C58),"0") -> 0
E113: =SUM(E61:E112) -> 6.3 | F113: =SUM(F61:F112) -> 47.69 | G113: =SUM(G61:G112) -> 12.93 | H113: =SUM(H61:H112) -> 19.8 | I113: =SUM(I61:I112) -> 0 | J113: =SUM(J61:J112) -> 64.92 | K113: =SUM(K61:K112) -> 0 | L113: =SUM(L61:L112) -> 0 | ... T113: =SUM(T61:T112) -> 3.13

Sheet 209
A1: PROGRAMA DE MANUTENÇÃO RODOVIÁRIA
D2: RODOVIAS PAVIMENTADAS | I2: DATA: | J2: ='202'!J2 -> 46204 | N2: TÉCNICO RESP. | O2: ='202'!O2 -> ENG. THIAGO TORQUATO
A3: FICHA DE INSPEÇÃO: | B3: =TT!C9 -> RODOVIA TO-181 - TRECHO FAZENDA COBRAPE - ENTR. BR-242 | Q3: REGIÃO: | S3: 11
A5: S.R.E. | B5: SENTIDO | C5: INÍCIO (KM) | D5: FIM (KM) | E5: CONDIÇÃO DO PAVIMENTO | J5: VEGETAÇÃO | L5: ELEM. DE DRENAGEM | O5: SIN. HOR. | R5: SIN. VERTICAL | U5: OBSERV.
E6: BOM | F6: REM. I. | G6: REM. L | H6: BUR. I | I6: BUR. L | J6: ADEQ. | K6: INADED. | L6: LIMPOS | M6: SUJOS | N6: DAN. | O6: BOM | P6: REG. | Q6: INEXIST. | R6: BOM | S6: POUCAS | T6: INEXIST.
A7: 181ETO0110 | B7: C | C7: 0 | D7: 3 | G7: X | J7: X | M7: X | Q7: X | T7: X
C8: =D7 -> 3 | D8: 4.5 | F8: X | H8: X | J8: X | M8: X | Q8: X | T8: X
C9: =D8 -> 4.5 | D9: 6 | G9: X | H9: X | J9: X | M9: X | Q9: X | T9: X
C10: =D9 -> 6 | D10: 8.5 | F10: X | H10: X | J10: X | M10: X | Q10: X | T10: X
A11: 181ETO0120 | B11: C | C11: =D10 -> 8.5 | D11: 10.5 | G11: X | J11: X | M11: X | P11: X | T11: X
C12: =D11 -> 10.5 | D12: 12 | F12: X | J12: X | M12: X | P12: X | T12: X
C13: =D12 -> 12 | D13: 16 | G13: X | I13: X | J13: X | M13: X | P13: X | T13: X
C14: =D13 -> 16 | D14: 17 | G14: X | J14: X | L14: X | P14: X | T14: X
C15: =D14 -> 17 | D15: 18.31 | G15: X | J15: X | L15: X | P15: X | T15: X
A16: 181ETO0120 | B16: C | C16: 0 | D16: 6.6 | G16: X | J16: X | L16: X | P16: X | T16: X
C17: =D16 -> 6.6 | D17: 17.36 | G17: X | J17: X | L17: X | P17: X | T17: X
L18: X
A32: LEGENDA | B32: CONDIÇÃO DO PAVIMENTO
A33: REM. I | B33: REMENDOS ISOLADOS | E33: ATÉ 10 REMENDOS/KM | I33: BUR. I | J33: BURACOS ISOLADOS | M33: ATÉ 5 BURACOS/KM
A34: REM. L | B34: REMENDOS AO LONGO | E34: MAIS DE 10 REMENDOS/KM | I34: BUR. L | J34: BURACOS AO LONGO | M34: MAIS DE 5 BURACOS/KM
E39: =IF(E7="X",(D7-C7),"0") -> 0 | F39: =IF(F7="X",(D7-C7),"0") -> 0 | G39: =IF(G7="X",(D7-C7),"0") -> 3 | H39: =IF(H7="X",(D7-C7),"0") -> 0 | I39: =IF(I7="X",(D7-C7),"0") -> 0 | J39: =IF(J7="X",(D7-C7),"0") -> 3 | K39: =IF(K7="X",(D7-C7),"0") -> 0 | L39: =IF(L7="X",(D7-C7),"0") -> 0 | M39: =IF(M7="X",(D7-C7),"0") -> 3 | N39: =IF(N7="X",(D7-C7),"0") -> 0 | O39: =IF(O7="X",(D7-C7),"0") -> 0 | P39: =IF(P7="X",(D7-C7),"0") -> 0 | Q39: =IF(Q7="X",(D7-C7),"0") -> 3 | R39: =IF(R7="X",(D7-C7),"0") -> 0 | S39: =IF(S7="X",(D7-C7),"0") -> 0 | T39: =IF(T7="X",(D7-C7),"0") -> 3
E40: =IF(E8="X",(D8-C8),"0") -> 0 | F40: =IF(F8="X",(D8-C8),"0") -> 1.5 | G40: =IF(G8="X",(D8-C8),"0") -> 0 | H40: =IF(H8="X",(D8-C8),"0") -> 1.5 | I40: =IF(I8="X",(D8-C8),"0") -> 0 | J40: =IF(J8="X",(D8-C8),"0") -> 1.5 | K40: =IF(K8="X",(D8-C8),"0") -> 0 | L40: =IF(L8="X",(D8-C8),"0") -> 0 | M40: =IF(M8="X",(D8-C8),"0") -> 1.5 | N40: =IF(N8="X",(D8-C8),"0") -> 0 | O40: =IF(O8="X",(D8-C8),"0") -> 0 | P40: =IF(P8="X",(D8-C8),"0") -> 0 | Q40: =IF(Q8="X",(D8-C8),"0") -> 1.5 | R40: =IF(R8="X",(D8-C8),"0") -> 0 | S40: =IF(S8="X",(D8-C8),"0") -> 0 | T40: =IF(T8="X",(D8-C8),"0") -> 1.5
E41: =IF(E9="X",(D9-C9),"0") -> 0 | F41: =IF(F9="X",(D9-C9),"0") -> 0 | G41: =IF(G9="X",(D9-C9),"0") -> 1.5 | H41: =IF(H9="X",(D9-C9),"0") -> 1.5 | I41: =IF(I9="X",(D9-C9),"0") -> 0 | J41: =IF(J9="X",(D9-C9),"0") -> 1.5 | K41: =IF(K9="X",(D9-C9),"0") -> 0 | L41: =IF(L9="X",(D9-C9),"0") -> 0 | M41: =IF(M9="X",(D9-C9),"0") -> 1.5 | N41: =IF(N9="X",(D9-C9),"0") -> 0 | O41: =IF(O9="X",(D9-C9),"0") -> 0 | P41: =IF(P9="X",(D9-C9),"0") -> 0 | Q41: =IF(Q9="X",(D9-C9),"0") -> 1.5 | R41: =IF(R9="X",(D9-C9),"0") -> 0 | S41: =IF(S9="X",(D9-C9),"0") -> 0 | T41: =IF(T9="X",(D9-C9),"0") -> 1.5
E42: =IF(E10="X",(D10-C10),"0") -> 0 | F42: =IF(F10="X",(D10-C10),"0") -> 2.5 | G42: =IF(G10="X",(D10-C10),"0") -> 0 | H42: =IF(H10="X",(D10-C10),"0") -> 2.5 | I42: =IF(I10="X",(D10-C10),"0") -> 0 | J42: =IF(J10="X",(D10-C10),"0") -> 2.5 | K42: =IF(K10="X",(D10-C10),"0") -> 0 | L42: =IF(L10="X",(D10-C10),"0") -> 0 | M42: =IF(M10="X",(D10-C10),"0") -> 2.5 | N42: =IF(N10="X",(D10-C10),"0") -> 0 | O42: =IF(O10="X",(D10-C10),"0") -> 0 | P42: =IF(P10="X",(D10-C10),"0") -> 0 | Q42: =IF(Q10="X",(D10-C10),"0") -> 2.5 | R42: =IF(R10="X",(D10-C10),"0") -> 0 | S42: =IF(S10="X",(D10-C10),"0") -> 0 | T42: =IF(T10="X",(D10-C10),"0") -> 2.5
E43: =IF(E11="X",(D11-C11),"0") -> 0 | F43: =IF(F11="X",(D11-C11),"0") -> 0 | G43: =IF(G11="X",(D11-C11),"0") -> 2 | H43: =IF(H11="X",(D11-C11),"0") -> 0 | I43: =IF(I11="X",(D11-C11),"0") -> 0 | J43: =IF(J11="X",(D11-C11),"0") -> 2 | K43: =IF(K11="X",(D11-C11),"0") -> 0 | L43: =IF(L11="X",(D11-C11),"0") -> 0 | M43: =IF(M11="X",(D11-C11),"0") -> 2 | N43: =IF(N11="X",(D11-C11),"0") -> 0 | O43: =IF(O11="X",(D11-C11),"0") -> 0 | P43: =IF(P11="X",(D11-C11),"0") -> 2 | Q43: =IF(Q11="X",(D11-C11),"0") -> 0 | R43: =IF(R11="X",(D11-C11),"0") -> 0 | S43: =IF(S11="X",(D11-C11),"0") -> 0 | T43: =IF(T11="X",(D11-C11),"0") -> 2
E44: =IF(E12="X",(D12-C12),"0") -> 0 | F44: =IF(F12="X",(D12-C12),"0") -> 1.5 | G44: =IF(G12="X",(D12-C12),"0") -> 0 | H44: =IF(H12="X",(D12-C12),"0") -> 0 | I44: =IF(I12="X",(D12-C12),"0") -> 0 | J44: =IF(J12="X",(D12-C12),"0") -> 1.5 | K44: =IF(K12="X",(D12-C12),"0") -> 0 | L44: =IF(L12="X",(D12-C12),"0") -> 0 | M44: =IF(M12="X",(D12-C12),"0") -> 1.5 | N44: =IF(N12="X",(D12-C12),"0") -> 0 | O44: =IF(O12="X",(D12-C12),"0") -> 0 | P44: =IF(P12="X",(D12-C12),"0") -> 1.5 | Q44: =IF(Q12="X",(D12-C12),"0") -> 0 | R44: =IF(R12="X",(D12-C12),"0") -> 0 | S44: =IF(S12="X",(D12-C12),"0") -> 0 | T44: =IF(T12="X",(D12-C12),"0") -> 1.5
E45: =IF(E13="X",(D13-C13),"0") -> 0 | F45: =IF(F13="X",(D13-C13),"0") -> 0 | G45: =IF(G13="X",(D13-C13),"0") -> 4 | H45: =IF(H13="X",(D13-C13),"0") -> 0 | I45: =IF(I13="X",(D13-C13),"0") -> 4 | J45: =IF(J13="X",(D13-C13),"0") -> 4 | K45: =IF(K13="X",(D13-C13),"0") -> 0 | L45: =IF(L13="X",(D13-C13),"0") -> 0 | M45: =IF(M13="X",(D13-C13),"0") -> 4 | N45: =IF(N13="X",(D13-C13),"0") -> 0 | O45: =IF(O13="X",(D13-C13),"0") -> 0 | P45: =IF(P13="X",(D13-C13),"0") -> 4 | Q45: =IF(Q13="X",(D13-C13),"0") -> 0 | R45: =IF(R13="X",(D13-C13),"0") -> 0 | S45: =IF(S13="X",(D13-C13),"0") -> 0 | T45: =IF(T13="X",(D13-C13),"0") -> 4
E46: =IF(E14="X",(D14-C14),"0") -> 0 | F46: =IF(F14="X",(D14-C14),"0") -> 0 | G46: =IF(G14="X",(D14-C14),"0") -> 1 | H46: =IF(H14="X",(D14-C14),"0") -> 0 | I46: =IF(I14="X",(D14-C14),"0") -> 0 | J46: =IF(J14="X",(D14-C14),"0") -> 1 | K46: =IF(K14="X",(D14-C14),"0") -> 0 | L46: =IF(L14="X",(D14-C14),"0") -> 1 | M46: =IF(M14="X",(D14-C14),"0") -> 0 | N46: =IF(N14="X",(D14-C14),"0") -> 0 | O46: =IF(O14="X",(D14-C14),"0") -> 0 | P46: =IF(P14="X",(D14-C14),"0") -> 1 | Q46: =IF(Q14="X",(D14-C14),"0") -> 0 | R46: =IF(R14="X",(D14-C14),"0") -> 0 | S46: =IF(S14="X",(D14-C14),"0") -> 0 | T46: =IF(T14="X",(D14-C14),"0") -> 1
E47: =IF(E15="X",(D15-C15),"0") -> 0 | F47: =IF(F15="X",(D15-C15),"0") -> 0 | G47: =IF(G15="X",(D15-C15),"0") -> 1.31 | H47: =IF(H15="X",(D15-C15),"0") -> 0 | I47: =IF(I15="X",(D15-C15),"0") -> 0 | J47: =IF(J15="X",(D15-C15),"0") -> 1.31 | K47: =IF(K15="X",(D15-C15),"0") -> 0 | L47: =IF(L15="X",(D15-C15),"0") -> 1.31 | M47: =IF(M15="X",(D15-C15),"0") -> 0 | N47: =IF(N15="X",(D15-C15),"0") -> 0 | O47: =IF(O15="X",(D15-C15),"0") -> 0 | P47: =IF(P15="X",(D15-C15),"0") -> 1.31 | Q47: =IF(Q15="X",(D15-C15),"0") -> 0 | R47: =IF(R15="X",(D15-C15),"0") -> 0 | S47: =IF(S15="X",(D15-C15),"0") -> 0 | T47: =IF(T15="X",(D15-C15),"0") -> 1.31
E48: =IF(E16="X",(D16-C16),"0") -> 0 | F48: =IF(F16="X",(D16-C16),"0") -> 0 | G48: =IF(G16="X",(D16-C16),"0") -> 6.6 | H48: =IF(H16="X",(D16-C16),"0") -> 0 | I48: =IF(I16="X",(D16-C16),"0") -> 0 | J48: =IF(J16="X",(D16-C16),"0") -> 6.6 | K48: =IF(K16="X",(D16-C16),"0") -> 0 | L48: =IF(L16="X",(D16-C16),"0") -> 6.6 | M48: =IF(M16="X",(D16-C16),"0") -> 0 | N48: =IF(N16="X",(D16-C16),"0") -> 0 | O48: =IF(O16="X",(D16-C16),"0") -> 0 | P48: =IF(P16="X",(D16-C16),"0") -> 6.6 | Q48: =IF(Q16="X",(D16-C16),"0") -> 0 | R48: =IF(R16="X",(D16-C16),"0") -> 0 | S48: =IF(S16="X",(D16-C16),"0") -> 0 | T48: =IF(T16="X",(D16-C16),"0") -> 6.6
E49: =IF(E17="X",(D17-C17),"0") -> 0 | F49: =IF(F17="X",(D17-C17),"0") -> 0 | G49: =IF(G17="X",(D17-C17),"0") -> 10.76 | H49: =IF(H17="X",(D17-C17),"0") -> 0 | I49: =IF(I17="X",(D17-C17),"0") -> 0 | J49: =IF(J17="X",(D17-C17),"0") -> 10.76 | K49: =IF(K17="X",(D17-C17),"0") -> 0 | L49: =IF(L17="X",(D17-C17),"0") -> 10.76 | M49: =IF(M17="X",(D17-C17),"0") -> 0 | N49: =IF(N17="X",(D17-C17),"0") -> 0 | O49: =IF(O17="X",(D17-C17),"0") -> 0 | P49: =IF(P17="X",(D17-C17),"0") -> 10.76 | Q49: =IF(Q17="X",(D17-C17),"0") -> 0 | R49: =IF(R17="X",(D17-C17),"0") -> 0 | S49: =IF(S17="X",(D17-C17),"0") -> 0 | T49: =IF(T17="X",(D17-C17),"0") -> 10.76
E50: =IF(E18="X",(D18-C18),"0") -> 0 | F50: =IF(F18="X",(D18-C18),"0") -> 0 | G50: =IF(G18="X",(D18-C18),"0") -> 0 | H50: =IF(H18="X",(D18-C18),"0") -> 0 | I50: =IF(I18="X",(D18-C18),"0") -> 0 | J50: =IF(J18="X",(D18-C18),"0") -> 0 | K50: =IF(K18="X",(D18-C18),"0") -> 0 | L50: =IF(L18="X",(D18-C18),"0") -> 0 | M50: =IF(M18="X",(D18-C18),"0") -> 0 | N50: =IF(N18="X",(D18-C18),"0") -> 0 | O50: =IF(O18="X",(D18-C18),"0") -> 0 | P50: =IF(P18="X",(D18-C18),"0") -> 0 | Q50: =IF(Q18="X",(D18-C18),"0") -> 0 | R50: =IF(R18="X",(D18-C18),"0") -> 0 | S50: =IF(S18="X",(D18-C18),"0") -> 0 | T50: =IF(T18="X",(D18-C18),"0") -> 0
... E59: =IF(E27="X",(D27-C27),"0") -> 0 | F59: =IF(F27="X",(D27-C27),"0") -> 0 | G59: =IF(G27="X",(D27-C27),"0") -> 0 | H59: =IF(H27="X",(D27-C27),"0") -> 0 | I59: =IF(I27="X",(D27-C27),"0") -> 0 | J59: =IF(J27="X",(D27-C27),"0") -> 0 | K59: =IF(K27="X",(D27-C27),"0") -> 0 | L59: =IF(L27="X",(D27-C27),"0") -> 0 | M59: =IF(M27="X",(D27-C27),"0") -> 0 | N59: =IF(N27="X",(D27-C27),"0") -> 0 | O59: =IF(O27="X",(D27-C27),"0") -> 0 | P59: =IF(P27="X",(D27-C27),"0") -> 0 | Q59: =IF(Q27="X",(D27-C27),"0") -> 0 | R59: =IF(R27="X",(D27-C27),"0") -> 0 | S59: =IF(S27="X",(D27-C27),"0") -> 0 | T59: =IF(T27="X",(D27-C27),"0") -> 0
E128: =SUM(E39:E126) -> 0 | F128: =SUM(F39:F126) -> 5.5 | G128: =SUM(G39:G126) -> 30.17 | H128: =SUM(H39:H126) -> 5.5 | I128: =SUM(I39:I126) -> 4 | J128: =SUM(J39:J126) -> 35.67 | K128: =SUM(K39:K126) -> 0 | L128: =SUM(L39:L126) -> 19.67 | ... T128: =SUM(T39:T126) -> 35.67

Sheet 210
A1: PROGRAMA DE MANUTENÇÃO RODOVIÁRIA
D2: RODOVIAS PAVIMENTADAS | F2: X | I2: DATA: | J2: ='202'!J2 -> 46204 | N2: TÉCNICO RESP. | O2: ='202'!O2 -> ENG. THIAGO TORQUATO
A3: FICHA DE INSPEÇÃO: | B3: =TT!C10 -> RODOVIA TO-181 - TRECHO ENTR. BR-242 - FUNDAÇÃO BRADESCO | Q3: REGIÃO: | S3: 11
A5: S.R.E. | B5: SENTIDO | C5: INÍCIO (KM) | D5: FIM (KM) | E5: CONDIÇÃO DO PAVIMENTO | J5: VEGETAÇÃO | L5: ELEM. DE DRENAGEM | O5: SIN. HOR. | R5: SIN. VERTICAL | U5: OBSERV.
E6: BOM | F6: REM. I. | G6: REM. L | H6: BUR. I | I6: BUR. L | J6: ADEQ. | K6: INADED. | L6: LIMPOS | M6: SUJOS | N6: DAN. | O6: BOM | P6: REG. | Q6: INEXIST. | R6: BOM | S6: POUCAS | T6: INEXIST.
A7: 181ETO0140 | B7: D | C7: 0 | D7: 1 | E7: X | G7: X | J7: X | L7: X | P7: X | R7: X
C8: 1 | D8: 8 | G8: X | J8: X | M8: X | N8: X | P8: X | T8: X
C9: 2 | D9: 11 | G9: X | J9: X | M9: X | N9: X | P9: X | T9: X
C10: 5 | D10: 14 | F10: X | J10: X | M10: X | N10: X | P10: X | T10: X
C11: 11.6 | D11: 26.16 | F11: X | J11: X | M11: X | N11: X | P11: X | S11: X
A32: LEGENDA | B32: CONDIÇÃO DO PAVIMENTO
A33: REM. I | B33: REMENDOS ISOLADOS | E33: ATÉ 10 REMENDOS/KM | I33: BUR. I | J33: BURACOS ISOLADOS | M33: ATÉ 5 BURACOS/KM
A34: REM. L | B34: REMENDOS AO LONGO | E34: MAIS DE 10 REMENDOS/KM | I34: BUR. L | J34: BURACOS AO LONGO | M34: MAIS DE 5 BURACOS/KM
E39: =IF(E7="X",(D7-C7),"0") -> 1 | F39: =IF(F7="X",(D7-C7),"0") -> 0 | G39: =IF(G7="X",(D7-C7),"0") -> 1 | H39: =IF(H7="X",(D7-C7),"0") -> 0 | I39: =IF(I7="X",(D7-C7),"0") -> 0 | J39: =IF(J7="X",(D7-C7),"0") -> 1 | K39: =IF(K7="X",(D7-C7),"0") -> 0 | L39: =IF(L7="X",(D7-C7),"0") -> 1 | M39: =IF(M7="X",(D7-C7),"0") -> 0 | N39: =IF(N7="X",(D7-C7),"0") -> 0 | O39: =IF(O7="X",(D7-C7),"0") -> 0 | P39: =IF(P7="X",(D7-C7),"0") -> 1 | Q39: =IF(Q7="X",(D7-C7),"0") -> 0 | R39: =IF(R7="X",(D7-C7),"0") -> 1 | S39: =IF(S7="X",(D7-C7),"0") -> 0 | T39: =IF(T7="X",(D7-C7),"0") -> 0
E40: =IF(E8="X",(D8-C8),"0") -> 0 | F40: =IF(F8="X",(D8-C8),"0") -> 0 | G40: =IF(G8="X",(D8-C8),"0") -> 7 | H40: =IF(H8="X",(D8-C8),"0") -> 0 | I40: =IF(I8="X",(D8-C8),"0") -> 0 | J40: =IF(J8="X",(D8-C8),"0") -> 7 | K40: =IF(K8="X",(D8-C8),"0") -> 0 | L40: =IF(L8="X",(D8-C8),"0") -> 0 | M40: =IF(M8="X",(D8-C8),"0") -> 7 | N40: =IF(N8="X",(D8-C8),"0") -> 7 | O40: =IF(O8="X",(D8-C8),"0") -> 0 | P40: =IF(P8="X",(D8-C8),"0") -> 7 | Q40: =IF(Q8="X",(D8-C8),"0") -> 0 | R40: =IF(R8="X",(D8-C8),"0") -> 0 | S40: =IF(S8="X",(D8-C8),"0") -> 0 | T40: =IF(T8="X",(D8-C8),"0") -> 7
E41: =IF(E9="X",(D9-C9),"0") -> 0 | F41: =IF(F9="X",(D9-C9),"0") -> 0 | G41: =IF(G9="X",(D9-C9),"0") -> 9 | H41: =IF(H9="X",(D9-C9),"0") -> 0 | I41: =IF(I9="X",(D9-C9),"0") -> 0 | J41: =IF(J9="X",(D9-C9),"0") -> 9 | K41: =IF(K9="X",(D9-C9),"0") -> 0 | L41: =IF(L9="X",(D9-C9),"0") -> 0 | M41: =IF(M9="X",(D9-C9),"0") -> 9 | N41: =IF(N9="X",(D9-C9),"0") -> 9 | O41: =IF(O9="X",(D9-C9),"0") -> 0 | P41: =IF(P9="X",(D9-C9),"0") -> 9 | Q41: =IF(Q9="X",(D9-C9),"0") -> 0 | R41: =IF(R9="X",(D9-C9),"0") -> 0 | S41: =IF(S9="X",(D9-C9),"0") -> 0 | T41: =IF(T9="X",(D9-C9),"0") -> 9
