Workbook

Sheet Trechos
A1: RELAÇÃO DOS TRECHOS DAS REGIÕES DE MANUTENÇÃO
A2: LOTE | B2: N. | C2: TRECHO | D2: S.R.E | E2: SUBTRECHOS | F2: EXT. (KM) | G2: TIPO | H2: 45839 | I2: 45870 | J2: 45901 | K2: 45931 | L2: 45962 | M2: 45992
A3: 1 | B3: 1 | C3: RODOVIA TO-010 - TRECHO ANANÁS - ENTR. BR-230 | D3: 010ETO0511 | E3: ANANÁS *TRECHO URBANO* | F3: 0.87749259 | G3: PSU | H3: X
A4: 1 | B4: 1 | C4: RODOVIA TO-010 - TRECHO ANANÁS - ENTR. BR-230 | D4: 010ETO0512 | E4: ANANÁS *TRECHO URBANO* | F4: 1.9892583 | G4: PSU | H4: X
A5: 1 | B5: 1 | C5: RODOVIA TO-010 - TRECHO ANANÁS - ENTR. BR-230 | D5: 010ETO0540 | E5: ANANÁS *TRECHO URBANO* - ENTR. TO-414(TAPUIO) | F5: 3.8103285 | G5: PPS | H5: X | J5: X
A6: 1 | B6: 1 | C6: RODOVIA TO-010 - TRECHO ANANÁS - ENTR. BR-230 | D6: 010ETO0550 | E6: ENTR. TO-414 (TAPUIO) - ENTR. TO-210 | F6: 1.6653951 | G6: PPS | H6: X | J6: X
A7: 1 | B7: 1 | C7: RODOVIA TO-010 - TRECHO ANANÁS - ENTR. BR-230 | D7: 010ETO0555 | E7: ENTR. TO-210 - FIM PAVIMENTACAO | F7: 1.3552325 | G7: PPS | H7: X
A8: 1 | B8: 2 | C8: RODOVIA TO-010 - TRECHO ENTR. BR-230 - ARAGUATINS | D8: 010ETO0630 | E8: ENTR. BR-230 - TRANSARAGUAIA | F8: 1.0305988 | G8: PPS | H8: X | I8: X
A9: 1 | B9: 2 | C9: RODOVIA TO-010 - TRECHO ENTR. BR-230 - ARAGUATINS | D9: 010ETO0640 | E9: TRANSARAGUAIA (BR-230) - ARAGUATINS | F9: 8.6075719 | G9: PPS | H9: X | I9: X
A10: 1 | B10: 3 | C10: RODOVIA TO-010 - TRECHO ARAGUATINS - ENTR. TO-201 | D10: 010ETO0650 | E10: ARAGUATINS - ENTR. TO-404 | F10: 7.7551854 | G10: PPS | H10: X | I10: X
A11: 1 | B11: 3 | C11: RODOVIA TO-010 - TRECHO ARAGUATINS - ENTR. TO-201 | D11: 010ETO0665 | E11: ENTR. TO-404 - POV. CANAÃ | F11: 28.047221 | G11: PPS | H11: X | I11: X
A12: 1 | B12: 3 | C12: RODOVIA TO-010 - TRECHO ARAGUATINS - ENTR. TO-201 | D12: 010ETO0670 | E12: CANAÃ - VILA UNIÃO | F12: 2.8623319 | G12: PPS | H12: X | I12: X
A13: 1 | B13: 3 | C13: RODOVIA TO-010 - TRECHO ARAGUATINS - ENTR. TO-201 | D13: 010ETO0680 | E13: VILA UNIÃO - ENTR. TO-201 | F13: 2.9422716 | G13: PPS | H13: X | I13: X
A14: 1 | B14: 4 | C14: RODOVIA TO-010 - TRECHO BURITI DO TOCANTINS (ENTR. TO-201) - SÃO SEBASTIÃO DO TOCANTINS | D14: 010ETO0690 | E14: ENTR. TO-201 - BURITI DO TOCANTINS *TRECHO URBANO* | F14: 3.6607758 | G14: PPS | H14: X | I14: X
A15: 1 | B15: 4 | C15: RODOVIA TO-010 - TRECHO BURITI DO TOCANTINS (ENTR. TO-201) - SÃO SEBASTIÃO DO TOCANTINS | D15: 010ETO0710 | E15: BURITI DO TOCANTINS *TRECHO URBANO* - SÃO SEBASTIÃO DO TOCANTINS *TRECHO URBANO* | F15: 5.589158 | G15: PPS | H15: X | I15: X
A16: 1 | B16: 5 | C16: RODOVIA TO-126 - TRECHO TOCANTINÓPOLIS - ENTR. BR-230 (AGUIARNÓPOLIS) | D16: 126ETO0151 | E16: PERÍMETRO URBANO TOCANTINOPOLIS | F16: 1.8623358 | G16: PDU | H16: X | J16: X
A17: 1 | B17: 5 | C17: RODOVIA TO-126 - TRECHO TOCANTINÓPOLIS - ENTR. BR-230 (AGUIARNÓPOLIS) | D17: 126ETO0190 | E17: TOCANTINÓPOLIS *TRECHO URBANO* - ENTR. ACESSO TRIPA NORTE | F17: 22.489852 | G17: PPS | H17: X | J17: X
A18: 1 | B18: 5 | C18: RODOVIA TO-126 - TRECHO TOCANTINÓPOLIS - ENTR. BR-230 (AGUIARNÓPOLIS) | D18: 126ETO0200 | E18: ENTR. ACESSO TRIPA NORTE - ENTR. BR-230 | F18: 3.2344796 | G18: PPS | H18: X | J18: X
A19: 1 | B19: 5 | C19: RODOVIA TO-126 - TRECHO TOCANTINÓPOLIS - ENTR. BR-230 (AGUIARNÓPOLIS) | D19: ACESSO | E19: ENTR.TO-126 - ASA NORTE | F19: 2.6525119 | G19: PPS | H19: X | J19: X
A20: 1 | B20: 6 | C20: RODOVIA TO-126 - TRECHO MAURILÂNDIA - TOCANTINÓPOLIS | D20: 126ETO0140 | E20: RIBEIRÃO GRANDE - FOLHA GROSSA | F20: 5.5291153 | G20: PPS | H20: X | J20: X
A21: 1 | B21: 6 | C21: RODOVIA TO-126 - TRECHO MAURILÂNDIA - TOCANTINÓPOLIS | D21: 126ETO0150 | E21: FOLHA GROSSA - TOCANTINÓPOLIS *TRECHO URBANO* | F21: 2.9848124 | G21: PPS | H21: X | J21: X
A22: 1 | B22: 7 | C22: RODOVIA TO-126 - TRECHO ITAGUATINS - MAURILÂNDIA DO TOCANTINS | D22: 126ETO0101 | E22: PERÍMETRO URBANO ITAGUATINS | F22: 0.74066591 | G22: PSU | H22: X | J22: X
A23: 1 | B23: 7 | C23: RODOVIA TO-126 - TRECHO ITAGUATINS - MAURILÂNDIA DO TOCANTINS | D23: 126ETO0120 | E23: ITAGUATINS *TRECHO URBANO* - MAURILÃNDIA DO TOCANTINS *TRECHO URBANO* | F23: 20.919422 | G23: PPS | H23: X | J23: X
A24: 1 | B24: 8 | C24: RODOVIA TO-126 - TRECHO SÍTIO NOVO DO TOCANTINS - ITAGUATINS | D24: 126ETO0090 | E24: ENTR. TO-201(B)(SÍTIO NOVO DO TOCANTINS) - CASTANHEIRO | F24: 11.35543 | G24: PPS | H24: X | J24: X
A25: 1 | B25: 8 | C25: RODOVIA TO-126 - TRECHO SÍTIO NOVO DO TOCANTINS - ITAGUATINS | D25: 126ETO0100 | E25: CASTANHEIRO - ITAGUATINS *TRECHO URBANO* | F25: 14.021183 | G25: PPS | H25: X | J25: X
A26: 1 | B26: 9 | C26: RODOVIA TO-126 - TRECHO SUMAUMA - SÍTIO NOVO DO TOCANTINS | D26: 126ETO0050 | E26: SUMAUMA *TRECHO URBANO* - SÃO PEDRO | F26: 7.917381 | G26: PPS | H26: X | I26: X | J26: X
A27: 1 | B27: 9 | C27: RODOVIA TO-126 - TRECHO SUMAUMA - SÍTIO NOVO DO TOCANTINS | D27: 126ETO0060 | E27: SÃO PEDRO - ENTR. TO-201 | F27: 6.5761498 | G27: PPS | H27: X | I27: X | J27: X
A28: 1 | B28: 9 | C28: RODOVIA TO-126 - TRECHO SUMAUMA - SÍTIO NOVO DO TOCANTINS | D28: 126ETO0080 | E28: ENTR. TO-201(A) - ENTR. TO-201(B)(SÍTIO NOVO DO TOCANTINS) | F28: 2.1814371 | G28: PPS | H28: X | I28: X
A29: 1 | B29: 10 | C29: RODOVIA TO-134 - TRECHO ANGICO - DARCINÓPOLIS | D29: 134ETO0220 | E29: ENTR. TO-210 (ANGICO) - AMIGOS DA TERRA | F29: 31.59718 | G29: PPS | H29: X | I29: X
A30: 1 | B30: 10 | C30: RODOVIA TO-134 - TRECHO ANGICO - DARCINÓPOLIS | D30: 134ETO0230 | E30: AMIGOS DA TERRA - ENTR. BR-226(DARCINÓPOLIS) | F30: 13.750622 | G30: PPS | H30: X | I30: X
A31: 1 | B31: 11 | C31: RODOVIA TO-134 - TRECHO LUZINÓPOLIS - ANGICO | D31: 134ETO0180 | E31: ENTR. BR-230(LUZINÓPOLIS) - SANTA HELENA | F31: 9.8047447 | G31: PPS | H31: X | I31: X | J31: X
A32: 1 | B32: 11 | C32: RODOVIA TO-134 - TRECHO LUZINÓPOLIS - ANGICO | D32: 134ETO0190 | E32: SANTA HELENA - BURITI | F32: 3.6265271 | G32: PPS | H32: X | I32: X | J32: X
A33: 1 | B33: 11 | C33: RODOVIA TO-134 - TRECHO LUZINÓPOLIS - ANGICO | D33: 134ETO0200 | E33: BURITI - ENTR. TO-210 (GROTÃO DE NAZARÉ) | F33: 3.5926666 | G33: PPS | H33: X | I33: X | J33: X
A34: 1 | B34: 11 | C34: RODOVIA TO-134 - TRECHO LUZINÓPOLIS - ANGICO | D34: 134ETO0210 | E34: ENTR. TO-210 (GROTÃO DE NAZARE) - ENTR. TO-210 (ANGICO) | F34: 7.4162558 | G34: PPS | H34: X | I34: X | J34: X
A35: 1 | B35: 13 | C35: RODOVIA TO-134 - TRECHO AXIXÁ DO TOCANTINS - ENTR. BR-230 | D35: 134ETO0071 | E35: AXIXÁ DO TOCANTINS *TRECHO URBANO* | F35: 0.41740117 | G35: PSU | J35: X
A36: 1 | B36: 13 | C36: RODOVIA TO-134 - TRECHO AXIXÁ DO TOCANTINS - ENTR. BR-230 | D36: 134ETO0110 | E36: AXIXÁ DO TOCANTINS *TRECHO URBANO* - ENTR. TO-409 | F36: 41.676456 | G36: PPS | H36: X | J36: X
A37: 1 | B37: 13 | C37: RODOVIA TO-134 - TRECHO AXIXÁ DO TOCANTINS - ENTR. BR-230 | D37: 134ETO0120 | E37: ENTR. TO-409 - ENTR. BR-230 | F37: 4.1233136 | G37: PPS | H37: X | J37: X
A38: 1 | B38: 14 | C38: RODOVIA TO-201 - TRECHO DIV. TO-MA - SÃO MIGUEL DO TOCANTINS | D38: 201ETO0010 | E38: DIV. TO-MA(PONTE RIO TOCANTINS) - ACESSO BELA VISTA | F38: 6.620899 | G38: PPS | H38: X | I38: X | J38: X
A39: 1 | B39: 14 | C39: RODOVIA TO-201 - TRECHO DIV. TO-MA - SÃO MIGUEL DO TOCANTINS | D39: 201ETO0020 | E39: ACESSO BELA VISTA - SÃO MIGUEL DO TOCANTINS | F39: 3.3736173 | G39: PPS | H39: X | I39: X | J39: X
A40: 1 | B40: 14 | C40: RODOVIA TO-201 - TRECHO DIV. TO-MA - SÃO MIGUEL DO TOCANTINS | D40: ACESSO | E40: BELA VISTA (BALSA) - ENTR. TO-201 | F40: 5.9161416 | G40: PPS | H40: X | I40: X | J40: X
...

Sheet 1
A1: PROGRAMA DE MANUTENÇÃORODOVIÁRIA
D2: RODOVIAS PAVIMENTADAS | I2: DATA: | J2: 46174 | N2: TÉCNICO RESP. | O2: LABORATORISTA -Claudiomiro V.Lopes
A3: FICHA DE INSPEÇÃO: | B3: =TT!C4 -> RODOVIA TO-010 - TRECHO ANANÁS - ENTR. BR-230
A5: S.R.E. | B5: SENTIDO | C5: INÍCIO (KM) | D5: FIM (KM) | E5: CONDIÇÃO DO PAVIMENTO | J5: VEGETAÇÃO | L5: ELEM. DE DRENAGEM | O5: SIN. HOR. | R5: SIN. VERTICAL | U5: OBSERV.
E6: BOM | F6: REM. I. | G6: REM. L | H6: BUR. I | I6: BUR. L | J6: ADEQ. | K6: INADED. | L6: LIMPOS | M6: SUJOS | N6: DAN. | O6: BOM | P6: REG. | Q6: INEXIST. | R6: BOM | S6: POUCAS | T6: INEXIST.
A7: 403ETO0021 | B7: C | C7: 0 | D7: 1 | I7: X | K7: X | Q7: X | T7: X
C8: =D7 -> 1 | D8: 2 | I8: X | K8: X | Q8: X | T8: X
C9: =D8 -> 2 | D9: 3 | I9: X | K9: X | Q9: X | T9: X
C10: =D9 -> 3 | D10: 3.81 | I10: X | K10: X | Q10: X | T10: X
A11: 010ETO0550 | B11: C | C11: 0 | D11: 1 | K11: X | Q11: X | T11: X
C12: =D11 -> 1 | D12: 1.67 | I12: X | K12: X | Q12: X | T12: X
A13: 010ETO0555 | B13: C | C13: 0 | D13: 1.36 | G13: X | K13: X | N13: X | Q13: X | T13: X
A15: 010ETO0511 | B15: C | C15: 0 | D15: 0.88 | F15: X | M15: X | Q15: X | S15: X
A17: 010ETO0512 | B17: C | C17: 0 | D17: 1.99 | F17: X | M17: X | Q17: X | S17: X
A32: LEGENDA | B32: CONDIÇÃO DO PAVIMENTO
A33: REM. I | B33: REMENDOS ISOLADOS | E33: ATÉ 10 REMENDOS/KM | I33: BUR. I | J33: BURACOS ISOLADOS | M33: ATÉ 5 BURACOS/KM
A34: REM. L | B34: REMENDOS AO LONGO | E34: MAIS DE 10 REMENDOS/KM | I34: BUR. L | J34: BURACOS AO LONGO | M34: MAIS DE 5 BURACOS/KM
E39: =IF(E7="X",(D7-C7),"0") -> 0 | F39: =IF(F7="X",(D7-C7),"0") -> 0 | G39: =IF(G7="X",(D7-C7),"0") -> 0 | H39: =IF(H7="X",(D7-C7),"0") -> 0 | I39: =IF(I7="X",(D7-C7),"0") -> 1 | J39: =IF(J7="X",(D7-C7),"0") -> 0 | K39: =IF(K7="X",(D7-C7),"0") -> 1 | L39: =IF(L7="X",(D7-C7),"0") -> 0 | M39: =IF(M7="X",(D7-C7),"0") -> 0 | N39: =IF(N7="X",(D7-C7),"0") -> 0 | O39: =IF(O7="X",(D7-C7),"0") -> 0 | P39: =IF(P7="X",(D7-C7),"0") -> 0 | Q39: =IF(Q7="X",(D7-C7),"0") -> 1 | R39: =IF(R7="X",(D7-C7),"0") -> 0 | S39: =IF(S7="X",(D7-C7),"0") -> 0 | T39: =IF(T7="X",(D7-C7),"0") -> 1
E40: =IF(E8="X",(D8-C8),"0") -> 0 | F40: =IF(F8="X",(D8-C8),"0") -> 0 | G40: =IF(G8="X",(D8-C8),"0") -> 0 | H40: =IF(H8="X",(D8-C8),"0") -> 0 | I40: =IF(I8="X",(D8-C8),"0") -> 1 | J40: =IF(J8="X",(D8-C8),"0") -> 0 | K40: =IF(K8="X",(D8-C8),"0") -> 1 | L40: =IF(L8="X",(D8-C8),"0") -> 0 | M40: =IF(M8="X",(D8-C8),"0") -> 0 | N40: =IF(N8="X",(D8-C8),"0") -> 0 | O40: =IF(O8="X",(D8-C8),"0") -> 0 | P40: =IF(P8="X",(D8-C8),"0") -> 0 | Q40: =IF(Q8="X",(D8-C8),"0") -> 1 | R40: =IF(R8="X",(D8-C8),"0") -> 0 | S40: =IF(S8="X",(D8-C8),"0") -> 0 | T40: =IF(T8="X",(D8-C8),"0") -> 1
E41: =IF(E9="X",(D9-C9),"0") -> 0 | F41: =IF(F9="X",(D9-C9),"0") -> 0 | G41: =IF(G9="X",(D9-C9),"0") -> 0 | H41: =IF(H9="X",(D9-C9),"0") -> 0 | I41: =IF(I9="X",(D9-C9),"0") -> 1 | J41: =IF(J9="X",(D9-C9),"0") -> 0 | K41: =IF(K9="X",(D9-C9),"0") -> 1 | L41: =IF(L9="X",(D9-C9),"0") -> 0 | M41: =IF(M9="X",(D9-C9),"0") -> 0 | N41: =IF(N9="X",(D9-C9),"0") -> 0 | O41: =IF(O9="X",(D9-C9),"0") -> 0 | P41: =IF(P9="X",(D9-C9),"0") -> 0 | Q41: =IF(Q9="X",(D9-C9),"0") -> 1 | R41: =IF(R9="X",(D9-C9),"0") -> 0 | S41: =IF(S9="X",(D9-C9),"0") -> 0 | T41: =IF(T9="X",(D9-C9),"0") -> 1
E42: =IF(E10="X",(D10-C10),"0") -> 0 | F42: =IF(F10="X",(D10-C10),"0") -> 0 | G42: =IF(G10="X",(D10-C10),"0") -> 0 | H42: =IF(H10="X",(D10-C10),"0") -> 0 | I42: =IF(I10="X",(D10-C10),"0") -> 0.81 | J42: =IF(J10="X",(D10-C10),"0") -> 0 | K42: =IF(K10="X",(D10-C10),"0") -> 0.81 | L42: =IF(L10="X",(D10-C10),"0") -> 0 | M42: =IF(M10="X",(D10-C10),"0") -> 0 | N42: =IF(N10="X",(D10-C10),"0") -> 0 | O42: =IF(O10="X",(D10-C10),"0") -> 0 | P42: =IF(P10="X",(D10-C10),"0") -> 0 | Q42: =IF(Q10="X",(D10-C10),"0") -> 0.81 | R42: =IF(R10="X",(D10-C10),"0") -> 0 | S42: =IF(S10="X",(D10-C10),"0") -> 0 | T42: =IF(T10="X",(D10-C10),"0") -> 0.81
E43: =IF(E11="X",(D11-C11),"0") -> 0 | F43: =IF(F11="X",(D11-C11),"0") -> 0 | G43: =IF(G11="X",(D11-C11),"0") -> 0 | H43: =IF(H11="X",(D11-C11),"0") -> 0 | I43: =IF(I11="X",(D11-C11),"0") -> 0 | J43: =IF(J11="X",(D11-C11),"0") -> 0 | K43: =IF(K11="X",(D11-C11),"0") -> 1 | L43: =IF(L11="X",(D11-C11),"0") -> 0 | M43: =IF(M11="X",(D11-C11),"0") -> 0 | N43: =IF(N11="X",(D11-C11),"0") -> 0 | O43: =IF(O11="X",(D11-C11),"0") -> 0 | P43: =IF(P11="X",(D11-C11),"0") -> 0 | Q43: =IF(Q11="X",(D11-C11),"0") -> 1 | R43: =IF(R11="X",(D11-C11),"0") -> 0 | S43: =IF(S11="X",(D11-C11),"0") -> 0 | T43: =IF(T11="X",(D11-C11),"0") -> 1
E44: =IF(E12="X",(D12-C12),"0") -> 0 | F44: =IF(F12="X",(D12-C12),"0") -> 0 | G44: =IF(G12="X",(D12-C12),"0") -> 0 | H44: =IF(H12="X",(D12-C12),"0") -> 0 | I44: =IF(I12="X",(D12-C12),"0") -> 0.67 | J44: =IF(J12="X",(D12-C12),"0") -> 0 | K44: =IF(K12="X",(D12-C12),"0") -> 0.67 | L44: =IF(L12="X",(D12-C12),"0") -> 0 | M44: =IF(M12="X",(D12-C12),"0") -> 0 | N44: =IF(N12="X",(D12-C12),"0") -> 0 | O44: =IF(O12="X",(D12-C12),"0") -> 0 | P44: =IF(P12="X",(D12-C12),"0") -> 0 | Q44: =IF(Q12="X",(D12-C12),"0") -> 0.67 | R44: =IF(R12="X",(D12-C12),"0") -> 0 | S44: =IF(S12="X",(D12-C12),"0") -> 0 | T44: =IF(T12="X",(D12-C12),"0") -> 0.67
E45: =IF(E13="X",(D13-C13),"0") -> 0 | F45: =IF(F13="X",(D13-C13),"0") -> 0 | G45: =IF(G13="X",(D13-C13),"0") -> 1.36 | H45: =IF(H13="X",(D13-C13),"0") -> 0 | I45: =IF(I13="X",(D13-C13),"0") -> 0 | J45: =IF(J13="X",(D13-C13),"0") -> 0 | K45: =IF(K13="X",(D13-C13),"0") -> 1.36 | L45: =IF(L13="X",(D13-C13),"0") -> 0 | M45: =IF(M13="X",(D13-C13),"0") -> 0 | N45: =IF(N13="X",(D13-C13),"0") -> 1.36 | O45: =IF(O13="X",(D13-C13),"0") -> 0 | P45: =IF(P13="X",(D13-C13),"0") -> 0 | Q45: =IF(Q13="X",(D13-C13),"0") -> 1.36 | R45: =IF(R13="X",(D13-C13),"0") -> 0 | S45: =IF(S13="X",(D13-C13),"0") -> 0 | T45: =IF(T13="X",(D13-C13),"0") -> 1.36
E46: =IF(E14="X",(D14-C14),"0") -> 0 | F46: =IF(F14="X",(D14-C14),"0") -> 0 | G46: =IF(G14="X",(D14-C14),"0") -> 0 | H46: =IF(H14="X",(D14-C14),"0") -> 0 | I46: =IF(I14="X",(D14-C14),"0") -> 0 | J46: =IF(J14="X",(D14-C14),"0") -> 0 | K46: =IF(K14="X",(D14-C14),"0") -> 0 | L46: =IF(L14="X",(D14-C14),"0") -> 0 | M46: =IF(M14="X",(D14-C14),"0") -> 0 | N46: =IF(N14="X",(D14-C14),"0") -> 0 | O46: =IF(O14="X",(D14-C14),"0") -> 0 | P46: =IF(P14="X",(D14-C14),"0") -> 0 | Q46: =IF(Q14="X",(D14-C14),"0") -> 0 | R46: =IF(R14="X",(D14-C14),"0") -> 0 | S46: =IF(S14="X",(D14-C14),"0") -> 0 | T46: =IF(T14="X",(D14-C14),"0") -> 0
E47: =IF(E15="X",(D15-C15),"0") -> 0 | F47: =IF(F15="X",(D15-C15),"0") -> 0.88 | G47: =IF(G15="X",(D15-C15),"0") -> 0 | H47: =IF(H15="X",(D15-C15),"0") -> 0 | I47: =IF(I15="X",(D15-C15),"0") -> 0 | J47: =IF(J15="X",(D15-C15),"0") -> 0 | K47: =IF(K15="X",(D15-C15),"0") -> 0 | L47: =IF(L15="X",(D15-C15),"0") -> 0 | M47: =IF(M15="X",(D15-C15),"0") -> 0.88 | N47: =IF(N15="X",(D15-C15),"0") -> 0 | O47: =IF(O15="X",(D15-C15),"0") -> 0 | P47: =IF(P15="X",(D15-C15),"0") -> 0 | Q47: =IF(Q15="X",(D15-C15),"0") -> 0.88 | R47: =IF(R15="X",(D15-C15),"0") -> 0 | S47: =IF(S15="X",(D15-C15),"0") -> 0.88 | T47: =IF(T15="X",(D15-C15),"0") -> 0
E48: =IF(E16="X",(D16-C16),"0") -> 0 | F48: =IF(F16="X",(D16-C16),"0") -> 0 | G48: =IF(G16="X",(D16-C16),"0") -> 0 | H48: =IF(H16="X",(D16-C16),"0") -> 0 | I48: =IF(I16="X",(D16-C16),"0") -> 0 | J48: =IF(J16="X",(D16-C16),"0") -> 0 | K48: =IF(K16="X",(D16-C16),"0") -> 0 | L48: =IF(L16="X",(D16-C16),"0") -> 0 | M48: =IF(M16="X",(D16-C16),"0") -> 0 | N48: =IF(N16="X",(D16-C16),"0") -> 0 | O48: =IF(O16="X",(D16-C16),"0") -> 0 | P48: =IF(P16="X",(D16-C16),"0") -> 0 | Q48: =IF(Q16="X",(D16-C16),"0") -> 0 | R48: =IF(R16="X",(D16-C16),"0") -> 0 | S48: =IF(S16="X",(D16-C16),"0") -> 0 | T48: =IF(T16="X",(D16-C16),"0") -> 0
E49: =IF(E17="X",(D17-C17),"0") -> 0 | F49: =IF(F17="X",(D17-C17),"0") -> 1.99 | G49: =IF(G17="X",(D17-C17),"0") -> 0 | H49: =IF(H17="X",(D17-C17),"0") -> 0 | I49: =IF(I17="X",(D17-C17),"0") -> 0 | J49: =IF(J17="X",(D17-C17),"0") -> 0 | K49: =IF(K17="X",(D17-C17),"0") -> 0 | L49: =IF(L17="X",(D17-C17),"0") -> 0 | M49: =IF(M17="X",(D17-C17),"0") -> 1.99 | N49: =IF(N17="X",(D17-C17),"0") -> 0 | O49: =IF(O17="X",(D17-C17),"0") -> 0 | P49: =IF(P17="X",(D17-C17),"0") -> 0 | Q49: =IF(Q17="X",(D17-C17),"0") -> 1.99 | R49: =IF(R17="X",(D17-C17),"0") -> 0 | S49: =IF(S17="X",(D17-C17),"0") -> 1.99 | T49: =IF(T17="X",(D17-C17),"0") -> 0
E50: =IF(E18="X",(D18-C18),"0") -> 0 | F50: =IF(F18="X",(D18-C18),"0") -> 0 | G50: =IF(G18="X",(D18-C18),"0") -> 0 | H50: =IF(H18="X",(D18-C18),"0") -> 0 | I50: =IF(I18="X",(D18-C18),"0") -> 0 | J50: =IF(J18="X",(D18-C18),"0") -> 0 | K50: =IF(K18="X",(D18-C18),"0") -> 0 | L50: =IF(L18="X",(D18-C18),"0") -> 0 | M50: =IF(M18="X",(D18-C18),"0") -> 0 | N50: =IF(N18="X",(D18-C18),"0") -> 0 | O50: =IF(O18="X",(D18-C18),"0") -> 0 | P50: =IF(P18="X",(D18-C18),"0") -> 0 | Q50: =IF(Q18="X",(D18-C18),"0") -> 0 | R50: =IF(R18="X",(D18-C18),"0") -> 0 | S50: =IF(S18="X",(D18-C18),"0") -> 0 | T50: =IF(T18="X",(D18-C18),"0") -> 0
... E95: =IF(E63="X",(D63-C63),"0") -> 0 | F95: =IF(F63="X",(D63-C63),"0") -> 0 | G95: =IF(G63="X",(D63-C63),"0") -> 0 | H95: =IF(H63="X",(D63-C63),"0") -> 0 | I95: =IF(I63="X",(D63-C63),"0") -> 0 | J95: =IF(J63="X",(D63-C63),"0") -> 0 | K95: =IF(K63="X",(D63-C63),"0") -> 0 | L95: =IF(L63="X",(D63-C63),"0") -> 0 | M95: =IF(M63="X",(D63-C63),"0") -> 0 | N95: =IF(N63="X",(D63-C63),"0") -> 0 | O95: =IF(O63="X",(D63-C63),"0") -> 0 | P95: =IF(P63="X",(D63-C63),"0") -> 0 | Q95: =IF(Q63="X",(D63-C63),"0") -> 0 | R95: =IF(R63="X",(D63-C63),"0") -> 0 | S95: =IF(S63="X",(D63-C63),"0") -> 0 | T95: =IF(T63="X",(D63-C63),"0") -> 0
E98: =SUM(E39:E95) -> 0 | F98: =SUM(F39:F95) -> 2.87 | G98: =SUM(G39:G95) -> 1.36 | H98: =SUM(H39:H95) -> 0 | I98: =SUM(I39:I95) -> 4.48 | J98: =SUM(J39:J95) -> 0 | K98: =SUM(K39:K95) -> 6.84 | L98: =SUM(L39:L95) -> 0 | ... T98: =SUM(T39:T95) -> 6.84

Sheet 2
A1: PROGRAMA DE MANUTENÇÃORODOVIÁRIA
D2: RODOVIAS PAVIMENTADAS | I2: DATA: | J2: ='1'!$J$2 -> 46174 | N2: TÉCNICO RESP. | O2: ='1'!$O$2 -> LABORATORISTA -Claudiomiro V.Lopes
A3: FICHA DE INSPEÇÃO: | B3: =TT!C5 -> RODOVIA TO-010 - TRECHO ENTR. BR-230 - ARAGUATINS
A5: S.R.E. | B5: SENTIDO | C5: INÍCIO (KM) | D5: FIM (KM) | E5: CONDIÇÃO DO PAVIMENTO | J5: VEGETAÇÃO | L5: ELEM. DE DRENAGEM | O5: SIN. HOR. | R5: SIN. VERTICAL | U5: OBSERV.
E6: BOM | F6: REM. I. | G6: REM. L | H6: BUR. I | I6: BUR. L | J6: ADEQ. | K6: INADED. | L6: LIMPOS | M6: SUJOS | N6: DAN. | O6: BOM | P6: REG. | Q6: INEXIST. | R6: BOM | S6: POUCAS | T6: INEXIST.
A7: 010ET00630 | B7: C | C7: 0 | D7: 2 | E7: X | J7: X | M7: X | P7: X | S7: X
C8: 0 | D8: 2 | E8: X | J8: X | M8: X | Q8: X | S8: X
C9: 2 | D9: 4 | E9: X | J9: X | M9: X | P9: X | S9: X
C10: 2 | D10: 4 | G10: X | J10: X | M10: X | Q10: X | S10: X
C11: 4 | D11: 6 | E11: X | J11: X | M11: X | P11: X | S11: X
C12: 4 | D12: 6 | G12: X | J12: X | M12: X | Q12: X | S12: X
C13: 6 | D13: 7.5 | E13: X | J13: X | M13: X | P13: X | S13: X
C14: 6 | D14: 7.5 | E14: X | J14: X | M14: X | Q14: X | S14: X
C15: 6 | D15: 7 | H15: X | K15: X | L15: X | O15: X | R15: X
C16: 7 | D16: 8 | H16: X | K16: X | L16: X | O16: X | R16: X
C17: 8 | D17: 8.61 | E17: X | K17: X | L17: X | O17: X | R17: X
A32: LEGENDA | B32: CONDIÇÃO DO PAVIMENTO
A33: REM. I | B33: REMENDOS ISOLADOS | E33: ATÉ 10 REMENDOS/KM | I33: BUR. I | J33: BURACOS ISOLADOS | M33: ATÉ 5 BURACOS/KM
A34: REM. L | B34: REMENDOS AO LONGO | E34: MAIS DE 10 REMENDOS/KM | I34: BUR. L | J34: BURACOS AO LONGO | M34: MAIS DE 5 BURACOS/KM
E39: =IF(E7="X",(D7-C7),"0") -> 2 | F39: =IF(F7="X",(D7-C7),"0") -> 0 | G39: =IF(G7="X",(D7-C7),"0") -> 0 | H39: =IF(H7="X",(D7-C7),"0") -> 0 | I39: =IF(I7="X",(D7-C7),"0") -> 0 | J39: =IF(J7="X",(D7-C7),"0") -> 2 | K39: =IF(K7="X",(D7-C7),"0") -> 0 | L39: =IF(L7="X",(D7-C7),"0") -> 0 | M39: =IF(M7="X",(D7-C7),"0") -> 2 | N39: =IF(N7="X",(D7-C7),"0") -> 0 | O39: =IF(O7="X",(D7-C7),"0") -> 0 | P39: =IF(P7="X",(D7-C7),"0") -> 2 | Q39: =IF(Q7="X",(D7-C7),"0") -> 0 | R39: =IF(R7="X",(D7-C7),"0") -> 0 | S39: =IF(S7="X",(D7-C7),"0") -> 2 | T39: =IF(T7="X",(D7-C7),"0") -> 0
E40: =IF(E8="X",(D8-C8),"0") -> 2 | F40: =IF(F8="X",(D8-C8),"0") -> 0 | G40: =IF(G8="X",(D8-C8),"0") -> 0 | H40: =IF(H8="X",(D8-C8),"0") -> 0 | I40: =IF(I8="X",(D8-C8),"0") -> 0 | J40: =IF(J8="X",(D8-C8),"0") -> 2 | K40: =IF(K8="X",(D8-C8),"0") -> 0 | L40: =IF(L8="X",(D8-C8),"0") -> 0 | M40: =IF(M8="X",(D8-C8),"0") -> 2 | N40: =IF(N8="X",(D8-C8),"0") -> 0 | O40: =IF(O8="X",(D8-C8),"0") -> 0 | P40: =IF(P8="X",(D8-C8),"0") -> 0 | Q40: =IF(Q8="X",(D8-C8),"0") -> 2 | R40: =IF(R8="X",(D8-C8),"0") -> 0 | S40: =IF(S8="X",(D8-C8),"0") -> 2 | T40: =IF(T8="X",(D8-C8),"0") -> 0
E41: =IF(E9="X",(D9-C9),"0") -> 2 | F41: =IF(F9="X",(D9-C9),"0") -> 0 | G41: =IF(G9="X",(D9-C9),"0") -> 0 | H41: =IF(H9="X",(D9-C9),"0") -> 0 | I41: =IF(I9="X",(D9-C9),"0") -> 0 | J41: =IF(J9="X",(D9-C9),"0") -> 2 | K41: =IF(K9="X",(D9-C9),"0") -> 0 | L41: =IF(L9="X",(D9-C9),"0") -> 0 | M41: =IF(M9="X",(D9-C9),"0") -> 2 | N41: =IF(N9="X",(D9-C9),"0") -> 0 | O41: =IF(O9="X",(D9-C9),"0") -> 0 | P41: =IF(P9="X",(D9-C9),"0") -> 2 | Q41: =IF(Q9="X",(D9-C9),"0") -> 0 | R41: =IF(R9="X",(D9-C9),"0") -> 0 | S41: =IF(S9="X",(D9-C9),"0") -> 2 | T41: =IF(T9="X",(D9-C9),"0") -> 0
E42: =IF(E10="X",(D10-C10),"0") -> 0 | F42: =IF(F10="X",(D10-C10),"0") -> 0 | G42: =IF(G10="X",(D10-C10),"0") -> 2 | H42: =IF(H10="X",(D10-C10),"0") -> 0 | I42: =IF(I10="X",(D10-C10),"0") -> 0 | J42: =IF(J10="X",(D10-C10),"0") -> 2 | K42: =IF(K10="X",(D10-C10),"0") -> 0 | L42: =IF(L10="X",(D10-C10),"0") -> 0 | M42: =IF(M10="X",(D10-C10),"0") -> 2 | N42: =IF(N10="X",(D10-C10),"0") -> 0 | O42: =IF(O10="X",(D10-C10),"0") -> 0 | P42: =IF(P10="X",(D10-C10),"0") -> 0 | Q42: =IF(Q10="X",(D10-C10),"0") -> 2 | R42: =IF(R10="X",(D10-C10),"0") -> 0 | S42: =IF(S10="X",(D10-C10),"0") -> 2 | T42: =IF(T10="X",(D10-C10),"0") -> 0
E43: =IF(E11="X",(D11-C11),"0") -> 2 | F43: =IF(F11="X",(D11-C11),"0") -> 0 | G43: =IF(G11="X",(D11-C11),"0") -> 0 | H43: =IF(H11="X",(D11-C11),"0") -> 0 | I43: =IF(I11="X",(D11-C11),"0") -> 0 | J43: =IF(J11="X",(D11-C11),"0") -> 2 | K43: =IF(K11="X",(D11-C11),"0") -> 0 | L43: =IF(L11="X",(D11-C11),"0") -> 0 | M43: =IF(M11="X",(D11-C11),"0") -> 2 | N43: =IF(N11="X",(D11-C11),"0") -> 0 | O43: =IF(O11="X",(D11-C11),"0") -> 0 | P43: =IF(P11="X",(D11-C11),"0") -> 2 | Q43: =IF(Q11="X",(D11-C11),"0") -> 0 | R43: =IF(R11="X",(D11-C11),"0") -> 0 | S43: =IF(S11="X",(D11-C11),"0") -> 2 | T43: =IF(T11="X",(D11-C11),"0") -> 0
E44: =IF(E12="X",(D12-C12),"0") -> 0 | F44: =IF(F12="X",(D12-C12),"0") -> 0 | G44: =IF(G12="X",(D12-C12),"0") -> 2 | H44: =IF(H12="X",(D12-C12),"0") -> 0 | I44: =IF(I12="X",(D12-C12),"0") -> 0 | J44: =IF(J12="X",(D12-C12),"0") -> 2 | K44: =IF(K12="X",(D12-C12),"0") -> 0 | L44: =IF(L12="X",(D12-C12),"0") -> 0 | M44: =IF(M12="X",(D12-C12),"0") -> 2 | N44: =IF(N12="X",(D12-C12),"0") -> 0 | O44: =IF(O12="X",(D12-C12),"0") -> 0 | P44: =IF(P12="X",(D12-C12),"0") -> 0 | Q44: =IF(Q12="X",(D12-C12),"0") -> 2 | R44: =IF(R12="X",(D12-C12),"0") -> 0 | S44: =IF(S12="X",(D12-C12),"0") -> 2 | T44: =IF(T12="X",(D12-C12),"0") -> 0
E45: =IF(E13="X",(D13-C13),"0") -> 1.5 | F45: =IF(F13="X",(D13-C13),"0") -> 0 | G45: =IF(G13="X",(D13-C13),"0") -> 0 | H45: =IF(H13="X",(D13-C13),"0") -> 0 | I45: =IF(I13="X",(D13-C13),"0") -> 0 | J45: =IF(J13="X",(D13-C13),"0") -> 1.5 | K45: =IF(K13="X",(D13-C13),"0") -> 0 | L45: =IF(L13="X",(D13-C13),"0") -> 0 | M45: =IF(M13="X",(D13-C13),"0") -> 1.5 | N45: =IF(N13="X",(D13-C13),"0") -> 0 | O45: =IF(O13="X",(D13-C13),"0") -> 0 | P45: =IF(P13="X",(D13-C13),"0") -> 1.5 | Q45: =IF(Q13="X",(D13-C13),"0") -> 0 | R45: =IF(R13="X",(D13-C13),"0") -> 0 | S45: =IF(S13="X",(D13-C13),"0") -> 1.5 | T45: =IF(T13="X",(D13-C13),"0") -> 0
E46: =IF(E14="X",(D14-C14),"0") -> 1.5 | F46: =IF(F14="X",(D14-C14),"0") -> 0 | G46: =IF(G14="X",(D14-C14),"0") -> 0 | H46: =IF(H14="X",(D14-C14),"0") -> 0 | I46: =IF(I14="X",(D14-C14),"0") -> 0 | J46: =IF(J14="X",(D14-C14),"0") -> 1.5 | K46: =IF(K14="X",(D14-C14),"0") -> 0 | L46: =IF(L14="X",(D14-C14),"0") -> 0 | M46: =IF(M14="X",(D14-C14),"0") -> 1.5 | N46: =IF(N14="X",(D14-C14),"0") -> 0 | O46: =IF(O14="X",(D14-C14),"0") -> 0 | P46: =IF(P14="X",(D14-C14),"0") -> 0 | Q46: =IF(Q14="X",(D14-C14),"0") -> 1.5 | R46: =IF(R14="X",(D14-C14),"0") -> 0 | S46: =IF(S14="X",(D14-C14),"0") -> 1.5 | T46: =IF(T14="X",(D14-C14),"0") -> 0
E47: =IF(E15="X",(D15-C15),"0") -> 0 | F47: =IF(F15="X",(D15-C15),"0") -> 0 | G47: =IF(G15="X",(D15-C15),"0") -> 0 | H47: =IF(H15="X",(D15-C15),"0") -> 1 | I47: =IF(I15="X",(D15-C15),"0") -> 0 | J47: =IF(J15="X",(D15-C15),"0") -> 0 | K47: =IF(K15="X",(D15-C15),"0") -> 1 | L47: =IF(L15="X",(D15-C15),"0") -> 1 | M47: =IF(M15="X",(D15-C15),"0") -> 0 | N47: =IF(N15="X",(D15-C15),"0") -> 0 | O47: =IF(O15="X",(D15-C15),"0") -> 1 | P47: =IF(P15="X",(D15-C15),"0") -> 0 | Q47: =IF(Q15="X",(D15-C15),"0") -> 0 | R47: =IF(R15="X",(D15-C15),"0") -> 1 | S47: =IF(S15="X",(D15-C15),"0") -> 0 | T47: =IF(T15="X",(D15-C15),"0") -> 0
E48: =IF(E16="X",(D16-C16),"0") -> 0 | F48: =IF(F16="X",(D16-C16),"0") -> 0 | G48: =IF(G16="X",(D16-C16),"0") -> 0 | H48: =IF(H16="X",(D16-C16),"0") -> 1 | I48: =IF(I16="X",(D16-C16),"0") -> 0 | J48: =IF(J16="X",(D16-C16),"0") -> 0 | K48: =IF(K16="X",(D16-C16),"0") -> 1 | L48: =IF(L16="X",(D16-C16),"0") -> 1 | M48: =IF(M16="X",(D16-C16),"0") -> 0 | N48: =IF(N16="X",(D16-C16),"0") -> 0 | O48: =IF(O16="X",(D16-C16),"0") -> 1 | P48: =IF(P16="X",(D16-C16),"0") -> 0 | Q48: =IF(Q16="X",(D16-C16),"0") -> 0 | R48: =IF(R16="X",(D16-C16),"0") -> 1 | S48: =IF(S16="X",(D16-C16),"0") -> 0 | T48: =IF(T16="X",(D16-C16),"0") -> 0
E49: =IF(E17="X",(D17-C17),"0") -> 0.61 | F49: =IF(F17="X",(D17-C17),"0") -> 0 | G49: =IF(G17="X",(D17-C17),"0") -> 0 | H49: =IF(H17="X",(D17-C17),"0") -> 0 | I49: =IF(I17="X",(D17-C17),"0") -> 0 | J49: =IF(J17="X",(D17-C17),"0") -> 0 | K49: =IF(K17="X",(D17-C17),"0") -> 0.61 | L49: =IF(L17="X",(D17-C17),"0") -> 0.61 | M49: =IF(M17="X",(D17-C17),"0") -> 0 | N49: =IF(N17="X",(D17-C17),"0") -> 0 | O49: =IF(O17="X",(D17-C17),"0") -> 0.61 | P49: =IF(P17="X",(D17-C17),"0") -> 0 | Q49: =IF(Q17="X",(D17-C17),"0") -> 0 | R49: =IF(R17="X",(D17-C17),"0") -> 0.61 | S49: =IF(S17="X",(D17-C17),"0") -> 0 | T49: =IF(T17="X",(D17-C17),"0") -> 0
E50: =IF(E18="X",(D18-C18),"0") -> 0 | F50: =IF(F18="X",(D18-C18),"0") -> 0 | G50: =IF(G18="X",(D18-C18),"0") -> 0 | H50: =IF(H18="X",(D18-C18),"0") -> 0 | I50: =IF(I18="X",(D18-C18),"0") -> 0 | J50: =IF(J18="X",(D18-C18),"0") -> 0 | K50: =IF(K18="X",(D18-C18),"0") -> 0 | L50: =IF(L18="X",(D18-C18),"0") -> 0 | M50: =IF(M18="X",(D18-C18),"0") -> 0 | N50: =IF(N18="X",(D18-C18),"0") -> 0 | O50: =IF(O18="X",(D18-C18),"0") -> 0 | P50: =IF(P18="X",(D18-C18),"0") -> 0 | Q50: =IF(Q18="X",(D18-C18),"0") -> 0 | R50: =IF(R18="X",(D18-C18),"0") -> 0 | S50: =IF(S18="X",(D18-C18),"0") -> 0 | T50: =IF(T18="X",(D18-C18),"0") -> 0
... E69: =IF(E37="X",(D37-C37),"0") -> 0 | F69: =IF(F37="X",(D37-C37),"0") -> 0 | G69: =IF(G37="X",(D37-C37),"0") -> 0 | H69: =IF(H37="X",(D37-C37),"0") -> 0 | I69: =IF(I37="X",(D37-C37),"0") -> 0 | J69: =IF(J37="X",(D37-C37),"0") -> 0 | K69: =IF(K37="X",(D37-C37),"0") -> 0 | L69: =IF(L37="X",(D37-C37),"0") -> 0 | M69: =IF(M37="X",(D37-C37),"0") -> 0 | N69: =IF(N37="X",(D37-C37),"0") -> 0 | O69: =IF(O37="X",(D37-C37),"0") -> 0 | P69: =IF(P37="X",(D37-C37),"0") -> 0 | Q69: =IF(Q37="X",(D37-C37),"0") -> 0 | R69: =IF(R37="X",(D37-C37),"0") -> 0 | S69: =IF(S37="X",(D37-C37),"0") -> 0 | T69: =IF(T37="X",(D37-C37),"0") -> 0
E72: =SUM(E39:E69) -> 11.61 | F72: =SUM(F39:F69) -> 0 | G72: =SUM(G39:G69) -> 4 | H72: =SUM(H39:H69) -> 2 | I72: =SUM(I39:I69) -> 0 | J72: =SUM(J39:J69) -> 15 | K72: =SUM(K39:K69) -> 2.61 | L72: =SUM(L39:L69) -> 2.61 | ... T72: =SUM(T39:T69) -> 0

Sheet 3
A1: PROGRAMA DE MANUTENÇÃORODOVIÁRIA
D2: RODOVIAS PAVIMENTADAS | I2: DATA: | J2: ='1'!$J$2 -> 46174 | N2: TÉCNICO RESP. | O2: ='1'!$O$2 -> LABORATORISTA -Claudiomiro V.Lopes
A3: FICHA DE INSPEÇÃO: | B3: =TT!C6 -> RODOVIA TO-010 - TRECHO ARAGUATINS - ENTR. TO-201
A5: S.R.E. | B5: SENTIDO | C5: INÍCIO (KM) | D5: FIM (KM) | E5: CONDIÇÃO DO PAVIMENTO | J5: VEGETAÇÃO | L5: ELEM. DE DRENAGEM | O5: SIN. HOR. | R5: SIN. VERTICAL | U5: OBSERV.
E6: BOM | F6: REM. I. | G6: REM. L | H6: BUR. I | I6: BUR. L | J6: ADEQ. | K6: INADED. | L6: LIMPOS | M6: SUJOS | N6: DAN. | O6: BOM | P6: REG. | Q6: INEXIST. | R6: BOM | S6: POUCAS | T6: INEXIST.
A7: 010ETO0650 | B7: C | C7: 0 | D7: 2 | E7: X | K7: X | M7: X | O7: X | S7: X
C8: 0 | D8: 2 | E8: X | K8: X | M8: X | O8: X | S8: X
C9: 2 | D9: 4 | E9: X | K9: X | M9: X | O9: X | S9: X
C10: 2 | D10: 4 | E10: X | K10: X | M10: X | O10: X | S10: X
C11: 4 | D11: 5.7 | E11: X | K11: X | M11: X | O11: X | S11: X
A12: 010ETO0665 | C12: 0 | D12: 2 | E12: X | H12: X | K12: X | M12: X | O12: X | S12: X
A13: 010ETO0670 | C13: 0 | D13: 2 | E13: X | K13: X | M13: X | O13: X | S13: X
A14: 010ETO0672 | C14: 2 | D14: 4 | E14: X | K14: X | M14: X | O14: X | S14: X
A15: 010ETO0680 | C15: 4 | D15: 6 | E15: X | K15: X | M15: X | O15: X | S15: X
C16: 6 | D16: 8 | E16: X | K16: X | M16: X | O16: X | S16: X
C17: 8 | D17: 10 | E17: X | K17: X | M17: X | O17: X | S17: X
C18: 10 | D18: 12 | E18: X | K18: X | M18: X | O18: X | S18: X
C19: 14 | D19: 16 | E19: X | K19: X | M19: X | O19: X | S19: X
C20: 16 | D20: 18 | E20: X | K20: X | M20: X | O20: X | S20: X
C21: 18 | D21: 20 | E21: X | K21: X | M21: X | O21: X | S21: X
C22: 20 | D22: 22 | E22: X | K22: X | M22: X | O22: X | S22: X
C23: 22 | D23: 24 | E23: X | K23: X | M23: X | O23: X | S23: X
C24: 24 | D24: 26 | E24: X | K24: X | M24: X | O24: X | S24: X
C25: 26 | D25: 28 | E25: X | J25: X | M25: X | O25: X | S25: X
C26: 28 | D26: 30 | E26: X | J26: X | M26: X | O26: X | S26: X
C27: 30 | D27: 32 | E27: X | J27: X | M27: X | O27: X | S27: X
C28: 32 | D28: 34 | E28: X | J28: X | M28: X | O28: X | S28: X
C29: 32 | D29: 34 | G29: X | K29: X | M29: X | O29: X | S29: X
A44: LEGENDA | B44: CONDIÇÃO DO PAVIMENTO
A45: REM. I | B45: REMENDOS ISOLADOS | E45: ATÉ 10 REMENDOS/KM | I45: BUR. I | J45: BURACOS ISOLADOS | M45: ATÉ 5 BURACOS/KM
A46: REM. L | B46: REMENDOS AO LONGO | E46: MAIS DE 10 REMENDOS/KM | I46: BUR. L | J46: BURACOS AO LONGO | M46: MAIS DE 5 BURACOS/KM
E51: =IF(E7="X",(D7-C7),"0") -> 2 | F51: =IF(F7="X",(D7-C7),"0") -> 0 | G51: =IF(G7="X",(D7-C7),"0") -> 0 | H51: =IF(H7="X",(D7-C7),"0") -> 0 | I51: =IF(I7="X",(D7-C7),"0") -> 0 | J51: =IF(J7="X",(D7-C7),"0") -> 0 | K51: =IF(K7="X",(D7-C7),"0") -> 2 | L51: =IF(L7="X",(D7-C7),"0") -> 0 | M51: =IF(M7="X",(D7-C7),"0") -> 2 | N51: =IF(N7="X",(D7-C7),"0") -> 0 | O51: =IF(O7="X",(D7-C7),"0") -> 2 | P51: =IF(P7="X",(D7-C7),"0") -> 0 | Q51: =IF(Q7="X",(D7-C7),"0") -> 0 | R51: =IF(R7="X",(D7-C7),"0") -> 0 | S51: =IF(S7="X",(D7-C7),"0") -> 2 | T51: =IF(T7="X",(D7-C7),"0") -> 0
E52: =IF(E8="X",(D8-C8),"0") -> 2 | F52: =IF(F8="X",(D8-C8),"0") -> 0 | G52: =IF(G8="X",(D8-C8),"0") -> 0 | H52: =IF(H8="X",(D8-C8),"0") -> 0 | I52: =IF(I8="X",(D8-C8),"0") -> 0 | J52: =IF(J8="X",(D8-C8),"0") -> 0 | K52: =IF(K8="X",(D8-C8),"0") -> 2 | L52: =IF(L8="X",(D8-C8),"0") -> 0 | M52: =IF(M8="X",(D8-C8),"0") -> 2 | N52: =IF(N8="X",(D8-C8),"0") -> 0 | O52: =IF(O8="X",(D8-C8),"0") -> 2 | P52: =IF(P8="X",(D8-C8),"0") -> 0 | Q52: =IF(Q8="X",(D8-C8),"0") -> 0 | R52: =IF(R8="X",(D8-C8),"0") -> 0 | S52: =IF(S8="X",(D8-C8),"0") -> 2 | T52: =IF(T8="X",(D8-C8),"0") -> 0
E53: =IF(E9="X",(D9-C9),"0") -> 2 | F53: =IF(F9="X",(D9-C9),"0") -> 0 | G53: =IF(G9="X",(D9-C9),"0") -> 0 | H53: =IF(H9="X",(D9-C9),"0") -> 0 | I53: =IF(I9="X",(D9-C9),"0") -> 0 | J53: =IF(J9="X",(D9-C9),"0") -> 0 | K53: =IF(K9="X",(D9-C9),"0") -> 2 | L53: =IF(L9="X",(D9-C9),"0") -> 0 | M53: =IF(M9="X",(D9-C9),"0") -> 2 | N53: =IF(N9="X",(D9-C9),"0") -> 0 | O53: =IF(O9="X",(D9-C9),"0") -> 2 | P53: =IF(P9="X",(D9-C9),"0") -> 0 | Q53: =IF(Q9="X",(D9-C9),"0") -> 0 | R53: =IF(R9="X",(D9-C9),"0") -> 0 | S53: =IF(S9="X",(D9-C9),"0") -> 2 | T53: =IF(T9="X",(D9-C9),"0") -> 0
E54: =IF(E10="X",(D10-C10),"0") -> 2 | F54: =IF(F10="X",(D10-C10),"0") -> 0 | G54: =IF(G10="X",(D10-C10),"0") -> 0 | H54: =IF(H10="X",(D10-C10),"0") -> 0 | I54: =IF(I10="X",(D10-C10),"0") -> 0 | J54: =IF(J10="X",(D10-C10),"0") -> 0 | K54: =IF(K10="X",(D10-C10),"0") -> 2 | L54: =IF(L10="X",(D10-C10),"0") -> 0 | M54: =IF(M10="X",(D10-C10),"0") -> 2 | N54: =IF(N10="X",(D10-C10),"0") -> 0 | O54: =IF(O10="X",(D10-C10),"0") -> 2 | P54: =IF(P10="X",(D10-C10),"0") -> 0 | Q54: =IF(Q10="X",(D10-C10),"0") -> 0 | R54: =IF(R10="X",(D10-C10),"0") -> 0 | S54: =IF(S10="X",(D10-C10),"0") -> 2 | T54: =IF(T10="X",(D10-C10),"0") -> 0
E55: =IF(E11="X",(D11-C11),"0") -> 1.7 | F55: =IF(F11="X",(D11-C11),"0") -> 0 | G55: =IF(G11="X",(D11-C11),"0") -> 0 | H55: =IF(H11="X",(D11-C11),"0") -> 0 | I55: =IF(I11="X",(D11-C11),"0") -> 0 | J55: =IF(J11="X",(D11-C11),"0") -> 0 | K55: =IF(K11="X",(D11-C11),"0") -> 1.7 | L55: =IF(L11="X",(D11-C11),"0") -> 0 | M55: =IF(M11="X",(D11-C11),"0") -> 1.7 | N55: =IF(N11="X",(D11-C11),"0") -> 0 | O55: =IF(O11="X",(D11-C11),"0") -> 1.7 | P55: =IF(P11="X",(D11-C11),"0") -> 0 | Q55: =IF(Q11="X",(D11-C11),"0") -> 0 | R55: =IF(R11="X",(D11-C11),"0") -> 0 | S55: =IF(S11="X",(D11-C11),"0") -> 1.7 | T55: =IF(T11="X",(D11-C11),"0") -> 0
E56: =IF(E12="X",(D12-C12),"0") -> 2 | F56: =IF(F12="X",(D12-C12),"0") -> 0 | G56: =IF(G12="X",(D12-C12),"0") -> 0 | H56: =IF(H12="X",(D12-C12),"0") -> 2 | I56: =IF(I12="X",(D12-C12),"0") -> 0 | J56: =IF(J12="X",(D12-C12),"0") -> 0 | K56: =IF(K12="X",(D12-C12),"0") -> 2 | L56: =IF(L12="X",(D12-C12),"0") -> 0 | M56: =IF(M12="X",(D12-C12),"0") -> 2 | N56: =IF(N12="X",(D12-C12),"0") -> 0 | O56: =IF(O12="X",(D12-C12),"0") -> 2 | P56: =IF(P12="X",(D12-C12),"0") -> 0 | Q56: =IF(Q12="X",(D12-C12),"0") -> 0 | R56: =IF(R12="X",(D12-C12),"0") -> 0 | S56: =IF(S12="X",(D12-C12),"0") -> 2 | T56: =IF(T12="X",(D12-C12),"0") -> 0
E57: =IF(E13="X",(D13-C13),"0") -> 2 | F57: =IF(F13="X",(D13-C13),"0") -> 0 | G57: =IF(G13="X",(D13-C13),"0") -> 0 | H57: =IF(H13="X",(D13-C13),"0") -> 0 | I57: =IF(I13="X",(D13-C13),"0") -> 0 | J57: =IF(J13="X",(D13-C13),"0") -> 0 | K57: =IF(K13="X",(D13-C13),"0") -> 2 | L57: =IF(L13="X",(D13-C13),"0") -> 0 | M57: =IF(M13="X",(D13-C13),"0") -> 2 | N57: =IF(N13="X",(D13-C13),"0") -> 0 | O57: =IF(O13="X",(D13-C13),"0") -> 2 | P57: =IF(P13="X",(D13-C13),"0") -> 0 | Q57: =IF(Q13="X",(D13-C13),"0") -> 0 | R57: =IF(R13="X",(D13-C13),"0") -> 0 | S57: =IF(S13="X",(D13-C13),"0") -> 2 | T57: =IF(T13="X",(D13-C13),"0") -> 0
E58: =IF(E14="X",(D14-C14),"0") -> 2 | F58: =IF(F14="X",(D14-C14),"0") -> 0 | G58: =IF(G14="X",(D14-C14),"0") -> 0 | H58: =IF(H14="X",(D14-C14),"0") -> 0 | I58: =IF(I14="X",(D14-C14),"0") -> 0 | J58: =IF(J14="X",(D14-C14),"0") -> 0 | K58: =IF(K14="X",(D14-C14),"0") -> 2 | L58: =IF(L14="X",(D14-C14),"0") -> 0 | M58: =IF(M14="X",(D14-C14),"0") -> 2 | N58: =IF(N14="X",(D14-C14),"0") -> 0 | O58: =IF(O14="X",(D14-C14),"0") -> 2 | P58: =IF(P14="X",(D14-C14),"0") -> 0 | Q58: =IF(Q14="X",(D14-C14),"0") -> 0 | R58: =IF(R14="X",(D14-C14),"0") -> 0 | S58: =IF(S14="X",(D14-C14),"0") -> 2 | T58: =IF(T14="X",(D14-C14),"0") -> 0
E59: =IF(E27="X",(D27-C27),"0") -> 2 | F59: =IF(F27="X",(D27-C27),"0") -> 0 | G59: =IF(G27="X",(D27-C27),"0") -> 0 | H59: =IF(H27="X",(D27-C27),"0") -> 0 | I59: =IF(I27="X",(D27-C27),"0") -> 0 | J59: =IF(J27="X",(D27-C27),"0") -> 2 | K59: =IF(K27="X",(D27-C27),"0") -> 0 | L59: =IF(L27="X",(D27-C27),"0") -> 0 | M59: =IF(M27="X",(D27-C27),"0") -> 2 | N59: =IF(N27="X",(D27-C27),"0") -> 0 | O59: =IF(O27="X",(D27-C27),"0") -> 2 | P59: =IF(P27="X",(D27-C27),"0") -> 0 | Q59: =IF(Q27="X",(D27-C27),"0") -> 0 | R59: =IF(R27="X",(D27-C27),"0") -> 0 | S59: =IF(S27="X",(D27-C27),"0") -> 2 | T59: =IF(T27="X",(D27-C27),"0") -> 0
...

Sheet 4
A1: PROGRAMA DE MANUTENÇÃORODOVIÁRIA
D2: RODOVIAS PAVIMENTADAS | I2: DATA: | J2: ='1'!$J$2 -> 46174 | N2: TÉCNICO RESP. | O2: ='1'!$O$2 -> LABORATORISTA -Claudiomiro V.Lopes
A3: FICHA DE INSPEÇÃO: | B3: =TT!C7 -> RODOVIA TO-010 - TRECHO BURITI DO TOCANTINS (ENTR. TO-201) - SÃO SEBASTIÃO DO TOCANTINS
A5: S.R.E. | B5: SENTIDO | C5: INÍCIO (KM) | D5: FIM (KM) | E5: CONDIÇÃO DO PAVIMENTO | J5: VEGETAÇÃO | L5: ELEM. DE DRENAGEM | O5: SIN. HOR. | R5: SIN. VERTICAL | U5: OBSERV.
E6: BOM | F6: REM. I. | G6: REM. L | H6: BUR. I | I6: BUR. L | J6: ADEQ. | K6: INADED. | L6: LIMPOS | M6: SUJOS | N6: DAN. | O6: BOM | P6: REG. | Q6: INEXIST. | R6: BOM | S6: POUCAS | T6: INEXIST.
A7: 010ETO0690 | C7: 0 | D7: 2 | E7: X | J7: X | M7: X | O7: X | S7: X
A8: 010ETO0710 | C8: 0 | D8: 2 | F8: X | J8: X | M8: X | O8: X | S8: X
C9: 2 | D9: 4 | E9: X | J9: X | M9: X | O9: X | S9: X
C10: 2 | D10: 4 | F10: X | J10: X | M10: X | O10: X | S10: X
C11: 4 | D11: 4.7 | E11: X | J11: X | M11: X | O11: X | S11: X
C12: 4 | D12: 4.7 | E12: X | J12: X | M12: X | O12: X | S12: X
C13: 0 | D13: 1 | E13: X | K13: X | M13: X | Q13: X | T13: X
C14: 1 | D14: 2 | H14: X | K14: X | M14: X | N14: X | Q14: X | T14: X
C15: 2 | D15: 3 | H15: X | K15: X | M15: X | Q15: X | T15: X
C16: 3 | D16: 3.66 | E16: X | K16: X | M16: X | Q16: X | T16: X
A32: LEGENDA | B32: CONDIÇÃO DO PAVIMENTO
A33: REM. I | B33: REMENDOS ISOLADOS | E33: ATÉ 10 REMENDOS/KM | I33: BUR. I | J33: BURACOS ISOLADOS | M33: ATÉ 5 BURACOS/KM
A34: REM. L | B34: REMENDOS AO LONGO | E34: MAIS DE 10 REMENDOS/KM | I34: BUR. L | J34: BURACOS AO LONGO | M34: MAIS DE 5 BURACOS/KM
E39: =IF(E7="X",(D7-C7),"0") -> 2 | F39: =IF(F7="X",(D7-C7),"0") -> 0 | G39: =IF(G7="X",(D7-C7),"0") -> 0 | H39: =IF(H7="X",(D7-C7),"0") -> 0 | I39: =IF(I7="X",(D7-C7),"0") -> 0 | J39: =IF(J7="X",(D7-C7),"0") -> 2 | K39: =IF(K7="X",(D7-C7),"0") -> 0 | L39: =IF(L7="X",(D7-C7),"0") -> 0 | M39: =IF(M7="X",(D7-C7),"0") -> 2 | N39: =IF(N7="X",(D7-C7),"0") -> 0 | O39: =IF(O7="X",(D7-C7),"0") -> 2 | P39: =IF(P7="X",(D7-C7),"0") -> 0 | Q39: =IF(Q7="X",(D7-C7),"0") -> 0 | R39: =IF(R7="X",(D7-C7),"0") -> 0 | S39: =IF(S7="X",(D7-C7),"0") -> 2 | T39: =IF(T7="X",(D7-C7),"0") -> 0
E40: =IF(E8="X",(D8-C8),"0") -> 0 | F40: =IF(F8="X",(D8-C8),"0") -> 2 | G40: =IF(G8="X",(D8-C8),"0") -> 0 | H40: =IF(H8="X",(D8-C8),"0") -> 0 | I40: =IF(I8="X",(D8-C8),"0") -> 0 | J40: =IF(J8="X",(D8-C8),"0") -> 2 | K40: =IF(K8="X",(D8-C8),"0") -> 0 | L40: =IF(L8="X",(D8-C8),"0") -> 0 | M40: =IF(M8="X",(D8-C8),"0") -> 2 | N40: =IF(N8="X",(D8-C8),"0") -> 0 | O40: =IF(O8="X",(D8-C8),"0") -> 2 | P40: =IF(P8="X",(D8-C8),"0") -> 0 | Q40: =IF(Q8="X",(D8-C8),"0") -> 0 | R40: =IF(R8="X",(D8-C8),"0") -> 0 | S40: =IF(S8="X",(D8-C8),"0") -> 2 | T40: =IF(T8="X",(D8-C8),"0") -> 0
E41: =IF(E9="X",(D9-C9),"0") -> 2 | F41: =IF(F9="X",(D9-C9),"0") -> 0 | G41: =IF(G9="X",(D9-C9),"0") -> 0 | H41: =IF(H9="X",(D9-C9),"0") -> 0 | I41: =IF(I9="X",(D9-C9),"0") -> 0 | J41: =IF(J9="X",(D9-C9),"0") -> 2 | K41: =IF(K9="X",(D9-C9),"0") -> 0 | L41: =IF(L9="X",(D9-C9),"0") -> 0 | M41: =IF(M9="X",(D9-C9),"0") -> 2 | N41: =IF(N9="X",(D9-C9),"0") -> 0 | O41: =IF(O9="X",(D9-C9),"0") -> 2 | P41: =IF(P9="X",(D9-C9),"0") -> 0 | Q41: =IF(Q9="X",(D9-C9),"0") -> 0 | R41: =IF(R9="X",(D9-C9),"0") -> 0 | S41: =IF(S9="X",(D9-C9),"0") -> 2 | T41: =IF(T9="X",(D9-C9),"0") -> 0
E42: =IF(E10="X",(D10-C10),"0") -> 0 | F42: =IF(F10="X",(D10-C10),"0") -> 2 | G42: =IF(G10="X",(D10-C10),"0") -> 0 | H42: =IF(H10="X",(D10-C10),"0") -> 0 | I42: =IF(I10="X",(D10-C10),"0") -> 0 | J42: =IF(J10="X",(D10-C10),"0") -> 2 | K42: =IF(K10="X",(D10-C10),"0") -> 0 | L42: =IF(L10="X",(D10-C10),"0") -> 0 | M42: =IF(M10="X",(D10-C10),"0") -> 2 | N42: =IF(N10="X",(D10-C10),"0") -> 0 | O42: =IF(O10="X",(D10-C10),"0") -> 2 | P42: =IF(P10="X",(D10-C10),"0") -> 0 | Q42: =IF(Q10="X",(D10-C10),"0") -> 0 | R42: =IF(R10="X",(D10-C10),"0") -> 0 | S42: =IF(S10="X",(D10-C10),"0") -> 2 | T42: =IF(T10="X",(D10-C10),"0") -> 0
E43: =IF(E11="X",(D11-C11),"0") -> 0.7 | F43: =IF(F11="X",(D11-C11),"0") -> 0 | G43: =IF(G11="X",(D11-C11),"0") -> 0 | H43: =IF(H11="X",(D11-C11),"0") -> 0 | I43: =IF(I11="X",(D11-C11),"0") -> 0 | J43: =IF(J11="X",(D11-C11),"0") -> 0.7 | K43: =IF(K11="X",(D11-C11),"0") -> 0 | L43: =IF(L11="X",(D11-C11),"0") -> 0 | M43: =IF(M11="X",(D11-C11),"0") -> 0.7 | N43: =IF(N11="X",(D11-C11),"0") -> 0 | O43: =IF(O11="X",(D11-C11),"0") -> 0.7 | P43: =IF(P11="X",(D11-C11),"0") -> 0 | Q43: =IF(Q11="X",(D11-C11),"0") -> 0 | R43: =IF(R11="X",(D11-C11),"0") -> 0 | S43: =IF(S11="X",(D11-C11),"0") -> 0.7 | T43: =IF(T11="X",(D11-C11),"0") -> 0
E44: =IF(E12="X",(D12-C12),"0") -> 0.7 | F44: =IF(F12="X",(D12-C12),"0") -> 0 | G44: =IF(G12="X",(D12-C12),"0") -> 0 | H44: =IF(H12="X",(D12-C12),"0") -> 0 | I44: =IF(I12="X",(D12-C12),"0") -> 0 | J44: =IF(J12="X",(D12-C12),"0") -> 0.7 | K44: =IF(K12="X",(D12-C12),"0") -> 0 | L44: =IF(L12="X",(D12-C12),"0") -> 0 | M44: =IF(M12="X",(D12-C12),"0") -> 0.7 | N44: =IF(N12="X",(D12-C12),"0") -> 0 | O44: =IF(O12="X",(D12-C12),"0") -> 0.7 | P44: =IF(P12="X",(D12-C12),"0") -> 0 | Q44: =IF(Q12="X",(D12-C12),"0") -> 0 | R44: =IF(R12="X",(D12-C12),"0") -> 0 | S44: =IF(S12="X",(D12-C12),"0") -> 0.7 | T44: =IF(T12="X",(D12-C12),"0") -> 0
E45: =IF(E13="X",(D13-C13),"0") -> 1 | F45: =IF(F13="X",(D13-C13),"0") -> 0 | G45: =IF(G13="X",(D13-C13),"0") -> 0 | H45: =IF(H13="X",(D13-C13),"0") -> 0 | I45: =IF(I13="X",(D13-C13),"0") -> 0 | J45: =IF(J13="X",(D13-C13),"0") -> 0 | K45: =IF(K13="X",(D13-C13),"0") -> 1 | L45: =IF(L13="X",(D13-C13),"0") -> 0 | M45: =IF(M13="X",(D13-C13),"0") -> 1 | N45: =IF(N13="X",(D13-C13),"0") -> 0 | O45: =IF(O13="X",(D13-C13),"0") -> 0 | P45: =IF(P13="X",(D13-C13),"0") -> 0 | Q45: =IF(Q13="X",(D13-C13),"0") -> 1 | R45: =IF(R13="X",(D13-C13),"0") -> 0 | S45: =IF(S13="X",(D13-C13),"0") -> 0 | T45: =IF(T13="X",(D13-C13),"0") -> 1
E46: =IF(E14="X",(D14-C14),"0") -> 0 | F46: =IF(F14="X",(D14-C14),"0") -> 0 | G46: =IF(G14="X",(D14-C14),"0") -> 0 | H46: =IF(H14="X",(D14-C14),"0") -> 1 | I46: =IF(I14="X",(D14-C14),"0") -> 0 | J46: =IF(J14="X",(D14-C14),"0") -> 0 | K46: =IF(K14="X",(D14-C14),"0") -> 1 | L46: =IF(L14="X",(D14-C14),"0") -> 0 | M46: =IF(M14="X",(D14-C14),"0") -> 1 | N46: =IF(N14="X",(D14-C14),"0") -> 1 | O46: =IF(O14="X",(D14-C14),"0") -> 0 | P46: =IF(P14="X",(D14-C14),"0") -> 0 | Q46: =IF(Q14="X",(D14-C14),"0") -> 1 | R46: =IF(R14="X",(D14-C14),"0") -> 0 | S46: =IF(S14="X",(D14-C14),"0") -> 0 | T46: =IF(T14="X",(D14-C14),"0") -> 1
E47: =IF(E15="X",(D15-C15),"0") -> 0 | F47: =IF(F15="X",(D15-C15),"0") -> 0 | G47: =IF(G15="X",(D15-C15),"0") -> 0 | H47: =IF(H15="X",(D15-C15),"0") -> 1 | I47: =IF(I15="X",(D15-C15),"0") -> 0 | J47: =IF(J15="X",(D15-C15),"0") -> 0 | K47: =IF(K15="X",(D15-C15),"0") -> 1 | L47: =IF(L15="X",(D15-C15),"0") -> 0 | M47: =IF(M15="X",(D15-C15),"0") -> 1 | N47: =IF(N15="X",(D15-C15),"0") -> 0 | O47: =IF(O15="X",(D15-C15),"0") -> 0 | P47: =IF(P15="X",(D15-C15),"0") -> 0 | Q47: =IF(Q15="X",(D15-C15),"0") -> 1 | R47: =IF(R15="X",(D15-C15),"0") -> 0 | S47: =IF(S15="X",(D15-C15),"0") -> 0 | T47: =IF(T15="X",(D15-C15),"0") -> 1
E48: =IF(E16="X",(D16-C16),"0") -> 0.66 | F48: =IF(F16="X",(D16-C16),"0") -> 0 | G48: =IF(G16="X",(D16-C16),"0") -> 0 | H48: =IF(H16="X",(D16-C16),"0") -> 0 | I48: =IF(I16="X",(D16-C16),"0") -> 0 | J48: =IF(J16="X",(D16-C16),"0") -> 0 | K48: =IF(K16="X",(D16-C16),"0") -> 0.66 | L48: =IF(L16="X",(D16-C16),"0") -> 0 | M48: =IF(M16="X",(D16-C16),"0") -> 0.66 | N48: =IF(N16="X",(D16-C16),"0") -> 0 | O48: =IF(O16="X",(D16-C16),"0") -> 0 | P48: =IF(P16="X",(D16-C16),"0") -> 0 | Q48: =IF(Q16="X",(D16-C16),"0") -> 0.66 | R48: =IF(R16="X",(D16-C16),"0") -> 0 | S48: =IF(S16="X",(D16-C16),"0") -> 0 | T48: =IF(T16="X",(D16-C16),"0") -> 0.66
E49: =IF(E17="X",(D17-C17),"0") -> 0 | F49: =IF(F17="X",(D17-C17),"0") -> 0 | G49: =IF(G17="X",(D17-C17),"0") -> 0 | H49: =IF(H17="X",(D17-C17),"0") -> 0 | I49: =IF(I17="X",(D17-C17),"0") -> 0 | J49: =IF(J17="X",(D17-C17),"0") -> 0 | K49: =IF(K17="X",(D17-C17),"0") -> 0 | L49: =IF(L17="X",(D17-C17),"0") -> 0 | M49: =IF(M17="X",(D17-C17),"0") -> 0 | N49: =IF(N17="X",(D17-C17),"0") -> 0 | O49: =IF(O17="X",(D17-C17),"0") -> 0 | P49: =IF(P17="X",(D17-C17),"0") -> 0 | Q49: =IF(Q17="X",(D17-C17),"0") -> 0 | R49: =IF(R17="X",(D17-C17),"0") -> 0 | S49: =IF(S17="X",(D17-C17),"0") -> 0 | T49: =IF(T17="X",(D17-C17),"0") -> 0
E50: =IF(E18="X",(D18-C18),"0") -> 0 | F50: =IF(F18="X",(D18-C18),"0") -> 0 | G50: =IF(G18="X",(D18-C18),"0") -> 0 | H50: =IF(H18="X",(D18-C18),"0") -> 0 | I50: =IF(I18="X",(D18-C18),"0") -> 0 | J50: =IF(J18="X",(D18-C18),"0") -> 0 | K50: =IF(K18="X",(D18-C18),"0") -> 0 | L50: =IF(L18="X",(D18-C18),"0") -> 0 | M50: =IF(M18="X",(D18-C18),"0") -> 0 | N50: =IF(N18="X",(D18-C18),"0") -> 0 | O50: =IF(O18="X",(D18-C18),"0") -> 0 | P50: =IF(P18="X",(D18-C18),"0") -> 0 | Q50: =IF(Q18="X",(D18-C18),"0") -> 0 | R50: =IF(R18="X",(D18-C18),"0") -> 0 | S50: =IF(S18="X",(D18-C18),"0") -> 0 | T50: =IF(T18="X",(D18-C18),"0") -> 0
... E127: =IF(E95="X",(D95-C95),"0") -> 0 | F127: =IF(F95="X",(D95-C95),"0") -> 0 | G127: =IF(G95="X",(D95-C95),"0") -> 0 | H127: =IF(H95="X",(D95-C95),"0") -> 0 | I127: =IF(I95="X",(D95-C95),"0") -> 0 | J127: =IF(J95="X",(D95-C95),"0") -> 0 | K127: =IF(K95="X",(D95-C95),"0") -> 0 | L127: =IF(L95="X",(D95-C95),"0") -> 0 | M127: =IF(M95="X",(D95-C95),"0") -> 0 | N127: =IF(N95="X",(D95-C95),"0") -> 0 | O127: =IF(O95="X",(D95-C95),"0") -> 0 | P127: =IF(P95="X",(D95-C95),"0") -> 0 | Q127: =IF(Q95="X",(D95-C95),"0") -> 0 | R127: =IF(R95="X",(D95-C95),"0") -> 0 | S127: =IF(S95="X",(D95-C95),"0") -> 0 | T127: =IF(T95="X",(D95-C95),"0") -> 0
E130: =SUM(E39:E127) -> 7.06 | F130: =SUM(F39:F127) -> 4 | G130: =SUM(G39:G127) -> 0 | H130: =SUM(H39:H127) -> 2 | I130: =SUM(I39:I127) -> 0 | J130: =SUM(J39:J127) -> 9.4 | K130: =SUM(K39:K127) -> 3.66 | L130: =SUM(L39:L127) -> 0 | ... T130: =SUM(T39:T127) -> 3.66

Sheet 5
A1: PROGRAMA DE MANUTENÇÃORODOVIÁRIA
D2: RODOVIAS PAVIMENTADAS | I2: DATA: | J2: ='1'!$J$2 -> 46174 | N2: TÉCNICO RESP. | O2: ='1'!$O$2 -> LABORATORISTA -Claudiomiro V.Lopes
A3: FICHA DE INSPEÇÃO: | B3: =TT!C8 -> RODOVIA TO-126 - TRECHO BR-230 ENTRE (AGUIARNÓPOLIS) A TOCANTINOPOLIS
A5: S.R.E. | B5: SENTIDO | C5: INÍCIO (KM) | D5: FIM (KM) | E5: CONDIÇÃO DO PAVIMENTO | J5: VEGETAÇÃO | L5: ELEM. DE DRENAGEM | O5: SIN. HOR. | R5: SIN. VERTICAL | U5: OBSERV.
E6: BOM | F6: REM. I. | G6: REM. L | H6: BUR. I | I6: BUR. L | J6: ADEQ. | K6: INADED. | L6: LIMPOS | M6: SUJOS | N6: DAN. | O6: BOM | P6: REG. | Q6: INEXIST. | R6: BOM | S6: POUCAS | T6: INEXIST.
A7: ACESSO | C7: 0 | D7: 2 | G7: X | K7: X | M7: X | P7: X | S7: X
A8: 126ETO0151 | C8: 0 | D8: 2 | E8: X | K8: X | M8: X | P8: X | S8: X
A9: 126ETO0190 | C9: =D8 -> 2 | D9: 4 | E9: X | K9: X | M9: X | P9: X | S9: X
A10: 126ETO0200 | C10: =D8 -> 2 | D10: 4 | G10: X | K10: X | M10: X | P10: X | S10: X
C11: =D10 -> 4 | D11: 6 | E11: X | K11: X | M11: X | P11: X | S11: X
C12: =D11 -> 6 | D12: 8 | E12: X | K12: X | M12: X | P12: X | S12: X
C13: =D11 -> 6 | D13: 8 | G13: X | K13: X | M13: X | P13: X | S13: X
C14: =D12 -> 8 | D14: 10 | E14: X | K14: X | M14: X | P14: X | S14: X
C15: =D13 -> 8 | D15: 10 | G15: X | K15: X | M15: X | O15: X | S15: X
C16: =D14 -> 10 | D16: 12 | E16: X | K16: X | M16: X | O16: X | S16: X
C17: =D16 -> 12 | D17: 14 | E17: X | K17: X | M17: X | O17: X | S17: X
C18: =D17 -> 14 | D18: 16 | E18: X | K18: X | M18: X | O18: X | S18: X
C19: =D18 -> 16 | D19: 18 | E19: X | K19: X | M19: X | O19: X | S19: X
C20: =D18 -> 16 | D20: 18 | F20: X | K20: X | M20: X | O20: X | S20: X
C21: =D19 -> 18 | D21: 20 | E21: X | K21: X | M21: X | O21: X | S21: X
C22: =D21 -> 20 | D22: 22 | E22: X | K22: X | M22: X | O22: X | S22: X
C23: =D22 -> 22 | D23: 22.4 | E23: X | K23: X | M23: X | O23: X | S23: X
C24: =D23 -> 22.4 | D24: 22.4 | E24: X | K24: X | M24: X | S24: X
C25: =D24 -> 22.4 | D25: 19 | E25: X | K25: X | M25: X | P25: X | S25: X
C26: =D25 -> 19 | D26: 20 | F26: X | K26: X | M26: X | P26: X | S26: X
C27: =D26 -> 20 | D27: 21 | F27: X | K27: X | M27: X | P27: X | S27: X
C28: =D27 -> 21 | D28: 22 | G28: X | K28: X | M28: X | P28: X | S28: X
C29: =D28 -> 22 | D29: 22.49 | G29: X | K29: X | M29: X | P29: X | S29: X
C30: 0 | D30: 1 | F30: X | K30: X | L30: X | P30: X | T30: X
C31: =D30 -> 1 | D31: 2 | F31: X | K31: X | L31: X | P31: X | T31: X
C32: =D31 -> 2 | D32: 3 | E32: X | K32: X | L32: X | P32: X | T32: X
C33: =D32 -> 3 | D33: 3.23 | E33: X | K33: X | L33: X | P33: X | S33: X
C34: 0 | D34: 1 | E34: X | K34: X | L34: X | P34: X | S34: X
C35: =D34 -> 1 | D35: 1.86 | E35: X | K35: X | L35: X | P35: X | S35: X
C36: 0 | D36: 1 | E36: X | K36: X | L36: X | P36: X | S36: X
C37: =D36 -> 1 | D37: 2 | G37: X | K37: X | L37: X | P37: X | S37: X
C38: =D37 -> 2 | D38: 2.65 | E38: X | K38: X | L38: X | P38: X | S38: X
A50: LEGENDA | B50: CONDIÇÃO DO PAVIMENTO
A51: REM. I | B51: REMENDOS ISOLADOS | E51: ATÉ 10 REMENDOS/KM | I51: BUR. I | J51: BURACOS ISOLADOS | M51: ATÉ 5 BURACOS/KM
A52: REM. L | B52: REMENDOS AO LONGO | E52: MAIS DE 10 REMENDOS/KM | I52: BUR. L | J52: BURACOS AO LONGO | M52: MAIS DE 5 BURACOS/KM
...

Sheet 6
A1: PROGRAMA DE MANUTENÇÃORODOVIÁRIA
D2: RODOVIAS PAVIMENTADAS | I2: DATA: | J2: ='1'!$J$2 -> 46174 | N2: TÉCNICO RESP. | O2: ='1'!$O$2 -> LABORATORISTA -Claudiomiro V.Lopes
A3: FICHA DE INSPEÇÃO: | B3: =TT!C9 -> RODOVIA TO-126 - TRECHO MAURILÂNDIA - TOCANTINÓPOLIS
A5: S.R.E. | B5: SENTIDO | C5: INÍCIO (KM) | D5: FIM (KM) | E5: CONDIÇÃO DO PAVIMENTO | J5: VEGETAÇÃO | L5: ELEM. DE DRENAGEM | O5: SIN. HOR. | R5: SIN. VERTICAL | U5: OBSERV.
E6: BOM | F6: REM. I. | G6: REM. L | H6: BUR. I | I6: BUR. L | J6: ADEQ. | K6: INADED. | L6: LIMPOS | M6: SUJOS | N6: DAN. | O6: BOM | P6: REG. | Q6: INEXIST. | R6: BOM | S6: POUCAS | T6: INEXIST.
A7: 126ETO0140 | B7: C | C7: =D6 -> 0 | D7: 1 | E7: X | J7: X | M7: x | O7: X | R7: X
C8: =D7 -> 1 | D8: 2 | F8: X | J8: X | M8: x | O8: X | R8: X
C9: =D8 -> 2 | D9: 3 | F9: X | J9: X | M9: x | O9: X | R9: X
C10: =D9 -> 3 | D10: 4 | E10: X | J10: X | M10: x | O10: X | R10: X
C11: =D10 -> 4 | D11: 5 | E11: X | J11: X | M11: x | O11: X | R11: X
C12: =D11 -> 5 | D12: 5.53 | E12: X | J12: X | M12: x | P12: X | R12: X
A13: 126ETO0150 | B13: C | C13: 0 | D13: 1 | E13: X | F13: X | J13: X | M13: x | O13: X | R13: X
C14: =D13 -> 1 | D14: 2 | E14: X | J14: X | M14: x | O14: X | R14: X
C15: =D14 -> 2 | D15: 2.98 | E15: X | J15: X | M15: x | O15: X | R15: X
A32: LEGENDA | B32: CONDIÇÃO DO PAVIMENTO
A33: REM. I | B33: REMENDOS ISOLADOS | E33: ATÉ 10 REMENDOS/KM | I33: BUR. I | J33: BURACOS ISOLADOS | M33: ATÉ 5 BURACOS/KM
A34: REM. L | B34: REMENDOS AO LONGO | E34: MAIS DE 10 REMENDOS/KM | I34: BUR. L | J34: BURACOS AO LONGO | M34: MAIS DE 5 BURACOS/KM
E39: =IF(E7="X",(D7-C7),"0") -> 1 | F39: =IF(F7="X",(D7-C7),"0") -> 0 | G39: =IF(G7="X",(D7-C7),"0") -> 0 | H39: =IF(H7="X",(D7-C7),"0") -> 0 | I39: =IF(I7="X",(D7-C7),"0") -> 0 | J39: =IF(J7="X",(D7-C7),"0") -> 1 | K39: =IF(K7="X",(D7-C7),"0") -> 0 | L39: =IF(L7="X",(D7-C7),"0") -> 0 | M39: =IF(M7="X",(D7-C7),"0") -> 1 | N39: =IF(N7="X",(D7-C7),"0") -> 0 | O39: =IF(O7="X",(D7-C7),"0") -> 1 | P39: =IF(P7="X",(D7-C7),"0") -> 0 | Q39: =IF(Q7="X",(D7-C7),"0") -> 0 | R39: =IF(R7="X",(D7-C7),"0") -> 1 | S39: =IF(S7="X",(D7-C7),"0") -> 0 | T39: =IF(T7="X",(D7-C7),"0") -> 0
E40: =IF(E8="X",(D8-C8),"0") -> 0 | F40: =IF(F8="X",(D8-C8),"0") -> 1 | G40: =IF(G8="X",(D8-C8),"0") -> 0 | H40: =IF(H8="X",(D8-C8),"0") -> 0 | I40: =IF(I8="X",(D8-C8),"0") -> 0 | J40: =IF(J8="X",(D8-C8),"0") -> 1 | K40: =IF(K8="X",(D8-C8),"0") -> 0 | L40: =IF(L8="X",(D8-C8),"0") -> 0 | M40: =IF(M8="X",(D8-C8),"0") -> 1 | N40: =IF(N8="X",(D8-C8),"0") -> 0 | O40: =IF(O8="X",(D8-C8),"0") -> 1 | P40: =IF(P8="X",(D8-C8),"0") -> 0 | Q40: =IF(Q8="X",(D8-C8),"0") -> 0 | R40: =IF(R8="X",(D8-C8),"0") -> 1 | S40: =IF(S8="X",(D8-C8),"0") -> 0 | T40: =IF(T8="X",(D8-C8),"0") -> 0
E41: =IF(E9="X",(D9-C9),"0") -> 0 | F41: =IF(F9="X",(D9-C9),"0") -> 1 | G41: =IF(G9="X",(D9-C9),"0") -> 0 | H41: =IF(H9="X",(D9-C9),"0") -> 0 | I41: =IF(I9="X",(D9-C9),"0") -> 0 | J41: =IF(J9="X",(D9-C9),"0") -> 1 | K41: =IF(K9="X",(D9-C9),"0") -> 0 | L41: =IF(L9="X",(D9-C9),"0") -> 0 | M41: =IF(M9="X",(D9-C9),"0") -> 1 | N41: =IF(N9="X",(D9-C9),"0") -> 0 | O41: =IF(O9="X",(D9-C9),"0") -> 1 | P41: =IF(P9="X",(D9-C9),"0") -> 0 | Q41: =IF(Q9="X",(D9-C9),"0") -> 0 | R41: =IF(R9="X",(D9-C9),"0") -> 1 | S41: =IF(S9="X",(D9-C9),"0") -> 0 | T41: =IF(T9="X",(D9-C9),"0") -> 0
E42: =IF(E10="X",(D10-C10),"0") -> 1 | F42: =IF(F10="X",(D10-C10),"0") -> 0 | G42: =IF(G10="X",(D10-C10),"0") -> 0 | H42: =IF(H10="X",(D10-C10),"0") -> 0 | I42: =IF(I10="X",(D10-C10),"0") -> 0 | J42: =IF(J10="X",(D10-C10),"0") -> 1 | K42: =IF(K10="X",(D10-C10),"0") -> 0 | L42: =IF(L10="X",(D10-C10),"0") -> 0 | M42: =IF(M10="X",(D10-C10),"0") -> 1 | N42: =IF(N10="X",(D10-C10),"0") -> 0 | O42: =IF(O10="X",(D10-C10),"0") -> 1 | P42: =IF(P10="X",(D10-C10),"0") -> 0 | Q42: =IF(Q10="X",(D10-C10),"0") -> 0 | R42: =IF(R10="X",(D10-C10),"0") -> 1 | S42: =IF(S10="X",(D10-C10),"0") -> 0 | T42: =IF(T10="X",(D10-C10),"0") -> 0
E43: =IF(E11="X",(D11-C11),"0") -> 1 | F43: =IF(F11="X",(D11-C11),"0") -> 0 | G43: =IF(G11="X",(D11-C11),"0") -> 0 | H43: =IF(H11="X",(D11-C11),"0") -> 0 | I43: =IF(I11="X",(D11-C11),"0") -> 0 | J43: =IF(J11="X",(D11-C11),"0") -> 1 | K43: =IF(K11="X",(D11-C11),"0") -> 0 | L43: =IF(L11="X",(D11-C11),"0") -> 0 | M43: =IF(M11="X",(D11-C11),"0") -> 1 | N43: =IF(N11="X",(D11-C11),"0") -> 0 | O43: =IF(O11="X",(D11-C11),"0") -> 1 | P43: =IF(P11="X",(D11-C11),"0") -> 0 | Q43: =IF(Q11="X",(D11-C11),"0") -> 0 | R43: =IF(R11="X",(D11-C11),"0") -> 1 | S43: =IF(S11="X",(D11-C11),"0") -> 0 | T43: =IF(T11="X",(D11-C11),"0") -> 0
E44: =IF(E12="X",(D12-C12),"0") -> 0.53 | F44: =IF(F12="X",(D12-C12),"0") -> 0 | G44: =IF(G12="X",(D12-C12),"0") -> 0 | H44: =IF(H12="X",(D12-C12),"0") -> 0 | I44: =IF(I12="X",(D12-C12),"0") -> 0 | J44: =IF(J12="X",(D12-C12),"0") -> 0.53 | K44: =IF(K12="X",(D12-C12),"0") -> 0 | L44: =IF(L12="X",(D12-C12),"0") -> 0 | M44: =IF(M12="X",(D12-C12),"0") -> 0.53 | N44: =IF(N12="X",(D12-C12),"0") -> 0 | O44: =IF(O12="X",(D12-C12),"0") -> 0 | P44: =IF(P12="X",(D12-C12),"0") -> 0.53 | Q44: =IF(Q12="X",(D12-C12),"0") -> 0 | R44: =IF(R12="X",(D12-C12),"0") -> 0.53 | S44: =IF(S12="X",(D12-C12),"0") -> 0 | T44: =IF(T12="X",(D12-C12),"0") -> 0
E45: =IF(E13="X",(D13-C13),"0") -> 1 | F45: =IF(F13="X",(D13-C13),"0") -> 1 | G45: =IF(G13="X",(D13-C13),"0") -> 0 | H45: =IF(H13="X",(D13-C13),"0") -> 0 | I45: =IF(I13="X",(D13-C13),"0") -> 0 | J45: =IF(J13="X",(D13-C13),"0") -> 1 | K45: =IF(K13="X",(D13-C13),"0") -> 0 | L45: =IF(L13="X",(D13-C13),"0") -> 0 | M45: =IF(M13="X",(D13-C13),"0") -> 1 | N45: =IF(N13="X",(D13-C13),"0") -> 0 | O45: =IF(O13="X",(D13-C13),"0") -> 1 | P45: =IF(P13="X",(D13-C13),"0") -> 0 | Q45: =IF(Q13="X",(D13-C13),"0") -> 0 | R45: =IF(R13="X",(D13-C13),"0") -> 1 | S45: =IF(S13="X",(D13-C13),"0") -> 0 | T45: =IF(T13="X",(D13-C13),"0") -> 0
E46: =IF(E14="X",(D14-C14),"0") -> 1 | F46: =IF(F14="X",(D14-C14),"0") -> 0 | G46: =IF(G14="X",(D14-C14),"0") -> 0 | H46: =IF(H14="X",(D14-C14),"0") -> 0 | I46: =IF(I14="X",(D14-C14),"0") -> 0 | J46: =IF(J14="X",(D14-C14),"0") -> 1 | K46: =IF(K14="X",(D14-C14),"0") -> 0 | L46: =IF(L14="X",(D14-C14),"0") -> 0 | M46: =IF(M14="X",(D14-C14),"0") -> 1 | N46: =IF(N14="X",(D14-C14),"0") -> 0 | O46: =IF(O14="X",(D14-C14),"0") -> 1 | P46: =IF(P14="X",(D14-C14),"0") -> 0 | Q46: =IF(Q14="X",(D14-C14),"0") -> 0 | R46: =IF(R14="X",(D14-C14),"0") -> 1 | S46: =IF(S14="X",(D14-C14),"0") -> 0 | T46: =IF(T14="X",(D14-C14),"0") -> 0
E47: =IF(E15="X",(D15-C15),"0") -> 0.98 | F47: =IF(F15="X",(D15-C15),"0") -> 0 | G47: =IF(G15="X",(D15-C15),"0") -> 0 | H47: =IF(H15="X",(D15-C15),"0") -> 0 | I47: =IF(I15="X",(D15-C15),"0") -> 0 | J47: =IF(J15="X",(D15-C15),"0") -> 0.98 | K47: =IF(K15="X",(D15-C15),"0") -> 0 | L47: =IF(L15="X",(D15-C15),"0") -> 0 | M47: =IF(M15="X",(D15-C15),"0") -> 0.98 | N47: =IF(N15="X",(D15-C15),"0") -> 0 | O47: =IF(O15="X",(D15-C15),"0") -> 0.98 | P47: =IF(P15="X",(D15-C15),"0") -> 0 | Q47: =IF(Q15="X",(D15-C15),"0") -> 0 | R47: =IF(R15="X",(D15-C15),"0") -> 0.98 | S47: =IF(S15="X",(D15-C15),"0") -> 0 | T47: =IF(T15="X",(D15-C15),"0") -> 0
E48: =IF(E16="X",(D16-C16),"0") -> 0 | F48: =IF(F16="X",(D16-C16),"0") -> 0 | G48: =IF(G16="X",(D16-C16),"0") -> 0 | H48: =IF(H16="X",(D16-C16),"0") -> 0 | I48: =IF(I16="X",(D16-C16),"0") -> 0 | J48: =IF(J16="X",(D16-C16),"0") -> 0 | K48: =IF(K16="X",(D16-C16),"0") -> 0 | L48: =IF(L16="X",(D16-C16),"0") -> 0 | M48: =IF(M16="X",(D16-C16),"0") -> 0 | N48: =IF(N16="X",(D16-C16),"0") -> 0 | O48: =IF(O16="X",(D16-C16),"0") -> 0 | P48: =IF(P16="X",(D16-C16),"0") -> 0 | Q48: =IF(Q16="X",(D16-C16),"0") -> 0 | R48: =IF(R16="X",(D16-C16),"0") -> 0 | S48: =IF(S16="X",(D16-C16),"0") -> 0 | T48: =IF(T16="X",(D16-C16),"0") -> 0
E49: =IF(E17="X",(D17-C17),"0") -> 0 | F49: =IF(F17="X",(D17-C17),"0") -> 0 | G49: =IF(G17="X",(D17-C17),"0") -> 0 | H49: =IF(H17="X",(D17-C17),"0") -> 0 | I49: =IF(I17="X",(D17-C17),"0") -> 0 | J49: =IF(J17="X",(D17-C17),"0") -> 0 | K49: =IF(K17="X",(D17-C17),"0") -> 0 | L49: =IF(L17="X",(D17-C17),"0") -> 0 | M49: =IF(M17="X",(D17-C17),"0") -> 0 | N49: =IF(N17="X",(D17-C17),"0") -> 0 | O49: =IF(O17="X",(D17-C17),"0") -> 0 | P49: =IF(P17="X",(D17-C17),"0") -> 0 | Q49: =IF(Q17="X",(D17-C17),"0") -> 0 | R49: =IF(R17="X",(D17-C17),"0") -> 0 | S49: =IF(S17="X",(D17-C17),"0") -> 0 | T49: =IF(T17="X",(D17-C17),"0") -> 0
E50: =IF(E18="X",(D18-C18),"0") -> 0 | F50: =IF(F18="X",(D18-C18),"0") -> 0 | G50: =IF(G18="X",(D18-C18),"0") -> 0 | H50: =IF(H18="X",(D18-C18),"0") -> 0 | I50: =IF(I18="X",(D18-C18),"0") -> 0 | J50: =IF(J18="X",(D18-C18),"0") -> 0 | K50: =IF(K18="X",(D18-C18),"0") -> 0 | L50: =IF(L18="X",(D18-C18),"0") -> 0 | M50: =IF(M18="X",(D18-C18),"0") -> 0 | N50: =IF(N18="X",(D18-C18),"0") -> 0 | O50: =IF(O18="X",(D18-C18),"0") -> 0 | P50: =IF(P18="X",(D18-C18),"0") -> 0 | Q50: =IF(Q18="X",(D18-C18),"0") -> 0 | R50: =IF(R18="X",(D18-C18),"0") -> 0 | S50: =IF(S18="X",(D18-C18),"0") -> 0 | T50: =IF(T18="X",(D18-C18),"0") -> 0
... E127: =IF(E95="X",(D95-C95),"0") -> 0 | F127: =IF(F95="X",(D95-C95),"0") -> 0 | G127: =IF(G95="X",(D95-C95),"0") -> 0 | H127: =IF(H95="X",(D95-C95),"0") -> 0 | I127: =IF(I95="X",(D95-C95),"0") -> 0 | J127: =IF(J95="X",(D95-C95),"0") -> 0 | K127: =IF(K95="X",(D95-C95),"0") -> 0 | L127: =IF(L95="X",(D95-C95),"0") -> 0 | M127: =IF(M95="X",(D95-C95),"0") -> 0 | N127: =IF(N95="X",(D95-C95),"0") -> 0 | O127: =IF(O95="X",(D95-C95),"0") -> 0 | P127: =IF(P95="X",(D95-C95),"0") -> 0 | Q127: =IF(Q95="X",(D95-C95),"0") -> 0 | R127: =IF(R95="X",(D95-C95),"0") -> 0 | S127: =IF(S95="X",(D95-C95),"0") -> 0 | T127: =IF(T95="X",(D95-C95),"0") -> 0
E130: =SUM(E39:E127) -> 6.51 | F130: =SUM(F39:F127) -> 3 | G130: =SUM(G39:G127) -> 0 | H130: =SUM(H39:H127) -> 0 | I130: =SUM(I39:I127) -> 0 | J130: =SUM(J39:J127) -> 8.51 | K130: =SUM(K39:K127) -> 0 | L130: =SUM(L39:L127) -> 0 | ... T130: =SUM(T39:T127) -> 0

Sheet 7
A1: PROGRAMA DE MANUTENÇÃORODOVIÁRIA
D2: RODOVIAS PAVIMENTADAS | I2: DATA: | J2: ='1'!$J$2 -> 46174 | N2: TÉCNICO RESP. | O2: ='1'!$O$2 -> LABORATORISTA -Claudiomiro V.Lopes
A3: FICHA DE INSPEÇÃO: | B3: =TT!C10 -> RODOVIA TO-126 - TRECHO ITAGUATINS - MAURILÂNDIA DO TOCANTINS
A5: S.R.E. | B5: SENTIDO | C5: INÍCIO (KM) | D5: FIM (KM) | E5: CONDIÇÃO DO PAVIMENTO | J5: VEGETAÇÃO | L5: ELEM. DE DRENAGEM | O5: SIN. HOR. | R5: SIN. VERTICAL | U5: OBSERV.
E6: BOM | F6: REM. I. | G6: REM. L | H6: BUR. I | I6: BUR. L | J6: ADEQ. | K6: INADED. | L6: LIMPOS | M6: SUJOS | N6: DAN. | O6: BOM | P6: REG. | Q6: INEXIST. | R6: BOM | S6: POUCAS | T6: INEXIST.
A7: 126ETO0101 | B7: C | C7: =D6 -> 0 | D7: 2 | E7: X | K7: X | L7: X | P7: X | S7: X | U7: KM-5,1 BORRACHUDO
A8: 126ETO0120 | B8: C | C8: 2 | D8: 4 | E8: X | K8: X | L8: X | P8: X | S8: X | U8: KM-5,6 a 5,8 BUR -L
C9: =D8 -> 4 | D9: 6 | E9: X | K9: X | M9: X | P9: X | S9: X | U9: KM-6,1 a 6,3 BUR-L
C10: =D9 -> 6 | D10: 8 | E10: X | K10: X | L10: X | O10: X | S10: X | U10: KM-8,1 BORRACHUDO
C11: =D10 -> 8 | D11: 10 | E11: X | K11: X | L11: X | O11: X | S11: X | U11: KM-15,9 16,3 BUR-L
C12: 8 | D12: 10 | E12: X | K12: X | L12: X | P12: X | S12: X
C13: =D12 -> 10 | D13: 12 | E13: X | H13: X | K13: X | L13: X | P13: X | S13: X | U13: POUCAS PLACAS E
C14: =D13 -> 12 | D14: 14 | E14: X | K14: X | M14: X | P14: X | S14: X | U14: ESTÃO EM BOAS
C15: 12 | D15: 14 | H15: X | K15: X | M15: X | P15: X | S15: X | U15: CONDIÇÔES
C16: =D15 -> 14 | D16: 16 | E16: X | K16: X | L16: X | O16: X | S16: X
C17: 14 | D17: 16 | E17: X | K17: X | L17: X | P17: X | S17: X
C18: 16 | D18: 18 | E18: X | K18: X | L18: X | O18: X | P18: X | S18: X
C19: 16 | D19: 18 | E19: X | H19: X | K19: X | L19: X | O19: X | P19: X | S19: X
C20: 18 | D20: 19.4 | E20: X | F20: X | K20: X | L20: X | O20: X | P20: X | S20: X
C21: =D20 -> 19.4 | D21: 14 | I21: X | K21: X | L21: X | O21: X | T21: X
C22: =D21 -> 14 | D22: 15 | E22: X | K22: X | M22: X | O22: X | T22: X
