Workbook

Sheet Trechos
A1: RELAÇÃO DOS TRECHOS DAS REGIÕES DE MANUTENÇÃO
A2: LOTE | B2: N. | C2: TRECHO | D2: S.R.E | E2: SUBTRECHOS | F2: EXT. (KM) | G2: TIPO | H2: 45839 | I2: 45870 | J2: 45901 | K2: 45931 | L2: 45962 | M2: 45992
A3: 2 | B3: 39 | C3: RODOVIA TO-010 - TRECHO RIACHINHO - ANANÁS | D3: 416ETO0040 | E3: ENTR. TO-010 - RIACHINHO | F3: 2.4295262 | G3: PPS | I3: X
A4: 2 | B4: 39 | C4: RODOVIA TO-010 - TRECHO RIACHINHO - ANANÁS | D4: 010ETO0500 | E4: ENTR. TO-416 - SÃO RAIMUNDO | F4: 4.2669872 | G4: PPS | I4: X
A5: 2 | B5: 39 | C5: RODOVIA TO-010 - TRECHO RIACHINHO - ANANÁS | D5: 010ETO0510 | E5: SÃO RAIMUNDO - ANANÁS *TRECHO URBANO* | F5: 3.7562933 | G5: PPS | I5: X
A6: 2 | B6: 40 | C6: RODOVIA TO-010 - TRECHO WANDERLÂNDIA - RIACHINHO | D6: 010ETO0421 | E6: WANDERLÂNDIA *TRECHO URBANO* | F6: 1.0835334 | G6: PSU | I6: X
A7: 2 | B7: 40 | C7: RODOVIA TO-010 - TRECHO WANDERLÂNDIA - RIACHINHO | D7: 010ETO0422 | E7: WANDERLÂNDIA *TRECHO URBANO* | F7: 0.7148177 | G7: PSU | I7: X
A8: 2 | B8: 40 | C8: RODOVIA TO-010 - TRECHO WANDERLÂNDIA - RIACHINHO | D8: 010ETO0430 | E8: WANDERLANDIA - ENTR. BR-153 | F8: 1.0743694 | G8: PPS | I8: X
A9: 2 | B9: 40 | C9: RODOVIA TO-010 - TRECHO WANDERLÂNDIA - RIACHINHO | D9: 010ETO0440 | E9: ENTR. BR-226 - ENTR.BR-153 | F9: 2.9880881 | G9: PPS | I9: X
A10: 2 | B10: 40 | C10: RODOVIA TO-010 - TRECHO WANDERLÂNDIA - RIACHINHO | D10: 010ETO0470 | E10: ENTR. BR-153 - CENTRO DOS BORGES | F10: 42.716102 | G10: PPS | I10: X
A11: 2 | B11: 40 | C11: RODOVIA TO-010 - TRECHO WANDERLÂNDIA - RIACHINHO | D11: 010ETO0480 | E11: CENTRO DOS BORGES - SOROROCA | F11: 5.2299312 | G11: PPS | I11: X
A12: 2 | B12: 40 | C12: RODOVIA TO-010 - TRECHO WANDERLÂNDIA - RIACHINHO | D12: 010ETO0490 | E12: SOROROCA - ENTR. TO-416 | F12: 6.9420402 | G12: PPS | I12: X
A13: 2 | B13: 41 | C13: RODOVIA TO-164 - TRECHO ENTR. BR-153 (XAMBIOÁ) - ARAGUANÃ | D13: 164ETO0101 | E13: ARAGUANÃ *TRECHO URBANO* | F13: 2.5646179 | G13: PSU | I13: X
A14: 2 | B14: 41 | C14: RODOVIA TO-164 - TRECHO ENTR. BR-153 (XAMBIOÁ) - ARAGUANÃ | D14: 164ETO0095 | E14: ENTR. BR-153 (XAMBIOÁ) - ENTR. TO-418 (XAMBIOAZINHO) | F14: 3.9243314 | G14: PPS | I14: X
... A55: 2 | B55: 57 | C55: RODOVIA TO-416 - TRECHO ENTR. BR-153 - RIACHINHO | D55: 416ETO0050 | E55: RIACHINHO - ENTR. BR-153 | F55: 32.246741 | G55: PPS | I55: X
A56: 2 | B56: 58 | C56: RODOVIA TO-416 - TRECHO ENTR. TO-222 - POVOADO COCALINHO | D56: 416ETO0100 | E56: POV. COCALINHO - ENTR. TO-222 | F56: 3.8680293 | G56: PPS
A57: 2 | B57: 61 | C57: RODOVIA TO-420 - TRECHO ENTR. BR-153 (POVOADO XAMBERLÂNDIA) - PIRAQUÊ - ENTR. BR-153 | D57: 420ETO0010 | E57: ENTR. BR-153 - PIRAQUÊ *TRECHO URBANO* | F57: 6.4242395 | G57: PPS | I57: X
A58: 2 | B58: 61 | C58: RODOVIA TO-420 - TRECHO ENTR. BR-153 (POVOADO XAMBERLÂNDIA) - PIRAQUÊ - ENTR. BR-153 | D58: 420ETO0030 | E58: PIRAQUÊ *TRECHO URBANO* - ENTR. BR-153 (XAMBERLÂNDIA) | F58: 31.717802 | G58: PPS | I58: X
A59: 2 | B59: 63 | C59: RODOVIA TO-427 - TRECHO PAU D'ARCO (DIVISA TO-PA) - ENTR. TO-226 | D59: 427ETO0010 | E59: ENTR. TO-226 - PAU D'ARCO *TRECHO URBANO* | F59: 28.990649 | G59: PPS | I59: X
F60: =SUM(F3:F59) -> 677.61588

Sheet 39
A1: PROGRAMA DE MANUTENÇÃORODOVIÁRIA
D2: RODOVIAS PAVIMENTADAS | I2: DATA: | J2: 46204 | N2: TÉCNICO RESP. | O2: ENG. VINICIUS RODRIGUES FERREIRA DE OLIVEIRA | T2: REGIÃO: | U2: 02
A3: FICHA DE INSPEÇÃO: | B3: =TT!C4 -> RODOVIA TO-010 - TRECHO RIACHINHO - ANANÁS
A5: S.R.E. | B5: SENTIDO | C5: INÍCIO (KM) | D5: FIM (KM) | E5: CONDIÇÃO DO PAVIMENTO | J5: VEGETAÇÃO | L5: ELEM. DE DRENAGEM | O5: SIN. HOR. | R5: SIN. VERTICAL | U5: OBSERV.
E6: BOM | F6: REM. I. | G6: REM. L | H6: BUR. I | I6: BUR. L | J6: ADEQ. | K6: INADED. | L6: LIMPOS | M6: SUJOS | N6: DAN. | O6: BOM | P6: REG. | Q6: INEXIST. | R6: BOM | S6: POUCAS | T6: INEXIST.
A7: 010ETO0510 | B7: D | C7: =D6 -> 0 | D7: 1 | G7: X | J7: X | M7: X | Q7: X | S7: X
C8: =D7 -> 1 | D8: 2 | G8: X | J8: X | M8: X | Q8: X | S8: X
C9: =D8 -> 2 | D9: 3 | G9: X | J9: X | M9: X | Q9: X | S9: X
C10: =D9 -> 3 | D10: 3.76 | G10: X | J10: X | M10: X | Q10: X | S10: X
A11: 010ETO0500 | B11: D | C11: 0 | D11: 1 | G11: X | J11: X | M11: X | Q11: X | S11: X
C12: =D11 -> 1 | D12: 2 | G12: X | J12: X | M12: X | Q12: X | S12: X
C13: =D12 -> 2 | D13: 3 | G13: X | J13: X | M13: X | Q13: X | S13: X
C14: =D13 -> 3 | D14: 4 | G14: X | J14: X | M14: X | Q14: X | S14: X
C15: =D14 -> 4 | D15: 4.27 | G15: X | J15: X | M15: X | Q15: X | S15: X
A16: 416ETO0040 | B16: D | C16: 0 | D16: 1 | G16: X | J16: X | M16: X | Q16: X | T16: X
C17: =D16 -> 1 | D17: 2 | G17: X | J17: X | M17: X | Q17: X | T17: X
C18: =D17 -> 2 | D18: 2.43 | G18: X | J18: X | M18: X | Q18: X | T18: X
A29: LEGENDA | B29: CONDIÇÃO DO PAVIMENTO
A30: REM. I | B30: REMENDOS ISOLADOS | E30: ATÉ 10 REMENDOS/KM | I30: BUR. I | J30: BURACOS ISOLADOS | M30: ATÉ 5 BURACOS/KM
A31: REM. L | B31: REMENDOS AO LONGO | E31: MAIS DE 10 REMENDOS/KM | I31: BUR. L | J31: BURACOS AO LONGO | M31: MAIS DE 5 BURACOS/KM
E36: =IF(E7="X",(D7-C7),"0") -> 0 | F36: =IF(F7="X",(D7-C7),"0") -> 0 | G36: =IF(G7="X",(D7-C7),"0") -> 1 | H36: =IF(H7="X",(D7-C7),"0") -> 0 | I36: =IF(I7="X",(D7-C7),"0") -> 0 | J36: =IF(J7="X",(D7-C7),"0") -> 1 | K36: =IF(K7="X",(D7-C7),"0") -> 0 | L36: =IF(L7="X",(D7-C7),"0") -> 0 | M36: =IF(M7="X",(D7-C7),"0") -> 1 | N36: =IF(N7="X",(D7-C7),"0") -> 0 | O36: =IF(O7="X",(D7-C7),"0") -> 0 | P36: =IF(P7="X",(D7-C7),"0") -> 0 | Q36: =IF(Q7="X",(D7-C7),"0") -> 1 | R36: =IF(R7="X",(D7-C7),"0") -> 0 | S36: =IF(S7="X",(D7-C7),"0") -> 1 | T36: =IF(T7="X",(D7-C7),"0") -> 0
E37: =IF(E8="X",(D8-C8),"0") -> 0 | F37: =IF(F8="X",(D8-C8),"0") -> 0 | G37: =IF(G8="X",(D8-C8),"0") -> 1 | H37: =IF(H8="X",(D8-C8),"0") -> 0 | I37: =IF(I8="X",(D8-C8),"0") -> 0 | J37: =IF(J8="X",(D8-C8),"0") -> 1 | K37: =IF(K8="X",(D8-C8),"0") -> 0 | L37: =IF(L8="X",(D8-C8),"0") -> 0 | M37: =IF(M8="X",(D8-C8),"0") -> 1 | N37: =IF(N8="X",(D8-C8),"0") -> 0 | O37: =IF(O8="X",(D8-C8),"0") -> 0 | P37: =IF(P8="X",(D8-C8),"0") -> 0 | Q37: =IF(Q8="X",(D8-C8),"0") -> 1 | R37: =IF(R8="X",(D8-C8),"0") -> 0 | S37: =IF(S8="X",(D8-C8),"0") -> 1 | T37: =IF(T8="X",(D8-C8),"0") -> 0
E38: =IF(E9="X",(D9-C9),"0") -> 0 | F38: =IF(F9="X",(D9-C9),"0") -> 0 | G38: =IF(G9="X",(D9-C9),"0") -> 1 | H38: =IF(H9="X",(D9-C9),"0") -> 0 | I38: =IF(I9="X",(D9-C9),"0") -> 0 | J38: =IF(J9="X",(D9-C9),"0") -> 1 | K38: =IF(K9="X",(D9-C9),"0") -> 0 | L38: =IF(L9="X",(D9-C9),"0") -> 0 | M38: =IF(M9="X",(D9-C9),"0") -> 1 | N38: =IF(N9="X",(D9-C9),"0") -> 0 | O38: =IF(O9="X",(D9-C9),"0") -> 0 | P38: =IF(P9="X",(D9-C9),"0") -> 0 | Q38: =IF(Q9="X",(D9-C9),"0") -> 1 | R38: =IF(R9="X",(D9-C9),"0") -> 0 | S38: =IF(S9="X",(D9-C9),"0") -> 1 | T38: =IF(T9="X",(D9-C9),"0") -> 0
E39: =IF(E10="X",(D10-C10),"0") -> 0 | F39: =IF(F10="X",(D10-C10),"0") -> 0 | G39: =IF(G10="X",(D10-C10),"0") -> 0.76 | H39: =IF(H10="X",(D10-C10),"0") -> 0 | I39: =IF(I10="X",(D10-C10),"0") -> 0 | J39: =IF(J10="X",(D10-C10),"0") -> 0.76 | K39: =IF(K10="X",(D10-C10),"0") -> 0 | L39: =IF(L10="X",(D10-C10),"0") -> 0 | M39: =IF(M10="X",(D10-C10),"0") -> 0.76 | N39: =IF(N10="X",(D10-C10),"0") -> 0 | O39: =IF(O10="X",(D10-C10),"0") -> 0 | P39: =IF(P10="X",(D10-C10),"0") -> 0 | Q39: =IF(Q10="X",(D10-C10),"0") -> 0.76 | R39: =IF(R10="X",(D10-C10),"0") -> 0 | S39: =IF(S10="X",(D10-C10),"0") -> 0.76 | T39: =IF(T10="X",(D10-C10),"0") -> 0
E40: =IF(E11="X",(D11-C11),"0") -> 0 | F40: =IF(F11="X",(D11-C11),"0") -> 0 | G40: =IF(G11="X",(D11-C11),"0") -> 1 | H40: =IF(H11="X",(D11-C11),"0") -> 0 | I40: =IF(I11="X",(D11-C11),"0") -> 0 | J40: =IF(J11="X",(D11-C11),"0") -> 1 | K40: =IF(K11="X",(D11-C11),"0") -> 0 | L40: =IF(L11="X",(D11-C11),"0") -> 0 | M40: =IF(M11="X",(D11-C11),"0") -> 1 | N40: =IF(N11="X",(D11-C11),"0") -> 0 | O40: =IF(O11="X",(D11-C11),"0") -> 0 | P40: =IF(P11="X",(D11-C11),"0") -> 0 | Q40: =IF(Q11="X",(D11-C11),"0") -> 1 | R40: =IF(R11="X",(D11-C11),"0") -> 0 | S40: =IF(S11="X",(D11-C11),"0") -> 1 | T40: =IF(T11="X",(D11-C11),"0") -> 0
E41: =IF(E12="X",(D12-C12),"0") -> 0 | F41: =IF(F12="X",(D12-C12),"0") -> 0 | G41: =IF(G12="X",(D12-C12),"0") -> 1 | H41: =IF(H12="X",(D12-C12),"0") -> 0 | I41: =IF(I12="X",(D12-C12),"0") -> 0 | J41: =IF(J12="X",(D12-C12),"0") -> 1 | K41: =IF(K12="X",(D12-C12),"0") -> 0 | L41: =IF(L12="X",(D12-C12),"0") -> 0 | M41: =IF(M12="X",(D12-C12),"0") -> 1 | N41: =IF(N12="X",(D12-C12),"0") -> 0 | O41: =IF(O12="X",(D12-C12),"0") -> 0 | P41: =IF(P12="X",(D12-C12),"0") -> 0 | Q41: =IF(Q12="X",(D12-C12),"0") -> 1 | R41: =IF(R12="X",(D12-C12),"0") -> 0 | S41: =IF(S12="X",(D12-C12),"0") -> 1 | T41: =IF(T12="X",(D12-C12),"0") -> 0
E42: =IF(E13="X",(D13-C13),"0") -> 0 | F42: =IF(F13="X",(D13-C13),"0") -> 0 | G42: =IF(G13="X",(D13-C13),"0") -> 1 | H42: =IF(H13="X",(D13-C13),"0") -> 0 | I42: =IF(I13="X",(D13-C13),"0") -> 0 | J42: =IF(J13="X",(D13-C13),"0") -> 1 | K42: =IF(K13="X",(D13-C13),"0") -> 0 | L42: =IF(L13="X",(D13-C13),"0") -> 0 | M42: =IF(M13="X",(D13-C13),"0") -> 1 | N42: =IF(N13="X",(D13-C13),"0") -> 0 | O42: =IF(O13="X",(D13-C13),"0") -> 0 | P42: =IF(P13="X",(D13-C13),"0") -> 0 | Q42: =IF(Q13="X",(D13-C13),"0") -> 1 | R42: =IF(R13="X",(D13-C13),"0") -> 0 | S42: =IF(S13="X",(D13-C13),"0") -> 1 | T42: =IF(T13="X",(D13-C13),"0") -> 0
E43: =IF(E14="X",(D14-C14),"0") -> 0 | F43: =IF(F14="X",(D14-C14),"0") -> 0 | G43: =IF(G14="X",(D14-C14),"0") -> 1 | H43: =IF(H14="X",(D14-C14),"0") -> 0 | I43: =IF(I14="X",(D14-C14),"0") -> 0 | J43: =IF(J14="X",(D14-C14),"0") -> 1 | K43: =IF(K14="X",(D14-C14),"0") -> 0 | L43: =IF(L14="X",(D14-C14),"0") -> 0 | M43: =IF(M14="X",(D14-C14),"0") -> 1 | N43: =IF(N14="X",(D14-C14),"0") -> 0 | O43: =IF(O14="X",(D14-C14),"0") -> 0 | P43: =IF(P14="X",(D14-C14),"0") -> 0 | Q43: =IF(Q14="X",(D14-C14),"0") -> 1 | R43: =IF(R14="X",(D14-C14),"0") -> 0 | S43: =IF(S14="X",(D14-C14),"0") -> 1 | T43: =IF(T14="X",(D14-C14),"0") -> 0
E44: =IF(E15="X",(D15-C15),"0") -> 0 | F44: =IF(F15="X",(D15-C15),"0") -> 0 | G44: =IF(G15="X",(D15-C15),"0") -> 0.27 | H44: =IF(H15="X",(D15-C15),"0") -> 0 | I44: =IF(I15="X",(D15-C15),"0") -> 0 | J44: =IF(J15="X",(D15-C15),"0") -> 0.27 | K44: =IF(K15="X",(D15-C15),"0") -> 0 | L44: =IF(L15="X",(D15-C15),"0") -> 0 | M44: =IF(M15="X",(D15-C15),"0") -> 0.27 | N44: =IF(N15="X",(D15-C15),"0") -> 0 | O44: =IF(O15="X",(D15-C15),"0") -> 0 | P44: =IF(P15="X",(D15-C15),"0") -> 0 | Q44: =IF(Q15="X",(D15-C15),"0") -> 0.27 | R44: =IF(R15="X",(D15-C15),"0") -> 0 | S44: =IF(S15="X",(D15-C15),"0") -> 0.27 | T44: =IF(T15="X",(D15-C15),"0") -> 0
E45: =IF(E16="X",(D16-C16),"0") -> 0 | F45: =IF(F16="X",(D16-C16),"0") -> 0 | G45: =IF(G16="X",(D16-C16),"0") -> 1 | H45: =IF(H16="X",(D16-C16),"0") -> 0 | I45: =IF(I16="X",(D16-C16),"0") -> 0 | J45: =IF(J16="X",(D16-C16),"0") -> 1 | K45: =IF(K16="X",(D16-C16),"0") -> 0 | L45: =IF(L16="X",(D16-C16),"0") -> 0 | M45: =IF(M16="X",(D16-C16),"0") -> 1 | N45: =IF(N16="X",(D16-C16),"0") -> 0 | O45: =IF(O16="X",(D16-C16),"0") -> 0 | P45: =IF(P16="X",(D16-C16),"0") -> 0 | Q45: =IF(Q16="X",(D16-C16),"0") -> 1 | R45: =IF(R16="X",(D16-C16),"0") -> 0 | S45: =IF(S16="X",(D16-C16),"0") -> 0 | T45: =IF(T16="X",(D16-C16),"0") -> 1
E46: =IF(E17="X",(D17-C17),"0") -> 0 | F46: =IF(F17="X",(D17-C17),"0") -> 0 | G46: =IF(G17="X",(D17-C17),"0") -> 1 | H46: =IF(H17="X",(D17-C17),"0") -> 0 | I46: =IF(I17="X",(D17-C17),"0") -> 0 | J46: =IF(J17="X",(D17-C17),"0") -> 1 | K46: =IF(K17="X",(D17-C17),"0") -> 0 | L46: =IF(L17="X",(D17-C17),"0") -> 0 | M46: =IF(M17="X",(D17-C17),"0") -> 1 | N46: =IF(N17="X",(D17-C17),"0") -> 0 | O46: =IF(O17="X",(D17-C17),"0") -> 0 | P46: =IF(P17="X",(D17-C17),"0") -> 0 | Q46: =IF(Q17="X",(D17-C17),"0") -> 1 | R46: =IF(R17="X",(D17-C17),"0") -> 0 | S46: =IF(S17="X",(D17-C17),"0") -> 0 | T46: =IF(T17="X",(D17-C17),"0") -> 1
E47: =IF(E18="X",(D18-C18),"0") -> 0 | F47: =IF(F18="X",(D18-C18),"0") -> 0 | G47: =IF(G18="X",(D18-C18),"0") -> 0.43 | H47: =IF(H18="X",(D18-C18),"0") -> 0 | I47: =IF(I18="X",(D18-C18),"0") -> 0 | J47: =IF(J18="X",(D18-C18),"0") -> 0.43 | K47: =IF(K18="X",(D18-C18),"0") -> 0 | L47: =IF(L18="X",(D18-C18),"0") -> 0 | M47: =IF(M18="X",(D18-C18),"0") -> 0.43 | N47: =IF(N18="X",(D18-C18),"0") -> 0 | O47: =IF(O18="X",(D18-C18),"0") -> 0 | P47: =IF(P18="X",(D18-C18),"0") -> 0 | Q47: =IF(Q18="X",(D18-C18),"0") -> 0.43 | R47: =IF(R18="X",(D18-C18),"0") -> 0 | S47: =IF(S18="X",(D18-C18),"0") -> 0 | T47: =IF(T18="X",(D18-C18),"0") -> 0.43
... E63: =IF(E34="X",(D34-C34),"0") -> 0 | F63: =IF(F34="X",(D34-C34),"0") -> 0 | G63: =IF(G34="X",(D34-C34),"0") -> 0 | H63: =IF(H34="X",(D34-C34),"0") -> 0 | I63: =IF(I34="X",(D34-C34),"0") -> 0 | J63: =IF(J34="X",(D34-C34),"0") -> 0 | K63: =IF(K34="X",(D34-C34),"0") -> 0 | L63: =IF(L34="X",(D34-C34),"0") -> 0 | M63: =IF(M34="X",(D34-C34),"0") -> 0 | N63: =IF(N34="X",(D34-C34),"0") -> 0 | O63: =IF(O34="X",(D34-C34),"0") -> 0 | P63: =IF(P34="X",(D34-C34),"0") -> 0 | Q63: =IF(Q34="X",(D34-C34),"0") -> 0 | R63: =IF(R34="X",(D34-C34),"0") -> 0 | S63: =IF(S34="X",(D34-C34),"0") -> 0 | T63: =IF(T34="X",(D34-C34),"0") -> 0
E66: =SUM(E36:E63) -> 0 | F66: =SUM(F36:F63) -> 0 | G66: =SUM(G36:G63) -> 10.46 | H66: =SUM(H36:H63) -> 0 | I66: =SUM(I36:I63) -> 0 | J66: =SUM(J36:J63) -> 10.46 | K66: =SUM(K36:K63) -> 0 | L66: =SUM(L36:L63) -> 0 | ... T66: =SUM(T36:T63) -> 2.43

Sheet 40
A1: PROGRAMA DE MANUTENÇÃORODOVIÁRIA
D2: RODOVIAS PAVIMENTADAS | I2: DATA: | J2: ='39'!J2 -> 46204 | N2: TÉCNICO RESP. | O2: ='39'!O2 -> ENG. VINICIUS RODRIGUES FERREIRA DE OLIVEIRA | T2: REGIÃO: | U2: 02
A3: FICHA DE INSPEÇÃO: | B3: =TT!C5 -> RODOVIA TO-010 - TRECHO WANDERLÂNDIA - RIACHINHO
A5: S.R.E. | B5: SENTIDO | C5: INÍCIO (KM) | D5: FIM (KM) | E5: CONDIÇÃO DO PAVIMENTO | J5: VEGETAÇÃO | L5: ELEM. DE DRENAGEM | O5: SIN. HOR. | R5: SIN. VERTICAL | U5: OBSERV.
E6: BOM | F6: REM. I. | G6: REM. L | H6: BUR. I | I6: BUR. L | J6: ADEQ. | K6: INADED. | L6: LIMPOS | M6: SUJOS | N6: DAN. | O6: BOM | P6: REG. | Q6: INEXIST. | R6: BOM | S6: POUCAS | T6: INEXIST.
A7: 010ETO0421 | B7: C | C7: 0 | D7: 1.08 | E7: X | J7: X | L7: X | Q7: X | T7: X
A8: 010ETO0422 | B8: C | C8: 0 | D8: 0.71 | E8: X | J8: X | L8: X | Q8: X | T8: X
A9: 010ETO0430 | B9: C | C9: 0 | D9: 1.07 | G9: X | J9: X | M9: X | Q9: X | T9: X
A10: 010ETO0440 | B10: C | C10: 0 | D10: 2.99 | E10: X | J10: X | N10: X | Q10: X | T10: X
A11: 010ETO0470 | B11: C | C11: 0 | D11: 6.4 | E11: X | J11: X | M11: X | O11: X | S11: X
C12: 6.4 | D12: 6.5 | E12: X | J12: X | M12: X | O12: X | S12: X
C13: 6.5 | D13: 22.5 | E13: X | J13: X | M13: X | O13: X | S13: X
C14: 22.5 | D14: 31.1 | E14: X | J14: X | M14: X | O14: X | S14: X
C15: 31.1 | D15: 36.9 | E15: X | J15: X | M15: X | O15: X | S15: X
C16: 36.9 | D16: 42.72 | E16: X | J16: X | M16: X | O16: X | S16: X
A17: 010ETO0480 | B17: C | C17: 0 | D17: 5.23 | E17: X | J17: X | M17: X | O17: X | S17: X
A18: 010ETO0490 | B18: C | C18: 0 | D18: 2.4 | E18: X | J18: X | M18: X | O18: X | S18: X
C19: 2.4 | D19: 6.94 | E19: X | J19: X | M19: X | O19: X | S19: X
A32: LEGENDA | B32: CONDIÇÃO DO PAVIMENTO
A33: REM. I | B33: REMENDOS ISOLADOS | E33: ATÉ 10 REMENDOS/KM | I33: BUR. I | J33: BURACOS ISOLADOS | M33: ATÉ 5 BURACOS/KM
A34: REM. L | B34: REMENDOS AO LONGO | E34: MAIS DE 10 REMENDOS/KM | I34: BUR. L | J34: BURACOS AO LONGO | M34: MAIS DE 5 BURACOS/KM
E39: =IF(E7="X",(D7-C7),"0") -> 1.08 | F39: =IF(F7="X",(D7-C7),"0") -> 0 | G39: =IF(G7="X",(D7-C7),"0") -> 0 | H39: =IF(H7="X",(D7-C7),"0") -> 0 | I39: =IF(I7="X",(D7-C7),"0") -> 0 | J39: =IF(J7="X",(D7-C7),"0") -> 1.08 | K39: =IF(K7="X",(D7-C7),"0") -> 0 | L39: =IF(L7="X",(D7-C7),"0") -> 1.08 | M39: =IF(M7="X",(D7-C7),"0") -> 0 | N39: =IF(N7="X",(D7-C7),"0") -> 0 | O39: =IF(O7="X",(D7-C7),"0") -> 0 | P39: =IF(P7="X",(D7-C7),"0") -> 0 | Q39: =IF(Q7="X",(D7-C7),"0") -> 1.08 | R39: =IF(R7="X",(D7-C7),"0") -> 0 | S39: =IF(S7="X",(D7-C7),"0") -> 0 | T39: =IF(T7="X",(D7-C7),"0") -> 1.08
E40: =IF(E8="X",(D8-C8),"0") -> 0.71 | F40: =IF(F8="X",(D8-C8),"0") -> 0 | G40: =IF(G8="X",(D8-C8),"0") -> 0 | H40: =IF(H8="X",(D8-C8),"0") -> 0 | I40: =IF(I8="X",(D8-C8),"0") -> 0 | J40: =IF(J8="X",(D8-C8),"0") -> 0.71 | K40: =IF(K8="X",(D8-C8),"0") -> 0 | L40: =IF(L8="X",(D8-C8),"0") -> 0.71 | M40: =IF(M8="X",(D8-C8),"0") -> 0 | N40: =IF(N8="X",(D8-C8),"0") -> 0 | O40: =IF(O8="X",(D8-C8),"0") -> 0 | P40: =IF(P8="X",(D8-C8),"0") -> 0 | Q40: =IF(Q8="X",(D8-C8),"0") -> 0.71 | R40: =IF(R8="X",(D8-C8),"0") -> 0 | S40: =IF(S8="X",(D8-C8),"0") -> 0 | T40: =IF(T8="X",(D8-C8),"0") -> 0.71
E41: =IF(E9="X",(D9-C9),"0") -> 0 | F41: =IF(F9="X",(D9-C9),"0") -> 0 | G41: =IF(G9="X",(D9-C9),"0") -> 1.07 | H41: =IF(H9="X",(D9-C9),"0") -> 0 | I41: =IF(I9="X",(D9-C9),"0") -> 0 | J41: =IF(J9="X",(D9-C9),"0") -> 1.07 | K41: =IF(K9="X",(D9-C9),"0") -> 0 | L41: =IF(L9="X",(D9-C9),"0") -> 0 | M41: =IF(M9="X",(D9-C9),"0") -> 1.07 | N41: =IF(N9="X",(D9-C9),"0") -> 0 | O41: =IF(O9="X",(D9-C9),"0") -> 0 | P41: =IF(P9="X",(D9-C9),"0") -> 0 | Q41: =IF(Q9="X",(D9-C9),"0") -> 1.07 | R41: =IF(R9="X",(D9-C9),"0") -> 0 | S41: =IF(S9="X",(D9-C9),"0") -> 0 | T41: =IF(T9="X",(D9-C9),"0") -> 1.07
E42: =IF(E10="X",(D10-C10),"0") -> 2.99 | F42: =IF(F10="X",(D10-C10),"0") -> 0 | G42: =IF(G10="X",(D10-C10),"0") -> 0 | H42: =IF(H10="X",(D10-C10),"0") -> 0 | I42: =IF(I10="X",(D10-C10),"0") -> 0 | J42: =IF(J10="X",(D10-C10),"0") -> 2.99 | K42: =IF(K10="X",(D10-C10),"0") -> 0 | L42: =IF(L10="X",(D10-C10),"0") -> 0 | M42: =IF(M10="X",(D10-C10),"0") -> 0 | N42: =IF(N10="X",(D10-C10),"0") -> 2.99 | O42: =IF(O10="X",(D10-C10),"0") -> 0 | P42: =IF(P10="X",(D10-C10),"0") -> 0 | Q42: =IF(Q10="X",(D10-C10),"0") -> 2.99 | R42: =IF(R10="X",(D10-C10),"0") -> 0 | S42: =IF(S10="X",(D10-C10),"0") -> 0 | T42: =IF(T10="X",(D10-C10),"0") -> 2.99
E43: =IF(E11="X",(D11-C11),"0") -> 6.4 | F43: =IF(F11="X",(D11-C11),"0") -> 0 | G43: =IF(G11="X",(D11-C11),"0") -> 0 | H43: =IF(H11="X",(D11-C11),"0") -> 0 | I43: =IF(I11="X",(D11-C11),"0") -> 0 | J43: =IF(J11="X",(D11-C11),"0") -> 6.4 | K43: =IF(K11="X",(D11-C11),"0") -> 0 | L43: =IF(L11="X",(D11-C11),"0") -> 0 | M43: =IF(M11="X",(D11-C11),"0") -> 6.4 | N43: =IF(N11="X",(D11-C11),"0") -> 0 | O43: =IF(O11="X",(D11-C11),"0") -> 6.4 | P43: =IF(P11="X",(D11-C11),"0") -> 0 | Q43: =IF(Q11="X",(D11-C11),"0") -> 0 | R43: =IF(R11="X",(D11-C11),"0") -> 0 | S43: =IF(S11="X",(D11-C11),"0") -> 6.4 | T43: =IF(T11="X",(D11-C11),"0") -> 0
E44: =IF(E12="X",(D12-C12),"0") -> 0.1 | F44: =IF(F12="X",(D12-C12),"0") -> 0 | G44: =IF(G12="X",(D12-C12),"0") -> 0 | H44: =IF(H12="X",(D12-C12),"0") -> 0 | I44: =IF(I12="X",(D12-C12),"0") -> 0 | J44: =IF(J12="X",(D12-C12),"0") -> 0.1 | K44: =IF(K12="X",(D12-C12),"0") -> 0 | L44: =IF(L12="X",(D12-C12),"0") -> 0 | M44: =IF(M12="X",(D12-C12),"0") -> 0.1 | N44: =IF(N12="X",(D12-C12),"0") -> 0 | O44: =IF(O12="X",(D12-C12),"0") -> 0.1 | P44: =IF(P12="X",(D12-C12),"0") -> 0 | Q44: =IF(Q12="X",(D12-C12),"0") -> 0 | R44: =IF(R12="X",(D12-C12),"0") -> 0 | S44: =IF(S12="X",(D12-C12),"0") -> 0.1 | T44: =IF(T12="X",(D12-C12),"0") -> 0
E45: =IF(E13="X",(D13-C13),"0") -> 16 | F45: =IF(F13="X",(D13-C13),"0") -> 0 | G45: =IF(G13="X",(D13-C13),"0") -> 0 | H45: =IF(H13="X",(D13-C13),"0") -> 0 | I45: =IF(I13="X",(D13-C13),"0") -> 0 | J45: =IF(J13="X",(D13-C13),"0") -> 16 | K45: =IF(K13="X",(D13-C13),"0") -> 0 | L45: =IF(L13="X",(D13-C13),"0") -> 0 | M45: =IF(M13="X",(D13-C13),"0") -> 16 | N45: =IF(N13="X",(D13-C13),"0") -> 0 | O45: =IF(O13="X",(D13-C13),"0") -> 16 | P45: =IF(P13="X",(D13-C13),"0") -> 0 | Q45: =IF(Q13="X",(D13-C13),"0") -> 0 | R45: =IF(R13="X",(D13-C13),"0") -> 0 | S45: =IF(S13="X",(D13-C13),"0") -> 16 | T45: =IF(T13="X",(D13-C13),"0") -> 0
E46: =IF(E14="X",(D14-C14),"0") -> 8.6 | F46: =IF(F14="X",(D14-C14),"0") -> 0 | G46: =IF(G14="X",(D14-C14),"0") -> 0 | H46: =IF(H14="X",(D14-C14),"0") -> 0 | I46: =IF(I14="X",(D14-C14),"0") -> 0 | J46: =IF(J14="X",(D14-C14),"0") -> 8.6 | K46: =IF(K14="X",(D14-C14),"0") -> 0 | L46: =IF(L14="X",(D14-C14),"0") -> 0 | M46: =IF(M14="X",(D14-C14),"0") -> 8.6 | N46: =IF(N14="X",(D14-C14),"0") -> 0 | O46: =IF(O14="X",(D14-C14),"0") -> 8.6 | P46: =IF(P14="X",(D14-C14),"0") -> 0 | Q46: =IF(Q14="X",(D14-C14),"0") -> 0 | R46: =IF(R14="X",(D14-C14),"0") -> 0 | S46: =IF(S14="X",(D14-C14),"0") -> 8.6 | T46: =IF(T14="X",(D14-C14),"0") -> 0
E47: =IF(E15="X",(D15-C15),"0") -> 5.8 | F47: =IF(F15="X",(D15-C15),"0") -> 0 | G47: =IF(G15="X",(D15-C15),"0") -> 0 | H47: =IF(H15="X",(D15-C15),"0") -> 0 | I47: =IF(I15="X",(D15-C15),"0") -> 0 | J47: =IF(J15="X",(D15-C15),"0") -> 5.8 | K47: =IF(K15="X",(D15-C15),"0") -> 0 | L47: =IF(L15="X",(D15-C15),"0") -> 0 | M47: =IF(M15="X",(D15-C15),"0") -> 5.8 | N47: =IF(N15="X",(D15-C15),"0") -> 0 | O47: =IF(O15="X",(D15-C15),"0") -> 5.8 | P47: =IF(P15="X",(D15-C15),"0") -> 0 | Q47: =IF(Q15="X",(D15-C15),"0") -> 0 | R47: =IF(R15="X",(D15-C15),"0") -> 0 | S47: =IF(S15="X",(D15-C15),"0") -> 5.8 | T47: =IF(T15="X",(D15-C15),"0") -> 0
E48: =IF(E16="X",(D16-C16),"0") -> 5.82 | F48: =IF(F16="X",(D16-C16),"0") -> 0 | G48: =IF(G16="X",(D16-C16),"0") -> 0 | H48: =IF(H16="X",(D16-C16),"0") -> 0 | I48: =IF(I16="X",(D16-C16),"0") -> 0 | J48: =IF(J16="X",(D16-C16),"0") -> 5.82 | K48: =IF(K16="X",(D16-C16),"0") -> 0 | L48: =IF(L16="X",(D16-C16),"0") -> 0 | M48: =IF(M16="X",(D16-C16),"0") -> 5.82 | N48: =IF(N16="X",(D16-C16),"0") -> 0 | O48: =IF(O16="X",(D16-C16),"0") -> 5.82 | P48: =IF(P16="X",(D16-C16),"0") -> 0 | Q48: =IF(Q16="X",(D16-C16),"0") -> 0 | R48: =IF(R16="X",(D16-C16),"0") -> 0 | S48: =IF(S16="X",(D16-C16),"0") -> 5.82 | T48: =IF(T16="X",(D16-C16),"0") -> 0
E49: =IF(E17="X",(D17-C17),"0") -> 5.23 | F49: =IF(F17="X",(D17-C17),"0") -> 0 | G49: =IF(G17="X",(D17-C17),"0") -> 0 | H49: =IF(H17="X",(D17-C17),"0") -> 0 | I49: =IF(I17="X",(D17-C17),"0") -> 0 | J49: =IF(J17="X",(D17-C17),"0") -> 5.23 | K49: =IF(K17="X",(D17-C17),"0") -> 0 | L49: =IF(L17="X",(D17-C17),"0") -> 0 | M49: =IF(M17="X",(D17-C17),"0") -> 5.23 | N49: =IF(N17="X",(D17-C17),"0") -> 0 | O49: =IF(O17="X",(D17-C17),"0") -> 5.23 | P49: =IF(P17="X",(D17-C17),"0") -> 0 | Q49: =IF(Q17="X",(D17-C17),"0") -> 0 | R49: =IF(R17="X",(D17-C17),"0") -> 0 | S49: =IF(S17="X",(D17-C17),"0") -> 5.23 | T49: =IF(T17="X",(D17-C17),"0") -> 0
E50: =IF(E18="X",(D18-C18),"0") -> 2.4 | F50: =IF(F18="X",(D18-C18),"0") -> 0 | G50: =IF(G18="X",(D18-C18),"0") -> 0 | H50: =IF(H18="X",(D18-C18),"0") -> 0 | I50: =IF(I18="X",(D18-C18),"0") -> 0 | J50: =IF(J18="X",(D18-C18),"0") -> 2.4 | K50: =IF(K18="X",(D18-C18),"0") -> 0 | L50: =IF(L18="X",(D18-C18),"0") -> 0 | M50: =IF(M18="X",(D18-C18),"0") -> 2.4 | N50: =IF(N18="X",(D18-C18),"0") -> 0 | O50: =IF(O18="X",(D18-C18),"0") -> 2.4 | P50: =IF(P18="X",(D18-C18),"0") -> 0 | Q50: =IF(Q18="X",(D18-C18),"0") -> 0 | R50: =IF(R18="X",(D18-C18),"0") -> 0 | S50: =IF(S18="X",(D18-C18),"0") -> 2.4 | T50: =IF(T18="X",(D18-C18),"0") -> 0
... E127: =IF(E95="X",(D95-C95),"0") -> 0 | F127: =IF(F95="X",(D95-C95),"0") -> 0 | G127: =IF(G95="X",(D95-C95),"0") -> 0 | H127: =IF(H95="X",(D95-C95),"0") -> 0 | I127: =IF(I95="X",(D95-C95),"0") -> 0 | J127: =IF(J95="X",(D95-C95),"0") -> 0 | K127: =IF(K95="X",(D95-C95),"0") -> 0 | L127: =IF(L95="X",(D95-C95),"0") -> 0 | M127: =IF(M95="X",(D95-C95),"0") -> 0 | N127: =IF(N95="X",(D95-C95),"0") -> 0 | O127: =IF(O95="X",(D95-C95),"0") -> 0 | P127: =IF(P95="X",(D95-C95),"0") -> 0 | Q127: =IF(Q95="X",(D95-C95),"0") -> 0 | R127: =IF(R95="X",(D95-C95),"0") -> 0 | S127: =IF(S95="X",(D95-C95),"0") -> 0 | T127: =IF(T95="X",(D95-C95),"0") -> 0
E130: =SUM(E39:E127) -> 59.67 | F130: =SUM(F39:F127) -> 0 | G130: =SUM(G39:G127) -> 1.07 | H130: =SUM(H39:H127) -> 0 | I130: =SUM(I39:I127) -> 0 | J130: =SUM(J39:J127) -> 60.74 | K130: =SUM(K39:K127) -> 0 | L130: =SUM(L39:L127) -> 1.79 | ... T130: =SUM(T39:T127) -> 5.85

Sheet 41
A1: PROGRAMA DE MANUTENÇÃORODOVIÁRIA
D2: RODOVIAS PAVIMENTADAS | I2: DATA: | J2: ='39'!J2 -> 46204 | N2: TÉCNICO RESP. | O2: ='39'!O2 -> ENG. VINICIUS RODRIGUES FERREIRA DE OLIVEIRA | T2: REGIÃO: | U2: 02
A3: FICHA DE INSPEÇÃO: | B3: =TT!C6 -> RODOVIA TO-164 - TRECHO ENTR. BR-153 (XAMBIOÁ) - ARAGUANÃ
A5: S.R.E. | B5: SENTIDO | C5: INÍCIO (KM) | D5: FIM (KM) | E5: CONDIÇÃO DO PAVIMENTO | J5: VEGETAÇÃO | L5: ELEM. DE DRENAGEM | O5: SIN. HOR. | R5: SIN. VERTICAL | U5: OBSERV.
E6: BOM | F6: REM. I. | G6: REM. L | H6: BUR. I | I6: BUR. L | J6: ADEQ. | K6: INADED. | L6: LIMPOS | M6: SUJOS | N6: DAN. | O6: BOM | P6: REG. | Q6: INEXIST. | R6: BOM | S6: POUCAS | T6: INEXIST.
A7: 164ETO0100 | B7: C | C7: 0 | D7: 1 | E7: X | J7: X | M7: X | O7: X | R7: X
C8: =D7 -> 1 | D8: 2 | E8: X | J8: X | M8: X | O8: X | R8: X
C9: =D8 -> 2 | D9: 3 | E9: X | J9: X | M9: X | O9: X | R9: X
C10: =D9 -> 3 | D10: 4 | E10: X | J10: X | M10: X | O10: X | R10: X
C11: =D10 -> 4 | D11: 5 | E11: X | J11: X | M11: X | O11: X | R11: X
C12: =D11 -> 5 | D12: 6 | F12: X | J12: X | M12: X | O12: X | R12: X
C13: =D12 -> 6 | D13: 7 | E13: X | J13: X | M13: X | O13: X | R13: X
C14: =D13 -> 7 | D14: 8 | E14: X | J14: X | M14: X | O14: X | R14: X
C15: =D14 -> 8 | D15: 9 | E15: X | J15: X | M15: X | O15: X | R15: X
C16: =D15 -> 9 | D16: 10 | H16: X | J16: X | M16: X | O16: X | R16: X
C17: =D16 -> 10 | D17: 11 | G17: X | J17: X | M17: X | O17: X | R17: X
C18: =D17 -> 11 | D18: 12 | E18: X | J18: X | M18: X | O18: X | R18: X
C19: =D18 -> 12 | D19: 13 | E19: X | J19: X | M19: X | O19: X | R19: X
C20: =D19 -> 13 | D20: 14 | E20: X | J20: X | M20: X | O20: X | R20: X
C21: =D20 -> 14 | D21: 15 | G21: X | J21: X | M21: X | O21: X | R21: X
C22: =D21 -> 15 | D22: 16 | G22: X | J22: X | M22: X | O22: X | R22: X
C23: =D22 -> 16 | D23: 17 | G23: X | J23: X | M23: X | O23: X | R23: X
C24: =D23 -> 17 | D24: 18 | E24: X | J24: X | M24: X | O24: X | R24: X
C25: =D24 -> 18 | D25: 19 | E25: X | J25: X | M25: X | O25: X | R25: X
C26: =D25 -> 19 | D26: 19.23 | E26: X | J26: X | M26: X | O26: X | R26: X
A27: 164ETO0101 | B27: C | C27: 0 | D27: 1 | E27: X | J27: X | L27: X | O27: X | R27: X
C28: =D27 -> 1 | D28: 2 | E28: X | J28: X | L28: X | O28: X | R28: X
C29: =D28 -> 2 | D29: 2.56 | E29: X | J29: X | L29: X | O29: X | R29: X
A30: 164ETO0095 | B30: C | C30: 0 | D30: 1 | E30: X | J30: X | M30: X | O30: X | R30: X
C31: =D30 -> 1 | D31: 2 | E31: X | J31: X | M31: X | O31: X | R31: X
C32: =D31 -> 2 | D32: 3 | E32: X | J32: X | M32: X | O32: X | R32: X
C33: =D32 -> 3 | D33: 3.92 | E33: X | J33: X | M33: X | O33: X | R33: X
A42: LEGENDA | B42: CONDIÇÃO DO PAVIMENTO
A43: REM. I | B43: REMENDOS ISOLADOS | E43: ATÉ 10 REMENDOS/KM | I43: BUR. I | J43: BURACOS ISOLADOS | M43: ATÉ 5 BURACOS/KM
A44: REM. L | B44: REMENDOS AO LONGO | E44: MAIS DE 10 REMENDOS/KM | I44: BUR. L | J44: BURACOS AO LONGO | M44: MAIS DE 5 BURACOS/KM
E49: =IF(E7="X",(D7-C7),"0") -> 1 | F49: =IF(F7="X",(D7-C7),"0") -> 0 | G49: =IF(G7="X",(D7-C7),"0") -> 0 | H49: =IF(H7="X",(D7-C7),"0") -> 0 | I49: =IF(I7="X",(D7-C7),"0") -> 0 | J49: =IF(J7="X",(D7-C7),"0") -> 1 | K49: =IF(K7="X",(D7-C7),"0") -> 0 | L49: =IF(L7="X",(D7-C7),"0") -> 0 | M49: =IF(M7="X",(D7-C7),"0") -> 1 | N49: =IF(N7="X",(D7-C7),"0") -> 0 | O49: =IF(O7="X",(D7-C7),"0") -> 1 | P49: =IF(P7="X",(D7-C7),"0") -> 0 | Q49: =IF(Q7="X",(D7-C7),"0") -> 0 | R49: =IF(R7="X",(D7-C7),"0") -> 1 | S49: =IF(S7="X",(D7-C7),"0") -> 0 | T49: =IF(T7="X",(D7-C7),"0") -> 0
E50: =IF(E8="X",(D8-C8),"0") -> 1 | F50: =IF(F8="X",(D8-C8),"0") -> 0 | G50: =IF(G8="X",(D8-C8),"0") -> 0 | H50: =IF(H8="X",(D8-C8),"0") -> 0 | I50: =IF(I8="X",(D8-C8),"0") -> 0 | J50: =IF(J8="X",(D8-C8),"0") -> 1 | K50: =IF(K8="X",(D8-C8),"0") -> 0 | L50: =IF(L8="X",(D8-C8),"0") -> 0 | M50: =IF(M8="X",(D8-C8),"0") -> 1 | N50: =IF(N8="X",(D8-C8),"0") -> 0 | O50: =IF(O8="X",(D8-C8),"0") -> 1 | P50: =IF(P8="X",(D8-C8),"0") -> 0 | Q50: =IF(Q8="X",(D8-C8),"0") -> 0 | R50: =IF(R8="X",(D8-C8),"0") -> 1 | S50: =IF(S8="X",(D8-C8),"0") -> 0 | T50: =IF(T8="X",(D8-C8),"0") -> 0
E51: =IF(E9="X",(D9-C9),"0") -> 1 | F51: =IF(F9="X",(D9-C9),"0") -> 0 | G51: =IF(G9="X",(D9-C9),"0") -> 0 | H51: =IF(H9="X",(D9-C9),"0") -> 0 | I51: =IF(I9="X",(D9-C9),"0") -> 0 | J51: =IF(J9="X",(D9-C9),"0") -> 1 | K51: =IF(K9="X",(D9-C9),"0") -> 0 | L51: =IF(L9="X",(D9-C9),"0") -> 0 | M51: =IF(M9="X",(D9-C9),"0") -> 1 | N51: =IF(N9="X",(D9-C9),"0") -> 0 | O51: =IF(O9="X",(D9-C9),"0") -> 1 | P51: =IF(P9="X",(D9-C9),"0") -> 0 | Q51: =IF(Q9="X",(D9-C9),"0") -> 0 | R51: =IF(R9="X",(D9-C9),"0") -> 1 | S51: =IF(S9="X",(D9-C9),"0") -> 0 | T51: =IF(T9="X",(D9-C9),"0") -> 0
E52: =IF(E10="X",(D10-C10),"0") -> 1 | F52: =IF(F10="X",(D10-C10),"0") -> 0 | G52: =IF(G10="X",(D10-C10),"0") -> 0 | H52: =IF(H10="X",(D10-C10),"0") -> 0 | I52: =IF(I10="X",(D10-C10),"0") -> 0 | J52: =IF(J10="X",(D10-C10),"0") -> 1 | K52: =IF(K10="X",(D10-C10),"0") -> 0 | L52: =IF(L10="X",(D10-C10),"0") -> 0 | M52: =IF(M10="X",(D10-C10),"0") -> 1 | N52: =IF(N10="X",(D10-C10),"0") -> 0 | O52: =IF(O10="X",(D10-C10),"0") -> 1 | P52: =IF(P10="X",(D10-C10),"0") -> 0 | Q52: =IF(Q10="X",(D10-C10),"0") -> 0 | R52: =IF(R10="X",(D10-C10),"0") -> 1 | S52: =IF(S10="X",(D10-C10),"0") -> 0 | T52: =IF(T10="X",(D10-C10),"0") -> 0
E53: =IF(E11="X",(D11-C11),"0") -> 1 | F53: =IF(F11="X",(D11-C11),"0") -> 0 | G53: =IF(G11="X",(D11-C11),"0") -> 0 | H53: =IF(H11="X",(D11-C11),"0") -> 0 | I53: =IF(I11="X",(D11-C11),"0") -> 0 | J53: =IF(J11="X",(D11-C11),"0") -> 1 | K53: =IF(K11="X",(D11-C11),"0") -> 0 | L53: =IF(L11="X",(D11-C11),"0") -> 0 | M53: =IF(M11="X",(D11-C11),"0") -> 1 | N53: =IF(N11="X",(D11-C11),"0") -> 0 | O53: =IF(O11="X",(D11-C11),"0") -> 1 | P53: =IF(P11="X",(D11-C11),"0") -> 0 | Q53: =IF(Q11="X",(D11-C11),"0") -> 0 | R53: =IF(R11="X",(D11-C11),"0") -> 1 | S53: =IF(S11="X",(D11-C11),"0") -> 0 | T53: =IF(T11="X",(D11-C11),"0") -> 0
...

Sheet 42
A1: PROGRAMA DE MANUTENÇÃORODOVIÁRIA
D2: RODOVIAS PAVIMENTADAS | I2: DATA: | J2: ='39'!J2 -> 46204 | N2: TÉCNICO RESP. | O2: ='39'!O2 -> ENG. VINICIUS RODRIGUES FERREIRA DE OLIVEIRA | T2: REGIÃO: | U2: 02
A3: FICHA DE INSPEÇÃO: | B3: =TT!C7 -> RODOVIA TO-164 - TRECHO FÁBRICA DE CIMENTO - XAMBIOÁ - ENTR. BR-153
A5: S.R.E. | B5: SENTIDO | C5: INÍCIO (KM) | D5: FIM (KM) | E5: CONDIÇÃO DO PAVIMENTO | J5: VEGETAÇÃO | L5: ELEM. DE DRENAGEM | O5: SIN. HOR. | R5: SIN. VERTICAL | U5: OBSERV.
E6: BOM | F6: REM. I. | G6: REM. L | H6: BUR. I | I6: BUR. L | J6: ADEQ. | K6: INADED. | L6: LIMPOS | M6: SUJOS | N6: DAN. | O6: BOM | P6: REG. | Q6: INEXIST. | R6: BOM | S6: POUCAS | T6: INEXIST.
A7: 164ETO0090 | B7: D | C7: 0 | D7: 1 | I7: X | J7: X | M7: X | Q7: X | T7: X
C8: =D7 -> 1 | D8: 2 | I8: X | J8: X | M8: X | Q8: X | T8: X
C9: =D8 -> 2 | D9: 3 | I9: X | J9: X | M9: X | Q9: X | T9: X
C10: =D9 -> 3 | D10: 3.62 | I10: X | J10: X | M10: X | Q10: X | T10: X
A11: 164ETO0080 | B11: D | C11: 0 | D11: 1 | I11: X | J11: X | M11: X | Q11: X | T11: X
C12: =D11 -> 1 | D12: 2 | I12: X | J12: X | M12: X | Q12: X | T12: X
C13: =D12 -> 2 | D13: 3 | I13: X | J13: X | M13: X | Q13: X | T13: X
C14: =D13 -> 3 | D14: 4 | E14: X | J14: X | M14: X | Q14: X | T14: X
C15: =D14 -> 4 | D15: 5 | I15: X | J15: X | M15: X | Q15: X | T15: X
C16: =D15 -> 5 | D16: 5.91 | E16: X | J16: X | M16: X | Q16: X | T16: X
A17: 164ETO0070 | B17: D | C17: 0 | D17: 1 | E17: X | J17: X | M17: X | Q17: X | T17: X
C18: =D17 -> 1 | D18: 2 | E18: X | J18: X | M18: X | Q18: X | T18: X
C19: =D18 -> 2 | D19: 3 | E19: X | J19: X | M19: X | Q19: X | T19: X
C20: =D19 -> 3 | D20: 3.92 | E20: X | J20: X | M20: X | Q20: X | T20: X
A29: LEGENDA | B29: CONDIÇÃO DO PAVIMENTO
A30: REM. I | B30: REMENDOS ISOLADOS | E30: ATÉ 10 REMENDOS/KM | I30: BUR. I | J30: BURACOS ISOLADOS | M30: ATÉ 5 BURACOS/KM
A31: REM. L | B31: REMENDOS AO LONGO | E31: MAIS DE 10 REMENDOS/KM | I31: BUR. L | J31: BURACOS AO LONGO | M31: MAIS DE 5 BURACOS/KM
E36: =IF(E7="X",(D7-C7),"0") -> 0 | F36: =IF(F7="X",(D7-C7),"0") -> 0 | G36: =IF(G7="X",(D7-C7),"0") -> 0 | H36: =IF(H7="X",(D7-C7),"0") -> 0 | I36: =IF(I7="X",(D7-C7),"0") -> 1 | J36: =IF(J7="X",(D7-C7),"0") -> 1 | K36: =IF(K7="X",(D7-C7),"0") -> 0 | L36: =IF(L7="X",(D7-C7),"0") -> 0 | M36: =IF(M7="X",(D7-C7),"0") -> 1 | N36: =IF(N7="X",(D7-C7),"0") -> 0 | O36: =IF(O7="X",(D7-C7),"0") -> 0 | P36: =IF(P7="X",(D7-C7),"0") -> 0 | Q36: =IF(Q7="X",(D7-C7),"0") -> 1 | R36: =IF(R7="X",(D7-C7),"0") -> 0 | S36: =IF(S7="X",(D7-C7),"0") -> 0 | T36: =IF(T7="X",(D7-C7),"0") -> 1
E37: =IF(E8="X",(D8-C8),"0") -> 0 | F37: =IF(F8="X",(D8-C8),"0") -> 0 | G37: =IF(G8="X",(D8-C8),"0") -> 0 | H37: =IF(H8="X",(D8-C8),"0") -> 0 | I37: =IF(I8="X",(D8-C8),"0") -> 1 | J37: =IF(J8="X",(D8-C8),"0") -> 1 | K37: =IF(K8="X",(D8-C8),"0") -> 0 | L37: =IF(L8="X",(D8-C8),"0") -> 0 | M37: =IF(M8="X",(D8-C8),"0") -> 1 | N37: =IF(N8="X",(D8-C8),"0") -> 0 | O37: =IF(O8="X",(D8-C8),"0") -> 0 | P37: =IF(P8="X",(D8-C8),"0") -> 0 | Q37: =IF(Q8="X",(D8-C8),"0") -> 1 | R37: =IF(R8="X",(D8-C8),"0") -> 0 | S37: =IF(S8="X",(D8-C8),"0") -> 0 | T37: =IF(T8="X",(D8-C8),"0") -> 1
E38: =IF(E9="X",(D9-C9),"0") -> 0 | F38: =IF(F9="X",(D9-C9),"0") -> 0 | G38: =IF(G9="X",(D9-C9),"0") -> 0 | H38: =IF(H9="X",(D9-C9),"0") -> 0 | I38: =IF(I9="X",(D9-C9),"0") -> 1 | J38: =IF(J9="X",(D9-C9),"0") -> 1 | K38: =IF(K9="X",(D9-C9),"0") -> 0 | L38: =IF(L9="X",(D9-C9),"0") -> 0 | M38: =IF(M9="X",(D9-C9),"0") -> 1 | N38: =IF(N9="X",(D9-C9),"0") -> 0 | O38: =IF(O9="X",(D9-C9),"0") -> 0 | P38: =IF(P9="X",(D9-C9),"0") -> 0 | Q38: =IF(Q9="X",(D9-C9),"0") -> 1 | R38: =IF(R9="X",(D9-C9),"0") -> 0 | S38: =IF(S9="X",(D9-C9),"0") -> 0 | T38: =IF(T9="X",(D9-C9),"0") -> 1
E39: =IF(E10="X",(D10-C10),"0") -> 0 | F39: =IF(F10="X",(D10-C10),"0") -> 0 | G39: =IF(G10="X",(D10-C10),"0") -> 0 | H39: =IF(H10="X",(D10-C10),"0") -> 0 | I39: =IF(I10="X",(D10-C10),"0") -> 0.62 | J39: =IF(J10="X",(D10-C10),"0") -> 0.62 | K39: =IF(K10="X",(D10-C10),"0") -> 0 | L39: =IF(L10="X",(D10-C10),"0") -> 0 | M39: =IF(M10="X",(D10-C10),"0") -> 0.62 | N39: =IF(N10="X",(D10-C10),"0") -> 0 | O39: =IF(O10="X",(D10-C10),"0") -> 0 | P39: =IF(P10="X",(D10-C10),"0") -> 0 | Q39: =IF(Q10="X",(D10-C10),"0") -> 0.62 | R39: =IF(R10="X",(D10-C10),"0") -> 0 | S39: =IF(S10="X",(D10-C10),"0") -> 0 | T39: =IF(T10="X",(D10-C10),"0") -> 0.62
E40: =IF(E11="X",(D11-C11),"0") -> 0 | F40: =IF(F11="X",(D11-C11),"0") -> 0 | G40: =IF(G11="X",(D11-C11),"0") -> 0 | H40: =IF(H11="X",(D11-C11),"0") -> 0 | I40: =IF(I11="X",(D11-C11),"0") -> 1 | J40: =IF(J11="X",(D11-C11),"0") -> 1 | K40: =IF(K11="X",(D11-C11),"0") -> 0 | L40: =IF(L11="X",(D11-C11),"0") -> 0 | M40: =IF(M11="X",(D11-C11),"0") -> 1 | N40: =IF(N11="X",(D11-C11),"0") -> 0 | O40: =IF(O11="X",(D11-C11),"0") -> 0 | P40: =IF(P11="X",(D11-C11),"0") -> 0 | Q40: =IF(Q11="X",(D11-C11),"0") -> 1 | R40: =IF(R11="X",(D11-C11),"0") -> 0 | S40: =IF(S11="X",(D11-C11),"0") -> 0 | T40: =IF(T11="X",(D11-C11),"0") -> 1
E41: =IF(E12="X",(D12-C12),"0") -> 0 | F41: =IF(F12="X",(D12-C12),"0") -> 0 | G41: =IF(G12="X",(D12-C12),"0") -> 0 | H41: =IF(H12="X",(D12-C12),"0") -> 0 | I41: =IF(I12="X",(D12-C12),"0") -> 1 | J41: =IF(J12="X",(D12-C12),"0") -> 1 | K41: =IF(K12="X",(D12-C12),"0") -> 0 | L41: =IF(L12="X",(D12-C12),"0") -> 0 | M41: =IF(M12="X",(D12-C12),"0") -> 1 | N41: =IF(N12="X",(D12-C12),"0") -> 0 | O41: =IF(O12="X",(D12-C12),"0") -> 0 | P41: =IF(P12="X",(D12-C12),"0") -> 0 | Q41: =IF(Q12="X",(D12-C12),"0") -> 1 | R41: =IF(R12="X",(D12-C12),"0") -> 0 | S41: =IF(S12="X",(D12-C12),"0") -> 0 | T41: =IF(T12="X",(D12-C12),"0") -> 1
E42: =IF(E13="X",(D13-C13),"0") -> 0 | F42: =IF(F13="X",(D13-C13),"0") -> 0 | G42: =IF(G13="X",(D13-C13),"0") -> 0 | H42: =IF(H13="X",(D13-C13),"0") -> 0 | I42: =IF(I13="X",(D13-C13),"0") -> 1 | J42: =IF(J13="X",(D13-C13),"0") -> 1 | K42: =IF(K13="X",(D13-C13),"0") -> 0 | L42: =IF(L13="X",(D13-C13),"0") -> 0 | M42: =IF(M13="X",(D13-C13),"0") -> 1 | N42: =IF(N13="X",(D13-C13),"0") -> 0 | O42: =IF(O13="X",(D13-C13),"0") -> 0 | P42: =IF(P13="X",(D13-C13),"0") -> 0 | Q42: =IF(Q13="X",(D13-C13),"0") -> 1 | R42: =IF(R13="X",(D13-C13),"0") -> 0 | S42: =IF(S13="X",(D13-C13),"0") -> 0 | T42: =IF(T13="X",(D13-C13),"0") -> 1
E43: =IF(E14="X",(D14-C14),"0") -> 1 | F43: =IF(F14="X",(D14-C14),"0") -> 0 | G43: =IF(G14="X",(D14-C14),"0") -> 0 | H43: =IF(H14="X",(D14-C14),"0") -> 0 | I43: =IF(I14="X",(D14-C14),"0") -> 0 | J43: =IF(J14="X",(D14-C14),"0") -> 1 | K43: =IF(K14="X",(D14-C14),"0") -> 0 | L43: =IF(L14="X",(D14-C14),"0") -> 0 | M43: =IF(M14="X",(D14-C14),"0") -> 1 | N43: =IF(N14="X",(D14-C14),"0") -> 0 | O43: =IF(O14="X",(D14-C14),"0") -> 0 | P43: =IF(P14="X",(D14-C14),"0") -> 0 | Q43: =IF(Q14="X",(D14-C14),"0") -> 1 | R43: =IF(R14="X",(D14-C14),"0") -> 0 | S43: =IF(S14="X",(D14-C14),"0") -> 0 | T43: =IF(T14="X",(D14-C14),"0") -> 1
E44: =IF(E15="X",(D15-C15),"0") -> 0 | F44: =IF(F15="X",(D15-C15),"0") -> 0 | G44: =IF(G15="X",(D15-C15),"0") -> 0 | H44: =IF(H15="X",(D15-C15),"0") -> 0 | I44: =IF(I15="X",(D15-C15),"0") -> 1 | J44: =IF(J15="X",(D15-C15),"0") -> 1 | K44: =IF(K15="X",(D15-C15),"0") -> 0 | L44: =IF(L15="X",(D15-C15),"0") -> 0 | M44: =IF(M15="X",(D15-C15),"0") -> 1 | N44: =IF(N15="X",(D15-C15),"0") -> 0 | O44: =IF(O15="X",(D15-C15),"0") -> 0 | P44: =IF(P15="X",(D15-C15),"0") -> 0 | Q44: =IF(Q15="X",(D15-C15),"0") -> 1 | R44: =IF(R15="X",(D15-C15),"0") -> 0 | S44: =IF(S15="X",(D15-C15),"0") -> 0 | T44: =IF(T15="X",(D15-C15),"0") -> 1
E45: =IF(E16="X",(D16-C16),"0") -> 0.91 | F45: =IF(F16="X",(D16-C16),"0") -> 0 | G45: =IF(G16="X",(D16-C16),"0") -> 0 | H45: =IF(H16="X",(D16-C16),"0") -> 0 | I45: =IF(I16="X",(D16-C16),"0") -> 0 | J45: =IF(J16="X",(D16-C16),"0") -> 0.91 | K45: =IF(K16="X",(D16-C16),"0") -> 0 | L45: =IF(L16="X",(D16-C16),"0") -> 0 | M45: =IF(M16="X",(D16-C16),"0") -> 0.91 | N45: =IF(N16="X",(D16-C16),"0") -> 0 | O45: =IF(O16="X",(D16-C16),"0") -> 0 | P45: =IF(P16="X",(D16-C16),"0") -> 0 | Q45: =IF(Q16="X",(D16-C16),"0") -> 0.91 | R45: =IF(R16="X",(D16-C16),"0") -> 0 | S45: =IF(S16="X",(D16-C16),"0") -> 0 | T45: =IF(T16="X",(D16-C16),"0") -> 0.91
E46: =IF(E17="X",(D17-C17),"0") -> 1 | F46: =IF(F17="X",(D17-C17),"0") -> 0 | G46: =IF(G17="X",(D17-C17),"0") -> 0 | H46: =IF(H17="X",(D17-C17),"0") -> 0 | I46: =IF(I17="X",(D17-C17),"0") -> 0 | J46: =IF(J17="X",(D17-C17),"0") -> 1 | K46: =IF(K17="X",(D17-C17),"0") -> 0 | L46: =IF(L17="X",(D17-C17),"0") -> 0 | M46: =IF(M17="X",(D17-C17),"0") -> 1 | N46: =IF(N17="X",(D17-C17),"0") -> 0 | O46: =IF(O17="X",(D17-C17),"0") -> 0 | P46: =IF(P17="X",(D17-C17),"0") -> 0 | Q46: =IF(Q17="X",(D17-C17),"0") -> 1 | R46: =IF(R17="X",(D17-C17),"0") -> 0 | S46: =IF(S17="X",(D17-C17),"0") -> 0 | T46: =IF(T17="X",(D17-C17),"0") -> 1
E47: =IF(E18="X",(D18-C18),"0") -> 1 | F47: =IF(F18="X",(D18-C18),"0") -> 0 | G47: =IF(G18="X",(D18-C18),"0") -> 0 | H47: =IF(H18="X",(D18-C18),"0") -> 0 | I47: =IF(I18="X",(D18-C18),"0") -> 0 | J47: =IF(J18="X",(D18-C18),"0") -> 1 | K47: =IF(K18="X",(D18-C18),"0") -> 0 | L47: =IF(L18="X",(D18-C18),"0") -> 0 | M47: =IF(M18="X",(D18-C18),"0") -> 1 | N47: =IF(N18="X",(D18-C18),"0") -> 0 | O47: =IF(O18="X",(D18-C18),"0") -> 0 | P47: =IF(P18="X",(D18-C18),"0") -> 0 | Q47: =IF(Q18="X",(D18-C18),"0") -> 1 | R47: =IF(R18="X",(D18-C18),"0") -> 0 | S47: =IF(S18="X",(D18-C18),"0") -> 0 | T47: =IF(T18="X",(D18-C18),"0") -> 1
... E86: =IF(E57="X",(D57-C57),"0") -> 0 | F86: =IF(F57="X",(D57-C57),"0") -> 0 | G86: =IF(G57="X",(D57-C57),"0") -> 0 | H86: =IF(H57="X",(D57-C57),"0") -> 0 | I86: =IF(I57="X",(D57-C57),"0") -> 0 | J86: =IF(J57="X",(D57-C57),"0") -> 0 | K86: =IF(K57="X",(D57-C57),"0") -> 0 | L86: =IF(L57="X",(D57-C57),"0") -> 0 | M86: =IF(M57="X",(D57-C57),"0") -> 0 | N86: =IF(N57="X",(D57-C57),"0") -> 0 | O86: =IF(O57="X",(D57-C57),"0") -> 0 | P86: =IF(P57="X",(D57-C57),"0") -> 0 | Q86: =IF(Q57="X",(D57-C57),"0") -> 0 | R86: =IF(R57="X",(D57-C57),"0") -> 0 | S86: =IF(S57="X",(D57-C57),"0") -> 0 | T86: =IF(T57="X",(D57-C57),"0") -> 0
E89: =SUM(E36:E86) -> 5.83 | F89: =SUM(F36:F86) -> 0 | G89: =SUM(G36:G86) -> 0 | H89: =SUM(H36:H86) -> 0 | I89: =SUM(I36:I86) -> 7.62 | J89: =SUM(J36:J86) -> 13.45 | K89: =SUM(K36:K86) -> 0 | L89: =SUM(L36:L86) -> 0 | ... T89: =SUM(T36:T86) -> 13.45

Sheet 43
A1: PROGRAMA DE MANUTENÇÃORODOVIÁRIA
D2: RODOVIAS PAVIMENTADAS | I2: DATA: | J2: ='39'!J2 -> 46204 | N2: TÉCNICO RESP. | O2: ='39'!O2 -> ENG. VINICIUS RODRIGUES FERREIRA DE OLIVEIRA | T2: REGIÃO: | U2: 02
A3: FICHA DE INSPEÇÃO: | B3: =TT!C8 -> RODOVIA TO-164 - TRECHO ARAGOMINAS - MURICILÂNDIA
A5: S.R.E. | B5: SENTIDO | C5: INÍCIO (KM) | D5: FIM (KM) | E5: CONDIÇÃO DO PAVIMENTO | J5: VEGETAÇÃO | L5: ELEM. DE DRENAGEM | O5: SIN. HOR. | R5: SIN. VERTICAL | U5: OBSERV.
E6: BOM | F6: REM. I. | G6: REM. L | H6: BUR. I | I6: BUR. L | J6: ADEQ. | K6: INADED. | L6: LIMPOS | M6: SUJOS | N6: DAN. | O6: BOM | P6: REG. | Q6: INEXIST. | R6: BOM | S6: POUCAS | T6: INEXIST.
A7: 164ETO0155 | B7: D | C7: 0 | D7: 0.9 | F7: X | J7: X | M7: X | P7: X | S7: X
A8: (222ETO0170) | B8: D | C8: 0.9 | D8: 2.6 | G8: X | J8: X | M8: X | P8: X | S8: X
B9: D | C9: 2.6 | D9: 3.8 | F9: X | J9: X | M9: X | P9: X | S9: X
B10: D | C10: 3.8 | D10: 5.5 | F10: X | J10: X | M10: X | P10: X | S10: X
B11: D | C11: 5.5 | D11: 10 | F11: X | J11: X | M11: X | P11: X | S11: X
B12: D | C12: 10 | D12: 20 | F12: X | J12: X | M12: X | P12: X | S12: X
A13: 164ETO0151 | B13: D | C13: 0 | D13: 1.15 | F13: X | J13: X | L13: X | P13: X | T13: X
A32: LEGENDA | B32: CONDIÇÃO DO PAVIMENTO
A33: REM. I | B33: REMENDOS ISOLADOS | E33: ATÉ 10 REMENDOS/KM | I33: BUR. I | J33: BURACOS ISOLADOS | M33: ATÉ 5 BURACOS/KM
A34: REM. L | B34: REMENDOS AO LONGO | E34: MAIS DE 10 REMENDOS/KM | I34: BUR. L | J34: BURACOS AO LONGO | M34: MAIS DE 5 BURACOS/KM
E39: =IF(E7="X",(D7-C7),"0") -> 0 | F39: =IF(F7="X",(D7-C7),"0") -> 0.9 | G39: =IF(G7="X",(D7-C7),"0") -> 0 | H39: =IF(H7="X",(D7-C7),"0") -> 0 | I39: =IF(I7="X",(D7-C7),"0") -> 0 | J39: =IF(J7="X",(D7-C7),"0") -> 0.9 | K39: =IF(K7="X",(D7-C7),"0") -> 0 | L39: =IF(L7="X",(D7-C7),"0") -> 0 | M39: =IF(M7="X",(D7-C7),"0") -> 0.9 | N39: =IF(N7="X",(D7-C7),"0") -> 0 | O39: =IF(O7="X",(D7-C7),"0") -> 0 | P39: =IF(P7="X",(D7-C7),"0") -> 0.9 | Q39: =IF(Q7="X",(D7-C7),"0") -> 0 | R39: =IF(R7="X",(D7-C7),"0") -> 0 | S39: =IF(S7="X",(D7-C7),"0") -> 0.9 | T39: =IF(T7="X",(D7-C7),"0") -> 0
E40: =IF(E8="X",(D8-C8),"0") -> 0 | F40: =IF(F8="X",(D8-C8),"0") -> 0 | G40: =IF(G8="X",(D8-C8),"0") -> 1.7 | H40: =IF(H8="X",(D8-C8),"0") -> 0 | I40: =IF(I8="X",(D8-C8),"0") -> 0 | J40: =IF(J8="X",(D8-C8),"0") -> 1.7 | K40: =IF(K8="X",(D8-C8),"0") -> 0 | L40: =IF(L8="X",(D8-C8),"0") -> 0 | M40: =IF(M8="X",(D8-C8),"0") -> 1.7 | N40: =IF(N8="X",(D8-C8),"0") -> 0 | O40: =IF(O8="X",(D8-C8),"0") -> 0 | P40: =IF(P8="X",(D8-C8),"0") -> 1.7 | Q40: =IF(Q8="X",(D8-C8),"0") -> 0 | R40: =IF(R8="X",(D8-C8),"0") -> 0 | S40: =IF(S8="X",(D8-C8),"0") -> 1.7 | T40: =IF(T8="X",(D8-C8),"0") -> 0
E41: =IF(E9="X",(D9-C9),"0") -> 0 | F41: =IF(F9="X",(D9-C9),"0") -> 1.2 | G41: =IF(G9="X",(D9-C9),"0") -> 0 | H41: =IF(H9="X",(D9-C9),"0") -> 0 | I41: =IF(I9="X",(D9-C9),"0") -> 0 | J41: =IF(J9="X",(D9-C9),"0") -> 1.2 | K41: =IF(K9="X",(D9-C9),"0") -> 0 | L41: =IF(L9="X",(D9-C9),"0") -> 0 | M41: =IF(M9="X",(D9-C9),"0") -> 1.2 | N41: =IF(N9="X",(D9-C9),"0") -> 0 | O41: =IF(O9="X",(D9-C9),"0") -> 0 | P41: =IF(P9="X",(D9-C9),"0") -> 1.2 | Q41: =IF(Q9="X",(D9-C9),"0") -> 0 | R41: =IF(R9="X",(D9-C9),"0") -> 0 | S41: =IF(S9="X",(D9-C9),"0") -> 1.2 | T41: =IF(T9="X",(D9-C9),"0") -> 0
E42: =IF(E10="X",(D10-C10),"0") -> 0 | F42: =IF(F10="X",(D10-C10),"0") -> 1.7 | G42: =IF(G10="X",(D10-C10),"0") -> 0 | H42: =IF(H10="X",(D10-C10),"0") -> 0 | I42: =IF(I10="X",(D10-C10),"0") -> 0 | J42: =IF(J10="X",(D10-C10),"0") -> 1.7 | K42: =IF(K10="X",(D10-C10),"0") -> 0 | L42: =IF(L10="X",(D10-C10),"0") -> 0 | M42: =IF(M10="X",(D10-C10),"0") -> 1.7 | N42: =IF(N10="X",(D10-C10),"0") -> 0 | O42: =IF(O10="X",(D10-C10),"0") -> 0 | P42: =IF(P10="X",(D10-C10),"0") -> 1.7 | Q42: =IF(Q10="X",(D10-C10),"0") -> 0 | R42: =IF(R10="X",(D10-C10),"0") -> 0 | S42: =IF(S10="X",(D10-C10),"0") -> 1.7 | T42: =IF(T10="X",(D10-C10),"0") -> 0
E43: =IF(E11="X",(D11-C11),"0") -> 0 | F43: =IF(F11="X",(D11-C11),"0") -> 4.5 | G43: =IF(G11="X",(D11-C11),"0") -> 0 | H43: =IF(H11="X",(D11-C11),"0") -> 0 | I43: =IF(I11="X",(D11-C11),"0") -> 0 | J43: =IF(J11="X",(D11-C11),"0") -> 4.5 | K43: =IF(K11="X",(D11-C11),"0") -> 0 | L43: =IF(L11="X",(D11-C11),"0") -> 0 | M43: =IF(M11="X",(D11-C11),"0") -> 4.5 | N43: =IF(N11="X",(D11-C11),"0") -> 0 | O43: =IF(O11="X",(D11-C11),"0") -> 0 | P43: =IF(P11="X",(D11-C11),"0") -> 4.5 | Q43: =IF(Q11="X",(D11-C11),"0") -> 0 | R43: =IF(R11="X",(D11-C11),"0") -> 0 | S43: =IF(S11="X",(D11-C11),"0") -> 4.5 | T43: =IF(T11="X",(D11-C11),"0") -> 0
E44: =IF(E12="X",(D12-C12),"0") -> 0 | F44: =IF(F12="X",(D12-C12),"0") -> 10 | G44: =IF(G12="X",(D12-C12),"0") -> 0 | H44: =IF(H12="X",(D12-C12),"0") -> 0 | I44: =IF(I12="X",(D12-C12),"0") -> 0 | J44: =IF(J12="X",(D12-C12),"0") -> 10 | K44: =IF(K12="X",(D12-C12),"0") -> 0 | L44: =IF(L12="X",(D12-C12),"0") -> 0 | M44: =IF(M12="X",(D12-C12),"0") -> 10 | N44: =IF(N12="X",(D12-C12),"0") -> 0 | O44: =IF(O12="X",(D12-C12),"0") -> 0 | P44: =IF(P12="X",(D12-C12),"0") -> 10 | Q44: =IF(Q12="X",(D12-C12),"0") -> 0 | R44: =IF(R12="X",(D12-C12),"0") -> 0 | S44: =IF(S12="X",(D12-C12),"0") -> 10 | T44: =IF(T12="X",(D12-C12),"0") -> 0
E45: =IF(E13="X",(D13-C13),"0") -> 0 | F45: =IF(F13="X",(D13-C13),"0") -> 1.15 | G45: =IF(G13="X",(D13-C13),"0") -> 0 | H45: =IF(H13="X",(D13-C13),"0") -> 0 | I45: =IF(I13="X",(D13-C13),"0") -> 0 | J45: =IF(J13="X",(D13-C13),"0") -> 1.15 | K45: =IF(K13="X",(D13-C13),"0") -> 0 | L45: =IF(L13="X",(D13-C13),"0") -> 1.15 | M45: =IF(M13="X",(D13-C13),"0") -> 0 | N45: =IF(N13="X",(D13-C13),"0") -> 0 | O45: =IF(O13="X",(D13-C13),"0") -> 0 | P45: =IF(P13="X",(D13-C13),"0") -> 1.15 | Q45: =IF(Q13="X",(D13-C13),"0") -> 0 | R45: =IF(R13="X",(D13-C13),"0") -> 0 | S45: =IF(S13="X",(D13-C13),"0") -> 0 | T45: =IF(T13="X",(D13-C13),"0") -> 1.15
E46: =IF(E14="X",(D14-C14),"0") -> 0 | F46: =IF(F14="X",(D14-C14),"0") -> 0 | G46: =IF(G14="X",(D14-C14),"0") -> 0 | H46: =IF(H14="X",(D14-C14),"0") -> 0 | I46: =IF(I14="X",(D14-C14),"0") -> 0 | J46: =IF(J14="X",(D14-C14),"0") -> 0 | K46: =IF(K14="X",(D14-C14),"0") -> 0 | L46: =IF(L14="X",(D14-C14),"0") -> 0 | M46: =IF(M14="X",(D14-C14),"0") -> 0 | N46: =IF(N14="X",(D14-C14),"0") -> 0 | O46: =IF(O14="X",(D14-C14),"0") -> 0 | P46: =IF(P14="X",(D14-C14),"0") -> 0 | Q46: =IF(Q14="X",(D14-C14),"0") -> 0 | R46: =IF(R14="X",(D14-C14),"0") -> 0 | S46: =IF(S14="X",(D14-C14),"0") -> 0 | T46: =IF(T14="X",(D14-C14),"0") -> 0
E47: =IF(E15="X",(D15-C15),"0") -> 0 | F47: =IF(F15="X",(D15-C15),"0") -> 0 | G47: =IF(G15="X",(D15-C15),"0") -> 0 | H47: =IF(H15="X",(D15-C15),"0") -> 0 | I47: =IF(I15="X",(D15-C15),"0") -> 0 | J47: =IF(J15="X",(D15-C15),"0") -> 0 | K47: =IF(K15="X",(D15-C15),"0") -> 0 | L47: =IF(L15="X",(D15-C15),"0") -> 0 | M47: =IF(M15="X",(D15-C15),"0") -> 0 | N47: =IF(N15="X",(D15-C15),"0") -> 0 | O47: =IF(O15="X",(D15-C15),"0") -> 0 | P47: =IF(P15="X",(D15-C15),"0") -> 0 | Q47: =IF(Q15="X",(D15-C15),"0") -> 0 | R47: =IF(R15="X",(D15-C15),"0") -> 0 | S47: =IF(S15="X",(D15-C15),"0") -> 0 | T47: =IF(T15="X",(D15-C15),"0") -> 0
E48: =IF(E16="X",(D16-C16),"0") -> 0 | F48: =IF(F16="X",(D16-C16),"0") -> 0 | G48: =IF(G16="X",(D16-C16),"0") -> 0 | H48: =IF(H16="X",(D16-C16),"0") -> 0 | I48: =IF(I16="X",(D16-C16),"0") -> 0 | J48: =IF(J16="X",(D16-C16),"0") -> 0 | K48: =IF(K16="X",(D16-C16),"0") -> 0 | L48: =IF(L16="X",(D16-C16),"0") -> 0 | M48: =IF(M16="X",(D16-C16),"0") -> 0 | N48: =IF(N16="X",(D16-C16),"0") -> 0 | O48: =IF(O16="X",(D16-C16),"0") -> 0 | P48: =IF(P16="X",(D16-C16),"0") -> 0 | Q48: =IF(Q16="X",(D16-C16),"0") -> 0 | R48: =IF(R16="X",(D16-C16),"0") -> 0 | S48: =IF(S16="X",(D16-C16),"0") -> 0 | T48: =IF(T16="X",(D16-C16),"0") -> 0
E49: =IF(E17="X",(D17-C17),"0") -> 0 | F49: =IF(F17="X",(D17-C17),"0") -> 0 | G49: =IF(G17="X",(D17-C17),"0") -> 0 | H49: =IF(H17="X",(D17-C17),"0") -> 0 | I49: =IF(I17="X",(D17-C17),"0") -> 0 | J49: =IF(J17="X",(D17-C17),"0") -> 0 | K49: =IF(K17="X",(D17-C17),"0") -> 0 | L49: =IF(L17="X",(D17-C17),"0") -> 0 | M49: =IF(M17="X",(D17-C17),"0") -> 0 | N49: =IF(N17="X",(D17-C17),"0") -> 0 | O49: =IF(O17="X",(D17-C17),"0") -> 0 | P49: =IF(P17="X",(D17-C17),"0") -> 0 | Q49: =IF(Q17="X",(D17-C17),"0") -> 0 | R49: =IF(R17="X",(D17-C17),"0") -> 0 | S49: =IF(S17="X",(D17-C17),"0") -> 0 | T49: =IF(T17="X",(D17-C17),"0") -> 0
E50: =IF(E18="X",(D18-C18),"0") -> 0 | F50: =IF(F18="X",(D18-C18),"0") -> 0 | G50: =IF(G18="X",(D18-C18),"0") -> 0 | H50: =IF(H18="X",(D18-C18),"0") -> 0 | I50: =IF(I18="X",(D18-C18),"0") -> 0 | J50: =IF(J18="X",(D18-C18),"0") -> 0 | K50: =IF(K18="X",(D18-C18),"0") -> 0 | L50: =IF(L18="X",(D18-C18),"0") -> 0 | M50: =IF(M18="X",(D18-C18),"0") -> 0 | N50: =IF(N18="X",(D18-C18),"0") -> 0 | O50: =IF(O18="X",(D18-C18),"0") -> 0 | P50: =IF(P18="X",(D18-C18),"0") -> 0 | Q50: =IF(Q18="X",(D18-C18),"0") -> 0 | R50: =IF(R18="X",(D18-C18),"0") -> 0 | S50: =IF(S18="X",(D18-C18),"0") -> 0 | T50: =IF(T18="X",(D18-C18),"0") -> 0
... E127: =IF(E95="X",(D95-C95),"0") -> 0 | F127: =IF(F95="X",(D95-C95),"0") -> 0 | G127: =IF(G95="X",(D95-C95),"0") -> 0 | H127: =IF(H95="X",(D95-C95),"0") -> 0 | I127: =IF(I95="X",(D95-C95),"0") -> 0 | J127: =IF(J95="X",(D95-C95),"0") -> 0 | K127: =IF(K95="X",(D95-C95),"0") -> 0 | L127: =IF(L95="X",(D95-C95),"0") -> 0 | M127: =IF(M95="X",(D95-C95),"0") -> 0 | N127: =IF(N95="X",(D95-C95),"0") -> 0 | O127: =IF(O95="X",(D95-C95),"0") -> 0 | P127: =IF(P95="X",(D95-C95),"0") -> 0 | Q127: =IF(Q95="X",(D95-C95),"0") -> 0 | R127: =IF(R95="X",(D95-C95),"0") -> 0 | S127: =IF(S95="X",(D95-C95),"0") -> 0 | T127: =IF(T95="X",(D95-C95),"0") -> 0
E130: =SUM(E39:E127) -> 0 | F130: =SUM(F39:F127) -> 19.45 | G130: =SUM(G39:G127) -> 1.7 | H130: =SUM(H39:H127) -> 0 | I130: =SUM(I39:I127) -> 0 | J130: =SUM(J39:J127) -> 21.15 | K130: =SUM(K39:K127) -> 0 | L130: =SUM(L39:L127) -> 1.15 | ... T130: =SUM(T39:T127) -> 1.15

Sheet 44
A1: PROGRAMA DE MANUTENÇÃORODOVIÁRIA
D2: RODOVIAS PAVIMENTADAS | I2: DATA: | J2: ='39'!J2 -> 46204 | N2: TÉCNICO RESP. | O2: ='39'!O2 -> ENG. VINICIUS RODRIGUES FERREIRA DE OLIVEIRA | T2: REGIÃO: | U2: 02
A3: FICHA DE INSPEÇÃO: | B3: =TT!C9 -> RODOVIA TO-164 - TRECHO ARAGUANÃ - CARMOLÂNDIA
A5: S.R.E. | B5: SENTIDO | C5: INÍCIO (KM) | D5: FIM (KM) | E5: CONDIÇÃO DO PAVIMENTO | J5: VEGETAÇÃO | L5: ELEM. DE DRENAGEM | O5: SIN. HOR. | R5: SIN. VERTICAL | U5: OBSERV.
E6: BOM | F6: REM. I. | G6: REM. L | H6: BUR. I | I6: BUR. L | J6: ADEQ. | K6: INADED. | L6: LIMPOS | M6: SUJOS | N6: DAN. | O6: BOM | P6: REG. | Q6: INEXIST. | R6: BOM | S6: POUCAS | T6: INEXIST.
A7: 164ETO0110 | B7: C | C7: 0 | D7: 1 | E7: X | J7: X | M7: X | O7: X | R7: X
C8: =D7 -> 1 | D8: 2 | E8: X | J8: X | M8: X | O8: X | R8: X
C9: =D8 -> 2 | D9: 3 | G9: X | J9: X | M9: X | O9: X | R9: X
C10: =D9 -> 3 | D10: 4 | G10: X | J10: X | M10: X | O10: X | R10: X
C11: =D10 -> 4 | D11: 5 | H11: X | J11: X | M11: X | O11: X | R11: X
C12: =D11 -> 5 | D12: 6 | H12: X | J12: X | M12: X | O12: X | R12: X
C13: =D12 -> 6 | D13: 7 | H13: X | J13: X | M13: X | O13: X | R13: X
C14: =D13 -> 7 | D14: 8 | H14: X | J14: X | M14: X | O14: X | R14: X
C15: =D14 -> 8 | D15: 9 | H15: X | J15: X | M15: X | O15: X | R15: X
C16: =D15 -> 9 | D16: 10 | H16: X | J16: X | M16: X | O16: X | R16: X
C17: =D16 -> 10 | D17: 11 | H17: X | J17: X | M17: X | O17: X | R17: X
C18: =D17 -> 11 | D18: 12 | H18: X | J18: X | M18: X | O18: X | R18: X
C19: =D18 -> 12 | D19: 13 | H19: X | J19: X | M19: X | O19: X | R19: X
C20: =D19 -> 13 | D20: 14 | E20: X | J20: X | M20: X | O20: X | R20: X
C21: =D20 -> 14 | D21: 15 | E21: X | J21: X | M21: X | O21: X | R21: X
C22: =D21 -> 15 | D22: 16 | E22: X | J22: X | M22: X | O22: X | R22: X
C23: =D22 -> 16 | D23: 17 | E23: X | J23: X | M23: X | O23: X | R23: X
C24: =D23 -> 17 | D24: 18 | E24: X | J24: X | M24: X | O24: X | R24: X
C25: =D24 -> 18 | D25: 19 | E25: X | J25: X | M25: X | O25: X | R25: X
C26: =D25 -> 19 | D26: 20 | G26: X | J26: X | M26: X | O26: X | R26: X
C27: =D26 -> 20 | D27: 21 | E27: X | J27: X | M27: X | O27: X | R27: X
C28: =D27 -> 21 | D28: 22 | E28: X | J28: X | M28: X | O28: X | R28: X
C29: =D28 -> 22 | D29: 23 | E29: X | J29: X | M29: X | O29: X | R29: X
C30: =D29 -> 23 | D30: 24 | E30: X | J30: X | M30: X | O30: X | R30: X
C31: =D30 -> 24 | D31: 25 | E31: X | J31: X | M31: X | O31: X | R31: X
C32: =D31 -> 25 | D32: 26 | E32: X | J32: X | M32: X | O32: X | R32: X
C33: =D32 -> 26 | D33: 27 | E33: X | J33: X | M33: X | O33: X | R33: X
C34: =D33 -> 27 | D34: 28 | E34: X | J34: X | M34: X | O34: X | R34: X
C35: =D34 -> 28 | D35: 29 | E35: X | J35: X | M35: X | O35: X | R35: X
C36: =D35 -> 29 | D36: 30 | E36: X | J36: X | M36: X | O36: X | R36: X
C37: =D36 -> 30 | D37: 31 | E37: X | J37: X | M37: X | O37: X | R37: X
C38: =D37 -> 31 | D38: 32 | E38: X | J38: X | M38: X | O38: X | R38: X
... C40: =D39 -> 33 | D40: 33.93 | E40: X | J40: X | M40: X | O40: X | R40: X
A41: 164ETO0120 | B41: C | C41: 0 | D41: 1 | E41: X | J41: X | M41: X | O41: X | R41: X
C42: =D7 -> 1 | D42: 2 | E42: X | J42: X | M42: X | O42: X | R42: X
...

Sheet 45
A1: PROGRAMA DE MANUTENÇÃORODOVIÁRIA
D2: RODOVIAS PAVIMENTADAS | I2: DATA: | J2: ='39'!J2 -> 46204 | N2: TÉCNICO RESP. | O2: ='39'!O2 -> ENG. VINICIUS RODRIGUES FERREIRA DE OLIVEIRA | T2: REGIÃO: | U2: 02
A3: FICHA DE INSPEÇÃO: | B3: =TT!C10 -> RODOVIA TO-164 - TRECHO CARMOLÂNDIA - ENTR. TO-222 - ARAGOMINAS
A5: S.R.E. | B5: SENTIDO | C5: INÍCIO (KM) | D5: FIM (KM) | E5: CONDIÇÃO DO PAVIMENTO | J5: VEGETAÇÃO | L5: ELEM. DE DRENAGEM | O5: SIN. HOR. | R5: SIN. VERTICAL | U5: OBSERV.
E6: BOM | F6: REM. I. | G6: REM. L | H6: BUR. I | I6: BUR. L | J6: ADEQ. | K6: INADED. | L6: LIMPOS | M6: SUJOS | N6: DAN. | O6: BOM | P6: REG. | Q6: INEXIST. | R6: BOM | S6: POUCAS | T6: INEXIST.
A7: 164ETO0130 | B7: D | C7: 0 | D7: 1 | E7: X | J7: X | M7: X | Q7: X | S7: X
C8: =D7 -> 1 | D8: 2 | E8: X | J8: X | M8: X | Q8: X | S8: X
C9: =D8 -> 2 | D9: 3 | G9: X | J9: X | M9: X | Q9: X | S9: X
C10: =D9 -> 3 | D10: 4 | G10: X | J10: X | Q10: X | S10: X
C11: =D10 -> 4 | D11: 5 | G11: X | J11: X | Q11: X | S11: X
C12: =D11 -> 5 | D12: 6 | G12: X | J12: X | M12: X | Q12: X | S12: X
C13: =D12 -> 6 | D13: 7 | G13: X | J13: X | M13: X | Q13: X | S13: X
C14: =D13 -> 7 | D14: 8 | E14: X | J14: X | M14: X | Q14: X | S14: X
C15: =D14 -> 8 | D15: 9 | G15: X | J15: X | M15: X | Q15: X | S15: X
C16: =D15 -> 9 | D16: 10 | G16: X | J16: X | Q16: X | S16: X
C17: =D16 -> 10 | D17: 11 | G17: X | J17: X | Q17: X | S17: X
C18: =D17 -> 11 | D18: 12 | G18: X | J18: X | Q18: X | S18: X
C19: =D18 -> 12 | D19: 13 | G19: X | J19: X | Q19: X | S19: X
C20: =D19 -> 13 | D20: 14 | G20: X | J20: X | Q20: X | S20: X
C21: =D20 -> 14 | D21: 15 | G21: X | J21: X | Q21: X | S21: X
C22: =D21 -> 15 | D22: 16 | G22: X | J22: X | Q22: X | S22: X
C23: =D22 -> 16 | D23: 17 | G23: X | J23: X | Q23: X | S23: X
C24: =D23 -> 17 | D24: 17.71 | G24: X | J24: X | Q24: X | S24: X
A25: 164ETO0140 | B25: C | C25: 0 | D25: 1 | G25: X | J25: X | M25: X | O25: X | S25: X
C26: 1 | D26: 4.4 | G26: X | J26: X | M26: X | O26: X | S26: X
C27: 4.4 | D27: 5.5 | G27: X | J27: X | M27: X | O27: X | S27: X
C28: 5.5 | D28: 11.97 | G28: X | J28: X | M28: X | Q28: X | S28: X
A29: 164ETO0150 | B29: C | C29: 0 | D29: 0.4 | E29: X | J29: X | M29: X | Q29: X | S29: X
C30: 0.4 | D30: 1.8 | E30: X | J30: X | M30: X | Q30: X | S30: X
C31: 1.8 | D31: 3.1 | E31: X | J31: X | M31: X | Q31: X | S31: X
C32: 3.1 | D32: 9.2 | E32: X | J32: X | M32: X | Q32: X | S32: X
C33: 9.2 | D33: 11.5 | E33: X | J33: X | M33: X | Q33: X | S33: X
C34: 11.5 | D34: 12.93 | E34: X | J34: X | M34: X | Q34: X | S34: X
A42: LEGENDA | B42: CONDIÇÃO DO PAVIMENTO
A43: REM. I | B43: REMENDOS ISOLADOS | E43: ATÉ 10 REMENDOS/KM | I43: BUR. I | J43: BURACOS ISOLADOS | M43: ATÉ 5 BURACOS/KM
A44: REM. L | B44: REMENDOS AO LONGO | E44: MAIS DE 10 REMENDOS/KM | I44: BUR. L | J44: BURACOS AO LONGO | M44: MAIS DE 5 BURACOS/KM
E49: =IF(E7="X",(D7-C7),"0") -> 1 | F49: =IF(F7="X",(D7-C7),"0") -> 0 | G49: =IF(G7="X",(D7-C7),"0") -> 0 | H49: =IF(H7="X",(D7-C7),"0") -> 0 | I49: =IF(I7="X",(D7-C7),"0") -> 0 | J49: =IF(J7="X",(D7-C7),"0") -> 1 | K49: =IF(K7="X",(D7-C7),"0") -> 0 | L49: =IF(L7="X",(D7-C7),"0") -> 0 | M49: =IF(M7="X",(D7-C7),"0") -> 1 | N49: =IF(N7="X",(D7-C7),"0") -> 0 | O49: =IF(O7="X",(D7-C7),"0") -> 0 | P49: =IF(P7="X",(D7-C7),"0") -> 0 | Q49: =IF(Q7="X",(D7-C7),"0") -> 1 | R49: =IF(R7="X",(D7-C7),"0") -> 0 | S49: =IF(S7="X",(D7-C7),"0") -> 1 | T49: =IF(T7="X",(D7-C7),"0") -> 0
E50: =IF(E8="X",(D8-C8),"0") -> 1 | F50: =IF(F8="X",(D8-C8),"0") -> 0 | G50: =IF(G8="X",(D8-C8),"0") -> 0 | H50: =IF(H8="X",(D8-C8),"0") -> 0 | I50: =IF(I8="X",(D8-C8),"0") -> 0 | J50: =IF(J8="X",(D8-C8),"0") -> 1 | K50: =IF(K8="X",(D8-C8),"0") -> 0 | L50: =IF(L8="X",(D8-C8),"0") -> 0 | M50: =IF(M8="X",(D8-C8),"0") -> 1 | N50: =IF(N8="X",(D8-C8),"0") -> 0 | O50: =IF(O8="X",(D8-C8),"0") -> 0 | P50: =IF(P8="X",(D8-C8),"0") -> 0 | Q50: =IF(Q8="X",(D8-C8),"0") -> 1 | R50: =IF(R8="X",(D8-C8),"0") -> 0 | S50: =IF(S8="X",(D8-C8),"0") -> 1 | T50: =IF(T8="X",(D8-C8),"0") -> 0
E51: =IF(E9="X",(D9-C9),"0") -> 0 | F51: =IF(F9="X",(D9-C9),"0") -> 0 | G51: =IF(G9="X",(D9-C9),"0") -> 1 | H51: =IF(H9="X",(D9-C9),"0") -> 0 | I51: =IF(I9="X",(D9-C9),"0") -> 0 | J51: =IF(J9="X",(D9-C9),"0") -> 1 | K51: =IF(K9="X",(D9-C9),"0") -> 0 | L51: =IF(L9="X",(D9-C9),"0") -> 0 | M51: =IF(M9="X",(D9-C9),"0") -> 1 | N51: =IF(N9="X",(D9-C9),"0") -> 0 | O51: =IF(O9="X",(D9-C9),"0") -> 0 | P51: =IF(P9="X",(D9-C9),"0") -> 0 | Q51: =IF(Q9="X",(D9-C9),"0") -> 1 | R51: =IF(R9="X",(D9-C9),"0") -> 0 | S51: =IF(S9="X",(D9-C9),"0") -> 1 | T51: =IF(T9="X",(D9-C9),"0") -> 0
E52: =IF(E10="X",(D10-C10),"0") -> 0 | F52: =IF(F10="X",(D10-C10),"0") -> 0 | G52: =IF(G10="X",(D10-C10),"0") -> 1 | H52: =IF(H10="X",(D10-C10),"0") -> 0 | I52: =IF(I10="X",(D10-C10),"0") -> 0 | J52: =IF(J10="X",(D10-C10),"0") -> 1 | K52: =IF(K10="X",(D10-C10),"0") -> 0 | L52: =IF(L10="X",(D10-C10),"0") -> 0 | M52: =IF(M10="X",(D10-C10),"0") -> 0 | N52: =IF(N10="X",(D10-C10),"0") -> 0 | O52: =IF(O10="X",(D10-C10),"0") -> 0 | P52: =IF(P10="X",(D10-C10),"0") -> 0 | Q52: =IF(Q10="X",(D10-C10),"0") -> 1 | R52: =IF(R10="X",(D10-C10),"0") -> 0 | S52: =IF(S10="X",(D10-C10),"0") -> 1 | T52: =IF(T10="X",(D10-C10),"0") -> 0
...

Sheet 46
A1: PROGRAMA DE MANUTENÇÃORODOVIÁRIA
D2: RODOVIAS PAVIMENTADAS | I2: DATA: | J2: ='39'!J2 -> 46204 | N2: TÉCNICO RESP. | O2: ='39'!O2 -> ENG. VINICIUS RODRIGUES FERREIRA DE OLIVEIRA | T2: REGIÃO: | U2: 02
A3: FICHA DE INSPEÇÃO: | B3: =TT!C11 -> RODOVIA TO-164 - TRECHO ENTR. TO-226 - POVOADO DEZENOVE - BERNARDO SAYÃO
A5: S.R.E. | B5: SENTIDO | C5: INÍCIO (KM) | D5: FIM (KM) | E5: CONDIÇÃO DO PAVIMENTO | J5: VEGETAÇÃO | L5: ELEM. DE DRENAGEM | O5: SIN. HOR. | R5: SIN. VERTICAL | U5: OBSERV.
E6: BOM | F6: REM. I. | G6: REM. L | H6: BUR. I | I6: BUR. L | J6: ADEQ. | K6: INADED. | L6: LIMPOS | M6: SUJOS | N6: DAN. | O6: BOM | P6: REG. | Q6: INEXIST. | R6: BOM | S6: POUCAS | T6: INEXIST.
A7: 164ETO0210 | B7: C | C7: 0 | D7: 8 | E7: X | K7: X | M7: X | P7: X | S7: X
C8: 8 | D8: 9 | I8: X | K8: X | M8: X | P8: X | S8: X
C9: 9 | D9: 11 | I9: X | K9: X | M9: X | P9: X | S9: X
C10: 11 | D10: 12.6 | E10: X | K10: X | N10: X | Q10: X | S10: X
C11: 12.6 | D11: 14.3 | H11: X | K11: X | M11: X | Q11: X | S11: X
C12: 14.3 | D12: 14.3 | E12: X | K12: X | N12: X | Q12: X | S12: X
C13: 14.3 | D13: 24.68 | E13: X | K13: X | M13: X | Q13: X | S13: X
A14: 164ETO0230 | B14: C | C14: 0 | D14: 1 | E14: X | K14: X | Q14: X | S14: X
C15: =D14 -> 1 | D15: 2 | E15: X | K15: X | L15: X | Q15: X | S15: X
C16: =D15 -> 2 | D16: 3 | H16: X | K16: X | L16: X | Q16: X | S16: X
C17: =D16 -> 3 | D17: 4 | H17: X | K17: X | L17: X | Q17: X | S17: X
C18: =D17 -> 4 | D18: 4.98 | E18: X | K18: X | Q18: X | S18: X
A19: 164ETO0240 | B19: C | C19: 0 | D19: 1 | E19: X | K19: X | L19: X | Q19: X | S19: X
C20: =D19 -> 1 | D20: 2 | E20: X | K20: X | L20: X | Q20: X | S20: X
C21: =D20 -> 2 | D21: 3 | E21: X | K21: X | L21: X | Q21: X | S21: X
C22: =D21 -> 3 | D22: 4 | E22: X | K22: X | L22: X | Q22: X | S22: X
C23: =D22 -> 4 | D23: 5 | E23: X | K23: X | Q23: X | S23: X
C24: =D23 -> 5 | D24: 6 | I24: X | K24: X | O24: X | S24: X
C25: =D24 -> 6 | D25: 7 | E25: X | K25: X | O25: X | S25: X
C26: =D25 -> 7 | D26: 8 | E26: X | K26: X | Q26: X | S26: X
C27: =D26 -> 8 | D27: 8.82 | E27: X | K27: X | Q27: X | S27: X
