Workbook

Sheet Trechos
A1: RELAÇÃO DOS TRECHOS DAS REGIÕES DE MANUTENÇÃO
A2: LOTE | B2: REGIÃO DE CONSERVAÇÃO | C2: CIDADE SEDE | D2: N° | E2: TRECHOS | F2: S.R.E. | G2: SUBTRECHOS | H2: EXT. (KM) | I2: TIPO | J2: 45839 | K2: 45870 | L2: 45901 | M2: 45931 | N2: 45962 | O2: 45992
A3: 1 | B3: 1 | C3: Tocantinópolis | D3: 1 | E3: RODOVIA TO-010 - TRECHO ANANÁS - ENTR. BR-230 | F3: 85.329429
A4: 1 | B4: 1 | C4: Tocantinópolis | D4: 2 | E4: RODOVIA TO-010 - TRECHO ENTR. BR-230 - ARAGUATINS | F4: 9.6381707
A5: 1 | B5: 1 | C5: Tocantinópolis | D5: 3 | E5: RODOVIA TO-010 - TRECHO ARAGUATINS - ENTR. TO-201 | F5: 41.607009
A6: 1 | B6: 1 | C6: Tocantinópolis | D6: 4 | E6: RODOVIA TO-010 - TRECHO BURITI DO TOCANTINS (ENTR. TO-201) - SÃO SEBASTIÃO DO TOCANTINS | F6: 9.2499338
A7: 1 | B7: 1 | C7: Tocantinópolis | D7: 5 | E7: RODOVIA TO-126 - TRECHO TOCANTINÓPOLIS - ENTR. BR-230 (AGUIARNÓPOLIS) | F7: 30.23918
A8: 1 | B8: 1 | C8: Tocantinópolis | D8: 6 | E8: RODOVIA TO-126 - TRECHO MAURILÂNDIA - TOCANTINÓPOLIS | F8: 43.993596
A9: 1 | B9: 1 | C9: Tocantinópolis | D9: 7 | E9: RODOVIA TO-126 - TRECHO ITAGUATINS - MAURILÂNDIA DO TOCANTINS | F9: 21.660088
A10: 1 | B10: 1 | C10: Tocantinópolis | D10: 8 | E10: RODOVIA TO-126 - TRECHO SÍTIO NOVO DO TOCANTINS - ITAGUATINS | F10: 25.376613
A11: 1 | B11: 1 | C11: Tocantinópolis | D11: 9 | E11: RODOVIA TO-126 - TRECHO SUMAUMA - SÍTIO NOVO DO TOCANTINS | F11: 16.674968
A12: 1 | B12: 1 | C12: Tocantinópolis | D12: 10 | E12: RODOVIA TO-134 - TRECHO ANGICO - DARCINÓPOLIS | F12: 45.347802
A13: 1 | B13: 1 | C13: Tocantinópolis | D13: 11 | E13: RODOVIA TO-134 - TRECHO LUZINÓPOLIS - ANGICO | F13: 24.440194
A14: 1 | B14: 1 | C14: Tocantinópolis | D14: 12 | E14: RODOVIA TO-134 - TRECHO RIO TOCANTINS (JATOBAL) - AXIXÁ DO TOCANTINS | F14: 26.301108
... A68: 2 | B68: 2 | C68: Araguaína I | D68: 66 | E68: RODOVIA TO-433 - TRECHO ENTR. TO-230 (POVOADO BRASILENE) - BERNARDO SAYÃO (ENTR. TO-164) | F68: 32.27987
A69: 3 | B69: 3 | C69: ARAGUAÍNA II | D69: 67 | E69: RODOVIA TO-010 - TRECHO ENTR. BR-010 (ITACAJÁ) - PALMEIRANTE | F69: 010ETO0250 | G69: ENTR. BR-010 - TRECHO ENTR. TO-226 (POV. CAMPOS) | H69: 58.16433 | I69: LEN
A70: 3 | B70: 3 | C70: ARAGUAÍNA II | D70: 67 | E70: RODOVIA TO-010 - TRECHO ENTR. BR-010 (ITACAJÁ) - PALMEIRANTE | F70: 010ETO0290 | G70: ENTR. TO-226 (CAMPOS) - RIO TOCANTINS ( BALSA PALMEIRANTE) | H70: 19.427802 | I70: LEN
A71: 3 | B71: 3 | C71: ARAGUAÍNA II | D71: 69 | E71: RODOVIA TO-010 - TRECHO ENTR. TO-222 (POVOADO FARTURÃO) - BABAÇULÂNDIA | F71: 010ETO0380 | G71: POV. FARTURAO - ENTR. TO-424 | H71: 33.591201 | I71: LEN | J71: X
A72: 3 | B72: 3 | C72: ARAGUAÍNA II | D72: 69 | E72: RODOVIA TO-010 - TRECHO ENTR. TO-222 (POVOADO FARTURÃO) - BABAÇULÂNDIA | F72: 010ETO0400 | G72: ENTR. TO-424 - TRECHO BABAÇULÂNDIA *TRECHO URBANO* | H72: 4.8384683 | I72: LEN | J72: X
A73: 3 | B73: 3 | C73: ARAGUAÍNA II | D73: 71 | E73: RODOVIA TO-020 - TRECHO RECURSOLÂNDIA - CAMPOS LINDOS | F73: 020ETO0210 | G73: FIM PAVIMENTAÇÃO - INICIO PAVIMENTACAO (CAMPOS LINDOS) | H73: 148.40783 | I73: EOP | J73: X
A74: 3 | B74: 3 | C74: ARAGUAÍNA II | D74: 72 | E74: RODOVIA TO-130 - TRECHO ENTR. TO-424 - TRECHO ENTR. TO-222 | F74: 130ETO0010 | G74: ENTR. TO-424 - TRECHO ENTR. TO-222 (A) | H74: 19.326516 | I74: LEN
A75: 3 | B75: 3 | C75: ARAGUAÍNA II | D75: 75 | E75: RODOVIA TO-226 - TRECHO NOVA OLINDA - ENTR. TO-010 | F75: 226ETO0190 | G75: ENTR.TO-010 - TRECHO POV. ALTO BONITO | H75: 36.768231 | I75: LEN | J75: X
A76: 3 | B76: 3 | C76: ARAGUAÍNA II | D76: 75 | E76: RODOVIA TO-226 - TRECHO NOVA OLINDA - ENTR. TO-010 | F76: 226ETO0200 | G76: POV. ALTO BONITO - NOVA OLINDA *TRECHO URBANO* | H76: 17.621405 | I76: LEN | J76: X
A77: 3 | B77: 3 | C77: ARAGUAÍNA II | D77: 76 | E77: RODOVIA TO-226 - TRECHO ENTR. TO-010 (POVOADO CAMPOS) - ENTR. BR-010 | F77: 226ETO0120 | G77: ENTR. BR-010-TO-130 - TRECHO BARRO VERMELHO | H77: 14.646522 | I77: LEN
A78: 3 | B78: 3 | C78: ARAGUAÍNA II | D78: 76 | E78: RODOVIA TO-226 - TRECHO ENTR. TO-010 (POVOADO CAMPOS) - ENTR. BR-010 | F78: 226ETO0130 | G78: BARRO VERMELHO - ENTR. TO-010 (CAMPOS) | H78: 13.697356 | I78: LEN
A79: 3 | B79: 3 | C79: ARAGUAÍNA II | D79: 79 | E79: RODOVIA TO-423 - TRECHO ARAGUAÍNA - ENTR. TO-424 | F79: 423ETO0020 | G79: ARAGUAINA *TRECHO URBANO* - ENTR. TO-424 | H79: 28.588959 | I79: LEN | J79: X
A80: 3 | B80: 3 | C80: ARAGUAÍNA II | D80: 81 | E80: RODOVIA TO-424 - TRECHO ENTR. TO-010 (BABAÇULÂNDIA) - ENTR. TO-222 | F80: 424ETO0010 | G80: ENTR. TO-222 - TRECHO CANA BRAVA | H80: 13.613922 | I80: LEN
A81: 3 | B81: 3 | C81: ARAGUAÍNA II | D81: 81 | E81: RODOVIA TO-424 - TRECHO ENTR. TO-010 (BABAÇULÂNDIA) - ENTR. TO-222 | F81: 424ETO0015 | G81: CANA BRAVA - ENTR. TO-130 | H81: 3.8645041 | I81: LEN
A82: 3 | B82: 3 | C82: ARAGUAÍNA II | D82: 81 | E82: RODOVIA TO-424 - TRECHO ENTR. TO-010 (BABAÇULÂNDIA) - ENTR. TO-222 | F82: 424ETO0020 | G82: ENTR. TO-130 - TRECHO ENTR. TO-010 | H82: 14.021279 | I82: LEN
A83: 3 | B83: 3 | C83: ARAGUAÍNA II | D83: 82 | E83: RODOVIA TO-425 - TRECHO ENTR. TO-130 (BARRA DO OURO) - GOIATINS | F83: 425ETO0010 | G83: GOIATINS *TRECHO URBANO* - ENTR. TO-130 | H83: 47.358812 | I83: LEN | J83: X
A84: 3 | B84: 3 | C84: ARAGUAÍNA II | D84: 83 | E84: RODOVIA TO-426 - TRECHO POVOADO CRAOLÂNDIA - ENTR. TO-226 | F84: 426ETO0010 | G84: ENTR. TO-226 - TRECHO POV. CRAOLÂNDIA | H84: 31.730768 | I84: LEN
A85: 3 | B85: 3 | C85: ARAGUAÍNA II | D85: 84 | E85: RODOVIA TO-428 - TRECHO POVOADO BANDEIRA - ENTR. TO-226 | F85: 428ETO0010 | G85: ENTR. TO-226 - TRECHO RANCHARIA | H85: 28.0702 | I85: LEN
A86: 3 | B86: 3 | C86: ARAGUAÍNA II | D86: 84 | E86: RODOVIA TO-428 - TRECHO POVOADO BANDEIRA - ENTR. TO-226 | F86: 428ETO0020 | G86: RANCHARIA - BANDEIRA | H86: 13.451489 | I86: LEN
H87: =SUBTOTAL(9,H69:H85) -> 533.7381
H88: 969.28715
A89: 4 | B89: 4 | C89: Guaraí I | D89: 88 | E89: RODOVIA TO-164 - TRECHO ENTR. TO-335 - ITAPORÃ DO TOCANTINS | F89: 65.895962
A90: 4 | B90: 4 | C90: Guaraí I | D90: 89 | E90: RODOVIA TO-164 - TRECHO ITAPORÃ DO TOCANTINS - COLMEIA | F90: 25.07399
A91: 4 | B91: 4 | C91: Guaraí I | D91: 90 | E91: RODOVIA TO-164 - TRECHO ENTR. TO-336 (POVOADO GOIANI DOS CAMPOS) - GOIANORTE | F91: 17.498487
A92: 4 | B92: 4 | C92: Guaraí I | D92: 91 | E92: RODOVIA TO-164 - TRECHO GOIANORTE - DOIS IRMÃOS | F92: 68.233968
A93: 4 | B93: 4 | C93: Guaraí I | D93: 92 | E93: RODOVIA TO-239 - TRECHO ENTR. BR-153 - PRESIDENTE KENNEDY | F93: 2.9517943
...

Sheet 67
A1: PROGRAMA DE MANUTENÇÃORODOVIÁRIA | I1: DATA: | J1: 46204 | L1: TÉCNICO RESP. | N1: ENG. VINICIUS RODRIGUES FERREIRA DE OLIVEIRA
F2: RODOVIAS NÃO PAVIMENTADAS
A3: FICHA DE INSPEÇÃO: | B3: =Trechos!E69 -> RODOVIA TO-010 - TRECHO ENTR. BR-010 (ITACAJÁ) - PALMEIRANTE
A5: S.R.E. | B5: SENTIDO | C5: INÍCIO (KM) | D5: FIM (KM) | E5: CONDIÇÃO DA PLATAFORMA | I5: DRENAGEM SUPERFICIAL | L5: OBSERV.
E6: BOM | F6: REG. (ATÉ 10 IRR./KM) | G6: RUÍM (+ 10 IRR./KM) | H6: PÉSSIMA (ATOLEIRO/PTO. CRÍTICO) | I6: LIMPA | J6: OBSTRUÍDA | K6: AUSENTE
A7: 010ETO0250 | B7: C | C7: 0 | D7: 58.16433 | F7: X | J7: X
A8: 010ETO0290 | B8: C | C8: 0 | D8: 19.427802 | F8: X | J8: X
E36: =IF(E7="X",(D7-C7),"0") -> 0 | F36: =IF(F7="X",(D7-C7),"0") -> 58.16433 | G36: =IF(G7="X",(D7-C7),"0") -> 0 | H36: =IF(H7="X",(D7-C7),"0") -> 0 | I36: =IF(I7="X",(D7-C7),"0") -> 0 | J36: =IF(J7="X",(D7-C7),"0") -> 58.16433 | K36: =IF(K7="X",(D7-C7),"0") -> 0
E37: =IF(E8="X",(D8-C8),"0") -> 0 | F37: =IF(F8="X",(D8-C8),"0") -> 19.427802 | G37: =IF(G8="X",(D8-C8),"0") -> 0 | H37: =IF(H8="X",(D8-C8),"0") -> 0 | I37: =IF(I8="X",(D8-C8),"0") -> 0 | J37: =IF(J8="X",(D8-C8),"0") -> 19.427802 | K37: =IF(K8="X",(D8-C8),"0") -> 0
E38: =IF(E9="X",(D9-C9),"0") -> 0 | F38: =IF(F9="X",(D9-C9),"0") -> 0 | G38: =IF(G9="X",(D9-C9),"0") -> 0 | H38: =IF(H9="X",(D9-C9),"0") -> 0 | I38: =IF(I9="X",(D9-C9),"0") -> 0 | J38: =IF(J9="X",(D9-C9),"0") -> 0 | K38: =IF(K9="X",(D9-C9),"0") -> 0
E39: =IF(E10="X",(D10-C10),"0") -> 0 | F39: =IF(F10="X",(D10-C10),"0") -> 0 | G39: =IF(G10="X",(D10-C10),"0") -> 0 | H39: =IF(H10="X",(D10-C10),"0") -> 0 | I39: =IF(I10="X",(D10-C10),"0") -> 0 | J39: =IF(J10="X",(D10-C10),"0") -> 0 | K39: =IF(K10="X",(D10-C10),"0") -> 0
E40: =IF(E11="X",(D11-C11),"0") -> 0 | F40: =IF(F11="X",(D11-C11),"0") -> 0 | G40: =IF(G11="X",(D11-C11),"0") -> 0 | H40: =IF(H11="X",(D11-C11),"0") -> 0 | I40: =IF(I11="X",(D11-C11),"0") -> 0 | J40: =IF(J11="X",(D11-C11),"0") -> 0 | K40: =IF(K11="X",(D11-C11),"0") -> 0
E41: =IF(E12="X",(D12-C12),"0") -> 0 | F41: =IF(F12="X",(D12-C12),"0") -> 0 | G41: =IF(G12="X",(D12-C12),"0") -> 0 | H41: =IF(H12="X",(D12-C12),"0") -> 0 | I41: =IF(I12="X",(D12-C12),"0") -> 0 | J41: =IF(J12="X",(D12-C12),"0") -> 0 | K41: =IF(K12="X",(D12-C12),"0") -> 0
E42: =IF(E13="X",(D13-C13),"0") -> 0 | F42: =IF(F13="X",(D13-C13),"0") -> 0 | G42: =IF(G13="X",(D13-C13),"0") -> 0 | H42: =IF(H13="X",(D13-C13),"0") -> 0 | I42: =IF(I13="X",(D13-C13),"0") -> 0 | J42: =IF(J13="X",(D13-C13),"0") -> 0 | K42: =IF(K13="X",(D13-C13),"0") -> 0
E43: =IF(E14="X",(D14-C14),"0") -> 0 | F43: =IF(F14="X",(D14-C14),"0") -> 0 | G43: =IF(G14="X",(D14-C14),"0") -> 0 | H43: =IF(H14="X",(D14-C14),"0") -> 0 | I43: =IF(I14="X",(D14-C14),"0") -> 0 | J43: =IF(J14="X",(D14-C14),"0") -> 0 | K43: =IF(K14="X",(D14-C14),"0") -> 0
E44: =IF(E15="X",(D15-C15),"0") -> 0 | F44: =IF(F15="X",(D15-C15),"0") -> 0 | G44: =IF(G15="X",(D15-C15),"0") -> 0 | H44: =IF(H15="X",(D15-C15),"0") -> 0 | I44: =IF(I15="X",(D15-C15),"0") -> 0 | J44: =IF(J15="X",(D15-C15),"0") -> 0 | K44: =IF(K15="X",(D15-C15),"0") -> 0
E45: =IF(E16="X",(D16-C16),"0") -> 0 | F45: =IF(F16="X",(D16-C16),"0") -> 0 | G45: =IF(G16="X",(D16-C16),"0") -> 0 | H45: =IF(H16="X",(D16-C16),"0") -> 0 | I45: =IF(I16="X",(D16-C16),"0") -> 0 | J45: =IF(J16="X",(D16-C16),"0") -> 0 | K45: =IF(K16="X",(D16-C16),"0") -> 0
E46: =IF(E17="X",(D17-C17),"0") -> 0 | F46: =IF(F17="X",(D17-C17),"0") -> 0 | G46: =IF(G17="X",(D17-C17),"0") -> 0 | H46: =IF(H17="X",(D17-C17),"0") -> 0 | I46: =IF(I17="X",(D17-C17),"0") -> 0 | J46: =IF(J17="X",(D17-C17),"0") -> 0 | K46: =IF(K17="X",(D17-C17),"0") -> 0
E47: =IF(E18="X",(D18-C18),"0") -> 0 | F47: =IF(F18="X",(D18-C18),"0") -> 0 | G47: =IF(G18="X",(D18-C18),"0") -> 0 | H47: =IF(H18="X",(D18-C18),"0") -> 0 | I47: =IF(I18="X",(D18-C18),"0") -> 0 | J47: =IF(J18="X",(D18-C18),"0") -> 0 | K47: =IF(K18="X",(D18-C18),"0") -> 0
... E61: =IF(E32="X",(D32-C32),"0") -> 0 | F61: =IF(F32="X",(D32-C32),"0") -> 0 | G61: =IF(G32="X",(D32-C32),"0") -> 0 | H61: =IF(H32="X",(D32-C32),"0") -> 0 | I61: =IF(I32="X",(D32-C32),"0") -> 0 | J61: =IF(J32="X",(D32-C32),"0") -> 0 | K61: =IF(K32="X",(D32-C32),"0") -> 0
E62: =SUM(E36:E61) -> 0 | F62: =SUM(F36:F61) -> 77.592133 | G62: =SUM(G36:G61) -> 0 | H62: =SUM(H36:H61) -> 0 | I62: =SUM(I36:I61) -> 0 | J62: =SUM(J36:J61) -> 77.592133 | K62: =SUM(K36:K61) -> 0

Sheet 69
A1: PROGRAMA DE MANUTENÇÃORODOVIÁRIA | I1: DATA: | J1: ='67'!$J$1 -> 46204 | L1: TÉCNICO RESP. | N1: ='67'!$N$1 -> ENG. VINICIUS RODRIGUES FERREIRA DE OLIVEIRA
F2: RODOVIAS NÃO PAVIMENTADAS
A3: FICHA DE INSPEÇÃO: | B3: =Trechos!E71 -> RODOVIA TO-010 - TRECHO ENTR. TO-222 (POVOADO FARTURÃO) - BABAÇULÂNDIA
A5: S.R.E. | B5: SENTIDO | C5: INÍCIO (KM) | D5: FIM (KM) | E5: CONDIÇÃO DA PLATAFORMA | I5: DRENAGEM SUPERFICIAL | L5: OBSERV.
E6: BOM | F6: REG. (ATÉ 10 IRR./KM) | G6: RUÍM (+ 10 IRR./KM) | H6: PÉSSIMA (ATOLEIRO/PTO. CRÍTICO) | I6: LIMPA | J6: OBSTRUÍDA | K6: AUSENTE
A7: 010ETO0380 | B7: D | C7: 0 | D7: 1 | E7: X | I7: X
B8: D | C8: =D7 -> 1 | D8: 2 | E8: X | I8: X
C9: =D8 -> 2 | D9: 3 | E9: X | I9: X
C10: =D9 -> 3 | D10: 4 | E10: X | I10: X
C11: =D10 -> 4 | D11: 5 | E11: X | I11: X
C12: =D11 -> 5 | D12: 6 | E12: X | I12: X
C13: =D12 -> 6 | D13: 7 | E13: X | I13: X
C14: =D13 -> 7 | D14: 8 | E14: X | I14: X
C15: =D14 -> 8 | D15: 9 | E15: X | I15: X
C16: =D15 -> 9 | D16: 10 | E16: X | I16: X
C17: =D16 -> 10 | D17: 11 | E17: X | I17: X
C18: =D17 -> 11 | D18: 12 | E18: X | I18: X
C19: =D18 -> 12 | D19: 13 | E19: X | I19: X
C20: =D19 -> 13 | D20: 14 | E20: X | I20: X
... C40: =D39 -> 33 | D40: 33.59 | E40: X | I40: X
A41: 010ETO0400 | B41: D | C41: 0 | D41: 1 | E41: X | K41: X
C42: =D41 -> 1 | D42: 4.84 | E42: X | K42: X
E47: =IF(E7="X",(D7-C7),"0") -> 1 | F47: =IF(F7="X",(D7-C7),"0") -> 0 | G47: =IF(G7="X",(D7-C7),"0") -> 0 | H47: =IF(H7="X",(D7-C7),"0") -> 0 | I47: =IF(I7="X",(D7-C7),"0") -> 1 | J47: =IF(J7="X",(D7-C7),"0") -> 0 | K47: =IF(K7="X",(D7-C7),"0") -> 0
E48: =IF(E8="X",(D8-C8),"0") -> 1 | F48: =IF(F8="X",(D8-C8),"0") -> 0 | G48: =IF(G8="X",(D8-C8),"0") -> 0 | H48: =IF(H8="X",(D8-C8),"0") -> 0 | I48: =IF(I8="X",(D8-C8),"0") -> 1 | J48: =IF(J8="X",(D8-C8),"0") -> 0 | K48: =IF(K8="X",(D8-C8),"0") -> 0
E49: =IF(E9="X",(D9-C9),"0") -> 1 | F49: =IF(F9="X",(D9-C9),"0") -> 0 | G49: =IF(G9="X",(D9-C9),"0") -> 0 | H49: =IF(H9="X",(D9-C9),"0") -> 0 | I49: =IF(I9="X",(D9-C9),"0") -> 1 | J49: =IF(J9="X",(D9-C9),"0") -> 0 | K49: =IF(K9="X",(D9-C9),"0") -> 0
E50: =IF(E10="X",(D10-C10),"0") -> 1 | F50: =IF(F10="X",(D10-C10),"0") -> 0 | G50: =IF(G10="X",(D10-C10),"0") -> 0 | H50: =IF(H10="X",(D10-C10),"0") -> 0 | I50: =IF(I10="X",(D10-C10),"0") -> 1 | J50: =IF(J10="X",(D10-C10),"0") -> 0 | K50: =IF(K10="X",(D10-C10),"0") -> 0
E51: =IF(E11="X",(D11-C11),"0") -> 1 | F51: =IF(F11="X",(D11-C11),"0") -> 0 | G51: =IF(G11="X",(D11-C11),"0") -> 0 | H51: =IF(H11="X",(D11-C11),"0") -> 0 | I51: =IF(I11="X",(D11-C11),"0") -> 1 | J51: =IF(J11="X",(D11-C11),"0") -> 0 | K51: =IF(K11="X",(D11-C11),"0") -> 0
E52: =IF(E12="X",(D12-C12),"0") -> 1 | F52: =IF(F12="X",(D12-C12),"0") -> 0 | G52: =IF(G12="X",(D12-C12),"0") -> 0 | H52: =IF(H12="X",(D12-C12),"0") -> 0 | I52: =IF(I12="X",(D12-C12),"0") -> 1 | J52: =IF(J12="X",(D12-C12),"0") -> 0 | K52: =IF(K12="X",(D12-C12),"0") -> 0
E53: =IF(E13="X",(D13-C13),"0") -> 1 | F53: =IF(F13="X",(D13-C13),"0") -> 0 | G53: =IF(G13="X",(D13-C13),"0") -> 0 | H53: =IF(H13="X",(D13-C13),"0") -> 0 | I53: =IF(I13="X",(D13-C13),"0") -> 1 | J53: =IF(J13="X",(D13-C13),"0") -> 0 | K53: =IF(K13="X",(D13-C13),"0") -> 0
E54: =IF(E14="X",(D14-C14),"0") -> 1 | F54: =IF(F14="X",(D14-C14),"0") -> 0 | G54: =IF(G14="X",(D14-C14),"0") -> 0 | H54: =IF(H14="X",(D14-C14),"0") -> 0 | I54: =IF(I14="X",(D14-C14),"0") -> 1 | J54: =IF(J14="X",(D14-C14),"0") -> 0 | K54: =IF(K14="X",(D14-C14),"0") -> 0
E55: =IF(E15="X",(D15-C15),"0") -> 1 | F55: =IF(F15="X",(D15-C15),"0") -> 0 | G55: =IF(G15="X",(D15-C15),"0") -> 0 | H55: =IF(H15="X",(D15-C15),"0") -> 0 | I55: =IF(I15="X",(D15-C15),"0") -> 1 | J55: =IF(J15="X",(D15-C15),"0") -> 0 | K55: =IF(K15="X",(D15-C15),"0") -> 0
E56: =IF(E16="X",(D16-C16),"0") -> 1 | F56: =IF(F16="X",(D16-C16),"0") -> 0 | G56: =IF(G16="X",(D16-C16),"0") -> 0 | H56: =IF(H16="X",(D16-C16),"0") -> 0 | I56: =IF(I16="X",(D16-C16),"0") -> 1 | J56: =IF(J16="X",(D16-C16),"0") -> 0 | K56: =IF(K16="X",(D16-C16),"0") -> 0
E57: =IF(E17="X",(D17-C17),"0") -> 1 | F57: =IF(F17="X",(D17-C17),"0") -> 0 | G57: =IF(G17="X",(D17-C17),"0") -> 0 | H57: =IF(H17="X",(D17-C17),"0") -> 0 | I57: =IF(I17="X",(D17-C17),"0") -> 1 | J57: =IF(J17="X",(D17-C17),"0") -> 0 | K57: =IF(K17="X",(D17-C17),"0") -> 0
E58: =IF(E18="X",(D18-C18),"0") -> 1 | F58: =IF(F18="X",(D18-C18),"0") -> 0 | G58: =IF(G18="X",(D18-C18),"0") -> 0 | H58: =IF(H18="X",(D18-C18),"0") -> 0 | I58: =IF(I18="X",(D18-C18),"0") -> 1 | J58: =IF(J18="X",(D18-C18),"0") -> 0 | K58: =IF(K18="X",(D18-C18),"0") -> 0
... E86: =IF(E46="X",(D46-C46),"0") -> 0 | F86: =IF(F46="X",(D46-C46),"0") -> 0 | G86: =IF(G46="X",(D46-C46),"0") -> 0 | H86: =IF(H46="X",(D46-C46),"0") -> 0 | I86: =IF(I46="X",(D46-C46),"0") -> 0 | J86: =IF(J46="X",(D46-C46),"0") -> 0 | K86: =IF(K46="X",(D46-C46),"0") -> 0
E87: =SUM(E47:E86) -> 38.43 | F87: =SUM(F47:F86) -> 0 | G87: =SUM(G47:G86) -> 0 | H87: =SUM(H47:H86) -> 0 | I87: =SUM(I47:I86) -> 33.59 | J87: =SUM(J47:J86) -> 0 | K87: =SUM(K47:K86) -> 4.84

Sheet 71
A1: PROGRAMA DE MANUTENÇÃORODOVIÁRIA | I1: DATA: | J1: ='67'!$J$1 -> 46204 | L1: TÉCNICO RESP. | N1: ='67'!$N$1 -> ENG. VINICIUS RODRIGUES FERREIRA DE OLIVEIRA
F2: RODOVIAS NÃO PAVIMENTADAS
A3: FICHA DE INSPEÇÃO: | B3: =Trechos!E73 -> RODOVIA TO-020 - TRECHO RECURSOLÂNDIA - CAMPOS LINDOS
A5: S.R.E. | B5: SENTIDO | C5: INÍCIO (KM) | D5: FIM (KM) | E5: CONDIÇÃO DA PLATAFORMA | I5: DRENAGEM SUPERFICIAL | L5: OBSERV.
E6: BOM | F6: REG. (ATÉ 10 IRR./KM) | G6: RUÍM (+ 10 IRR./KM) | H6: PÉSSIMA (ATOLEIRO/PTO. CRÍTICO) | I6: LIMPA | J6: OBSTRUÍDA | K6: AUSENTE
A7: 020ETO0210 | B7: C | C7: 0 | D7: 1 | F7: X | J7: X
C8: =D7 -> 1 | D8: 2 | F8: X | J8: X
C9: =D8 -> 2 | D9: 3 | F9: X | J9: X
C10: =D9 -> 3 | D10: 4 | F10: X | J10: X
C11: =D10 -> 4 | D11: 5 | F11: X | J11: X
C12: =D11 -> 5 | D12: 6 | F12: X | J12: X
C13: =D12 -> 6 | D13: 7 | F13: X | J13: X
C14: =D13 -> 7 | D14: 8 | F14: X | J14: X
C15: =D14 -> 8 | D15: 9 | F15: X | J15: X
C16: =D15 -> 9 | D16: 10 | F16: X | J16: X
C17: =D16 -> 10 | D17: 11 | G17: X | J17: X
C18: =D17 -> 11 | D18: 12 | G18: X | J18: X
C19: =D18 -> 12 | D19: 13 | G19: X | J19: X
C20: =D19 -> 13 | D20: 14 | G20: X | J20: X
C21: =D20 -> 14 | D21: 15 | G21: X | J21: X
C22: =D21 -> 15 | D22: 16 | G22: X | J22: X
C23: =D22 -> 16 | D23: 17 | G23: X | J23: X
C24: =D23 -> 17 | D24: 18 | G24: X | J24: X
C25: =D24 -> 18 | D25: 19 | F25: X | J25: X
C26: =D25 -> 19 | D26: 20 | F26: X | J26: X
C27: =D26 -> 20 | D27: 21 | F27: X | J27: X
C28: =D27 -> 21 | D28: 22 | F28: X | J28: X
C29: =D28 -> 22 | D29: 23 | F29: X | J29: X
C30: =D29 -> 23 | D30: 24 | F30: X | J30: X
C31: =D30 -> 24 | D31: 25 | F31: X | J31: X
C32: =D31 -> 25 | D32: 26 | F32: X | J32: X
C33: =D32 -> 26 | D33: 27 | F33: X | J33: X
C34: =D33 -> 27 | D34: 28 | F34: X | J34: X
C35: =D34 -> 28 | D35: 29 | F35: X | J35: X
C36: =D35 -> 29 | D36: 30 | F36: X | J36: X
... C39: =D38 -> 32 | D39: 33 | F39: X | J39: X
E46: =IF(E7="X",(D7-C7),"0") -> 0 | F46: =IF(F7="X",(D7-C7),"0") -> 1 | G46: =IF(G7="X",(D7-C7),"0") -> 0 | H46: =IF(H7="X",(D7-C7),"0") -> 0 | I46: =IF(I7="X",(D7-C7),"0") -> 0 | J46: =IF(J7="X",(D7-C7),"0") -> 1 | K46: =IF(K7="X",(D7-C7),"0") -> 0
E47: =IF(E8="X",(D8-C8),"0") -> 0 | F47: =IF(F8="X",(D8-C8),"0") -> 1 | G47: =IF(G8="X",(D8-C8),"0") -> 0 | H47: =IF(H8="X",(D8-C8),"0") -> 0 | I47: =IF(I8="X",(D8-C8),"0") -> 0 | J47: =IF(J8="X",(D8-C8),"0") -> 1 | K47: =IF(K8="X",(D8-C8),"0") -> 0
E48: =IF(E9="X",(D9-C9),"0") -> 0 | F48: =IF(F9="X",(D9-C9),"0") -> 1 | G48: =IF(G9="X",(D9-C9),"0") -> 0 | H48: =IF(H9="X",(D9-C9),"0") -> 0 | I48: =IF(I9="X",(D9-C9),"0") -> 0 | J48: =IF(J9="X",(D9-C9),"0") -> 1 | K48: =IF(K9="X",(D9-C9),"0") -> 0
E49: =IF(E10="X",(D10-C10),"0") -> 0 | F49: =IF(F10="X",(D10-C10),"0") -> 1 | G49: =IF(G10="X",(D10-C10),"0") -> 0 | H49: =IF(H10="X",(D10-C10),"0") -> 0 | I49: =IF(I10="X",(D10-C10),"0") -> 0 | J49: =IF(J10="X",(D10-C10),"0") -> 1 | K49: =IF(K10="X",(D10-C10),"0") -> 0
...

Sheet 72
A1: PROGRAMA DE MANUTENÇÃORODOVIÁRIA | I1: DATA: | J1: ='67'!$J$1 -> 46204 | L1: TÉCNICO RESP. | N1: ='67'!$N$1 -> ENG. VINICIUS RODRIGUES FERREIRA DE OLIVEIRA
F2: RODOVIAS NÃO PAVIMENTADAS
A3: FICHA DE INSPEÇÃO: | B3: =Trechos!E74 -> RODOVIA TO-130 - TRECHO ENTR. TO-424 - TRECHO ENTR. TO-222
A5: S.R.E. | B5: SENTIDO | C5: INÍCIO (KM) | D5: FIM (KM) | E5: CONDIÇÃO DA PLATAFORMA | I5: DRENAGEM SUPERFICIAL | L5: OBSERV.
E6: BOM | F6: REG. (ATÉ 10 IRR./KM) | G6: RUÍM (+ 10 IRR./KM) | H6: PÉSSIMA (ATOLEIRO/PTO. CRÍTICO) | I6: LIMPA | J6: OBSTRUÍDA | K6: AUSENTE
A7: 130ETO0010 | B7: C | C7: 0 | D7: 1 | F7: X | J7: X
C8: =D7 -> 1 | D8: 2 | F8: X | J8: X
C9: =D8 -> 2 | D9: 3 | F9: X | J9: X
C10: =D9 -> 3 | D10: 4 | F10: X | J10: X
C11: =D10 -> 4 | D11: 5 | F11: X | J11: X
C12: =D11 -> 5 | D12: 6 | F12: X | J12: X
C13: =D12 -> 6 | D13: 7 | F13: X | J13: X
C14: =D13 -> 7 | D14: 8 | F14: X | J14: X
C15: =D14 -> 8 | D15: 9 | F15: X | J15: X
C16: =D15 -> 9 | D16: 10 | F16: X | J16: X
C17: =D16 -> 10 | D17: 11 | F17: X | J17: X
C18: =D17 -> 11 | D18: 12 | F18: X | J18: X
C19: =D18 -> 12 | D19: 13 | F19: X | J19: X
... C26: =D25 -> 19 | D26: 19.33 | F26: X | J26: X
E31: =IF(E7="X",(D7-C7),"0") -> 0 | F31: =IF(F7="X",(D7-C7),"0") -> 1 | G31: =IF(G7="X",(D7-C7),"0") -> 0 | H31: =IF(H7="X",(D7-C7),"0") -> 0 | I31: =IF(I7="X",(D7-C7),"0") -> 0 | J31: =IF(J7="X",(D7-C7),"0") -> 1 | K31: =IF(K7="X",(D7-C7),"0") -> 0
E32: =IF(E8="X",(D8-C8),"0") -> 0 | F32: =IF(F8="X",(D8-C8),"0") -> 1 | G32: =IF(G8="X",(D8-C8),"0") -> 0 | H32: =IF(H8="X",(D8-C8),"0") -> 0 | I32: =IF(I8="X",(D8-C8),"0") -> 0 | J32: =IF(J8="X",(D8-C8),"0") -> 1 | K32: =IF(K8="X",(D8-C8),"0") -> 0
E33: =IF(E9="X",(D9-C9),"0") -> 0 | F33: =IF(F9="X",(D9-C9),"0") -> 1 | G33: =IF(G9="X",(D9-C9),"0") -> 0 | H33: =IF(H9="X",(D9-C9),"0") -> 0 | I33: =IF(I9="X",(D9-C9),"0") -> 0 | J33: =IF(J9="X",(D9-C9),"0") -> 1 | K33: =IF(K9="X",(D9-C9),"0") -> 0
E34: =IF(E10="X",(D10-C10),"0") -> 0 | F34: =IF(F10="X",(D10-C10),"0") -> 1 | G34: =IF(G10="X",(D10-C10),"0") -> 0 | H34: =IF(H10="X",(D10-C10),"0") -> 0 | I34: =IF(I10="X",(D10-C10),"0") -> 0 | J34: =IF(J10="X",(D10-C10),"0") -> 1 | K34: =IF(K10="X",(D10-C10),"0") -> 0
E35: =IF(E11="X",(D11-C11),"0") -> 0 | F35: =IF(F11="X",(D11-C11),"0") -> 1 | G35: =IF(G11="X",(D11-C11),"0") -> 0 | H35: =IF(H11="X",(D11-C11),"0") -> 0 | I35: =IF(I11="X",(D11-C11),"0") -> 0 | J35: =IF(J11="X",(D11-C11),"0") -> 1 | K35: =IF(K11="X",(D11-C11),"0") -> 0
E36: =IF(E12="X",(D12-C12),"0") -> 0 | F36: =IF(F12="X",(D12-C12),"0") -> 1 | G36: =IF(G12="X",(D12-C12),"0") -> 0 | H36: =IF(H12="X",(D12-C12),"0") -> 0 | I36: =IF(I12="X",(D12-C12),"0") -> 0 | J36: =IF(J12="X",(D12-C12),"0") -> 1 | K36: =IF(K12="X",(D12-C12),"0") -> 0
E37: =IF(E13="X",(D13-C13),"0") -> 0 | F37: =IF(F13="X",(D13-C13),"0") -> 1 | G37: =IF(G13="X",(D13-C13),"0") -> 0 | H37: =IF(H13="X",(D13-C13),"0") -> 0 | I37: =IF(I13="X",(D13-C13),"0") -> 0 | J37: =IF(J13="X",(D13-C13),"0") -> 1 | K37: =IF(K13="X",(D13-C13),"0") -> 0
E38: =IF(E14="X",(D14-C14),"0") -> 0 | F38: =IF(F14="X",(D14-C14),"0") -> 1 | G38: =IF(G14="X",(D14-C14),"0") -> 0 | H38: =IF(H14="X",(D14-C14),"0") -> 0 | I38: =IF(I14="X",(D14-C14),"0") -> 0 | J38: =IF(J14="X",(D14-C14),"0") -> 1 | K38: =IF(K14="X",(D14-C14),"0") -> 0
E39: =IF(E15="X",(D15-C15),"0") -> 0 | F39: =IF(F15="X",(D15-C15),"0") -> 1 | G39: =IF(G15="X",(D15-C15),"0") -> 0 | H39: =IF(H15="X",(D15-C15),"0") -> 0 | I39: =IF(I15="X",(D15-C15),"0") -> 0 | J39: =IF(J15="X",(D15-C15),"0") -> 1 | K39: =IF(K15="X",(D15-C15),"0") -> 0
E40: =IF(E16="X",(D16-C16),"0") -> 0 | F40: =IF(F16="X",(D16-C16),"0") -> 1 | G40: =IF(G16="X",(D16-C16),"0") -> 0 | H40: =IF(H16="X",(D16-C16),"0") -> 0 | I40: =IF(I16="X",(D16-C16),"0") -> 0 | J40: =IF(J16="X",(D16-C16),"0") -> 1 | K40: =IF(K16="X",(D16-C16),"0") -> 0
E41: =IF(E17="X",(D17-C17),"0") -> 0 | F41: =IF(F17="X",(D17-C17),"0") -> 1 | G41: =IF(G17="X",(D17-C17),"0") -> 0 | H41: =IF(H17="X",(D17-C17),"0") -> 0 | I41: =IF(I17="X",(D17-C17),"0") -> 0 | J41: =IF(J17="X",(D17-C17),"0") -> 1 | K41: =IF(K17="X",(D17-C17),"0") -> 0
E42: =IF(E18="X",(D18-C18),"0") -> 0 | F42: =IF(F18="X",(D18-C18),"0") -> 1 | G42: =IF(G18="X",(D18-C18),"0") -> 0 | H42: =IF(H18="X",(D18-C18),"0") -> 0 | I42: =IF(I18="X",(D18-C18),"0") -> 0 | J42: =IF(J18="X",(D18-C18),"0") -> 1 | K42: =IF(K18="X",(D18-C18),"0") -> 0
... E52: =IF(E28="X",(D28-C28),"0") -> 0 | F52: =IF(F28="X",(D28-C28),"0") -> 0 | G52: =IF(G28="X",(D28-C28),"0") -> 0 | H52: =IF(H28="X",(D28-C28),"0") -> 0 | I52: =IF(I28="X",(D28-C28),"0") -> 0 | J52: =IF(J28="X",(D28-C28),"0") -> 0 | K52: =IF(K28="X",(D28-C28),"0") -> 0
E53: =SUM(E31:E52) -> 0 | F53: =SUM(F31:F52) -> 19.33 | G53: =SUM(G31:G52) -> 0 | H53: =SUM(H31:H52) -> 0 | I53: =SUM(I31:I52) -> 0 | J53: =SUM(J31:J52) -> 19.33 | K53: =SUM(K31:K52) -> 0

Sheet 75
A1: PROGRAMA DE MANUTENÇÃORODOVIÁRIA | I1: DATA: | J1: ='67'!$J$1 -> 46204 | L1: TÉCNICO RESP. | N1: ='67'!$N$1 -> ENG. VINICIUS RODRIGUES FERREIRA DE OLIVEIRA
F2: RODOVIAS NÃO PAVIMENTADAS
A3: FICHA DE INSPEÇÃO: | B3: =TT!C8 -> RODOVIA TO-226 - TRECHO NOVA OLINDA - ENTR. TO-010
A5: S.R.E. | B5: SENTIDO | C5: INÍCIO (KM) | D5: FIM (KM) | E5: CONDIÇÃO DA PLATAFORMA | I5: DRENAGEM SUPERFICIAL | L5: OBSERV.
E6: BOM | F6: REG. (ATÉ 10 IRR./KM) | G6: RUÍM (+ 10 IRR./KM) | H6: PÉSSIMA (ATOLEIRO/PTO. CRÍTICO) | I6: LIMPA | J6: OBSTRUÍDA | K6: AUSENTE
A7: 226ETO0200 | B7: D | C7: 0 | D7: 6.3 | F7: X | J7: X
A8: 226ETO0200 | B8: D | C8: =D7 -> 6.3 | D8: 6.4 | F8: X | J8: X
A9: 226ETO0200 | B9: D | C9: =D8 -> 6.4 | D9: 7 | F9: X | J9: X
A10: 226ETO0200 | B10: D | C10: =D9 -> 7 | D10: 7.1 | F10: X | J10: X
A11: 226ETO0200 | B11: D | C11: =D10 -> 7.1 | D11: 9.7 | F11: X | J11: X
A12: 226ETO0200 | B12: D | C12: =D11 -> 9.7 | D12: 9.9 | F12: X | J12: X
A13: 226ETO0200 | B13: D | C13: =D12 -> 9.9 | D13: 11.1 | F13: X | J13: X
A14: 226ETO0200 | B14: D | C14: =D13 -> 11.1 | D14: 12 | F14: X | J14: X
A15: 226ETO0200 | B15: D | C15: =D14 -> 12 | D15: 12.9 | F15: X | J15: X
A16: 226ETO0200 | B16: D | C16: =D15 -> 12.9 | D16: 13.8 | F16: X | J16: X
A17: 226ETO0200 | B17: D | C17: =D16 -> 13.8 | D17: 17.62 | F17: X | J17: X
A18: 226ETO0190 | B18: D | C18: 0 | D18: 1.1 | F18: X | J18: X
A19: 226ETO0190 | B19: D | C19: =D18 -> 1.1 | D19: 1.8 | F19: X | J19: X
A20: 226ETO0190 | B20: D | C20: =D19 -> 1.8 | D20: 2 | F20: X | J20: X
A21: 226ETO0190 | B21: D | C21: =D20 -> 2 | D21: 2.2 | F21: X | J21: X
A22: 226ETO0190 | B22: D | C22: =D21 -> 2.2 | D22: 2.6 | F22: X | J22: X
A23: 226ETO0190 | B23: D | C23: =D22 -> 2.6 | D23: 5 | F23: X | J23: X
A24: 226ETO0190 | B24: D | C24: =D23 -> 5 | D24: 6.6 | F24: X | J24: X
A25: 226ETO0190 | B25: D | C25: =D24 -> 6.6 | D25: 6.8 | F25: X | J25: X
A26: 226ETO0190 | B26: D | C26: =D25 -> 6.8 | D26: 9.3 | F26: X | J26: X
A27: 226ETO0190 | B27: D | C27: =D26 -> 9.3 | D27: 11 | F27: X | J27: X
A28: 226ETO0190 | B28: D | C28: =D27 -> 11 | D28: 13 | F28: X | J28: X
A29: 226ETO0190 | B29: D | C29: =D28 -> 13 | D29: 13.1 | F29: X | J29: X
A30: 226ETO0190 | B30: D | C30: =D29 -> 13.1 | D30: 14.5 | F30: X | J30: X
... A41: 226ETO0190 | B41: D | C41: =D40 -> 35 | D41: 36.77 | F41: X | J41: X
E49: =IF(E7="X",(D7-C7),"0") -> 0 | F49: =IF(F7="X",(D7-C7),"0") -> 6.3 | G49: =IF(G7="X",(D7-C7),"0") -> 0 | H49: =IF(H7="X",(D7-C7),"0") -> 0 | I49: =IF(I7="X",(D7-C7),"0") -> 0 | J49: =IF(J7="X",(D7-C7),"0") -> 6.3 | K49: =IF(K7="X",(D7-C7),"0") -> 0
E50: =IF(E8="X",(D8-C8),"0") -> 0 | F50: =IF(F8="X",(D8-C8),"0") -> 0.1 | G50: =IF(G8="X",(D8-C8),"0") -> 0 | H50: =IF(H8="X",(D8-C8),"0") -> 0 | I50: =IF(I8="X",(D8-C8),"0") -> 0 | J50: =IF(J8="X",(D8-C8),"0") -> 0.1 | K50: =IF(K8="X",(D8-C8),"0") -> 0
E51: =IF(E9="X",(D9-C9),"0") -> 0 | F51: =IF(F9="X",(D9-C9),"0") -> 0.6 | G51: =IF(G9="X",(D9-C9),"0") -> 0 | H51: =IF(H9="X",(D9-C9),"0") -> 0 | I51: =IF(I9="X",(D9-C9),"0") -> 0 | J51: =IF(J9="X",(D9-C9),"0") -> 0.6 | K51: =IF(K9="X",(D9-C9),"0") -> 0
E52: =IF(E10="X",(D10-C10),"0") -> 0 | F52: =IF(F10="X",(D10-C10),"0") -> 0.1 | G52: =IF(G10="X",(D10-C10),"0") -> 0 | H52: =IF(H10="X",(D10-C10),"0") -> 0 | I52: =IF(I10="X",(D10-C10),"0") -> 0 | J52: =IF(J10="X",(D10-C10),"0") -> 0.1 | K52: =IF(K10="X",(D10-C10),"0") -> 0
E53: =IF(E11="X",(D11-C11),"0") -> 0 | F53: =IF(F11="X",(D11-C11),"0") -> 2.6 | G53: =IF(G11="X",(D11-C11),"0") -> 0 | H53: =IF(H11="X",(D11-C11),"0") -> 0 | I53: =IF(I11="X",(D11-C11),"0") -> 0 | J53: =IF(J11="X",(D11-C11),"0") -> 2.6 | K53: =IF(K11="X",(D11-C11),"0") -> 0
E54: =IF(E12="X",(D12-C12),"0") -> 0 | F54: =IF(F12="X",(D12-C12),"0") -> 0.2 | G54: =IF(G12="X",(D12-C12),"0") -> 0 | H54: =IF(H12="X",(D12-C12),"0") -> 0 | I54: =IF(I12="X",(D12-C12),"0") -> 0 | J54: =IF(J12="X",(D12-C12),"0") -> 0.2 | K54: =IF(K12="X",(D12-C12),"0") -> 0
E55: =IF(E13="X",(D13-C13),"0") -> 0 | F55: =IF(F13="X",(D13-C13),"0") -> 1.2 | G55: =IF(G13="X",(D13-C13),"0") -> 0 | H55: =IF(H13="X",(D13-C13),"0") -> 0 | I55: =IF(I13="X",(D13-C13),"0") -> 0 | J55: =IF(J13="X",(D13-C13),"0") -> 1.2 | K55: =IF(K13="X",(D13-C13),"0") -> 0
E56: =IF(E14="X",(D14-C14),"0") -> 0 | F56: =IF(F14="X",(D14-C14),"0") -> 0.9 | G56: =IF(G14="X",(D14-C14),"0") -> 0 | H56: =IF(H14="X",(D14-C14),"0") -> 0 | I56: =IF(I14="X",(D14-C14),"0") -> 0 | J56: =IF(J14="X",(D14-C14),"0") -> 0.9 | K56: =IF(K14="X",(D14-C14),"0") -> 0
E57: =IF(E15="X",(D15-C15),"0") -> 0 | F57: =IF(F15="X",(D15-C15),"0") -> 0.9 | G57: =IF(G15="X",(D15-C15),"0") -> 0 | H57: =IF(H15="X",(D15-C15),"0") -> 0 | I57: =IF(I15="X",(D15-C15),"0") -> 0 | J57: =IF(J15="X",(D15-C15),"0") -> 0.9 | K57: =IF(K15="X",(D15-C15),"0") -> 0
E58: =IF(E16="X",(D16-C16),"0") -> 0 | F58: =IF(F16="X",(D16-C16),"0") -> 0.9 | G58: =IF(G16="X",(D16-C16),"0") -> 0 | H58: =IF(H16="X",(D16-C16),"0") -> 0 | I58: =IF(I16="X",(D16-C16),"0") -> 0 | J58: =IF(J16="X",(D16-C16),"0") -> 0.9 | K58: =IF(K16="X",(D16-C16),"0") -> 0
...

Sheet 76
A1: PROGRAMA DE MANUTENÇÃORODOVIÁRIA | I1: DATA: | J1: ='67'!$J$1 -> 46204 | L1: TÉCNICO RESP. | N1: ='67'!$N$1 -> ENG. VINICIUS RODRIGUES FERREIRA DE OLIVEIRA
F2: RODOVIAS NÃO PAVIMENTADAS
A3: FICHA DE INSPEÇÃO: | B3: =Trechos!E77 -> RODOVIA TO-226 - TRECHO ENTR. TO-010 (POVOADO CAMPOS) - ENTR. BR-010
A5: S.R.E. | B5: SENTIDO | C5: INÍCIO (KM) | D5: FIM (KM) | E5: CONDIÇÃO DA PLATAFORMA | I5: DRENAGEM SUPERFICIAL | L5: OBSERV.
E6: BOM | F6: REG. (ATÉ 10 IRR./KM) | G6: RUÍM (+ 10 IRR./KM) | H6: PÉSSIMA (ATOLEIRO/PTO. CRÍTICO) | I6: LIMPA | J6: OBSTRUÍDA | K6: AUSENTE
A7: 226ETO0120 | B7: C | C7: 0 | D7: 14.646522 | F7: X | J7: X
A8: 226ETO0130 | B8: C | C8: 0 | D8: 13.697356 | F8: X | J8: X
E36: =IF(E7="X",(D7-C7),"0") -> 0 | F36: =IF(F7="X",(D7-C7),"0") -> 14.646522 | G36: =IF(G7="X",(D7-C7),"0") -> 0 | H36: =IF(H7="X",(D7-C7),"0") -> 0 | I36: =IF(I7="X",(D7-C7),"0") -> 0 | J36: =IF(J7="X",(D7-C7),"0") -> 14.646522 | K36: =IF(K7="X",(D7-C7),"0") -> 0
E37: =IF(E8="X",(D8-C8),"0") -> 0 | F37: =IF(F8="X",(D8-C8),"0") -> 13.697356 | G37: =IF(G8="X",(D8-C8),"0") -> 0 | H37: =IF(H8="X",(D8-C8),"0") -> 0 | I37: =IF(I8="X",(D8-C8),"0") -> 0 | J37: =IF(J8="X",(D8-C8),"0") -> 13.697356 | K37: =IF(K8="X",(D8-C8),"0") -> 0
E38: =IF(E9="X",(D9-C9),"0") -> 0 | F38: =IF(F9="X",(D9-C9),"0") -> 0 | G38: =IF(G9="X",(D9-C9),"0") -> 0 | H38: =IF(H9="X",(D9-C9),"0") -> 0 | I38: =IF(I9="X",(D9-C9),"0") -> 0 | J38: =IF(J9="X",(D9-C9),"0") -> 0 | K38: =IF(K9="X",(D9-C9),"0") -> 0
E39: =IF(E10="X",(D10-C10),"0") -> 0 | F39: =IF(F10="X",(D10-C10),"0") -> 0 | G39: =IF(G10="X",(D10-C10),"0") -> 0 | H39: =IF(H10="X",(D10-C10),"0") -> 0 | I39: =IF(I10="X",(D10-C10),"0") -> 0 | J39: =IF(J10="X",(D10-C10),"0") -> 0 | K39: =IF(K10="X",(D10-C10),"0") -> 0
E40: =IF(E11="X",(D11-C11),"0") -> 0 | F40: =IF(F11="X",(D11-C11),"0") -> 0 | G40: =IF(G11="X",(D11-C11),"0") -> 0 | H40: =IF(H11="X",(D11-C11),"0") -> 0 | I40: =IF(I11="X",(D11-C11),"0") -> 0 | J40: =IF(J11="X",(D11-C11),"0") -> 0 | K40: =IF(K11="X",(D11-C11),"0") -> 0
E41: =IF(E12="X",(D12-C12),"0") -> 0 | F41: =IF(F12="X",(D12-C12),"0") -> 0 | G41: =IF(G12="X",(D12-C12),"0") -> 0 | H41: =IF(H12="X",(D12-C12),"0") -> 0 | I41: =IF(I12="X",(D12-C12),"0") -> 0 | J41: =IF(J12="X",(D12-C12),"0") -> 0 | K41: =IF(K12="X",(D12-C12),"0") -> 0
E42: =IF(E13="X",(D13-C13),"0") -> 0 | F42: =IF(F13="X",(D13-C13),"0") -> 0 | G42: =IF(G13="X",(D13-C13),"0") -> 0 | H42: =IF(H13="X",(D13-C13),"0") -> 0 | I42: =IF(I13="X",(D13-C13),"0") -> 0 | J42: =IF(J13="X",(D13-C13),"0") -> 0 | K42: =IF(K13="X",(D13-C13),"0") -> 0
E43: =IF(E14="X",(D14-C14),"0") -> 0 | F43: =IF(F14="X",(D14-C14),"0") -> 0 | G43: =IF(G14="X",(D14-C14),"0") -> 0 | H43: =IF(H14="X",(D14-C14),"0") -> 0 | I43: =IF(I14="X",(D14-C14),"0") -> 0 | J43: =IF(J14="X",(D14-C14),"0") -> 0 | K43: =IF(K14="X",(D14-C14),"0") -> 0
E44: =IF(E15="X",(D15-C15),"0") -> 0 | F44: =IF(F15="X",(D15-C15),"0") -> 0 | G44: =IF(G15="X",(D15-C15),"0") -> 0 | H44: =IF(H15="X",(D15-C15),"0") -> 0 | I44: =IF(I15="X",(D15-C15),"0") -> 0 | J44: =IF(J15="X",(D15-C15),"0") -> 0 | K44: =IF(K15="X",(D15-C15),"0") -> 0
E45: =IF(E16="X",(D16-C16),"0") -> 0 | F45: =IF(F16="X",(D16-C16),"0") -> 0 | G45: =IF(G16="X",(D16-C16),"0") -> 0 | H45: =IF(H16="X",(D16-C16),"0") -> 0 | I45: =IF(I16="X",(D16-C16),"0") -> 0 | J45: =IF(J16="X",(D16-C16),"0") -> 0 | K45: =IF(K16="X",(D16-C16),"0") -> 0
E46: =IF(E17="X",(D17-C17),"0") -> 0 | F46: =IF(F17="X",(D17-C17),"0") -> 0 | G46: =IF(G17="X",(D17-C17),"0") -> 0 | H46: =IF(H17="X",(D17-C17),"0") -> 0 | I46: =IF(I17="X",(D17-C17),"0") -> 0 | J46: =IF(J17="X",(D17-C17),"0") -> 0 | K46: =IF(K17="X",(D17-C17),"0") -> 0
E47: =IF(E18="X",(D18-C18),"0") -> 0 | F47: =IF(F18="X",(D18-C18),"0") -> 0 | G47: =IF(G18="X",(D18-C18),"0") -> 0 | H47: =IF(H18="X",(D18-C18),"0") -> 0 | I47: =IF(I18="X",(D18-C18),"0") -> 0 | J47: =IF(J18="X",(D18-C18),"0") -> 0 | K47: =IF(K18="X",(D18-C18),"0") -> 0
... E61: =IF(E32="X",(D32-C32),"0") -> 0 | F61: =IF(F32="X",(D32-C32),"0") -> 0 | G61: =IF(G32="X",(D32-C32),"0") -> 0 | H61: =IF(H32="X",(D32-C32),"0") -> 0 | I61: =IF(I32="X",(D32-C32),"0") -> 0 | J61: =IF(J32="X",(D32-C32),"0") -> 0 | K61: =IF(K32="X",(D32-C32),"0") -> 0
E62: =SUM(E36:E61) -> 0 | F62: =SUM(F36:F61) -> 28.343878 | G62: =SUM(G36:G61) -> 0 | H62: =SUM(H36:H61) -> 0 | I62: =SUM(I36:I61) -> 0 | J62: =SUM(J36:J61) -> 28.343878 | K62: =SUM(K36:K61) -> 0

Sheet 79
A1: PROGRAMA DE MANUTENÇÃORODOVIÁRIA | I1: DATA: | J1: ='67'!$J$1 -> 46204 | L1: TÉCNICO RESP. | N1: ='67'!$N$1 -> ENG. VINICIUS RODRIGUES FERREIRA DE OLIVEIRA
F2: RODOVIAS NÃO PAVIMENTADAS
A3: FICHA DE INSPEÇÃO: | B3: =Trechos!E79 -> RODOVIA TO-423 - TRECHO ARAGUAÍNA - ENTR. TO-424
A5: S.R.E. | B5: SENTIDO | C5: INÍCIO (KM) | D5: FIM (KM) | E5: CONDIÇÃO DA PLATAFORMA | I5: DRENAGEM SUPERFICIAL | L5: OBSERV.
E6: BOM | F6: REG. (ATÉ 10 IRR./KM) | G6: RUÍM (+ 10 IRR./KM) | H6: PÉSSIMA (ATOLEIRO/PTO. CRÍTICO) | I6: LIMPA | J6: OBSTRUÍDA | K6: AUSENTE
A7: 423ETO0020 | B7: C | C7: 0 | D7: 1 | F7: X | J7: X
C8: =D7 -> 1 | D8: 2 | F8: X | J8: X
C9: =D8 -> 2 | D9: 3 | F9: X | J9: X
C10: =D9 -> 3 | D10: 4 | F10: X | J10: X
C11: =D10 -> 4 | D11: 5 | F11: X | J11: X
C12: =D11 -> 5 | D12: 6 | F12: X | J12: X
C13: =D12 -> 6 | D13: 7 | F13: X | J13: X
C14: =D13 -> 7 | D14: 8 | F14: X | J14: X
C15: =D14 -> 8 | D15: 9 | F15: X | J15: X
C16: =D15 -> 9 | D16: 10 | F16: X | J16: X
C17: =D16 -> 10 | D17: 11 | F17: X | J17: X
C18: =D17 -> 11 | D18: 12 | F18: X | J18: X
C19: =D18 -> 12 | D19: 13 | F19: X | J19: X
... C30: =D29 -> 23 | D30: 24 | F30: X | J30: X
C31: =D30 -> 24 | D31: 25 | G31: X | J31: X
C32: =D31 -> 25 | D32: 26 | G32: X | J32: X
C33: =D32 -> 26 | D33: 27 | F33: X | J33: X
C34: =D33 -> 27 | D34: 28 | F34: X | J34: X
C35: =D34 -> 28 | D35: 28.59 | F35: X | J35: X
E38: =IF(E7="X",(D7-C7),"0") -> 0 | F38: =IF(F7="X",(D7-C7),"0") -> 1 | G38: =IF(G7="X",(D7-C7),"0") -> 0 | H38: =IF(H7="X",(D7-C7),"0") -> 0 | I38: =IF(I7="X",(D7-C7),"0") -> 0 | J38: =IF(J7="X",(D7-C7),"0") -> 1 | K38: =IF(K7="X",(D7-C7),"0") -> 0
E39: =IF(E8="X",(D8-C8),"0") -> 0 | F39: =IF(F8="X",(D8-C8),"0") -> 1 | G39: =IF(G8="X",(D8-C8),"0") -> 0 | H39: =IF(H8="X",(D8-C8),"0") -> 0 | I39: =IF(I8="X",(D8-C8),"0") -> 0 | J39: =IF(J8="X",(D8-C8),"0") -> 1 | K39: =IF(K8="X",(D8-C8),"0") -> 0
E40: =IF(E9="X",(D9-C9),"0") -> 0 | F40: =IF(F9="X",(D9-C9),"0") -> 1 | G40: =IF(G9="X",(D9-C9),"0") -> 0 | H40: =IF(H9="X",(D9-C9),"0") -> 0 | I40: =IF(I9="X",(D9-C9),"0") -> 0 | J40: =IF(J9="X",(D9-C9),"0") -> 1 | K40: =IF(K9="X",(D9-C9),"0") -> 0
E41: =IF(E10="X",(D10-C10),"0") -> 0 | F41: =IF(F10="X",(D10-C10),"0") -> 1 | G41: =IF(G10="X",(D10-C10),"0") -> 0 | H41: =IF(H10="X",(D10-C10),"0") -> 0 | I41: =IF(I10="X",(D10-C10),"0") -> 0 | J41: =IF(J10="X",(D10-C10),"0") -> 1 | K41: =IF(K10="X",(D10-C10),"0") -> 0
E42: =IF(E11="X",(D11-C11),"0") -> 0 | F42: =IF(F11="X",(D11-C11),"0") -> 1 | G42: =IF(G11="X",(D11-C11),"0") -> 0 | H42: =IF(H11="X",(D11-C11),"0") -> 0 | I42: =IF(I11="X",(D11-C11),"0") -> 0 | J42: =IF(J11="X",(D11-C11),"0") -> 1 | K42: =IF(K11="X",(D11-C11),"0") -> 0
E43: =IF(E12="X",(D12-C12),"0") -> 0 | F43: =IF(F12="X",(D12-C12),"0") -> 1 | G43: =IF(G12="X",(D12-C12),"0") -> 0 | H43: =IF(H12="X",(D12-C12),"0") -> 0 | I43: =IF(I12="X",(D12-C12),"0") -> 0 | J43: =IF(J12="X",(D12-C12),"0") -> 1 | K43: =IF(K12="X",(D12-C12),"0") -> 0
E44: =IF(E13="X",(D13-C13),"0") -> 0 | F44: =IF(F13="X",(D13-C13),"0") -> 1 | G44: =IF(G13="X",(D13-C13),"0") -> 0 | H44: =IF(H13="X",(D13-C13),"0") -> 0 | I44: =IF(I13="X",(D13-C13),"0") -> 0 | J44: =IF(J13="X",(D13-C13),"0") -> 1 | K44: =IF(K13="X",(D13-C13),"0") -> 0
E45: =IF(E14="X",(D14-C14),"0") -> 0 | F45: =IF(F14="X",(D14-C14),"0") -> 1 | G45: =IF(G14="X",(D14-C14),"0") -> 0 | H45: =IF(H14="X",(D14-C14),"0") -> 0 | I45: =IF(I14="X",(D14-C14),"0") -> 0 | J45: =IF(J14="X",(D14-C14),"0") -> 1 | K45: =IF(K14="X",(D14-C14),"0") -> 0
E46: =IF(E15="X",(D15-C15),"0") -> 0 | F46: =IF(F15="X",(D15-C15),"0") -> 1 | G46: =IF(G15="X",(D15-C15),"0") -> 0 | H46: =IF(H15="X",(D15-C15),"0") -> 0 | I46: =IF(I15="X",(D15-C15),"0") -> 0 | J46: =IF(J15="X",(D15-C15),"0") -> 1 | K46: =IF(K15="X",(D15-C15),"0") -> 0
E47: =IF(E16="X",(D16-C16),"0") -> 0 | F47: =IF(F16="X",(D16-C16),"0") -> 1 | G47: =IF(G16="X",(D16-C16),"0") -> 0 | H47: =IF(H16="X",(D16-C16),"0") -> 0 | I47: =IF(I16="X",(D16-C16),"0") -> 0 | J47: =IF(J16="X",(D16-C16),"0") -> 1 | K47: =IF(K16="X",(D16-C16),"0") -> 0
E48: =IF(E17="X",(D17-C17),"0") -> 0 | F48: =IF(F17="X",(D17-C17),"0") -> 1 | G48: =IF(G17="X",(D17-C17),"0") -> 0 | H48: =IF(H17="X",(D17-C17),"0") -> 0 | I48: =IF(I17="X",(D17-C17),"0") -> 0 | J48: =IF(J17="X",(D17-C17),"0") -> 1 | K48: =IF(K17="X",(D17-C17),"0") -> 0
E49: =IF(E18="X",(D18-C18),"0") -> 0 | F49: =IF(F18="X",(D18-C18),"0") -> 1 | G49: =IF(G18="X",(D18-C18),"0") -> 0 | H49: =IF(H18="X",(D18-C18),"0") -> 0 | I49: =IF(I18="X",(D18-C18),"0") -> 0 | J49: =IF(J18="X",(D18-C18),"0") -> 1 | K49: =IF(K18="X",(D18-C18),"0") -> 0
... E68: =IF(E37="X",(D37-C37),"0") -> 0 | F68: =IF(F37="X",(D37-C37),"0") -> 0 | G68: =IF(G37="X",(D37-C37),"0") -> 0 | H68: =IF(H37="X",(D37-C37),"0") -> 0 | I68: =IF(I37="X",(D37-C37),"0") -> 0 | J68: =IF(J37="X",(D37-C37),"0") -> 0 | K68: =IF(K37="X",(D37-C37),"0") -> 0
E69: =SUM(E38:E68) -> 0 | F69: =SUM(F38:F68) -> 26.59 | G69: =SUM(G38:G68) -> 2 | H69: =SUM(H38:H68) -> 0 | I69: =SUM(I38:I68) -> 0 | J69: =SUM(J38:J68) -> 28.59 | K69: =SUM(K38:K68) -> 0

Sheet 81
A1: PROGRAMA DE MANUTENÇÃORODOVIÁRIA | I1: DATA: | J1: ='67'!$J$1 -> 46204 | L1: TÉCNICO RESP. | N1: ='67'!$N$1 -> ENG. VINICIUS RODRIGUES FERREIRA DE OLIVEIRA
F2: RODOVIAS NÃO PAVIMENTADAS
A3: FICHA DE INSPEÇÃO: | B3: =Trechos!E81 -> RODOVIA TO-424 - TRECHO ENTR. TO-010 (BABAÇULÂNDIA) - ENTR. TO-222
A5: S.R.E. | B5: SENTIDO | C5: INÍCIO (KM) | D5: FIM (KM) | E5: CONDIÇÃO DA PLATAFORMA | I5: DRENAGEM SUPERFICIAL | L5: OBSERV.
E6: BOM | F6: REG. (ATÉ 10 IRR./KM) | G6: RUÍM (+ 10 IRR./KM) | H6: PÉSSIMA (ATOLEIRO/PTO. CRÍTICO) | I6: LIMPA | J6: OBSTRUÍDA | K6: AUSENTE
A7: 424ETO0020 | B7: D | C7: 0 | D7: 1 | F7: X | I7: X
C8: =D7 -> 1 | D8: 2 | F8: X | I8: X
C9: =D8 -> 2 | D9: 3 | F9: X | I9: X
C10: =D9 -> 3 | D10: 4 | F10: X | I10: X
C11: =D10 -> 4 | D11: 5 | F11: X | I11: X
C12: =D11 -> 5 | D12: 6 | F12: X | I12: X
C13: =D12 -> 6 | D13: 7 | F13: X | I13: X
C14: =D13 -> 7 | D14: 8 | F14: X | I14: X
C15: =D14 -> 8 | D15: 9 | F15: X | I15: X
C16: =D15 -> 9 | D16: 10 | F16: X | I16: X
C17: =D16 -> 10 | D17: 11 | F17: X | I17: X
C18: =D17 -> 11 | D18: 12 | F18: X | I18: X
C19: =D18 -> 12 | D19: 13 | F19: X | I19: X
... C21: =D20 -> 14 | D21: 14.02 | F21: X | I21: X
A22: 424ETO0015 | B22: D | C22: 0 | D22: 1 | F22: X | I22: X
C23: =D22 -> 1 | D23: 2 | F23: X | I23: X
C24: =D23 -> 2 | D24: 3 | F24: X | I24: X
C25: =D24 -> 3 | D25: 3.86 | F25: X | I25: X
A26: 424ETO0010 | B26: D | C26: 0 | D26: 1 | F26: X | I26: X
C27: =D26 -> 1 | D27: 2 | F27: X | I27: X
C28: =D27 -> 2 | D28: 3 | F28: X | I28: X
C29: =D28 -> 3 | D29: 4 | F29: X | I29: X
C30: =D29 -> 4 | D30: 5 | F30: X | I30: X
C31: =D30 -> 5 | D31: 6 | F31: X | I31: X
C32: =D31 -> 6 | D32: 7 | F32: X | I32: X
C33: =D32 -> 7 | D33: 8 | F33: X | I33: X
C34: =D33 -> 8 | D34: 9 | F34: X | I34: X
C35: =D34 -> 9 | D35: 10 | F35: X | I35: X
C36: =D35 -> 10 | D36: 11 | F36: X | I36: X
C37: =D36 -> 11 | D37: 12 | F37: X | I37: X
C38: =D37 -> 12 | D38: 13 | F38: X | I38: X
C39: =D38 -> 13 | D39: 13.61 | F39: X | I39: X
E44: =IF(E7="X",(D7-C7),"0") -> 0 | F44: =IF(F7="X",(D7-C7),"0") -> 1 | G44: =IF(G7="X",(D7-C7),"0") -> 0 | H44: =IF(H7="X",(D7-C7),"0") -> 0 | I44: =IF(I7="X",(D7-C7),"0") -> 1 | J44: =IF(J7="X",(D7-C7),"0") -> 0 | K44: =IF(K7="X",(D7-C7),"0") -> 0
E45: =IF(E8="X",(D8-C8),"0") -> 0 | F45: =IF(F8="X",(D8-C8),"0") -> 1 | G45: =IF(G8="X",(D8-C8),"0") -> 0 | H45: =IF(H8="X",(D8-C8),"0") -> 0 | I45: =IF(I8="X",(D8-C8),"0") -> 1 | J45: =IF(J8="X",(D8-C8),"0") -> 0 | K45: =IF(K8="X",(D8-C8),"0") -> 0
E46: =IF(E9="X",(D9-C9),"0") -> 0 | F46: =IF(F9="X",(D9-C9),"0") -> 1 | G46: =IF(G9="X",(D9-C9),"0") -> 0 | H46: =IF(H9="X",(D9-C9),"0") -> 0 | I46: =IF(I9="X",(D9-C9),"0") -> 1 | J46: =IF(J9="X",(D9-C9),"0") -> 0 | K46: =IF(K9="X",(D9-C9),"0") -> 0
...

Sheet 82
A1: PROGRAMA DE MANUTENÇÃORODOVIÁRIA | I1: DATA: | J1: ='67'!$J$1 -> 46204 | L1: TÉCNICO RESP. | N1: ='67'!$N$1 -> ENG. VINICIUS RODRIGUES FERREIRA DE OLIVEIRA
F2: RODOVIAS NÃO PAVIMENTADAS
A3: FICHA DE INSPEÇÃO: | B3: =Trechos!E83 -> RODOVIA TO-425 - TRECHO ENTR. TO-130 (BARRA DO OURO) - GOIATINS
A5: S.R.E. | B5: SENTIDO | C5: INÍCIO (KM) | D5: FIM (KM) | E5: CONDIÇÃO DA PLATAFORMA | I5: DRENAGEM SUPERFICIAL | L5: OBSERV.
E6: BOM | F6: REG. (ATÉ 10 IRR./KM) | G6: RUÍM (+ 10 IRR./KM) | H6: PÉSSIMA (ATOLEIRO/PTO. CRÍTICO) | I6: LIMPA | J6: OBSTRUÍDA | K6: AUSENTE
A7: 425ETO0010 | B7: C | C7: 0 | D7: 1 | F7: X | J7: X
C8: =D7 -> 1 | D8: 2 | F8: X | J8: X
C9: =D8 -> 2 | D9: 3 | F9: X | J9: X
C10: =D9 -> 3 | D10: 4 | F10: X | J10: X
C11: =D10 -> 4 | D11: 5 | F11: X | J11: X
C12: =D11 -> 5 | D12: 6 | F12: X | J12: X
C13: =D12 -> 6 | D13: 7 | F13: X | J13: X
C14: =D13 -> 7 | D14: 8 | F14: X | J14: X
C15: =D14 -> 8 | D15: 9 | F15: X | J15: X
C16: =D15 -> 9 | D16: 10 | F16: X | J16: X
C17: =D16 -> 10 | D17: 11 | F17: X | J17: X
C18: =D17 -> 11 | D18: 12 | F18: X | J18: X
C19: =D18 -> 12 | D19: 13 | F19: X | J19: X
... C54: =D53 -> 47 | D54: 47.36 | F54: X | J54: X
E57: =IF(E7="X",(D7-C7),"0") -> 0 | F57: =IF(F7="X",(D7-C7),"0") -> 1 | G57: =IF(G7="X",(D7-C7),"0") -> 0 | H57: =IF(H7="X",(D7-C7),"0") -> 0 | I57: =IF(I7="X",(D7-C7),"0") -> 0 | J57: =IF(J7="X",(D7-C7),"0") -> 1 | K57: =IF(K7="X",(D7-C7),"0") -> 0
E58: =IF(E8="X",(D8-C8),"0") -> 0 | F58: =IF(F8="X",(D8-C8),"0") -> 1 | G58: =IF(G8="X",(D8-C8),"0") -> 0 | H58: =IF(H8="X",(D8-C8),"0") -> 0 | I58: =IF(I8="X",(D8-C8),"0") -> 0 | J58: =IF(J8="X",(D8-C8),"0") -> 1 | K58: =IF(K8="X",(D8-C8),"0") -> 0
E59: =IF(E9="X",(D9-C9),"0") -> 0 | F59: =IF(F9="X",(D9-C9),"0") -> 1 | G59: =IF(G9="X",(D9-C9),"0") -> 0 | H59: =IF(H9="X",(D9-C9),"0") -> 0 | I59: =IF(I9="X",(D9-C9),"0") -> 0 | J59: =IF(J9="X",(D9-C9),"0") -> 1 | K59: =IF(K9="X",(D9-C9),"0") -> 0
E60: =IF(E10="X",(D10-C10),"0") -> 0 | F60: =IF(F10="X",(D10-C10),"0") -> 1 | G60: =IF(G10="X",(D10-C10),"0") -> 0 | H60: =IF(H10="X",(D10-C10),"0") -> 0 | I60: =IF(I10="X",(D10-C10),"0") -> 0 | J60: =IF(J10="X",(D10-C10),"0") -> 1 | K60: =IF(K10="X",(D10-C10),"0") -> 0
E61: =IF(E11="X",(D11-C11),"0") -> 0 | F61: =IF(F11="X",(D11-C11),"0") -> 1 | G61: =IF(G11="X",(D11-C11),"0") -> 0 | H61: =IF(H11="X",(D11-C11),"0") -> 0 | I61: =IF(I11="X",(D11-C11),"0") -> 0 | J61: =IF(J11="X",(D11-C11),"0") -> 1 | K61: =IF(K11="X",(D11-C11),"0") -> 0
E62: =IF(E12="X",(D12-C12),"0") -> 0 | F62: =IF(F12="X",(D12-C12),"0") -> 1 | G62: =IF(G12="X",(D12-C12),"0") -> 0 | H62: =IF(H12="X",(D12-C12),"0") -> 0 | I62: =IF(I12="X",(D12-C12),"0") -> 0 | J62: =IF(J12="X",(D12-C12),"0") -> 1 | K62: =IF(K12="X",(D12-C12),"0") -> 0
E63: =IF(E13="X",(D13-C13),"0") -> 0 | F63: =IF(F13="X",(D13-C13),"0") -> 1 | G63: =IF(G13="X",(D13-C13),"0") -> 0 | H63: =IF(H13="X",(D13-C13),"0") -> 0 | I63: =IF(I13="X",(D13-C13),"0") -> 0 | J63: =IF(J13="X",(D13-C13),"0") -> 1 | K63: =IF(K13="X",(D13-C13),"0") -> 0
E64: =IF(E14="X",(D14-C14),"0") -> 0 | F64: =IF(F14="X",(D14-C14),"0") -> 1 | G64: =IF(G14="X",(D14-C14),"0") -> 0 | H64: =IF(H14="X",(D14-C14),"0") -> 0 | I64: =IF(I14="X",(D14-C14),"0") -> 0 | J64: =IF(J14="X",(D14-C14),"0") -> 1 | K64: =IF(K14="X",(D14-C14),"0") -> 0
E65: =IF(E15="X",(D15-C15),"0") -> 0 | F65: =IF(F15="X",(D15-C15),"0") -> 1 | G65: =IF(G15="X",(D15-C15),"0") -> 0 | H65: =IF(H15="X",(D15-C15),"0") -> 0 | I65: =IF(I15="X",(D15-C15),"0") -> 0 | J65: =IF(J15="X",(D15-C15),"0") -> 1 | K65: =IF(K15="X",(D15-C15),"0") -> 0
E66: =IF(E16="X",(D16-C16),"0") -> 0 | F66: =IF(F16="X",(D16-C16),"0") -> 1 | G66: =IF(G16="X",(D16-C16),"0") -> 0 | H66: =IF(H16="X",(D16-C16),"0") -> 0 | I66: =IF(I16="X",(D16-C16),"0") -> 0 | J66: =IF(J16="X",(D16-C16),"0") -> 1 | K66: =IF(K16="X",(D16-C16),"0") -> 0
E67: =IF(E17="X",(D17-C17),"0") -> 0 | F67: =IF(F17="X",(D17-C17),"0") -> 1 | G67: =IF(G17="X",(D17-C17),"0") -> 0 | H67: =IF(H17="X",(D17-C17),"0") -> 0 | I67: =IF(I17="X",(D17-C17),"0") -> 0 | J67: =IF(J17="X",(D17-C17),"0") -> 1 | K67: =IF(K17="X",(D17-C17),"0") -> 0
E68: =IF(E18="X",(D18-C18),"0") -> 0 | F68: =IF(F18="X",(D18-C18),"0") -> 1 | G68: =IF(G18="X",(D18-C18),"0") -> 0 | H68: =IF(H18="X",(D18-C18),"0") -> 0 | I68: =IF(I18="X",(D18-C18),"0") -> 0 | J68: =IF(J18="X",(D18-C18),"0") -> 1 | K68: =IF(K18="X",(D18-C18),"0") -> 0
... E107: =IF(E57="X",(D57-C57),"0") -> 0 | F107: =IF(F57="X",(D57-C57),"0") -> 0 | G107: =IF(G57="X",(D57-C57),"0") -> 0 | H107: =IF(H57="X",(D57-C57),"0") -> 0 | I107: =IF(I57="X",(D57-C57),"0") -> 0 | J107: =IF(J57="X",(D57-C57),"0") -> 0 | K107: =IF(K57="X",(D57-C57),"0") -> 0
E108: =SUM(E57:E107) -> 0 | F108: =SUM(F57:F107) -> 47.36 | G108: =SUM(G57:G107) -> 0 | H108: =SUM(H57:H107) -> 0 | I108: =SUM(I57:I107) -> 0 | J108: =SUM(J57:J107) -> 47.36 | K108: =SUM(K57:K107) -> 0

Sheet 83
A1: PROGRAMA DE MANUTENÇÃORODOVIÁRIA | I1: DATA: | J1: ='67'!$J$1 -> 46204 | L1: TÉCNICO RESP. | N1: ='67'!$N$1 -> ENG. VINICIUS RODRIGUES FERREIRA DE OLIVEIRA
F2: RODOVIAS NÃO PAVIMENTADAS
A3: FICHA DE INSPEÇÃO: | B3: =Trechos!E84 -> RODOVIA TO-426 - TRECHO POVOADO CRAOLÂNDIA - ENTR. TO-226
A5: S.R.E. | B5: SENTIDO | C5: INÍCIO (KM) | D5: FIM (KM) | E5: CONDIÇÃO DA PLATAFORMA | I5: DRENAGEM SUPERFICIAL | L5: OBSERV.
E6: BOM | F6: REG. (ATÉ 10 IRR./KM) | G6: RUÍM (+ 10 IRR./KM) | H6: PÉSSIMA (ATOLEIRO/PTO. CRÍTICO) | I6: LIMPA | J6: OBSTRUÍDA | K6: AUSENTE
A7: 426ETO0010 | B7: C | C7: 0 | D7: 31.73 | F7: X | J7: X
E36: =IF(E7="X",(D7-C7),"0") -> 0 | F36: =IF(F7="X",(D7-C7),"0") -> 31.73 | G36: =IF(G7="X",(D7-C7),"0") -> 0 | H36: =IF(H7="X",(D7-C7),"0") -> 0 | I36: =IF(I7="X",(D7-C7),"0") -> 0 | J36: =IF(J7="X",(D7-C7),"0") -> 31.73 | K36: =IF(K7="X",(D7-C7),"0") -> 0
E37: =IF(E8="X",(D8-C8),"0") -> 0 | F37: =IF(F8="X",(D8-C8),"0") -> 0 | G37: =IF(G8="X",(D8-C8),"0") -> 0 | H37: =IF(H8="X",(D8-C8),"0") -> 0 | I37: =IF(I8="X",(D8-C8),"0") -> 0 | J37: =IF(J8="X",(D8-C8),"0") -> 0 | K37: =IF(K8="X",(D8-C8),"0") -> 0
E38: =IF(E9="X",(D9-C9),"0") -> 0 | F38: =IF(F9="X",(D9-C9),"0") -> 0 | G38: =IF(G9="X",(D9-C9),"0") -> 0 | H38: =IF(H9="X",(D9-C9),"0") -> 0 | I38: =IF(I9="X",(D9-C9),"0") -> 0 | J38: =IF(J9="X",(D9-C9),"0") -> 0 | K38: =IF(K9="X",(D9-C9),"0") -> 0
E39: =IF(E10="X",(D10-C10),"0") -> 0 | F39: =IF(F10="X",(D10-C10),"0") -> 0 | G39: =IF(G10="X",(D10-C10),"0") -> 0 | H39: =IF(H10="X",(D10-C10),"0") -> 0 | I39: =IF(I10="X",(D10-C10),"0") -> 0 | J39: =IF(J10="X",(D10-C10),"0") -> 0 | K39: =IF(K10="X",(D10-C10),"0") -> 0
E40: =IF(E11="X",(D11-C11),"0") -> 0 | F40: =IF(F11="X",(D11-C11),"0") -> 0 | G40: =IF(G11="X",(D11-C11),"0") -> 0 | H40: =IF(H11="X",(D11-C11),"0") -> 0 | I40: =IF(I11="X",(D11-C11),"0") -> 0 | J40: =IF(J11="X",(D11-C11),"0") -> 0 | K40: =IF(K11="X",(D11-C11),"0") -> 0
E41: =IF(E12="X",(D12-C12),"0") -> 0 | F41: =IF(F12="X",(D12-C12),"0") -> 0 | G41: =IF(G12="X",(D12-C12),"0") -> 0 | H41: =IF(H12="X",(D12-C12),"0") -> 0 | I41: =IF(I12="X",(D12-C12),"0") -> 0 | J41: =IF(J12="X",(D12-C12),"0") -> 0 | K41: =IF(K12="X",(D12-C12),"0") -> 0
E42: =IF(E13="X",(D13-C13),"0") -> 0 | F42: =IF(F13="X",(D13-C13),"0") -> 0 | G42: =IF(G13="X",(D13-C13),"0") -> 0 | H42: =IF(H13="X",(D13-C13),"0") -> 0 | I42: =IF(I13="X",(D13-C13),"0") -> 0 | J42: =IF(J13="X",(D13-C13),"0") -> 0 | K42: =IF(K13="X",(D13-C13),"0") -> 0
E43: =IF(E14="X",(D14-C14),"0") -> 0 | F43: =IF(F14="X",(D14-C14),"0") -> 0 | G43: =IF(G14="X",(D14-C14),"0") -> 0 | H43: =IF(H14="X",(D14-C14),"0") -> 0 | I43: =IF(I14="X",(D14-C14),"0") -> 0 | J43: =IF(J14="X",(D14-C14),"0") -> 0 | K43: =IF(K14="X",(D14-C14),"0") -> 0
E44: =IF(E15="X",(D15-C15),"0") -> 0 | F44: =IF(F15="X",(D15-C15),"0") -> 0 | G44: =IF(G15="X",(D15-C15),"0") -> 0 | H44: =IF(H15="X",(D15-C15),"0") -> 0 | I44: =IF(I15="X",(D15-C15),"0") -> 0 | J44: =IF(J15="X",(D15-C15),"0") -> 0 | K44: =IF(K15="X",(D15-C15),"0") -> 0
E45: =IF(E16="X",(D16-C16),"0") -> 0 | F45: =IF(F16="X",(D16-C16),"0") -> 0 | G45: =IF(G16="X",(D16-C16),"0") -> 0 | H45: =IF(H16="X",(D16-C16),"0") -> 0 | I45: =IF(I16="X",(D16-C16),"0") -> 0 | J45: =IF(J16="X",(D16-C16),"0") -> 0 | K45: =IF(K16="X",(D16-C16),"0") -> 0
E46: =IF(E17="X",(D17-C17),"0") -> 0 | F46: =IF(F17="X",(D17-C17),"0") -> 0 | G46: =IF(G17="X",(D17-C17),"0") -> 0 | H46: =IF(H17="X",(D17-C17),"0") -> 0 | I46: =IF(I17="X",(D17-C17),"0") -> 0 | J46: =IF(J17="X",(D17-C17),"0") -> 0 | K46: =IF(K17="X",(D17-C17),"0") -> 0
E47: =IF(E18="X",(D18-C18),"0") -> 0 | F47: =IF(F18="X",(D18-C18),"0") -> 0 | G47: =IF(G18="X",(D18-C18),"0") -> 0 | H47: =IF(H18="X",(D18-C18),"0") -> 0 | I47: =IF(I18="X",(D18-C18),"0") -> 0 | J47: =IF(J18="X",(D18-C18),"0") -> 0 | K47: =IF(K18="X",(D18-C18),"0") -> 0
... E61: =IF(E32="X",(D32-C32),"0") -> 0 | F61: =IF(F32="X",(D32-C32),"0") -> 0 | G61: =IF(G32="X",(D32-C32),"0") -> 0 | H61: =IF(H32="X",(D32-C32),"0") -> 0 | I61: =IF(I32="X",(D32-C32),"0") -> 0 | J61: =IF(J32="X",(D32-C32),"0") -> 0 | K61: =IF(K32="X",(D32-C32),"0") -> 0
E62: =SUM(E36:E61) -> 0 | F62: =SUM(F36:F61) -> 31.73 | G62: =SUM(G36:G61) -> 0 | H62: =SUM(H36:H61) -> 0 | I62: =SUM(I36:I61) -> 0 | J62: =SUM(J36:J61) -> 31.73 | K62: =SUM(K36:K61) -> 0

Sheet 84
A1: PROGRAMA DE MANUTENÇÃORODOVIÁRIA | I1: DATA: | J1: ='67'!$J$1 -> 46204 | L1: TÉCNICO RESP. | N1: ='67'!$N$1 -> ENG. VINICIUS RODRIGUES FERREIRA DE OLIVEIRA
F2: RODOVIAS NÃO PAVIMENTADAS
A3: FICHA DE INSPEÇÃO: | B3: =Trechos!E85 -> RODOVIA TO-428 - TRECHO POVOADO BANDEIRA - ENTR. TO-226
A5: S.R.E. | B5: SENTIDO | C5: INÍCIO (KM) | D5: FIM (KM) | E5: CONDIÇÃO DA PLATAFORMA | I5: DRENAGEM SUPERFICIAL | L5: OBSERV.
E6: BOM | F6: REG. (ATÉ 10 IRR./KM) | G6: RUÍM (+ 10 IRR./KM) | H6: PÉSSIMA (ATOLEIRO/PTO. CRÍTICO) | I6: LIMPA | J6: OBSTRUÍDA | K6: AUSENTE
A7: 428ETO0010 | B7: C | C7: 0 | D7: 28.0702 | F7: X | J7: X
A8: 428ETO0020 | B8: C | C8: 0 | D8: 13.451489 | F8: X | J8: X
E36: =IF(E7="X",(D7-C7),"0") -> 0 | F36: =IF(F7="X",(D7-C7),"0") -> 28.0702 | G36: =IF(G7="X",(D7-C7),"0") -> 0 | H36: =IF(H7="X",(D7-C7),"0") -> 0 | I36: =IF(I7="X",(D7-C7),"0") -> 0 | J36: =IF(J7="X",(D7-C7),"0") -> 28.0702 | K36: =IF(K7="X",(D7-C7),"0") -> 0
E37: =IF(E8="X",(D8-C8),"0") -> 0 | F37: =IF(F8="X",(D8-C8),"0") -> 13.451489 | G37: =IF(G8="X",(D8-C8),"0") -> 0 | H37: =IF(H8="X",(D8-C8),"0") -> 0 | I37: =IF(I8="X",(D8-C8),"0") -> 0 | J37: =IF(J8="X",(D8-C8),"0") -> 13.451489 | K37: =IF(K8="X",(D8-C8),"0") -> 0
E38: =IF(E9="X",(D9-C9),"0") -> 0 | F38: =IF(F9="X",(D9-C9),"0") -> 0 | G38: =IF(G9="X",(D9-C9),"0") -> 0 | H38: =IF(H9="X",(D9-C9),"0") -> 0 | I38: =IF(I9="X",(D9-C9),"0") -> 0 | J38: =IF(J9="X",(D9-C9),"0") -> 0 | K38: =IF(K9="X",(D9-C9),"0") -> 0
E39: =IF(E10="X",(D10-C10),"0") -> 0 | F39: =IF(F10="X",(D10-C10),"0") -> 0 | G39: =IF(G10="X",(D10-C10),"0") -> 0 | H39: =IF(H10="X",(D10-C10),"0") -> 0 | I39: =IF(I10="X",(D10-C10),"0") -> 0 | J39: =IF(J10="X",(D10-C10),"0") -> 0 | K39: =IF(K10="X",(D10-C10),"0") -> 0
E40: =IF(E11="X",(D11-C11),"0") -> 0 | F40: =IF(F11="X",(D11-C11),"0") -> 0 | G40: =IF(G11="X",(D11-C11),"0") -> 0 | H40: =IF(H11="X",(D11-C11),"0") -> 0 | I40: =IF(I11="X",(D11-C11),"0") -> 0 | J40: =IF(J11="X",(D11-C11),"0") -> 0 | K40: =IF(K11="X",(D11-C11),"0") -> 0
E41: =IF(E12="X",(D12-C12),"0") -> 0 | F41: =IF(F12="X",(D12-C12),"0") -> 0 | G41: =IF(G12="X",(D12-C12),"0") -> 0 | H41: =IF(H12="X",(D12-C12),"0") -> 0 | I41: =IF(I12="X",(D12-C12),"0") -> 0 | J41: =IF(J12="X",(D12-C12),"0") -> 0 | K41: =IF(K12="X",(D12-C12),"0") -> 0
E42: =IF(E13="X",(D13-C13),"0") -> 0 | F42: =IF(F13="X",(D13-C13),"0") -> 0 | G42: =IF(G13="X",(D13-C13),"0") -> 0 | H42: =IF(H13="X",(D13-C13),"0") -> 0 | I42: =IF(I13="X",(D13-C13),"0") -> 0 | J42: =IF(J13="X",(D13-C13),"0") -> 0 | K42: =IF(K13="X",(D13-C13),"0") -> 0
E43: =IF(E14="X",(D14-C14),"0") -> 0 | F43: =IF(F14="X",(D14-C14),"0") -> 0 | G43: =IF(G14="X",(D14-C14),"0") -> 0 | H43: =IF(H14="X",(D14-C14),"0") -> 0 | I43: =IF(I14="X",(D14-C14),"0") -> 0 | J43: =IF(J14="X",(D14-C14),"0") -> 0 | K43: =IF(K14="X",(D14-C14),"0") -> 0
E44: =IF(E15="X",(D15-C15),"0") -> 0 | F44: =IF(F15="X",(D15-C15),"0") -> 0 | G44: =IF(G15="X",(D15-C15),"0") -> 0 | H44: =IF(H15="X",(D15-C15),"0") -> 0 | I44: =IF(I15="X",(D15-C15),"0") -> 0 | J44: =IF(J15="X",(D15-C15),"0") -> 0 | K44: =IF(K15="X",(D15-C15),"0") -> 0
E45: =IF(E16="X",(D16-C16),"0") -> 0 | F45: =IF(F16="X",(D16-C16),"0") -> 0 | G45: =IF(G16="X",(D16-C16),"0") -> 0 | H45: =IF(H16="X",(D16-C16),"0") -> 0 | I45: =IF(I16="X",(D16-C16),"0") -> 0 | J45: =IF(J16="X",(D16-C16),"0") -> 0 | K45: =IF(K16="X",(D16-C16),"0") -> 0
E46: =IF(E17="X",(D17-C17),"0") -> 0 | F46: =IF(F17="X",(D17-C17),"0") -> 0 | G46: =IF(G17="X",(D17-C17),"0") -> 0 | H46: =IF(H17="X",(D17-C17),"0") -> 0 | I46: =IF(I17="X",(D17-C17),"0") -> 0 | J46: =IF(J17="X",(D17-C17),"0") -> 0 | K46: =IF(K17="X",(D17-C17),"0") -> 0
E47: =IF(E18="X",(D18-C18),"0") -> 0 | F47: =IF(F18="X",(D18-C18),"0") -> 0 | G47: =IF(G18="X",(D18-C18),"0") -> 0 | H47: =IF(H18="X",(D18-C18),"0") -> 0 | I47: =IF(I18="X",(D18-C18),"0") -> 0 | J47: =IF(J18="X",(D18-C18),"0") -> 0 | K47: =IF(K18="X",(D18-C18),"0") -> 0
... E61: =IF(E32="X",(D32-C32),"0") -> 0 | F61: =IF(F32="X",(D32-C32),"0") -> 0 | G61: =IF(G32="X",(D32-C32),"0") -> 0 | H61: =IF(H32="X",(D32-C32),"0") -> 0 | I61: =IF(I32="X",(D32-C32),"0") -> 0 | J61: =IF(J32="X",(D32-C32),"0") -> 0 | K61: =IF(K32="X",(D32-C32),"0") -> 0
E62: =SUM(E36:E61) -> 0 | F62: =SUM(F36:F61) -> 41.521689 | G62: =SUM(G36:G61) -> 0 | H62: =SUM(H36:H61) -> 0 | I62: =SUM(I36:I61) -> 0 | J62: =SUM(J36:J61) -> 41.521689 | K62: =SUM(K36:K61) -> 0

Sheet TT
B1: RESUMO
B2: Nº DO TRECHO | C2: TRECHO | D2: CONDIÇÃO DA PLATAFORMA | H2: DRENAGEM SUPERFICIAL
D3: BOM | E3: REG. (ATÉ 10 IRR./KM) | F3: RUÍM (+ 10 IRR./KM) | G3: PÉSSIMA (ATOLEIRO/PTO. CRÍTICO) | H3: LIMPA | I3: OBSTRUÍDA | J3: AUSENTE
B4: 67 | C4: RODOVIA TO-010 - TRECHO ENTR. BR-010 (ITACAJÁ) - PALMEIRANTE | D4: ='67'!E62 -> 0 | E4: ='67'!F62 -> 77.592133 | F4: ='67'!G62 -> 0 | G4: ='67'!H62 -> 0 | H4: ='67'!I62 -> 0 | I4: ='67'!J62 -> 77.592133 | J4: ='67'!K62 -> 0
B5: 69 | C5: RODOVIA TO-010 - TRECHO ENTR. TO-222 (POVOADO FARTURÃO) - BABAÇULÂNDIA | D5: ='69'!E87 -> 38.43 | E5: ='69'!F87 -> 0 | F5: ='69'!G87 -> 0 | G5: ='69'!H87 -> 0 | H5: ='69'!I87 -> 33.59 | I5: ='69'!J87 -> 0 | J5: ='69'!K87 -> 4.84
B6: 71 | C6: RODOVIA TO-020 - TRECHO RECURSOLÂNDIA - CAMPOS LINDOS | D6: ='71'!E84 -> 0 | E6: ='71'!F84 -> 25 | F6: ='71'!G84 -> 8 | G6: ='71'!H84 -> 0 | H6: ='71'!I84 -> 0 | I6: ='71'!J84 -> 33 | J6: ='71'!K84 -> 0
B7: 72 | C7: RODOVIA TO-130 - TRECHO ENTR. TO-424 - TRECHO ENTR. TO-222 | D7: ='72'!E53 -> 0 | E7: ='72'!F53 -> 19.33 | F7: ='72'!G53 -> 0 | G7: ='72'!H53 -> 0 | H7: ='72'!I53 -> 0 | I7: ='72'!J53 -> 19.33 | J7: ='72'!K53 -> 0
B8: 75 | C8: RODOVIA TO-226 - TRECHO NOVA OLINDA - ENTR. TO-010 | D8: ='75'!E89 -> 0 | E8: ='75'!F89 -> 54.39 | F8: ='75'!G89 -> 0 | G8: ='75'!H89 -> 0 | H8: ='75'!I89 -> 0 | I8: ='75'!J89 -> 54.39 | J8: ='75'!K89 -> 0
B9: 76 | C9: RODOVIA TO-226 - TRECHO ENTR. TO-010 (POVOADO CAMPOS) - ENTR. BR-010 | D9: ='76'!E89 -> 0 | E9: ='76'!F89 -> 0 | F9: ='76'!G89 -> 0 | G9: ='76'!H89 -> 0 | H9: ='76'!I89 -> 0 | I9: ='76'!J89 -> 0 | J9: ='76'!K89 -> 0
B10: 79 | C10: RODOVIA TO-423 - TRECHO ARAGUAÍNA - ENTR. TO-424 | D10: ='79'!E69 -> 0 | E10: ='79'!F69 -> 26.59 | F10: ='79'!G69 -> 2 | G10: ='79'!H69 -> 0 | H10: ='79'!I69 -> 0 | I10: ='79'!J69 -> 28.59 | J10: ='79'!K69 -> 0
B11: 81 | C11: RODOVIA TO-424 - TRECHO ENTR. TO-010 (BABAÇULÂNDIA) - ENTR. TO-222 | D11: ='76'!E89 -> 0 | E11: ='76'!F89 -> 0 | F11: ='76'!G89 -> 0 | G11: ='76'!H89 -> 0 | H11: ='76'!I89 -> 0 | I11: ='76'!J89 -> 0 | J11: ='76'!K89 -> 0
B12: 82 | C12: RODOVIA TO-425 - TRECHO ENTR. TO-130 (BARRA DO OURO) - GOIATINS | D12: ='82'!E108 -> 0 | E12: ='82'!F108 -> 47.36 | F12: ='82'!G108 -> 0 | G12: ='82'!H108 -> 0 | H12: ='82'!I108 -> 0 | I12: ='82'!J108 -> 47.36 | J12: ='82'!K108 -> 0
B13: 83 | C13: RODOVIA TO-426 - TRECHO POVOADO CRAOLÂNDIA - ENTR. TO-226 | D13: ='83'!E62 -> 0 | E13: ='83'!F62 -> 31.73 | F13: ='83'!G62 -> 0 | G13: ='83'!H62 -> 0 | H13: ='83'!I62 -> 0 | I13: ='83'!J62 -> 31.73 | J13: ='83'!K62 -> 0
B14: 84 | C14: RODOVIA TO-428 - TRECHO POVOADO BANDEIRA - ENTR. TO-226 | D14: ='84'!E62 -> 0 | E14: ='84'!F62 -> 41.521689 | F14: ='84'!G62 -> 0 | G14: ='84'!H62 -> 0 | H14: ='84'!I62 -> 0 | I14: ='84'!J62 -> 41.521689 | J14: ='84'!K62 -> 0
B16: PERCORRIDO NO MÊS: | D16: =SUM(D4:D14) -> 38.43 | E16: =SUM(E4:E14) -> 323.51382 | F16: =SUM(F4:F14) -> 10 | G16: =SUM(G4:G14) -> 0 | H16: =SUM(H4:H14) -> 33.59 | I16: =SUM(I4:I14) -> 333.51382 | J16: =SUM(J4:J14) -> 4.84
B17: TOTAL: | G17: =SUM(D16:G16) -> 371.94382
B18: % DA EXTENSÃO DA MALHA: | G18: =G17/Trechos!H275 -> 0.67973483
