Workbook

Sheet Trechos
A1: RELAÇÃO DOS TRECHOS DAS REGIÕES DE MANUTENÇÃO
A2: LOTE | B2: CIDADE SEDE | C2: NÚMERO TRECHO | D2: TRECHO | E2: S.R.E | F2: SUBTRECHOS | G2: EXT. (KM) | H2: TIPO | I2: 45839 | J2: 45870 | K2: 45901 | L2: 45931 | M2: 45962 | N2: 45992
A3: 3 | B3: ARAGUAÍNA II | C3: 67 | D3: RODOVIA TO-010 - TRECHO ENTR. BR-010 (ITACAJÁ) - PALMEIRANTE | E3: 010ETO0250 | F3: ENTR. BR-010 - TRECHO ENTR. TO-226 (POV. CAMPOS) | G3: 58.16433 | H3: LEN
A4: 3 | B4: ARAGUAÍNA II | C4: 67 | D4: RODOVIA TO-010 - TRECHO ENTR. BR-010 (ITACAJÁ) - PALMEIRANTE | E4: 010ETO0290 | F4: ENTR. TO-226 (CAMPOS) - RIO TOCANTINS ( BALSA PALMEIRANTE) | G4: 19.427802 | H4: LEN
A5: 3 | B5: ARAGUAÍNA II | C5: 68 | D5: RODOVIA TO-010 - TRECHO PALMEIRANTE - ENTR. TO-222 (POVOADO BIELÂNDIA) | E5: 010ETO0320 | F5: PALMERANTE *TRECHO URBANO* - ENTR. TO-335 | G5: 10.999804 | H5: PPS | I5: X
A6: 3 | B6: ARAGUAÍNA II | C6: 68 | D6: RODOVIA TO-010 - TRECHO PALMEIRANTE - ENTR. TO-222 (POVOADO BIELÂNDIA) | E6: 010ETO0330 | F6: ENTR.TO-335 - TRECHO ENTR.TO-226 | G6: 9.147414 | H6: PPS | I6: X
A7: 3 | B7: ARAGUAÍNA II | C7: 68 | D7: RODOVIA TO-010 - TRECHO PALMEIRANTE - ENTR. TO-222 (POVOADO BIELÂNDIA) | E7: 010ETO0340 | F7: ENTR. TO-226 - TRECHO POV. CICILÃNDIA | G7: 11.531266 | H7: PPS | I7: X
A8: 3 | B8: ARAGUAÍNA II | C8: 68 | D8: RODOVIA TO-010 - TRECHO PALMEIRANTE - ENTR. TO-222 (POVOADO BIELÂNDIA) | E8: 010ETO0350 | F8: POV. CICILÃNDIA - ENTR. TO-130 | G8: 25.891159 | H8: PPS | I8: X
A9: 3 | B9: ARAGUAÍNA II | C9: 68 | D9: RODOVIA TO-010 - TRECHO PALMEIRANTE - ENTR. TO-222 (POVOADO BIELÂNDIA) | E9: 010ETO0360 | F9: ENTR. TO-130 - TRECHO BIELÂNDIA | G9: 14.862138 | H9: PPS | I9: X | J9: X
A10: 3 | B10: ARAGUAÍNA II | C10: 69 | D10: RODOVIA TO-010 - TRECHO ENTR. TO-222 (POVOADO FARTURÃO) - BABAÇULÂNDIA | E10: 010ETO0380 | F10: POV. FARTURAO - ENTR. TO-424 | G10: 33.591201 | H10: LEN
A11: 3 | B11: ARAGUAÍNA II | C11: 69 | D11: RODOVIA TO-010 - TRECHO ENTR. TO-222 (POVOADO FARTURÃO) - BABAÇULÂNDIA | E11: 010ETO0400 | F11: ENTR. TO-424 - TRECHO BABAÇULÂNDIA *TRECHO URBANO* | G11: 4.8384683 | H11: LEN
A12: 3 | B12: ARAGUAÍNA II | C12: 70 | D12: RODOVIA TO-010 - TRECHO BABAÇULÂNDIA - WANDERLÂNDIA | E12: 010ETO0420 | F12: BABAÇULÂNDIA *TRECHO URBANO* - WANDERLÂNDIA *TRECHO URBANO* | G12: 54.5733 | H12: PPS | I12: X
A13: 3 | B13: ARAGUAÍNA II | C13: 71 | D13: RODOVIA TO-020 - TRECHO RECURSOLÂNDIA - CAMPOS LINDOS | E13: 020ETO0200 | F13: RECURSOLÂNDIA *TRECHO URBANO* - FIM PAVIMENTAÇÃO | G13: 2.898153 | H13: PPS
A14: 3 | B14: ARAGUAÍNA II | C14: 71 | D14: RODOVIA TO-020 - TRECHO RECURSOLÂNDIA - CAMPOS LINDOS | E14: 020ETO0210 | F14: FIM PAVIMENTAÇÃO - INICIO PAVIMENTACAO (CAMPOS LINDOS) | G14: 148.40783 | H14: EOP
A15: 3 | B15: ARAGUAÍNA II | C15: 71 | D15: RODOVIA TO-020 - TRECHO RECURSOLÂNDIA - CAMPOS LINDOS | E15: 020ETO0215 | F15: INICIO PAVIMENTACAO (CAMPOS LINDOS) - ENTR. TO-226 | G15: 2.708768 | H15: PPS
A16: 3 | B16: ARAGUAÍNA II | C16: 72 | D16: RODOVIA TO-130 - TRECHO ENTR. TO-424 - TRECHO ENTR. TO-222 | E16: 130ETO0010 | F16: ENTR. TO-424 - TRECHO ENTR. TO-222 (A) | G16: 19.326516 | H16: LEN
A17: 3 | B17: ARAGUAÍNA II | C17: 73 | D17: RODOVIA TO-130 - TRECHO ENTR. TO-010 - TRECHO BARRA DO OURO - ENTR. BR-010 (POVOADO MORRO GRANDE) | E17: 130ETO0040 | F17: ENTR. TO-010 - TRECHO BARRA DO OURO | G17: 25.199964 | H17: PPS | I17: X
A18: 3 | B18: ARAGUAÍNA II | C18: 73 | D18: RODOVIA TO-130 - TRECHO ENTR. TO-010 - TRECHO BARRA DO OURO - ENTR. BR-010 (POVOADO MORRO GRANDE) | E18: 130ETO0060 | F18: BARRA DO OURO - ENTR. TO-425 | G18: 3.7520251 | H18: PPS | I18: X
A19: 3 | B19: ARAGUAÍNA II | C19: 73 | D19: RODOVIA TO-130 - TRECHO ENTR. TO-010 - TRECHO BARRA DO OURO - ENTR. BR-010 (POVOADO MORRO GRANDE) | E19: 130ETO0070 | F19: ENTR. TO-425 - TRECHO MORRO GRANDE *TRECHO URBANO* | G19: 20.011595 | H19: PPS | I19: X
A20: 3 | B20: ARAGUAÍNA II | C20: 74 | D20: RODOVIA TO-222 - TRECHO ARAGUAÍNA - FILADÉLFIA | E20: 222ETO0010 | F20: FILADÉLFIA *TRECHO URBANO* - ENTR. TO-424 | G20: 7.6612658 | H20: PPS | J20: X
A21: 3 | B21: ARAGUAÍNA II | C21: 74 | D21: RODOVIA TO-222 - TRECHO ARAGUAÍNA - FILADÉLFIA | E21: 222ETO0020 | F21: ENTR. TO-424 - TRECHO ENTR. TO-130 | G21: 21.662136 | H21: PPS | J21: X
A22: 3 | B22: ARAGUAÍNA II | C22: 74 | D22: RODOVIA TO-222 - TRECHO ARAGUAÍNA - FILADÉLFIA | E22: 222ETO0030 | F22: ENTR. TO-130 (A) - ENTR. TO-130 (B) - TO-010 POV. BIELANDIA | G22: 20.248567 | H22: PPS
A23: 3 | B23: ARAGUAÍNA II | C23: 74 | D23: RODOVIA TO-222 - TRECHO ARAGUAÍNA - FILADÉLFIA | E23: 010ETO0370 | F23: ENTR. TO-222(BIELÂNDIA) - POV. FARTURÃO | G23: 26.227299 | H23: PPS | I23: X | J23: X
A24: 3 | B24: ARAGUAÍNA II | C24: 74 | D24: RODOVIA TO-222 - TRECHO ARAGUAÍNA - FILADÉLFIA | E24: 222ETO0060 | F24: FARTURÃO - ENTR. TO-424 | G24: 8.3712251 | H24: PPS | I24: X
A25: 3 | B25: ARAGUAÍNA II | C25: 74 | D25: RODOVIA TO-222 - TRECHO ARAGUAÍNA - FILADÉLFIA | E25: 222ETO0070 | F25: ENTR. TO-424 - TRECHO ARAGUAINA *TRECHO URBANO* | G25: 16.874871 | H25: PPS | I25: X
A26: 3 | B26: ARAGUAÍNA II | C26: 75 | D26: RODOVIA TO-226 - TRECHO NOVA OLINDA - ENTR. TO-010 | E26: 226ETO0190 | F26: ENTR.TO-010 - TRECHO POV. ALTO BONITO | G26: 36.768231 | H26: LEN
A27: 3 | B27: ARAGUAÍNA II | C27: 75 | D27: RODOVIA TO-226 - TRECHO NOVA OLINDA - ENTR. TO-010 | E27: 226ETO0200 | F27: POV. ALTO BONITO - NOVA OLINDA *TRECHO URBANO* | G27: 17.621405 | H27: LEN
A28: 3 | B28: ARAGUAÍNA II | C28: 75 | D28: RODOVIA TO-226 - TRECHO NOVA OLINDA - ENTR. TO-010 | E28: 226ETO0201 | F28: NOVA OLINDA *TRECHO URBANO* | G28: 2.154377 | H28: PSU | I28: X
A29: 3 | B29: ARAGUAÍNA II | C29: 76 | D29: RODOVIA TO-226 - TRECHO ENTR. TO-010 (POVOADO CAMPOS) - ENTR. BR-010 | E29: 226ETO0120 | F29: ENTR. BR-010-TO-130 - TRECHO BARRO VERMELHO | G29: 14.646522 | H29: LEN
A30: 3 | B30: ARAGUAÍNA II | C30: 76 | D30: RODOVIA TO-226 - TRECHO ENTR. TO-010 (POVOADO CAMPOS) - ENTR. BR-010 | E30: 226ETO0130 | F30: BARRO VERMELHO - ENTR. TO-010 (CAMPOS) | G30: 13.697356 | H30: LEN
A31: 3 | B31: ARAGUAÍNA II | C31: 77 | D31: RODOVIA TO-226 - TRECHO GOIATINS - CAMPOS LINDOS - DIV TO-MA | E31: 226ETO0010 | F31: DIV TO-MA - ENTR. TO-020 (CAMPOS LINDOS) | G31: 1.6907709 | H31: PPS
A32: 3 | B32: ARAGUAÍNA II | C32: 77 | D32: RODOVIA TO-226 - TRECHO GOIATINS - CAMPOS LINDOS - DIV TO-MA | E32: 226ETO0020 | F32: ENTR. TO-020 (CAMPOS LINDOS) - ENTR. TO-428 | G32: 10.2995 | H32: PPS | J32: X
A33: 3 | B33: ARAGUAÍNA II | C33: 77 | D33: RODOVIA TO-226 - TRECHO GOIATINS - CAMPOS LINDOS - DIV TO-MA | E33: 226ETO0030 | F33: ENTR. TO-428 - TRECHO BARRA DA ESTIVA | G33: 37.294819 | H33: PPS | J33: X
A34: 3 | B34: ARAGUAÍNA II | C34: 77 | D34: RODOVIA TO-226 - TRECHO GOIATINS - CAMPOS LINDOS - DIV TO-MA | E34: 226ETO0040 | F34: BARRA DA ESTIVA - ENTR. TO-426 (CRAOLÂNDIA) | G34: 17.638641 | H34: PPS | J34: X
A35: 3 | B35: ARAGUAÍNA II | C35: 77 | D35: RODOVIA TO-226 - TRECHO GOIATINS - CAMPOS LINDOS - DIV TO-MA | E35: 226ETO0050 | F35: ENTR. TO-426 (CRAOLÂNDIA) - GOIATINS *TRECHO URBANO* | G35: 24.572677 | H35: PPS | J35: X
A36: 3 | B36: ARAGUAÍNA II | C36: 77 | D36: RODOVIA TO-226 - TRECHO GOIATINS - CAMPOS LINDOS - DIV TO-MA | E36: 226ETO0051 | F36: GOIATINS *TRECHO URBANO* | G36: 0.10420991 | H36: PSU
A37: 3 | B37: ARAGUAÍNA II | C37: 77 | D37: RODOVIA TO-226 - TRECHO GOIATINS - CAMPOS LINDOS - DIV TO-MA | E37: 226ETO0052 | F37: GOIATINS *TRECHO URBANO* | G37: 0.44754673 | H37: PSU
A38: 3 | B38: ARAGUAÍNA II | C38: 78 | D38: RODOVIA TO-422 - TRECHO ENTR. BR-153 - TRECHO DISTRITO AGROINDUSTRIAL DE ARAGUAÍNA | E38: 422ETO0010 | F38: ENTR. BR-153 - TRECHO ZONA DE PROCESSAMENTO DE EXPORTAÇÃO | G38: 7.7776106 | H38: PPS | I38: X
A39: 3 | B39: ARAGUAÍNA II | C39: 79 | D39: RODOVIA TO-423 - TRECHO ARAGUAÍNA - ENTR. TO-424 | E39: 423ETO0020 | F39: ARAGUAINA *TRECHO URBANO* - ENTR. TO-424 | G39: 28.588959 | H39: LEN
A40: 3 | B40: ARAGUAÍNA II | C40: 80 | D40: RODOVIA TO-424 - TRECHO ENTR. TO-222 (PLAT. MULTI-MODAL) - BABAÇULÂNDIA | E40: 424ETO0050 | F40: ENTR. TO-010 (BABAÇULÂNDIA *TRECHO URBANO*) - VILA CORRENTE | G40: 13.989538 | H40: PPS | I40: X
...

Sheet 68
A1: PROGRAMA DE MANUTENÇÃORODOVIÁRIA
D2: RODOVIAS PAVIMENTADAS | I2: DATA: | J2: 46204 | N2: TÉCNICO RESP. | O2: ENG. VINÍCIUS RODRIGUES FERREIRA DE OLIVEIRA
A3: FICHA DE INSPEÇÃO: | B3: =TT!C4 -> RODOVIA TO-010 - TRECHO PALMEIRANTE - ENTR. TO-222 (POVOADO BIELÂNDIA)
A5: S.R.E. | B5: SENTIDO | C5: INÍCIO (KM) | D5: FIM (KM) | E5: CONDIÇÃO DO PAVIMENTO | J5: VEGETAÇÃO | L5: ELEM. DE DRENAGEM | O5: SIN. HOR. | R5: SIN. VERTICAL | U5: OBSERV.
E6: BOM | F6: REM. I. | G6: REM. L | H6: BUR. I | I6: BUR. L | J6: ADEQ. | K6: INADED. | L6: LIMPOS | M6: SUJOS | N6: DAN. | O6: BOM | P6: REG. | Q6: INEXIST. | R6: BOM | S6: POUCAS | T6: INEXIST.
A7: 010ETO0360 | B7: C | C7: 0 | D7: 1 | E7: X | K7: X | M7: X | O7: X | S7: X | U7: 14,86 km
C8: =D7 -> 1 | D8: 2 | E8: X | K8: X | M8: X | O8: X | S8: X
C9: =D8 -> 2 | D9: 3 | E9: X | K9: X | M9: X | O9: X | S9: X
C10: =D9 -> 3 | D10: 4 | E10: X | K10: X | M10: X | O10: X | S10: X
C11: =D10 -> 4 | D11: 5 | E11: X | K11: X | M11: X | O11: X | S11: X
C12: =D11 -> 5 | D12: 6 | E12: X | K12: X | M12: X | O12: X | S12: X
C13: =D12 -> 6 | D13: 7 | E13: X | K13: X | M13: X | O13: X | S13: X
C14: =D13 -> 7 | D14: 8 | E14: X | K14: X | M14: X | O14: X | S14: X
C15: =D14 -> 8 | D15: 9 | E15: X | K15: X | M15: X | O15: X | S15: X
C16: =D15 -> 9 | D16: 10 | E16: X | K16: X | M16: X | O16: X | S16: X
C17: =D16 -> 10 | D17: 11 | E17: X | K17: X | M17: X | O17: X | S17: X
C18: =D17 -> 11 | D18: 12 | E18: X | K18: X | M18: X | O18: X | S18: X
C19: =D18 -> 12 | D19: 13 | E19: X | K19: X | M19: X | O19: X | S19: X
... C21: =D20 -> 14 | D21: 14.86 | E21: X | K21: X | M21: X | O21: X | S21: X
A23: 010ETO0320 | C23: 0 | D23: 10.999804 | E23: X | K23: X | M23: X | O23: X | S23: X
A24: 010ETO0330 | C24: 0 | D24: 9.147414 | H24: X | K24: X | M24: X | O24: X | S24: X
A26: 010ETO0340 | C26: 0 | D26: 11.531266 | E26: X | K26: X | M26: X | O26: X | S26: X
A30: 010ETO0350 | C30: 0 | D30: 25.891159 | E30: X | K30: X | M30: X | O30: X | S30: X
A36: LEGENDA | B36: CONDIÇÃO DO PAVIMENTO
A37: REM. I | B37: REMENDOS ISOLADOS | E37: ATÉ 10 REMENDOS/KM | I37: BUR. I | J37: BURACOS ISOLADOS | M37: ATÉ 5 BURACOS/KM
A38: REM. L | B38: REMENDOS AO LONGO | E38: MAIS DE 10 REMENDOS/KM | I38: BUR. L | J38: BURACOS AO LONGO | M38: MAIS DE 5 BURACOS/KM
E43: =IF(E7="X",(D7-C7),"0") -> 1 | F43: =IF(F7="X",(D7-C7),"0") -> 0 | G43: =IF(G7="X",(D7-C7),"0") -> 0 | H43: =IF(H7="X",(D7-C7),"0") -> 0 | I43: =IF(I7="X",(D7-C7),"0") -> 0 | J43: =IF(J7="X",(D7-C7),"0") -> 0 | K43: =IF(K7="X",(D7-C7),"0") -> 1 | L43: =IF(L7="X",(D7-C7),"0") -> 0 | M43: =IF(M7="X",(D7-C7),"0") -> 1 | N43: =IF(N7="X",(D7-C7),"0") -> 0 | O43: =IF(O7="X",(D7-C7),"0") -> 1 | P43: =IF(P7="X",(D7-C7),"0") -> 0 | Q43: =IF(Q7="X",(D7-C7),"0") -> 0 | R43: =IF(R7="X",(D7-C7),"0") -> 0 | S43: =IF(S7="X",(D7-C7),"0") -> 1 | T43: =IF(T7="X",(D7-C7),"0") -> 0
E44: =IF(E8="X",(D8-C8),"0") -> 1 | F44: =IF(F8="X",(D8-C8),"0") -> 0 | G44: =IF(G8="X",(D8-C8),"0") -> 0 | H44: =IF(H8="X",(D8-C8),"0") -> 0 | I44: =IF(I8="X",(D8-C8),"0") -> 0 | J44: =IF(J8="X",(D8-C8),"0") -> 0 | K44: =IF(K8="X",(D8-C8),"0") -> 1 | L44: =IF(L8="X",(D8-C8),"0") -> 0 | M44: =IF(M8="X",(D8-C8),"0") -> 1 | N44: =IF(N8="X",(D8-C8),"0") -> 0 | O44: =IF(O8="X",(D8-C8),"0") -> 1 | P44: =IF(P8="X",(D8-C8),"0") -> 0 | Q44: =IF(Q8="X",(D8-C8),"0") -> 0 | R44: =IF(R8="X",(D8-C8),"0") -> 0 | S44: =IF(S8="X",(D8-C8),"0") -> 1 | T44: =IF(T8="X",(D8-C8),"0") -> 0
E45: =IF(E9="X",(D9-C9),"0") -> 1 | F45: =IF(F9="X",(D9-C9),"0") -> 0 | G45: =IF(G9="X",(D9-C9),"0") -> 0 | H45: =IF(H9="X",(D9-C9),"0") -> 0 | I45: =IF(I9="X",(D9-C9),"0") -> 0 | J45: =IF(J9="X",(D9-C9),"0") -> 0 | K45: =IF(K9="X",(D9-C9),"0") -> 1 | L45: =IF(L9="X",(D9-C9),"0") -> 0 | M45: =IF(M9="X",(D9-C9),"0") -> 1 | N45: =IF(N9="X",(D9-C9),"0") -> 0 | O45: =IF(O9="X",(D9-C9),"0") -> 1 | P45: =IF(P9="X",(D9-C9),"0") -> 0 | Q45: =IF(Q9="X",(D9-C9),"0") -> 0 | R45: =IF(R9="X",(D9-C9),"0") -> 0 | S45: =IF(S9="X",(D9-C9),"0") -> 1 | T45: =IF(T9="X",(D9-C9),"0") -> 0
E46: =IF(E10="X",(D10-C10),"0") -> 1 | F46: =IF(F10="X",(D10-C10),"0") -> 0 | G46: =IF(G10="X",(D10-C10),"0") -> 0 | H46: =IF(H10="X",(D10-C10),"0") -> 0 | I46: =IF(I10="X",(D10-C10),"0") -> 0 | J46: =IF(J10="X",(D10-C10),"0") -> 0 | K46: =IF(K10="X",(D10-C10),"0") -> 1 | L46: =IF(L10="X",(D10-C10),"0") -> 0 | M46: =IF(M10="X",(D10-C10),"0") -> 1 | N46: =IF(N10="X",(D10-C10),"0") -> 0 | O46: =IF(O10="X",(D10-C10),"0") -> 1 | P46: =IF(P10="X",(D10-C10),"0") -> 0 | Q46: =IF(Q10="X",(D10-C10),"0") -> 0 | R46: =IF(R10="X",(D10-C10),"0") -> 0 | S46: =IF(S10="X",(D10-C10),"0") -> 1 | T46: =IF(T10="X",(D10-C10),"0") -> 0
E47: =IF(E11="X",(D11-C11),"0") -> 1 | F47: =IF(F11="X",(D11-C11),"0") -> 0 | G47: =IF(G11="X",(D11-C11),"0") -> 0 | H47: =IF(H11="X",(D11-C11),"0") -> 0 | I47: =IF(I11="X",(D11-C11),"0") -> 0 | J47: =IF(J11="X",(D11-C11),"0") -> 0 | K47: =IF(K11="X",(D11-C11),"0") -> 1 | L47: =IF(L11="X",(D11-C11),"0") -> 0 | M47: =IF(M11="X",(D11-C11),"0") -> 1 | N47: =IF(N11="X",(D11-C11),"0") -> 0 | O47: =IF(O11="X",(D11-C11),"0") -> 1 | P47: =IF(P11="X",(D11-C11),"0") -> 0 | Q47: =IF(Q11="X",(D11-C11),"0") -> 0 | R47: =IF(R11="X",(D11-C11),"0") -> 0 | S47: =IF(S11="X",(D11-C11),"0") -> 1 | T47: =IF(T11="X",(D11-C11),"0") -> 0
E48: =IF(E12="X",(D12-C12),"0") -> 1 | F48: =IF(F12="X",(D12-C12),"0") -> 0 | G48: =IF(G12="X",(D12-C12),"0") -> 0 | H48: =IF(H12="X",(D12-C12),"0") -> 0 | I48: =IF(I12="X",(D12-C12),"0") -> 0 | J48: =IF(J12="X",(D12-C12),"0") -> 0 | K48: =IF(K12="X",(D12-C12),"0") -> 1 | L48: =IF(L12="X",(D12-C12),"0") -> 0 | M48: =IF(M12="X",(D12-C12),"0") -> 1 | N48: =IF(N12="X",(D12-C12),"0") -> 0 | O48: =IF(O12="X",(D12-C12),"0") -> 1 | P48: =IF(P12="X",(D12-C12),"0") -> 0 | Q48: =IF(Q12="X",(D12-C12),"0") -> 0 | R48: =IF(R12="X",(D12-C12),"0") -> 0 | S48: =IF(S12="X",(D12-C12),"0") -> 1 | T48: =IF(T12="X",(D12-C12),"0") -> 0
E49: =IF(E13="X",(D13-C13),"0") -> 1 | F49: =IF(F13="X",(D13-C13),"0") -> 0 | G49: =IF(G13="X",(D13-C13),"0") -> 0 | H49: =IF(H13="X",(D13-C13),"0") -> 0 | I49: =IF(I13="X",(D13-C13),"0") -> 0 | J49: =IF(J13="X",(D13-C13),"0") -> 0 | K49: =IF(K13="X",(D13-C13),"0") -> 1 | L49: =IF(L13="X",(D13-C13),"0") -> 0 | M49: =IF(M13="X",(D13-C13),"0") -> 1 | N49: =IF(N13="X",(D13-C13),"0") -> 0 | O49: =IF(O13="X",(D13-C13),"0") -> 1 | P49: =IF(P13="X",(D13-C13),"0") -> 0 | Q49: =IF(Q13="X",(D13-C13),"0") -> 0 | R49: =IF(R13="X",(D13-C13),"0") -> 0 | S49: =IF(S13="X",(D13-C13),"0") -> 1 | T49: =IF(T13="X",(D13-C13),"0") -> 0
E50: =IF(E14="X",(D14-C14),"0") -> 1 | F50: =IF(F14="X",(D14-C14),"0") -> 0 | G50: =IF(G14="X",(D14-C14),"0") -> 0 | H50: =IF(H14="X",(D14-C14),"0") -> 0 | I50: =IF(I14="X",(D14-C14),"0") -> 0 | J50: =IF(J14="X",(D14-C14),"0") -> 0 | K50: =IF(K14="X",(D14-C14),"0") -> 1 | L50: =IF(L14="X",(D14-C14),"0") -> 0 | M50: =IF(M14="X",(D14-C14),"0") -> 1 | N50: =IF(N14="X",(D14-C14),"0") -> 0 | O50: =IF(O14="X",(D14-C14),"0") -> 1 | P50: =IF(P14="X",(D14-C14),"0") -> 0 | Q50: =IF(Q14="X",(D14-C14),"0") -> 0 | R50: =IF(R14="X",(D14-C14),"0") -> 0 | S50: =IF(S14="X",(D14-C14),"0") -> 1 | T50: =IF(T14="X",(D14-C14),"0") -> 0
E51: =IF(E15="X",(D15-C15),"0") -> 1 | F51: =IF(F15="X",(D15-C15),"0") -> 0 | G51: =IF(G15="X",(D15-C15),"0") -> 0 | H51: =IF(H15="X",(D15-C15),"0") -> 0 | I51: =IF(I15="X",(D15-C15),"0") -> 0 | J51: =IF(J15="X",(D15-C15),"0") -> 0 | K51: =IF(K15="X",(D15-C15),"0") -> 1 | L51: =IF(L15="X",(D15-C15),"0") -> 0 | M51: =IF(M15="X",(D15-C15),"0") -> 1 | N51: =IF(N15="X",(D15-C15),"0") -> 0 | O51: =IF(O15="X",(D15-C15),"0") -> 1 | P51: =IF(P15="X",(D15-C15),"0") -> 0 | Q51: =IF(Q15="X",(D15-C15),"0") -> 0 | R51: =IF(R15="X",(D15-C15),"0") -> 0 | S51: =IF(S15="X",(D15-C15),"0") -> 1 | T51: =IF(T15="X",(D15-C15),"0") -> 0
E52: =IF(E16="X",(D16-C16),"0") -> 1 | F52: =IF(F16="X",(D16-C16),"0") -> 0 | G52: =IF(G16="X",(D16-C16),"0") -> 0 | H52: =IF(H16="X",(D16-C16),"0") -> 0 | I52: =IF(I16="X",(D16-C16),"0") -> 0 | J52: =IF(J16="X",(D16-C16),"0") -> 0 | K52: =IF(K16="X",(D16-C16),"0") -> 1 | L52: =IF(L16="X",(D16-C16),"0") -> 0 | M52: =IF(M16="X",(D16-C16),"0") -> 1 | N52: =IF(N16="X",(D16-C16),"0") -> 0 | O52: =IF(O16="X",(D16-C16),"0") -> 1 | P52: =IF(P16="X",(D16-C16),"0") -> 0 | Q52: =IF(Q16="X",(D16-C16),"0") -> 0 | R52: =IF(R16="X",(D16-C16),"0") -> 0 | S52: =IF(S16="X",(D16-C16),"0") -> 1 | T52: =IF(T16="X",(D16-C16),"0") -> 0
E53: =IF(E17="X",(D17-C17),"0") -> 1 | F53: =IF(F17="X",(D17-C17),"0") -> 0 | G53: =IF(G17="X",(D17-C17),"0") -> 0 | H53: =IF(H17="X",(D17-C17),"0") -> 0 | I53: =IF(I17="X",(D17-C17),"0") -> 0 | J53: =IF(J17="X",(D17-C17),"0") -> 0 | K53: =IF(K17="X",(D17-C17),"0") -> 1 | L53: =IF(L17="X",(D17-C17),"0") -> 0 | M53: =IF(M17="X",(D17-C17),"0") -> 1 | N53: =IF(N17="X",(D17-C17),"0") -> 0 | O53: =IF(O17="X",(D17-C17),"0") -> 1 | P53: =IF(P17="X",(D17-C17),"0") -> 0 | Q53: =IF(Q17="X",(D17-C17),"0") -> 0 | R53: =IF(R17="X",(D17-C17),"0") -> 0 | S53: =IF(S17="X",(D17-C17),"0") -> 1 | T53: =IF(T17="X",(D17-C17),"0") -> 0
E54: =IF(E18="X",(D18-C18),"0") -> 1 | F54: =IF(F18="X",(D18-C18),"0") -> 0 | G54: =IF(G18="X",(D18-C18),"0") -> 0 | H54: =IF(H18="X",(D18-C18),"0") -> 0 | I54: =IF(I18="X",(D18-C18),"0") -> 0 | J54: =IF(J18="X",(D18-C18),"0") -> 0 | K54: =IF(K18="X",(D18-C18),"0") -> 1 | L54: =IF(L18="X",(D18-C18),"0") -> 0 | M54: =IF(M18="X",(D18-C18),"0") -> 1 | N54: =IF(N18="X",(D18-C18),"0") -> 0 | O54: =IF(O18="X",(D18-C18),"0") -> 1 | P54: =IF(P18="X",(D18-C18),"0") -> 0 | Q54: =IF(Q18="X",(D18-C18),"0") -> 0 | R54: =IF(R18="X",(D18-C18),"0") -> 0 | S54: =IF(S18="X",(D18-C18),"0") -> 1 | T54: =IF(T18="X",(D18-C18),"0") -> 0
... E130: =IF(E94="X",(D94-C94),"0") -> 0 | F130: =IF(F94="X",(D94-C94),"0") -> 0 | G130: =IF(G94="X",(D94-C94),"0") -> 0 | H130: =IF(H94="X",(D94-C94),"0") -> 0 | I130: =IF(I94="X",(D94-C94),"0") -> 0 | J130: =IF(J94="X",(D94-C94),"0") -> 0 | K130: =IF(K94="X",(D94-C94),"0") -> 0 | L130: =IF(L94="X",(D94-C94),"0") -> 0 | M130: =IF(M94="X",(D94-C94),"0") -> 0 | N130: =IF(N94="X",(D94-C94),"0") -> 0 | O130: =IF(O94="X",(D94-C94),"0") -> 0 | P130: =IF(P94="X",(D94-C94),"0") -> 0 | Q130: =IF(Q94="X",(D94-C94),"0") -> 0 | R130: =IF(R94="X",(D94-C94),"0") -> 0 | S130: =IF(S94="X",(D94-C94),"0") -> 0 | T130: =IF(T94="X",(D94-C94),"0") -> 0
E131: =SUM(E43:E130) -> 63.282228 | F131: =SUM(F43:F130) -> 0 | G131: =SUM(G43:G130) -> 0 | H131: =SUM(H43:H130) -> 9.147414 | I131: =SUM(I43:I130) -> 0 | J131: =SUM(J43:J130) -> 0 | K131: =SUM(K43:K130) -> 72.429642 | L131: =SUM(L43:L130) -> 0 | ... T131: =SUM(T43:T130) -> 0

Sheet 70
A1: PROGRAMA DE MANUTENÇÃORODOVIÁRIA
D2: RODOVIAS PAVIMENTADAS | I2: DATA: | J2: ='68'!$J$2 -> 46204 | N2: TÉCNICO RESP. | O2: ='68'!$O$2 -> ENG. VINÍCIUS RODRIGUES FERREIRA DE OLIVEIRA
A3: FICHA DE INSPEÇÃO: | B3: =TT!C5 -> RODOVIA TO-010 - TRECHO BABAÇULÂNDIA - WANDERLÂNDIA
A5: S.R.E. | B5: SENTIDO | C5: INÍCIO (KM) | D5: FIM (KM) | E5: CONDIÇÃO DO PAVIMENTO | J5: VEGETAÇÃO | L5: ELEM. DE DRENAGEM | O5: SIN. HOR. | R5: SIN. VERTICAL | U5: OBSERV.
E6: BOM | F6: REM. I. | G6: REM. L | H6: BUR. I | I6: BUR. L | J6: ADEQ. | K6: INADED. | L6: LIMPOS | M6: SUJOS | N6: DAN. | O6: BOM | P6: REG. | Q6: INEXIST. | R6: BOM | S6: POUCAS | T6: INEXIST.
A7: 010ETO0420 | B7: D | C7: 0 | D7: 1 | E7: X | K7: X | M7: X | O7: X | R7: X
C8: =D7 -> 1 | D8: 2 | E8: X | K8: X | M8: X | O8: X | R8: X
C9: =D8 -> 2 | D9: 3 | E9: X | K9: X | M9: X | O9: X | R9: X
C10: =D9 -> 3 | D10: 4 | E10: X | K10: X | M10: X | O10: X | R10: X
C11: =D10 -> 4 | D11: 5 | E11: X | K11: X | M11: X | O11: X | R11: X
C12: =D11 -> 5 | D12: 6 | E12: X | K12: X | M12: X | O12: X | R12: X
C13: =D12 -> 6 | D13: 7 | I13: X | K13: X | O13: X | R13: X
C14: =D13 -> 7 | D14: 8 | E14: X | K14: X | M14: X | O14: X | R14: X
C15: =D14 -> 8 | D15: 9 | E15: X | K15: X | M15: X | O15: X | R15: X
C16: =D15 -> 9 | D16: 10 | E16: X | K16: X | M16: X | O16: X | R16: X
C17: =D16 -> 10 | D17: 11 | E17: X | K17: X | M17: X | O17: X | R17: X
C18: =D17 -> 11 | D18: 12 | E18: X | K18: X | M18: X | O18: X | R18: X
C19: =D18 -> 12 | D19: 13 | E19: X | K19: X | O19: X | R19: X
C20: =D19 -> 13 | D20: 14 | E20: X | K20: X | O20: X | R20: X
C21: =D20 -> 14 | D21: 15 | H21: X | K21: X | O21: X | R21: X
C22: =D21 -> 15 | D22: 16 | E22: X | K22: X | O22: X | R22: X
C23: =D22 -> 16 | D23: 17 | E23: X | K23: X | O23: X | R23: X
C24: =D23 -> 17 | D24: 18 | E24: X | K24: X | O24: X | R24: X
C25: =D24 -> 18 | D25: 19 | E25: X | K25: X | O25: X | R25: X
C26: =D25 -> 19 | D26: 20 | H26: X | K26: X | O26: X | R26: X
C27: =D26 -> 20 | D27: 21 | E27: X | K27: X | O27: X | R27: X
C28: =D27 -> 21 | D28: 22 | E28: X | K28: X | O28: X | R28: X
C29: =D28 -> 22 | D29: 23 | E29: X | K29: X | O29: X | R29: X
C30: =D29 -> 23 | D30: 24 | E30: X | K30: X | O30: X | R30: X
C31: =D30 -> 24 | D31: 25 | E31: X | K31: X | O31: X | R31: X
C32: =D31 -> 25 | D32: 26 | E32: X | K32: X | M32: X | O32: X | R32: X
C33: =D32 -> 26 | D33: 27 | E33: X | K33: X | M33: X | O33: X | R33: X
C34: =D33 -> 27 | D34: 28 | E34: X | K34: X | O34: X | R34: X
C35: =D34 -> 28 | D35: 29 | E35: X | K35: X | O35: X | R35: X
C36: =D35 -> 29 | D36: 30 | E36: X | K36: X | O36: X | R36: X
C37: =D36 -> 30 | D37: 31 | E37: X | K37: X | O37: X | R37: X
C38: =D37 -> 31 | D38: 32 | E38: X | K38: X | M38: X | O38: X | R38: X
C39: =D38 -> 32 | D39: 33 | E39: X | K39: X | O39: X | R39: X
C40: =D39 -> 33 | D40: 34 | E40: X | K40: X | O40: X | R40: X
C41: =D40 -> 34 | D41: 35 | H41: X | K41: X | M41: X | O41: X | R41: X
...

Sheet 71
A1: PROGRAMA DE MANUTENÇÃORODOVIÁRIA
D2: RODOVIAS PAVIMENTADAS | I2: DATA: | J2: ='68'!$J$2 -> 46204 | N2: TÉCNICO RESP. | O2: ='68'!$O$2 -> ENG. VINÍCIUS RODRIGUES FERREIRA DE OLIVEIRA
A3: FICHA DE INSPEÇÃO: | B3: =TT!C6 -> RODOVIA TO-020 - TRECHO RECURSOLÂNDIA - CAMPOS LINDOS
A5: S.R.E. | B5: SENTIDO | C5: INÍCIO (KM) | D5: FIM (KM) | E5: CONDIÇÃO DO PAVIMENTO | J5: VEGETAÇÃO | L5: ELEM. DE DRENAGEM | O5: SIN. HOR. | R5: SIN. VERTICAL | U5: OBSERV.
E6: BOM | F6: REM. I. | G6: REM. L | H6: BUR. I | I6: BUR. L | J6: ADEQ. | K6: INADED. | L6: LIMPOS | M6: SUJOS | N6: DAN. | O6: BOM | P6: REG. | Q6: INEXIST. | R6: BOM | S6: POUCAS | T6: INEXIST.
A7: 020ETO0200 | B7: C | C7: 0 | D7: 2.9 | E7: X | K7: X | M7: X | Q7: X | T7: X
A8: 020ETO0215 | B8: C | C8: 0 | D8: 1 | E8: X | K8: X | L8: X | P8: X | S8: X
C9: =D8 -> 1 | D9: 2 | E9: X | K9: X | L9: X | P9: X | S9: X
C10: =D9 -> 2 | D10: 2.71 | E10: X | K10: X | L10: X | P10: X | S10: X
A48: LEGENDA | B48: CONDIÇÃO DO PAVIMENTO
A49: REM. I | B49: REMENDOS ISOLADOS | E49: ATÉ 10 REMENDOS/KM | I49: BUR. I | J49: BURACOS ISOLADOS | M49: ATÉ 5 BURACOS/KM
A50: REM. L | B50: REMENDOS AO LONGO | E50: MAIS DE 10 REMENDOS/KM | I50: BUR. L | J50: BURACOS AO LONGO | M50: MAIS DE 5 BURACOS/KM
E55: =IF(E7="X",(D7-C7),"0") -> 2.9 | F55: =IF(F7="X",(D7-C7),"0") -> 0 | G55: =IF(G7="X",(D7-C7),"0") -> 0 | H55: =IF(H7="X",(D7-C7),"0") -> 0 | I55: =IF(I7="X",(D7-C7),"0") -> 0 | J55: =IF(J7="X",(D7-C7),"0") -> 0 | K55: =IF(K7="X",(D7-C7),"0") -> 2.9 | L55: =IF(L7="X",(D7-C7),"0") -> 0 | M55: =IF(M7="X",(D7-C7),"0") -> 2.9 | N55: =IF(N7="X",(D7-C7),"0") -> 0 | O55: =IF(O7="X",(D7-C7),"0") -> 0 | P55: =IF(P7="X",(D7-C7),"0") -> 0 | Q55: =IF(Q7="X",(D7-C7),"0") -> 2.9 | R55: =IF(R7="X",(D7-C7),"0") -> 0 | S55: =IF(S7="X",(D7-C7),"0") -> 0 | T55: =IF(T7="X",(D7-C7),"0") -> 2.9
E56: =IF(E8="X",(D8-C8),"0") -> 1 | F56: =IF(F8="X",(D8-C8),"0") -> 0 | G56: =IF(G8="X",(D8-C8),"0") -> 0 | H56: =IF(H8="X",(D8-C8),"0") -> 0 | I56: =IF(I8="X",(D8-C8),"0") -> 0 | J56: =IF(J8="X",(D8-C8),"0") -> 0 | K56: =IF(K8="X",(D8-C8),"0") -> 1 | L56: =IF(L8="X",(D8-C8),"0") -> 1 | M56: =IF(M8="X",(D8-C8),"0") -> 0 | N56: =IF(N8="X",(D8-C8),"0") -> 0 | O56: =IF(O8="X",(D8-C8),"0") -> 0 | P56: =IF(P8="X",(D8-C8),"0") -> 1 | Q56: =IF(Q8="X",(D8-C8),"0") -> 0 | R56: =IF(R8="X",(D8-C8),"0") -> 0 | S56: =IF(S8="X",(D8-C8),"0") -> 1 | T56: =IF(T8="X",(D8-C8),"0") -> 0
E57: =IF(E9="X",(D9-C9),"0") -> 1 | F57: =IF(F9="X",(D9-C9),"0") -> 0 | G57: =IF(G9="X",(D9-C9),"0") -> 0 | H57: =IF(H9="X",(D9-C9),"0") -> 0 | I57: =IF(I9="X",(D9-C9),"0") -> 0 | J57: =IF(J9="X",(D9-C9),"0") -> 0 | K57: =IF(K9="X",(D9-C9),"0") -> 1 | L57: =IF(L9="X",(D9-C9),"0") -> 1 | M57: =IF(M9="X",(D9-C9),"0") -> 0 | N57: =IF(N9="X",(D9-C9),"0") -> 0 | O57: =IF(O9="X",(D9-C9),"0") -> 0 | P57: =IF(P9="X",(D9-C9),"0") -> 1 | Q57: =IF(Q9="X",(D9-C9),"0") -> 0 | R57: =IF(R9="X",(D9-C9),"0") -> 0 | S57: =IF(S9="X",(D9-C9),"0") -> 1 | T57: =IF(T9="X",(D9-C9),"0") -> 0
E58: =IF(E10="X",(D10-C10),"0") -> 0.71 | F58: =IF(F10="X",(D10-C10),"0") -> 0 | G58: =IF(G10="X",(D10-C10),"0") -> 0 | H58: =IF(H10="X",(D10-C10),"0") -> 0 | I58: =IF(I10="X",(D10-C10),"0") -> 0 | J58: =IF(J10="X",(D10-C10),"0") -> 0 | K58: =IF(K10="X",(D10-C10),"0") -> 0.71 | L58: =IF(L10="X",(D10-C10),"0") -> 0.71 | M58: =IF(M10="X",(D10-C10),"0") -> 0 | N58: =IF(N10="X",(D10-C10),"0") -> 0 | O58: =IF(O10="X",(D10-C10),"0") -> 0 | P58: =IF(P10="X",(D10-C10),"0") -> 0.71 | Q58: =IF(Q10="X",(D10-C10),"0") -> 0 | R58: =IF(R10="X",(D10-C10),"0") -> 0 | S58: =IF(S10="X",(D10-C10),"0") -> 0.71 | T58: =IF(T10="X",(D10-C10),"0") -> 0
E59: =IF(E11="X",(D11-C11),"0") -> 0 | F59: =IF(F11="X",(D11-C11),"0") -> 0 | G59: =IF(G11="X",(D11-C11),"0") -> 0 | H59: =IF(H11="X",(D11-C11),"0") -> 0 | I59: =IF(I11="X",(D11-C11),"0") -> 0 | J59: =IF(J11="X",(D11-C11),"0") -> 0 | K59: =IF(K11="X",(D11-C11),"0") -> 0 | L59: =IF(L11="X",(D11-C11),"0") -> 0 | M59: =IF(M11="X",(D11-C11),"0") -> 0 | N59: =IF(N11="X",(D11-C11),"0") -> 0 | O59: =IF(O11="X",(D11-C11),"0") -> 0 | P59: =IF(P11="X",(D11-C11),"0") -> 0 | Q59: =IF(Q11="X",(D11-C11),"0") -> 0 | R59: =IF(R11="X",(D11-C11),"0") -> 0 | S59: =IF(S11="X",(D11-C11),"0") -> 0 | T59: =IF(T11="X",(D11-C11),"0") -> 0
E60: =IF(E12="X",(D12-C12),"0") -> 0 | F60: =IF(F12="X",(D12-C12),"0") -> 0 | G60: =IF(G12="X",(D12-C12),"0") -> 0 | H60: =IF(H12="X",(D12-C12),"0") -> 0 | I60: =IF(I12="X",(D12-C12),"0") -> 0 | J60: =IF(J12="X",(D12-C12),"0") -> 0 | K60: =IF(K12="X",(D12-C12),"0") -> 0 | L60: =IF(L12="X",(D12-C12),"0") -> 0 | M60: =IF(M12="X",(D12-C12),"0") -> 0 | N60: =IF(N12="X",(D12-C12),"0") -> 0 | O60: =IF(O12="X",(D12-C12),"0") -> 0 | P60: =IF(P12="X",(D12-C12),"0") -> 0 | Q60: =IF(Q12="X",(D12-C12),"0") -> 0 | R60: =IF(R12="X",(D12-C12),"0") -> 0 | S60: =IF(S12="X",(D12-C12),"0") -> 0 | T60: =IF(T12="X",(D12-C12),"0") -> 0
E61: =IF(E13="X",(D13-C13),"0") -> 0 | F61: =IF(F13="X",(D13-C13),"0") -> 0 | G61: =IF(G13="X",(D13-C13),"0") -> 0 | H61: =IF(H13="X",(D13-C13),"0") -> 0 | I61: =IF(I13="X",(D13-C13),"0") -> 0 | J61: =IF(J13="X",(D13-C13),"0") -> 0 | K61: =IF(K13="X",(D13-C13),"0") -> 0 | L61: =IF(L13="X",(D13-C13),"0") -> 0 | M61: =IF(M13="X",(D13-C13),"0") -> 0 | N61: =IF(N13="X",(D13-C13),"0") -> 0 | O61: =IF(O13="X",(D13-C13),"0") -> 0 | P61: =IF(P13="X",(D13-C13),"0") -> 0 | Q61: =IF(Q13="X",(D13-C13),"0") -> 0 | R61: =IF(R13="X",(D13-C13),"0") -> 0 | S61: =IF(S13="X",(D13-C13),"0") -> 0 | T61: =IF(T13="X",(D13-C13),"0") -> 0
E62: =IF(E14="X",(D14-C14),"0") -> 0 | F62: =IF(F14="X",(D14-C14),"0") -> 0 | G62: =IF(G14="X",(D14-C14),"0") -> 0 | H62: =IF(H14="X",(D14-C14),"0") -> 0 | I62: =IF(I14="X",(D14-C14),"0") -> 0 | J62: =IF(J14="X",(D14-C14),"0") -> 0 | K62: =IF(K14="X",(D14-C14),"0") -> 0 | L62: =IF(L14="X",(D14-C14),"0") -> 0 | M62: =IF(M14="X",(D14-C14),"0") -> 0 | N62: =IF(N14="X",(D14-C14),"0") -> 0 | O62: =IF(O14="X",(D14-C14),"0") -> 0 | P62: =IF(P14="X",(D14-C14),"0") -> 0 | Q62: =IF(Q14="X",(D14-C14),"0") -> 0 | R62: =IF(R14="X",(D14-C14),"0") -> 0 | S62: =IF(S14="X",(D14-C14),"0") -> 0 | T62: =IF(T14="X",(D14-C14),"0") -> 0
E63: =IF(E15="X",(D15-C15),"0") -> 0 | F63: =IF(F15="X",(D15-C15),"0") -> 0 | G63: =IF(G15="X",(D15-C15),"0") -> 0 | H63: =IF(H15="X",(D15-C15),"0") -> 0 | I63: =IF(I15="X",(D15-C15),"0") -> 0 | J63: =IF(J15="X",(D15-C15),"0") -> 0 | K63: =IF(K15="X",(D15-C15),"0") -> 0 | L63: =IF(L15="X",(D15-C15),"0") -> 0 | M63: =IF(M15="X",(D15-C15),"0") -> 0 | N63: =IF(N15="X",(D15-C15),"0") -> 0 | O63: =IF(O15="X",(D15-C15),"0") -> 0 | P63: =IF(P15="X",(D15-C15),"0") -> 0 | Q63: =IF(Q15="X",(D15-C15),"0") -> 0 | R63: =IF(R15="X",(D15-C15),"0") -> 0 | S63: =IF(S15="X",(D15-C15),"0") -> 0 | T63: =IF(T15="X",(D15-C15),"0") -> 0
E64: =IF(E16="X",(D16-C16),"0") -> 0 | F64: =IF(F16="X",(D16-C16),"0") -> 0 | G64: =IF(G16="X",(D16-C16),"0") -> 0 | H64: =IF(H16="X",(D16-C16),"0") -> 0 | I64: =IF(I16="X",(D16-C16),"0") -> 0 | J64: =IF(J16="X",(D16-C16),"0") -> 0 | K64: =IF(K16="X",(D16-C16),"0") -> 0 | L64: =IF(L16="X",(D16-C16),"0") -> 0 | M64: =IF(M16="X",(D16-C16),"0") -> 0 | N64: =IF(N16="X",(D16-C16),"0") -> 0 | O64: =IF(O16="X",(D16-C16),"0") -> 0 | P64: =IF(P16="X",(D16-C16),"0") -> 0 | Q64: =IF(Q16="X",(D16-C16),"0") -> 0 | R64: =IF(R16="X",(D16-C16),"0") -> 0 | S64: =IF(S16="X",(D16-C16),"0") -> 0 | T64: =IF(T16="X",(D16-C16),"0") -> 0
E65: =IF(E17="X",(D17-C17),"0") -> 0 | F65: =IF(F17="X",(D17-C17),"0") -> 0 | G65: =IF(G17="X",(D17-C17),"0") -> 0 | H65: =IF(H17="X",(D17-C17),"0") -> 0 | I65: =IF(I17="X",(D17-C17),"0") -> 0 | J65: =IF(J17="X",(D17-C17),"0") -> 0 | K65: =IF(K17="X",(D17-C17),"0") -> 0 | L65: =IF(L17="X",(D17-C17),"0") -> 0 | M65: =IF(M17="X",(D17-C17),"0") -> 0 | N65: =IF(N17="X",(D17-C17),"0") -> 0 | O65: =IF(O17="X",(D17-C17),"0") -> 0 | P65: =IF(P17="X",(D17-C17),"0") -> 0 | Q65: =IF(Q17="X",(D17-C17),"0") -> 0 | R65: =IF(R17="X",(D17-C17),"0") -> 0 | S65: =IF(S17="X",(D17-C17),"0") -> 0 | T65: =IF(T17="X",(D17-C17),"0") -> 0
E66: =IF(E18="X",(D18-C18),"0") -> 0 | F66: =IF(F18="X",(D18-C18),"0") -> 0 | G66: =IF(G18="X",(D18-C18),"0") -> 0 | H66: =IF(H18="X",(D18-C18),"0") -> 0 | I66: =IF(I18="X",(D18-C18),"0") -> 0 | J66: =IF(J18="X",(D18-C18),"0") -> 0 | K66: =IF(K18="X",(D18-C18),"0") -> 0 | L66: =IF(L18="X",(D18-C18),"0") -> 0 | M66: =IF(M18="X",(D18-C18),"0") -> 0 | N66: =IF(N18="X",(D18-C18),"0") -> 0 | O66: =IF(O18="X",(D18-C18),"0") -> 0 | P66: =IF(P18="X",(D18-C18),"0") -> 0 | Q66: =IF(Q18="X",(D18-C18),"0") -> 0 | R66: =IF(R18="X",(D18-C18),"0") -> 0 | S66: =IF(S18="X",(D18-C18),"0") -> 0 | T66: =IF(T18="X",(D18-C18),"0") -> 0
... E142: =IF(E94="X",(D94-C94),"0") -> 0 | F142: =IF(F94="X",(D94-C94),"0") -> 0 | G142: =IF(G94="X",(D94-C94),"0") -> 0 | H142: =IF(H94="X",(D94-C94),"0") -> 0 | I142: =IF(I94="X",(D94-C94),"0") -> 0 | J142: =IF(J94="X",(D94-C94),"0") -> 0 | K142: =IF(K94="X",(D94-C94),"0") -> 0 | L142: =IF(L94="X",(D94-C94),"0") -> 0 | M142: =IF(M94="X",(D94-C94),"0") -> 0 | N142: =IF(N94="X",(D94-C94),"0") -> 0 | O142: =IF(O94="X",(D94-C94),"0") -> 0 | P142: =IF(P94="X",(D94-C94),"0") -> 0 | Q142: =IF(Q94="X",(D94-C94),"0") -> 0 | R142: =IF(R94="X",(D94-C94),"0") -> 0 | S142: =IF(S94="X",(D94-C94),"0") -> 0 | T142: =IF(T94="X",(D94-C94),"0") -> 0
E143: =SUM(E55:E142) -> 5.61 | F143: =SUM(F55:F142) -> 0 | G143: =SUM(G55:G142) -> 0 | H143: =SUM(H55:H142) -> 0 | I143: =SUM(I55:I142) -> 0 | J143: =SUM(J55:J142) -> 0 | K143: =SUM(K55:K142) -> 5.61 | L143: =SUM(L55:L142) -> 2.71 | ... T143: =SUM(T55:T142) -> 2.9

Sheet 73
A1: PROGRAMA DE MANUTENÇÃORODOVIÁRIA
D2: RODOVIAS PAVIMENTADAS | I2: DATA: | J2: ='68'!$J$2 -> 46204 | N2: TÉCNICO RESP. | O2: ='68'!$O$2 -> ENG. VINÍCIUS RODRIGUES FERREIRA DE OLIVEIRA
A3: FICHA DE INSPEÇÃO: | B3: =TT!C7 -> RODOVIA TO-130 - TRECHO ENTR. TO-010 - TRECHO BARRA DO OURO - ENTR. BR-010 (POVOADO MORRO GRANDE)
A5: S.R.E. | B5: SENTIDO | C5: INÍCIO (KM) | D5: FIM (KM) | E5: CONDIÇÃO DO PAVIMENTO | J5: VEGETAÇÃO | L5: ELEM. DE DRENAGEM | O5: SIN. HOR. | R5: SIN. VERTICAL | U5: OBSERV.
E6: BOM | F6: REM. I. | G6: REM. L | H6: BUR. I | I6: BUR. L | J6: ADEQ. | K6: INADED. | L6: LIMPOS | M6: SUJOS | N6: DAN. | O6: BOM | P6: REG. | Q6: INEXIST. | R6: BOM | S6: POUCAS | T6: INEXIST.
A7: 130ETO0070 | B7: D | C7: 0 | D7: 0.4 | E7: X | K7: X | M7: X | O7: X | R7: X
C8: =D7 -> 0.4 | D8: 2.5 | E8: X | K8: X | M8: X | O8: X | R8: X
C9: =D8 -> 2.5 | D9: 2.7 | F9: X | K9: X | M9: X | O9: X | R9: X
C10: =D9 -> 2.7 | D10: 3.4 | E10: X | K10: X | N10: X | O10: X | R10: X
C11: =D10 -> 3.4 | D11: 5 | E11: X | H11: X | K11: X | M11: X | O11: X | R11: X
C12: =D11 -> 5 | D12: 5.1 | I12: X | K12: X | M12: X | O12: X | R12: X
C13: =D12 -> 5.1 | D13: 10.9 | E13: X | K13: X | M13: X | O13: X | R13: X
C14: =D13 -> 10.9 | D14: 11 | I14: X | K14: X | M14: X | O14: X | R14: X
C15: =D14 -> 11 | D15: 12.8 | E15: X | K15: X | M15: X | O15: X | R15: X
C16: =D15 -> 12.8 | D16: 13 | H16: X | K16: X | M16: X | O16: X | R16: X
C17: =D16 -> 13 | D17: 14.3 | E17: X | K17: X | M17: X | O17: X | R17: X
C18: =D17 -> 14.3 | D18: 14.4 | I18: X | K18: X | M18: X | O18: X | R18: X
C19: =D18 -> 14.4 | D19: 20.1 | I19: X | K19: X | M19: X | O19: X | R19: X
A20: 130ETO0060 | B20: D | C20: 0 | D20: 3.75 | E20: X | K20: X | M20: X | O20: X | R20: X
A21: 130ETO0040 | B21: D | C21: 0 | D21: 1 | E21: X | K21: X | M21: X | Q21: X | S21: X
C22: =D21 -> 1 | D22: 2 | E22: X | K22: X | M22: X | Q22: X | S22: X
C23: =D22 -> 2 | D23: 3 | E23: X | K23: X | M23: X | Q23: X | S23: X
C24: =D23 -> 3 | D24: 4 | E24: X | K24: X | M24: X | Q24: X | S24: X
C25: =D24 -> 4 | D25: 5 | E25: X | K25: X | M25: X | Q25: X | S25: X
C26: =D25 -> 5 | D26: 6 | E26: X | K26: X | M26: X | Q26: X | S26: X
C27: =D26 -> 6 | D27: 7 | E27: X | K27: X | M27: X | Q27: X | S27: X
C28: =D27 -> 7 | D28: 8 | E28: X | K28: X | M28: X | Q28: X | S28: X
C29: =D28 -> 8 | D29: 9 | E29: X | K29: X | M29: X | Q29: X | S29: X
C30: =D29 -> 9 | D30: 10 | E30: X | K30: X | M30: X | Q30: X | S30: X
C31: =D30 -> 10 | D31: 11 | E31: X | K31: X | M31: X | Q31: X | S31: X
C32: =D31 -> 11 | D32: 12 | E32: X | K32: X | M32: X | Q32: X | S32: X
C33: =D32 -> 12 | D33: 13 | E33: X | K33: X | M33: X | Q33: X | S33: X
... C46: =D45 -> 25 | D46: 25.2 | E46: X | K46: X | M46: X | Q46: X | S46: X
A52: LEGENDA | B52: CONDIÇÃO DO PAVIMENTO
A53: REM. I | B53: REMENDOS ISOLADOS | E53: ATÉ 10 REMENDOS/KM | I53: BUR. I | J53: BURACOS ISOLADOS | M53: ATÉ 5 BURACOS/KM
A54: REM. L | B54: REMENDOS AO LONGO | E54: MAIS DE 10 REMENDOS/KM | I54: BUR. L | J54: BURACOS AO LONGO | M54: MAIS DE 5 BURACOS/KM
E59: =IF(E7="X",(D7-C7),"0") -> 0.4 | F59: =IF(F7="X",(D7-C7),"0") -> 0 | G59: =IF(G7="X",(D7-C7),"0") -> 0 | H59: =IF(H7="X",(D7-C7),"0") -> 0 | I59: =IF(I7="X",(D7-C7),"0") -> 0 | J59: =IF(J7="X",(D7-C7),"0") -> 0 | K59: =IF(K7="X",(D7-C7),"0") -> 0.4 | L59: =IF(L7="X",(D7-C7),"0") -> 0 | M59: =IF(M7="X",(D7-C7),"0") -> 0.4 | N59: =IF(N7="X",(D7-C7),"0") -> 0 | O59: =IF(O7="X",(D7-C7),"0") -> 0.4 | P59: =IF(P7="X",(D7-C7),"0") -> 0 | Q59: =IF(Q7="X",(D7-C7),"0") -> 0 | R59: =IF(R7="X",(D7-C7),"0") -> 0.4 | S59: =IF(S7="X",(D7-C7),"0") -> 0 | T59: =IF(T7="X",(D7-C7),"0") -> 0
E60: =IF(E8="X",(D8-C8),"0") -> 2.1 | F60: =IF(F8="X",(D8-C8),"0") -> 0 | G60: =IF(G8="X",(D8-C8),"0") -> 0 | H60: =IF(H8="X",(D8-C8),"0") -> 0 | I60: =IF(I8="X",(D8-C8),"0") -> 0 | J60: =IF(J8="X",(D8-C8),"0") -> 0 | K60: =IF(K8="X",(D8-C8),"0") -> 2.1 | L60: =IF(L8="X",(D8-C8),"0") -> 0 | M60: =IF(M8="X",(D8-C8),"0") -> 2.1 | N60: =IF(N8="X",(D8-C8),"0") -> 0 | O60: =IF(O8="X",(D8-C8),"0") -> 2.1 | P60: =IF(P8="X",(D8-C8),"0") -> 0 | Q60: =IF(Q8="X",(D8-C8),"0") -> 0 | R60: =IF(R8="X",(D8-C8),"0") -> 2.1 | S60: =IF(S8="X",(D8-C8),"0") -> 0 | T60: =IF(T8="X",(D8-C8),"0") -> 0
E61: =IF(E9="X",(D9-C9),"0") -> 0 | F61: =IF(F9="X",(D9-C9),"0") -> 0.2 | G61: =IF(G9="X",(D9-C9),"0") -> 0 | H61: =IF(H9="X",(D9-C9),"0") -> 0 | I61: =IF(I9="X",(D9-C9),"0") -> 0 | J61: =IF(J9="X",(D9-C9),"0") -> 0 | K61: =IF(K9="X",(D9-C9),"0") -> 0.2 | L61: =IF(L9="X",(D9-C9),"0") -> 0 | M61: =IF(M9="X",(D9-C9),"0") -> 0.2 | N61: =IF(N9="X",(D9-C9),"0") -> 0 | O61: =IF(O9="X",(D9-C9),"0") -> 0.2 | P61: =IF(P9="X",(D9-C9),"0") -> 0 | Q61: =IF(Q9="X",(D9-C9),"0") -> 0 | R61: =IF(R9="X",(D9-C9),"0") -> 0.2 | S61: =IF(S9="X",(D9-C9),"0") -> 0 | T61: =IF(T9="X",(D9-C9),"0") -> 0
E62: =IF(E10="X",(D10-C10),"0") -> 0.7 | F62: =IF(F10="X",(D10-C10),"0") -> 0 | G62: =IF(G10="X",(D10-C10),"0") -> 0 | H62: =IF(H10="X",(D10-C10),"0") -> 0 | I62: =IF(I10="X",(D10-C10),"0") -> 0 | J62: =IF(J10="X",(D10-C10),"0") -> 0 | K62: =IF(K10="X",(D10-C10),"0") -> 0.7 | L62: =IF(L10="X",(D10-C10),"0") -> 0 | M62: =IF(M10="X",(D10-C10),"0") -> 0 | N62: =IF(N10="X",(D10-C10),"0") -> 0.7 | O62: =IF(O10="X",(D10-C10),"0") -> 0.7 | P62: =IF(P10="X",(D10-C10),"0") -> 0 | Q62: =IF(Q10="X",(D10-C10),"0") -> 0 | R62: =IF(R10="X",(D10-C10),"0") -> 0.7 | S62: =IF(S10="X",(D10-C10),"0") -> 0 | T62: =IF(T10="X",(D10-C10),"0") -> 0
...

Sheet 74
A1: PROGRAMA DE MANUTENÇÃORODOVIÁRIA
D2: RODOVIAS PAVIMENTADAS | I2: DATA: | J2: ='68'!$J$2 -> 46204 | N2: TÉCNICO RESP. | O2: ='68'!$O$2 -> ENG. VINÍCIUS RODRIGUES FERREIRA DE OLIVEIRA
A3: FICHA DE INSPEÇÃO: | B3: =TT!C8 -> RODOVIA TO-222 - TRECHO ARAGUAÍNA - FILADÉLFIA
A5: S.R.E. | B5: SENTIDO | C5: INÍCIO (KM) | D5: FIM (KM) | E5: CONDIÇÃO DO PAVIMENTO | J5: VEGETAÇÃO | L5: ELEM. DE DRENAGEM | O5: SIN. HOR. | R5: SIN. VERTICAL | U5: OBSERV.
E6: BOM | F6: REM. I. | G6: REM. L | H6: BUR. I | I6: BUR. L | J6: ADEQ. | K6: INADED. | L6: LIMPOS | M6: SUJOS | N6: DAN. | O6: BOM | P6: REG. | Q6: INEXIST. | R6: BOM | S6: POUCAS | T6: INEXIST.
A7: 010ETO0370 | B7: D | C7: 0 | D7: 0.5 | H7: X | K7: X | M7: X | O7: X | S7: X
A8: 010ETO0370 | B8: D | C8: =D7 -> 0.5 | D8: 4 | I8: X | K8: X | M8: X | O8: X | S8: X
A9: 010ETO0370 | B9: D | C9: =D8 -> 4 | D9: 9 | H9: X | K9: X | M9: X | O9: X | S9: X
A10: 010ETO0370 | B10: D | C10: =D9 -> 9 | D10: 15 | H10: X | K10: X | M10: X | O10: X | S10: X
A11: 010ETO0370 | B11: D | C11: =D10 -> 15 | D11: 26.23 | H11: X | K11: X | M11: X | O11: X | S11: X
O12: X | S12: X
A13: 222ETO0060 | B13: C | C13: 0 | D13: 8.37 | E13: X | O13: X | S13: X
A14: 222ETO0070 | B14: C | C14: 0 | D14: 16.87 | E14: X | O14: X | S14: X
A15: 222ETO0030 | B15: C | C15: 0 | D15: 4 | E15: X | O15: X | S15: X
C16: 4 | D16: 5 | E16: X | O16: X | S16: X
C17: 5 | D17: 6 | E17: X | O17: X | S17: X
C18: 6 | D18: 10 | E18: X | O18: X | S18: X
C19: 10 | D19: 13 | E19: X | O19: X | S19: X
C20: 13 | D20: 15 | E20: X | O20: X | S20: X
C21: 15 | D21: 19 | E21: X | O21: X | S21: X
C22: 19 | D22: 20.25 | E22: X | O22: X | S22: X
A23: 222ETO0020 | C23: 0 | D23: 3 | E23: X | K23: X | M23: X | O23: X | S23: X
C24: =D23 -> 3 | D24: 7 | E24: X | K24: X | M24: X | O24: X | S24: X
C25: =D24 -> 7 | D25: 10 | E25: X | K25: X | M25: X | O25: X | S25: X
C26: =D25 -> 10 | D26: 14 | E26: X | K26: X | M26: X | O26: X | S26: X
C27: =D26 -> 14 | D27: 21.66 | E27: X | K27: X | M27: X | O27: X | S27: X
A28: 222ETO0010 | C28: 0 | D28: 5 | E28: X | K28: X | M28: X | O28: X | S28: X
C29: 5 | D29: 7.66 | G29: X | I29: X | J29: X | M29: X | O29: X | S29: X
A38: LEGENDA | B38: CONDIÇÃO DO PAVIMENTO
A39: REM. I | B39: REMENDOS ISOLADOS | E39: ATÉ 10 REMENDOS/KM | I39: BUR. I | J39: BURACOS ISOLADOS | M39: ATÉ 5 BURACOS/KM
A40: REM. L | B40: REMENDOS AO LONGO | E40: MAIS DE 10 REMENDOS/KM | I40: BUR. L | J40: BURACOS AO LONGO | M40: MAIS DE 5 BURACOS/KM
E45: =IF(E7="X",($D$7-$C$7),"0") -> 0 | F45: =IF(F7="X",($D$7-$C$7),"0") -> 0 | G45: =IF(G7="X",($D$7-$C$7),"0") -> 0 | H45: =IF(H7="X",($D$7-$C$7),"0") -> 0.5 | I45: =IF(I7="X",($D$7-$C$7),"0") -> 0 | J45: =IF(J7="X",(D7-C7),"0") -> 0 | K45: =IF(K7="X",($D$7-$C$7),"0") -> 0.5 | L45: =IF(L7="X",($D$7-$C$7),"0") -> 0 | M45: =IF(M7="X",($D$7-$C$7),"0") -> 0.5 | N45: =IF(N7="X",($D$7-$C$7),"0") -> 0 | O45: =IF(O7="X",($D$7-$C$7),"0") -> 0.5 | P45: =IF(P7="X",($D$7-$C$7),"0") -> 0 | Q45: =IF(Q7="X",($D$7-$C$7),"0") -> 0 | R45: =IF(R7="X",($D$7-$C$7),"0") -> 0 | ... T45: =IF(T7="X",($D$7-$C$7),"0") -> 0
E46: =IF(E8="X",($D$7-$C$7),"0") -> 0 | F46: =IF(F8="X",($D$7-$C$7),"0") -> 0 | G46: =IF(G8="X",($D$7-$C$7),"0") -> 0 | H46: =IF(H8="X",($D$7-$C$7),"0") -> 0 | I46: =IF(I8="X",($D$7-$C$7),"0") -> 0.5 | J46: =IF(J8="X",(D8-C8),"0") -> 0 | K46: =IF(K8="X",($D$7-$C$7),"0") -> 0.5 | L46: =IF(L8="X",($D$7-$C$7),"0") -> 0 | M46: =IF(M8="X",($D$7-$C$7),"0") -> 0.5 | N46: =IF(N8="X",($D$7-$C$7),"0") -> 0 | O46: =IF(O8="X",($D$7-$C$7),"0") -> 0.5 | P46: =IF(P8="X",($D$7-$C$7),"0") -> 0 | Q46: =IF(Q8="X",($D$7-$C$7),"0") -> 0 | R46: =IF(R8="X",($D$7-$C$7),"0") -> 0 | ... T46: =IF(T8="X",($D$7-$C$7),"0") -> 0
E47: =IF(E9="X",($D$7-$C$7),"0") -> 0 | F47: =IF(F9="X",($D$7-$C$7),"0") -> 0 | G47: =IF(G9="X",($D$7-$C$7),"0") -> 0 | H47: =IF(H9="X",($D$7-$C$7),"0") -> 0.5 | I47: =IF(I9="X",($D$7-$C$7),"0") -> 0 | J47: =IF(J9="X",(D9-C9),"0") -> 0 | K47: =IF(K9="X",($D$7-$C$7),"0") -> 0.5 | L47: =IF(L9="X",($D$7-$C$7),"0") -> 0 | M47: =IF(M9="X",($D$7-$C$7),"0") -> 0.5 | N47: =IF(N9="X",($D$7-$C$7),"0") -> 0 | O47: =IF(O9="X",($D$7-$C$7),"0") -> 0.5 | P47: =IF(P9="X",($D$7-$C$7),"0") -> 0 | Q47: =IF(Q9="X",($D$7-$C$7),"0") -> 0 | R47: =IF(R9="X",($D$7-$C$7),"0") -> 0 | ... T47: =IF(T9="X",($D$7-$C$7),"0") -> 0
E48: =IF(E10="X",($D$7-$C$7),"0") -> 0 | F48: =IF(F10="X",($D$7-$C$7),"0") -> 0 | G48: =IF(G10="X",($D$7-$C$7),"0") -> 0 | H48: =IF(H10="X",($D$7-$C$7),"0") -> 0.5 | I48: =IF(I10="X",($D$7-$C$7),"0") -> 0 | J48: =IF(J10="X",(D10-C10),"0") -> 0 | K48: =IF(K10="X",($D$7-$C$7),"0") -> 0.5 | L48: =IF(L10="X",($D$7-$C$7),"0") -> 0 | M48: =IF(M10="X",($D$7-$C$7),"0") -> 0.5 | N48: =IF(N10="X",($D$7-$C$7),"0") -> 0 | O48: =IF(O10="X",($D$7-$C$7),"0") -> 0.5 | P48: =IF(P10="X",($D$7-$C$7),"0") -> 0 | Q48: =IF(Q10="X",($D$7-$C$7),"0") -> 0 | R48: =IF(R10="X",($D$7-$C$7),"0") -> 0 | ... T48: =IF(T10="X",($D$7-$C$7),"0") -> 0
E49: =IF(E11="X",($D$7-$C$7),"0") -> 0 | F49: =IF(F11="X",($D$7-$C$7),"0") -> 0 | G49: =IF(G11="X",($D$7-$C$7),"0") -> 0 | H49: =IF(H11="X",($D$7-$C$7),"0") -> 0.5 | I49: =IF(I11="X",($D$7-$C$7),"0") -> 0 | J49: =IF(J11="X",(D11-C11),"0") -> 0 | K49: =IF(K11="X",($D$7-$C$7),"0") -> 0.5 | L49: =IF(L11="X",($D$7-$C$7),"0") -> 0 | M49: =IF(M11="X",($D$7-$C$7),"0") -> 0.5 | N49: =IF(N11="X",($D$7-$C$7),"0") -> 0 | O49: =IF(O11="X",($D$7-$C$7),"0") -> 0.5 | P49: =IF(P11="X",($D$7-$C$7),"0") -> 0 | Q49: =IF(Q11="X",($D$7-$C$7),"0") -> 0 | R49: =IF(R11="X",($D$7-$C$7),"0") -> 0 | ... T49: =IF(T11="X",($D$7-$C$7),"0") -> 0
E50: =IF(E12="X",($D$7-$C$7),"0") -> 0 | F50: =IF(F12="X",($D$7-$C$7),"0") -> 0 | G50: =IF(G12="X",($D$7-$C$7),"0") -> 0 | H50: =IF(H12="X",($D$7-$C$7),"0") -> 0 | I50: =IF(I12="X",($D$7-$C$7),"0") -> 0 | J50: =IF(J12="X",(D12-C12),"0") -> 0 | K50: =IF(K12="X",($D$7-$C$7),"0") -> 0 | L50: =IF(L12="X",($D$7-$C$7),"0") -> 0 | M50: =IF(M12="X",($D$7-$C$7),"0") -> 0 | N50: =IF(N12="X",($D$7-$C$7),"0") -> 0 | O50: =IF(O12="X",($D$7-$C$7),"0") -> 0.5 | P50: =IF(P12="X",($D$7-$C$7),"0") -> 0 | Q50: =IF(Q12="X",($D$7-$C$7),"0") -> 0 | R50: =IF(R12="X",($D$7-$C$7),"0") -> 0 | ... T50: =IF(T12="X",($D$7-$C$7),"0") -> 0
E51: =IF(E13="X",($D$7-$C$7),"0") -> 0.5 | F51: =IF(F13="X",($D$7-$C$7),"0") -> 0 | G51: =IF(G13="X",($D$7-$C$7),"0") -> 0 | H51: =IF(H13="X",($D$7-$C$7),"0") -> 0 | I51: =IF(I13="X",($D$7-$C$7),"0") -> 0 | J51: =IF(J13="X",(D13-C13),"0") -> 0 | K51: =IF(K13="X",($D$7-$C$7),"0") -> 0 | L51: =IF(L13="X",($D$7-$C$7),"0") -> 0 | M51: =IF(M13="X",($D$7-$C$7),"0") -> 0 | N51: =IF(N13="X",($D$7-$C$7),"0") -> 0 | O51: =IF(O13="X",($D$7-$C$7),"0") -> 0.5 | P51: =IF(P13="X",($D$7-$C$7),"0") -> 0 | Q51: =IF(Q13="X",($D$7-$C$7),"0") -> 0 | R51: =IF(R13="X",($D$7-$C$7),"0") -> 0 | ... T51: =IF(T13="X",($D$7-$C$7),"0") -> 0
E52: =IF(E14="X",($D$7-$C$7),"0") -> 0.5 | F52: =IF(F14="X",($D$7-$C$7),"0") -> 0 | G52: =IF(G14="X",($D$7-$C$7),"0") -> 0 | H52: =IF(H14="X",($D$7-$C$7),"0") -> 0 | I52: =IF(I14="X",($D$7-$C$7),"0") -> 0 | J52: =IF(J14="X",(D14-C14),"0") -> 0 | K52: =IF(K14="X",($D$7-$C$7),"0") -> 0 | L52: =IF(L14="X",($D$7-$C$7),"0") -> 0 | M52: =IF(M14="X",($D$7-$C$7),"0") -> 0 | N52: =IF(N14="X",($D$7-$C$7),"0") -> 0 | O52: =IF(O14="X",($D$7-$C$7),"0") -> 0.5 | P52: =IF(P14="X",($D$7-$C$7),"0") -> 0 | Q52: =IF(Q14="X",($D$7-$C$7),"0") -> 0 | R52: =IF(R14="X",($D$7-$C$7),"0") -> 0 | ... T52: =IF(T14="X",($D$7-$C$7),"0") -> 0
E53: =IF(E15="X",($D$7-$C$7),"0") -> 0.5 | F53: =IF(F15="X",($D$7-$C$7),"0") -> 0 | G53: =IF(G15="X",($D$7-$C$7),"0") -> 0 | H53: =IF(H15="X",($D$7-$C$7),"0") -> 0 | I53: =IF(I15="X",($D$7-$C$7),"0") -> 0 | J53: =IF(J15="X",(D15-C15),"0") -> 0 | K53: =IF(K15="X",($D$7-$C$7),"0") -> 0 | L53: =IF(L15="X",($D$7-$C$7),"0") -> 0 | M53: =IF(M15="X",($D$7-$C$7),"0") -> 0 | N53: =IF(N15="X",($D$7-$C$7),"0") -> 0 | O53: =IF(O15="X",($D$7-$C$7),"0") -> 0.5 | P53: =IF(P15="X",($D$7-$C$7),"0") -> 0 | Q53: =IF(Q15="X",($D$7-$C$7),"0") -> 0 | R53: =IF(R15="X",($D$7-$C$7),"0") -> 0 | ... T53: =IF(T15="X",($D$7-$C$7),"0") -> 0
...

Sheet 75
A1: PROGRAMA DE MANUTENÇÃORODOVIÁRIA
D2: RODOVIAS PAVIMENTADAS | I2: DATA: | J2: ='68'!$J$2 -> 46204 | N2: TÉCNICO RESP. | O2: ='68'!$O$2 -> ENG. VINÍCIUS RODRIGUES FERREIRA DE OLIVEIRA
A3: FICHA DE INSPEÇÃO: | B3: =TT!C9 -> RODOVIA TO-226 - TRECHO NOVA OLINDA - ENTR. TO-010
A5: S.R.E. | B5: SENTIDO | C5: INÍCIO (KM) | D5: FIM (KM) | E5: CONDIÇÃO DO PAVIMENTO | J5: VEGETAÇÃO | L5: ELEM. DE DRENAGEM | O5: SIN. HOR. | R5: SIN. VERTICAL | U5: OBSERV.
E6: BOM | F6: REM. I. | G6: REM. L | H6: BUR. I | I6: BUR. L | J6: ADEQ. | K6: INADED. | L6: LIMPOS | M6: SUJOS | N6: DAN. | O6: BOM | P6: REG. | Q6: INEXIST. | R6: BOM | S6: POUCAS | T6: INEXIST.
A7: 226ETO0201 | B7: D | C7: 0 | D7: 0.4 | E7: X | K7: X | M7: X | Q7: X | R7: X
A8: 226ETO0201 | B8: D | C8: =D7 -> 0.4 | D8: 1.3 | F8: X | K8: X | M8: X | P8: X | R8: X
A9: 226ETO0201 | B9: D | C9: =D8 -> 1.3 | D9: 2.15 | F9: X | K9: X | M9: X | Q9: X | T9: X
A32: LEGENDA | B32: CONDIÇÃO DO PAVIMENTO
A33: REM. I | B33: REMENDOS ISOLADOS | E33: ATÉ 10 REMENDOS/KM | I33: BUR. I | J33: BURACOS ISOLADOS | M33: ATÉ 5 BURACOS/KM
A34: REM. L | B34: REMENDOS AO LONGO | E34: MAIS DE 10 REMENDOS/KM | I34: BUR. L | J34: BURACOS AO LONGO | M34: MAIS DE 5 BURACOS/KM
E39: =IF(E7="X",($D$7-$C$7),"0") -> 0.4 | F39: =IF(F7="X",($D$7-$C$7),"0") -> 0 | G39: =IF(G7="X",($D$7-$C$7),"0") -> 0 | H39: =IF(H7="X",($D$7-$C$7),"0") -> 0 | I39: =IF(I7="X",($D$7-$C$7),"0") -> 0 | J39: =IF(J7="X",($D$7-$C$7),"0") -> 0 | K39: =IF(K7="X",($D$7-$C$7),"0") -> 0.4 | L39: =IF(L7="X",($D$7-$C$7),"0") -> 0 | ... T39: =IF(T7="X",($D$7-$C$7),"0") -> 0
E40: =IF(E8="X",($D$8-$C$8),"0") -> 0 | F40: =IF(F8="X",($D$8-$C$8),"0") -> 0.9 | G40: =IF(G8="X",($D$8-$C$8),"0") -> 0 | H40: =IF(H8="X",($D$8-$C$8),"0") -> 0 | I40: =IF(I8="X",($D$8-$C$8),"0") -> 0 | J40: =IF(J8="X",($D$8-$C$8),"0") -> 0 | K40: =IF(K8="X",($D$8-$C$8),"0") -> 0.9 | L40: =IF(L8="X",($D$8-$C$8),"0") -> 0 | ... T40: =IF(T8="X",($D$8-$C$8),"0") -> 0
E41: =IF(E9="X",($D$9-$C$9),"0") -> 0 | F41: =IF(F9="X",($D$9-$C$9),"0") -> 0.85 | G41: =IF(G9="X",($D$9-$C$9),"0") -> 0 | H41: =IF(H9="X",($D$9-$C$9),"0") -> 0 | I41: =IF(I9="X",($D$9-$C$9),"0") -> 0 | J41: =IF(J9="X",($D$9-$C$9),"0") -> 0 | K41: =IF(K9="X",($D$9-$C$9),"0") -> 0.85 | L41: =IF(L9="X",($D$9-$C$9),"0") -> 0 | ... T41: =IF(T9="X",($D$9-$C$9),"0") -> 0.85
E42: =IF(E10="X",($D$10-$C$10),"0") -> 0 | F42: =IF(F10="X",($D$10-$C$10),"0") -> 0 | G42: =IF(G10="X",($D$10-$C$10),"0") -> 0 | H42: =IF(H10="X",($D$10-$C$10),"0") -> 0 | I42: =IF(I10="X",($D$10-$C$10),"0") -> 0 | J42: =IF(J10="X",($D$10-$C$10),"0") -> 0 | K42: =IF(K10="X",($D$10-$C$10),"0") -> 0 | L42: =IF(L10="X",($D$10-$C$10),"0") -> 0 | ... T42: =IF(T10="X",($D$10-$C$10),"0") -> 0
E43: =IF(E11="X",($D$11-$C$11),"0") -> 0 | F43: =IF(F11="X",($D$11-$C$11),"0") -> 0 | G43: =IF(G11="X",($D$11-$C$11),"0") -> 0 | H43: =IF(H11="X",($D$11-$C$11),"0") -> 0 | I43: =IF(I11="X",($D$11-$C$11),"0") -> 0 | J43: =IF(J11="X",($D$11-$C$11),"0") -> 0 | K43: =IF(K11="X",($D$11-$C$11),"0") -> 0 | L43: =IF(L11="X",($D$11-$C$11),"0") -> 0 | ... T43: =IF(T11="X",($D$11-$C$11),"0") -> 0
E44: =IF(E12="X",($D$12-$C$12),"0") -> 0 | F44: =IF(F12="X",($D$12-$C$12),"0") -> 0 | G44: =IF(G12="X",($D$12-$C$12),"0") -> 0 | H44: =IF(H12="X",($D$12-$C$12),"0") -> 0 | I44: =IF(I12="X",($D$12-$C$12),"0") -> 0 | J44: =IF(J12="X",($D$12-$C$12),"0") -> 0 | K44: =IF(K12="X",($D$12-$C$12),"0") -> 0 | L44: =IF(L12="X",($D$12-$C$12),"0") -> 0 | ... T44: =IF(T12="X",($D$12-$C$12),"0") -> 0
E45: =IF(E13="X",($D$13-$C$13),"0") -> 0 | F45: =IF(F13="X",($D$13-$C$13),"0") -> 0 | G45: =IF(G13="X",($D$13-$C$13),"0") -> 0 | H45: =IF(H13="X",($D$13-$C$13),"0") -> 0 | I45: =IF(I13="X",($D$13-$C$13),"0") -> 0 | J45: =IF(J13="X",($D$13-$C$13),"0") -> 0 | K45: =IF(K13="X",($D$13-$C$13),"0") -> 0 | L45: =IF(L13="X",($D$13-$C$13),"0") -> 0 | ... T45: =IF(T13="X",($D$13-$C$13),"0") -> 0
E46: =IF(E14="X",($D$14-$C$14),"0") -> 0 | F46: =IF(F14="X",($D$14-$C$14),"0") -> 0 | G46: =IF(G14="X",($D$14-$C$14),"0") -> 0 | H46: =IF(H14="X",($D$14-$C$14),"0") -> 0 | I46: =IF(I14="X",($D$14-$C$14),"0") -> 0 | J46: =IF(J14="X",($D$14-$C$14),"0") -> 0 | K46: =IF(K14="X",($D$14-$C$14),"0") -> 0 | L46: =IF(L14="X",($D$14-$C$14),"0") -> 0 | ... T46: =IF(T14="X",($D$14-$C$14),"0") -> 0
E47: =IF(E15="X",($D$15-$C$15),"0") -> 0 | F47: =IF(F15="X",($D$15-$C$15),"0") -> 0 | G47: =IF(G15="X",($D$15-$C$15),"0") -> 0 | H47: =IF(H15="X",($D$15-$C$15),"0") -> 0 | I47: =IF(I15="X",($D$15-$C$15),"0") -> 0 | J47: =IF(J15="X",($D$15-$C$15),"0") -> 0 | K47: =IF(K15="X",($D$15-$C$15),"0") -> 0 | L47: =IF(L15="X",($D$15-$C$15),"0") -> 0 | ... T47: =IF(T15="X",($D$15-$C$15),"0") -> 0
E48: =IF(E16="X",($D$16-$C$16),"0") -> 0 | F48: =IF(F16="X",($D$16-$C$16),"0") -> 0 | G48: =IF(G16="X",($D$16-$C$16),"0") -> 0 | H48: =IF(H16="X",($D$16-$C$16),"0") -> 0 | I48: =IF(I16="X",($D$16-$C$16),"0") -> 0 | J48: =IF(J16="X",($D$16-$C$16),"0") -> 0 | K48: =IF(K16="X",($D$16-$C$16),"0") -> 0 | L48: =IF(L16="X",($D$16-$C$16),"0") -> 0 | ... T48: =IF(T16="X",($D$16-$C$16),"0") -> 0
E49: =IF(E17="X",($D$17-$C$17),"0") -> 0 | F49: =IF(F17="X",($D$17-$C$17),"0") -> 0 | G49: =IF(G17="X",($D$17-$C$17),"0") -> 0 | H49: =IF(H17="X",($D$17-$C$17),"0") -> 0 | I49: =IF(I17="X",($D$17-$C$17),"0") -> 0 | J49: =IF(J17="X",($D$17-$C$17),"0") -> 0 | K49: =IF(K17="X",($D$17-$C$17),"0") -> 0 | L49: =IF(L17="X",($D$17-$C$17),"0") -> 0 | ... T49: =IF(T17="X",($D$17-$C$17),"0") -> 0
E50: =IF(E18="X",($D$18-$C$18),"0") -> 0 | F50: =IF(F18="X",($D$18-$C$18),"0") -> 0 | G50: =IF(G18="X",($D$18-$C$18),"0") -> 0 | H50: =IF(H18="X",($D$18-$C$18),"0") -> 0 | I50: =IF(I18="X",($D$18-$C$18),"0") -> 0 | J50: =IF(J18="X",($D$18-$C$18),"0") -> 0 | K50: =IF(K18="X",($D$18-$C$18),"0") -> 0 | L50: =IF(L18="X",($D$18-$C$18),"0") -> 0 | ... T50: =IF(T18="X",($D$18-$C$18),"0") -> 0
E51: =IF(E19="X",($D$19-$C$19),"0") -> 0 | F51: =IF(F19="X",($D$19-$C$19),"0") -> 0 | G51: =IF(G19="X",($D$19-$C$19),"0") -> 0 | H51: =IF(H19="X",($D$19-$C$19),"0") -> 0 | I51: =IF(I19="X",($D$19-$C$19),"0") -> 0 | J51: =IF(J19="X",($D$19-$C$19),"0") -> 0 | K51: =IF(K19="X",($D$19-$C$19),"0") -> 0 | L51: =IF(L19="X",($D$19-$C$19),"0") -> 0 | ... T51: =IF(T19="X",($D$19-$C$19),"0") -> 0
E52: =IF(E20="X",($D$20-$C$20),"0") -> 0 | F52: =IF(F20="X",($D$20-$C$20),"0") -> 0 | G52: =IF(G20="X",($D$20-$C$20),"0") -> 0 | H52: =IF(H20="X",($D$20-$C$20),"0") -> 0 | I52: =IF(I20="X",($D$20-$C$20),"0") -> 0 | J52: =IF(J20="X",($D$20-$C$20),"0") -> 0 | K52: =IF(K20="X",($D$20-$C$20),"0") -> 0 | L52: =IF(L20="X",($D$20-$C$20),"0") -> 0 | ... T52: =IF(T20="X",($D$20-$C$20),"0") -> 0
E53: =IF(E21="X",($D$21-$C$21),"0") -> 0 | F53: =IF(F21="X",($D$21-$C$21),"0") -> 0 | G53: =IF(G21="X",($D$21-$C$21),"0") -> 0 | H53: =IF(H21="X",($D$21-$C$21),"0") -> 0 | I53: =IF(I21="X",($D$21-$C$21),"0") -> 0 | J53: =IF(J21="X",($D$21-$C$21),"0") -> 0 | K53: =IF(K21="X",($D$21-$C$21),"0") -> 0 | L53: =IF(L21="X",($D$21-$C$21),"0") -> 0 | ... T53: =IF(T21="X",($D$21-$C$21),"0") -> 0
E54: =IF(E22="X",($D$22-$C$22),"0") -> 0 | F54: =IF(F22="X",($D$22-$C$22),"0") -> 0 | G54: =IF(G22="X",($D$22-$C$22),"0") -> 0 | H54: =IF(H22="X",($D$22-$C$22),"0") -> 0 | I54: =IF(I22="X",($D$22-$C$22),"0") -> 0 | J54: =IF(J22="X",($D$22-$C$22),"0") -> 0 | K54: =IF(K22="X",($D$22-$C$22),"0") -> 0 | L54: =IF(L22="X",($D$22-$C$22),"0") -> 0 | ... T54: =IF(T22="X",($D$22-$C$22),"0") -> 0
E55: =IF(E23="X",($D$23-$C$23),"0") -> 0 | F55: =IF(F23="X",($D$23-$C$23),"0") -> 0 | G55: =IF(G23="X",($D$23-$C$23),"0") -> 0 | H55: =IF(H23="X",($D$23-$C$23),"0") -> 0 | I55: =IF(I23="X",($D$23-$C$23),"0") -> 0 | J55: =IF(J23="X",($D$23-$C$23),"0") -> 0 | K55: =IF(K23="X",($D$23-$C$23),"0") -> 0 | L55: =IF(L23="X",($D$23-$C$23),"0") -> 0 | ... T55: =IF(T23="X",($D$23-$C$23),"0") -> 0
E56: =IF(E24="X",($D$24-$C$24),"0") -> 0 | F56: =IF(F24="X",($D$24-$C$24),"0") -> 0 | G56: =IF(G24="X",($D$24-$C$24),"0") -> 0 | H56: =IF(H24="X",($D$24-$C$24),"0") -> 0 | I56: =IF(I24="X",($D$24-$C$24),"0") -> 0 | J56: =IF(J24="X",($D$24-$C$24),"0") -> 0 | K56: =IF(K24="X",($D$24-$C$24),"0") -> 0 | L56: =IF(L24="X",($D$24-$C$24),"0") -> 0 | ... T56: =IF(T24="X",($D$24-$C$24),"0") -> 0
E57: =IF(E25="X",($D$25-$C$25),"0") -> 0 | F57: =IF(F25="X",($D$25-$C$25),"0") -> 0 | G57: =IF(G25="X",($D$25-$C$25),"0") -> 0 | H57: =IF(H25="X",($D$25-$C$25),"0") -> 0 | I57: =IF(I25="X",($D$25-$C$25),"0") -> 0 | J57: =IF(J25="X",($D$25-$C$25),"0") -> 0 | K57: =IF(K25="X",($D$25-$C$25),"0") -> 0 | L57: =IF(L25="X",($D$25-$C$25),"0") -> 0 | ... T57: =IF(T25="X",($D$25-$C$25),"0") -> 0
E58: =IF(E26="X",($D$26-$C$26),"0") -> 0 | F58: =IF(F26="X",($D$26-$C$26),"0") -> 0 | G58: =IF(G26="X",($D$26-$C$26),"0") -> 0 | H58: =IF(H26="X",($D$26-$C$26),"0") -> 0 | I58: =IF(I26="X",($D$26-$C$26),"0") -> 0 | J58: =IF(J26="X",($D$26-$C$26),"0") -> 0 | K58: =IF(K26="X",($D$26-$C$26),"0") -> 0 | L58: =IF(L26="X",($D$26-$C$26),"0") -> 0 | ... T58: =IF(T26="X",($D$26-$C$26),"0") -> 0
E59: =IF(E27="X",($D$27-$C$27),"0") -> 0 | F59: =IF(F27="X",($D$27-$C$27),"0") -> 0 | G59: =IF(G27="X",($D$27-$C$27),"0") -> 0 | H59: =IF(H27="X",($D$27-$C$27),"0") -> 0 | I59: =IF(I27="X",($D$27-$C$27),"0") -> 0 | J59: =IF(J27="X",($D$27-$C$27),"0") -> 0 | K59: =IF(K27="X",($D$27-$C$27),"0") -> 0 | L59: =IF(L27="X",($D$27-$C$27),"0") -> 0 | ... T59: =IF(T27="X",($D$27-$C$27),"0") -> 0
E60: =IF(E28="X",($D$28-$C$28),"0") -> 0 | F60: =IF(F28="X",($D$28-$C$28),"0") -> 0 | G60: =IF(G28="X",($D$28-$C$28),"0") -> 0 | H60: =IF(H28="X",($D$28-$C$28),"0") -> 0 | I60: =IF(I28="X",($D$28-$C$28),"0") -> 0 | J60: =IF(J28="X",($D$28-$C$28),"0") -> 0 | K60: =IF(K28="X",($D$28-$C$28),"0") -> 0 | L60: =IF(L28="X",($D$28-$C$28),"0") -> 0 | ... T60: =IF(T28="X",($D$28-$C$28),"0") -> 0
E61: =IF(E29="X",($D$29-$C$29),"0") -> 0 | F61: =IF(F29="X",($D$29-$C$29),"0") -> 0 | G61: =IF(G29="X",($D$29-$C$29),"0") -> 0 | H61: =IF(H29="X",($D$29-$C$29),"0") -> 0 | I61: =IF(I29="X",($D$29-$C$29),"0") -> 0 | J61: =IF(J29="X",($D$29-$C$29),"0") -> 0 | K61: =IF(K29="X",($D$29-$C$29),"0") -> 0 | L61: =IF(L29="X",($D$29-$C$29),"0") -> 0 | ... T61: =IF(T29="X",($D$29-$C$29),"0") -> 0
E62: =IF(E30="X",($D$30-$C$30),"0") -> 0 | F62: =IF(F30="X",($D$30-$C$30),"0") -> 0 | G62: =IF(G30="X",($D$30-$C$30),"0") -> 0 | H62: =IF(H30="X",($D$30-$C$30),"0") -> 0 | I62: =IF(I30="X",($D$30-$C$30),"0") -> 0 | J62: =IF(J30="X",($D$30-$C$30),"0") -> 0 | K62: =IF(K30="X",($D$30-$C$30),"0") -> 0 | L62: =IF(L30="X",($D$30-$C$30),"0") -> 0 | ... T62: =IF(T30="X",($D$30-$C$30),"0") -> 0
E127: =SUM(E39:E126) -> 0.4 | F127: =SUM(F39:F126) -> 1.75 | G127: =SUM(G39:G126) -> 0 | H127: =SUM(H39:H126) -> 0 | I127: =SUM(I39:I126) -> 0 | J127: =SUM(J39:J126) -> 0 | K127: =SUM(K39:K126) -> 2.15 | L127: =SUM(L39:L126) -> 0 | ... T127: =SUM(T39:T126) -> 0.85

Sheet 77
A1: PROGRAMA DE MANUTENÇÃORODOVIÁRIA
D2: RODOVIAS PAVIMENTADAS | I2: DATA: | J2: ='68'!$J$2 -> 46204 | N2: TÉCNICO RESP. | O2: ='68'!$O$2 -> ENG. VINÍCIUS RODRIGUES FERREIRA DE OLIVEIRA
A3: FICHA DE INSPEÇÃO: | B3: =TT!C10 -> RODOVIA TO-226 - TRECHO GOIATINS - CAMPOS LINDOS - DIV TO-MA
A5: S.R.E. | B5: SENTIDO | C5: INÍCIO (KM) | D5: FIM (KM) | E5: CONDIÇÃO DO PAVIMENTO | J5: VEGETAÇÃO | L5: ELEM. DE DRENAGEM | O5: SIN. HOR. | R5: SIN. VERTICAL | U5: OBSERV.
E6: BOM | F6: REM. I. | G6: REM. L | H6: BUR. I | I6: BUR. L | J6: ADEQ. | K6: INADED. | L6: LIMPOS | M6: SUJOS | N6: DAN. | O6: BOM | P6: REG. | Q6: INEXIST. | R6: BOM | S6: POUCAS | T6: INEXIST.
A7: 226ETO0050 | B7: D | C7: 0 | D7: 1 | G7: X | I7: X | J7: X | M7: X | O7: X | T7: X
C8: =D7 -> 1 | D8: 2 | G8: X | H8: X | I8: X | J8: X | M8: X | O8: X | T8: X
C9: =D8 -> 2 | D9: 3 | H9: X | J9: X | M9: X | O9: X | T9: X
C10: =D9 -> 3 | D10: 4 | G10: X | I10: X | J10: X | M10: X | O10: X | T10: X
C11: =D10 -> 4 | D11: 5 | G11: X | I11: X | J11: X | M11: X | O11: X | T11: X
C12: =D11 -> 5 | D12: 6 | E12: X | J12: X | M12: X | O12: X | T12: X
C13: =D12 -> 6 | D13: 7 | G13: X | I13: X | J13: X | O13: X | T13: X
C14: =D13 -> 7 | D14: 8 | G14: X | I14: X | J14: X | O14: X | T14: X
C15: =D14 -> 8 | D15: 9 | G15: X | I15: X | J15: X | O15: X | T15: X
C16: =D15 -> 9 | D16: 10 | E16: X | J16: X | O16: X | T16: X
C17: =D16 -> 10 | D17: 11 | E17: X | J17: X | O17: X | T17: X
C18: =D17 -> 11 | D18: 12 | E18: X | J18: X | M18: X | O18: X | T18: X
C19: =D18 -> 12 | D19: 13 | E19: X | J19: X | M19: X | O19: X | T19: X
C20: =D19 -> 13 | D20: 14 | F20: X | J20: X | M20: X | O20: X | T20: X
C21: =D20 -> 14 | D21: 15 | E21: X | J21: X | M21: X | O21: X | T21: X
C22: =D21 -> 15 | D22: 16 | E22: X | J22: X | O22: X | T22: X
C23: =D22 -> 16 | D23: 17 | E23: X | J23: X | O23: X | T23: X
C24: =D23 -> 17 | D24: 18 | G24: X | H24: X | I24: X | J24: X | O24: X | T24: X
C25: =D24 -> 18 | D25: 19 | E25: X | J25: X | O25: X | T25: X
C26: =D25 -> 19 | D26: 20 | G26: X | H26: X | I26: X | J26: X | O26: X | T26: X
C27: =D26 -> 20 | D27: 21 | E27: X | J27: X | O27: X | T27: X
C28: =D27 -> 21 | D28: 22 | E28: X | J28: X | O28: X | T28: X
C29: =D28 -> 22 | D29: 23 | E29: X | J29: X | O29: X | T29: X
C30: =D29 -> 23 | D30: 24.57 | E30: X | J30: X | O30: X | T30: X
A31: 226ETO0040 | B31: D | C31: 0 | D31: 1 | E31: X | J31: X | O31: X | S31: X
C32: =D31 -> 1 | D32: 2 | E32: X | J32: X | O32: X | S32: X
C33: =D32 -> 2 | D33: 3 | E33: X | J33: X | O33: X | S33: X
C34: =D33 -> 3 | D34: 4 | E34: X | J34: X | O34: X | S34: X
C35: =D34 -> 4 | D35: 5 | E35: X | J35: X | O35: X | T35: X
C36: =D35 -> 5 | D36: 6 | E36: X | J36: X | O36: X | T36: X
C37: =D36 -> 6 | D37: 7 | E37: X | J37: X | O37: X | T37: X
C38: =D37 -> 7 | D38: 8 | E38: X | J38: X | O38: X | T38: X
C39: =D38 -> 8 | D39: 9 | E39: X | J39: X | M39: X | O39: X | T39: X
C40: =D39 -> 9 | D40: 10 | E40: X | J40: X | M40: X | O40: X | T40: X
C41: =D40 -> 10 | D41: 11 | E41: X | J41: X | O41: X | T41: X
...

Sheet 78
A1: PROGRAMA DE MANUTENÇÃORODOVIÁRIA
D2: RODOVIAS PAVIMENTADAS | I2: DATA: | J2: ='68'!$J$2 -> 46204 | N2: TÉCNICO RESP. | O2: ='68'!$O$2 -> ENG. VINÍCIUS RODRIGUES FERREIRA DE OLIVEIRA
A3: FICHA DE INSPEÇÃO: | B3: =TT!C11 -> RODOVIA TO-422 - TRECHO ENTR. BR-153 - TRECHO DISTRITO AGROINDUSTRIAL DE ARAGUAÍNA
A5: S.R.E. | B5: SENTIDO | C5: INÍCIO (KM) | D5: FIM (KM) | E5: CONDIÇÃO DO PAVIMENTO | J5: VEGETAÇÃO | L5: ELEM. DE DRENAGEM | O5: SIN. HOR. | R5: SIN. VERTICAL | U5: OBSERV.
E6: BOM | F6: REM. I. | G6: REM. L | H6: BUR. I | I6: BUR. L | J6: ADEQ. | K6: INADED. | L6: LIMPOS | M6: SUJOS | N6: DAN. | O6: BOM | P6: REG. | Q6: INEXIST. | R6: BOM | S6: POUCAS | T6: INEXIST.
A7: 422ETO0010 | B7: D | C7: 0 | D7: 7.78 | E7: X | K7: X | M7: X | P7: X | R7: X
A32: LEGENDA | B32: CONDIÇÃO DO PAVIMENTO
A33: REM. I | B33: REMENDOS ISOLADOS | E33: ATÉ 10 REMENDOS/KM | I33: BUR. I | J33: BURACOS ISOLADOS | M33: ATÉ 5 BURACOS/KM
A34: REM. L | B34: REMENDOS AO LONGO | E34: MAIS DE 10 REMENDOS/KM | I34: BUR. L | J34: BURACOS AO LONGO | M34: MAIS DE 5 BURACOS/KM
E39: =IF(E7="X",($D$7-$C$7),"0") -> 7.78 | F39: =IF(F7="X",($D$7-$C$7),"0") -> 0 | G39: =IF(G7="X",($D$7-$C$7),"0") -> 0 | H39: =IF(H7="X",($D$7-$C$7),"0") -> 0 | I39: =IF(I7="X",($D$7-$C$7),"0") -> 0 | J39: =IF(J7="X",($D$7-$C$7),"0") -> 0 | K39: =IF(K7="X",($D$7-$C$7),"0") -> 7.78 | L39: =IF(L7="X",($D$7-$C$7),"0") -> 0 | ... T39: =IF(T7="X",($D$7-$C$7),"0") -> 0
