Workbook

Sheet Trechos
A1: RELAÇÃO DOS TRECHOS DAS REGIÕES DE MANUTENÇÃO
A2: LOTE | B2: REGIÃO DE CONSERVAÇÃO | C2: CIDADE SEDE | D2: N° | E2: TRECHO | F2: S.R.E | G2: SUBTRECHOS | H2: EXT. (KM) | I2: TIPO | J2: 45839 | K2: 45870 | L2: 45901 | M2: 45931 | N2: 45962 | O2: 45992
A3: 1 | B3: 1 | C3: TOCANTINÓPOLIS | D3: 1 | E3: RODOVIA TO-010 - TRECHO ANANÁS - ENTR. BR-230 | F3: 010ETO0511 | G3: ANANÁS *TRECHO URBANO* | H3: 0.87749259 | I3: PSU
A4: 1 | B4: 1 | C4: TOCANTINÓPOLIS | D4: 1 | E4: RODOVIA TO-010 - TRECHO ANANÁS - ENTR. BR-230 | F4: 010ETO0512 | G4: ANANÁS *TRECHO URBANO* | H4: 1.9892583 | I4: PSU
A5: 1 | B5: 1 | C5: TOCANTINÓPOLIS | D5: 1 | E5: RODOVIA TO-010 - TRECHO ANANÁS - ENTR. BR-230 | F5: 010ETO0540 | G5: ANANÁS *TRECHO URBANO* - ENTR. TO-414(TAPUIO) | H5: 3.8103285 | I5: PPS
A6: 1 | B6: 1 | C6: TOCANTINÓPOLIS | D6: 1 | E6: RODOVIA TO-010 - TRECHO ANANÁS - ENTR. BR-230 | F6: 010ETO0550 | G6: ENTR. TO-414 (TAPUIO) - ENTR. TO-210 | H6: 1.6653951 | I6: PPS
A7: 1 | B7: 1 | C7: TOCANTINÓPOLIS | D7: 1 | E7: RODOVIA TO-010 - TRECHO ANANÁS - ENTR. BR-230 | F7: 010ETO0555 | G7: ENTR. TO-210 - FIM PAVIMENTACAO | H7: 1.3552325 | I7: PPS
A8: 1 | B8: 1 | C8: TOCANTINÓPOLIS | D8: 1 | E8: RODOVIA TO-010 - TRECHO ANANÁS - ENTR. BR-230 | F8: 010ETO0560 | G8: FIM PAVIMENTACAO - ENTR. TO-205 | H8: 32.187522 | I8: EOP | J8: X | K8: X
A9: 1 | B9: 1 | C9: TOCANTINÓPOLIS | D9: 1 | E9: RODOVIA TO-010 - TRECHO ANANÁS - ENTR. BR-230 | F9: 010ETO0570 | G9: ENTR. TO-205 - RONCA | H9: 5.3799354 | I9: EOP | J9: X | K9: X
A10: 1 | B10: 1 | C10: TOCANTINÓPOLIS | D10: 1 | E10: RODOVIA TO-010 - TRECHO ANANÁS - ENTR. BR-230 | F10: 010ETO0580 | G10: RONCA - NATAL | H10: 16.209854 | I10: EOP | J10: X | K10: X
A11: 1 | B11: 1 | C11: TOCANTINÓPOLIS | D11: 1 | E11: RODOVIA TO-010 - TRECHO ANANÁS - ENTR. BR-230 | F11: 010ETO0590 | G11: NATAL - ESPERANCA VIVA | H11: 1.3456448 | I11: EOP | J11: X | K11: X
A12: 1 | B12: 1 | C12: TOCANTINÓPOLIS | D12: 1 | E12: RODOVIA TO-010 - TRECHO ANANÁS - ENTR. BR-230 | F12: 010ETO0600 | G12: ESPERANCA VIVA - VILA NOVA | H12: 7.2939257 | I12: EOP | J12: X | K12: X
A13: 1 | B13: 1 | C13: TOCANTINÓPOLIS | D13: 1 | E13: RODOVIA TO-010 - TRECHO ANANÁS - ENTR. BR-230 | F13: 010ETO0610 | G13: VILA NOVA - TAQUARI | H13: 3.8572587 | I13: EOP | J13: X | K13: X
A14: 1 | B14: 1 | C14: TOCANTINÓPOLIS | D14: 1 | E14: RODOVIA TO-010 - TRECHO ANANÁS - ENTR. BR-230 | F14: 010ETO0620 | G14: TAQUARI - ENTR. BR-230 | H14: 9.3575815 | I14: EOP | J14: X | K14: X
A15: 1 | B15: 1 | C15: TOCANTINÓPOLIS | D15: 2 | E15: RODOVIA TO-010 - TRECHO ENTR. BR-230 - ARAGUATINS | F15: 010ETO0630 | G15: ENTR. BR-230 - TRANSARAGUAIA | H15: 1.0305988 | I15: PPS
A16: 1 | B16: 1 | C16: TOCANTINÓPOLIS | D16: 2 | E16: RODOVIA TO-010 - TRECHO ENTR. BR-230 - ARAGUATINS | F16: 010ETO0640 | G16: TRANSARAGUAIA (BR-230) - ARAGUATINS | H16: 8.6075719 | I16: PPS
A17: 1 | B17: 1 | C17: TOCANTINÓPOLIS | D17: 3 | E17: RODOVIA TO-010 - TRECHO ARAGUATINS - ENTR. TO-201 | F17: 010ETO0650 | G17: ARAGUATINS - ENTR. TO-404 | H17: 7.7551854 | I17: PPS
A18: 1 | B18: 1 | C18: TOCANTINÓPOLIS | D18: 3 | E18: RODOVIA TO-010 - TRECHO ARAGUATINS - ENTR. TO-201 | F18: 010ETO0665 | G18: ENTR. TO-404 - POV. CANAÃ | H18: 28.047221 | I18: PPS
A19: 1 | B19: 1 | C19: TOCANTINÓPOLIS | D19: 3 | E19: RODOVIA TO-010 - TRECHO ARAGUATINS - ENTR. TO-201 | F19: 010ETO0670 | G19: CANAÃ - VILA UNIÃO | H19: 2.8623319 | I19: PPS
A20: 1 | B20: 1 | C20: TOCANTINÓPOLIS | D20: 3 | E20: RODOVIA TO-010 - TRECHO ARAGUATINS - ENTR. TO-201 | F20: 010ETO0680 | G20: VILA UNIÃO - ENTR. TO-201 | H20: 2.9422716 | I20: PPS
A21: 1 | B21: 1 | C21: TOCANTINÓPOLIS | D21: 4 | E21: RODOVIA TO-010 - TRECHO BURITI DO TOCANTINS (ENTR. TO-201) - SÃO SEBASTIÃO DO TOCANTINS | F21: 010ETO0690 | G21: ENTR. TO-201 - BURITI DO TOCANTINS *TRECHO URBANO* | H21: 3.6607758 | I21: PPS
A22: 1 | B22: 1 | C22: TOCANTINÓPOLIS | D22: 4 | E22: RODOVIA TO-010 - TRECHO BURITI DO TOCANTINS (ENTR. TO-201) - SÃO SEBASTIÃO DO TOCANTINS | F22: 010ETO0710 | G22: BURITI DO TOCANTINS *TRECHO URBANO* - SÃO SEBASTIÃO DO TOCANTINS *TRECHO URBANO* | H22: 5.589158 | I22: PPS
A23: 1 | B23: 1 | C23: TOCANTINÓPOLIS | D23: 5 | E23: RODOVIA TO-126 - TRECHO TOCANTINÓPOLIS - ENTR. BR-230 (AGUIARNÓPOLIS) | F23: 126ETO0151 | G23: PERÍMETRO URBANO TOCANTINOPOLIS | H23: 1.8623358 | I23: PDU
A24: 1 | B24: 1 | C24: TOCANTINÓPOLIS | D24: 5 | E24: RODOVIA TO-126 - TRECHO TOCANTINÓPOLIS - ENTR. BR-230 (AGUIARNÓPOLIS) | F24: 126ETO0190 | G24: TOCANTINÓPOLIS *TRECHO URBANO* - ENTR. ACESSO TRIPA NORTE | H24: 22.489852 | I24: PPS
A25: 1 | B25: 1 | C25: TOCANTINÓPOLIS | D25: 5 | E25: RODOVIA TO-126 - TRECHO TOCANTINÓPOLIS - ENTR. BR-230 (AGUIARNÓPOLIS) | F25: 126ETO0200 | G25: ENTR. ACESSO TRIPA NORTE - ENTR. BR-230 | H25: 3.2344796 | I25: PPS
A26: 1 | B26: 1 | C26: TOCANTINÓPOLIS | D26: 5 | E26: RODOVIA TO-126 - TRECHO TOCANTINÓPOLIS - ENTR. BR-230 (AGUIARNÓPOLIS) | F26: ACESSO | G26: ENTR.TO-126 - ASA NORTE | H26: 2.6525119 | I26: PPS
A27: 1 | B27: 1 | C27: TOCANTINÓPOLIS | D27: 6 | E27: RODOVIA TO-126 - TRECHO MAURILÂNDIA - TOCANTINÓPOLIS | F27: 126ETO0130 | G27: MAURILÃNDIA DO TOCANTINS *TRECHO URBANO* - RIBEIRÃO GRANDE | H27: 35.479669 | I27: LEN | J27: X
A28: 1 | B28: 1 | C28: TOCANTINÓPOLIS | D28: 6 | E28: RODOVIA TO-126 - TRECHO MAURILÂNDIA - TOCANTINÓPOLIS | F28: 126ETO0140 | G28: RIBEIRÃO GRANDE - FOLHA GROSSA | H28: 5.5291153 | I28: PPS
A29: 1 | B29: 1 | C29: TOCANTINÓPOLIS | D29: 6 | E29: RODOVIA TO-126 - TRECHO MAURILÂNDIA - TOCANTINÓPOLIS | F29: 126ETO0150 | G29: FOLHA GROSSA - TOCANTINÓPOLIS *TRECHO URBANO* | H29: 2.9848124 | I29: PPS
A30: 1 | B30: 1 | C30: TOCANTINÓPOLIS | D30: 7 | E30: RODOVIA TO-126 - TRECHO ITAGUATINS - MAURILÂNDIA DO TOCANTINS | F30: 126ETO0101 | G30: PERÍMETRO URBANO ITAGUATINS | H30: 0.74066591 | I30: PSU
A31: 1 | B31: 1 | C31: TOCANTINÓPOLIS | D31: 7 | E31: RODOVIA TO-126 - TRECHO ITAGUATINS - MAURILÂNDIA DO TOCANTINS | F31: 126ETO0120 | G31: ITAGUATINS *TRECHO URBANO* - MAURILÃNDIA DO TOCANTINS *TRECHO URBANO* | H31: 20.919422 | I31: PPS
A32: 1 | B32: 1 | C32: TOCANTINÓPOLIS | D32: 8 | E32: RODOVIA TO-126 - TRECHO SÍTIO NOVO DO TOCANTINS - ITAGUATINS | F32: 126ETO0090 | G32: ENTR. TO-201(B)(SÍTIO NOVO DO TOCANTINS) - CASTANHEIRO | H32: 11.35543 | I32: PPS
A33: 1 | B33: 1 | C33: TOCANTINÓPOLIS | D33: 8 | E33: RODOVIA TO-126 - TRECHO SÍTIO NOVO DO TOCANTINS - ITAGUATINS | F33: 126ETO0100 | G33: CASTANHEIRO - ITAGUATINS *TRECHO URBANO* | H33: 14.021183 | I33: PPS
A34: 1 | B34: 1 | C34: TOCANTINÓPOLIS | D34: 9 | E34: RODOVIA TO-126 - TRECHO SUMAUMA - SÍTIO NOVO DO TOCANTINS | F34: 126ETO0050 | G34: SUMAUMA *TRECHO URBANO* - SÃO PEDRO | H34: 7.917381 | I34: PPS
A35: 1 | B35: 1 | C35: TOCANTINÓPOLIS | D35: 9 | E35: RODOVIA TO-126 - TRECHO SUMAUMA - SÍTIO NOVO DO TOCANTINS | F35: 126ETO0060 | G35: SÃO PEDRO - ENTR. TO-201 | H35: 6.5761498 | I35: PPS
A36: 1 | B36: 1 | C36: TOCANTINÓPOLIS | D36: 9 | E36: RODOVIA TO-126 - TRECHO SUMAUMA - SÍTIO NOVO DO TOCANTINS | F36: 126ETO0080 | G36: ENTR. TO-201(A) - ENTR. TO-201(B)(SÍTIO NOVO DO TOCANTINS) | H36: 2.1814371 | I36: PPS
A37: 1 | B37: 1 | C37: TOCANTINÓPOLIS | D37: 10 | E37: RODOVIA TO-134 - TRECHO ANGICO - DARCINÓPOLIS | F37: 134ETO0220 | G37: ENTR. TO-210 (ANGICO) - AMIGOS DA TERRA | H37: 31.59718 | I37: PPS
A38: 1 | B38: 1 | C38: TOCANTINÓPOLIS | D38: 10 | E38: RODOVIA TO-134 - TRECHO ANGICO - DARCINÓPOLIS | F38: 134ETO0230 | G38: AMIGOS DA TERRA - ENTR. BR-226(DARCINÓPOLIS) | H38: 13.750622 | I38: PPS
A39: 1 | B39: 1 | C39: TOCANTINÓPOLIS | D39: 11 | E39: RODOVIA TO-134 - TRECHO LUZINÓPOLIS - ANGICO | F39: 134ETO0180 | G39: ENTR. BR-230(LUZINÓPOLIS) - SANTA HELENA | H39: 9.8047447 | I39: PPS
... A42: 1 | B42: 1 | C42: TOCANTINÓPOLIS | D42: 11 | E42: RODOVIA TO-134 - TRECHO LUZINÓPOLIS - ANGICO | F42: 134ETO0210 | G42: ENTR. TO-210 (GROTÃO DE NAZARE) - ENTR. TO-210 (ANGICO) | H42: 7.4162558 | I42: PPS
...

Sheet 1
A1: PROGRAMA DE MANUTENÇÃORODOVIÁRIA | I1: DATA: | J1: 46204 | L1: TÉCNICO RESP. | N1: ENG. VINÍCIUS RODRIGUES FERREIRA DE OLIVEIRA
F2: RODOVIAS NÃO PAVIMENTADAS
A3: FICHA DE INSPEÇÃO: | B3: =TT!C4 -> RODOVIA TO-010 - TRECHO ANANÁS - ENTR. BR-230
A5: S.R.E. | B5: SENTIDO | C5: INÍCIO (KM) | D5: FIM (KM) | E5: CONDIÇÃO DA PLATAFORMA | I5: DRENAGEM SUPERFICIAL | L5: OBSERV.
E6: BOM | F6: REG. (ATÉ 10 IRR./KM) | G6: RUÍM (+ 10 IRR./KM) | H6: PÉSSIMA (ATOLEIRO/PTO. CRÍTICO) | I6: LIMPA | J6: OBSTRUÍDA | K6: AUSENTE
A7: 010ETO0560 | B7: C | C7: 0 | D7: 1 | F7: X | K7: X
C8: =D7 -> 1 | D8: 2 | F8: X | K8: X
C9: =D8 -> 2 | D9: 3 | F9: X | K9: X
C10: =D9 -> 3 | D10: 4 | F10: X | K10: X
C11: =D10 -> 4 | D11: 5 | F11: X | K11: X
C12: =D11 -> 5 | D12: 6 | F12: X | K12: X
C13: =D12 -> 6 | D13: 7 | F13: X | I13: X
C14: =D13 -> 7 | D14: 8 | F14: X | I14: X
C15: =D14 -> 8 | D15: 9 | F15: X | I15: X
C16: =D15 -> 9 | D16: 10 | F16: X | I16: X
C17: =D16 -> 10 | D17: 11 | F17: X | I17: X
C18: =D17 -> 11 | D18: 12 | F18: X | I18: X
C19: =D18 -> 12 | D19: 13 | F19: X | I19: X
C20: =D19 -> 13 | D20: 14 | F20: X | I20: X
C21: =D20 -> 14 | D21: 15 | F21: X | I21: X
C22: =D21 -> 15 | D22: 16 | F22: X | I22: X
C23: =D22 -> 16 | D23: 17 | F23: X | I23: X
C24: =D23 -> 17 | D24: 18 | F24: X | I24: X
... C38: =D37 -> 31 | D38: 32.19 | F38: X | I38: X
A39: 010ETO0570 | B39: C | C39: 0 | D39: 1 | E39: X | I39: X
C40: =D39 -> 1 | D40: 2 | E40: X | I40: X
C41: =D40 -> 2 | D41: 3 | E41: X | I41: X
C42: =D41 -> 3 | D42: 4 | E42: X | I42: X
C43: =D42 -> 4 | D43: 5 | E43: X | I43: X
C44: =D43 -> 5 | D44: 5.38 | E44: X | I44: X
A45: 010ETO0580 | B45: C | C45: 0 | D45: 1 | F45: X | I45: X
C46: =D45 -> 1 | D46: 2 | F46: X | I46: X
C47: =D46 -> 2 | D47: 3 | F47: X | I47: X
C48: =D47 -> 3 | D48: 4 | F48: X | I48: X
C49: =D48 -> 4 | D49: 5 | F49: X | I49: X
C50: =D49 -> 5 | D50: 6 | F50: X | I50: X
C51: =D50 -> 6 | D51: 7 | F51: X | I51: X
C52: =D51 -> 7 | D52: 8 | F52: X | I52: X
C53: =D52 -> 8 | D53: 9 | F53: X | I53: X
C54: =D53 -> 9 | D54: 10 | F54: X | I54: X
...

Sheet 6
A1: PROGRAMA DE MANUTENÇÃORODOVIÁRIA | I1: DATA: | J1: ='1'!J1 -> 46204 | L1: TÉCNICO RESP. | N1: ='1'!N1 -> ENG. VINÍCIUS RODRIGUES FERREIRA DE OLIVEIRA
F2: RODOVIAS NÃO PAVIMENTADAS
A3: FICHA DE INSPEÇÃO: | B3: =TT!C5 -> RODOVIA TO-126 - TRECHO MAURILÂNDIA - TOCANTINÓPOLIS
A5: S.R.E. | B5: SENTIDO | C5: INÍCIO (KM) | D5: FIM (KM) | E5: CONDIÇÃO DA PLATAFORMA | I5: DRENAGEM SUPERFICIAL | L5: OBSERV.
E6: BOM | F6: REG. (ATÉ 10 IRR./KM) | G6: RUÍM (+ 10 IRR./KM) | H6: PÉSSIMA (ATOLEIRO/PTO. CRÍTICO) | I6: LIMPA | J6: OBSTRUÍDA | K6: AUSENTE
A7: 126ETO0130 | B7: C | C7: 0 | D7: 2 | F7: X | K7: X
C8: =D7 -> 2 | D8: 4 | F8: X | K8: X
C9: =D8 -> 4 | D9: 6 | F9: X | I9: X | L9: ALTO INDICE DE BURACOS E VALETAS
C10: =D9 -> 6 | D10: 8 | F10: X | I10: X | L10: ALTO INDICE DE BURACOS E VALETAS
C11: =D10 -> 8 | D11: 10 | E11: X | K11: X
C12: =D11 -> 10 | D12: 12 | E12: X | I12: X
C13: =D12 -> 12 | D13: 14 | E13: X | I13: X
C14: =D13 -> 14 | D14: 16 | E14: X | I14: X
C15: =D14 -> 16 | D15: 18 | E15: X | I15: X | L15: GREIDE REBAIXADO
C16: =D15 -> 18 | D16: 20 | E16: X | I16: X | L16: GREIDE REBAIXADO
C17: =D16 -> 20 | D17: 22 | E17: X | I17: X | L17: GREIDE REBAIXADO
C18: =D17 -> 22 | D18: 24 | E18: X | I18: X | L18: GREIDE REBAIXADO
C19: =D18 -> 24 | D19: 26 | E19: X | I19: X | L19: GREIDE REBAIXADO
C20: =D19 -> 26 | D20: 28 | E20: X | I20: X | L20: GREIDE REBAIXADO
C21: =D20 -> 28 | D21: 30 | E21: X | I21: X | L21: GREIDE REBAIXADO
C22: =D21 -> 30 | D22: 32 | F22: X | I22: X | L22: GREIDE REBAIXADO
C23: =D22 -> 32 | D23: =Trechos!H27 -> 35.479669 | F23: X | I23: X | L23: GREIDE REBAIXADO
E36: =IF(E7="X",(D7-C7),"0") -> 0 | F36: =IF(F7="X",(D7-C7),"0") -> 2 | G36: =IF(G7="X",(D7-C7),"0") -> 0 | H36: =IF(H7="X",(D7-C7),"0") -> 0 | I36: =IF(I7="X",(D7-C7),"0") -> 0 | J36: =IF(J7="X",(D7-C7),"0") -> 0 | K36: =IF(K7="X",(D7-C7),"0") -> 2
E37: =IF(E8="X",(D8-C8),"0") -> 0 | F37: =IF(F8="X",(D8-C8),"0") -> 2 | G37: =IF(G8="X",(D8-C8),"0") -> 0 | H37: =IF(H8="X",(D8-C8),"0") -> 0 | I37: =IF(I8="X",(D8-C8),"0") -> 0 | J37: =IF(J8="X",(D8-C8),"0") -> 0 | K37: =IF(K8="X",(D8-C8),"0") -> 2
E38: =IF(E9="X",(D9-C9),"0") -> 0 | F38: =IF(F9="X",(D9-C9),"0") -> 2 | G38: =IF(G9="X",(D9-C9),"0") -> 0 | H38: =IF(H9="X",(D9-C9),"0") -> 0 | I38: =IF(I9="X",(D9-C9),"0") -> 2 | J38: =IF(J9="X",(D9-C9),"0") -> 0 | K38: =IF(K9="X",(D9-C9),"0") -> 0
E39: =IF(E10="X",(D10-C10),"0") -> 0 | F39: =IF(F10="X",(D10-C10),"0") -> 2 | G39: =IF(G10="X",(D10-C10),"0") -> 0 | H39: =IF(H10="X",(D10-C10),"0") -> 0 | I39: =IF(I10="X",(D10-C10),"0") -> 2 | J39: =IF(J10="X",(D10-C10),"0") -> 0 | K39: =IF(K10="X",(D10-C10),"0") -> 0
E40: =IF(E11="X",(D11-C11),"0") -> 2 | F40: =IF(F11="X",(D11-C11),"0") -> 0 | G40: =IF(G11="X",(D11-C11),"0") -> 0 | H40: =IF(H11="X",(D11-C11),"0") -> 0 | I40: =IF(I11="X",(D11-C11),"0") -> 0 | J40: =IF(J11="X",(D11-C11),"0") -> 0 | K40: =IF(K11="X",(D11-C11),"0") -> 2
E41: =IF(E12="X",(D12-C12),"0") -> 2 | F41: =IF(F12="X",(D12-C12),"0") -> 0 | G41: =IF(G12="X",(D12-C12),"0") -> 0 | H41: =IF(H12="X",(D12-C12),"0") -> 0 | I41: =IF(I12="X",(D12-C12),"0") -> 2 | J41: =IF(J12="X",(D12-C12),"0") -> 0 | K41: =IF(K12="X",(D12-C12),"0") -> 0
E42: =IF(E13="X",(D13-C13),"0") -> 2 | F42: =IF(F13="X",(D13-C13),"0") -> 0 | G42: =IF(G13="X",(D13-C13),"0") -> 0 | H42: =IF(H13="X",(D13-C13),"0") -> 0 | I42: =IF(I13="X",(D13-C13),"0") -> 2 | J42: =IF(J13="X",(D13-C13),"0") -> 0 | K42: =IF(K13="X",(D13-C13),"0") -> 0
E43: =IF(E14="X",(D14-C14),"0") -> 2 | F43: =IF(F14="X",(D14-C14),"0") -> 0 | G43: =IF(G14="X",(D14-C14),"0") -> 0 | H43: =IF(H14="X",(D14-C14),"0") -> 0 | I43: =IF(I14="X",(D14-C14),"0") -> 2 | J43: =IF(J14="X",(D14-C14),"0") -> 0 | K43: =IF(K14="X",(D14-C14),"0") -> 0
E44: =IF(E15="X",(D15-C15),"0") -> 2 | F44: =IF(F15="X",(D15-C15),"0") -> 0 | G44: =IF(G15="X",(D15-C15),"0") -> 0 | H44: =IF(H15="X",(D15-C15),"0") -> 0 | I44: =IF(I15="X",(D15-C15),"0") -> 2 | J44: =IF(J15="X",(D15-C15),"0") -> 0 | K44: =IF(K15="X",(D15-C15),"0") -> 0
E45: =IF(E16="X",(D16-C16),"0") -> 2 | F45: =IF(F16="X",(D16-C16),"0") -> 0 | G45: =IF(G16="X",(D16-C16),"0") -> 0 | H45: =IF(H16="X",(D16-C16),"0") -> 0 | I45: =IF(I16="X",(D16-C16),"0") -> 2 | J45: =IF(J16="X",(D16-C16),"0") -> 0 | K45: =IF(K16="X",(D16-C16),"0") -> 0
E46: =IF(E17="X",(D17-C17),"0") -> 2 | F46: =IF(F17="X",(D17-C17),"0") -> 0 | G46: =IF(G17="X",(D17-C17),"0") -> 0 | H46: =IF(H17="X",(D17-C17),"0") -> 0 | I46: =IF(I17="X",(D17-C17),"0") -> 2 | J46: =IF(J17="X",(D17-C17),"0") -> 0 | K46: =IF(K17="X",(D17-C17),"0") -> 0
E47: =IF(E18="X",(D18-C18),"0") -> 2 | F47: =IF(F18="X",(D18-C18),"0") -> 0 | G47: =IF(G18="X",(D18-C18),"0") -> 0 | H47: =IF(H18="X",(D18-C18),"0") -> 0 | I47: =IF(I18="X",(D18-C18),"0") -> 2 | J47: =IF(J18="X",(D18-C18),"0") -> 0 | K47: =IF(K18="X",(D18-C18),"0") -> 0
... E61: =IF(E32="X",(D32-C32),"0") -> 0 | F61: =IF(F32="X",(D32-C32),"0") -> 0 | G61: =IF(G32="X",(D32-C32),"0") -> 0 | H61: =IF(H32="X",(D32-C32),"0") -> 0 | I61: =IF(I32="X",(D32-C32),"0") -> 0 | J61: =IF(J32="X",(D32-C32),"0") -> 0 | K61: =IF(K32="X",(D32-C32),"0") -> 0
E62: =SUM(E36:E61) -> 22 | F62: =SUM(F36:F61) -> 13.479669 | G62: =SUM(G36:G61) -> 0 | H62: =SUM(H36:H61) -> 0 | I62: =SUM(I36:I61) -> 29.479669 | J62: =SUM(J36:J61) -> 0 | K62: =SUM(K36:K61) -> 6

Sheet 12
A1: PROGRAMA DE MANUTENÇÃORODOVIÁRIA | I1: DATA: | J1: ='1'!J1 -> 46204 | L1: TÉCNICO RESP. | N1: ENG. VINICIUS RODRIGUES
F2: RODOVIAS NÃO PAVIMENTADAS
A3: FICHA DE INSPEÇÃO: | B3: =TT!C6 -> RODOVIA TO-134 - TRECHO RIO TOCANTINS (JATOBAL) - AXIXÁ DO TOCANTINS
A5: S.R.E. | B5: SENTIDO | C5: INÍCIO (KM) | D5: FIM (KM) | E5: CONDIÇÃO DA PLATAFORMA | I5: DRENAGEM SUPERFICIAL | L5: OBSERV.
E6: BOM | F6: REG. (ATÉ 10 IRR./KM) | G6: RUÍM (+ 10 IRR./KM) | H6: PÉSSIMA (ATOLEIRO/PTO. CRÍTICO) | I6: LIMPA | J6: OBSTRUÍDA | K6: AUSENTE
A7: 134ETO0070 | B7: D | C7: 0 | D7: 2 | G7: X | J7: X | L7: PISTA PATROLADA MAS COM IRREGULARIDADES E MAT. FINO SOBRE A PISTA
C8: =D7 -> 2 | D8: 4 | G8: X | J8: X | L8: PISTA PATROLADA MAS COM IRREGULARIDADES E MAT. FINO SOBRE A PISTA
C9: =D8 -> 4 | D9: 6 | G9: X | J9: X | L9: PISTA PATROLADA MAS COM IRREGULARIDADES E MAT. FINO SOBRE A PISTA
C10: =D9 -> 6 | D10: 8 | G10: X | J10: X | L10: PISTA PATROLADA MAS COM IRREGULARIDADES E MAT. FINO SOBRE A PISTA
C11: =D10 -> 8 | D11: 10 | G11: X | J11: X | L11: PISTA PATROLADA MAS COM IRREGULARIDADES E MAT. FINO SOBRE A PISTA
C12: =D11 -> 10 | D12: 12 | G12: X | J12: X
C13: =D12 -> 12 | D13: 14 | G13: X | J13: X | L13: KM 12,2 AO 14,2 - PAV. TSD (VILA FOLHA SECA)
C14: =D13 -> 14 | D14: 16 | G14: X | J14: X | L14: MATERIAL FINO SOBRE A PISTA
C15: =D14 -> 16 | D15: 18 | G15: X | J15: X | L15: MATERIAL FINO SOBRE A PISTA
C16: =D15 -> 18 | D16: 20 | G16: X | J16: X | L16: MATERIAL FINO SOBRE A PISTA
C17: =D16 -> 20 | D17: 22 | G17: X | J17: X | L17: MATERIAL FINO SOBRE A PISTA
C18: =D17 -> 22 | D18: 24 | G18: X | J18: X
C19: =D18 -> 24 | D19: 26.3 | G19: X | J19: X
E36: =IF(E7="X",(D7-C7),"0") -> 0 | F36: =IF(F7="X",(D7-C7),"0") -> 0 | G36: =IF(G7="X",(D7-C7),"0") -> 2 | H36: =IF(H7="X",(D7-C7),"0") -> 0 | I36: =IF(I7="X",(D7-C7),"0") -> 0 | J36: =IF(J7="X",(D7-C7),"0") -> 2 | K36: =IF(K7="X",(D7-C7),"0") -> 0
E37: =IF(E8="X",(D8-C8),"0") -> 0 | F37: =IF(F8="X",(D8-C8),"0") -> 0 | G37: =IF(G8="X",(D8-C8),"0") -> 2 | H37: =IF(H8="X",(D8-C8),"0") -> 0 | I37: =IF(I8="X",(D8-C8),"0") -> 0 | J37: =IF(J8="X",(D8-C8),"0") -> 2 | K37: =IF(K8="X",(D8-C8),"0") -> 0
E38: =IF(E9="X",(D9-C9),"0") -> 0 | F38: =IF(F9="X",(D9-C9),"0") -> 0 | G38: =IF(G9="X",(D9-C9),"0") -> 2 | H38: =IF(H9="X",(D9-C9),"0") -> 0 | I38: =IF(I9="X",(D9-C9),"0") -> 0 | J38: =IF(J9="X",(D9-C9),"0") -> 2 | K38: =IF(K9="X",(D9-C9),"0") -> 0
E39: =IF(E10="X",(D10-C10),"0") -> 0 | F39: =IF(F10="X",(D10-C10),"0") -> 0 | G39: =IF(G10="X",(D10-C10),"0") -> 2 | H39: =IF(H10="X",(D10-C10),"0") -> 0 | I39: =IF(I10="X",(D10-C10),"0") -> 0 | J39: =IF(J10="X",(D10-C10),"0") -> 2 | K39: =IF(K10="X",(D10-C10),"0") -> 0
E40: =IF(E11="X",(D11-C11),"0") -> 0 | F40: =IF(F11="X",(D11-C11),"0") -> 0 | G40: =IF(G11="X",(D11-C11),"0") -> 2 | H40: =IF(H11="X",(D11-C11),"0") -> 0 | I40: =IF(I11="X",(D11-C11),"0") -> 0 | J40: =IF(J11="X",(D11-C11),"0") -> 2 | K40: =IF(K11="X",(D11-C11),"0") -> 0
E41: =IF(E12="X",(D12-C12),"0") -> 0 | F41: =IF(F12="X",(D12-C12),"0") -> 0 | G41: =IF(G12="X",(D12-C12),"0") -> 2 | H41: =IF(H12="X",(D12-C12),"0") -> 0 | I41: =IF(I12="X",(D12-C12),"0") -> 0 | J41: =IF(J12="X",(D12-C12),"0") -> 2 | K41: =IF(K12="X",(D12-C12),"0") -> 0
E42: =IF(E13="X",(D13-C13),"0") -> 0 | F42: =IF(F13="X",(D13-C13),"0") -> 0 | G42: =IF(G13="X",(D13-C13),"0") -> 2 | H42: =IF(H13="X",(D13-C13),"0") -> 0 | I42: =IF(I13="X",(D13-C13),"0") -> 0 | J42: =IF(J13="X",(D13-C13),"0") -> 2 | K42: =IF(K13="X",(D13-C13),"0") -> 0
E43: =IF(E14="X",(D14-C14),"0") -> 0 | F43: =IF(F14="X",(D14-C14),"0") -> 0 | G43: =IF(G14="X",(D14-C14),"0") -> 2 | H43: =IF(H14="X",(D14-C14),"0") -> 0 | I43: =IF(I14="X",(D14-C14),"0") -> 0 | J43: =IF(J14="X",(D14-C14),"0") -> 2 | K43: =IF(K14="X",(D14-C14),"0") -> 0
E44: =IF(E15="X",(D15-C15),"0") -> 0 | F44: =IF(F15="X",(D15-C15),"0") -> 0 | G44: =IF(G15="X",(D15-C15),"0") -> 2 | H44: =IF(H15="X",(D15-C15),"0") -> 0 | I44: =IF(I15="X",(D15-C15),"0") -> 0 | J44: =IF(J15="X",(D15-C15),"0") -> 2 | K44: =IF(K15="X",(D15-C15),"0") -> 0
E45: =IF(E16="X",(D16-C16),"0") -> 0 | F45: =IF(F16="X",(D16-C16),"0") -> 0 | G45: =IF(G16="X",(D16-C16),"0") -> 2 | H45: =IF(H16="X",(D16-C16),"0") -> 0 | I45: =IF(I16="X",(D16-C16),"0") -> 0 | J45: =IF(J16="X",(D16-C16),"0") -> 2 | K45: =IF(K16="X",(D16-C16),"0") -> 0
E46: =IF(E17="X",(D17-C17),"0") -> 0 | F46: =IF(F17="X",(D17-C17),"0") -> 0 | G46: =IF(G17="X",(D17-C17),"0") -> 2 | H46: =IF(H17="X",(D17-C17),"0") -> 0 | I46: =IF(I17="X",(D17-C17),"0") -> 0 | J46: =IF(J17="X",(D17-C17),"0") -> 2 | K46: =IF(K17="X",(D17-C17),"0") -> 0
E47: =IF(E18="X",(D18-C18),"0") -> 0 | F47: =IF(F18="X",(D18-C18),"0") -> 0 | G47: =IF(G18="X",(D18-C18),"0") -> 2 | H47: =IF(H18="X",(D18-C18),"0") -> 0 | I47: =IF(I18="X",(D18-C18),"0") -> 0 | J47: =IF(J18="X",(D18-C18),"0") -> 2 | K47: =IF(K18="X",(D18-C18),"0") -> 0
... E61: =IF(E32="X",(D32-C32),"0") -> 0 | F61: =IF(F32="X",(D32-C32),"0") -> 0 | G61: =IF(G32="X",(D32-C32),"0") -> 0 | H61: =IF(H32="X",(D32-C32),"0") -> 0 | I61: =IF(I32="X",(D32-C32),"0") -> 0 | J61: =IF(J32="X",(D32-C32),"0") -> 0 | K61: =IF(K32="X",(D32-C32),"0") -> 0
E62: =SUM(E36:E61) -> 0 | F62: =SUM(F36:F61) -> 0 | G62: =SUM(G36:G61) -> 26.3 | H62: =SUM(H36:H61) -> 0 | I62: =SUM(I36:I61) -> 0 | J62: =SUM(J36:J61) -> 26.3 | K62: =SUM(K36:K61) -> 0

Sheet 20
A1: PROGRAMA DE MANUTENÇÃORODOVIÁRIA | I1: DATA: | J1: ='1'!J1 -> 46204 | L1: TÉCNICO RESP. | N1: ENG. VINICIUS RODRIGUES
F2: RODOVIAS NÃO PAVIMENTADAS
A3: FICHA DE INSPEÇÃO: | B3: =TT!C7 -> RODOVIA TO-201 - TRECHO ESPERANTINA - DIVISA TO-MA
A5: S.R.E. | B5: SENTIDO | C5: INÍCIO (KM) | D5: FIM (KM) | E5: CONDIÇÃO DA PLATAFORMA | I5: DRENAGEM SUPERFICIAL | L5: OBSERV.
E6: BOM | F6: REG. (ATÉ 10 IRR./KM) | G6: RUÍM (+ 10 IRR./KM) | H6: PÉSSIMA (ATOLEIRO/PTO. CRÍTICO) | I6: LIMPA | J6: OBSTRUÍDA | K6: AUSENTE
A7: 201ETO0260 | C7: =D6 -> 0 | D7: 1 | E7: X | I7: X
C8: =D7 -> 1 | D8: 2 | E8: X | I8: X
C9: =D8 -> 2 | D9: 3 | F9: X | I9: X
C10: =D9 -> 3 | D10: 4 | F10: X | J10: X
C11: =D10 -> 4 | D11: 5 | F11: X | J11: X
C12: =D11 -> 5 | D12: 6 | F12: X | J12: X
C13: =D12 -> 6 | D13: 7 | F13: X | J13: X
C14: =D13 -> 7 | D14: 8 | F14: X | J14: X
C15: =D14 -> 8 | D15: 8.64 | F15: X | I15: X
A16: 201ETO0270 | C16: 0 | D16: 1 | F16: X | J16: X
C17: =D16 -> 1 | D17: 2 | F17: X | J17: X
C18: =D17 -> 2 | D18: 3 | F18: X | J18: X
C19: =D18 -> 3 | D19: 4 | F19: X | J19: X
C20: =D19 -> 4 | D20: 5 | E20: X | J20: X
C21: =D20 -> 5 | D21: 6 | E21: X | J21: X
C22: =D21 -> 6 | D22: 7 | E22: X | J22: X
C23: =D22 -> 7 | D23: 8 | E23: X | J23: X
C24: =D23 -> 8 | D24: 9 | E24: X | J24: X
C25: =D24 -> 9 | D25: 10 | E25: X | J25: X
C26: =D25 -> 10 | D26: 11 | F26: X | J26: X
C27: =D26 -> 11 | D27: 12 | F27: X | J27: X
C28: =D27 -> 12 | D28: 12.57 | F28: X | J28: X
E36: =IF(E7="X",(D7-C7),"0") -> 1 | F36: =IF(F7="X",(D7-C7),"0") -> 0 | G36: =IF(G7="X",(D7-C7),"0") -> 0 | H36: =IF(H7="X",(D7-C7),"0") -> 0 | I36: =IF(I7="X",(D7-C7),"0") -> 1 | J36: =IF(J7="X",(D7-C7),"0") -> 0 | K36: =IF(K7="X",(D7-C7),"0") -> 0
E37: =IF(E8="X",(D8-C8),"0") -> 1 | F37: =IF(F8="X",(D8-C8),"0") -> 0 | G37: =IF(G8="X",(D8-C8),"0") -> 0 | H37: =IF(H8="X",(D8-C8),"0") -> 0 | I37: =IF(I8="X",(D8-C8),"0") -> 1 | J37: =IF(J8="X",(D8-C8),"0") -> 0 | K37: =IF(K8="X",(D8-C8),"0") -> 0
E38: =IF(E9="X",(D9-C9),"0") -> 0 | F38: =IF(F9="X",(D9-C9),"0") -> 1 | G38: =IF(G9="X",(D9-C9),"0") -> 0 | H38: =IF(H9="X",(D9-C9),"0") -> 0 | I38: =IF(I9="X",(D9-C9),"0") -> 1 | J38: =IF(J9="X",(D9-C9),"0") -> 0 | K38: =IF(K9="X",(D9-C9),"0") -> 0
E39: =IF(E10="X",(D10-C10),"0") -> 0 | F39: =IF(F10="X",(D10-C10),"0") -> 1 | G39: =IF(G10="X",(D10-C10),"0") -> 0 | H39: =IF(H10="X",(D10-C10),"0") -> 0 | I39: =IF(I10="X",(D10-C10),"0") -> 0 | J39: =IF(J10="X",(D10-C10),"0") -> 1 | K39: =IF(K10="X",(D10-C10),"0") -> 0
E40: =IF(E11="X",(D11-C11),"0") -> 0 | F40: =IF(F11="X",(D11-C11),"0") -> 1 | G40: =IF(G11="X",(D11-C11),"0") -> 0 | H40: =IF(H11="X",(D11-C11),"0") -> 0 | I40: =IF(I11="X",(D11-C11),"0") -> 0 | J40: =IF(J11="X",(D11-C11),"0") -> 1 | K40: =IF(K11="X",(D11-C11),"0") -> 0
E41: =IF(E12="X",(D12-C12),"0") -> 0 | F41: =IF(F12="X",(D12-C12),"0") -> 1 | G41: =IF(G12="X",(D12-C12),"0") -> 0 | H41: =IF(H12="X",(D12-C12),"0") -> 0 | I41: =IF(I12="X",(D12-C12),"0") -> 0 | J41: =IF(J12="X",(D12-C12),"0") -> 1 | K41: =IF(K12="X",(D12-C12),"0") -> 0
E42: =IF(E13="X",(D13-C13),"0") -> 0 | F42: =IF(F13="X",(D13-C13),"0") -> 1 | G42: =IF(G13="X",(D13-C13),"0") -> 0 | H42: =IF(H13="X",(D13-C13),"0") -> 0 | I42: =IF(I13="X",(D13-C13),"0") -> 0 | J42: =IF(J13="X",(D13-C13),"0") -> 1 | K42: =IF(K13="X",(D13-C13),"0") -> 0
E43: =IF(E14="X",(D14-C14),"0") -> 0 | F43: =IF(F14="X",(D14-C14),"0") -> 1 | G43: =IF(G14="X",(D14-C14),"0") -> 0 | H43: =IF(H14="X",(D14-C14),"0") -> 0 | I43: =IF(I14="X",(D14-C14),"0") -> 0 | J43: =IF(J14="X",(D14-C14),"0") -> 1 | K43: =IF(K14="X",(D14-C14),"0") -> 0
E44: =IF(E15="X",(D15-C15),"0") -> 0 | F44: =IF(F15="X",(D15-C15),"0") -> 0.64 | G44: =IF(G15="X",(D15-C15),"0") -> 0 | H44: =IF(H15="X",(D15-C15),"0") -> 0 | I44: =IF(I15="X",(D15-C15),"0") -> 0.64 | J44: =IF(J15="X",(D15-C15),"0") -> 0 | K44: =IF(K15="X",(D15-C15),"0") -> 0
E45: =IF(E16="X",(D16-C16),"0") -> 0 | F45: =IF(F16="X",(D16-C16),"0") -> 1 | G45: =IF(G16="X",(D16-C16),"0") -> 0 | H45: =IF(H16="X",(D16-C16),"0") -> 0 | I45: =IF(I16="X",(D16-C16),"0") -> 0 | J45: =IF(J16="X",(D16-C16),"0") -> 1 | K45: =IF(K16="X",(D16-C16),"0") -> 0
E46: =IF(E17="X",(D17-C17),"0") -> 0 | F46: =IF(F17="X",(D17-C17),"0") -> 1 | G46: =IF(G17="X",(D17-C17),"0") -> 0 | H46: =IF(H17="X",(D17-C17),"0") -> 0 | I46: =IF(I17="X",(D17-C17),"0") -> 0 | J46: =IF(J17="X",(D17-C17),"0") -> 1 | K46: =IF(K17="X",(D17-C17),"0") -> 0
E47: =IF(E18="X",(D18-C18),"0") -> 0 | F47: =IF(F18="X",(D18-C18),"0") -> 1 | G47: =IF(G18="X",(D18-C18),"0") -> 0 | H47: =IF(H18="X",(D18-C18),"0") -> 0 | I47: =IF(I18="X",(D18-C18),"0") -> 0 | J47: =IF(J18="X",(D18-C18),"0") -> 1 | K47: =IF(K18="X",(D18-C18),"0") -> 0
... E61: =IF(E32="X",(D32-C32),"0") -> 0 | F61: =IF(F32="X",(D32-C32),"0") -> 0 | G61: =IF(G32="X",(D32-C32),"0") -> 0 | H61: =IF(H32="X",(D32-C32),"0") -> 0 | I61: =IF(I32="X",(D32-C32),"0") -> 0 | J61: =IF(J32="X",(D32-C32),"0") -> 0 | K61: =IF(K32="X",(D32-C32),"0") -> 0
...

Sheet 21
A1: PROGRAMA DE MANUTENÇÃORODOVIÁRIA | I1: DATA: | J1: ='1'!J1 -> 46204 | L1: TÉCNICO RESP. | N1: ENG. VINICIUS RODRIGUES
F2: RODOVIAS NÃO PAVIMENTADAS
A3: FICHA DE INSPEÇÃO: | B3: =TT!C8 -> RODOVIA TO-205 - TRECHO SÃO BENTO DO TOCANTINS - ENTR. TO-010
A5: S.R.E. | B5: SENTIDO | C5: INÍCIO (KM) | D5: FIM (KM) | E5: CONDIÇÃO DA PLATAFORMA | I5: DRENAGEM SUPERFICIAL | L5: OBSERV.
E6: BOM | F6: REG. (ATÉ 10 IRR./KM) | G6: RUÍM (+ 10 IRR./KM) | H6: PÉSSIMA (ATOLEIRO/PTO. CRÍTICO) | I6: LIMPA | J6: OBSTRUÍDA | K6: AUSENTE
A7: 205ETO0010 | B7: D | C7: 0 | D7: 1 | E7: X | J7: X
C8: =D7 -> 1 | D8: 2 | E8: X | J8: X
C9: =D8 -> 2 | D9: 3 | E9: X | J9: X
C10: =D9 -> 3 | D10: 4 | E10: X | J10: X | L10: AUSENCIA DE DRENAGEM E MATERIAL FINO SOBRE A PISTA
C11: =D10 -> 4 | D11: 5 | F11: X | J11: X
C12: =D11 -> 5 | D12: 6 | E12: X | J12: X
C13: =D12 -> 6 | D13: 7 | F13: X | I13: X
C14: =D13 -> 7 | D14: 8 | F14: X | I14: X | L14: GREIDE REBAIXADO
C15: =D14 -> 8 | D15: 9 | E15: X | I15: X | L15: GREIDE REBAIXADO
C16: =D15 -> 9 | D16: 10 | E16: X | I16: X
C17: =D16 -> 10 | D17: 11 | E17: X | J17: X
C18: =D17 -> 11 | D18: 12 | E18: X | J18: X
C19: =D18 -> 12 | D19: 13 | F19: X | J19: X
C20: =D19 -> 13 | D20: 14 | F20: X | I20: X
C21: =D20 -> 14 | D21: 15 | F21: X | I21: X
C22: =D21 -> 15 | D22: 16 | F22: X | I22: X
C23: =D22 -> 16 | D23: 17 | F23: X | J23: X
C24: =D23 -> 17 | D24: 18 | F24: X | I24: X
C25: =D24 -> 18 | D25: 19 | E25: X | I25: X
C26: =D25 -> 19 | D26: 20 | E26: X | I26: X
C27: =D26 -> 20 | D27: 21 | E27: X | I27: X
C28: =D27 -> 21 | D28: 22 | E28: X | J28: X
C29: =D28 -> 22 | D29: 23 | E29: X | I29: X
C30: =D29 -> 23 | D30: 24 | E30: X | I30: X
C31: =D30 -> 24 | D31: 25 | E31: X | I31: X
C32: =D31 -> 25 | D32: 25.67 | E32: X | I32: X
E36: =IF(E7="X",(D7-C7),"0") -> 1 | F36: =IF(F7="X",(D7-C7),"0") -> 0 | G36: =IF(G7="X",(D7-C7),"0") -> 0 | H36: =IF(H7="X",(D7-C7),"0") -> 0 | I36: =IF(I7="X",(D7-C7),"0") -> 0 | J36: =IF(J7="X",(D7-C7),"0") -> 1 | K36: =IF(K7="X",(D7-C7),"0") -> 0
E37: =IF(E8="X",(D8-C8),"0") -> 1 | F37: =IF(F8="X",(D8-C8),"0") -> 0 | G37: =IF(G8="X",(D8-C8),"0") -> 0 | H37: =IF(H8="X",(D8-C8),"0") -> 0 | I37: =IF(I8="X",(D8-C8),"0") -> 0 | J37: =IF(J8="X",(D8-C8),"0") -> 1 | K37: =IF(K8="X",(D8-C8),"0") -> 0
E38: =IF(E9="X",(D9-C9),"0") -> 1 | F38: =IF(F9="X",(D9-C9),"0") -> 0 | G38: =IF(G9="X",(D9-C9),"0") -> 0 | H38: =IF(H9="X",(D9-C9),"0") -> 0 | I38: =IF(I9="X",(D9-C9),"0") -> 0 | J38: =IF(J9="X",(D9-C9),"0") -> 1 | K38: =IF(K9="X",(D9-C9),"0") -> 0
E39: =IF(E10="X",(D10-C10),"0") -> 1 | F39: =IF(F10="X",(D10-C10),"0") -> 0 | G39: =IF(G10="X",(D10-C10),"0") -> 0 | H39: =IF(H10="X",(D10-C10),"0") -> 0 | I39: =IF(I10="X",(D10-C10),"0") -> 0 | J39: =IF(J10="X",(D10-C10),"0") -> 1 | K39: =IF(K10="X",(D10-C10),"0") -> 0
E40: =IF(E11="X",(D11-C11),"0") -> 0 | F40: =IF(F11="X",(D11-C11),"0") -> 1 | G40: =IF(G11="X",(D11-C11),"0") -> 0 | H40: =IF(H11="X",(D11-C11),"0") -> 0 | I40: =IF(I11="X",(D11-C11),"0") -> 0 | J40: =IF(J11="X",(D11-C11),"0") -> 1 | K40: =IF(K11="X",(D11-C11),"0") -> 0
E41: =IF(E12="X",(D12-C12),"0") -> 1 | F41: =IF(F12="X",(D12-C12),"0") -> 0 | G41: =IF(G12="X",(D12-C12),"0") -> 0 | H41: =IF(H12="X",(D12-C12),"0") -> 0 | I41: =IF(I12="X",(D12-C12),"0") -> 0 | J41: =IF(J12="X",(D12-C12),"0") -> 1 | K41: =IF(K12="X",(D12-C12),"0") -> 0
E42: =IF(E13="X",(D13-C13),"0") -> 0 | F42: =IF(F13="X",(D13-C13),"0") -> 1 | G42: =IF(G13="X",(D13-C13),"0") -> 0 | H42: =IF(H13="X",(D13-C13),"0") -> 0 | I42: =IF(I13="X",(D13-C13),"0") -> 1 | J42: =IF(J13="X",(D13-C13),"0") -> 0 | K42: =IF(K13="X",(D13-C13),"0") -> 0
E43: =IF(E14="X",(D14-C14),"0") -> 0 | F43: =IF(F14="X",(D14-C14),"0") -> 1 | G43: =IF(G14="X",(D14-C14),"0") -> 0 | H43: =IF(H14="X",(D14-C14),"0") -> 0 | I43: =IF(I14="X",(D14-C14),"0") -> 1 | J43: =IF(J14="X",(D14-C14),"0") -> 0 | K43: =IF(K14="X",(D14-C14),"0") -> 0
E44: =IF(E15="X",(D15-C15),"0") -> 1 | F44: =IF(F15="X",(D15-C15),"0") -> 0 | G44: =IF(G15="X",(D15-C15),"0") -> 0 | H44: =IF(H15="X",(D15-C15),"0") -> 0 | I44: =IF(I15="X",(D15-C15),"0") -> 1 | J44: =IF(J15="X",(D15-C15),"0") -> 0 | K44: =IF(K15="X",(D15-C15),"0") -> 0
...

Sheet 22
A1: PROGRAMA DE MANUTENÇÃORODOVIÁRIA | I1: DATA: | J1: ='1'!J1 -> 46204 | L1: TÉCNICO RESP. | N1: LABORATORISTA -CLAUDIOMIRO VIEIRA LOPES
F2: RODOVIAS NÃO PAVIMENTADAS
A3: FICHA DE INSPEÇÃO: | B3: =TT!C9 -> RODOVIA TO-210 - TRECHO ENTR. TO-010 - DIVISA TO-PA (VILA ANTONINA)
A5: S.R.E. | B5: SENTIDO | C5: INÍCIO (KM) | D5: FIM (KM) | E5: CONDIÇÃO DA PLATAFORMA | I5: DRENAGEM SUPERFICIAL | L5: OBSERV.
E6: BOM | F6: REG. (ATÉ 10 IRR./KM) | G6: RUÍM (+ 10 IRR./KM) | H6: PÉSSIMA (ATOLEIRO/PTO. CRÍTICO) | I6: LIMPA | J6: OBSTRUÍDA | K6: AUSENTE
A7: 210ETO0290 | B7: C | C7: 0 | D7: 2 | E7: X | I7: X | L7: BUEIRO SIMPLES KM-0,2 ( 0,70 / 0,70 )
C8: =D7 -> 2 | D8: 4 | F8: X | K8: X | L8: BUEIRO SIMPLES KM-4,70 ( 1,10 / 1,10 ) ESTAR SEM CABECA
C9: =D8 -> 4 | D9: 6 | F9: X | I9: X | L9: BUEIRO SIMPLES KM-5,3 ( 1,20/ 1,20 )
C10: =D9 -> 6 | D10: 8 | F10: X | I10: X | L10: BUEIRO SIMPLES KM-9,9 ( 1,20/ 1,20 )
C11: =D10 -> 8 | D11: 10 | E11: X | I11: X | L11: BUEIRO DUPLO KM-12,3 (1,20 / 1,20)
C12: =D11 -> 10 | D12: 12 | F12: X | I12: X | L12: PONTE DE CONCRETO KM-13,9 ( 4.45 / 6,20 )
C13: =D12 -> 12 | D13: 14 | F13: X | I13: X | L13: BUEIRO SIMPLES KM-14,6 ( 0,70 / 0,70 )
C14: =D13 -> 14 | D14: 16 | F14: X | I14: X | L14: GALERIA KM-16,0 ( 2,50 / 2,50 )
C15: =D14 -> 16 | D15: 18 | E15: X | J15: X | L15: PONTO CRITICO KM- 16,7
C16: =D15 -> 18 | D16: 20 | F16: X | I16: X | L16: PONTE DE CONCRETO KM-22,4 ( 4.45 / 30,30 )
C17: =D16 -> 20 | D17: 22 | F17: X | I17: X | L17: PONTE DE CONCRETO KM-24,6 ( 4.45 / 12,10 )
C18: =D17 -> 22 | D18: 24 | F18: X | I18: X | L18: BUEIRO SIMPLES KM-26,3 ( 0,70 / 0,70 )
C19: =D18 -> 24 | D19: 26 | F19: X | I19: X | L19: BUEIRO SIMPLES KM-29,0 ( 1,10 / 1,10 ) ESTAR OBSTRUIDO
C20: =D19 -> 26 | D20: 28 | F20: X | I20: X | L20: PONTE DE CONCRETO KM-30,6 ( 4.45 / 11,0 )
C21: =D20 -> 28 | D21: 30 | F21: X | I21: X | L21: BUEIRO DUPLO KM-31,6 (1,20 / 1,20) ESTAR OBSTRUIDO
C22: =D21 -> 30 | D22: 32 | F22: X | I22: X | L22: PONTE DE CONCRETO KM-33,4 ( 4.45 / 10,0 )
C23: =D22 -> 32 | D23: 34 | E23: X | I23: X
C24: =D23 -> 34 | D24: 36 | F24: X | I24: X
C25: =D24 -> 36 | D25: 37.2 | E25: X | I25: X
C26: =D25 -> 37.2 | D26: 38.25 | E26: X | J26: X
E48: =IF(E7="X",(D7-C7),"0") -> 2 | F48: =IF(F7="X",(D7-C7),"0") -> 0 | G48: =IF(G7="X",(D7-C7),"0") -> 0 | H48: =IF(H7="X",(D7-C7),"0") -> 0 | I48: =IF(I7="X",(D7-C7),"0") -> 2 | J48: =IF(J7="X",(D7-C7),"0") -> 0 | K48: =IF(K7="X",(D7-C7),"0") -> 0
E49: =IF(E8="X",(D8-C8),"0") -> 0 | F49: =IF(F8="X",(D8-C8),"0") -> 2 | G49: =IF(G8="X",(D8-C8),"0") -> 0 | H49: =IF(H8="X",(D8-C8),"0") -> 0 | I49: =IF(I8="X",(D8-C8),"0") -> 0 | J49: =IF(J8="X",(D8-C8),"0") -> 0 | K49: =IF(K8="X",(D8-C8),"0") -> 2
E50: =IF(E9="X",(D9-C9),"0") -> 0 | F50: =IF(F9="X",(D9-C9),"0") -> 2 | G50: =IF(G9="X",(D9-C9),"0") -> 0 | H50: =IF(H9="X",(D9-C9),"0") -> 0 | I50: =IF(I9="X",(D9-C9),"0") -> 2 | J50: =IF(J9="X",(D9-C9),"0") -> 0 | K50: =IF(K9="X",(D9-C9),"0") -> 0
E51: =IF(E10="X",(D10-C10),"0") -> 0 | F51: =IF(F10="X",(D10-C10),"0") -> 2 | G51: =IF(G10="X",(D10-C10),"0") -> 0 | H51: =IF(H10="X",(D10-C10),"0") -> 0 | I51: =IF(I10="X",(D10-C10),"0") -> 2 | J51: =IF(J10="X",(D10-C10),"0") -> 0 | K51: =IF(K10="X",(D10-C10),"0") -> 0
E52: =IF(E11="X",(D11-C11),"0") -> 2 | F52: =IF(F11="X",(D11-C11),"0") -> 0 | G52: =IF(G11="X",(D11-C11),"0") -> 0 | H52: =IF(H11="X",(D11-C11),"0") -> 0 | I52: =IF(I11="X",(D11-C11),"0") -> 2 | J52: =IF(J11="X",(D11-C11),"0") -> 0 | K52: =IF(K11="X",(D11-C11),"0") -> 0
E53: =IF(E12="X",(D12-C12),"0") -> 0 | F53: =IF(F12="X",(D12-C12),"0") -> 2 | G53: =IF(G12="X",(D12-C12),"0") -> 0 | H53: =IF(H12="X",(D12-C12),"0") -> 0 | I53: =IF(I12="X",(D12-C12),"0") -> 2 | J53: =IF(J12="X",(D12-C12),"0") -> 0 | K53: =IF(K12="X",(D12-C12),"0") -> 0
E54: =IF(E13="X",(D13-C13),"0") -> 0 | F54: =IF(F13="X",(D13-C13),"0") -> 2 | G54: =IF(G13="X",(D13-C13),"0") -> 0 | H54: =IF(H13="X",(D13-C13),"0") -> 0 | I54: =IF(I13="X",(D13-C13),"0") -> 2 | J54: =IF(J13="X",(D13-C13),"0") -> 0 | K54: =IF(K13="X",(D13-C13),"0") -> 0
E55: =IF(E14="X",(D14-C14),"0") -> 0 | F55: =IF(F14="X",(D14-C14),"0") -> 2 | G55: =IF(G14="X",(D14-C14),"0") -> 0 | H55: =IF(H14="X",(D14-C14),"0") -> 0 | I55: =IF(I14="X",(D14-C14),"0") -> 2 | J55: =IF(J14="X",(D14-C14),"0") -> 0 | K55: =IF(K14="X",(D14-C14),"0") -> 0
E56: =IF(E15="X",(D15-C15),"0") -> 2 | F56: =IF(F15="X",(D15-C15),"0") -> 0 | G56: =IF(G15="X",(D15-C15),"0") -> 0 | H56: =IF(H15="X",(D15-C15),"0") -> 0 | I56: =IF(I15="X",(D15-C15),"0") -> 0 | J56: =IF(J15="X",(D15-C15),"0") -> 2 | K56: =IF(K15="X",(D15-C15),"0") -> 0
E57: =IF(E16="X",(D16-C16),"0") -> 0 | F57: =IF(F16="X",(D16-C16),"0") -> 2 | G57: =IF(G16="X",(D16-C16),"0") -> 0 | H57: =IF(H16="X",(D16-C16),"0") -> 0 | I57: =IF(I16="X",(D16-C16),"0") -> 2 | J57: =IF(J16="X",(D16-C16),"0") -> 0 | K57: =IF(K16="X",(D16-C16),"0") -> 0
E58: =IF(E17="X",(D17-C17),"0") -> 0 | F58: =IF(F17="X",(D17-C17),"0") -> 2 | G58: =IF(G17="X",(D17-C17),"0") -> 0 | H58: =IF(H17="X",(D17-C17),"0") -> 0 | I58: =IF(I17="X",(D17-C17),"0") -> 2 | J58: =IF(J17="X",(D17-C17),"0") -> 0 | K58: =IF(K17="X",(D17-C17),"0") -> 0
E59: =IF(E18="X",(D18-C18),"0") -> 0 | F59: =IF(F18="X",(D18-C18),"0") -> 2 | G59: =IF(G18="X",(D18-C18),"0") -> 0 | H59: =IF(H18="X",(D18-C18),"0") -> 0 | I59: =IF(I18="X",(D18-C18),"0") -> 2 | J59: =IF(J18="X",(D18-C18),"0") -> 0 | K59: =IF(K18="X",(D18-C18),"0") -> 0
... E87: =IF(E46="X",(D46-C46),"0") -> 0 | F87: =IF(F46="X",(D46-C46),"0") -> 0 | G87: =IF(G46="X",(D46-C46),"0") -> 0 | H87: =IF(H46="X",(D46-C46),"0") -> 0 | I87: =IF(I46="X",(D46-C46),"0") -> 0 | J87: =IF(J46="X",(D46-C46),"0") -> 0 | K87: =IF(K46="X",(D46-C46),"0") -> 0
E88: =SUM(E48:E87) -> 10.25 | F88: =SUM(F48:F87) -> 28 | G88: =SUM(G48:G87) -> 0 | H88: =SUM(H48:H87) -> 0 | I88: =SUM(I48:I87) -> 33.2 | J88: =SUM(J48:J87) -> 3.05 | K88: =SUM(K48:K87) -> 2

Sheet 25
A1: PROGRAMA DE MANUTENÇÃORODOVIÁRIA | I1: DATA: | J1: ='1'!J1 -> 46204 | L1: TÉCNICO RESP. | N1: ENG. VINICIUS RODRIGUES
F2: RODOVIAS NÃO PAVIMENTADAS
A3: FICHA DE INSPEÇÃO: | B3: =TT!C10 -> RODOVIA TO-210 - TRECHO TOCANTINÓPOLIS - NAZARÉ
A5: S.R.E. | B5: SENTIDO | C5: INÍCIO (KM) | D5: FIM (KM) | E5: CONDIÇÃO DA PLATAFORMA | I5: DRENAGEM SUPERFICIAL | L5: OBSERV.
E6: BOM | F6: REG. (ATÉ 10 IRR./KM) | G6: RUÍM (+ 10 IRR./KM) | H6: PÉSSIMA (ATOLEIRO/PTO. CRÍTICO) | I6: LIMPA | J6: OBSTRUÍDA | K6: AUSENTE
A7: 210ETO0090 | C7: 0 | D7: 2 | E7: X | I7: X
A8: 210ETO0100 | C8: =D7 -> 2 | D8: 4 | E8: X | I8: X
C9: =D8 -> 4 | D9: 6 | E9: X | I9: X | L9: BUEIRO SIMPLES KM-6,5 ( 1,20/ 1,20 )
C10: =D9 -> 6 | D10: 8 | E10: X | I10: X | L10: BUEIRO DUPLO KM-7,5 (1,20 / 1,20)
C11: =D10 -> 8 | D11: 10 | E11: X | I11: X | L11: PONTE DE CONCRETO KM-8,4 ( 4.45 / 30,0 )
C12: =D11 -> 10 | D12: 12 | E12: X | I12: X
C13: =D12 -> 12 | D13: 14 | E13: X | I13: X | L13: BUEIRO SIMPLES KM-10,3 ( 1,10/ 1,10 )
C14: =D13 -> 14 | D14: 15.5 | E14: X | I14: X | L14: BUEIRO SIMPLES KM-10,9 ( 1,20/ 1,20 )
L15: BUEIRO SIMPLES KM-11,8 ( 1,10/ 1,10 )
L16: BUEIRO SIMPLES KM-13,4 ( 1,10/ 1,10 )
L17: BUEIRO DUPLO KM-14,2 (1,10 / 1,10)
L18: PONTE DE CONCRETO KM-15,0 ( 3,70 / 10,0 )
E36: =IF(E7="X",(D7-C7),"0") -> 2 | F36: =IF(F7="X",(D7-C7),"0") -> 0 | G36: =IF(G7="X",(D7-C7),"0") -> 0 | H36: =IF(H7="X",(D7-C7),"0") -> 0 | I36: =IF(I7="X",(D7-C7),"0") -> 2 | J36: =IF(J7="X",(D7-C7),"0") -> 0 | K36: =IF(K7="X",(D7-C7),"0") -> 0
E37: =IF(E8="X",(D8-C8),"0") -> 2 | F37: =IF(F8="X",(D8-C8),"0") -> 0 | G37: =IF(G8="X",(D8-C8),"0") -> 0 | H37: =IF(H8="X",(D8-C8),"0") -> 0 | I37: =IF(I8="X",(D8-C8),"0") -> 2 | J37: =IF(J8="X",(D8-C8),"0") -> 0 | K37: =IF(K8="X",(D8-C8),"0") -> 0
E38: =IF(E9="X",(D9-C9),"0") -> 2 | F38: =IF(F9="X",(D9-C9),"0") -> 0 | G38: =IF(G9="X",(D9-C9),"0") -> 0 | H38: =IF(H9="X",(D9-C9),"0") -> 0 | I38: =IF(I9="X",(D9-C9),"0") -> 2 | J38: =IF(J9="X",(D9-C9),"0") -> 0 | K38: =IF(K9="X",(D9-C9),"0") -> 0
E39: =IF(E10="X",(D10-C10),"0") -> 2 | F39: =IF(F10="X",(D10-C10),"0") -> 0 | G39: =IF(G10="X",(D10-C10),"0") -> 0 | H39: =IF(H10="X",(D10-C10),"0") -> 0 | I39: =IF(I10="X",(D10-C10),"0") -> 2 | J39: =IF(J10="X",(D10-C10),"0") -> 0 | K39: =IF(K10="X",(D10-C10),"0") -> 0
E40: =IF(E11="X",(D11-C11),"0") -> 2 | F40: =IF(F11="X",(D11-C11),"0") -> 0 | G40: =IF(G11="X",(D11-C11),"0") -> 0 | H40: =IF(H11="X",(D11-C11),"0") -> 0 | I40: =IF(I11="X",(D11-C11),"0") -> 2 | J40: =IF(J11="X",(D11-C11),"0") -> 0 | K40: =IF(K11="X",(D11-C11),"0") -> 0
E41: =IF(E12="X",(D12-C12),"0") -> 2 | F41: =IF(F12="X",(D12-C12),"0") -> 0 | G41: =IF(G12="X",(D12-C12),"0") -> 0 | H41: =IF(H12="X",(D12-C12),"0") -> 0 | I41: =IF(I12="X",(D12-C12),"0") -> 2 | J41: =IF(J12="X",(D12-C12),"0") -> 0 | K41: =IF(K12="X",(D12-C12),"0") -> 0
E42: =IF(E13="X",(D13-C13),"0") -> 2 | F42: =IF(F13="X",(D13-C13),"0") -> 0 | G42: =IF(G13="X",(D13-C13),"0") -> 0 | H42: =IF(H13="X",(D13-C13),"0") -> 0 | I42: =IF(I13="X",(D13-C13),"0") -> 2 | J42: =IF(J13="X",(D13-C13),"0") -> 0 | K42: =IF(K13="X",(D13-C13),"0") -> 0
E43: =IF(E14="X",(D14-C14),"0") -> 1.5 | F43: =IF(F14="X",(D14-C14),"0") -> 0 | G43: =IF(G14="X",(D14-C14),"0") -> 0 | H43: =IF(H14="X",(D14-C14),"0") -> 0 | I43: =IF(I14="X",(D14-C14),"0") -> 1.5 | J43: =IF(J14="X",(D14-C14),"0") -> 0 | K43: =IF(K14="X",(D14-C14),"0") -> 0
E44: =IF(E15="X",(D15-C15),"0") -> 0 | F44: =IF(F15="X",(D15-C15),"0") -> 0 | G44: =IF(G15="X",(D15-C15),"0") -> 0 | H44: =IF(H15="X",(D15-C15),"0") -> 0 | I44: =IF(I15="X",(D15-C15),"0") -> 0 | J44: =IF(J15="X",(D15-C15),"0") -> 0 | K44: =IF(K15="X",(D15-C15),"0") -> 0
E45: =IF(E16="X",(D16-C16),"0") -> 0 | F45: =IF(F16="X",(D16-C16),"0") -> 0 | G45: =IF(G16="X",(D16-C16),"0") -> 0 | H45: =IF(H16="X",(D16-C16),"0") -> 0 | I45: =IF(I16="X",(D16-C16),"0") -> 0 | J45: =IF(J16="X",(D16-C16),"0") -> 0 | K45: =IF(K16="X",(D16-C16),"0") -> 0
E46: =IF(E17="X",(D17-C17),"0") -> 0 | F46: =IF(F17="X",(D17-C17),"0") -> 0 | G46: =IF(G17="X",(D17-C17),"0") -> 0 | H46: =IF(H17="X",(D17-C17),"0") -> 0 | I46: =IF(I17="X",(D17-C17),"0") -> 0 | J46: =IF(J17="X",(D17-C17),"0") -> 0 | K46: =IF(K17="X",(D17-C17),"0") -> 0
E47: =IF(E18="X",(D18-C18),"0") -> 0 | F47: =IF(F18="X",(D18-C18),"0") -> 0 | G47: =IF(G18="X",(D18-C18),"0") -> 0 | H47: =IF(H18="X",(D18-C18),"0") -> 0 | I47: =IF(I18="X",(D18-C18),"0") -> 0 | J47: =IF(J18="X",(D18-C18),"0") -> 0 | K47: =IF(K18="X",(D18-C18),"0") -> 0
... E61: =IF(E32="X",(D32-C32),"0") -> 0 | F61: =IF(F32="X",(D32-C32),"0") -> 0 | G61: =IF(G32="X",(D32-C32),"0") -> 0 | H61: =IF(H32="X",(D32-C32),"0") -> 0 | I61: =IF(I32="X",(D32-C32),"0") -> 0 | J61: =IF(J32="X",(D32-C32),"0") -> 0 | K61: =IF(K32="X",(D32-C32),"0") -> 0
E62: =SUM(E36:E61) -> 15.5 | F62: =SUM(F36:F61) -> 0 | G62: =SUM(G36:G61) -> 0 | H62: =SUM(H36:H61) -> 0 | I62: =SUM(I36:I61) -> 15.5 | J62: =SUM(J36:J61) -> 0 | K62: =SUM(K36:K61) -> 0

Sheet 26
A1: PROGRAMA DE MANUTENÇÃORODOVIÁRIA | I1: DATA: | J1: ='1'!J1 -> 46204 | L1: TÉCNICO RESP. | N1: ENG. VINICIUS RODRIGUES
F2: RODOVIAS NÃO PAVIMENTADAS
A3: FICHA DE INSPEÇÃO: | B3: =TT!C11 -> RODOVIA TO-402 - TRECHO DIVISA TO-MA (VILA JURANDIR BELIZARIO) - ENTR. TO-201
A5: S.R.E. | B5: SENTIDO | C5: INÍCIO (KM) | D5: FIM (KM) | E5: CONDIÇÃO DA PLATAFORMA | I5: DRENAGEM SUPERFICIAL | L5: OBSERV.
E6: BOM | F6: REG. (ATÉ 10 IRR./KM) | G6: RUÍM (+ 10 IRR./KM) | H6: PÉSSIMA (ATOLEIRO/PTO. CRÍTICO) | I6: LIMPA | J6: OBSTRUÍDA | K6: AUSENTE
A7: 402ETO0010 | B7: C | C7: 0 | D7: 1 | E7: X | J7: X
C8: =D7 -> 1 | D8: 2 | E8: X | J8: X
C9: =D8 -> 2 | D9: 3 | E9: X | J9: X
C10: =D9 -> 3 | D10: 4 | F10: X | J10: X
C11: =D10 -> 4 | D11: 5 | F11: X | J11: X
C12: =D11 -> 5 | D12: 6 | F12: X | J12: X
C13: =D12 -> 6 | D13: 7 | F13: X | J13: X
C14: =D13 -> 7 | D14: 8 | F14: X | J14: X
C15: =D14 -> 8 | D15: 9 | F15: X | J15: X
C16: =D15 -> 9 | D16: 10 | F16: X | J16: X
C17: =D16 -> 10 | D17: 11 | F17: X | J17: X
C18: =D17 -> 11 | D18: 12 | F18: X | J18: X
C19: =D18 -> 12 | D19: 13 | F19: X | J19: X
C20: =D19 -> 13 | D20: 14 | F20: X | J20: X
C21: =D20 -> 14 | D21: 14.27 | F21: X | J21: X
E36: =IF(E7="X",(D7-C7),"0") -> 1 | F36: =IF(F7="X",(D7-C7),"0") -> 0 | G36: =IF(G7="X",(D7-C7),"0") -> 0 | H36: =IF(H7="X",(D7-C7),"0") -> 0 | I36: =IF(I7="X",(D7-C7),"0") -> 0 | J36: =IF(J7="X",(D7-C7),"0") -> 1 | K36: =IF(K7="X",(D7-C7),"0") -> 0
E37: =IF(E8="X",(D8-C8),"0") -> 1 | F37: =IF(F8="X",(D8-C8),"0") -> 0 | G37: =IF(G8="X",(D8-C8),"0") -> 0 | H37: =IF(H8="X",(D8-C8),"0") -> 0 | I37: =IF(I8="X",(D8-C8),"0") -> 0 | J37: =IF(J8="X",(D8-C8),"0") -> 1 | K37: =IF(K8="X",(D8-C8),"0") -> 0
E38: =IF(E9="X",(D9-C9),"0") -> 1 | F38: =IF(F9="X",(D9-C9),"0") -> 0 | G38: =IF(G9="X",(D9-C9),"0") -> 0 | H38: =IF(H9="X",(D9-C9),"0") -> 0 | I38: =IF(I9="X",(D9-C9),"0") -> 0 | J38: =IF(J9="X",(D9-C9),"0") -> 1 | K38: =IF(K9="X",(D9-C9),"0") -> 0
E39: =IF(E10="X",(D10-C10),"0") -> 0 | F39: =IF(F10="X",(D10-C10),"0") -> 1 | G39: =IF(G10="X",(D10-C10),"0") -> 0 | H39: =IF(H10="X",(D10-C10),"0") -> 0 | I39: =IF(I10="X",(D10-C10),"0") -> 0 | J39: =IF(J10="X",(D10-C10),"0") -> 1 | K39: =IF(K10="X",(D10-C10),"0") -> 0
E40: =IF(E11="X",(D11-C11),"0") -> 0 | F40: =IF(F11="X",(D11-C11),"0") -> 1 | G40: =IF(G11="X",(D11-C11),"0") -> 0 | H40: =IF(H11="X",(D11-C11),"0") -> 0 | I40: =IF(I11="X",(D11-C11),"0") -> 0 | J40: =IF(J11="X",(D11-C11),"0") -> 1 | K40: =IF(K11="X",(D11-C11),"0") -> 0
E41: =IF(E12="X",(D12-C12),"0") -> 0 | F41: =IF(F12="X",(D12-C12),"0") -> 1 | G41: =IF(G12="X",(D12-C12),"0") -> 0 | H41: =IF(H12="X",(D12-C12),"0") -> 0 | I41: =IF(I12="X",(D12-C12),"0") -> 0 | J41: =IF(J12="X",(D12-C12),"0") -> 1 | K41: =IF(K12="X",(D12-C12),"0") -> 0
E42: =IF(E13="X",(D13-C13),"0") -> 0 | F42: =IF(F13="X",(D13-C13),"0") -> 1 | G42: =IF(G13="X",(D13-C13),"0") -> 0 | H42: =IF(H13="X",(D13-C13),"0") -> 0 | I42: =IF(I13="X",(D13-C13),"0") -> 0 | J42: =IF(J13="X",(D13-C13),"0") -> 1 | K42: =IF(K13="X",(D13-C13),"0") -> 0
E43: =IF(E14="X",(D14-C14),"0") -> 0 | F43: =IF(F14="X",(D14-C14),"0") -> 1 | G43: =IF(G14="X",(D14-C14),"0") -> 0 | H43: =IF(H14="X",(D14-C14),"0") -> 0 | I43: =IF(I14="X",(D14-C14),"0") -> 0 | J43: =IF(J14="X",(D14-C14),"0") -> 1 | K43: =IF(K14="X",(D14-C14),"0") -> 0
E44: =IF(E15="X",(D15-C15),"0") -> 0 | F44: =IF(F15="X",(D15-C15),"0") -> 1 | G44: =IF(G15="X",(D15-C15),"0") -> 0 | H44: =IF(H15="X",(D15-C15),"0") -> 0 | I44: =IF(I15="X",(D15-C15),"0") -> 0 | J44: =IF(J15="X",(D15-C15),"0") -> 1 | K44: =IF(K15="X",(D15-C15),"0") -> 0
E45: =IF(E16="X",(D16-C16),"0") -> 0 | F45: =IF(F16="X",(D16-C16),"0") -> 1 | G45: =IF(G16="X",(D16-C16),"0") -> 0 | H45: =IF(H16="X",(D16-C16),"0") -> 0 | I45: =IF(I16="X",(D16-C16),"0") -> 0 | J45: =IF(J16="X",(D16-C16),"0") -> 1 | K45: =IF(K16="X",(D16-C16),"0") -> 0
E46: =IF(E17="X",(D17-C17),"0") -> 0 | F46: =IF(F17="X",(D17-C17),"0") -> 1 | G46: =IF(G17="X",(D17-C17),"0") -> 0 | H46: =IF(H17="X",(D17-C17),"0") -> 0 | I46: =IF(I17="X",(D17-C17),"0") -> 0 | J46: =IF(J17="X",(D17-C17),"0") -> 1 | K46: =IF(K17="X",(D17-C17),"0") -> 0
E47: =IF(E18="X",(D18-C18),"0") -> 0 | F47: =IF(F18="X",(D18-C18),"0") -> 1 | G47: =IF(G18="X",(D18-C18),"0") -> 0 | H47: =IF(H18="X",(D18-C18),"0") -> 0 | I47: =IF(I18="X",(D18-C18),"0") -> 0 | J47: =IF(J18="X",(D18-C18),"0") -> 1 | K47: =IF(K18="X",(D18-C18),"0") -> 0
... E61: =IF(E32="X",(D32-C32),"0") -> 0 | F61: =IF(F32="X",(D32-C32),"0") -> 0 | G61: =IF(G32="X",(D32-C32),"0") -> 0 | H61: =IF(H32="X",(D32-C32),"0") -> 0 | I61: =IF(I32="X",(D32-C32),"0") -> 0 | J61: =IF(J32="X",(D32-C32),"0") -> 0 | K61: =IF(K32="X",(D32-C32),"0") -> 0
E62: =SUM(E36:E61) -> 3 | F62: =SUM(F36:F61) -> 11.27 | G62: =SUM(G36:G61) -> 0 | H62: =SUM(H36:H61) -> 0 | I62: =SUM(I36:I61) -> 0 | J62: =SUM(J36:J61) -> 14.27 | K62: =SUM(K36:K61) -> 0

Sheet 27
A1: PROGRAMA DE MANUTENÇÃORODOVIÁRIA | I1: DATA: | J1: ='1'!J1 -> 46204 | L1: TÉCNICO RESP. | N1: LABORATORISTA -CLAUDIOMIRO VIEIRA LOPES
F2: RODOVIAS NÃO PAVIMENTADAS
A3: FICHA DE INSPEÇÃO: | B3: =TT!C12 -> RODOVIA TO-403 - TRECHO CARRASCO BONITO - SAMPAIO
A5: S.R.E. | B5: SENTIDO | C5: INÍCIO (KM) | D5: FIM (KM) | E5: CONDIÇÃO DA PLATAFORMA | I5: DRENAGEM SUPERFICIAL | L5: OBSERV.
E6: BOM | F6: REG. (ATÉ 10 IRR./KM) | G6: RUÍM (+ 10 IRR./KM) | H6: PÉSSIMA (ATOLEIRO/PTO. CRÍTICO) | I6: LIMPA | J6: OBSTRUÍDA | K6: AUSENTE
A7: 403ETO0010 | B7: C | C7: =D6 -> 0 | D7: 2 | F7: X | I7: X | L7: PONTE DE CONCRETO KM-0,400 (4.45/12.0)
C8: 0 | D8: 2 | E8: X | J8: X | L8: BUEIRO DUPLO KM-0,800 (0.70/0.70)
C9: =D8 -> 2 | D9: 4 | E9: X | J9: X | L9: BUEIRO DUPLO KM-5,500 (2.00/2.00)
C10: =D8 -> 2 | D10: 4 | F10: X | I10: X
C11: =D10 -> 4 | D11: 6 | G11: X | J11: X
C12: =D11 -> 6 | D12: 8 | F12: X | I12: X
C13: =D11 -> 6 | D13: 8 | E13: X | I13: X
C14: =D13 -> 8 | D14: 10 | F14: X | I14: X
C15: =D14 -> 10 | D15: 10.6 | F15: X | I15: X
A19: 403ETO0020 | B19: C | C19: 0 | D19: 2 | F19: X | K19: X | L19: PONTE DE CONCRETO KM-1,00 (3.40/24.00)
C20: =D19 -> 2 | D20: 4 | F20: X | K20: X | L20: PONTE DE MADEIRA KM-1,10 (4.30/4.40)
C21: =D20 -> 4 | D21: 6 | F21: X | J21: X | L21: PONTE DE CONCRETO KM-1,40 (4.50/10.40)
C22: =D21 -> 6 | D22: 7.2 | G22: X | K22: X | L22: BUEIRO DUPLO KM-5,00 (1.10/1.10)
E36: =IF(E7="X",(D7-C7),"0") -> 0 | F36: =IF(F7="X",(D7-C7),"0") -> 2 | G36: =IF(G7="X",(D7-C7),"0") -> 0 | H36: =IF(H7="X",(D7-C7),"0") -> 0 | I36: =IF(I7="X",(D7-C7),"0") -> 2 | J36: =IF(J7="X",(D7-C7),"0") -> 0 | K36: =IF(K7="X",(D7-C7),"0") -> 0
E37: =IF(E8="X",(D8-C8),"0") -> 2 | F37: =IF(F8="X",(D8-C8),"0") -> 0 | G37: =IF(G8="X",(D8-C8),"0") -> 0 | H37: =IF(H8="X",(D8-C8),"0") -> 0 | I37: =IF(I8="X",(D8-C8),"0") -> 0 | J37: =IF(J8="X",(D8-C8),"0") -> 2 | K37: =IF(K8="X",(D8-C8),"0") -> 0
E38: =IF(E9="X",(D9-C9),"0") -> 2 | F38: =IF(F9="X",(D9-C9),"0") -> 0 | G38: =IF(G9="X",(D9-C9),"0") -> 0 | H38: =IF(H9="X",(D9-C9),"0") -> 0 | I38: =IF(I9="X",(D9-C9),"0") -> 0 | J38: =IF(J9="X",(D9-C9),"0") -> 2 | K38: =IF(K9="X",(D9-C9),"0") -> 0
E39: =IF(E10="X",(D10-C10),"0") -> 0 | F39: =IF(F10="X",(D10-C10),"0") -> 2 | G39: =IF(G10="X",(D10-C10),"0") -> 0 | H39: =IF(H10="X",(D10-C10),"0") -> 0 | I39: =IF(I10="X",(D10-C10),"0") -> 2 | J39: =IF(J10="X",(D10-C10),"0") -> 0 | K39: =IF(K10="X",(D10-C10),"0") -> 0
E40: =IF(E11="X",(D11-C11),"0") -> 0 | F40: =IF(F11="X",(D11-C11),"0") -> 0 | G40: =IF(G11="X",(D11-C11),"0") -> 2 | H40: =IF(H11="X",(D11-C11),"0") -> 0 | I40: =IF(I11="X",(D11-C11),"0") -> 0 | J40: =IF(J11="X",(D11-C11),"0") -> 2 | K40: =IF(K11="X",(D11-C11),"0") -> 0
E41: =IF(E12="X",(D12-C12),"0") -> 0 | F41: =IF(F12="X",(D12-C12),"0") -> 2 | G41: =IF(G12="X",(D12-C12),"0") -> 0 | H41: =IF(H12="X",(D12-C12),"0") -> 0 | I41: =IF(I12="X",(D12-C12),"0") -> 2 | J41: =IF(J12="X",(D12-C12),"0") -> 0 | K41: =IF(K12="X",(D12-C12),"0") -> 0
E42: =IF(E13="X",(D13-C13),"0") -> 2 | F42: =IF(F13="X",(D13-C13),"0") -> 0 | G42: =IF(G13="X",(D13-C13),"0") -> 0 | H42: =IF(H13="X",(D13-C13),"0") -> 0 | I42: =IF(I13="X",(D13-C13),"0") -> 2 | J42: =IF(J13="X",(D13-C13),"0") -> 0 | K42: =IF(K13="X",(D13-C13),"0") -> 0
E43: =IF(E14="X",(D14-C14),"0") -> 0 | F43: =IF(F14="X",(D14-C14),"0") -> 2 | G43: =IF(G14="X",(D14-C14),"0") -> 0 | H43: =IF(H14="X",(D14-C14),"0") -> 0 | I43: =IF(I14="X",(D14-C14),"0") -> 2 | J43: =IF(J14="X",(D14-C14),"0") -> 0 | K43: =IF(K14="X",(D14-C14),"0") -> 0
E44: =IF(E15="X",(D15-C15),"0") -> 0 | F44: =IF(F15="X",(D15-C15),"0") -> 0.6 | G44: =IF(G15="X",(D15-C15),"0") -> 0 | H44: =IF(H15="X",(D15-C15),"0") -> 0 | I44: =IF(I15="X",(D15-C15),"0") -> 0.6 | J44: =IF(J15="X",(D15-C15),"0") -> 0 | K44: =IF(K15="X",(D15-C15),"0") -> 0
E45: =IF(E16="X",(D16-C16),"0") -> 0 | F45: =IF(F16="X",(D16-C16),"0") -> 0 | G45: =IF(G16="X",(D16-C16),"0") -> 0 | H45: =IF(H16="X",(D16-C16),"0") -> 0 | I45: =IF(I16="X",(D16-C16),"0") -> 0 | J45: =IF(J16="X",(D16-C16),"0") -> 0 | K45: =IF(K16="X",(D16-C16),"0") -> 0
E46: =IF(E17="X",(D17-C17),"0") -> 0 | F46: =IF(F17="X",(D17-C17),"0") -> 0 | G46: =IF(G17="X",(D17-C17),"0") -> 0 | H46: =IF(H17="X",(D17-C17),"0") -> 0 | I46: =IF(I17="X",(D17-C17),"0") -> 0 | J46: =IF(J17="X",(D17-C17),"0") -> 0 | K46: =IF(K17="X",(D17-C17),"0") -> 0
E47: =IF(E18="X",(D18-C18),"0") -> 0 | F47: =IF(F18="X",(D18-C18),"0") -> 0 | G47: =IF(G18="X",(D18-C18),"0") -> 0 | H47: =IF(H18="X",(D18-C18),"0") -> 0 | I47: =IF(I18="X",(D18-C18),"0") -> 0 | J47: =IF(J18="X",(D18-C18),"0") -> 0 | K47: =IF(K18="X",(D18-C18),"0") -> 0
... E61: =IF(E32="X",(D32-C32),"0") -> 0 | F61: =IF(F32="X",(D32-C32),"0") -> 0 | G61: =IF(G32="X",(D32-C32),"0") -> 0 | H61: =IF(H32="X",(D32-C32),"0") -> 0 | I61: =IF(I32="X",(D32-C32),"0") -> 0 | J61: =IF(J32="X",(D32-C32),"0") -> 0 | K61: =IF(K32="X",(D32-C32),"0") -> 0
E62: =SUM(E36:E61) -> 6 | F62: =SUM(F36:F61) -> 14.6 | G62: =SUM(G36:G61) -> 3.2 | H62: =SUM(H36:H61) -> 0 | I62: =SUM(I36:I61) -> 10.6 | J62: =SUM(J36:J61) -> 8 | K62: =SUM(K36:K61) -> 5.2

Sheet 31
A1: PROGRAMA DE MANUTENÇÃORODOVIÁRIA | I1: DATA: | J1: ='1'!J1 -> 46204 | L1: TÉCNICO RESP. | N1: ENG. VINICIUS RODRIGUES
F2: RODOVIAS NÃO PAVIMENTADAS
A3: FICHA DE INSPEÇÃO: | B3: =TT!C13 -> RODOVIA TO-405 - TRECHO AXIXÁ DO TOCANTINS - ENTR. BR-230
A5: S.R.E. | B5: SENTIDO | C5: INÍCIO (KM) | D5: FIM (KM) | E5: CONDIÇÃO DA PLATAFORMA | I5: DRENAGEM SUPERFICIAL | L5: OBSERV.
E6: BOM | F6: REG. (ATÉ 10 IRR./KM) | G6: RUÍM (+ 10 IRR./KM) | H6: PÉSSIMA (ATOLEIRO/PTO. CRÍTICO) | I6: LIMPA | J6: OBSTRUÍDA | K6: AUSENTE
A7: 405ETO020 | B7: C | C7: 0 | D7: 1 | E7: X | I7: X
C8: =D7 -> 1 | D8: 2 | E8: X | I8: X
C9: =D8 -> 2 | D9: 2.64 | E9: X | I9: X
A10: 405ETO030 | B10: C | C10: 0 | D10: 1 | F10: X | I10: X
C11: =D10 -> 1 | D11: 2 | F11: X | I11: X
C12: =D11 -> 2 | D12: 3 | F12: X | I12: X
C13: =D12 -> 3 | D13: 4 | F13: X | I13: X
C14: =D13 -> 4 | D14: 4.91 | F14: X | I14: X
A15: 405ETO040 | B15: C | C15: 0 | D15: 1 | E15: X | I15: X
C16: =D15 -> 1 | D16: 2 | E16: X | I16: X
C17: =D16 -> 2 | D17: 3 | F17: X | I17: X
C18: =D17 -> 3 | D18: 4 | F18: X | I18: X
C19: =D18 -> 4 | D19: 5 | F19: X | I19: X
C20: =D19 -> 5 | D20: 6 | F20: X | I20: X
C21: =D20 -> 6 | D21: 7 | F21: X | I21: X
C22: =D21 -> 7 | D22: 8 | F22: X | I22: X
C23: =D22 -> 8 | D23: 9 | F23: X | I23: X
C24: =D23 -> 9 | D24: 10 | F24: X | I24: X
C25: =D24 -> 10 | D25: 11 | F25: X | I25: X
C26: =D25 -> 11 | D26: 12 | F26: X | I26: X
C27: =D26 -> 12 | D27: 13 | F27: X | I27: X
C28: =D27 -> 13 | D28: 14 | F28: X | I28: X
C29: =D28 -> 14 | D29: 15 | F29: X | I29: X
C30: =D29 -> 15 | D30: 16 | F30: X | J30: X
C31: =D30 -> 16 | D31: 17 | F31: X | J31: X
C32: =D31 -> 17 | D32: 18 | F32: X | J32: X
C33: =D32 -> 18 | D33: 18.04 | F33: X | J33: X
A34: 405ETO050 | B34: C | C34: 0 | D34: 1 | F34: X | J34: X
C35: =D34 -> 1 | D35: 2 | F35: X | J35: X
C36: =D35 -> 2 | D36: 3 | F36: X | J36: X
C37: =D36 -> 3 | D37: 4 | F37: X | J37: X
C38: =D37 -> 4 | D38: 5 | F38: X | J38: X
C39: =D38 -> 5 | D39: 6 | F39: X | J39: X
C40: =D39 -> 6 | D40: 7 | F40: X | J40: X
C41: =D40 -> 7 | D41: 8 | F41: X | J41: X
...

Sheet 33
A1: PROGRAMA DE MANUTENÇÃORODOVIÁRIA | I1: DATA: | J1: ='1'!J1 -> 46204 | L1: TÉCNICO RESP. | N1: ENG. VINICIUS RODRIGUES
F2: RODOVIAS NÃO PAVIMENTADAS
A3: FICHA DE INSPEÇÃO: | B3: =TT!C14 -> RODOVIA TO-409 - TRECHO MAURILÂNDIA - ENTR. TO-134
A5: S.R.E. | B5: SENTIDO | C5: INÍCIO (KM) | D5: FIM (KM) | E5: CONDIÇÃO DA PLATAFORMA | I5: DRENAGEM SUPERFICIAL | L5: OBSERV.
E6: BOM | F6: REG. (ATÉ 10 IRR./KM) | G6: RUÍM (+ 10 IRR./KM) | H6: PÉSSIMA (ATOLEIRO/PTO. CRÍTICO) | I6: LIMPA | J6: OBSTRUÍDA | K6: AUSENTE
A7: 409ETO0020 | B7: D | C7: 0 | D7: 1 | F7: X | I7: X
C8: =D7 -> 1 | D8: 2 | F8: X | I8: X
C9: =D8 -> 2 | D9: 3 | F9: X | I9: X
C10: =D9 -> 3 | D10: 4 | E10: X | I10: X
C11: =D10 -> 4 | D11: 5 | E11: X | I11: X
C12: =D11 -> 5 | D12: 6 | F12: X | I12: X
C13: =D12 -> 6 | D13: 7 | F13: X | I13: X
C14: =D13 -> 7 | D14: 8 | F14: X | I14: X
C15: =D14 -> 8 | D15: 9 | F15: X | I15: X
C16: =D15 -> 9 | D16: 10 | E16: X | J16: X
C17: =D16 -> 10 | D17: 11 | E17: X | J17: X
C18: =D17 -> 11 | D18: 12 | E18: X | J18: X
C19: =D18 -> 12 | D19: 13 | E19: X | J19: X
C20: =D19 -> 13 | D20: 14 | E20: X | J20: X
C21: =D20 -> 14 | D21: 15 | E21: X | J21: X
C22: =D21 -> 15 | D22: 16 | E22: X | J22: X
C23: =D22 -> 16 | D23: 17 | F23: X | J23: X
C24: =D23 -> 17 | D24: 18 | F24: X | J24: X
C25: =D24 -> 18 | D25: 18.41 | F25: X | J25: X
A26: 409ETO0030 | B26: D | C26: 0 | D26: 1 | E26: X | J26: X
C27: =D26 -> 1 | D27: 2 | E27: X | J27: X
C28: =D27 -> 2 | D28: 3 | E28: X | J28: X
C29: =D28 -> 3 | D29: 4 | E29: X | J29: X
C30: =D29 -> 4 | D30: 5 | E30: X | J30: X
C31: =D30 -> 5 | D31: 6 | E31: X | J31: X
C32: =D31 -> 6 | D32: 7 | E32: X | J32: X
C33: =D32 -> 7 | D33: 8 | F33: X | J33: X
C34: =D33 -> 8 | D34: 9 | F34: X | J34: X
C35: =D34 -> 9 | D35: 10 | E35: X | J35: X
C36: =D35 -> 10 | D36: 11 | E36: X | J36: X
C37: =D36 -> 11 | D37: 12 | E37: X | I37: X
C38: =D37 -> 12 | D38: 13 | E38: X | I38: X
C39: =D38 -> 13 | D39: 14 | E39: X | I39: X
C40: =D39 -> 14 | D40: 15 | E40: X | I40: X
C41: =D40 -> 15 | D41: 16 | E41: X | I41: X
...

Sheet 34
A1: PROGRAMA DE MANUTENÇÃORODOVIÁRIA | I1: DATA: | J1: ='1'!J1 -> 46204 | L1: TÉCNICO RESP. | N1: LABORATORISTA -CLAUDIOMIRO VIEIRA LOPES
F2: RODOVIAS NÃO PAVIMENTADAS
A3: FICHA DE INSPEÇÃO: | B3: =TT!C15 -> RODOVIA TO-414 - TRECHO CACHOEIRINHA - ENTR. TO-010 (TAPUIO)
A5: S.R.E. | B5: SENTIDO | C5: INÍCIO (KM) | D5: FIM (KM) | E5: CONDIÇÃO DA PLATAFORMA | I5: DRENAGEM SUPERFICIAL | L5: OBSERV.
E6: BOM | F6: REG. (ATÉ 10 IRR./KM) | G6: RUÍM (+ 10 IRR./KM) | H6: PÉSSIMA (ATOLEIRO/PTO. CRÍTICO) | I6: LIMPA | J6: OBSTRUÍDA | K6: AUSENTE
A7: 414ETO0020 | B7: C | C7: 0 | D7: 2 | F7: X | K7: X | L7: PONTE DE CONCRETO KM-0,0 (4.45/20,30)
C8: =D7 -> 2 | D8: 4 | F8: X | J8: X | L8: POSSIVEL ATOLEIRO KM-1,1 E SEM DRENAGEM
C9: =D8 -> 4 | D9: 6 | F9: X | K9: X | L9: POSSIVEL ATOLEIRO KM-1,7 E EROZAO ( 1,0 / 10,0)
C10: =D9 -> 6 | D10: 8 | F10: X | I10: X | L10: EROZAO KM-4,2 ( 1,0 / 4,0 )
C11: =D10 -> 8 | D11: 10 | E11: X | I11: X | L11: EROZAO KM-4,9 ( 1,0 / 6,0 )
C12: =D11 -> 10 | D12: 12 | E12: X | I12: X | L12: PONTE DE CONCRETO KM-9,1 (4.45/34,40)
C13: =D12 -> 12 | D13: 14 | E13: X | I13: X | L13: EROZAO KM-20,4 ( 2,0 / 10,0 )
C14: =D13 -> 14 | D14: 16 | E14: X | I14: X | L14: EROZAO KM-27,4 ( 1,0 / 10,0 )
C15: =D14 -> 16 | D15: 18 | E15: X | I15: X | L15: EROZAO KM-24,5 ( 3,5 / 11,0 )
C16: =D15 -> 18 | D16: 20 | E16: X | I16: X | L16: PONTE DE CONCRETO KM-28,2 (4.45/25,0)
C17: =D16 -> 20 | D17: 22 | F17: X | I17: X | L17: POSSIVEL ATOLEIRO KM-28,9
C18: =D17 -> 22 | D18: 24 | F18: X | J18: X | L18: FAZER PATROLAMENTO DO KM-0,0 A 6,00 E KM-20,00 A 29,00
C19: =D18 -> 24 | D19: 26 | F19: X | J19: X
C20: =D19 -> 26 | D20: 28 | F20: X | J20: X
C21: =D20 -> 28 | D21: 30 | F21: X | J21: X
C22: =D21 -> 30 | D22: 31.6 | F22: X | J22: X
E45: =IF(E7="X",(D7-C7),"0") -> 0 | F45: =IF(F7="X",(D7-C7),"0") -> 2 | G45: =IF(G7="X",(D7-C7),"0") -> 0 | H45: =IF(H7="X",(D7-C7),"0") -> 0 | I45: =IF(I7="X",(D7-C7),"0") -> 0 | J45: =IF(J7="X",(D7-C7),"0") -> 0 | K45: =IF(K7="X",(D7-C7),"0") -> 2
E46: =IF(E8="X",(D8-C8),"0") -> 0 | F46: =IF(F8="X",(D8-C8),"0") -> 2 | G46: =IF(G8="X",(D8-C8),"0") -> 0 | H46: =IF(H8="X",(D8-C8),"0") -> 0 | I46: =IF(I8="X",(D8-C8),"0") -> 0 | J46: =IF(J8="X",(D8-C8),"0") -> 2 | K46: =IF(K8="X",(D8-C8),"0") -> 0
E47: =IF(E9="X",(D9-C9),"0") -> 0 | F47: =IF(F9="X",(D9-C9),"0") -> 2 | G47: =IF(G9="X",(D9-C9),"0") -> 0 | H47: =IF(H9="X",(D9-C9),"0") -> 0 | I47: =IF(I9="X",(D9-C9),"0") -> 0 | J47: =IF(J9="X",(D9-C9),"0") -> 0 | K47: =IF(K9="X",(D9-C9),"0") -> 2
E48: =IF(E10="X",(D10-C10),"0") -> 0 | F48: =IF(F10="X",(D10-C10),"0") -> 2 | G48: =IF(G10="X",(D10-C10),"0") -> 0 | H48: =IF(H10="X",(D10-C10),"0") -> 0 | I48: =IF(I10="X",(D10-C10),"0") -> 2 | J48: =IF(J10="X",(D10-C10),"0") -> 0 | K48: =IF(K10="X",(D10-C10),"0") -> 0
E49: =IF(E11="X",(D11-C11),"0") -> 2 | F49: =IF(F11="X",(D11-C11),"0") -> 0 | G49: =IF(G11="X",(D11-C11),"0") -> 0 | H49: =IF(H11="X",(D11-C11),"0") -> 0 | I49: =IF(I11="X",(D11-C11),"0") -> 2 | J49: =IF(J11="X",(D11-C11),"0") -> 0 | K49: =IF(K11="X",(D11-C11),"0") -> 0
E50: =IF(E12="X",(D12-C12),"0") -> 2 | F50: =IF(F12="X",(D12-C12),"0") -> 0 | G50: =IF(G12="X",(D12-C12),"0") -> 0 | H50: =IF(H12="X",(D12-C12),"0") -> 0 | I50: =IF(I12="X",(D12-C12),"0") -> 2 | J50: =IF(J12="X",(D12-C12),"0") -> 0 | K50: =IF(K12="X",(D12-C12),"0") -> 0
E51: =IF(E13="X",(D13-C13),"0") -> 2 | F51: =IF(F13="X",(D13-C13),"0") -> 0 | G51: =IF(G13="X",(D13-C13),"0") -> 0 | H51: =IF(H13="X",(D13-C13),"0") -> 0 | I51: =IF(I13="X",(D13-C13),"0") -> 2 | J51: =IF(J13="X",(D13-C13),"0") -> 0 | K51: =IF(K13="X",(D13-C13),"0") -> 0
E52: =IF(E14="X",(D14-C14),"0") -> 2 | F52: =IF(F14="X",(D14-C14),"0") -> 0 | G52: =IF(G14="X",(D14-C14),"0") -> 0 | H52: =IF(H14="X",(D14-C14),"0") -> 0 | I52: =IF(I14="X",(D14-C14),"0") -> 2 | J52: =IF(J14="X",(D14-C14),"0") -> 0 | K52: =IF(K14="X",(D14-C14),"0") -> 0
E53: =IF(E15="X",(D15-C15),"0") -> 2 | F53: =IF(F15="X",(D15-C15),"0") -> 0 | G53: =IF(G15="X",(D15-C15),"0") -> 0 | H53: =IF(H15="X",(D15-C15),"0") -> 0 | I53: =IF(I15="X",(D15-C15),"0") -> 2 | J53: =IF(J15="X",(D15-C15),"0") -> 0 | K53: =IF(K15="X",(D15-C15),"0") -> 0
E54: =IF(E16="X",(D16-C16),"0") -> 2 | F54: =IF(F16="X",(D16-C16),"0") -> 0 | G54: =IF(G16="X",(D16-C16),"0") -> 0 | H54: =IF(H16="X",(D16-C16),"0") -> 0 | I54: =IF(I16="X",(D16-C16),"0") -> 2 | J54: =IF(J16="X",(D16-C16),"0") -> 0 | K54: =IF(K16="X",(D16-C16),"0") -> 0
E55: =IF(E17="X",(D17-C17),"0") -> 0 | F55: =IF(F17="X",(D17-C17),"0") -> 2 | G55: =IF(G17="X",(D17-C17),"0") -> 0 | H55: =IF(H17="X",(D17-C17),"0") -> 0 | I55: =IF(I17="X",(D17-C17),"0") -> 2 | J55: =IF(J17="X",(D17-C17),"0") -> 0 | K55: =IF(K17="X",(D17-C17),"0") -> 0
E56: =IF(E18="X",(D18-C18),"0") -> 0 | F56: =IF(F18="X",(D18-C18),"0") -> 2 | G56: =IF(G18="X",(D18-C18),"0") -> 0 | H56: =IF(H18="X",(D18-C18),"0") -> 0 | I56: =IF(I18="X",(D18-C18),"0") -> 0 | J56: =IF(J18="X",(D18-C18),"0") -> 2 | K56: =IF(K18="X",(D18-C18),"0") -> 0
... E84: =IF(E46="X",(D46-C46),"0") -> 0 | F84: =IF(F46="X",(D46-C46),"0") -> 0 | G84: =IF(G46="X",(D46-C46),"0") -> 0 | H84: =IF(H46="X",(D46-C46),"0") -> 0 | I84: =IF(I46="X",(D46-C46),"0") -> 0 | J84: =IF(J46="X",(D46-C46),"0") -> 0 | K84: =IF(K46="X",(D46-C46),"0") -> 0
E85: =SUM(E45:E84) -> 12 | F85: =SUM(F45:F84) -> 19.6 | G85: =SUM(G45:G84) -> 0 | H85: =SUM(H45:H84) -> 0 | I85: =SUM(I45:I84) -> 16 | J85: =SUM(J45:J84) -> 11.6 | K85: =SUM(K45:K84) -> 4

Sheet 37
