Workbook

Sheet RESUMO
A1: RESUMO CONSOLIDADO — REGIÃO 1 — RODOVIAS NÃO PAVIMENTADAS | M1: Valores dos gráficos — troca 0 por N/D para a fatia não aparecer. Não editar.
A2: Todos os números vêm das abas dos trechos por referência direta. Não digite nada aqui. A coluna CONFERÊNCIA acusa qualquer trecho em que a soma das marcações não fecha com a extensão. | M2: =IF(D16=0,NA(),D16) -> 54.607987 | N2: =IF(E16=0,NA(),E16) -> 324.7225 | O2: =IF(F16=0,NA(),F16) -> 27.554416 | P2: =IF(G16=0,NA(),G16) -> #N/A | Q2: =IF(H16=0,NA(),H16) -> 62.607987 | R2: =IF(I16=0,NA(),I16) -> 344.27692 | S2: =IF(J16=0,NA(),J16) -> #N/A
A4: Nº TRECHO | B4: TRECHO | C4: EXTENSÃO (KM) | D4: CONDIÇÃO DA PLATAFORMA | H4: DRENAGEM SUPERFICIAL | K4: CONFERÊNCIA
D5: BOM | E5: REG. (ATÉ 10 IRR./KM) | F5: RUIM (+ 10 IRR./KM) | G5: PÉSSIMA (ATOLEIRO/PTO. CRÍTICO) | H5: LIMPA | I5: OBSTRUÍDA | J5: AUSENTE
A6: 46 | B6: RODOVIA TO-164 - TRECHO ENTR. TO-226 - POVOADO DEZENOVE - BERNARDO SAYÃO | C6: ='46'!I45 -> 27.973982 | D6: ='46'!F42 -> 0 | E6: ='46'!G42 -> 27.973982 | F6: ='46'!H42 -> 0 | G6: ='46'!I42 -> 0 | H6: ='46'!J42 -> 0 | I6: ='46'!K42 -> 27.973982 | J6: ='46'!L42 -> 0 | K6: =IF(SUM(D6:G6)=0,"— não preenchido",IF(ROUND(SUM(D6:G6)-C6,3)=0,"OK","ERRO — dif. de "&ROUND(SUM(D6:G6)-C6,3)&" km")) -> OK
A7: 47 | B7: RODOVIA TO-164 - TRECHO MURICILÂNDIA - ENTR. TO-226 | C7: ='47'!I63 -> 43.321833 | D7: ='47'!F60 -> 5 | E7: ='47'!G60 -> 33.321833 | F7: ='47'!H60 -> 5 | G7: ='47'!I60 -> 0 | H7: ='47'!J60 -> 0 | I7: ='47'!K60 -> 43.321833 | J7: ='47'!L60 -> 0 | K7: =IF(SUM(D7:G7)=0,"— não preenchido",IF(ROUND(SUM(D7:G7)-C7,3)=0,"OK","ERRO — dif. de "&ROUND(SUM(D7:G7)-C7,3)&" km")) -> OK
A8: 48 | B8: RODOVIA TO-165 - TRECHO SANTA FÉ DO ARAGUAIA - ENTR. TO-226 - ARAPOEMA | C8: ='48'!I112 -> 92.523276 | D8: ='48'!F109 -> 0 | E8: ='48'!G109 -> 80.523276 | F8: ='48'!H109 -> 12 | G8: ='48'!I109 -> 0 | H8: ='48'!J109 -> 0 | I8: ='48'!K109 -> 92.523276 | J8: ='48'!L109 -> 0 | K8: =IF(SUM(D8:G8)=0,"— não preenchido",IF(ROUND(SUM(D8:G8)-C8,3)=0,"OK","ERRO — dif. de "&ROUND(SUM(D8:G8)-C8,3)&" km")) -> OK
A9: 49 | B9: RODOVIA TO-166 - TRECHO ENTR. TO-222 - ENTR. TO-226 - ARAPOEMA | C9: ='49'!I112 -> 91.536749 | D9: ='49'!F109 -> 0 | E9: ='49'!G109 -> 91.536749 | F9: ='49'!H109 -> 0 | G9: ='49'!I109 -> 0 | H9: ='49'!J109 -> 0 | I9: ='49'!K109 -> 91.536749 | J9: ='49'!L109 -> 0 | K9: =IF(SUM(D9:G9)=0,"— não preenchido",IF(ROUND(SUM(D9:G9)-C9,3)=0,"OK","ERRO — dif. de "&ROUND(SUM(D9:G9)-C9,3)&" km")) -> OK
A10: 59 | B10: RODOVIA TO-418 - TRECHO ENTR. BR-153 - ENTR. TO-164 | C10: ='59'!I61 -> 43.086791 | D10: ='59'!F58 -> 0 | E10: ='59'!G58 -> 43.086791 | F10: ='59'!H58 -> 0 | G10: ='59'!I58 -> 0 | H10: ='59'!J58 -> 0 | I10: ='59'!K58 -> 43.086791 | J10: ='59'!L58 -> 0 | K10: =IF(SUM(D10:G10)=0,"— não preenchido",IF(ROUND(SUM(D10:G10)-C10,3)=0,"OK","ERRO — dif. de "&ROUND(SUM(D10:G10)-C10,3)&" km")) -> OK
A11: 60 | B11: RODOVIA TO-419 - TRECHO POVOADO BARRA DA GROTA - ENTR. TO-222 | C11: ='60'!I47 -> 29.115565 | D11: ='60'!F44 -> 23.115565 | E11: ='60'!G44 -> 6 | F11: ='60'!H44 -> 0 | G11: ='60'!I44 -> 0 | H11: ='60'!J44 -> 29.115565 | I11: ='60'!K44 -> 0 | J11: ='60'!L44 -> 0 | K11: =IF(SUM(D11:G11)=0,"— não preenchido",IF(ROUND(SUM(D11:G11)-C11,3)=0,"OK","ERRO — dif. de "&ROUND(SUM(D11:G11)-C11,3)&" km")) -> OK
A12: 62 | B12: RODOVIA TO-421 - TRECHO ARAGUAÍNA - POVOADO GROTÃO | C12: ='62'!I33 -> 13.554416 | D12: ='62'!F30 -> 0 | E12: ='62'!G30 -> 3 | F12: ='62'!H30 -> 10.554416 | G12: ='62'!I30 -> 0 | H12: ='62'!J30 -> 0 | I12: ='62'!K30 -> 13.554416 | J12: ='62'!L30 -> 0 | K12: =IF(SUM(D12:G12)=0,"— não preenchido",IF(ROUND(SUM(D12:G12)-C12,3)=0,"OK","ERRO — dif. de "&ROUND(SUM(D12:G12)-C12,3)&" km")) -> OK
A13: 64 | B13: RODOVIA TO-429 - TRECHO ENTR. TO-230 (ARAPOEMA) - POVOADO ARACAJI | C13: ='64'!I34 -> 16.852537 | D13: ='64'!F31 -> 12.852537 | E13: ='64'!G31 -> 4 | F13: ='64'!H31 -> 0 | G13: ='64'!I31 -> 0 | H13: ='64'!J31 -> 16.852537 | I13: ='64'!K31 -> 0 | J13: ='64'!L31 -> 0 | K13: =IF(SUM(D13:G13)=0,"— não preenchido",IF(ROUND(SUM(D13:G13)-C13,3)=0,"OK","ERRO — dif. de "&ROUND(SUM(D13:G13)-C13,3)&" km")) -> OK
A14: 65 | B14: RODOVIA TO-430 - TRECHO POVOADO CORIOLANDO (ENTR. TO-230 - ARAPOEMA) - ENTR. TO-164 | C14: ='65'!I34 -> 16.639885 | D14: ='65'!F31 -> 13.639885 | E14: ='65'!G31 -> 3 | F14: ='65'!H31 -> 0 | G14: ='65'!I31 -> 0 | H14: ='65'!J31 -> 16.639885 | I14: ='65'!K31 -> 0 | J14: ='65'!L31 -> 0 | K14: =IF(SUM(D14:G14)=0,"— não preenchido",IF(ROUND(SUM(D14:G14)-C14,3)=0,"OK","ERRO — dif. de "&ROUND(SUM(D14:G14)-C14,3)&" km")) -> OK
A15: 66 | B15: RODOVIA TO-433 - TRECHO ENTR. TO-230 (POVOADO BRASILENE) - BERNARDO SAYÃO (ENTR. TO-164) | C15: ='66'!I50 -> 32.27987 | D15: ='66'!F47 -> 0 | E15: ='66'!G47 -> 32.27987 | F15: ='66'!H47 -> 0 | G15: ='66'!I47 -> 0 | H15: ='66'!J47 -> 0 | I15: ='66'!K47 -> 32.27987 | J15: ='66'!L47 -> 0 | K15: =IF(SUM(D15:G15)=0,"— não preenchido",IF(ROUND(SUM(D15:G15)-C15,3)=0,"OK","ERRO — dif. de "&ROUND(SUM(D15:G15)-C15,3)&" km")) -> OK
B16: TOTAL PERCORRIDO NO MÊS | C16: =SUM(C6:C15) -> 406.88491 | D16: =SUM(D6:D15) -> 54.607987 | E16: =SUM(E6:E15) -> 324.7225 | F16: =SUM(F6:F15) -> 27.554416 | G16: =SUM(G6:G15) -> 0 | H16: =SUM(H6:H15) -> 62.607987 | I16: =SUM(I6:I15) -> 344.27692 | J16: =SUM(J6:J15) -> 0
B17: % DA EXTENSÃO DA MALHA (406.88 km) | D17: =SUM(D16:G16)/406.88 -> 1.0000121 | H17: (soma do grupo 'CONDIÇÃO DA PLATAFORMA' dividida pela malha)

Sheet 46
A1: PROGRAMA DE MANUTENÇÃO RODOVIÁRIA — FICHA DE INSPEÇÃO — RODOVIAS NÃO PAVIMENTADAS | P1: Valores dos gráficos — troca 0 por N/D para a fatia não aparecer. Não editar.
A2: REGIÃO: 2 — ARAGUAÍNA I | D2: MÊS / ANO: | F2: 46235 | G2: DATA: | J2: TÉCNICO: | K2: ENG. VINICIUS RODRIGUES FERREIRA DE OLIVEIRA | P2: =IF(F42=0,NA(),F42) -> #N/A | Q2: =IF(G42=0,NA(),G42) -> 27.973982 | R2: =IF(H42=0,NA(),H42) -> #N/A | S2: =IF(I42=0,NA(),I42) -> #N/A | T2: =IF(J42=0,NA(),J42) -> #N/A | U2: =IF(K42=0,NA(),K42) -> 27.973982 | V2: =IF(L42=0,NA(),L42) -> #N/A
A3: TRECHO 46 — RODOVIA TO-164 - TRECHO ENTR. TO-226 - POVOADO DEZENOVE - BERNARDO SAYÃO | K3: EXTENSÃO: 27,974 km · 1 S.R.E.
A4: COMO PREENCHER: uma X em UMA coluna de cada grupo, por linha. Se houver mais de um defeito no mesmo km, marque o PREDOMINANTE e escreva o resto em OBSERVAÇÕES. A quilometragem é contada de 0 até o fim de CADA S.R.E. (não é o marco da rodovia).
A6: S.R.E. | B6: SENT. | C6: INÍCIO (KM) | D6: FIM (KM) | E6: EXT. (KM) | F6: CONDIÇÃO DA PLATAFORMA | J6: DRENAGEM SUPERFICIAL | M6: OBSERVAÇÕES | N6: CONFERÊNCIA (só na tela)
F7: BOM | G7: REG. (ATÉ 10 IRR./KM) | H7: RUIM (+ 10 IRR./KM) | I7: PÉSSIMA (ATOLEIRO/PTO. CRÍTICO) | J7: LIMPA | K7: OBSTRUÍDA | L7: AUSENTE
A8: S.R.E. 164ETO0190 | ENTR. TO-226 (B) - ENTR. TO-230 | EOP · Estadual · 27.974 km · início: -7.640594, -48.792035
A9: 164ETO0190 | B9: C | C9: 0 | D9: 1 | E9: =D9-C9 -> 1 | G9: X | K9: X | N9: =IF(COUNTA(F9:L9)=0,"— não preenchido",IF(COUNTIF(F9:I9,"X")<>1,"FALTA/DUPLA: CONDIÇÃO DA PLATAFORMA",IF(COUNTIF(J9:L9,"X")<>1,"FALTA/DUPLA: DRENAGEM SUPERFICIAL","OK"))) -> OK
A10: 164ETO0190 | B10: C | C10: 1 | D10: 2 | E10: =D10-C10 -> 1 | G10: X | K10: X | N10: =IF(COUNTA(F10:L10)=0,"— não preenchido",IF(COUNTIF(F10:I10,"X")<>1,"FALTA/DUPLA: CONDIÇÃO DA PLATAFORMA",IF(COUNTIF(J10:L10,"X")<>1,"FALTA/DUPLA: DRENAGEM SUPERFICIAL","OK"))) -> OK
A11: 164ETO0190 | B11: C | C11: 2 | D11: 3 | E11: =D11-C11 -> 1 | G11: X | K11: X | N11: =IF(COUNTA(F11:L11)=0,"— não preenchido",IF(COUNTIF(F11:I11,"X")<>1,"FALTA/DUPLA: CONDIÇÃO DA PLATAFORMA",IF(COUNTIF(J11:L11,"X")<>1,"FALTA/DUPLA: DRENAGEM SUPERFICIAL","OK"))) -> OK
A12: 164ETO0190 | B12: C | C12: 3 | D12: 4 | E12: =D12-C12 -> 1 | G12: X | K12: X | N12: =IF(COUNTA(F12:L12)=0,"— não preenchido",IF(COUNTIF(F12:I12,"X")<>1,"FALTA/DUPLA: CONDIÇÃO DA PLATAFORMA",IF(COUNTIF(J12:L12,"X")<>1,"FALTA/DUPLA: DRENAGEM SUPERFICIAL","OK"))) -> OK
A13: 164ETO0190 | B13: C | C13: 4 | D13: 5 | E13: =D13-C13 -> 1 | G13: X | K13: X | N13: =IF(COUNTA(F13:L13)=0,"— não preenchido",IF(COUNTIF(F13:I13,"X")<>1,"FALTA/DUPLA: CONDIÇÃO DA PLATAFORMA",IF(COUNTIF(J13:L13,"X")<>1,"FALTA/DUPLA: DRENAGEM SUPERFICIAL","OK"))) -> OK
A14: 164ETO0190 | B14: C | C14: 5 | D14: 6 | E14: =D14-C14 -> 1 | G14: X | K14: X | N14: =IF(COUNTA(F14:L14)=0,"— não preenchido",IF(COUNTIF(F14:I14,"X")<>1,"FALTA/DUPLA: CONDIÇÃO DA PLATAFORMA",IF(COUNTIF(J14:L14,"X")<>1,"FALTA/DUPLA: DRENAGEM SUPERFICIAL","OK"))) -> OK
A15: 164ETO0190 | B15: C | C15: 6 | D15: 7 | E15: =D15-C15 -> 1 | G15: X | K15: X | N15: =IF(COUNTA(F15:L15)=0,"— não preenchido",IF(COUNTIF(F15:I15,"X")<>1,"FALTA/DUPLA: CONDIÇÃO DA PLATAFORMA",IF(COUNTIF(J15:L15,"X")<>1,"FALTA/DUPLA: DRENAGEM SUPERFICIAL","OK"))) -> OK
A16: 164ETO0190 | B16: C | C16: 7 | D16: 8 | E16: =D16-C16 -> 1 | G16: X | K16: X | N16: =IF(COUNTA(F16:L16)=0,"— não preenchido",IF(COUNTIF(F16:I16,"X")<>1,"FALTA/DUPLA: CONDIÇÃO DA PLATAFORMA",IF(COUNTIF(J16:L16,"X")<>1,"FALTA/DUPLA: DRENAGEM SUPERFICIAL","OK"))) -> OK
A17: 164ETO0190 | B17: C | C17: 8 | D17: 9 | E17: =D17-C17 -> 1 | G17: X | K17: X | N17: =IF(COUNTA(F17:L17)=0,"— não preenchido",IF(COUNTIF(F17:I17,"X")<>1,"FALTA/DUPLA: CONDIÇÃO DA PLATAFORMA",IF(COUNTIF(J17:L17,"X")<>1,"FALTA/DUPLA: DRENAGEM SUPERFICIAL","OK"))) -> OK
A18: 164ETO0190 | B18: C | C18: 9 | D18: 10 | E18: =D18-C18 -> 1 | G18: X | K18: X | N18: =IF(COUNTA(F18:L18)=0,"— não preenchido",IF(COUNTIF(F18:I18,"X")<>1,"FALTA/DUPLA: CONDIÇÃO DA PLATAFORMA",IF(COUNTIF(J18:L18,"X")<>1,"FALTA/DUPLA: DRENAGEM SUPERFICIAL","OK"))) -> OK
A19: 164ETO0190 | B19: C | C19: 10 | D19: 11 | E19: =D19-C19 -> 1 | G19: X | K19: X | N19: =IF(COUNTA(F19:L19)=0,"— não preenchido",IF(COUNTIF(F19:I19,"X")<>1,"FALTA/DUPLA: CONDIÇÃO DA PLATAFORMA",IF(COUNTIF(J19:L19,"X")<>1,"FALTA/DUPLA: DRENAGEM SUPERFICIAL","OK"))) -> OK
A20: 164ETO0190 | B20: C | C20: 11 | D20: 12 | E20: =D20-C20 -> 1 | G20: X | K20: X | N20: =IF(COUNTA(F20:L20)=0,"— não preenchido",IF(COUNTIF(F20:I20,"X")<>1,"FALTA/DUPLA: CONDIÇÃO DA PLATAFORMA",IF(COUNTIF(J20:L20,"X")<>1,"FALTA/DUPLA: DRENAGEM SUPERFICIAL","OK"))) -> OK
... A36: 164ETO0190 | B36: C | C36: 27 | D36: 27.973982 | E36: =D36-C36 -> 0.97398215 | G36: X | K36: X | N36: =IF(COUNTA(F36:L36)=0,"— não preenchido",IF(COUNTIF(F36:I36,"X")<>1,"FALTA/DUPLA: CONDIÇÃO DA PLATAFORMA",IF(COUNTIF(J36:L36,"X")<>1,"FALTA/DUPLA: DRENAGEM SUPERFICIAL","OK"))) -> OK
A38: ____________________________________________ | G38: ____________________________________________
A39: TÉCNICO RESPONSÁVEL PELA INSPEÇÃO | G39: VISTO DA SUPERVISÃO
A41: RESUMO DO TRECHO — KM LANÇADO POR ITEM
A42: KM LANÇADO | F42: =SUMIF(F$9:F$36,"X",$E$9:$E$36) -> 0 | G42: =SUMIF(G$9:G$36,"X",$E$9:$E$36) -> 27.973982 | H42: =SUMIF(H$9:H$36,"X",$E$9:$E$36) -> 0 | I42: =SUMIF(I$9:I$36,"X",$E$9:$E$36) -> 0 | J42: =SUMIF(J$9:J$36,"X",$E$9:$E$36) -> 0 | K42: =SUMIF(K$9:K$36,"X",$E$9:$E$36) -> 27.973982 | L42: =SUMIF(L$9:L$36,"X",$E$9:$E$36) -> 0
A43: % DA EXTENSÃO | F43: =IF($I45=0,0,F42/$I45) -> 0 | G43: =IF($I45=0,0,G42/$I45) -> 1 | H43: =IF($I45=0,0,H42/$I45) -> 0 | I43: =IF($I45=0,0,I42/$I45) -> 0 | J43: =IF($I45=0,0,J42/$I45) -> 0 | K43: =IF($I45=0,0,K42/$I45) -> 1 | L43: =IF($I45=0,0,L42/$I45) -> 0
A44: CONFERÊNCIA POR GRUPO | F44: =IF(SUM(F42:I42)=0,"— não preenchido",IF(ROUND(SUM(F42:I42)-$I45,3)=0,"OK — "&ROUND(SUM(F42:I42),3)&" km","ERRO — dif. de "&ROUND(SUM(F42:I42)-$I45,3)&" km")) -> OK — 27,974 km | J44: =IF(SUM(J42:L42)=0,"— não preenchido",IF(ROUND(SUM(J42:L42)-$I45,3)=0,"OK — "&ROUND(SUM(J42:L42),3)&" km","ERRO — dif. de "&ROUND(SUM(J42:L42)-$I45,3)&" km")) -> OK — 27,974 km
A45: EXTENSÃO TOTAL DO TRECHO | I45: =SUM(E9:E36) -> 27.973982 | M45: =COUNTIF(N9:N36,"OK")&" de "&COUNT($E$9:$E$36)&" linhas conferidas" -> 28 de 28 linhas conferidas
A47: LEGENDA
A48: REGULAR | E48: Até 10 irregularidades por km
A49: RUIM | E49: Mais de 10 irregularidades por km
A50: PÉSSIMA | E50: Atoleiro ou ponto crítico
A51: SIT. | E51: LEN = leito natural · EOP = em obras de pavimentação
A52: FAIXA AZUL | E52: Cabeçalho de cada S.R.E.: descrição, situação, jurisdição, extensão e coordenada de início.
A53: INÍCIO / FIM (KM) | E53: Contados de 0 até o fim de CADA S.R.E. Não é o marco quilométrico da rodovia.
A54: SENT. | E54: C = crescente · D = decrescente
A55: FAIXA CINZA | E55: Segmento fora do escopo do contrato: você passa por ele, mas não preenche.
A56: CÉLULA VERMELHA | E56: Mais de uma X no mesmo grupo. Apague uma delas.
A57: CONFERÊNCIA | E57: Só na tela, não sai impresso. Fica OK com uma X em cada grupo.

Sheet 47
A1: PROGRAMA DE MANUTENÇÃO RODOVIÁRIA — FICHA DE INSPEÇÃO — RODOVIAS NÃO PAVIMENTADAS | P1: Valores dos gráficos — troca 0 por N/D para a fatia não aparecer. Não editar.
A2: REGIÃO: 2 — ARAGUAÍNA I | D2: MÊS / ANO: | F2: =IF('46'!F2="","",'46'!F2) -> 46235 | G2: DATA: | I2: =IF('46'!I2="","",'46'!I2) | J2: TÉCNICO: | K2: =IF('46'!K2="","",'46'!K2) -> ENG. VINICIUS RODRIGUES FERREIRA DE OLIVEIRA | P2: =IF(F60=0,NA(),F60) -> 5 | Q2: =IF(G60=0,NA(),G60) -> 33.321833 | R2: =IF(H60=0,NA(),H60) -> 5 | S2: =IF(I60=0,NA(),I60) -> #N/A | T2: =IF(J60=0,NA(),J60) -> #N/A | U2: =IF(K60=0,NA(),K60) -> 43.321833 | V2: =IF(L60=0,NA(),L60) -> #N/A
A3: TRECHO 47 — RODOVIA TO-164 - TRECHO MURICILÂNDIA - ENTR. TO-226 | K3: EXTENSÃO: 43,322 km · 2 S.R.E.
A4: COMO PREENCHER: uma X em UMA coluna de cada grupo, por linha. Se houver mais de um defeito no mesmo km, marque o PREDOMINANTE e escreva o resto em OBSERVAÇÕES. A quilometragem é contada de 0 até o fim de CADA S.R.E. (não é o marco da rodovia).
A6: S.R.E. | B6: SENT. | C6: INÍCIO (KM) | D6: FIM (KM) | E6: EXT. (KM) | F6: CONDIÇÃO DA PLATAFORMA | J6: DRENAGEM SUPERFICIAL | M6: OBSERVAÇÕES | N6: CONFERÊNCIA (só na tela)
F7: BOM | G7: REG. (ATÉ 10 IRR./KM) | H7: RUIM (+ 10 IRR./KM) | I7: PÉSSIMA (ATOLEIRO/PTO. CRÍTICO) | J7: LIMPA | K7: OBSTRUÍDA | L7: AUSENTE
A8: S.R.E. 164ETO0160 | MURICILÃNDIA * TRECHO URBANO* - COCALANDIA | EOP · Estadual · 9.009 km · início: -7.154833, -48.609922
A9: 164ETO0160 | B9: C | C9: 0 | D9: 1 | E9: =D9-C9 -> 1 | G9: X | K9: X | N9: =IF(COUNTA(F9:L9)=0,"— não preenchido",IF(COUNTIF(F9:I9,"X")<>1,"FALTA/DUPLA: CONDIÇÃO DA PLATAFORMA",IF(COUNTIF(J9:L9,"X")<>1,"FALTA/DUPLA: DRENAGEM SUPERFICIAL","OK"))) -> OK
A10: 164ETO0160 | B10: C | C10: 1 | D10: 2 | E10: =D10-C10 -> 1 | G10: X | K10: X | N10: =IF(COUNTA(F10:L10)=0,"— não preenchido",IF(COUNTIF(F10:I10,"X")<>1,"FALTA/DUPLA: CONDIÇÃO DA PLATAFORMA",IF(COUNTIF(J10:L10,"X")<>1,"FALTA/DUPLA: DRENAGEM SUPERFICIAL","OK"))) -> OK
A11: 164ETO0160 | B11: C | C11: 2 | D11: 3 | E11: =D11-C11 -> 1 | G11: X | K11: X | N11: =IF(COUNTA(F11:L11)=0,"— não preenchido",IF(COUNTIF(F11:I11,"X")<>1,"FALTA/DUPLA: CONDIÇÃO DA PLATAFORMA",IF(COUNTIF(J11:L11,"X")<>1,"FALTA/DUPLA: DRENAGEM SUPERFICIAL","OK"))) -> OK
A12: 164ETO0160 | B12: C | C12: 3 | D12: 4 | E12: =D12-C12 -> 1 | H12: X | K12: X | N12: =IF(COUNTA(F12:L12)=0,"— não preenchido",IF(COUNTIF(F12:I12,"X")<>1,"FALTA/DUPLA: CONDIÇÃO DA PLATAFORMA",IF(COUNTIF(J12:L12,"X")<>1,"FALTA/DUPLA: DRENAGEM SUPERFICIAL","OK"))) -> OK
A13: 164ETO0160 | B13: C | C13: 4 | D13: 5 | E13: =D13-C13 -> 1 | G13: X | K13: X | N13: =IF(COUNTA(F13:L13)=0,"— não preenchido",IF(COUNTIF(F13:I13,"X")<>1,"FALTA/DUPLA: CONDIÇÃO DA PLATAFORMA",IF(COUNTIF(J13:L13,"X")<>1,"FALTA/DUPLA: DRENAGEM SUPERFICIAL","OK"))) -> OK
A14: 164ETO0160 | B14: C | C14: 5 | D14: 6 | E14: =D14-C14 -> 1 | G14: X | K14: X | N14: =IF(COUNTA(F14:L14)=0,"— não preenchido",IF(COUNTIF(F14:I14,"X")<>1,"FALTA/DUPLA: CONDIÇÃO DA PLATAFORMA",IF(COUNTIF(J14:L14,"X")<>1,"FALTA/DUPLA: DRENAGEM SUPERFICIAL","OK"))) -> OK
A15: 164ETO0160 | B15: C | C15: 6 | D15: 7 | E15: =D15-C15 -> 1 | G15: X | K15: X | N15: =IF(COUNTA(F15:L15)=0,"— não preenchido",IF(COUNTIF(F15:I15,"X")<>1,"FALTA/DUPLA: CONDIÇÃO DA PLATAFORMA",IF(COUNTIF(J15:L15,"X")<>1,"FALTA/DUPLA: DRENAGEM SUPERFICIAL","OK"))) -> OK
A16: 164ETO0160 | B16: C | C16: 7 | D16: 8 | E16: =D16-C16 -> 1 | G16: X | K16: X | N16: =IF(COUNTA(F16:L16)=0,"— não preenchido",IF(COUNTIF(F16:I16,"X")<>1,"FALTA/DUPLA: CONDIÇÃO DA PLATAFORMA",IF(COUNTIF(J16:L16,"X")<>1,"FALTA/DUPLA: DRENAGEM SUPERFICIAL","OK"))) -> OK
A17: 164ETO0160 | B17: C | C17: 8 | D17: 9 | E17: =D17-C17 -> 1 | G17: X | K17: X | N17: =IF(COUNTA(F17:L17)=0,"— não preenchido",IF(COUNTIF(F17:I17,"X")<>1,"FALTA/DUPLA: CONDIÇÃO DA PLATAFORMA",IF(COUNTIF(J17:L17,"X")<>1,"FALTA/DUPLA: DRENAGEM SUPERFICIAL","OK"))) -> OK
A18: 164ETO0160 | B18: C | C18: 9 | D18: 9.0092407 | E18: =D18-C18 -> 0.0092407101 | G18: X | K18: X | N18: =IF(COUNTA(F18:L18)=0,"— não preenchido",IF(COUNTIF(F18:I18,"X")<>1,"FALTA/DUPLA: CONDIÇÃO DA PLATAFORMA",IF(COUNTIF(J18:L18,"X")<>1,"FALTA/DUPLA: DRENAGEM SUPERFICIAL","OK"))) -> OK
A19: S.R.E. 164ETO0170 | COCALANDIA - ENTR. TO-226 (A) | EOP · Estadual · 34.313 km · início: -7.223845, -48.622338
A20: 164ETO0170 | B20: C | C20: 0 | D20: 1 | E20: =D20-C20 -> 1 | G20: X | K20: X | N20: =IF(COUNTA(F20:L20)=0,"— não preenchido",IF(COUNTIF(F20:I20,"X")<>1,"FALTA/DUPLA: CONDIÇÃO DA PLATAFORMA",IF(COUNTIF(J20:L20,"X")<>1,"FALTA/DUPLA: DRENAGEM SUPERFICIAL","OK"))) -> OK
A21: 164ETO0170 | B21: C | C21: 1 | D21: 2 | E21: =D21-C21 -> 1 | G21: X | K21: X | N21: =IF(COUNTA(F21:L21)=0,"— não preenchido",IF(COUNTIF(F21:I21,"X")<>1,"FALTA/DUPLA: CONDIÇÃO DA PLATAFORMA",IF(COUNTIF(J21:L21,"X")<>1,"FALTA/DUPLA: DRENAGEM SUPERFICIAL","OK"))) -> OK
A22: 164ETO0170 | B22: C | C22: 2 | D22: 3 | E22: =D22-C22 -> 1 | H22: X | K22: X | N22: =IF(COUNTA(F22:L22)=0,"— não preenchido",IF(COUNTIF(F22:I22,"X")<>1,"FALTA/DUPLA: CONDIÇÃO DA PLATAFORMA",IF(COUNTIF(J22:L22,"X")<>1,"FALTA/DUPLA: DRENAGEM SUPERFICIAL","OK"))) -> OK
A23: 164ETO0170 | B23: C | C23: 3 | D23: 4 | E23: =D23-C23 -> 1 | H23: X | K23: X | N23: =IF(COUNTA(F23:L23)=0,"— não preenchido",IF(COUNTIF(F23:I23,"X")<>1,"FALTA/DUPLA: CONDIÇÃO DA PLATAFORMA",IF(COUNTIF(J23:L23,"X")<>1,"FALTA/DUPLA: DRENAGEM SUPERFICIAL","OK"))) -> OK
A24: 164ETO0170 | B24: C | C24: 4 | D24: 5 | E24: =D24-C24 -> 1 | H24: X | K24: X | N24: =IF(COUNTA(F24:L24)=0,"— não preenchido",IF(COUNTIF(F24:I24,"X")<>1,"FALTA/DUPLA: CONDIÇÃO DA PLATAFORMA",IF(COUNTIF(J24:L24,"X")<>1,"FALTA/DUPLA: DRENAGEM SUPERFICIAL","OK"))) -> OK
A25: 164ETO0170 | B25: C | C25: 5 | D25: 6 | E25: =D25-C25 -> 1 | G25: X | K25: X | N25: =IF(COUNTA(F25:L25)=0,"— não preenchido",IF(COUNTIF(F25:I25,"X")<>1,"FALTA/DUPLA: CONDIÇÃO DA PLATAFORMA",IF(COUNTIF(J25:L25,"X")<>1,"FALTA/DUPLA: DRENAGEM SUPERFICIAL","OK"))) -> OK
A26: 164ETO0170 | B26: C | C26: 6 | D26: 7 | E26: =D26-C26 -> 1 | G26: X | K26: X | N26: =IF(COUNTA(F26:L26)=0,"— não preenchido",IF(COUNTIF(F26:I26,"X")<>1,"FALTA/DUPLA: CONDIÇÃO DA PLATAFORMA",IF(COUNTIF(J26:L26,"X")<>1,"FALTA/DUPLA: DRENAGEM SUPERFICIAL","OK"))) -> OK
A27: 164ETO0170 | B27: C | C27: 7 | D27: 8 | E27: =D27-C27 -> 1 | G27: X | K27: X | N27: =IF(COUNTA(F27:L27)=0,"— não preenchido",IF(COUNTIF(F27:I27,"X")<>1,"FALTA/DUPLA: CONDIÇÃO DA PLATAFORMA",IF(COUNTIF(J27:L27,"X")<>1,"FALTA/DUPLA: DRENAGEM SUPERFICIAL","OK"))) -> OK
A28: 164ETO0170 | B28: C | C28: 8 | D28: 9 | E28: =D28-C28 -> 1 | G28: X | K28: X | N28: =IF(COUNTA(F28:L28)=0,"— não preenchido",IF(COUNTIF(F28:I28,"X")<>1,"FALTA/DUPLA: CONDIÇÃO DA PLATAFORMA",IF(COUNTIF(J28:L28,"X")<>1,"FALTA/DUPLA: DRENAGEM SUPERFICIAL","OK"))) -> OK
A29: 164ETO0170 | B29: C | C29: 9 | D29: 10 | E29: =D29-C29 -> 1 | G29: X | K29: X | N29: =IF(COUNTA(F29:L29)=0,"— não preenchido",IF(COUNTIF(F29:I29,"X")<>1,"FALTA/DUPLA: CONDIÇÃO DA PLATAFORMA",IF(COUNTIF(J29:L29,"X")<>1,"FALTA/DUPLA: DRENAGEM SUPERFICIAL","OK"))) -> OK
A30: 164ETO0170 | B30: C | C30: 10 | D30: 11 | E30: =D30-C30 -> 1 | G30: X | K30: X | N30: =IF(COUNTA(F30:L30)=0,"— não preenchido",IF(COUNTIF(F30:I30,"X")<>1,"FALTA/DUPLA: CONDIÇÃO DA PLATAFORMA",IF(COUNTIF(J30:L30,"X")<>1,"FALTA/DUPLA: DRENAGEM SUPERFICIAL","OK"))) -> OK
A31: 164ETO0170 | B31: C | C31: 11 | D31: 12 | E31: =D31-C31 -> 1 | G31: X | K31: X | N31: =IF(COUNTA(F31:L31)=0,"— não preenchido",IF(COUNTIF(F31:I31,"X")<>1,"FALTA/DUPLA: CONDIÇÃO DA PLATAFORMA",IF(COUNTIF(J31:L31,"X")<>1,"FALTA/DUPLA: DRENAGEM SUPERFICIAL","OK"))) -> OK
A32: 164ETO0170 | B32: C | C32: 12 | D32: 13 | E32: =D32-C32 -> 1 | G32: X | K32: X | N32: =IF(COUNTA(F32:L32)=0,"— não preenchido",IF(COUNTIF(F32:I32,"X")<>1,"FALTA/DUPLA: CONDIÇÃO DA PLATAFORMA",IF(COUNTIF(J32:L32,"X")<>1,"FALTA/DUPLA: DRENAGEM SUPERFICIAL","OK"))) -> OK
A33: 164ETO0170 | B33: C | C33: 13 | D33: 14 | E33: =D33-C33 -> 1 | G33: X | K33: X | N33: =IF(COUNTA(F33:L33)=0,"— não preenchido",IF(COUNTIF(F33:I33,"X")<>1,"FALTA/DUPLA: CONDIÇÃO DA PLATAFORMA",IF(COUNTIF(J33:L33,"X")<>1,"FALTA/DUPLA: DRENAGEM SUPERFICIAL","OK"))) -> OK
A34: 164ETO0170 | B34: C | C34: 14 | D34: 15 | E34: =D34-C34 -> 1 | G34: X | K34: X | N34: =IF(COUNTA(F34:L34)=0,"— não preenchido",IF(COUNTIF(F34:I34,"X")<>1,"FALTA/DUPLA: CONDIÇÃO DA PLATAFORMA",IF(COUNTIF(J34:L34,"X")<>1,"FALTA/DUPLA: DRENAGEM SUPERFICIAL","OK"))) -> OK
A35: 164ETO0170 | B35: C | C35: 15 | D35: 16 | E35: =D35-C35 -> 1 | G35: X | K35: X | N35: =IF(COUNTA(F35:L35)=0,"— não preenchido",IF(COUNTIF(F35:I35,"X")<>1,"FALTA/DUPLA: CONDIÇÃO DA PLATAFORMA",IF(COUNTIF(J35:L35,"X")<>1,"FALTA/DUPLA: DRENAGEM SUPERFICIAL","OK"))) -> OK
A36: 164ETO0170 | B36: C | C36: 16 | D36: 17 | E36: =D36-C36 -> 1 | F36: X | K36: X | N36: =IF(COUNTA(F36:L36)=0,"— não preenchido",IF(COUNTIF(F36:I36,"X")<>1,"FALTA/DUPLA: CONDIÇÃO DA PLATAFORMA",IF(COUNTIF(J36:L36,"X")<>1,"FALTA/DUPLA: DRENAGEM SUPERFICIAL","OK"))) -> OK
A37: 164ETO0170 | B37: C | C37: 17 | D37: 18 | E37: =D37-C37 -> 1 | F37: X | K37: X | N37: =IF(COUNTA(F37:L37)=0,"— não preenchido",IF(COUNTIF(F37:I37,"X")<>1,"FALTA/DUPLA: CONDIÇÃO DA PLATAFORMA",IF(COUNTIF(J37:L37,"X")<>1,"FALTA/DUPLA: DRENAGEM SUPERFICIAL","OK"))) -> OK
A38: 164ETO0170 | B38: C | C38: 18 | D38: 19 | E38: =D38-C38 -> 1 | F38: X | K38: X | N38: =IF(COUNTA(F38:L38)=0,"— não preenchido",IF(COUNTIF(F38:I38,"X")<>1,"FALTA/DUPLA: CONDIÇÃO DA PLATAFORMA",IF(COUNTIF(J38:L38,"X")<>1,"FALTA/DUPLA: DRENAGEM SUPERFICIAL","OK"))) -> OK
A39: 164ETO0170 | B39: C | C39: 19 | D39: 20 | E39: =D39-C39 -> 1 | F39: X | K39: X | N39: =IF(COUNTA(F39:L39)=0,"— não preenchido",IF(COUNTIF(F39:I39,"X")<>1,"FALTA/DUPLA: CONDIÇÃO DA PLATAFORMA",IF(COUNTIF(J39:L39,"X")<>1,"FALTA/DUPLA: DRENAGEM SUPERFICIAL","OK"))) -> OK
A40: 164ETO0170 | B40: C | C40: 20 | D40: 21 | E40: =D40-C40 -> 1 | F40: X | K40: X | N40: =IF(COUNTA(F40:L40)=0,"— não preenchido",IF(COUNTIF(F40:I40,"X")<>1,"FALTA/DUPLA: CONDIÇÃO DA PLATAFORMA",IF(COUNTIF(J40:L40,"X")<>1,"FALTA/DUPLA: DRENAGEM SUPERFICIAL","OK"))) -> OK
A41: 164ETO0170 | B41: C | C41: 21 | D41: 22 | E41: =D41-C41 -> 1 | G41: X | K41: X | N41: =IF(COUNTA(F41:L41)=0,"— não preenchido",IF(COUNTIF(F41:I41,"X")<>1,"FALTA/DUPLA: CONDIÇÃO DA PLATAFORMA",IF(COUNTIF(J41:L41,"X")<>1,"FALTA/DUPLA: DRENAGEM SUPERFICIAL","OK"))) -> OK
...

Sheet 48
A1: PROGRAMA DE MANUTENÇÃO RODOVIÁRIA — FICHA DE INSPEÇÃO — RODOVIAS NÃO PAVIMENTADAS | P1: Valores dos gráficos — troca 0 por N/D para a fatia não aparecer. Não editar.
A2: REGIÃO: 2 — ARAGUAÍNA I | D2: MÊS / ANO: | F2: =IF('46'!F2="","",'46'!F2) -> 46235 | G2: DATA: | I2: =IF('46'!I2="","",'46'!I2) | J2: TÉCNICO: | K2: =IF('46'!K2="","",'46'!K2) -> ENG. VINICIUS RODRIGUES FERREIRA DE OLIVEIRA | P2: =IF(F109=0,NA(),F109) -> #N/A | Q2: =IF(G109=0,NA(),G109) -> 80.523276 | R2: =IF(H109=0,NA(),H109) -> 12 | S2: =IF(I109=0,NA(),I109) -> #N/A | T2: =IF(J109=0,NA(),J109) -> #N/A | U2: =IF(K109=0,NA(),K109) -> 92.523276 | V2: =IF(L109=0,NA(),L109) -> #N/A
A3: TRECHO 48 — RODOVIA TO-165 - TRECHO SANTA FÉ DO ARAGUAIA - ENTR. TO-226 - ARAPOEMA | K3: EXTENSÃO: 92,523 km · 2 S.R.E.
A4: COMO PREENCHER: uma X em UMA coluna de cada grupo, por linha. Se houver mais de um defeito no mesmo km, marque o PREDOMINANTE e escreva o resto em OBSERVAÇÕES. A quilometragem é contada de 0 até o fim de CADA S.R.E. (não é o marco da rodovia).
A6: S.R.E. | B6: SENT. | C6: INÍCIO (KM) | D6: FIM (KM) | E6: EXT. (KM) | F6: CONDIÇÃO DA PLATAFORMA | J6: DRENAGEM SUPERFICIAL | M6: OBSERVAÇÕES | N6: CONFERÊNCIA (só na tela)
F7: BOM | G7: REG. (ATÉ 10 IRR./KM) | H7: RUIM (+ 10 IRR./KM) | I7: PÉSSIMA (ATOLEIRO/PTO. CRÍTICO) | J7: LIMPA | K7: OBSTRUÍDA | L7: AUSENTE
A8: S.R.E. 165ETO0100 | SANTA FÉ DO ARAGUAIA *TRECHO URBANO* - ENTR. TO-226 | LEN · Estadual · 51.534 km · início: -7.154445, -48.697131
A9: 165ETO0100 | B9: C | C9: 0 | D9: 1 | E9: =D9-C9 -> 1 | G9: X | K9: X | N9: =IF(COUNTA(F9:L9)=0,"— não preenchido",IF(COUNTIF(F9:I9,"X")<>1,"FALTA/DUPLA: CONDIÇÃO DA PLATAFORMA",IF(COUNTIF(J9:L9,"X")<>1,"FALTA/DUPLA: DRENAGEM SUPERFICIAL","OK"))) -> OK
A10: 165ETO0100 | B10: C | C10: 1 | D10: 2 | E10: =D10-C10 -> 1 | G10: X | K10: X | N10: =IF(COUNTA(F10:L10)=0,"— não preenchido",IF(COUNTIF(F10:I10,"X")<>1,"FALTA/DUPLA: CONDIÇÃO DA PLATAFORMA",IF(COUNTIF(J10:L10,"X")<>1,"FALTA/DUPLA: DRENAGEM SUPERFICIAL","OK"))) -> OK
A11: 165ETO0100 | B11: C | C11: 2 | D11: 3 | E11: =D11-C11 -> 1 | G11: X | K11: X | N11: =IF(COUNTA(F11:L11)=0,"— não preenchido",IF(COUNTIF(F11:I11,"X")<>1,"FALTA/DUPLA: CONDIÇÃO DA PLATAFORMA",IF(COUNTIF(J11:L11,"X")<>1,"FALTA/DUPLA: DRENAGEM SUPERFICIAL","OK"))) -> OK
A12: 165ETO0100 | B12: C | C12: 3 | D12: 4 | E12: =D12-C12 -> 1 | G12: X | K12: X | N12: =IF(COUNTA(F12:L12)=0,"— não preenchido",IF(COUNTIF(F12:I12,"X")<>1,"FALTA/DUPLA: CONDIÇÃO DA PLATAFORMA",IF(COUNTIF(J12:L12,"X")<>1,"FALTA/DUPLA: DRENAGEM SUPERFICIAL","OK"))) -> OK
A13: 165ETO0100 | B13: C | C13: 4 | D13: 5 | E13: =D13-C13 -> 1 | G13: X | K13: X | N13: =IF(COUNTA(F13:L13)=0,"— não preenchido",IF(COUNTIF(F13:I13,"X")<>1,"FALTA/DUPLA: CONDIÇÃO DA PLATAFORMA",IF(COUNTIF(J13:L13,"X")<>1,"FALTA/DUPLA: DRENAGEM SUPERFICIAL","OK"))) -> OK
A14: 165ETO0100 | B14: C | C14: 5 | D14: 6 | E14: =D14-C14 -> 1 | G14: X | K14: X | N14: =IF(COUNTA(F14:L14)=0,"— não preenchido",IF(COUNTIF(F14:I14,"X")<>1,"FALTA/DUPLA: CONDIÇÃO DA PLATAFORMA",IF(COUNTIF(J14:L14,"X")<>1,"FALTA/DUPLA: DRENAGEM SUPERFICIAL","OK"))) -> OK
A15: 165ETO0100 | B15: C | C15: 6 | D15: 7 | E15: =D15-C15 -> 1 | H15: X | K15: X | N15: =IF(COUNTA(F15:L15)=0,"— não preenchido",IF(COUNTIF(F15:I15,"X")<>1,"FALTA/DUPLA: CONDIÇÃO DA PLATAFORMA",IF(COUNTIF(J15:L15,"X")<>1,"FALTA/DUPLA: DRENAGEM SUPERFICIAL","OK"))) -> OK
A16: 165ETO0100 | B16: C | C16: 7 | D16: 8 | E16: =D16-C16 -> 1 | H16: X | K16: X | N16: =IF(COUNTA(F16:L16)=0,"— não preenchido",IF(COUNTIF(F16:I16,"X")<>1,"FALTA/DUPLA: CONDIÇÃO DA PLATAFORMA",IF(COUNTIF(J16:L16,"X")<>1,"FALTA/DUPLA: DRENAGEM SUPERFICIAL","OK"))) -> OK
A17: 165ETO0100 | B17: C | C17: 8 | D17: 9 | E17: =D17-C17 -> 1 | G17: X | K17: X | N17: =IF(COUNTA(F17:L17)=0,"— não preenchido",IF(COUNTIF(F17:I17,"X")<>1,"FALTA/DUPLA: CONDIÇÃO DA PLATAFORMA",IF(COUNTIF(J17:L17,"X")<>1,"FALTA/DUPLA: DRENAGEM SUPERFICIAL","OK"))) -> OK
A18: 165ETO0100 | B18: C | C18: 9 | D18: 10 | E18: =D18-C18 -> 1 | G18: X | K18: X | N18: =IF(COUNTA(F18:L18)=0,"— não preenchido",IF(COUNTIF(F18:I18,"X")<>1,"FALTA/DUPLA: CONDIÇÃO DA PLATAFORMA",IF(COUNTIF(J18:L18,"X")<>1,"FALTA/DUPLA: DRENAGEM SUPERFICIAL","OK"))) -> OK
A19: 165ETO0100 | B19: C | C19: 10 | D19: 11 | E19: =D19-C19 -> 1 | G19: X | K19: X | N19: =IF(COUNTA(F19:L19)=0,"— não preenchido",IF(COUNTIF(F19:I19,"X")<>1,"FALTA/DUPLA: CONDIÇÃO DA PLATAFORMA",IF(COUNTIF(J19:L19,"X")<>1,"FALTA/DUPLA: DRENAGEM SUPERFICIAL","OK"))) -> OK
A20: 165ETO0100 | B20: C | C20: 11 | D20: 12 | E20: =D20-C20 -> 1 | G20: X | K20: X | N20: =IF(COUNTA(F20:L20)=0,"— não preenchido",IF(COUNTIF(F20:I20,"X")<>1,"FALTA/DUPLA: CONDIÇÃO DA PLATAFORMA",IF(COUNTIF(J20:L20,"X")<>1,"FALTA/DUPLA: DRENAGEM SUPERFICIAL","OK"))) -> OK
A21: 165ETO0100 | B21: C | C21: 12 | D21: 13 | E21: =D21-C21 -> 1 | G21: X | K21: X | N21: =IF(COUNTA(F21:L21)=0,"— não preenchido",IF(COUNTIF(F21:I21,"X")<>1,"FALTA/DUPLA: CONDIÇÃO DA PLATAFORMA",IF(COUNTIF(J21:L21,"X")<>1,"FALTA/DUPLA: DRENAGEM SUPERFICIAL","OK"))) -> OK
A22: 165ETO0100 | B22: C | C22: 13 | D22: 14 | E22: =D22-C22 -> 1 | G22: X | K22: X | N22: =IF(COUNTA(F22:L22)=0,"— não preenchido",IF(COUNTIF(F22:I22,"X")<>1,"FALTA/DUPLA: CONDIÇÃO DA PLATAFORMA",IF(COUNTIF(J22:L22,"X")<>1,"FALTA/DUPLA: DRENAGEM SUPERFICIAL","OK"))) -> OK
A23: 165ETO0100 | B23: C | C23: 14 | D23: 15 | E23: =D23-C23 -> 1 | G23: X | K23: X | N23: =IF(COUNTA(F23:L23)=0,"— não preenchido",IF(COUNTIF(F23:I23,"X")<>1,"FALTA/DUPLA: CONDIÇÃO DA PLATAFORMA",IF(COUNTIF(J23:L23,"X")<>1,"FALTA/DUPLA: DRENAGEM SUPERFICIAL","OK"))) -> OK
A24: 165ETO0100 | B24: C | C24: 15 | D24: 16 | E24: =D24-C24 -> 1 | G24: X | K24: X | N24: =IF(COUNTA(F24:L24)=0,"— não preenchido",IF(COUNTIF(F24:I24,"X")<>1,"FALTA/DUPLA: CONDIÇÃO DA PLATAFORMA",IF(COUNTIF(J24:L24,"X")<>1,"FALTA/DUPLA: DRENAGEM SUPERFICIAL","OK"))) -> OK
A25: 165ETO0100 | B25: C | C25: 16 | D25: 17 | E25: =D25-C25 -> 1 | H25: X | K25: X | N25: =IF(COUNTA(F25:L25)=0,"— não preenchido",IF(COUNTIF(F25:I25,"X")<>1,"FALTA/DUPLA: CONDIÇÃO DA PLATAFORMA",IF(COUNTIF(J25:L25,"X")<>1,"FALTA/DUPLA: DRENAGEM SUPERFICIAL","OK"))) -> OK
A26: 165ETO0100 | B26: C | C26: 17 | D26: 18 | E26: =D26-C26 -> 1 | H26: X | K26: X | N26: =IF(COUNTA(F26:L26)=0,"— não preenchido",IF(COUNTIF(F26:I26,"X")<>1,"FALTA/DUPLA: CONDIÇÃO DA PLATAFORMA",IF(COUNTIF(J26:L26,"X")<>1,"FALTA/DUPLA: DRENAGEM SUPERFICIAL","OK"))) -> OK
A27: 165ETO0100 | B27: C | C27: 18 | D27: 19 | E27: =D27-C27 -> 1 | G27: X | K27: X | N27: =IF(COUNTA(F27:L27)=0,"— não preenchido",IF(COUNTIF(F27:I27,"X")<>1,"FALTA/DUPLA: CONDIÇÃO DA PLATAFORMA",IF(COUNTIF(J27:L27,"X")<>1,"FALTA/DUPLA: DRENAGEM SUPERFICIAL","OK"))) -> OK
A28: 165ETO0100 | B28: C | C28: 19 | D28: 20 | E28: =D28-C28 -> 1 | G28: X | K28: X | N28: =IF(COUNTA(F28:L28)=0,"— não preenchido",IF(COUNTIF(F28:I28,"X")<>1,"FALTA/DUPLA: CONDIÇÃO DA PLATAFORMA",IF(COUNTIF(J28:L28,"X")<>1,"FALTA/DUPLA: DRENAGEM SUPERFICIAL","OK"))) -> OK
A29: 165ETO0100 | B29: C | C29: 20 | D29: 21 | E29: =D29-C29 -> 1 | H29: X | K29: X | N29: =IF(COUNTA(F29:L29)=0,"— não preenchido",IF(COUNTIF(F29:I29,"X")<>1,"FALTA/DUPLA: CONDIÇÃO DA PLATAFORMA",IF(COUNTIF(J29:L29,"X")<>1,"FALTA/DUPLA: DRENAGEM SUPERFICIAL","OK"))) -> OK
A30: 165ETO0100 | B30: C | C30: 21 | D30: 22 | E30: =D30-C30 -> 1 | G30: X | K30: X | N30: =IF(COUNTA(F30:L30)=0,"— não preenchido",IF(COUNTIF(F30:I30,"X")<>1,"FALTA/DUPLA: CONDIÇÃO DA PLATAFORMA",IF(COUNTIF(J30:L30,"X")<>1,"FALTA/DUPLA: DRENAGEM SUPERFICIAL","OK"))) -> OK
A31: 165ETO0100 | B31: C | C31: 22 | D31: 23 | E31: =D31-C31 -> 1 | H31: X | K31: X | N31: =IF(COUNTA(F31:L31)=0,"— não preenchido",IF(COUNTIF(F31:I31,"X")<>1,"FALTA/DUPLA: CONDIÇÃO DA PLATAFORMA",IF(COUNTIF(J31:L31,"X")<>1,"FALTA/DUPLA: DRENAGEM SUPERFICIAL","OK"))) -> OK
A32: 165ETO0100 | B32: C | C32: 23 | D32: 24 | E32: =D32-C32 -> 1 | G32: X | K32: X | N32: =IF(COUNTA(F32:L32)=0,"— não preenchido",IF(COUNTIF(F32:I32,"X")<>1,"FALTA/DUPLA: CONDIÇÃO DA PLATAFORMA",IF(COUNTIF(J32:L32,"X")<>1,"FALTA/DUPLA: DRENAGEM SUPERFICIAL","OK"))) -> OK
A33: 165ETO0100 | B33: C | C33: 24 | D33: 25 | E33: =D33-C33 -> 1 | G33: X | K33: X | N33: =IF(COUNTA(F33:L33)=0,"— não preenchido",IF(COUNTIF(F33:I33,"X")<>1,"FALTA/DUPLA: CONDIÇÃO DA PLATAFORMA",IF(COUNTIF(J33:L33,"X")<>1,"FALTA/DUPLA: DRENAGEM SUPERFICIAL","OK"))) -> OK
A34: 165ETO0100 | B34: C | C34: 25 | D34: 26 | E34: =D34-C34 -> 1 | G34: X | K34: X | N34: =IF(COUNTA(F34:L34)=0,"— não preenchido",IF(COUNTIF(F34:I34,"X")<>1,"FALTA/DUPLA: CONDIÇÃO DA PLATAFORMA",IF(COUNTIF(J34:L34,"X")<>1,"FALTA/DUPLA: DRENAGEM SUPERFICIAL","OK"))) -> OK
A35: 165ETO0100 | B35: C | C35: 26 | D35: 27 | E35: =D35-C35 -> 1 | G35: X | K35: X | N35: =IF(COUNTA(F35:L35)=0,"— não preenchido",IF(COUNTIF(F35:I35,"X")<>1,"FALTA/DUPLA: CONDIÇÃO DA PLATAFORMA",IF(COUNTIF(J35:L35,"X")<>1,"FALTA/DUPLA: DRENAGEM SUPERFICIAL","OK"))) -> OK
A36: 165ETO0100 | B36: C | C36: 27 | D36: 28 | E36: =D36-C36 -> 1 | G36: X | K36: X | N36: =IF(COUNTA(F36:L36)=0,"— não preenchido",IF(COUNTIF(F36:I36,"X")<>1,"FALTA/DUPLA: CONDIÇÃO DA PLATAFORMA",IF(COUNTIF(J36:L36,"X")<>1,"FALTA/DUPLA: DRENAGEM SUPERFICIAL","OK"))) -> OK
A37: 165ETO0100 | B37: C | C37: 28 | D37: 29 | E37: =D37-C37 -> 1 | G37: X | K37: X | N37: =IF(COUNTA(F37:L37)=0,"— não preenchido",IF(COUNTIF(F37:I37,"X")<>1,"FALTA/DUPLA: CONDIÇÃO DA PLATAFORMA",IF(COUNTIF(J37:L37,"X")<>1,"FALTA/DUPLA: DRENAGEM SUPERFICIAL","OK"))) -> OK
A38: 165ETO0100 | B38: C | C38: 29 | D38: 30 | E38: =D38-C38 -> 1 | G38: X | K38: X | N38: =IF(COUNTA(F38:L38)=0,"— não preenchido",IF(COUNTIF(F38:I38,"X")<>1,"FALTA/DUPLA: CONDIÇÃO DA PLATAFORMA",IF(COUNTIF(J38:L38,"X")<>1,"FALTA/DUPLA: DRENAGEM SUPERFICIAL","OK"))) -> OK
A39: 165ETO0100 | B39: C | C39: 30 | D39: 31 | E39: =D39-C39 -> 1 | G39: X | K39: X | N39: =IF(COUNTA(F39:L39)=0,"— não preenchido",IF(COUNTIF(F39:I39,"X")<>1,"FALTA/DUPLA: CONDIÇÃO DA PLATAFORMA",IF(COUNTIF(J39:L39,"X")<>1,"FALTA/DUPLA: DRENAGEM SUPERFICIAL","OK"))) -> OK
A40: 165ETO0100 | B40: C | C40: 31 | D40: 32 | E40: =D40-C40 -> 1 | G40: X | K40: X | N40: =IF(COUNTA(F40:L40)=0,"— não preenchido",IF(COUNTIF(F40:I40,"X")<>1,"FALTA/DUPLA: CONDIÇÃO DA PLATAFORMA",IF(COUNTIF(J40:L40,"X")<>1,"FALTA/DUPLA: DRENAGEM SUPERFICIAL","OK"))) -> OK
A41: 165ETO0100 | B41: C | C41: 32 | D41: 33 | E41: =D41-C41 -> 1 | G41: X | K41: X | N41: =IF(COUNTA(F41:L41)=0,"— não preenchido",IF(COUNTIF(F41:I41,"X")<>1,"FALTA/DUPLA: CONDIÇÃO DA PLATAFORMA",IF(COUNTIF(J41:L41,"X")<>1,"FALTA/DUPLA: DRENAGEM SUPERFICIAL","OK"))) -> OK
...

Sheet 49
A1: PROGRAMA DE MANUTENÇÃO RODOVIÁRIA — FICHA DE INSPEÇÃO — RODOVIAS NÃO PAVIMENTADAS | P1: Valores dos gráficos — troca 0 por N/D para a fatia não aparecer. Não editar.
A2: REGIÃO: 2 — ARAGUAÍNA I | D2: MÊS / ANO: | F2: =IF('46'!F2="","",'46'!F2) -> 46235 | G2: DATA: | I2: =IF('46'!I2="","",'46'!I2) | J2: TÉCNICO: | K2: =IF('46'!K2="","",'46'!K2) -> ENG. VINICIUS RODRIGUES FERREIRA DE OLIVEIRA | P2: =IF(F109=0,NA(),F109) -> #N/A | Q2: =IF(G109=0,NA(),G109) -> 91.536749 | R2: =IF(H109=0,NA(),H109) -> #N/A | S2: =IF(I109=0,NA(),I109) -> #N/A | T2: =IF(J109=0,NA(),J109) -> #N/A | U2: =IF(K109=0,NA(),K109) -> 91.536749 | V2: =IF(L109=0,NA(),L109) -> #N/A
A3: TRECHO 49 — RODOVIA TO-166 - TRECHO ENTR. TO-222 - ENTR. TO-226 - ARAPOEMA | K3: EXTENSÃO: 91,537 km · 2 S.R.E.
A4: COMO PREENCHER: uma X em UMA coluna de cada grupo, por linha. Se houver mais de um defeito no mesmo km, marque o PREDOMINANTE e escreva o resto em OBSERVAÇÕES. A quilometragem é contada de 0 até o fim de CADA S.R.E. (não é o marco da rodovia).
A6: S.R.E. | B6: SENT. | C6: INÍCIO (KM) | D6: FIM (KM) | E6: EXT. (KM) | F6: CONDIÇÃO DA PLATAFORMA | J6: DRENAGEM SUPERFICIAL | M6: OBSERVAÇÕES | N6: CONFERÊNCIA (só na tela)
F7: BOM | G7: REG. (ATÉ 10 IRR./KM) | H7: RUIM (+ 10 IRR./KM) | I7: PÉSSIMA (ATOLEIRO/PTO. CRÍTICO) | J7: LIMPA | K7: OBSTRUÍDA | L7: AUSENTE
A8: S.R.E. 166ETO0100 | ENTR. TO-222 - ENTR.TO-226 (A) | LEN · Estadual · 56.531 km · início: -7.008066, -48.963547
A9: 166ETO0100 | B9: C | C9: 0 | D9: 1 | E9: =D9-C9 -> 1 | G9: X | K9: X | N9: =IF(COUNTA(F9:L9)=0,"— não preenchido",IF(COUNTIF(F9:I9,"X")<>1,"FALTA/DUPLA: CONDIÇÃO DA PLATAFORMA",IF(COUNTIF(J9:L9,"X")<>1,"FALTA/DUPLA: DRENAGEM SUPERFICIAL","OK"))) -> OK
A10: 166ETO0100 | B10: C | C10: 1 | D10: 2 | E10: =D10-C10 -> 1 | G10: X | K10: X | N10: =IF(COUNTA(F10:L10)=0,"— não preenchido",IF(COUNTIF(F10:I10,"X")<>1,"FALTA/DUPLA: CONDIÇÃO DA PLATAFORMA",IF(COUNTIF(J10:L10,"X")<>1,"FALTA/DUPLA: DRENAGEM SUPERFICIAL","OK"))) -> OK
A11: 166ETO0100 | B11: C | C11: 2 | D11: 3 | E11: =D11-C11 -> 1 | G11: X | K11: X | N11: =IF(COUNTA(F11:L11)=0,"— não preenchido",IF(COUNTIF(F11:I11,"X")<>1,"FALTA/DUPLA: CONDIÇÃO DA PLATAFORMA",IF(COUNTIF(J11:L11,"X")<>1,"FALTA/DUPLA: DRENAGEM SUPERFICIAL","OK"))) -> OK
A12: 166ETO0100 | B12: C | C12: 3 | D12: 4 | E12: =D12-C12 -> 1 | G12: X | K12: X | N12: =IF(COUNTA(F12:L12)=0,"— não preenchido",IF(COUNTIF(F12:I12,"X")<>1,"FALTA/DUPLA: CONDIÇÃO DA PLATAFORMA",IF(COUNTIF(J12:L12,"X")<>1,"FALTA/DUPLA: DRENAGEM SUPERFICIAL","OK"))) -> OK
A13: 166ETO0100 | B13: C | C13: 4 | D13: 5 | E13: =D13-C13 -> 1 | G13: X | K13: X | N13: =IF(COUNTA(F13:L13)=0,"— não preenchido",IF(COUNTIF(F13:I13,"X")<>1,"FALTA/DUPLA: CONDIÇÃO DA PLATAFORMA",IF(COUNTIF(J13:L13,"X")<>1,"FALTA/DUPLA: DRENAGEM SUPERFICIAL","OK"))) -> OK
A14: 166ETO0100 | B14: C | C14: 5 | D14: 6 | E14: =D14-C14 -> 1 | G14: X | K14: X | N14: =IF(COUNTA(F14:L14)=0,"— não preenchido",IF(COUNTIF(F14:I14,"X")<>1,"FALTA/DUPLA: CONDIÇÃO DA PLATAFORMA",IF(COUNTIF(J14:L14,"X")<>1,"FALTA/DUPLA: DRENAGEM SUPERFICIAL","OK"))) -> OK
A15: 166ETO0100 | B15: C | C15: 6 | D15: 7 | E15: =D15-C15 -> 1 | G15: X | K15: X | N15: =IF(COUNTA(F15:L15)=0,"— não preenchido",IF(COUNTIF(F15:I15,"X")<>1,"FALTA/DUPLA: CONDIÇÃO DA PLATAFORMA",IF(COUNTIF(J15:L15,"X")<>1,"FALTA/DUPLA: DRENAGEM SUPERFICIAL","OK"))) -> OK
A16: 166ETO0100 | B16: C | C16: 7 | D16: 8 | E16: =D16-C16 -> 1 | G16: X | K16: X | N16: =IF(COUNTA(F16:L16)=0,"— não preenchido",IF(COUNTIF(F16:I16,"X")<>1,"FALTA/DUPLA: CONDIÇÃO DA PLATAFORMA",IF(COUNTIF(J16:L16,"X")<>1,"FALTA/DUPLA: DRENAGEM SUPERFICIAL","OK"))) -> OK
A17: 166ETO0100 | B17: C | C17: 8 | D17: 9 | E17: =D17-C17 -> 1 | G17: X | K17: X | N17: =IF(COUNTA(F17:L17)=0,"— não preenchido",IF(COUNTIF(F17:I17,"X")<>1,"FALTA/DUPLA: CONDIÇÃO DA PLATAFORMA",IF(COUNTIF(J17:L17,"X")<>1,"FALTA/DUPLA: DRENAGEM SUPERFICIAL","OK"))) -> OK
A18: 166ETO0100 | B18: C | C18: 9 | D18: 10 | E18: =D18-C18 -> 1 | G18: X | K18: X | N18: =IF(COUNTA(F18:L18)=0,"— não preenchido",IF(COUNTIF(F18:I18,"X")<>1,"FALTA/DUPLA: CONDIÇÃO DA PLATAFORMA",IF(COUNTIF(J18:L18,"X")<>1,"FALTA/DUPLA: DRENAGEM SUPERFICIAL","OK"))) -> OK
A19: 166ETO0100 | B19: C | C19: 10 | D19: 11 | E19: =D19-C19 -> 1 | G19: X | K19: X | N19: =IF(COUNTA(F19:L19)=0,"— não preenchido",IF(COUNTIF(F19:I19,"X")<>1,"FALTA/DUPLA: CONDIÇÃO DA PLATAFORMA",IF(COUNTIF(J19:L19,"X")<>1,"FALTA/DUPLA: DRENAGEM SUPERFICIAL","OK"))) -> OK
A20: 166ETO0100 | B20: C | C20: 11 | D20: 12 | E20: =D20-C20 -> 1 | G20: X | K20: X | N20: =IF(COUNTA(F20:L20)=0,"— não preenchido",IF(COUNTIF(F20:I20,"X")<>1,"FALTA/DUPLA: CONDIÇÃO DA PLATAFORMA",IF(COUNTIF(J20:L20,"X")<>1,"FALTA/DUPLA: DRENAGEM SUPERFICIAL","OK"))) -> OK
... A65: 166ETO0100 | B65: C | C65: 56 | D65: 56.531259 | E65: =D65-C65 -> 0.53125856 | G65: X | K65: X | N65: =IF(COUNTA(F65:L65)=0,"— não preenchido",IF(COUNTIF(F65:I65,"X")<>1,"FALTA/DUPLA: CONDIÇÃO DA PLATAFORMA",IF(COUNTIF(J65:L65,"X")<>1,"FALTA/DUPLA: DRENAGEM SUPERFICIAL","OK"))) -> OK
A66: ▲ AQUI HÁ 1.588 km FORA DO ESCOPO DO CONTRATO (perímetro urbano de jurisdição municipal). Você passa por ele, mas NÃO preenche.
A67: S.R.E. 166ETO0120 | ENTR. TO-226 - ARAPOEMA *TRECHO URBANO* | LEN · Estadual · 35.005 km · início: -7.379367, -49.070044
A68: 166ETO0120 | B68: C | C68: 0 | D68: 1 | E68: =D68-C68 -> 1 | G68: X | K68: X | N68: =IF(COUNTA(F68:L68)=0,"— não preenchido",IF(COUNTIF(F68:I68,"X")<>1,"FALTA/DUPLA: CONDIÇÃO DA PLATAFORMA",IF(COUNTIF(J68:L68,"X")<>1,"FALTA/DUPLA: DRENAGEM SUPERFICIAL","OK"))) -> OK
A69: 166ETO0120 | B69: C | C69: 1 | D69: 2 | E69: =D69-C69 -> 1 | G69: X | K69: X | N69: =IF(COUNTA(F69:L69)=0,"— não preenchido",IF(COUNTIF(F69:I69,"X")<>1,"FALTA/DUPLA: CONDIÇÃO DA PLATAFORMA",IF(COUNTIF(J69:L69,"X")<>1,"FALTA/DUPLA: DRENAGEM SUPERFICIAL","OK"))) -> OK
A70: 166ETO0120 | B70: C | C70: 2 | D70: 3 | E70: =D70-C70 -> 1 | G70: X | K70: X | N70: =IF(COUNTA(F70:L70)=0,"— não preenchido",IF(COUNTIF(F70:I70,"X")<>1,"FALTA/DUPLA: CONDIÇÃO DA PLATAFORMA",IF(COUNTIF(J70:L70,"X")<>1,"FALTA/DUPLA: DRENAGEM SUPERFICIAL","OK"))) -> OK
A71: 166ETO0120 | B71: C | C71: 3 | D71: 4 | E71: =D71-C71 -> 1 | G71: X | K71: X | N71: =IF(COUNTA(F71:L71)=0,"— não preenchido",IF(COUNTIF(F71:I71,"X")<>1,"FALTA/DUPLA: CONDIÇÃO DA PLATAFORMA",IF(COUNTIF(J71:L71,"X")<>1,"FALTA/DUPLA: DRENAGEM SUPERFICIAL","OK"))) -> OK
A72: 166ETO0120 | B72: C | C72: 4 | D72: 5 | E72: =D72-C72 -> 1 | G72: X | K72: X | N72: =IF(COUNTA(F72:L72)=0,"— não preenchido",IF(COUNTIF(F72:I72,"X")<>1,"FALTA/DUPLA: CONDIÇÃO DA PLATAFORMA",IF(COUNTIF(J72:L72,"X")<>1,"FALTA/DUPLA: DRENAGEM SUPERFICIAL","OK"))) -> OK
A73: 166ETO0120 | B73: C | C73: 5 | D73: 6 | E73: =D73-C73 -> 1 | G73: X | K73: X | N73: =IF(COUNTA(F73:L73)=0,"— não preenchido",IF(COUNTIF(F73:I73,"X")<>1,"FALTA/DUPLA: CONDIÇÃO DA PLATAFORMA",IF(COUNTIF(J73:L73,"X")<>1,"FALTA/DUPLA: DRENAGEM SUPERFICIAL","OK"))) -> OK
A74: 166ETO0120 | B74: C | C74: 6 | D74: 7 | E74: =D74-C74 -> 1 | G74: X | K74: X | N74: =IF(COUNTA(F74:L74)=0,"— não preenchido",IF(COUNTIF(F74:I74,"X")<>1,"FALTA/DUPLA: CONDIÇÃO DA PLATAFORMA",IF(COUNTIF(J74:L74,"X")<>1,"FALTA/DUPLA: DRENAGEM SUPERFICIAL","OK"))) -> OK
A75: 166ETO0120 | B75: C | C75: 7 | D75: 8 | E75: =D75-C75 -> 1 | G75: X | K75: X | N75: =IF(COUNTA(F75:L75)=0,"— não preenchido",IF(COUNTIF(F75:I75,"X")<>1,"FALTA/DUPLA: CONDIÇÃO DA PLATAFORMA",IF(COUNTIF(J75:L75,"X")<>1,"FALTA/DUPLA: DRENAGEM SUPERFICIAL","OK"))) -> OK
A76: 166ETO0120 | B76: C | C76: 8 | D76: 9 | E76: =D76-C76 -> 1 | G76: X | K76: X | N76: =IF(COUNTA(F76:L76)=0,"— não preenchido",IF(COUNTIF(F76:I76,"X")<>1,"FALTA/DUPLA: CONDIÇÃO DA PLATAFORMA",IF(COUNTIF(J76:L76,"X")<>1,"FALTA/DUPLA: DRENAGEM SUPERFICIAL","OK"))) -> OK
A77: 166ETO0120 | B77: C | C77: 9 | D77: 10 | E77: =D77-C77 -> 1 | G77: X | K77: X | N77: =IF(COUNTA(F77:L77)=0,"— não preenchido",IF(COUNTIF(F77:I77,"X")<>1,"FALTA/DUPLA: CONDIÇÃO DA PLATAFORMA",IF(COUNTIF(J77:L77,"X")<>1,"FALTA/DUPLA: DRENAGEM SUPERFICIAL","OK"))) -> OK
A78: 166ETO0120 | B78: C | C78: 10 | D78: 11 | E78: =D78-C78 -> 1 | G78: X | K78: X | N78: =IF(COUNTA(F78:L78)=0,"— não preenchido",IF(COUNTIF(F78:I78,"X")<>1,"FALTA/DUPLA: CONDIÇÃO DA PLATAFORMA",IF(COUNTIF(J78:L78,"X")<>1,"FALTA/DUPLA: DRENAGEM SUPERFICIAL","OK"))) -> OK
A79: 166ETO0120 | B79: C | C79: 11 | D79: 12 | E79: =D79-C79 -> 1 | G79: X | K79: X | N79: =IF(COUNTA(F79:L79)=0,"— não preenchido",IF(COUNTIF(F79:I79,"X")<>1,"FALTA/DUPLA: CONDIÇÃO DA PLATAFORMA",IF(COUNTIF(J79:L79,"X")<>1,"FALTA/DUPLA: DRENAGEM SUPERFICIAL","OK"))) -> OK
... A103: 166ETO0120 | B103: C | C103: 35 | D103: 35.005491 | E103: =D103-C103 -> 0.0054908094 | G103: X | K103: X | N103: =IF(COUNTA(F103:L103)=0,"— não preenchido",IF(COUNTIF(F103:I103,"X")<>1,"FALTA/DUPLA: CONDIÇÃO DA PLATAFORMA",IF(COUNTIF(J103:L103,"X")<>1,"FALTA/DUPLA: DRENAGEM SUPERFICIAL","OK"))) -> OK
A105: ____________________________________________ | G105: ____________________________________________
A106: TÉCNICO RESPONSÁVEL PELA INSPEÇÃO | G106: VISTO DA SUPERVISÃO
A108: RESUMO DO TRECHO — KM LANÇADO POR ITEM
A109: KM LANÇADO | F109: =SUMIF(F$9:F$103,"X",$E$9:$E$103) -> 0 | G109: =SUMIF(G$9:G$103,"X",$E$9:$E$103) -> 91.536749 | H109: =SUMIF(H$9:H$103,"X",$E$9:$E$103) -> 0 | I109: =SUMIF(I$9:I$103,"X",$E$9:$E$103) -> 0 | J109: =SUMIF(J$9:J$103,"X",$E$9:$E$103) -> 0 | K109: =SUMIF(K$9:K$103,"X",$E$9:$E$103) -> 91.536749 | L109: =SUMIF(L$9:L$103,"X",$E$9:$E$103) -> 0
A110: % DA EXTENSÃO | F110: =IF($I112=0,0,F109/$I112) -> 0 | G110: =IF($I112=0,0,G109/$I112) -> 1 | H110: =IF($I112=0,0,H109/$I112) -> 0 | I110: =IF($I112=0,0,I109/$I112) -> 0 | J110: =IF($I112=0,0,J109/$I112) -> 0 | K110: =IF($I112=0,0,K109/$I112) -> 1 | L110: =IF($I112=0,0,L109/$I112) -> 0
...

Sheet 59
A1: PROGRAMA DE MANUTENÇÃO RODOVIÁRIA — FICHA DE INSPEÇÃO — RODOVIAS NÃO PAVIMENTADAS | P1: Valores dos gráficos — troca 0 por N/D para a fatia não aparecer. Não editar.
A2: REGIÃO: 2 — ARAGUAÍNA I | D2: MÊS / ANO: | F2: =IF('46'!F2="","",'46'!F2) -> 46235 | G2: DATA: | I2: =IF('46'!I2="","",'46'!I2) | J2: TÉCNICO: | K2: =IF('46'!K2="","",'46'!K2) -> ENG. VINICIUS RODRIGUES FERREIRA DE OLIVEIRA | P2: =IF(F58=0,NA(),F58) -> #N/A | Q2: =IF(G58=0,NA(),G58) -> 43.086791 | R2: =IF(H58=0,NA(),H58) -> #N/A | S2: =IF(I58=0,NA(),I58) -> #N/A | T2: =IF(J58=0,NA(),J58) -> #N/A | U2: =IF(K58=0,NA(),K58) -> 43.086791 | V2: =IF(L58=0,NA(),L58) -> #N/A
A3: TRECHO 59 — RODOVIA TO-418 - TRECHO ENTR. BR-153 - ENTR. TO-164 | K3: EXTENSÃO: 43,087 km · 1 S.R.E.
A4: COMO PREENCHER: uma X em UMA coluna de cada grupo, por linha. Se houver mais de um defeito no mesmo km, marque o PREDOMINANTE e escreva o resto em OBSERVAÇÕES. A quilometragem é contada de 0 até o fim de CADA S.R.E. (não é o marco da rodovia).
A6: S.R.E. | B6: SENT. | C6: INÍCIO (KM) | D6: FIM (KM) | E6: EXT. (KM) | F6: CONDIÇÃO DA PLATAFORMA | J6: DRENAGEM SUPERFICIAL | M6: OBSERVAÇÕES | N6: CONFERÊNCIA (só na tela)
F7: BOM | G7: REG. (ATÉ 10 IRR./KM) | H7: RUIM (+ 10 IRR./KM) | I7: PÉSSIMA (ATOLEIRO/PTO. CRÍTICO) | J7: LIMPA | K7: OBSTRUÍDA | L7: AUSENTE
A8: S.R.E. 418ETO0010 | ENTR. TO-164 (XAMBIOAZINHO) - ENTR. BR-153 | LEN · Estadual · 43.087 km · início: -6.615803, -48.358511
A9: 418ETO0010 | B9: C | C9: 0 | D9: 1 | E9: =D9-C9 -> 1 | G9: X | K9: X | N9: =IF(COUNTA(F9:L9)=0,"— não preenchido",IF(COUNTIF(F9:I9,"X")<>1,"FALTA/DUPLA: CONDIÇÃO DA PLATAFORMA",IF(COUNTIF(J9:L9,"X")<>1,"FALTA/DUPLA: DRENAGEM SUPERFICIAL","OK"))) -> OK
A10: 418ETO0010 | B10: C | C10: 1 | D10: 2 | E10: =D10-C10 -> 1 | G10: X | K10: X | N10: =IF(COUNTA(F10:L10)=0,"— não preenchido",IF(COUNTIF(F10:I10,"X")<>1,"FALTA/DUPLA: CONDIÇÃO DA PLATAFORMA",IF(COUNTIF(J10:L10,"X")<>1,"FALTA/DUPLA: DRENAGEM SUPERFICIAL","OK"))) -> OK
A11: 418ETO0010 | B11: C | C11: 2 | D11: 3 | E11: =D11-C11 -> 1 | G11: X | K11: X | N11: =IF(COUNTA(F11:L11)=0,"— não preenchido",IF(COUNTIF(F11:I11,"X")<>1,"FALTA/DUPLA: CONDIÇÃO DA PLATAFORMA",IF(COUNTIF(J11:L11,"X")<>1,"FALTA/DUPLA: DRENAGEM SUPERFICIAL","OK"))) -> OK
A12: 418ETO0010 | B12: C | C12: 3 | D12: 4 | E12: =D12-C12 -> 1 | G12: X | K12: X | N12: =IF(COUNTA(F12:L12)=0,"— não preenchido",IF(COUNTIF(F12:I12,"X")<>1,"FALTA/DUPLA: CONDIÇÃO DA PLATAFORMA",IF(COUNTIF(J12:L12,"X")<>1,"FALTA/DUPLA: DRENAGEM SUPERFICIAL","OK"))) -> OK
A13: 418ETO0010 | B13: C | C13: 4 | D13: 5 | E13: =D13-C13 -> 1 | G13: X | K13: X | N13: =IF(COUNTA(F13:L13)=0,"— não preenchido",IF(COUNTIF(F13:I13,"X")<>1,"FALTA/DUPLA: CONDIÇÃO DA PLATAFORMA",IF(COUNTIF(J13:L13,"X")<>1,"FALTA/DUPLA: DRENAGEM SUPERFICIAL","OK"))) -> OK
A14: 418ETO0010 | B14: C | C14: 5 | D14: 6 | E14: =D14-C14 -> 1 | G14: X | K14: X | N14: =IF(COUNTA(F14:L14)=0,"— não preenchido",IF(COUNTIF(F14:I14,"X")<>1,"FALTA/DUPLA: CONDIÇÃO DA PLATAFORMA",IF(COUNTIF(J14:L14,"X")<>1,"FALTA/DUPLA: DRENAGEM SUPERFICIAL","OK"))) -> OK
A15: 418ETO0010 | B15: C | C15: 6 | D15: 7 | E15: =D15-C15 -> 1 | G15: X | K15: X | N15: =IF(COUNTA(F15:L15)=0,"— não preenchido",IF(COUNTIF(F15:I15,"X")<>1,"FALTA/DUPLA: CONDIÇÃO DA PLATAFORMA",IF(COUNTIF(J15:L15,"X")<>1,"FALTA/DUPLA: DRENAGEM SUPERFICIAL","OK"))) -> OK
A16: 418ETO0010 | B16: C | C16: 7 | D16: 8 | E16: =D16-C16 -> 1 | G16: X | K16: X | N16: =IF(COUNTA(F16:L16)=0,"— não preenchido",IF(COUNTIF(F16:I16,"X")<>1,"FALTA/DUPLA: CONDIÇÃO DA PLATAFORMA",IF(COUNTIF(J16:L16,"X")<>1,"FALTA/DUPLA: DRENAGEM SUPERFICIAL","OK"))) -> OK
A17: 418ETO0010 | B17: C | C17: 8 | D17: 9 | E17: =D17-C17 -> 1 | G17: X | K17: X | N17: =IF(COUNTA(F17:L17)=0,"— não preenchido",IF(COUNTIF(F17:I17,"X")<>1,"FALTA/DUPLA: CONDIÇÃO DA PLATAFORMA",IF(COUNTIF(J17:L17,"X")<>1,"FALTA/DUPLA: DRENAGEM SUPERFICIAL","OK"))) -> OK
A18: 418ETO0010 | B18: C | C18: 9 | D18: 10 | E18: =D18-C18 -> 1 | G18: X | K18: X | N18: =IF(COUNTA(F18:L18)=0,"— não preenchido",IF(COUNTIF(F18:I18,"X")<>1,"FALTA/DUPLA: CONDIÇÃO DA PLATAFORMA",IF(COUNTIF(J18:L18,"X")<>1,"FALTA/DUPLA: DRENAGEM SUPERFICIAL","OK"))) -> OK
A19: 418ETO0010 | B19: C | C19: 10 | D19: 11 | E19: =D19-C19 -> 1 | G19: X | K19: X | N19: =IF(COUNTA(F19:L19)=0,"— não preenchido",IF(COUNTIF(F19:I19,"X")<>1,"FALTA/DUPLA: CONDIÇÃO DA PLATAFORMA",IF(COUNTIF(J19:L19,"X")<>1,"FALTA/DUPLA: DRENAGEM SUPERFICIAL","OK"))) -> OK
A20: 418ETO0010 | B20: C | C20: 11 | D20: 12 | E20: =D20-C20 -> 1 | G20: X | K20: X | N20: =IF(COUNTA(F20:L20)=0,"— não preenchido",IF(COUNTIF(F20:I20,"X")<>1,"FALTA/DUPLA: CONDIÇÃO DA PLATAFORMA",IF(COUNTIF(J20:L20,"X")<>1,"FALTA/DUPLA: DRENAGEM SUPERFICIAL","OK"))) -> OK
... A52: 418ETO0010 | B52: C | C52: 43 | D52: 43.086791 | E52: =D52-C52 -> 0.086791464 | G52: X | K52: X | N52: =IF(COUNTA(F52:L52)=0,"— não preenchido",IF(COUNTIF(F52:I52,"X")<>1,"FALTA/DUPLA: CONDIÇÃO DA PLATAFORMA",IF(COUNTIF(J52:L52,"X")<>1,"FALTA/DUPLA: DRENAGEM SUPERFICIAL","OK"))) -> OK
A54: ____________________________________________ | G54: ____________________________________________
A55: TÉCNICO RESPONSÁVEL PELA INSPEÇÃO | G55: VISTO DA SUPERVISÃO
A57: RESUMO DO TRECHO — KM LANÇADO POR ITEM
A58: KM LANÇADO | F58: =SUMIF(F$9:F$52,"X",$E$9:$E$52) -> 0 | G58: =SUMIF(G$9:G$52,"X",$E$9:$E$52) -> 43.086791 | H58: =SUMIF(H$9:H$52,"X",$E$9:$E$52) -> 0 | I58: =SUMIF(I$9:I$52,"X",$E$9:$E$52) -> 0 | J58: =SUMIF(J$9:J$52,"X",$E$9:$E$52) -> 0 | K58: =SUMIF(K$9:K$52,"X",$E$9:$E$52) -> 43.086791 | L58: =SUMIF(L$9:L$52,"X",$E$9:$E$52) -> 0
A59: % DA EXTENSÃO | F59: =IF($I61=0,0,F58/$I61) -> 0 | G59: =IF($I61=0,0,G58/$I61) -> 1 | H59: =IF($I61=0,0,H58/$I61) -> 0 | I59: =IF($I61=0,0,I58/$I61) -> 0 | J59: =IF($I61=0,0,J58/$I61) -> 0 | K59: =IF($I61=0,0,K58/$I61) -> 1 | L59: =IF($I61=0,0,L58/$I61) -> 0
A60: CONFERÊNCIA POR GRUPO | F60: =IF(SUM(F58:I58)=0,"— não preenchido",IF(ROUND(SUM(F58:I58)-$I61,3)=0,"OK — "&ROUND(SUM(F58:I58),3)&" km","ERRO — dif. de "&ROUND(SUM(F58:I58)-$I61,3)&" km")) -> OK — 43,087 km | J60: =IF(SUM(J58:L58)=0,"— não preenchido",IF(ROUND(SUM(J58:L58)-$I61,3)=0,"OK — "&ROUND(SUM(J58:L58),3)&" km","ERRO — dif. de "&ROUND(SUM(J58:L58)-$I61,3)&" km")) -> OK — 43,087 km
A61: EXTENSÃO TOTAL DO TRECHO | I61: =SUM(E9:E52) -> 43.086791 | M61: =COUNTIF(N9:N52,"OK")&" de "&COUNT($E$9:$E$52)&" linhas conferidas" -> 44 de 44 linhas conferidas
A63: LEGENDA
A64: REGULAR | E64: Até 10 irregularidades por km
A65: RUIM | E65: Mais de 10 irregularidades por km
A66: PÉSSIMA | E66: Atoleiro ou ponto crítico
A67: SIT. | E67: LEN = leito natural · EOP = em obras de pavimentação
A68: FAIXA AZUL | E68: Cabeçalho de cada S.R.E.: descrição, situação, jurisdição, extensão e coordenada de início.
A69: INÍCIO / FIM (KM) | E69: Contados de 0 até o fim de CADA S.R.E. Não é o marco quilométrico da rodovia.
A70: SENT. | E70: C = crescente · D = decrescente
A71: FAIXA CINZA | E71: Segmento fora do escopo do contrato: você passa por ele, mas não preenche.
A72: CÉLULA VERMELHA | E72: Mais de uma X no mesmo grupo. Apague uma delas.
A73: CONFERÊNCIA | E73: Só na tela, não sai impresso. Fica OK com uma X em cada grupo.

Sheet 60
A1: PROGRAMA DE MANUTENÇÃO RODOVIÁRIA — FICHA DE INSPEÇÃO — RODOVIAS NÃO PAVIMENTADAS | P1: Valores dos gráficos — troca 0 por N/D para a fatia não aparecer. Não editar.
A2: REGIÃO: 2 — ARAGUAÍNA I | D2: MÊS / ANO: | F2: =IF('46'!F2="","",'46'!F2) -> 46235 | G2: DATA: | I2: =IF('46'!I2="","",'46'!I2) | J2: TÉCNICO: | K2: =IF('46'!K2="","",'46'!K2) -> ENG. VINICIUS RODRIGUES FERREIRA DE OLIVEIRA | P2: =IF(F44=0,NA(),F44) -> 23.115565 | Q2: =IF(G44=0,NA(),G44) -> 6 | R2: =IF(H44=0,NA(),H44) -> #N/A | S2: =IF(I44=0,NA(),I44) -> #N/A | T2: =IF(J44=0,NA(),J44) -> 29.115565 | U2: =IF(K44=0,NA(),K44) -> #N/A | V2: =IF(L44=0,NA(),L44) -> #N/A
A3: TRECHO 60 — RODOVIA TO-419 - TRECHO POVOADO BARRA DA GROTA - ENTR. TO-222 | K3: EXTENSÃO: 29,116 km · 1 S.R.E.
A4: COMO PREENCHER: uma X em UMA coluna de cada grupo, por linha. Se houver mais de um defeito no mesmo km, marque o PREDOMINANTE e escreva o resto em OBSERVAÇÕES. A quilometragem é contada de 0 até o fim de CADA S.R.E. (não é o marco da rodovia).
A6: S.R.E. | B6: SENT. | C6: INÍCIO (KM) | D6: FIM (KM) | E6: EXT. (KM) | F6: CONDIÇÃO DA PLATAFORMA | J6: DRENAGEM SUPERFICIAL | M6: OBSERVAÇÕES | N6: CONFERÊNCIA (só na tela)
F7: BOM | G7: REG. (ATÉ 10 IRR./KM) | H7: RUIM (+ 10 IRR./KM) | I7: PÉSSIMA (ATOLEIRO/PTO. CRÍTICO) | J7: LIMPA | K7: OBSTRUÍDA | L7: AUSENTE
A8: S.R.E. 419ETO0010 | ENTR. TO-222 (BARRA DA GROTA) - ENTR. TO-222 (BRITADOR) | LEN · Estadual · 29.116 km · início: -7.208771, -48.302157
A9: 419ETO0010 | B9: C | C9: 0 | D9: 1 | E9: =D9-C9 -> 1 | F9: X | J9: X | N9: =IF(COUNTA(F9:L9)=0,"— não preenchido",IF(COUNTIF(F9:I9,"X")<>1,"FALTA/DUPLA: CONDIÇÃO DA PLATAFORMA",IF(COUNTIF(J9:L9,"X")<>1,"FALTA/DUPLA: DRENAGEM SUPERFICIAL","OK"))) -> OK
A10: 419ETO0010 | B10: C | C10: 1 | D10: 2 | E10: =D10-C10 -> 1 | F10: X | J10: X | N10: =IF(COUNTA(F10:L10)=0,"— não preenchido",IF(COUNTIF(F10:I10,"X")<>1,"FALTA/DUPLA: CONDIÇÃO DA PLATAFORMA",IF(COUNTIF(J10:L10,"X")<>1,"FALTA/DUPLA: DRENAGEM SUPERFICIAL","OK"))) -> OK
A11: 419ETO0010 | B11: C | C11: 2 | D11: 3 | E11: =D11-C11 -> 1 | F11: X | J11: X | N11: =IF(COUNTA(F11:L11)=0,"— não preenchido",IF(COUNTIF(F11:I11,"X")<>1,"FALTA/DUPLA: CONDIÇÃO DA PLATAFORMA",IF(COUNTIF(J11:L11,"X")<>1,"FALTA/DUPLA: DRENAGEM SUPERFICIAL","OK"))) -> OK
A12: 419ETO0010 | B12: C | C12: 3 | D12: 4 | E12: =D12-C12 -> 1 | F12: X | J12: X | N12: =IF(COUNTA(F12:L12)=0,"— não preenchido",IF(COUNTIF(F12:I12,"X")<>1,"FALTA/DUPLA: CONDIÇÃO DA PLATAFORMA",IF(COUNTIF(J12:L12,"X")<>1,"FALTA/DUPLA: DRENAGEM SUPERFICIAL","OK"))) -> OK
A13: 419ETO0010 | B13: C | C13: 4 | D13: 5 | E13: =D13-C13 -> 1 | G13: X | J13: X | N13: =IF(COUNTA(F13:L13)=0,"— não preenchido",IF(COUNTIF(F13:I13,"X")<>1,"FALTA/DUPLA: CONDIÇÃO DA PLATAFORMA",IF(COUNTIF(J13:L13,"X")<>1,"FALTA/DUPLA: DRENAGEM SUPERFICIAL","OK"))) -> OK
A14: 419ETO0010 | B14: C | C14: 5 | D14: 6 | E14: =D14-C14 -> 1 | F14: X | J14: X | N14: =IF(COUNTA(F14:L14)=0,"— não preenchido",IF(COUNTIF(F14:I14,"X")<>1,"FALTA/DUPLA: CONDIÇÃO DA PLATAFORMA",IF(COUNTIF(J14:L14,"X")<>1,"FALTA/DUPLA: DRENAGEM SUPERFICIAL","OK"))) -> OK
A15: 419ETO0010 | B15: C | C15: 6 | D15: 7 | E15: =D15-C15 -> 1 | G15: X | J15: X | N15: =IF(COUNTA(F15:L15)=0,"— não preenchido",IF(COUNTIF(F15:I15,"X")<>1,"FALTA/DUPLA: CONDIÇÃO DA PLATAFORMA",IF(COUNTIF(J15:L15,"X")<>1,"FALTA/DUPLA: DRENAGEM SUPERFICIAL","OK"))) -> OK
A16: 419ETO0010 | B16: C | C16: 7 | D16: 8 | E16: =D16-C16 -> 1 | F16: X | J16: X | N16: =IF(COUNTA(F16:L16)=0,"— não preenchido",IF(COUNTIF(F16:I16,"X")<>1,"FALTA/DUPLA: CONDIÇÃO DA PLATAFORMA",IF(COUNTIF(J16:L16,"X")<>1,"FALTA/DUPLA: DRENAGEM SUPERFICIAL","OK"))) -> OK
A17: 419ETO0010 | B17: C | C17: 8 | D17: 9 | E17: =D17-C17 -> 1 | F17: X | J17: X | N17: =IF(COUNTA(F17:L17)=0,"— não preenchido",IF(COUNTIF(F17:I17,"X")<>1,"FALTA/DUPLA: CONDIÇÃO DA PLATAFORMA",IF(COUNTIF(J17:L17,"X")<>1,"FALTA/DUPLA: DRENAGEM SUPERFICIAL","OK"))) -> OK
A18: 419ETO0010 | B18: C | C18: 9 | D18: 10 | E18: =D18-C18 -> 1 | F18: X | J18: X | N18: =IF(COUNTA(F18:L18)=0,"— não preenchido",IF(COUNTIF(F18:I18,"X")<>1,"FALTA/DUPLA: CONDIÇÃO DA PLATAFORMA",IF(COUNTIF(J18:L18,"X")<>1,"FALTA/DUPLA: DRENAGEM SUPERFICIAL","OK"))) -> OK
A19: 419ETO0010 | B19: C | C19: 10 | D19: 11 | E19: =D19-C19 -> 1 | F19: X | J19: X | N19: =IF(COUNTA(F19:L19)=0,"— não preenchido",IF(COUNTIF(F19:I19,"X")<>1,"FALTA/DUPLA: CONDIÇÃO DA PLATAFORMA",IF(COUNTIF(J19:L19,"X")<>1,"FALTA/DUPLA: DRENAGEM SUPERFICIAL","OK"))) -> OK
A20: 419ETO0010 | B20: C | C20: 11 | D20: 12 | E20: =D20-C20 -> 1 | G20: X | J20: X | N20: =IF(COUNTA(F20:L20)=0,"— não preenchido",IF(COUNTIF(F20:I20,"X")<>1,"FALTA/DUPLA: CONDIÇÃO DA PLATAFORMA",IF(COUNTIF(J20:L20,"X")<>1,"FALTA/DUPLA: DRENAGEM SUPERFICIAL","OK"))) -> OK
A21: 419ETO0010 | B21: C | C21: 12 | D21: 13 | E21: =D21-C21 -> 1 | G21: X | J21: X | N21: =IF(COUNTA(F21:L21)=0,"— não preenchido",IF(COUNTIF(F21:I21,"X")<>1,"FALTA/DUPLA: CONDIÇÃO DA PLATAFORMA",IF(COUNTIF(J21:L21,"X")<>1,"FALTA/DUPLA: DRENAGEM SUPERFICIAL","OK"))) -> OK
A22: 419ETO0010 | B22: C | C22: 13 | D22: 14 | E22: =D22-C22 -> 1 | G22: X | J22: X | N22: =IF(COUNTA(F22:L22)=0,"— não preenchido",IF(COUNTIF(F22:I22,"X")<>1,"FALTA/DUPLA: CONDIÇÃO DA PLATAFORMA",IF(COUNTIF(J22:L22,"X")<>1,"FALTA/DUPLA: DRENAGEM SUPERFICIAL","OK"))) -> OK
A23: 419ETO0010 | B23: C | C23: 14 | D23: 15 | E23: =D23-C23 -> 1 | G23: X | J23: X | N23: =IF(COUNTA(F23:L23)=0,"— não preenchido",IF(COUNTIF(F23:I23,"X")<>1,"FALTA/DUPLA: CONDIÇÃO DA PLATAFORMA",IF(COUNTIF(J23:L23,"X")<>1,"FALTA/DUPLA: DRENAGEM SUPERFICIAL","OK"))) -> OK
A24: 419ETO0010 | B24: C | C24: 15 | D24: 16 | E24: =D24-C24 -> 1 | F24: X | J24: X | N24: =IF(COUNTA(F24:L24)=0,"— não preenchido",IF(COUNTIF(F24:I24,"X")<>1,"FALTA/DUPLA: CONDIÇÃO DA PLATAFORMA",IF(COUNTIF(J24:L24,"X")<>1,"FALTA/DUPLA: DRENAGEM SUPERFICIAL","OK"))) -> OK
A25: 419ETO0010 | B25: C | C25: 16 | D25: 17 | E25: =D25-C25 -> 1 | F25: X | J25: X | N25: =IF(COUNTA(F25:L25)=0,"— não preenchido",IF(COUNTIF(F25:I25,"X")<>1,"FALTA/DUPLA: CONDIÇÃO DA PLATAFORMA",IF(COUNTIF(J25:L25,"X")<>1,"FALTA/DUPLA: DRENAGEM SUPERFICIAL","OK"))) -> OK
A26: 419ETO0010 | B26: C | C26: 17 | D26: 18 | E26: =D26-C26 -> 1 | F26: X | J26: X | N26: =IF(COUNTA(F26:L26)=0,"— não preenchido",IF(COUNTIF(F26:I26,"X")<>1,"FALTA/DUPLA: CONDIÇÃO DA PLATAFORMA",IF(COUNTIF(J26:L26,"X")<>1,"FALTA/DUPLA: DRENAGEM SUPERFICIAL","OK"))) -> OK
A27: 419ETO0010 | B27: C | C27: 18 | D27: 19 | E27: =D27-C27 -> 1 | F27: X | J27: X | N27: =IF(COUNTA(F27:L27)=0,"— não preenchido",IF(COUNTIF(F27:I27,"X")<>1,"FALTA/DUPLA: CONDIÇÃO DA PLATAFORMA",IF(COUNTIF(J27:L27,"X")<>1,"FALTA/DUPLA: DRENAGEM SUPERFICIAL","OK"))) -> OK
A28: 419ETO0010 | B28: C | C28: 19 | D28: 20 | E28: =D28-C28 -> 1 | F28: X | J28: X | N28: =IF(COUNTA(F28:L28)=0,"— não preenchido",IF(COUNTIF(F28:I28,"X")<>1,"FALTA/DUPLA: CONDIÇÃO DA PLATAFORMA",IF(COUNTIF(J28:L28,"X")<>1,"FALTA/DUPLA: DRENAGEM SUPERFICIAL","OK"))) -> OK
A29: 419ETO0010 | B29: C | C29: 20 | D29: 21 | E29: =D29-C29 -> 1 | F29: X | J29: X | N29: =IF(COUNTA(F29:L29)=0,"— não preenchido",IF(COUNTIF(F29:I29,"X")<>1,"FALTA/DUPLA: CONDIÇÃO DA PLATAFORMA",IF(COUNTIF(J29:L29,"X")<>1,"FALTA/DUPLA: DRENAGEM SUPERFICIAL","OK"))) -> OK
A30: 419ETO0010 | B30: C | C30: 21 | D30: 22 | E30: =D30-C30 -> 1 | F30: X | J30: X | N30: =IF(COUNTA(F30:L30)=0,"— não preenchido",IF(COUNTIF(F30:I30,"X")<>1,"FALTA/DUPLA: CONDIÇÃO DA PLATAFORMA",IF(COUNTIF(J30:L30,"X")<>1,"FALTA/DUPLA: DRENAGEM SUPERFICIAL","OK"))) -> OK
A31: 419ETO0010 | B31: C | C31: 22 | D31: 23 | E31: =D31-C31 -> 1 | F31: X | J31: X | N31: =IF(COUNTA(F31:L31)=0,"— não preenchido",IF(COUNTIF(F31:I31,"X")<>1,"FALTA/DUPLA: CONDIÇÃO DA PLATAFORMA",IF(COUNTIF(J31:L31,"X")<>1,"FALTA/DUPLA: DRENAGEM SUPERFICIAL","OK"))) -> OK
A32: 419ETO0010 | B32: C | C32: 23 | D32: 24 | E32: =D32-C32 -> 1 | F32: X | J32: X | N32: =IF(COUNTA(F32:L32)=0,"— não preenchido",IF(COUNTIF(F32:I32,"X")<>1,"FALTA/DUPLA: CONDIÇÃO DA PLATAFORMA",IF(COUNTIF(J32:L32,"X")<>1,"FALTA/DUPLA: DRENAGEM SUPERFICIAL","OK"))) -> OK
A33: 419ETO0010 | B33: C | C33: 24 | D33: 25 | E33: =D33-C33 -> 1 | F33: X | J33: X | N33: =IF(COUNTA(F33:L33)=0,"— não preenchido",IF(COUNTIF(F33:I33,"X")<>1,"FALTA/DUPLA: CONDIÇÃO DA PLATAFORMA",IF(COUNTIF(J33:L33,"X")<>1,"FALTA/DUPLA: DRENAGEM SUPERFICIAL","OK"))) -> OK
A34: 419ETO0010 | B34: C | C34: 25 | D34: 26 | E34: =D34-C34 -> 1 | F34: X | J34: X | N34: =IF(COUNTA(F34:L34)=0,"— não preenchido",IF(COUNTIF(F34:I34,"X")<>1,"FALTA/DUPLA: CONDIÇÃO DA PLATAFORMA",IF(COUNTIF(J34:L34,"X")<>1,"FALTA/DUPLA: DRENAGEM SUPERFICIAL","OK"))) -> OK
A35: 419ETO0010 | B35: C | C35: 26 | D35: 27 | E35: =D35-C35 -> 1 | F35: X | J35: X | N35: =IF(COUNTA(F35:L35)=0,"— não preenchido",IF(COUNTIF(F35:I35,"X")<>1,"FALTA/DUPLA: CONDIÇÃO DA PLATAFORMA",IF(COUNTIF(J35:L35,"X")<>1,"FALTA/DUPLA: DRENAGEM SUPERFICIAL","OK"))) -> OK
... A38: 419ETO0010 | B38: C | C38: 29 | D38: 29.115565 | E38: =D38-C38 -> 0.11556488 | F38: X | J38: X | N38: =IF(COUNTA(F38:L38)=0,"— não preenchido",IF(COUNTIF(F38:I38,"X")<>1,"FALTA/DUPLA: CONDIÇÃO DA PLATAFORMA",IF(COUNTIF(J38:L38,"X")<>1,"FALTA/DUPLA: DRENAGEM SUPERFICIAL","OK"))) -> OK
A40: ____________________________________________ | G40: ____________________________________________
A41: TÉCNICO RESPONSÁVEL PELA INSPEÇÃO | G41: VISTO DA SUPERVISÃO
A43: RESUMO DO TRECHO — KM LANÇADO POR ITEM
A44: KM LANÇADO | F44: =SUMIF(F$9:F$38,"X",$E$9:$E$38) -> 23.115565 | G44: =SUMIF(G$9:G$38,"X",$E$9:$E$38) -> 6 | H44: =SUMIF(H$9:H$38,"X",$E$9:$E$38) -> 0 | I44: =SUMIF(I$9:I$38,"X",$E$9:$E$38) -> 0 | J44: =SUMIF(J$9:J$38,"X",$E$9:$E$38) -> 29.115565 | K44: =SUMIF(K$9:K$38,"X",$E$9:$E$38) -> 0 | L44: =SUMIF(L$9:L$38,"X",$E$9:$E$38) -> 0
