Workbook

Sheet RESUMO
A1: RESUMO CONSOLIDADO — REGIÃO 1 — RODOVIAS NÃO PAVIMENTADAS | M1: Valores dos gráficos — troca 0 por N/D para a fatia não aparecer. Não editar.
A2: Todos os números vêm das abas dos trechos por referência direta. Não digite nada aqui. A coluna CONFERÊNCIA acusa qualquer trecho em que a soma das marcações não fecha com a extensão. | M2: =IF(D17=0,NA(),D17) -> 51.429669 | N2: =IF(E17=0,NA(),E17) -> 330.41845 | O2: =IF(F17=0,NA(),F17) -> 165.34147 | P2: =IF(G17=0,NA(),G17) -> #N/A | Q2: =IF(H17=0,NA(),H17) -> 33.591201 | R2: =IF(I17=0,NA(),I17) -> 508.75992 | S2: =IF(J17=0,NA(),J17) -> 4.8384683
A4: Nº TRECHO | B4: TRECHO | C4: EXTENSÃO (KM) | D4: CONDIÇÃO DA PLATAFORMA | H4: DRENAGEM SUPERFICIAL | K4: CONFERÊNCIA
D5: BOM | E5: REG. (ATÉ 10 IRR./KM) | F5: RUIM (+ 10 IRR./KM) | G5: PÉSSIMA (ATOLEIRO/PTO. CRÍTICO) | H5: LIMPA | I5: OBSTRUÍDA | J5: AUSENTE
A6: 67 | B6: RODOVIA TO-010 - TRECHO ENTR. BR-010 (ITACAJÁ) - PALMEIRANTE | C6: ='67'!I97 -> 77.592133 | D6: ='67'!F94 -> 0 | E6: ='67'!G94 -> 77.592133 | F6: ='67'!H94 -> 0 | G6: ='67'!I94 -> 0 | H6: ='67'!J94 -> 0 | I6: ='67'!K94 -> 77.592133 | J6: ='67'!L94 -> 0 | K6: =IF(SUM(D6:G6)=0,"— não preenchido",IF(ROUND(SUM(D6:G6)-C6,3)=0,"OK","ERRO — dif. de "&ROUND(SUM(D6:G6)-C6,3)&" km")) -> OK
A7: 69 | B7: RODOVIA TO-010 - TRECHO ENTR. TO-222 (POVOADO FARTURÃO) - BABAÇULÂNDIA | C7: ='69'!I57 -> 38.429669 | D7: ='69'!F54 -> 38.429669 | E7: ='69'!G54 -> 0 | F7: ='69'!H54 -> 0 | G7: ='69'!I54 -> 0 | H7: ='69'!J54 -> 33.591201 | I7: ='69'!K54 -> 0 | J7: ='69'!L54 -> 4.8384683 | K7: =IF(SUM(D7:G7)=0,"— não preenchido",IF(ROUND(SUM(D7:G7)-C7,3)=0,"OK","ERRO — dif. de "&ROUND(SUM(D7:G7)-C7,3)&" km")) -> OK
A8: 71 | B8: RODOVIA TO-020 - TRECHO RECURSOLÂNDIA - CAMPOS LINDOS | C8: ='71'!I166 -> 148.40783 | D8: ='71'!F163 -> 0 | E8: ='71'!G163 -> 25 | F8: ='71'!H163 -> 123.40783 | G8: ='71'!I163 -> 0 | H8: ='71'!J163 -> 0 | I8: ='71'!K163 -> 148.40783 | J8: ='71'!L163 -> 0 | K8: =IF(SUM(D8:G8)=0,"— não preenchido",IF(ROUND(SUM(D8:G8)-C8,3)=0,"OK","ERRO — dif. de "&ROUND(SUM(D8:G8)-C8,3)&" km")) -> OK
A9: 72 | B9: RODOVIA TO-130 - TRECHO ENTR. TO-424 - TRECHO ENTR. TO-222 | C9: ='72'!I37 -> 19.326516 | D9: ='72'!F34 -> 0 | E9: ='72'!G34 -> 15.326516 | F9: ='72'!H34 -> 4 | G9: ='72'!I34 -> 0 | H9: ='72'!J34 -> 0 | I9: ='72'!K34 -> 19.326516 | J9: ='72'!L34 -> 0 | K9: =IF(SUM(D9:G9)=0,"— não preenchido",IF(ROUND(SUM(D9:G9)-C9,3)=0,"OK","ERRO — dif. de "&ROUND(SUM(D9:G9)-C9,3)&" km")) -> OK
A10: 75 | B10: RODOVIA TO-226 - TRECHO NOVA OLINDA - ENTR. TO-010 | C10: ='75'!I73 -> 54.389636 | D10: ='75'!F70 -> 0 | E10: ='75'!G70 -> 52.389636 | F10: ='75'!H70 -> 2 | G10: ='75'!I70 -> 0 | H10: ='75'!J70 -> 0 | I10: ='75'!K70 -> 54.389636 | J10: ='75'!L70 -> 0 | K10: =IF(SUM(D10:G10)=0,"— não preenchido",IF(ROUND(SUM(D10:G10)-C10,3)=0,"OK","ERRO — dif. de "&ROUND(SUM(D10:G10)-C10,3)&" km")) -> OK
A11: 76 | B11: RODOVIA TO-226 - TRECHO ENTR. TO-010 (POVOADO CAMPOS) - ENTR. BR-010 | C11: ='76'!I47 -> 28.343878 | D11: ='76'!F44 -> 3 | E11: ='76'!G44 -> 22.343878 | F11: ='76'!H44 -> 3 | G11: ='76'!I44 -> 0 | H11: ='76'!J44 -> 0 | I11: ='76'!K44 -> 28.343878 | J11: ='76'!L44 -> 0 | K11: =IF(SUM(D11:G11)=0,"— não preenchido",IF(ROUND(SUM(D11:G11)-C11,3)=0,"OK","ERRO — dif. de "&ROUND(SUM(D11:G11)-C11,3)&" km")) -> OK
A12: 79 | B12: RODOVIA TO-423 - TRECHO ARAGUAÍNA - ENTR. TO-424 | C12: ='79'!I46 -> 28.588959 | D12: ='79'!F43 -> 2 | E12: ='79'!G43 -> 22 | F12: ='79'!H43 -> 4.5889588 | G12: ='79'!I43 -> 0 | H12: ='79'!J43 -> 0 | I12: ='79'!K43 -> 28.588959 | J12: ='79'!L43 -> 0 | K12: =IF(SUM(D12:G12)=0,"— não preenchido",IF(ROUND(SUM(D12:G12)-C12,3)=0,"OK","ERRO — dif. de "&ROUND(SUM(D12:G12)-C12,3)&" km")) -> OK
A13: 81 | B13: RODOVIA TO-424 - TRECHO ENTR. TO-010 (BABAÇULÂNDIA) - ENTR. TO-222 | C13: ='81'!I52 -> 31.499705 | D13: ='81'!F49 -> 8 | E13: ='81'!G49 -> 17.885783 | F13: ='81'!H49 -> 5.6139219 | G13: ='81'!I49 -> 0 | H13: ='81'!J49 -> 0 | I13: ='81'!K49 -> 31.499705 | J13: ='81'!L49 -> 0 | K13: =IF(SUM(D13:G13)=0,"— não preenchido",IF(ROUND(SUM(D13:G13)-C13,3)=0,"OK","ERRO — dif. de "&ROUND(SUM(D13:G13)-C13,3)&" km")) -> OK
A14: 82 | B14: RODOVIA TO-425 - TRECHO ENTR. TO-130 (BARRA DO OURO) - GOIATINS | C14: ='82'!I65 -> 47.358812 | D14: ='82'!F62 -> 0 | E14: ='82'!G62 -> 47.358812 | F14: ='82'!H62 -> 0 | G14: ='82'!I62 -> 0 | H14: ='82'!J62 -> 0 | I14: ='82'!K62 -> 47.358812 | J14: ='82'!L62 -> 0 | K14: =IF(SUM(D14:G14)=0,"— não preenchido",IF(ROUND(SUM(D14:G14)-C14,3)=0,"OK","ERRO — dif. de "&ROUND(SUM(D14:G14)-C14,3)&" km")) -> OK
A15: 83 | B15: RODOVIA TO-426 - TRECHO POVOADO CRAOLÂNDIA - ENTR. TO-226 | C15: ='83'!I49 -> 31.730768 | D15: ='83'!F46 -> 0 | E15: ='83'!G46 -> 20 | F15: ='83'!H46 -> 11.730768 | G15: ='83'!I46 -> 0 | H15: ='83'!J46 -> 0 | I15: ='83'!K46 -> 31.730768 | J15: ='83'!L46 -> 0 | K15: =IF(SUM(D15:G15)=0,"— não preenchido",IF(ROUND(SUM(D15:G15)-C15,3)=0,"OK","ERRO — dif. de "&ROUND(SUM(D15:G15)-C15,3)&" km")) -> OK
A16: 84 | B16: RODOVIA TO-428 - TRECHO POVOADO BANDEIRA - ENTR. TO-226 | C16: ='84'!I61 -> 41.521689 | D16: ='84'!F58 -> 0 | E16: ='84'!G58 -> 30.521689 | F16: ='84'!H58 -> 11 | G16: ='84'!I58 -> 0 | H16: ='84'!J58 -> 0 | I16: ='84'!K58 -> 41.521689 | J16: ='84'!L58 -> 0 | K16: =IF(SUM(D16:G16)=0,"— não preenchido",IF(ROUND(SUM(D16:G16)-C16,3)=0,"OK","ERRO — dif. de "&ROUND(SUM(D16:G16)-C16,3)&" km")) -> OK
B17: TOTAL PERCORRIDO NO MÊS | C17: =SUM(C6:C16) -> 547.18959 | D17: =SUM(D6:D16) -> 51.429669 | E17: =SUM(E6:E16) -> 330.41845 | F17: =SUM(F6:F16) -> 165.34147 | G17: =SUM(G6:G16) -> 0 | H17: =SUM(H6:H16) -> 33.591201 | I17: =SUM(I6:I16) -> 508.75992 | J17: =SUM(J6:J16) -> 4.8384683
B18: % DA EXTENSÃO DA MALHA (547.19 km) | D18: =SUM(D17:G17)/547.19 -> 0.99999925 | H18: (soma do grupo 'CONDIÇÃO DA PLATAFORMA' dividida pela malha)

Sheet 67
A1: PROGRAMA DE MANUTENÇÃO RODOVIÁRIA — FICHA DE INSPEÇÃO — RODOVIAS NÃO PAVIMENTADAS | P1: Valores dos gráficos — troca 0 por N/D para a fatia não aparecer. Não editar.
A2: REGIÃO: 3 — ARAGUAÍNA II | D2: MÊS / ANO: | F2: 46235 | G2: DATA: | J2: TÉCNICO: | K2: ENG. VINICIUS RODRIGUES FERREIRA DE OLIVEIRA | P2: =IF(F94=0,NA(),F94) -> #N/A | Q2: =IF(G94=0,NA(),G94) -> 77.592133 | R2: =IF(H94=0,NA(),H94) -> #N/A | S2: =IF(I94=0,NA(),I94) -> #N/A | T2: =IF(J94=0,NA(),J94) -> #N/A | U2: =IF(K94=0,NA(),K94) -> 77.592133 | V2: =IF(L94=0,NA(),L94) -> #N/A
A3: TRECHO 67 — RODOVIA TO-010 - TRECHO ENTR. BR-010 (ITACAJÁ) - PALMEIRANTE | K3: EXTENSÃO: 77,592 km · 2 S.R.E.
A4: COMO PREENCHER: uma X em UMA coluna de cada grupo, por linha. Se houver mais de um defeito no mesmo km, marque o PREDOMINANTE e escreva o resto em OBSERVAÇÕES. A quilometragem é contada de 0 até o fim de CADA S.R.E. (não é o marco da rodovia).
A6: S.R.E. | B6: SENT. | C6: INÍCIO (KM) | D6: FIM (KM) | E6: EXT. (KM) | F6: CONDIÇÃO DA PLATAFORMA | J6: DRENAGEM SUPERFICIAL | M6: OBSERVAÇÕES | N6: CONFERÊNCIA (só na tela)
F7: BOM | G7: REG. (ATÉ 10 IRR./KM) | H7: RUIM (+ 10 IRR./KM) | I7: PÉSSIMA (ATOLEIRO/PTO. CRÍTICO) | J7: LIMPA | K7: OBSTRUÍDA | L7: AUSENTE
A8: S.R.E. 010ETO0250 | ENTR. BR-010 - TRECHO ENTR. TO-226 (POV. CAMPOS) | LEN · Estadual · 58.164 km · início: -8.340994, -47.74331
A9: 010ETO0250 | B9: C | C9: 0 | D9: 1 | E9: =D9-C9 -> 1 | G9: X | K9: X | N9: =IF(COUNTA(F9:L9)=0,"— não preenchido",IF(COUNTIF(F9:I9,"X")<>1,"FALTA/DUPLA: CONDIÇÃO DA PLATAFORMA",IF(COUNTIF(J9:L9,"X")<>1,"FALTA/DUPLA: DRENAGEM SUPERFICIAL","OK"))) -> OK
A10: 010ETO0250 | B10: C | C10: 1 | D10: 2 | E10: =D10-C10 -> 1 | G10: X | K10: X | N10: =IF(COUNTA(F10:L10)=0,"— não preenchido",IF(COUNTIF(F10:I10,"X")<>1,"FALTA/DUPLA: CONDIÇÃO DA PLATAFORMA",IF(COUNTIF(J10:L10,"X")<>1,"FALTA/DUPLA: DRENAGEM SUPERFICIAL","OK"))) -> OK
A11: 010ETO0250 | B11: C | C11: 2 | D11: 3 | E11: =D11-C11 -> 1 | G11: X | K11: X | N11: =IF(COUNTA(F11:L11)=0,"— não preenchido",IF(COUNTIF(F11:I11,"X")<>1,"FALTA/DUPLA: CONDIÇÃO DA PLATAFORMA",IF(COUNTIF(J11:L11,"X")<>1,"FALTA/DUPLA: DRENAGEM SUPERFICIAL","OK"))) -> OK
A12: 010ETO0250 | B12: C | C12: 3 | D12: 4 | E12: =D12-C12 -> 1 | G12: X | K12: X | N12: =IF(COUNTA(F12:L12)=0,"— não preenchido",IF(COUNTIF(F12:I12,"X")<>1,"FALTA/DUPLA: CONDIÇÃO DA PLATAFORMA",IF(COUNTIF(J12:L12,"X")<>1,"FALTA/DUPLA: DRENAGEM SUPERFICIAL","OK"))) -> OK
A13: 010ETO0250 | B13: C | C13: 4 | D13: 5 | E13: =D13-C13 -> 1 | G13: X | K13: X | N13: =IF(COUNTA(F13:L13)=0,"— não preenchido",IF(COUNTIF(F13:I13,"X")<>1,"FALTA/DUPLA: CONDIÇÃO DA PLATAFORMA",IF(COUNTIF(J13:L13,"X")<>1,"FALTA/DUPLA: DRENAGEM SUPERFICIAL","OK"))) -> OK
A14: 010ETO0250 | B14: C | C14: 5 | D14: 6 | E14: =D14-C14 -> 1 | G14: X | K14: X | N14: =IF(COUNTA(F14:L14)=0,"— não preenchido",IF(COUNTIF(F14:I14,"X")<>1,"FALTA/DUPLA: CONDIÇÃO DA PLATAFORMA",IF(COUNTIF(J14:L14,"X")<>1,"FALTA/DUPLA: DRENAGEM SUPERFICIAL","OK"))) -> OK
A15: 010ETO0250 | B15: C | C15: 6 | D15: 7 | E15: =D15-C15 -> 1 | G15: X | K15: X | N15: =IF(COUNTA(F15:L15)=0,"— não preenchido",IF(COUNTIF(F15:I15,"X")<>1,"FALTA/DUPLA: CONDIÇÃO DA PLATAFORMA",IF(COUNTIF(J15:L15,"X")<>1,"FALTA/DUPLA: DRENAGEM SUPERFICIAL","OK"))) -> OK
A16: 010ETO0250 | B16: C | C16: 7 | D16: 8 | E16: =D16-C16 -> 1 | G16: X | K16: X | N16: =IF(COUNTA(F16:L16)=0,"— não preenchido",IF(COUNTIF(F16:I16,"X")<>1,"FALTA/DUPLA: CONDIÇÃO DA PLATAFORMA",IF(COUNTIF(J16:L16,"X")<>1,"FALTA/DUPLA: DRENAGEM SUPERFICIAL","OK"))) -> OK
A17: 010ETO0250 | B17: C | C17: 8 | D17: 9 | E17: =D17-C17 -> 1 | G17: X | K17: X | N17: =IF(COUNTA(F17:L17)=0,"— não preenchido",IF(COUNTIF(F17:I17,"X")<>1,"FALTA/DUPLA: CONDIÇÃO DA PLATAFORMA",IF(COUNTIF(J17:L17,"X")<>1,"FALTA/DUPLA: DRENAGEM SUPERFICIAL","OK"))) -> OK
A18: 010ETO0250 | B18: C | C18: 9 | D18: 10 | E18: =D18-C18 -> 1 | G18: X | K18: X | N18: =IF(COUNTA(F18:L18)=0,"— não preenchido",IF(COUNTIF(F18:I18,"X")<>1,"FALTA/DUPLA: CONDIÇÃO DA PLATAFORMA",IF(COUNTIF(J18:L18,"X")<>1,"FALTA/DUPLA: DRENAGEM SUPERFICIAL","OK"))) -> OK
A19: 010ETO0250 | B19: C | C19: 10 | D19: 11 | E19: =D19-C19 -> 1 | G19: X | K19: X | N19: =IF(COUNTA(F19:L19)=0,"— não preenchido",IF(COUNTIF(F19:I19,"X")<>1,"FALTA/DUPLA: CONDIÇÃO DA PLATAFORMA",IF(COUNTIF(J19:L19,"X")<>1,"FALTA/DUPLA: DRENAGEM SUPERFICIAL","OK"))) -> OK
A20: 010ETO0250 | B20: C | C20: 11 | D20: 12 | E20: =D20-C20 -> 1 | G20: X | K20: X | N20: =IF(COUNTA(F20:L20)=0,"— não preenchido",IF(COUNTIF(F20:I20,"X")<>1,"FALTA/DUPLA: CONDIÇÃO DA PLATAFORMA",IF(COUNTIF(J20:L20,"X")<>1,"FALTA/DUPLA: DRENAGEM SUPERFICIAL","OK"))) -> OK
... A67: 010ETO0250 | B67: C | C67: 58 | D67: 58.16433 | E67: =D67-C67 -> 0.16433048 | G67: X | K67: X | N67: =IF(COUNTA(F67:L67)=0,"— não preenchido",IF(COUNTIF(F67:I67,"X")<>1,"FALTA/DUPLA: CONDIÇÃO DA PLATAFORMA",IF(COUNTIF(J67:L67,"X")<>1,"FALTA/DUPLA: DRENAGEM SUPERFICIAL","OK"))) -> OK
A68: S.R.E. 010ETO0290 | ENTR. TO-226 (CAMPOS) - RIO TOCANTINS ( BALSA PALMEIRANTE) | LEN · Estadual · 19.428 km · início: -7.944864, -47.806618
A69: 010ETO0290 | B69: C | C69: 0 | D69: 1 | E69: =D69-C69 -> 1 | G69: X | K69: X | N69: =IF(COUNTA(F69:L69)=0,"— não preenchido",IF(COUNTIF(F69:I69,"X")<>1,"FALTA/DUPLA: CONDIÇÃO DA PLATAFORMA",IF(COUNTIF(J69:L69,"X")<>1,"FALTA/DUPLA: DRENAGEM SUPERFICIAL","OK"))) -> OK
A70: 010ETO0290 | B70: C | C70: 1 | D70: 2 | E70: =D70-C70 -> 1 | G70: X | K70: X | N70: =IF(COUNTA(F70:L70)=0,"— não preenchido",IF(COUNTIF(F70:I70,"X")<>1,"FALTA/DUPLA: CONDIÇÃO DA PLATAFORMA",IF(COUNTIF(J70:L70,"X")<>1,"FALTA/DUPLA: DRENAGEM SUPERFICIAL","OK"))) -> OK
A71: 010ETO0290 | B71: C | C71: 2 | D71: 3 | E71: =D71-C71 -> 1 | G71: X | K71: X | N71: =IF(COUNTA(F71:L71)=0,"— não preenchido",IF(COUNTIF(F71:I71,"X")<>1,"FALTA/DUPLA: CONDIÇÃO DA PLATAFORMA",IF(COUNTIF(J71:L71,"X")<>1,"FALTA/DUPLA: DRENAGEM SUPERFICIAL","OK"))) -> OK
A72: 010ETO0290 | B72: C | C72: 3 | D72: 4 | E72: =D72-C72 -> 1 | G72: X | K72: X | N72: =IF(COUNTA(F72:L72)=0,"— não preenchido",IF(COUNTIF(F72:I72,"X")<>1,"FALTA/DUPLA: CONDIÇÃO DA PLATAFORMA",IF(COUNTIF(J72:L72,"X")<>1,"FALTA/DUPLA: DRENAGEM SUPERFICIAL","OK"))) -> OK
A73: 010ETO0290 | B73: C | C73: 4 | D73: 5 | E73: =D73-C73 -> 1 | G73: X | K73: X | N73: =IF(COUNTA(F73:L73)=0,"— não preenchido",IF(COUNTIF(F73:I73,"X")<>1,"FALTA/DUPLA: CONDIÇÃO DA PLATAFORMA",IF(COUNTIF(J73:L73,"X")<>1,"FALTA/DUPLA: DRENAGEM SUPERFICIAL","OK"))) -> OK
A74: 010ETO0290 | B74: C | C74: 5 | D74: 6 | E74: =D74-C74 -> 1 | G74: X | K74: X | N74: =IF(COUNTA(F74:L74)=0,"— não preenchido",IF(COUNTIF(F74:I74,"X")<>1,"FALTA/DUPLA: CONDIÇÃO DA PLATAFORMA",IF(COUNTIF(J74:L74,"X")<>1,"FALTA/DUPLA: DRENAGEM SUPERFICIAL","OK"))) -> OK
A75: 010ETO0290 | B75: C | C75: 6 | D75: 7 | E75: =D75-C75 -> 1 | G75: X | K75: X | N75: =IF(COUNTA(F75:L75)=0,"— não preenchido",IF(COUNTIF(F75:I75,"X")<>1,"FALTA/DUPLA: CONDIÇÃO DA PLATAFORMA",IF(COUNTIF(J75:L75,"X")<>1,"FALTA/DUPLA: DRENAGEM SUPERFICIAL","OK"))) -> OK
A76: 010ETO0290 | B76: C | C76: 7 | D76: 8 | E76: =D76-C76 -> 1 | G76: X | K76: X | N76: =IF(COUNTA(F76:L76)=0,"— não preenchido",IF(COUNTIF(F76:I76,"X")<>1,"FALTA/DUPLA: CONDIÇÃO DA PLATAFORMA",IF(COUNTIF(J76:L76,"X")<>1,"FALTA/DUPLA: DRENAGEM SUPERFICIAL","OK"))) -> OK
A77: 010ETO0290 | B77: C | C77: 8 | D77: 9 | E77: =D77-C77 -> 1 | G77: X | K77: X | N77: =IF(COUNTA(F77:L77)=0,"— não preenchido",IF(COUNTIF(F77:I77,"X")<>1,"FALTA/DUPLA: CONDIÇÃO DA PLATAFORMA",IF(COUNTIF(J77:L77,"X")<>1,"FALTA/DUPLA: DRENAGEM SUPERFICIAL","OK"))) -> OK
A78: 010ETO0290 | B78: C | C78: 9 | D78: 10 | E78: =D78-C78 -> 1 | G78: X | K78: X | N78: =IF(COUNTA(F78:L78)=0,"— não preenchido",IF(COUNTIF(F78:I78,"X")<>1,"FALTA/DUPLA: CONDIÇÃO DA PLATAFORMA",IF(COUNTIF(J78:L78,"X")<>1,"FALTA/DUPLA: DRENAGEM SUPERFICIAL","OK"))) -> OK
A79: 010ETO0290 | B79: C | C79: 10 | D79: 11 | E79: =D79-C79 -> 1 | G79: X | K79: X | N79: =IF(COUNTA(F79:L79)=0,"— não preenchido",IF(COUNTIF(F79:I79,"X")<>1,"FALTA/DUPLA: CONDIÇÃO DA PLATAFORMA",IF(COUNTIF(J79:L79,"X")<>1,"FALTA/DUPLA: DRENAGEM SUPERFICIAL","OK"))) -> OK
A80: 010ETO0290 | B80: C | C80: 11 | D80: 12 | E80: =D80-C80 -> 1 | G80: X | K80: X | N80: =IF(COUNTA(F80:L80)=0,"— não preenchido",IF(COUNTIF(F80:I80,"X")<>1,"FALTA/DUPLA: CONDIÇÃO DA PLATAFORMA",IF(COUNTIF(J80:L80,"X")<>1,"FALTA/DUPLA: DRENAGEM SUPERFICIAL","OK"))) -> OK
... A88: 010ETO0290 | B88: C | C88: 19 | D88: 19.427802 | E88: =D88-C88 -> 0.42780233 | G88: X | K88: X | N88: =IF(COUNTA(F88:L88)=0,"— não preenchido",IF(COUNTIF(F88:I88,"X")<>1,"FALTA/DUPLA: CONDIÇÃO DA PLATAFORMA",IF(COUNTIF(J88:L88,"X")<>1,"FALTA/DUPLA: DRENAGEM SUPERFICIAL","OK"))) -> OK
A90: ____________________________________________ | G90: ____________________________________________
A91: TÉCNICO RESPONSÁVEL PELA INSPEÇÃO | G91: VISTO DA SUPERVISÃO
A93: RESUMO DO TRECHO — KM LANÇADO POR ITEM
A94: KM LANÇADO | F94: =SUMIF(F$9:F$88,"X",$E$9:$E$88) -> 0 | G94: =SUMIF(G$9:G$88,"X",$E$9:$E$88) -> 77.592133 | H94: =SUMIF(H$9:H$88,"X",$E$9:$E$88) -> 0 | I94: =SUMIF(I$9:I$88,"X",$E$9:$E$88) -> 0 | J94: =SUMIF(J$9:J$88,"X",$E$9:$E$88) -> 0 | K94: =SUMIF(K$9:K$88,"X",$E$9:$E$88) -> 77.592133 | L94: =SUMIF(L$9:L$88,"X",$E$9:$E$88) -> 0
A95: % DA EXTENSÃO | F95: =IF($I97=0,0,F94/$I97) -> 0 | G95: =IF($I97=0,0,G94/$I97) -> 1 | H95: =IF($I97=0,0,H94/$I97) -> 0 | I95: =IF($I97=0,0,I94/$I97) -> 0 | J95: =IF($I97=0,0,J94/$I97) -> 0 | K95: =IF($I97=0,0,K94/$I97) -> 1 | L95: =IF($I97=0,0,L94/$I97) -> 0
A96: CONFERÊNCIA POR GRUPO | F96: =IF(SUM(F94:I94)=0,"— não preenchido",IF(ROUND(SUM(F94:I94)-$I97,3)=0,"OK — "&ROUND(SUM(F94:I94),3)&" km","ERRO — dif. de "&ROUND(SUM(F94:I94)-$I97,3)&" km")) -> OK — 77,592 km | J96: =IF(SUM(J94:L94)=0,"— não preenchido",IF(ROUND(SUM(J94:L94)-$I97,3)=0,"OK — "&ROUND(SUM(J94:L94),3)&" km","ERRO — dif. de "&ROUND(SUM(J94:L94)-$I97,3)&" km")) -> OK — 77,592 km
...

Sheet 69
A1: PROGRAMA DE MANUTENÇÃO RODOVIÁRIA — FICHA DE INSPEÇÃO — RODOVIAS NÃO PAVIMENTADAS | P1: Valores dos gráficos — troca 0 por N/D para a fatia não aparecer. Não editar.
A2: REGIÃO: 3 — ARAGUAÍNA II | D2: MÊS / ANO: | F2: =IF('67'!F2="","",'67'!F2) -> 46235 | G2: DATA: | I2: =IF('67'!I2="","",'67'!I2) | J2: TÉCNICO: | K2: =IF('67'!K2="","",'67'!K2) -> ENG. VINICIUS RODRIGUES FERREIRA DE OLIVEIRA | P2: =IF(F54=0,NA(),F54) -> 38.429669 | Q2: =IF(G54=0,NA(),G54) -> #N/A | R2: =IF(H54=0,NA(),H54) -> #N/A | S2: =IF(I54=0,NA(),I54) -> #N/A | T2: =IF(J54=0,NA(),J54) -> 33.591201 | U2: =IF(K54=0,NA(),K54) -> #N/A | V2: =IF(L54=0,NA(),L54) -> 4.8384683
A3: TRECHO 69 — RODOVIA TO-010 - TRECHO ENTR. TO-222 (POVOADO FARTURÃO) - BABAÇULÂNDIA | K3: EXTENSÃO: 38,430 km · 2 S.R.E.
A4: COMO PREENCHER: uma X em UMA coluna de cada grupo, por linha. Se houver mais de um defeito no mesmo km, marque o PREDOMINANTE e escreva o resto em OBSERVAÇÕES. A quilometragem é contada de 0 até o fim de CADA S.R.E. (não é o marco da rodovia).
A6: S.R.E. | B6: SENT. | C6: INÍCIO (KM) | D6: FIM (KM) | E6: EXT. (KM) | F6: CONDIÇÃO DA PLATAFORMA | J6: DRENAGEM SUPERFICIAL | M6: OBSERVAÇÕES | N6: CONFERÊNCIA (só na tela)
F7: BOM | G7: REG. (ATÉ 10 IRR./KM) | H7: RUIM (+ 10 IRR./KM) | I7: PÉSSIMA (ATOLEIRO/PTO. CRÍTICO) | J7: LIMPA | K7: OBSTRUÍDA | L7: AUSENTE
A8: S.R.E. 010ETO0380 | POV. FARTURAO - ENTR. TO-424 | LEN · Estadual · 33.591 km · início: -7.365975, -48.010799
A9: 010ETO0380 | B9: C | C9: 0 | D9: 1 | E9: =D9-C9 -> 1 | F9: X | J9: X | N9: =IF(COUNTA(F9:L9)=0,"— não preenchido",IF(COUNTIF(F9:I9,"X")<>1,"FALTA/DUPLA: CONDIÇÃO DA PLATAFORMA",IF(COUNTIF(J9:L9,"X")<>1,"FALTA/DUPLA: DRENAGEM SUPERFICIAL","OK"))) -> OK
A10: 010ETO0380 | B10: C | C10: 1 | D10: 2 | E10: =D10-C10 -> 1 | F10: X | J10: X | N10: =IF(COUNTA(F10:L10)=0,"— não preenchido",IF(COUNTIF(F10:I10,"X")<>1,"FALTA/DUPLA: CONDIÇÃO DA PLATAFORMA",IF(COUNTIF(J10:L10,"X")<>1,"FALTA/DUPLA: DRENAGEM SUPERFICIAL","OK"))) -> OK
A11: 010ETO0380 | B11: C | C11: 2 | D11: 3 | E11: =D11-C11 -> 1 | F11: X | J11: X | N11: =IF(COUNTA(F11:L11)=0,"— não preenchido",IF(COUNTIF(F11:I11,"X")<>1,"FALTA/DUPLA: CONDIÇÃO DA PLATAFORMA",IF(COUNTIF(J11:L11,"X")<>1,"FALTA/DUPLA: DRENAGEM SUPERFICIAL","OK"))) -> OK
A12: 010ETO0380 | B12: C | C12: 3 | D12: 4 | E12: =D12-C12 -> 1 | F12: X | J12: X | N12: =IF(COUNTA(F12:L12)=0,"— não preenchido",IF(COUNTIF(F12:I12,"X")<>1,"FALTA/DUPLA: CONDIÇÃO DA PLATAFORMA",IF(COUNTIF(J12:L12,"X")<>1,"FALTA/DUPLA: DRENAGEM SUPERFICIAL","OK"))) -> OK
A13: 010ETO0380 | B13: C | C13: 4 | D13: 5 | E13: =D13-C13 -> 1 | F13: X | J13: X | N13: =IF(COUNTA(F13:L13)=0,"— não preenchido",IF(COUNTIF(F13:I13,"X")<>1,"FALTA/DUPLA: CONDIÇÃO DA PLATAFORMA",IF(COUNTIF(J13:L13,"X")<>1,"FALTA/DUPLA: DRENAGEM SUPERFICIAL","OK"))) -> OK
A14: 010ETO0380 | B14: C | C14: 5 | D14: 6 | E14: =D14-C14 -> 1 | F14: X | J14: X | N14: =IF(COUNTA(F14:L14)=0,"— não preenchido",IF(COUNTIF(F14:I14,"X")<>1,"FALTA/DUPLA: CONDIÇÃO DA PLATAFORMA",IF(COUNTIF(J14:L14,"X")<>1,"FALTA/DUPLA: DRENAGEM SUPERFICIAL","OK"))) -> OK
A15: 010ETO0380 | B15: C | C15: 6 | D15: 7 | E15: =D15-C15 -> 1 | F15: X | J15: X | N15: =IF(COUNTA(F15:L15)=0,"— não preenchido",IF(COUNTIF(F15:I15,"X")<>1,"FALTA/DUPLA: CONDIÇÃO DA PLATAFORMA",IF(COUNTIF(J15:L15,"X")<>1,"FALTA/DUPLA: DRENAGEM SUPERFICIAL","OK"))) -> OK
A16: 010ETO0380 | B16: C | C16: 7 | D16: 8 | E16: =D16-C16 -> 1 | F16: X | J16: X | N16: =IF(COUNTA(F16:L16)=0,"— não preenchido",IF(COUNTIF(F16:I16,"X")<>1,"FALTA/DUPLA: CONDIÇÃO DA PLATAFORMA",IF(COUNTIF(J16:L16,"X")<>1,"FALTA/DUPLA: DRENAGEM SUPERFICIAL","OK"))) -> OK
A17: 010ETO0380 | B17: C | C17: 8 | D17: 9 | E17: =D17-C17 -> 1 | F17: X | J17: X | N17: =IF(COUNTA(F17:L17)=0,"— não preenchido",IF(COUNTIF(F17:I17,"X")<>1,"FALTA/DUPLA: CONDIÇÃO DA PLATAFORMA",IF(COUNTIF(J17:L17,"X")<>1,"FALTA/DUPLA: DRENAGEM SUPERFICIAL","OK"))) -> OK
A18: 010ETO0380 | B18: C | C18: 9 | D18: 10 | E18: =D18-C18 -> 1 | F18: X | J18: X | N18: =IF(COUNTA(F18:L18)=0,"— não preenchido",IF(COUNTIF(F18:I18,"X")<>1,"FALTA/DUPLA: CONDIÇÃO DA PLATAFORMA",IF(COUNTIF(J18:L18,"X")<>1,"FALTA/DUPLA: DRENAGEM SUPERFICIAL","OK"))) -> OK
A19: 010ETO0380 | B19: C | C19: 10 | D19: 11 | E19: =D19-C19 -> 1 | F19: X | J19: X | N19: =IF(COUNTA(F19:L19)=0,"— não preenchido",IF(COUNTIF(F19:I19,"X")<>1,"FALTA/DUPLA: CONDIÇÃO DA PLATAFORMA",IF(COUNTIF(J19:L19,"X")<>1,"FALTA/DUPLA: DRENAGEM SUPERFICIAL","OK"))) -> OK
A20: 010ETO0380 | B20: C | C20: 11 | D20: 12 | E20: =D20-C20 -> 1 | F20: X | J20: X | N20: =IF(COUNTA(F20:L20)=0,"— não preenchido",IF(COUNTIF(F20:I20,"X")<>1,"FALTA/DUPLA: CONDIÇÃO DA PLATAFORMA",IF(COUNTIF(J20:L20,"X")<>1,"FALTA/DUPLA: DRENAGEM SUPERFICIAL","OK"))) -> OK
... A42: 010ETO0380 | B42: C | C42: 33 | D42: 33.591201 | E42: =D42-C42 -> 0.5912005 | F42: X | J42: X | N42: =IF(COUNTA(F42:L42)=0,"— não preenchido",IF(COUNTIF(F42:I42,"X")<>1,"FALTA/DUPLA: CONDIÇÃO DA PLATAFORMA",IF(COUNTIF(J42:L42,"X")<>1,"FALTA/DUPLA: DRENAGEM SUPERFICIAL","OK"))) -> OK
A43: S.R.E. 010ETO0400 | ENTR. TO-424 - TRECHO BABAÇULÂNDIA *TRECHO URBANO* | LEN · Estadual · 4.838 km · início: -7.246646, -47.775707
A44: 010ETO0400 | B44: C | C44: 0 | D44: 1 | E44: =D44-C44 -> 1 | F44: X | L44: X | N44: =IF(COUNTA(F44:L44)=0,"— não preenchido",IF(COUNTIF(F44:I44,"X")<>1,"FALTA/DUPLA: CONDIÇÃO DA PLATAFORMA",IF(COUNTIF(J44:L44,"X")<>1,"FALTA/DUPLA: DRENAGEM SUPERFICIAL","OK"))) -> OK
A45: 010ETO0400 | B45: C | C45: 1 | D45: 2 | E45: =D45-C45 -> 1 | F45: X | L45: X | N45: =IF(COUNTA(F45:L45)=0,"— não preenchido",IF(COUNTIF(F45:I45,"X")<>1,"FALTA/DUPLA: CONDIÇÃO DA PLATAFORMA",IF(COUNTIF(J45:L45,"X")<>1,"FALTA/DUPLA: DRENAGEM SUPERFICIAL","OK"))) -> OK
A46: 010ETO0400 | B46: C | C46: 2 | D46: 3 | E46: =D46-C46 -> 1 | F46: X | L46: X | N46: =IF(COUNTA(F46:L46)=0,"— não preenchido",IF(COUNTIF(F46:I46,"X")<>1,"FALTA/DUPLA: CONDIÇÃO DA PLATAFORMA",IF(COUNTIF(J46:L46,"X")<>1,"FALTA/DUPLA: DRENAGEM SUPERFICIAL","OK"))) -> OK
A47: 010ETO0400 | B47: C | C47: 3 | D47: 4 | E47: =D47-C47 -> 1 | F47: X | L47: X | N47: =IF(COUNTA(F47:L47)=0,"— não preenchido",IF(COUNTIF(F47:I47,"X")<>1,"FALTA/DUPLA: CONDIÇÃO DA PLATAFORMA",IF(COUNTIF(J47:L47,"X")<>1,"FALTA/DUPLA: DRENAGEM SUPERFICIAL","OK"))) -> OK
A48: 010ETO0400 | B48: C | C48: 4 | D48: 4.8384683 | E48: =D48-C48 -> 0.83846835 | F48: X | L48: X | N48: =IF(COUNTA(F48:L48)=0,"— não preenchido",IF(COUNTIF(F48:I48,"X")<>1,"FALTA/DUPLA: CONDIÇÃO DA PLATAFORMA",IF(COUNTIF(J48:L48,"X")<>1,"FALTA/DUPLA: DRENAGEM SUPERFICIAL","OK"))) -> OK
A50: ____________________________________________ | G50: ____________________________________________
A51: TÉCNICO RESPONSÁVEL PELA INSPEÇÃO | G51: VISTO DA SUPERVISÃO
A53: RESUMO DO TRECHO — KM LANÇADO POR ITEM
A54: KM LANÇADO | F54: =SUMIF(F$9:F$48,"X",$E$9:$E$48) -> 38.429669 | G54: =SUMIF(G$9:G$48,"X",$E$9:$E$48) -> 0 | H54: =SUMIF(H$9:H$48,"X",$E$9:$E$48) -> 0 | I54: =SUMIF(I$9:I$48,"X",$E$9:$E$48) -> 0 | J54: =SUMIF(J$9:J$48,"X",$E$9:$E$48) -> 33.591201 | K54: =SUMIF(K$9:K$48,"X",$E$9:$E$48) -> 0 | L54: =SUMIF(L$9:L$48,"X",$E$9:$E$48) -> 4.8384683
A55: % DA EXTENSÃO | F55: =IF($I57=0,0,F54/$I57) -> 1 | G55: =IF($I57=0,0,G54/$I57) -> 0 | H55: =IF($I57=0,0,H54/$I57) -> 0 | I55: =IF($I57=0,0,I54/$I57) -> 0 | J55: =IF($I57=0,0,J54/$I57) -> 0.8740955 | K55: =IF($I57=0,0,K54/$I57) -> 0 | L55: =IF($I57=0,0,L54/$I57) -> 0.1259045
A56: CONFERÊNCIA POR GRUPO | F56: =IF(SUM(F54:I54)=0,"— não preenchido",IF(ROUND(SUM(F54:I54)-$I57,3)=0,"OK — "&ROUND(SUM(F54:I54),3)&" km","ERRO — dif. de "&ROUND(SUM(F54:I54)-$I57,3)&" km")) -> OK — 38,43 km | J56: =IF(SUM(J54:L54)=0,"— não preenchido",IF(ROUND(SUM(J54:L54)-$I57,3)=0,"OK — "&ROUND(SUM(J54:L54),3)&" km","ERRO — dif. de "&ROUND(SUM(J54:L54)-$I57,3)&" km")) -> OK — 38,43 km
A57: EXTENSÃO TOTAL DO TRECHO | I57: =SUM(E9:E48) -> 38.429669 | M57: =COUNTIF(N9:N48,"OK")&" de "&COUNT($E$9:$E$48)&" linhas conferidas" -> 39 de 39 linhas conferidas
A59: LEGENDA
A60: REGULAR | E60: Até 10 irregularidades por km
A61: RUIM | E61: Mais de 10 irregularidades por km
A62: PÉSSIMA | E62: Atoleiro ou ponto crítico
A63: SIT. | E63: LEN = leito natural · EOP = em obras de pavimentação
A64: FAIXA AZUL | E64: Cabeçalho de cada S.R.E.: descrição, situação, jurisdição, extensão e coordenada de início.
A65: INÍCIO / FIM (KM) | E65: Contados de 0 até o fim de CADA S.R.E. Não é o marco quilométrico da rodovia.
...

Sheet 71
A1: PROGRAMA DE MANUTENÇÃO RODOVIÁRIA — FICHA DE INSPEÇÃO — RODOVIAS NÃO PAVIMENTADAS | P1: Valores dos gráficos — troca 0 por N/D para a fatia não aparecer. Não editar.
A2: REGIÃO: 3 — ARAGUAÍNA II | D2: MÊS / ANO: | F2: =IF('67'!F2="","",'67'!F2) -> 46235 | G2: DATA: | I2: =IF('67'!I2="","",'67'!I2) | J2: TÉCNICO: | K2: =IF('67'!K2="","",'67'!K2) -> ENG. VINICIUS RODRIGUES FERREIRA DE OLIVEIRA | P2: =IF(F163=0,NA(),F163) -> #N/A | Q2: =IF(G163=0,NA(),G163) -> 25 | R2: =IF(H163=0,NA(),H163) -> 123.40783 | S2: =IF(I163=0,NA(),I163) -> #N/A | T2: =IF(J163=0,NA(),J163) -> #N/A | U2: =IF(K163=0,NA(),K163) -> 148.40783 | V2: =IF(L163=0,NA(),L163) -> #N/A
A3: TRECHO 71 — RODOVIA TO-020 - TRECHO RECURSOLÂNDIA - CAMPOS LINDOS | K3: EXTENSÃO: 148,408 km · 1 S.R.E.
A4: COMO PREENCHER: uma X em UMA coluna de cada grupo, por linha. Se houver mais de um defeito no mesmo km, marque o PREDOMINANTE e escreva o resto em OBSERVAÇÕES. A quilometragem é contada de 0 até o fim de CADA S.R.E. (não é o marco da rodovia).
A6: S.R.E. | B6: SENT. | C6: INÍCIO (KM) | D6: FIM (KM) | E6: EXT. (KM) | F6: CONDIÇÃO DA PLATAFORMA | J6: DRENAGEM SUPERFICIAL | M6: OBSERVAÇÕES | N6: CONFERÊNCIA (só na tela)
F7: BOM | G7: REG. (ATÉ 10 IRR./KM) | H7: RUIM (+ 10 IRR./KM) | I7: PÉSSIMA (ATOLEIRO/PTO. CRÍTICO) | J7: LIMPA | K7: OBSTRUÍDA | L7: AUSENTE
A8: S.R.E. 020ETO0210 | FIM PAVIMENTAÇÃO - INICIO PAVIMENTACAO (CAMPOS LINDOS) | EOP · Estadual · 148.408 km · início: -8.0515, -46.668261
A9: 020ETO0210 | B9: C | C9: 0 | D9: 1 | E9: =D9-C9 -> 1 | G9: X | K9: X | N9: =IF(COUNTA(F9:L9)=0,"— não preenchido",IF(COUNTIF(F9:I9,"X")<>1,"FALTA/DUPLA: CONDIÇÃO DA PLATAFORMA",IF(COUNTIF(J9:L9,"X")<>1,"FALTA/DUPLA: DRENAGEM SUPERFICIAL","OK"))) -> OK
A10: 020ETO0210 | B10: C | C10: 1 | D10: 2 | E10: =D10-C10 -> 1 | G10: X | K10: X | N10: =IF(COUNTA(F10:L10)=0,"— não preenchido",IF(COUNTIF(F10:I10,"X")<>1,"FALTA/DUPLA: CONDIÇÃO DA PLATAFORMA",IF(COUNTIF(J10:L10,"X")<>1,"FALTA/DUPLA: DRENAGEM SUPERFICIAL","OK"))) -> OK
A11: 020ETO0210 | B11: C | C11: 2 | D11: 3 | E11: =D11-C11 -> 1 | G11: X | K11: X | N11: =IF(COUNTA(F11:L11)=0,"— não preenchido",IF(COUNTIF(F11:I11,"X")<>1,"FALTA/DUPLA: CONDIÇÃO DA PLATAFORMA",IF(COUNTIF(J11:L11,"X")<>1,"FALTA/DUPLA: DRENAGEM SUPERFICIAL","OK"))) -> OK
A12: 020ETO0210 | B12: C | C12: 3 | D12: 4 | E12: =D12-C12 -> 1 | G12: X | K12: X | N12: =IF(COUNTA(F12:L12)=0,"— não preenchido",IF(COUNTIF(F12:I12,"X")<>1,"FALTA/DUPLA: CONDIÇÃO DA PLATAFORMA",IF(COUNTIF(J12:L12,"X")<>1,"FALTA/DUPLA: DRENAGEM SUPERFICIAL","OK"))) -> OK
A13: 020ETO0210 | B13: C | C13: 4 | D13: 5 | E13: =D13-C13 -> 1 | G13: X | K13: X | N13: =IF(COUNTA(F13:L13)=0,"— não preenchido",IF(COUNTIF(F13:I13,"X")<>1,"FALTA/DUPLA: CONDIÇÃO DA PLATAFORMA",IF(COUNTIF(J13:L13,"X")<>1,"FALTA/DUPLA: DRENAGEM SUPERFICIAL","OK"))) -> OK
A14: 020ETO0210 | B14: C | C14: 5 | D14: 6 | E14: =D14-C14 -> 1 | G14: X | K14: X | N14: =IF(COUNTA(F14:L14)=0,"— não preenchido",IF(COUNTIF(F14:I14,"X")<>1,"FALTA/DUPLA: CONDIÇÃO DA PLATAFORMA",IF(COUNTIF(J14:L14,"X")<>1,"FALTA/DUPLA: DRENAGEM SUPERFICIAL","OK"))) -> OK
A15: 020ETO0210 | B15: C | C15: 6 | D15: 7 | E15: =D15-C15 -> 1 | G15: X | K15: X | N15: =IF(COUNTA(F15:L15)=0,"— não preenchido",IF(COUNTIF(F15:I15,"X")<>1,"FALTA/DUPLA: CONDIÇÃO DA PLATAFORMA",IF(COUNTIF(J15:L15,"X")<>1,"FALTA/DUPLA: DRENAGEM SUPERFICIAL","OK"))) -> OK
A16: 020ETO0210 | B16: C | C16: 7 | D16: 8 | E16: =D16-C16 -> 1 | G16: X | K16: X | N16: =IF(COUNTA(F16:L16)=0,"— não preenchido",IF(COUNTIF(F16:I16,"X")<>1,"FALTA/DUPLA: CONDIÇÃO DA PLATAFORMA",IF(COUNTIF(J16:L16,"X")<>1,"FALTA/DUPLA: DRENAGEM SUPERFICIAL","OK"))) -> OK
A17: 020ETO0210 | B17: C | C17: 8 | D17: 9 | E17: =D17-C17 -> 1 | G17: X | K17: X | N17: =IF(COUNTA(F17:L17)=0,"— não preenchido",IF(COUNTIF(F17:I17,"X")<>1,"FALTA/DUPLA: CONDIÇÃO DA PLATAFORMA",IF(COUNTIF(J17:L17,"X")<>1,"FALTA/DUPLA: DRENAGEM SUPERFICIAL","OK"))) -> OK
A18: 020ETO0210 | B18: C | C18: 9 | D18: 10 | E18: =D18-C18 -> 1 | G18: X | K18: X | N18: =IF(COUNTA(F18:L18)=0,"— não preenchido",IF(COUNTIF(F18:I18,"X")<>1,"FALTA/DUPLA: CONDIÇÃO DA PLATAFORMA",IF(COUNTIF(J18:L18,"X")<>1,"FALTA/DUPLA: DRENAGEM SUPERFICIAL","OK"))) -> OK
A19: 020ETO0210 | B19: C | C19: 10 | D19: 11 | E19: =D19-C19 -> 1 | H19: X | K19: X | N19: =IF(COUNTA(F19:L19)=0,"— não preenchido",IF(COUNTIF(F19:I19,"X")<>1,"FALTA/DUPLA: CONDIÇÃO DA PLATAFORMA",IF(COUNTIF(J19:L19,"X")<>1,"FALTA/DUPLA: DRENAGEM SUPERFICIAL","OK"))) -> OK
A20: 020ETO0210 | B20: C | C20: 11 | D20: 12 | E20: =D20-C20 -> 1 | H20: X | K20: X | N20: =IF(COUNTA(F20:L20)=0,"— não preenchido",IF(COUNTIF(F20:I20,"X")<>1,"FALTA/DUPLA: CONDIÇÃO DA PLATAFORMA",IF(COUNTIF(J20:L20,"X")<>1,"FALTA/DUPLA: DRENAGEM SUPERFICIAL","OK"))) -> OK
A21: 020ETO0210 | B21: C | C21: 12 | D21: 13 | E21: =D21-C21 -> 1 | H21: X | K21: X | N21: =IF(COUNTA(F21:L21)=0,"— não preenchido",IF(COUNTIF(F21:I21,"X")<>1,"FALTA/DUPLA: CONDIÇÃO DA PLATAFORMA",IF(COUNTIF(J21:L21,"X")<>1,"FALTA/DUPLA: DRENAGEM SUPERFICIAL","OK"))) -> OK
A22: 020ETO0210 | B22: C | C22: 13 | D22: 14 | E22: =D22-C22 -> 1 | H22: X | K22: X | N22: =IF(COUNTA(F22:L22)=0,"— não preenchido",IF(COUNTIF(F22:I22,"X")<>1,"FALTA/DUPLA: CONDIÇÃO DA PLATAFORMA",IF(COUNTIF(J22:L22,"X")<>1,"FALTA/DUPLA: DRENAGEM SUPERFICIAL","OK"))) -> OK
A23: 020ETO0210 | B23: C | C23: 14 | D23: 15 | E23: =D23-C23 -> 1 | H23: X | K23: X | N23: =IF(COUNTA(F23:L23)=0,"— não preenchido",IF(COUNTIF(F23:I23,"X")<>1,"FALTA/DUPLA: CONDIÇÃO DA PLATAFORMA",IF(COUNTIF(J23:L23,"X")<>1,"FALTA/DUPLA: DRENAGEM SUPERFICIAL","OK"))) -> OK
A24: 020ETO0210 | B24: C | C24: 15 | D24: 16 | E24: =D24-C24 -> 1 | H24: X | K24: X | N24: =IF(COUNTA(F24:L24)=0,"— não preenchido",IF(COUNTIF(F24:I24,"X")<>1,"FALTA/DUPLA: CONDIÇÃO DA PLATAFORMA",IF(COUNTIF(J24:L24,"X")<>1,"FALTA/DUPLA: DRENAGEM SUPERFICIAL","OK"))) -> OK
A25: 020ETO0210 | B25: C | C25: 16 | D25: 17 | E25: =D25-C25 -> 1 | H25: X | K25: X | N25: =IF(COUNTA(F25:L25)=0,"— não preenchido",IF(COUNTIF(F25:I25,"X")<>1,"FALTA/DUPLA: CONDIÇÃO DA PLATAFORMA",IF(COUNTIF(J25:L25,"X")<>1,"FALTA/DUPLA: DRENAGEM SUPERFICIAL","OK"))) -> OK
A26: 020ETO0210 | B26: C | C26: 17 | D26: 18 | E26: =D26-C26 -> 1 | H26: X | K26: X | N26: =IF(COUNTA(F26:L26)=0,"— não preenchido",IF(COUNTIF(F26:I26,"X")<>1,"FALTA/DUPLA: CONDIÇÃO DA PLATAFORMA",IF(COUNTIF(J26:L26,"X")<>1,"FALTA/DUPLA: DRENAGEM SUPERFICIAL","OK"))) -> OK
A27: 020ETO0210 | B27: C | C27: 18 | D27: 19 | E27: =D27-C27 -> 1 | G27: X | K27: X | N27: =IF(COUNTA(F27:L27)=0,"— não preenchido",IF(COUNTIF(F27:I27,"X")<>1,"FALTA/DUPLA: CONDIÇÃO DA PLATAFORMA",IF(COUNTIF(J27:L27,"X")<>1,"FALTA/DUPLA: DRENAGEM SUPERFICIAL","OK"))) -> OK
A28: 020ETO0210 | B28: C | C28: 19 | D28: 20 | E28: =D28-C28 -> 1 | G28: X | K28: X | N28: =IF(COUNTA(F28:L28)=0,"— não preenchido",IF(COUNTIF(F28:I28,"X")<>1,"FALTA/DUPLA: CONDIÇÃO DA PLATAFORMA",IF(COUNTIF(J28:L28,"X")<>1,"FALTA/DUPLA: DRENAGEM SUPERFICIAL","OK"))) -> OK
A29: 020ETO0210 | B29: C | C29: 20 | D29: 21 | E29: =D29-C29 -> 1 | G29: X | K29: X | N29: =IF(COUNTA(F29:L29)=0,"— não preenchido",IF(COUNTIF(F29:I29,"X")<>1,"FALTA/DUPLA: CONDIÇÃO DA PLATAFORMA",IF(COUNTIF(J29:L29,"X")<>1,"FALTA/DUPLA: DRENAGEM SUPERFICIAL","OK"))) -> OK
A30: 020ETO0210 | B30: C | C30: 21 | D30: 22 | E30: =D30-C30 -> 1 | G30: X | K30: X | N30: =IF(COUNTA(F30:L30)=0,"— não preenchido",IF(COUNTIF(F30:I30,"X")<>1,"FALTA/DUPLA: CONDIÇÃO DA PLATAFORMA",IF(COUNTIF(J30:L30,"X")<>1,"FALTA/DUPLA: DRENAGEM SUPERFICIAL","OK"))) -> OK
A31: 020ETO0210 | B31: C | C31: 22 | D31: 23 | E31: =D31-C31 -> 1 | G31: X | K31: X | N31: =IF(COUNTA(F31:L31)=0,"— não preenchido",IF(COUNTIF(F31:I31,"X")<>1,"FALTA/DUPLA: CONDIÇÃO DA PLATAFORMA",IF(COUNTIF(J31:L31,"X")<>1,"FALTA/DUPLA: DRENAGEM SUPERFICIAL","OK"))) -> OK
A32: 020ETO0210 | B32: C | C32: 23 | D32: 24 | E32: =D32-C32 -> 1 | G32: X | K32: X | N32: =IF(COUNTA(F32:L32)=0,"— não preenchido",IF(COUNTIF(F32:I32,"X")<>1,"FALTA/DUPLA: CONDIÇÃO DA PLATAFORMA",IF(COUNTIF(J32:L32,"X")<>1,"FALTA/DUPLA: DRENAGEM SUPERFICIAL","OK"))) -> OK
A33: 020ETO0210 | B33: C | C33: 24 | D33: 25 | E33: =D33-C33 -> 1 | G33: X | K33: X | N33: =IF(COUNTA(F33:L33)=0,"— não preenchido",IF(COUNTIF(F33:I33,"X")<>1,"FALTA/DUPLA: CONDIÇÃO DA PLATAFORMA",IF(COUNTIF(J33:L33,"X")<>1,"FALTA/DUPLA: DRENAGEM SUPERFICIAL","OK"))) -> OK
A34: 020ETO0210 | B34: C | C34: 25 | D34: 26 | E34: =D34-C34 -> 1 | G34: X | K34: X | N34: =IF(COUNTA(F34:L34)=0,"— não preenchido",IF(COUNTIF(F34:I34,"X")<>1,"FALTA/DUPLA: CONDIÇÃO DA PLATAFORMA",IF(COUNTIF(J34:L34,"X")<>1,"FALTA/DUPLA: DRENAGEM SUPERFICIAL","OK"))) -> OK
A35: 020ETO0210 | B35: C | C35: 26 | D35: 27 | E35: =D35-C35 -> 1 | G35: X | K35: X | N35: =IF(COUNTA(F35:L35)=0,"— não preenchido",IF(COUNTIF(F35:I35,"X")<>1,"FALTA/DUPLA: CONDIÇÃO DA PLATAFORMA",IF(COUNTIF(J35:L35,"X")<>1,"FALTA/DUPLA: DRENAGEM SUPERFICIAL","OK"))) -> OK
A36: 020ETO0210 | B36: C | C36: 27 | D36: 28 | E36: =D36-C36 -> 1 | G36: X | K36: X | N36: =IF(COUNTA(F36:L36)=0,"— não preenchido",IF(COUNTIF(F36:I36,"X")<>1,"FALTA/DUPLA: CONDIÇÃO DA PLATAFORMA",IF(COUNTIF(J36:L36,"X")<>1,"FALTA/DUPLA: DRENAGEM SUPERFICIAL","OK"))) -> OK
A37: 020ETO0210 | B37: C | C37: 28 | D37: 29 | E37: =D37-C37 -> 1 | G37: X | K37: X | N37: =IF(COUNTA(F37:L37)=0,"— não preenchido",IF(COUNTIF(F37:I37,"X")<>1,"FALTA/DUPLA: CONDIÇÃO DA PLATAFORMA",IF(COUNTIF(J37:L37,"X")<>1,"FALTA/DUPLA: DRENAGEM SUPERFICIAL","OK"))) -> OK
A38: 020ETO0210 | B38: C | C38: 29 | D38: 30 | E38: =D38-C38 -> 1 | G38: X | K38: X | N38: =IF(COUNTA(F38:L38)=0,"— não preenchido",IF(COUNTIF(F38:I38,"X")<>1,"FALTA/DUPLA: CONDIÇÃO DA PLATAFORMA",IF(COUNTIF(J38:L38,"X")<>1,"FALTA/DUPLA: DRENAGEM SUPERFICIAL","OK"))) -> OK
... A41: 020ETO0210 | B41: C | C41: 32 | D41: 33 | E41: =D41-C41 -> 1 | G41: X | K41: X | N41: =IF(COUNTA(F41:L41)=0,"— não preenchido",IF(COUNTIF(F41:I41,"X")<>1,"FALTA/DUPLA: CONDIÇÃO DA PLATAFORMA",IF(COUNTIF(J41:L41,"X")<>1,"FALTA/DUPLA: DRENAGEM SUPERFICIAL","OK"))) -> OK
A42: 020ETO0210 | B42: C | C42: 33 | D42: 34 | E42: =D42-C42 -> 1 | H42: X | K42: X | N42: =IF(COUNTA(F42:L42)=0,"— não preenchido",IF(COUNTIF(F42:I42,"X")<>1,"FALTA/DUPLA: CONDIÇÃO DA PLATAFORMA",IF(COUNTIF(J42:L42,"X")<>1,"FALTA/DUPLA: DRENAGEM SUPERFICIAL","OK"))) -> OK
A43: 020ETO0210 | B43: C | C43: 34 | D43: 35 | E43: =D43-C43 -> 1 | H43: X | K43: X | N43: =IF(COUNTA(F43:L43)=0,"— não preenchido",IF(COUNTIF(F43:I43,"X")<>1,"FALTA/DUPLA: CONDIÇÃO DA PLATAFORMA",IF(COUNTIF(J43:L43,"X")<>1,"FALTA/DUPLA: DRENAGEM SUPERFICIAL","OK"))) -> OK
...

Sheet 72
A1: PROGRAMA DE MANUTENÇÃO RODOVIÁRIA — FICHA DE INSPEÇÃO — RODOVIAS NÃO PAVIMENTADAS | P1: Valores dos gráficos — troca 0 por N/D para a fatia não aparecer. Não editar.
A2: REGIÃO: 3 — ARAGUAÍNA II | D2: MÊS / ANO: | F2: =IF('67'!F2="","",'67'!F2) -> 46235 | G2: DATA: | I2: =IF('67'!I2="","",'67'!I2) | J2: TÉCNICO: | K2: =IF('67'!K2="","",'67'!K2) -> ENG. VINICIUS RODRIGUES FERREIRA DE OLIVEIRA | P2: =IF(F34=0,NA(),F34) -> #N/A | Q2: =IF(G34=0,NA(),G34) -> 15.326516 | R2: =IF(H34=0,NA(),H34) -> 4 | S2: =IF(I34=0,NA(),I34) -> #N/A | T2: =IF(J34=0,NA(),J34) -> #N/A | U2: =IF(K34=0,NA(),K34) -> 19.326516 | V2: =IF(L34=0,NA(),L34) -> #N/A
A3: TRECHO 72 — RODOVIA TO-130 - TRECHO ENTR. TO-424 - TRECHO ENTR. TO-222 | K3: EXTENSÃO: 19,327 km · 1 S.R.E.
A4: COMO PREENCHER: uma X em UMA coluna de cada grupo, por linha. Se houver mais de um defeito no mesmo km, marque o PREDOMINANTE e escreva o resto em OBSERVAÇÕES. A quilometragem é contada de 0 até o fim de CADA S.R.E. (não é o marco da rodovia).
A6: S.R.E. | B6: SENT. | C6: INÍCIO (KM) | D6: FIM (KM) | E6: EXT. (KM) | F6: CONDIÇÃO DA PLATAFORMA | J6: DRENAGEM SUPERFICIAL | M6: OBSERVAÇÕES | N6: CONFERÊNCIA (só na tela)
F7: BOM | G7: REG. (ATÉ 10 IRR./KM) | H7: RUIM (+ 10 IRR./KM) | I7: PÉSSIMA (ATOLEIRO/PTO. CRÍTICO) | J7: LIMPA | K7: OBSTRUÍDA | L7: AUSENTE
A8: S.R.E. 130ETO0010 | ENTR. TO-424 - TRECHO ENTR. TO-222 (A) | LEN · Estadual · 19.327 km · início: -7.427496, -47.71581
A9: 130ETO0010 | B9: C | C9: 0 | D9: 1 | E9: =D9-C9 -> 1 | G9: X | K9: X | N9: =IF(COUNTA(F9:L9)=0,"— não preenchido",IF(COUNTIF(F9:I9,"X")<>1,"FALTA/DUPLA: CONDIÇÃO DA PLATAFORMA",IF(COUNTIF(J9:L9,"X")<>1,"FALTA/DUPLA: DRENAGEM SUPERFICIAL","OK"))) -> OK
A10: 130ETO0010 | B10: C | C10: 1 | D10: 2 | E10: =D10-C10 -> 1 | G10: X | K10: X | N10: =IF(COUNTA(F10:L10)=0,"— não preenchido",IF(COUNTIF(F10:I10,"X")<>1,"FALTA/DUPLA: CONDIÇÃO DA PLATAFORMA",IF(COUNTIF(J10:L10,"X")<>1,"FALTA/DUPLA: DRENAGEM SUPERFICIAL","OK"))) -> OK
A11: 130ETO0010 | B11: C | C11: 2 | D11: 3 | E11: =D11-C11 -> 1 | G11: X | K11: X | N11: =IF(COUNTA(F11:L11)=0,"— não preenchido",IF(COUNTIF(F11:I11,"X")<>1,"FALTA/DUPLA: CONDIÇÃO DA PLATAFORMA",IF(COUNTIF(J11:L11,"X")<>1,"FALTA/DUPLA: DRENAGEM SUPERFICIAL","OK"))) -> OK
A12: 130ETO0010 | B12: C | C12: 3 | D12: 4 | E12: =D12-C12 -> 1 | H12: X | K12: X | N12: =IF(COUNTA(F12:L12)=0,"— não preenchido",IF(COUNTIF(F12:I12,"X")<>1,"FALTA/DUPLA: CONDIÇÃO DA PLATAFORMA",IF(COUNTIF(J12:L12,"X")<>1,"FALTA/DUPLA: DRENAGEM SUPERFICIAL","OK"))) -> OK
A13: 130ETO0010 | B13: C | C13: 4 | D13: 5 | E13: =D13-C13 -> 1 | H13: X | K13: X | N13: =IF(COUNTA(F13:L13)=0,"— não preenchido",IF(COUNTIF(F13:I13,"X")<>1,"FALTA/DUPLA: CONDIÇÃO DA PLATAFORMA",IF(COUNTIF(J13:L13,"X")<>1,"FALTA/DUPLA: DRENAGEM SUPERFICIAL","OK"))) -> OK
A14: 130ETO0010 | B14: C | C14: 5 | D14: 6 | E14: =D14-C14 -> 1 | H14: X | K14: X | N14: =IF(COUNTA(F14:L14)=0,"— não preenchido",IF(COUNTIF(F14:I14,"X")<>1,"FALTA/DUPLA: CONDIÇÃO DA PLATAFORMA",IF(COUNTIF(J14:L14,"X")<>1,"FALTA/DUPLA: DRENAGEM SUPERFICIAL","OK"))) -> OK
A15: 130ETO0010 | B15: C | C15: 6 | D15: 7 | E15: =D15-C15 -> 1 | G15: X | K15: X | N15: =IF(COUNTA(F15:L15)=0,"— não preenchido",IF(COUNTIF(F15:I15,"X")<>1,"FALTA/DUPLA: CONDIÇÃO DA PLATAFORMA",IF(COUNTIF(J15:L15,"X")<>1,"FALTA/DUPLA: DRENAGEM SUPERFICIAL","OK"))) -> OK
A16: 130ETO0010 | B16: C | C16: 7 | D16: 8 | E16: =D16-C16 -> 1 | G16: X | K16: X | N16: =IF(COUNTA(F16:L16)=0,"— não preenchido",IF(COUNTIF(F16:I16,"X")<>1,"FALTA/DUPLA: CONDIÇÃO DA PLATAFORMA",IF(COUNTIF(J16:L16,"X")<>1,"FALTA/DUPLA: DRENAGEM SUPERFICIAL","OK"))) -> OK
A17: 130ETO0010 | B17: C | C17: 8 | D17: 9 | E17: =D17-C17 -> 1 | G17: X | K17: X | N17: =IF(COUNTA(F17:L17)=0,"— não preenchido",IF(COUNTIF(F17:I17,"X")<>1,"FALTA/DUPLA: CONDIÇÃO DA PLATAFORMA",IF(COUNTIF(J17:L17,"X")<>1,"FALTA/DUPLA: DRENAGEM SUPERFICIAL","OK"))) -> OK
A18: 130ETO0010 | B18: C | C18: 9 | D18: 10 | E18: =D18-C18 -> 1 | G18: X | K18: X | N18: =IF(COUNTA(F18:L18)=0,"— não preenchido",IF(COUNTIF(F18:I18,"X")<>1,"FALTA/DUPLA: CONDIÇÃO DA PLATAFORMA",IF(COUNTIF(J18:L18,"X")<>1,"FALTA/DUPLA: DRENAGEM SUPERFICIAL","OK"))) -> OK
A19: 130ETO0010 | B19: C | C19: 10 | D19: 11 | E19: =D19-C19 -> 1 | G19: X | K19: X | N19: =IF(COUNTA(F19:L19)=0,"— não preenchido",IF(COUNTIF(F19:I19,"X")<>1,"FALTA/DUPLA: CONDIÇÃO DA PLATAFORMA",IF(COUNTIF(J19:L19,"X")<>1,"FALTA/DUPLA: DRENAGEM SUPERFICIAL","OK"))) -> OK
A20: 130ETO0010 | B20: C | C20: 11 | D20: 12 | E20: =D20-C20 -> 1 | G20: X | K20: X | N20: =IF(COUNTA(F20:L20)=0,"— não preenchido",IF(COUNTIF(F20:I20,"X")<>1,"FALTA/DUPLA: CONDIÇÃO DA PLATAFORMA",IF(COUNTIF(J20:L20,"X")<>1,"FALTA/DUPLA: DRENAGEM SUPERFICIAL","OK"))) -> OK
A21: 130ETO0010 | B21: C | C21: 12 | D21: 13 | E21: =D21-C21 -> 1 | G21: X | K21: X | N21: =IF(COUNTA(F21:L21)=0,"— não preenchido",IF(COUNTIF(F21:I21,"X")<>1,"FALTA/DUPLA: CONDIÇÃO DA PLATAFORMA",IF(COUNTIF(J21:L21,"X")<>1,"FALTA/DUPLA: DRENAGEM SUPERFICIAL","OK"))) -> OK
A22: 130ETO0010 | B22: C | C22: 13 | D22: 14 | E22: =D22-C22 -> 1 | G22: X | K22: X | N22: =IF(COUNTA(F22:L22)=0,"— não preenchido",IF(COUNTIF(F22:I22,"X")<>1,"FALTA/DUPLA: CONDIÇÃO DA PLATAFORMA",IF(COUNTIF(J22:L22,"X")<>1,"FALTA/DUPLA: DRENAGEM SUPERFICIAL","OK"))) -> OK
A23: 130ETO0010 | B23: C | C23: 14 | D23: 15 | E23: =D23-C23 -> 1 | G23: X | K23: X | N23: =IF(COUNTA(F23:L23)=0,"— não preenchido",IF(COUNTIF(F23:I23,"X")<>1,"FALTA/DUPLA: CONDIÇÃO DA PLATAFORMA",IF(COUNTIF(J23:L23,"X")<>1,"FALTA/DUPLA: DRENAGEM SUPERFICIAL","OK"))) -> OK
A24: 130ETO0010 | B24: C | C24: 15 | D24: 16 | E24: =D24-C24 -> 1 | G24: X | K24: X | N24: =IF(COUNTA(F24:L24)=0,"— não preenchido",IF(COUNTIF(F24:I24,"X")<>1,"FALTA/DUPLA: CONDIÇÃO DA PLATAFORMA",IF(COUNTIF(J24:L24,"X")<>1,"FALTA/DUPLA: DRENAGEM SUPERFICIAL","OK"))) -> OK
A25: 130ETO0010 | B25: C | C25: 16 | D25: 17 | E25: =D25-C25 -> 1 | H25: X | K25: X | N25: =IF(COUNTA(F25:L25)=0,"— não preenchido",IF(COUNTIF(F25:I25,"X")<>1,"FALTA/DUPLA: CONDIÇÃO DA PLATAFORMA",IF(COUNTIF(J25:L25,"X")<>1,"FALTA/DUPLA: DRENAGEM SUPERFICIAL","OK"))) -> OK
A26: 130ETO0010 | B26: C | C26: 17 | D26: 18 | E26: =D26-C26 -> 1 | G26: X | K26: X | N26: =IF(COUNTA(F26:L26)=0,"— não preenchido",IF(COUNTIF(F26:I26,"X")<>1,"FALTA/DUPLA: CONDIÇÃO DA PLATAFORMA",IF(COUNTIF(J26:L26,"X")<>1,"FALTA/DUPLA: DRENAGEM SUPERFICIAL","OK"))) -> OK
A27: 130ETO0010 | B27: C | C27: 18 | D27: 19 | E27: =D27-C27 -> 1 | G27: X | K27: X | N27: =IF(COUNTA(F27:L27)=0,"— não preenchido",IF(COUNTIF(F27:I27,"X")<>1,"FALTA/DUPLA: CONDIÇÃO DA PLATAFORMA",IF(COUNTIF(J27:L27,"X")<>1,"FALTA/DUPLA: DRENAGEM SUPERFICIAL","OK"))) -> OK
A28: 130ETO0010 | B28: C | C28: 19 | D28: 19.326516 | E28: =D28-C28 -> 0.32651615 | G28: X | K28: X | N28: =IF(COUNTA(F28:L28)=0,"— não preenchido",IF(COUNTIF(F28:I28,"X")<>1,"FALTA/DUPLA: CONDIÇÃO DA PLATAFORMA",IF(COUNTIF(J28:L28,"X")<>1,"FALTA/DUPLA: DRENAGEM SUPERFICIAL","OK"))) -> OK
A30: ____________________________________________ | G30: ____________________________________________
A31: TÉCNICO RESPONSÁVEL PELA INSPEÇÃO | G31: VISTO DA SUPERVISÃO
A33: RESUMO DO TRECHO — KM LANÇADO POR ITEM
A34: KM LANÇADO | F34: =SUMIF(F$9:F$28,"X",$E$9:$E$28) -> 0 | G34: =SUMIF(G$9:G$28,"X",$E$9:$E$28) -> 15.326516 | H34: =SUMIF(H$9:H$28,"X",$E$9:$E$28) -> 4 | I34: =SUMIF(I$9:I$28,"X",$E$9:$E$28) -> 0 | J34: =SUMIF(J$9:J$28,"X",$E$9:$E$28) -> 0 | K34: =SUMIF(K$9:K$28,"X",$E$9:$E$28) -> 19.326516 | L34: =SUMIF(L$9:L$28,"X",$E$9:$E$28) -> 0
A35: % DA EXTENSÃO | F35: =IF($I37=0,0,F34/$I37) -> 0 | G35: =IF($I37=0,0,G34/$I37) -> 0.79303047 | H35: =IF($I37=0,0,H34/$I37) -> 0.20696953 | I35: =IF($I37=0,0,I34/$I37) -> 0 | J35: =IF($I37=0,0,J34/$I37) -> 0 | K35: =IF($I37=0,0,K34/$I37) -> 1 | L35: =IF($I37=0,0,L34/$I37) -> 0
A36: CONFERÊNCIA POR GRUPO | F36: =IF(SUM(F34:I34)=0,"— não preenchido",IF(ROUND(SUM(F34:I34)-$I37,3)=0,"OK — "&ROUND(SUM(F34:I34),3)&" km","ERRO — dif. de "&ROUND(SUM(F34:I34)-$I37,3)&" km")) -> OK — 19,327 km | J36: =IF(SUM(J34:L34)=0,"— não preenchido",IF(ROUND(SUM(J34:L34)-$I37,3)=0,"OK — "&ROUND(SUM(J34:L34),3)&" km","ERRO — dif. de "&ROUND(SUM(J34:L34)-$I37,3)&" km")) -> OK — 19,327 km
A37: EXTENSÃO TOTAL DO TRECHO | I37: =SUM(E9:E28) -> 19.326516 | M37: =COUNTIF(N9:N28,"OK")&" de "&COUNT($E$9:$E$28)&" linhas conferidas" -> 20 de 20 linhas conferidas
A39: LEGENDA
A40: REGULAR | E40: Até 10 irregularidades por km
A41: RUIM | E41: Mais de 10 irregularidades por km
A42: PÉSSIMA | E42: Atoleiro ou ponto crítico
A43: SIT. | E43: LEN = leito natural · EOP = em obras de pavimentação
A44: FAIXA AZUL | E44: Cabeçalho de cada S.R.E.: descrição, situação, jurisdição, extensão e coordenada de início.
...

Sheet 75
A1: PROGRAMA DE MANUTENÇÃO RODOVIÁRIA — FICHA DE INSPEÇÃO — RODOVIAS NÃO PAVIMENTADAS | P1: Valores dos gráficos — troca 0 por N/D para a fatia não aparecer. Não editar.
A2: REGIÃO: 3 — ARAGUAÍNA II | D2: MÊS / ANO: | F2: =IF('67'!F2="","",'67'!F2) -> 46235 | G2: DATA: | I2: =IF('67'!I2="","",'67'!I2) | J2: TÉCNICO: | K2: =IF('67'!K2="","",'67'!K2) -> ENG. VINICIUS RODRIGUES FERREIRA DE OLIVEIRA | P2: =IF(F70=0,NA(),F70) -> #N/A | Q2: =IF(G70=0,NA(),G70) -> 52.389636 | R2: =IF(H70=0,NA(),H70) -> 2 | S2: =IF(I70=0,NA(),I70) -> #N/A | T2: =IF(J70=0,NA(),J70) -> #N/A | U2: =IF(K70=0,NA(),K70) -> 54.389636 | V2: =IF(L70=0,NA(),L70) -> #N/A
A3: TRECHO 75 — RODOVIA TO-226 - TRECHO NOVA OLINDA - ENTR. TO-010 | K3: EXTENSÃO: 54,390 km · 2 S.R.E.
A4: COMO PREENCHER: uma X em UMA coluna de cada grupo, por linha. Se houver mais de um defeito no mesmo km, marque o PREDOMINANTE e escreva o resto em OBSERVAÇÕES. A quilometragem é contada de 0 até o fim de CADA S.R.E. (não é o marco da rodovia).
A6: S.R.E. | B6: SENT. | C6: INÍCIO (KM) | D6: FIM (KM) | E6: EXT. (KM) | F6: CONDIÇÃO DA PLATAFORMA | J6: DRENAGEM SUPERFICIAL | M6: OBSERVAÇÕES | N6: CONFERÊNCIA (só na tela)
F7: BOM | G7: REG. (ATÉ 10 IRR./KM) | H7: RUIM (+ 10 IRR./KM) | I7: PÉSSIMA (ATOLEIRO/PTO. CRÍTICO) | J7: LIMPA | K7: OBSTRUÍDA | L7: AUSENTE
A8: S.R.E. 226ETO0190 | ENTR.TO-010 - TRECHO POV. ALTO BONITO | LEN · Estadual · 36.768 km · início: -7.642978, -48.284114
A9: 226ETO0190 | B9: C | C9: 0 | D9: 1 | E9: =D9-C9 -> 1 | G9: X | K9: X | N9: =IF(COUNTA(F9:L9)=0,"— não preenchido",IF(COUNTIF(F9:I9,"X")<>1,"FALTA/DUPLA: CONDIÇÃO DA PLATAFORMA",IF(COUNTIF(J9:L9,"X")<>1,"FALTA/DUPLA: DRENAGEM SUPERFICIAL","OK"))) -> OK
A10: 226ETO0190 | B10: C | C10: 1 | D10: 2 | E10: =D10-C10 -> 1 | G10: X | K10: X | N10: =IF(COUNTA(F10:L10)=0,"— não preenchido",IF(COUNTIF(F10:I10,"X")<>1,"FALTA/DUPLA: CONDIÇÃO DA PLATAFORMA",IF(COUNTIF(J10:L10,"X")<>1,"FALTA/DUPLA: DRENAGEM SUPERFICIAL","OK"))) -> OK
A11: 226ETO0190 | B11: C | C11: 2 | D11: 3 | E11: =D11-C11 -> 1 | G11: X | K11: X | N11: =IF(COUNTA(F11:L11)=0,"— não preenchido",IF(COUNTIF(F11:I11,"X")<>1,"FALTA/DUPLA: CONDIÇÃO DA PLATAFORMA",IF(COUNTIF(J11:L11,"X")<>1,"FALTA/DUPLA: DRENAGEM SUPERFICIAL","OK"))) -> OK
A12: 226ETO0190 | B12: C | C12: 3 | D12: 4 | E12: =D12-C12 -> 1 | G12: X | K12: X | N12: =IF(COUNTA(F12:L12)=0,"— não preenchido",IF(COUNTIF(F12:I12,"X")<>1,"FALTA/DUPLA: CONDIÇÃO DA PLATAFORMA",IF(COUNTIF(J12:L12,"X")<>1,"FALTA/DUPLA: DRENAGEM SUPERFICIAL","OK"))) -> OK
A13: 226ETO0190 | B13: C | C13: 4 | D13: 5 | E13: =D13-C13 -> 1 | G13: X | K13: X | N13: =IF(COUNTA(F13:L13)=0,"— não preenchido",IF(COUNTIF(F13:I13,"X")<>1,"FALTA/DUPLA: CONDIÇÃO DA PLATAFORMA",IF(COUNTIF(J13:L13,"X")<>1,"FALTA/DUPLA: DRENAGEM SUPERFICIAL","OK"))) -> OK
A14: 226ETO0190 | B14: C | C14: 5 | D14: 6 | E14: =D14-C14 -> 1 | H14: X | K14: X | N14: =IF(COUNTA(F14:L14)=0,"— não preenchido",IF(COUNTIF(F14:I14,"X")<>1,"FALTA/DUPLA: CONDIÇÃO DA PLATAFORMA",IF(COUNTIF(J14:L14,"X")<>1,"FALTA/DUPLA: DRENAGEM SUPERFICIAL","OK"))) -> OK
A15: 226ETO0190 | B15: C | C15: 6 | D15: 7 | E15: =D15-C15 -> 1 | H15: X | K15: X | N15: =IF(COUNTA(F15:L15)=0,"— não preenchido",IF(COUNTIF(F15:I15,"X")<>1,"FALTA/DUPLA: CONDIÇÃO DA PLATAFORMA",IF(COUNTIF(J15:L15,"X")<>1,"FALTA/DUPLA: DRENAGEM SUPERFICIAL","OK"))) -> OK
A16: 226ETO0190 | B16: C | C16: 7 | D16: 8 | E16: =D16-C16 -> 1 | G16: X | K16: X | N16: =IF(COUNTA(F16:L16)=0,"— não preenchido",IF(COUNTIF(F16:I16,"X")<>1,"FALTA/DUPLA: CONDIÇÃO DA PLATAFORMA",IF(COUNTIF(J16:L16,"X")<>1,"FALTA/DUPLA: DRENAGEM SUPERFICIAL","OK"))) -> OK
A17: 226ETO0190 | B17: C | C17: 8 | D17: 9 | E17: =D17-C17 -> 1 | G17: X | K17: X | N17: =IF(COUNTA(F17:L17)=0,"— não preenchido",IF(COUNTIF(F17:I17,"X")<>1,"FALTA/DUPLA: CONDIÇÃO DA PLATAFORMA",IF(COUNTIF(J17:L17,"X")<>1,"FALTA/DUPLA: DRENAGEM SUPERFICIAL","OK"))) -> OK
A18: 226ETO0190 | B18: C | C18: 9 | D18: 10 | E18: =D18-C18 -> 1 | G18: X | K18: X | N18: =IF(COUNTA(F18:L18)=0,"— não preenchido",IF(COUNTIF(F18:I18,"X")<>1,"FALTA/DUPLA: CONDIÇÃO DA PLATAFORMA",IF(COUNTIF(J18:L18,"X")<>1,"FALTA/DUPLA: DRENAGEM SUPERFICIAL","OK"))) -> OK
A19: 226ETO0190 | B19: C | C19: 10 | D19: 11 | E19: =D19-C19 -> 1 | G19: X | K19: X | N19: =IF(COUNTA(F19:L19)=0,"— não preenchido",IF(COUNTIF(F19:I19,"X")<>1,"FALTA/DUPLA: CONDIÇÃO DA PLATAFORMA",IF(COUNTIF(J19:L19,"X")<>1,"FALTA/DUPLA: DRENAGEM SUPERFICIAL","OK"))) -> OK
A20: 226ETO0190 | B20: C | C20: 11 | D20: 12 | E20: =D20-C20 -> 1 | G20: X | K20: X | N20: =IF(COUNTA(F20:L20)=0,"— não preenchido",IF(COUNTIF(F20:I20,"X")<>1,"FALTA/DUPLA: CONDIÇÃO DA PLATAFORMA",IF(COUNTIF(J20:L20,"X")<>1,"FALTA/DUPLA: DRENAGEM SUPERFICIAL","OK"))) -> OK
A21: 226ETO0190 | B21: C | C21: 12 | D21: 13 | E21: =D21-C21 -> 1 | G21: X | K21: X | N21: =IF(COUNTA(F21:L21)=0,"— não preenchido",IF(COUNTIF(F21:I21,"X")<>1,"FALTA/DUPLA: CONDIÇÃO DA PLATAFORMA",IF(COUNTIF(J21:L21,"X")<>1,"FALTA/DUPLA: DRENAGEM SUPERFICIAL","OK"))) -> OK
A22: 226ETO0190 | B22: C | C22: 13 | D22: 14 | E22: =D22-C22 -> 1 | G22: X | K22: X | N22: =IF(COUNTA(F22:L22)=0,"— não preenchido",IF(COUNTIF(F22:I22,"X")<>1,"FALTA/DUPLA: CONDIÇÃO DA PLATAFORMA",IF(COUNTIF(J22:L22,"X")<>1,"FALTA/DUPLA: DRENAGEM SUPERFICIAL","OK"))) -> OK
A23: 226ETO0190 | B23: C | C23: 14 | D23: 15 | E23: =D23-C23 -> 1 | G23: X | K23: X | N23: =IF(COUNTA(F23:L23)=0,"— não preenchido",IF(COUNTIF(F23:I23,"X")<>1,"FALTA/DUPLA: CONDIÇÃO DA PLATAFORMA",IF(COUNTIF(J23:L23,"X")<>1,"FALTA/DUPLA: DRENAGEM SUPERFICIAL","OK"))) -> OK
A24: 226ETO0190 | B24: C | C24: 15 | D24: 16 | E24: =D24-C24 -> 1 | G24: X | K24: X | N24: =IF(COUNTA(F24:L24)=0,"— não preenchido",IF(COUNTIF(F24:I24,"X")<>1,"FALTA/DUPLA: CONDIÇÃO DA PLATAFORMA",IF(COUNTIF(J24:L24,"X")<>1,"FALTA/DUPLA: DRENAGEM SUPERFICIAL","OK"))) -> OK
A25: 226ETO0190 | B25: C | C25: 16 | D25: 17 | E25: =D25-C25 -> 1 | G25: X | K25: X | N25: =IF(COUNTA(F25:L25)=0,"— não preenchido",IF(COUNTIF(F25:I25,"X")<>1,"FALTA/DUPLA: CONDIÇÃO DA PLATAFORMA",IF(COUNTIF(J25:L25,"X")<>1,"FALTA/DUPLA: DRENAGEM SUPERFICIAL","OK"))) -> OK
A26: 226ETO0190 | B26: C | C26: 17 | D26: 18 | E26: =D26-C26 -> 1 | G26: X | K26: X | N26: =IF(COUNTA(F26:L26)=0,"— não preenchido",IF(COUNTIF(F26:I26,"X")<>1,"FALTA/DUPLA: CONDIÇÃO DA PLATAFORMA",IF(COUNTIF(J26:L26,"X")<>1,"FALTA/DUPLA: DRENAGEM SUPERFICIAL","OK"))) -> OK
A27: 226ETO0190 | B27: C | C27: 18 | D27: 19 | E27: =D27-C27 -> 1 | G27: X | K27: X | N27: =IF(COUNTA(F27:L27)=0,"— não preenchido",IF(COUNTIF(F27:I27,"X")<>1,"FALTA/DUPLA: CONDIÇÃO DA PLATAFORMA",IF(COUNTIF(J27:L27,"X")<>1,"FALTA/DUPLA: DRENAGEM SUPERFICIAL","OK"))) -> OK
... A45: 226ETO0190 | B45: C | C45: 36 | D45: 36.768231 | E45: =D45-C45 -> 0.7682307 | G45: X | K45: X | N45: =IF(COUNTA(F45:L45)=0,"— não preenchido",IF(COUNTIF(F45:I45,"X")<>1,"FALTA/DUPLA: CONDIÇÃO DA PLATAFORMA",IF(COUNTIF(J45:L45,"X")<>1,"FALTA/DUPLA: DRENAGEM SUPERFICIAL","OK"))) -> OK
A46: S.R.E. 226ETO0200 | POV. ALTO BONITO - NOVA OLINDA *TRECHO URBANO* | LEN · Estadual · 17.621 km · início: -7.642978, -48.284114
A47: 226ETO0200 | B47: C | C47: 0 | D47: 1 | E47: =D47-C47 -> 1 | G47: X | K47: X | N47: =IF(COUNTA(F47:L47)=0,"— não preenchido",IF(COUNTIF(F47:I47,"X")<>1,"FALTA/DUPLA: CONDIÇÃO DA PLATAFORMA",IF(COUNTIF(J47:L47,"X")<>1,"FALTA/DUPLA: DRENAGEM SUPERFICIAL","OK"))) -> OK
A48: 226ETO0200 | B48: C | C48: 1 | D48: 2 | E48: =D48-C48 -> 1 | G48: X | K48: X | N48: =IF(COUNTA(F48:L48)=0,"— não preenchido",IF(COUNTIF(F48:I48,"X")<>1,"FALTA/DUPLA: CONDIÇÃO DA PLATAFORMA",IF(COUNTIF(J48:L48,"X")<>1,"FALTA/DUPLA: DRENAGEM SUPERFICIAL","OK"))) -> OK
A49: 226ETO0200 | B49: C | C49: 2 | D49: 3 | E49: =D49-C49 -> 1 | G49: X | K49: X | N49: =IF(COUNTA(F49:L49)=0,"— não preenchido",IF(COUNTIF(F49:I49,"X")<>1,"FALTA/DUPLA: CONDIÇÃO DA PLATAFORMA",IF(COUNTIF(J49:L49,"X")<>1,"FALTA/DUPLA: DRENAGEM SUPERFICIAL","OK"))) -> OK
A50: 226ETO0200 | B50: C | C50: 3 | D50: 4 | E50: =D50-C50 -> 1 | G50: X | K50: X | N50: =IF(COUNTA(F50:L50)=0,"— não preenchido",IF(COUNTIF(F50:I50,"X")<>1,"FALTA/DUPLA: CONDIÇÃO DA PLATAFORMA",IF(COUNTIF(J50:L50,"X")<>1,"FALTA/DUPLA: DRENAGEM SUPERFICIAL","OK"))) -> OK
A51: 226ETO0200 | B51: C | C51: 4 | D51: 5 | E51: =D51-C51 -> 1 | G51: X | K51: X | N51: =IF(COUNTA(F51:L51)=0,"— não preenchido",IF(COUNTIF(F51:I51,"X")<>1,"FALTA/DUPLA: CONDIÇÃO DA PLATAFORMA",IF(COUNTIF(J51:L51,"X")<>1,"FALTA/DUPLA: DRENAGEM SUPERFICIAL","OK"))) -> OK
A52: 226ETO0200 | B52: C | C52: 5 | D52: 6 | E52: =D52-C52 -> 1 | G52: X | K52: X | N52: =IF(COUNTA(F52:L52)=0,"— não preenchido",IF(COUNTIF(F52:I52,"X")<>1,"FALTA/DUPLA: CONDIÇÃO DA PLATAFORMA",IF(COUNTIF(J52:L52,"X")<>1,"FALTA/DUPLA: DRENAGEM SUPERFICIAL","OK"))) -> OK
A53: 226ETO0200 | B53: C | C53: 6 | D53: 7 | E53: =D53-C53 -> 1 | G53: X | K53: X | N53: =IF(COUNTA(F53:L53)=0,"— não preenchido",IF(COUNTIF(F53:I53,"X")<>1,"FALTA/DUPLA: CONDIÇÃO DA PLATAFORMA",IF(COUNTIF(J53:L53,"X")<>1,"FALTA/DUPLA: DRENAGEM SUPERFICIAL","OK"))) -> OK
A54: 226ETO0200 | B54: C | C54: 7 | D54: 8 | E54: =D54-C54 -> 1 | G54: X | K54: X | N54: =IF(COUNTA(F54:L54)=0,"— não preenchido",IF(COUNTIF(F54:I54,"X")<>1,"FALTA/DUPLA: CONDIÇÃO DA PLATAFORMA",IF(COUNTIF(J54:L54,"X")<>1,"FALTA/DUPLA: DRENAGEM SUPERFICIAL","OK"))) -> OK
A55: 226ETO0200 | B55: C | C55: 8 | D55: 9 | E55: =D55-C55 -> 1 | G55: X | K55: X | N55: =IF(COUNTA(F55:L55)=0,"— não preenchido",IF(COUNTIF(F55:I55,"X")<>1,"FALTA/DUPLA: CONDIÇÃO DA PLATAFORMA",IF(COUNTIF(J55:L55,"X")<>1,"FALTA/DUPLA: DRENAGEM SUPERFICIAL","OK"))) -> OK
A56: 226ETO0200 | B56: C | C56: 9 | D56: 10 | E56: =D56-C56 -> 1 | G56: X | K56: X | N56: =IF(COUNTA(F56:L56)=0,"— não preenchido",IF(COUNTIF(F56:I56,"X")<>1,"FALTA/DUPLA: CONDIÇÃO DA PLATAFORMA",IF(COUNTIF(J56:L56,"X")<>1,"FALTA/DUPLA: DRENAGEM SUPERFICIAL","OK"))) -> OK
A57: 226ETO0200 | B57: C | C57: 10 | D57: 11 | E57: =D57-C57 -> 1 | G57: X | K57: X | N57: =IF(COUNTA(F57:L57)=0,"— não preenchido",IF(COUNTIF(F57:I57,"X")<>1,"FALTA/DUPLA: CONDIÇÃO DA PLATAFORMA",IF(COUNTIF(J57:L57,"X")<>1,"FALTA/DUPLA: DRENAGEM SUPERFICIAL","OK"))) -> OK
A58: 226ETO0200 | B58: C | C58: 11 | D58: 12 | E58: =D58-C58 -> 1 | G58: X | K58: X | N58: =IF(COUNTA(F58:L58)=0,"— não preenchido",IF(COUNTIF(F58:I58,"X")<>1,"FALTA/DUPLA: CONDIÇÃO DA PLATAFORMA",IF(COUNTIF(J58:L58,"X")<>1,"FALTA/DUPLA: DRENAGEM SUPERFICIAL","OK"))) -> OK
...

Sheet 76
A1: PROGRAMA DE MANUTENÇÃO RODOVIÁRIA — FICHA DE INSPEÇÃO — RODOVIAS NÃO PAVIMENTADAS | P1: Valores dos gráficos — troca 0 por N/D para a fatia não aparecer. Não editar.
A2: REGIÃO: 3 — ARAGUAÍNA II | D2: MÊS / ANO: | F2: =IF('67'!F2="","",'67'!F2) -> 46235 | G2: DATA: | I2: =IF('67'!I2="","",'67'!I2) | J2: TÉCNICO: | K2: =IF('67'!K2="","",'67'!K2) -> ENG. VINICIUS RODRIGUES FERREIRA DE OLIVEIRA | P2: =IF(F44=0,NA(),F44) -> 3 | Q2: =IF(G44=0,NA(),G44) -> 22.343878 | R2: =IF(H44=0,NA(),H44) -> 3 | S2: =IF(I44=0,NA(),I44) -> #N/A | T2: =IF(J44=0,NA(),J44) -> #N/A | U2: =IF(K44=0,NA(),K44) -> 28.343878 | V2: =IF(L44=0,NA(),L44) -> #N/A
A3: TRECHO 76 — RODOVIA TO-226 - TRECHO ENTR. TO-010 (POVOADO CAMPOS) - ENTR. BR-010 | K3: EXTENSÃO: 28,344 km · 2 S.R.E.
A4: COMO PREENCHER: uma X em UMA coluna de cada grupo, por linha. Se houver mais de um defeito no mesmo km, marque o PREDOMINANTE e escreva o resto em OBSERVAÇÕES. A quilometragem é contada de 0 até o fim de CADA S.R.E. (não é o marco da rodovia).
A6: S.R.E. | B6: SENT. | C6: INÍCIO (KM) | D6: FIM (KM) | E6: EXT. (KM) | F6: CONDIÇÃO DA PLATAFORMA | J6: DRENAGEM SUPERFICIAL | M6: OBSERVAÇÕES | N6: CONFERÊNCIA (só na tela)
F7: BOM | G7: REG. (ATÉ 10 IRR./KM) | H7: RUIM (+ 10 IRR./KM) | I7: PÉSSIMA (ATOLEIRO/PTO. CRÍTICO) | J7: LIMPA | K7: OBSTRUÍDA | L7: AUSENTE
A8: S.R.E. 226ETO0120 | ENTR. BR-010-TO-130 - TRECHO BARRO VERMELHO | LEN · Estadual · 14.647 km · início: -8.008101, -47.583625
A9: 226ETO0120 | B9: C | C9: 0 | D9: 1 | E9: =D9-C9 -> 1 | G9: X | K9: X | N9: =IF(COUNTA(F9:L9)=0,"— não preenchido",IF(COUNTIF(F9:I9,"X")<>1,"FALTA/DUPLA: CONDIÇÃO DA PLATAFORMA",IF(COUNTIF(J9:L9,"X")<>1,"FALTA/DUPLA: DRENAGEM SUPERFICIAL","OK"))) -> OK
A10: 226ETO0120 | B10: C | C10: 1 | D10: 2 | E10: =D10-C10 -> 1 | F10: X | K10: X | N10: =IF(COUNTA(F10:L10)=0,"— não preenchido",IF(COUNTIF(F10:I10,"X")<>1,"FALTA/DUPLA: CONDIÇÃO DA PLATAFORMA",IF(COUNTIF(J10:L10,"X")<>1,"FALTA/DUPLA: DRENAGEM SUPERFICIAL","OK"))) -> OK
A11: 226ETO0120 | B11: C | C11: 2 | D11: 3 | E11: =D11-C11 -> 1 | G11: X | K11: X | N11: =IF(COUNTA(F11:L11)=0,"— não preenchido",IF(COUNTIF(F11:I11,"X")<>1,"FALTA/DUPLA: CONDIÇÃO DA PLATAFORMA",IF(COUNTIF(J11:L11,"X")<>1,"FALTA/DUPLA: DRENAGEM SUPERFICIAL","OK"))) -> OK
A12: 226ETO0120 | B12: C | C12: 3 | D12: 4 | E12: =D12-C12 -> 1 | H12: X | K12: X | N12: =IF(COUNTA(F12:L12)=0,"— não preenchido",IF(COUNTIF(F12:I12,"X")<>1,"FALTA/DUPLA: CONDIÇÃO DA PLATAFORMA",IF(COUNTIF(J12:L12,"X")<>1,"FALTA/DUPLA: DRENAGEM SUPERFICIAL","OK"))) -> OK
A13: 226ETO0120 | B13: C | C13: 4 | D13: 5 | E13: =D13-C13 -> 1 | G13: X | K13: X | N13: =IF(COUNTA(F13:L13)=0,"— não preenchido",IF(COUNTIF(F13:I13,"X")<>1,"FALTA/DUPLA: CONDIÇÃO DA PLATAFORMA",IF(COUNTIF(J13:L13,"X")<>1,"FALTA/DUPLA: DRENAGEM SUPERFICIAL","OK"))) -> OK
A14: 226ETO0120 | B14: C | C14: 5 | D14: 6 | E14: =D14-C14 -> 1 | G14: X | K14: X | N14: =IF(COUNTA(F14:L14)=0,"— não preenchido",IF(COUNTIF(F14:I14,"X")<>1,"FALTA/DUPLA: CONDIÇÃO DA PLATAFORMA",IF(COUNTIF(J14:L14,"X")<>1,"FALTA/DUPLA: DRENAGEM SUPERFICIAL","OK"))) -> OK
A15: 226ETO0120 | B15: C | C15: 6 | D15: 7 | E15: =D15-C15 -> 1 | G15: X | K15: X | N15: =IF(COUNTA(F15:L15)=0,"— não preenchido",IF(COUNTIF(F15:I15,"X")<>1,"FALTA/DUPLA: CONDIÇÃO DA PLATAFORMA",IF(COUNTIF(J15:L15,"X")<>1,"FALTA/DUPLA: DRENAGEM SUPERFICIAL","OK"))) -> OK
A16: 226ETO0120 | B16: C | C16: 7 | D16: 8 | E16: =D16-C16 -> 1 | G16: X | K16: X | N16: =IF(COUNTA(F16:L16)=0,"— não preenchido",IF(COUNTIF(F16:I16,"X")<>1,"FALTA/DUPLA: CONDIÇÃO DA PLATAFORMA",IF(COUNTIF(J16:L16,"X")<>1,"FALTA/DUPLA: DRENAGEM SUPERFICIAL","OK"))) -> OK
A17: 226ETO0120 | B17: C | C17: 8 | D17: 9 | E17: =D17-C17 -> 1 | H17: X | K17: X | N17: =IF(COUNTA(F17:L17)=0,"— não preenchido",IF(COUNTIF(F17:I17,"X")<>1,"FALTA/DUPLA: CONDIÇÃO DA PLATAFORMA",IF(COUNTIF(J17:L17,"X")<>1,"FALTA/DUPLA: DRENAGEM SUPERFICIAL","OK"))) -> OK
A18: 226ETO0120 | B18: C | C18: 9 | D18: 10 | E18: =D18-C18 -> 1 | G18: X | K18: X | N18: =IF(COUNTA(F18:L18)=0,"— não preenchido",IF(COUNTIF(F18:I18,"X")<>1,"FALTA/DUPLA: CONDIÇÃO DA PLATAFORMA",IF(COUNTIF(J18:L18,"X")<>1,"FALTA/DUPLA: DRENAGEM SUPERFICIAL","OK"))) -> OK
A19: 226ETO0120 | B19: C | C19: 10 | D19: 11 | E19: =D19-C19 -> 1 | G19: X | K19: X | N19: =IF(COUNTA(F19:L19)=0,"— não preenchido",IF(COUNTIF(F19:I19,"X")<>1,"FALTA/DUPLA: CONDIÇÃO DA PLATAFORMA",IF(COUNTIF(J19:L19,"X")<>1,"FALTA/DUPLA: DRENAGEM SUPERFICIAL","OK"))) -> OK
A20: 226ETO0120 | B20: C | C20: 11 | D20: 12 | E20: =D20-C20 -> 1 | G20: X | K20: X | N20: =IF(COUNTA(F20:L20)=0,"— não preenchido",IF(COUNTIF(F20:I20,"X")<>1,"FALTA/DUPLA: CONDIÇÃO DA PLATAFORMA",IF(COUNTIF(J20:L20,"X")<>1,"FALTA/DUPLA: DRENAGEM SUPERFICIAL","OK"))) -> OK
A21: 226ETO0120 | B21: C | C21: 12 | D21: 13 | E21: =D21-C21 -> 1 | G21: X | K21: X | N21: =IF(COUNTA(F21:L21)=0,"— não preenchido",IF(COUNTIF(F21:I21,"X")<>1,"FALTA/DUPLA: CONDIÇÃO DA PLATAFORMA",IF(COUNTIF(J21:L21,"X")<>1,"FALTA/DUPLA: DRENAGEM SUPERFICIAL","OK"))) -> OK
A22: 226ETO0120 | B22: C | C22: 13 | D22: 14 | E22: =D22-C22 -> 1 | G22: X | K22: X | N22: =IF(COUNTA(F22:L22)=0,"— não preenchido",IF(COUNTIF(F22:I22,"X")<>1,"FALTA/DUPLA: CONDIÇÃO DA PLATAFORMA",IF(COUNTIF(J22:L22,"X")<>1,"FALTA/DUPLA: DRENAGEM SUPERFICIAL","OK"))) -> OK
A23: 226ETO0120 | B23: C | C23: 14 | D23: 14.646522 | E23: =D23-C23 -> 0.64652165 | G23: X | K23: X | N23: =IF(COUNTA(F23:L23)=0,"— não preenchido",IF(COUNTIF(F23:I23,"X")<>1,"FALTA/DUPLA: CONDIÇÃO DA PLATAFORMA",IF(COUNTIF(J23:L23,"X")<>1,"FALTA/DUPLA: DRENAGEM SUPERFICIAL","OK"))) -> OK
A24: S.R.E. 226ETO0130 | BARRO VERMELHO - ENTR. TO-010 (CAMPOS) | LEN · Estadual · 13.697 km · início: -7.979919, -47.695868
A25: 226ETO0130 | B25: C | C25: 0 | D25: 1 | E25: =D25-C25 -> 1 | G25: X | K25: X | N25: =IF(COUNTA(F25:L25)=0,"— não preenchido",IF(COUNTIF(F25:I25,"X")<>1,"FALTA/DUPLA: CONDIÇÃO DA PLATAFORMA",IF(COUNTIF(J25:L25,"X")<>1,"FALTA/DUPLA: DRENAGEM SUPERFICIAL","OK"))) -> OK
A26: 226ETO0130 | B26: C | C26: 1 | D26: 2 | E26: =D26-C26 -> 1 | H26: X | K26: X | N26: =IF(COUNTA(F26:L26)=0,"— não preenchido",IF(COUNTIF(F26:I26,"X")<>1,"FALTA/DUPLA: CONDIÇÃO DA PLATAFORMA",IF(COUNTIF(J26:L26,"X")<>1,"FALTA/DUPLA: DRENAGEM SUPERFICIAL","OK"))) -> OK
