Workbook

Sheet RESUMO
A1: RESUMO CONSOLIDADO — REGIÃO 1 — RODOVIAS PAVIMENTADAS | V1: Valores dos gráficos — troca 0 por N/D para a fatia não aparecer. Não editar.
A2: Todos os números vêm das abas dos trechos por referência direta. Não digite nada aqui. A coluna CONFERÊNCIA acusa qualquer trecho em que a soma das marcações não fecha com a extensão. | V2: =IF(D26=0,NA(),D26) -> 357.8146 | W2: =IF(E26=0,NA(),E26) -> 106.56371 | X2: =IF(F26=0,NA(),F26) -> 113.95533 | Y2: =IF(G26=0,NA(),G26) -> 30.42424 | Z2: =IF(H26=0,NA(),H26) -> 39.867345 | AA2: =IF(I26=0,NA(),I26) -> 524.3603 | AB2: =IF(J26=0,NA(),J26) -> 153.25558 | AC2: =IF(K26=0,NA(),K26) -> 22.658043 | ... AK2: =IF(S26=0,NA(),S26) -> 191.56596
A4: Nº TRECHO | B4: TRECHO | C4: EXTENSÃO (KM) | D4: CONDIÇÃO DO PAVIMENTO | I4: VEGETAÇÃO | K4: ELEM. DE DRENAGEM | N4: SIN. HORIZ. | Q4: SIN. VERTICAL | T4: CONFERÊNCIA
D5: BOM | E5: REM. I. | F5: REM. L. | G5: BUR. I. | H5: BUR. L. | I5: ADEQ. | J5: INAD. | K5: LIMPOS | L5: SUJOS | M5: DAN. | N5: BOM | O5: REG. | P5: INEXIST. | Q5: BOM | R5: POUCAS | S5: INEXIST.
A6: 39 | B6: RODOVIA TO-010 - TRECHO RIACHINHO - ANANÁS | C6: ='39'!R32 -> 10.452807 | D6: ='39'!F29 -> 0 | E6: ='39'!G29 -> 0 | F6: ='39'!H29 -> 10.452807 | G6: ='39'!I29 -> 0 | H6: ='39'!J29 -> 0 | I6: ='39'!K29 -> 10.452807 | J6: ='39'!L29 -> 0 | K6: ='39'!M29 -> 0 | ... S6: ='39'!U29 -> 2.4295262 | T6: =IF(SUM(D6:H6)=0,"— não preenchido",IF(ROUND(SUM(D6:H6)-C6,3)=0,"OK","ERRO — dif. de "&ROUND(SUM(D6:H6)-C6,3)&" km")) -> OK
A7: 40 | B7: RODOVIA TO-010 - TRECHO WANDERLÂNDIA - RIACHINHO | C7: ='40'!R87 -> 60.748882 | D7: ='40'!F84 -> 59.674513 | E7: ='40'!G84 -> 0 | F7: ='40'!H84 -> 1.0743694 | G7: ='40'!I84 -> 0 | H7: ='40'!J84 -> 0 | I7: ='40'!K84 -> 60.748882 | J7: ='40'!L84 -> 0 | K7: ='40'!M84 -> 1.7983511 | ... S7: ='40'!U84 -> 5.8608086 | T7: =IF(SUM(D7:H7)=0,"— não preenchido",IF(ROUND(SUM(D7:H7)-C7,3)=0,"OK","ERRO — dif. de "&ROUND(SUM(D7:H7)-C7,3)&" km")) -> OK
A8: 41 | B8: RODOVIA TO-164 - TRECHO ENTR. BR-153 (XAMBIOÁ) - ARAGUANÃ | C8: ='41'!R46 -> 25.715093 | D8: ='41'!F43 -> 19.715093 | E8: ='41'!G43 -> 1 | F8: ='41'!H43 -> 4 | G8: ='41'!I43 -> 1 | H8: ='41'!J43 -> 0 | I8: ='41'!K43 -> 25.715093 | J8: ='41'!L43 -> 0 | K8: ='41'!M43 -> 2.5646179 | ... S8: ='41'!U43 -> 0 | T8: =IF(SUM(D8:H8)=0,"— não preenchido",IF(ROUND(SUM(D8:H8)-C8,3)=0,"OK","ERRO — dif. de "&ROUND(SUM(D8:H8)-C8,3)&" km")) -> OK
A9: 42 | B9: RODOVIA TO-164 - TRECHO FÁBRICA DE CIMENTO - XAMBIOÁ - ENTR. BR-153 | C9: ='42'!R33 -> 13.45061 | D9: ='42'!F30 -> 4.8300059 | E9: ='42'!G30 -> 0 | F9: ='42'!H30 -> 0 | G9: ='42'!I30 -> 1 | H9: ='42'!J30 -> 7.6206039 | I9: ='42'!K30 -> 13.45061 | J9: ='42'!L30 -> 0 | K9: ='42'!M30 -> 0 | ... S9: ='42'!U30 -> 13.45061 | T9: =IF(SUM(D9:H9)=0,"— não preenchido",IF(ROUND(SUM(D9:H9)-C9,3)=0,"OK","ERRO — dif. de "&ROUND(SUM(D9:H9)-C9,3)&" km")) -> OK
A10: 43 | B10: RODOVIA TO-164 - TRECHO ARAGOMINAS - MURICILÂNDIA | C10: ='43'!R40 -> 21.14779 | D10: ='43'!F37 -> 0 | E10: ='43'!G37 -> 15.998808 | F10: ='43'!H37 -> 5.1489827 | G10: ='43'!I37 -> 0 | H10: ='43'!J37 -> 0 | I10: ='43'!K37 -> 8.9988076 | J10: ='43'!L37 -> 12.148983 | K10: ='43'!M37 -> 0.99880763 | ... S10: ='43'!U37 -> 0.99880763 | T10: =IF(SUM(D10:H10)=0,"— não preenchido",IF(ROUND(SUM(D10:H10)-C10,3)=0,"OK","ERRO — dif. de "&ROUND(SUM(D10:H10)-C10,3)&" km")) -> OK
A11: 44 | B11: RODOVIA TO-164 - TRECHO ARAGUANÃ - CARMOLÂNDIA | C11: ='44'!R79 -> 60.402239 | D11: ='44'!F76 -> 48.402239 | E11: ='44'!G76 -> 9 | F11: ='44'!H76 -> 3 | G11: ='44'!I76 -> 0 | H11: ='44'!J76 -> 0 | I11: ='44'!K76 -> 60.402239 | J11: ='44'!L76 -> 0 | K11: ='44'!M76 -> 2.4746415 | ... S11: ='44'!U76 -> 0 | T11: =IF(SUM(D11:H11)=0,"— não preenchido",IF(ROUND(SUM(D11:H11)-C11,3)=0,"OK","ERRO — dif. de "&ROUND(SUM(D11:H11)-C11,3)&" km")) -> OK
A12: 45 | B12: RODOVIA TO-164 - TRECHO CARMOLÂNDIA - ENTR. TO-222 - ARAGOMINAS | C12: ='45'!R62 -> 42.611403 | D12: ='45'!F59 -> 15.93419 | E12: ='45'!G59 -> 0 | F12: ='45'!H59 -> 26.677212 | G12: ='45'!I59 -> 0 | H12: ='45'!J59 -> 0 | I12: ='45'!K59 -> 3 | J12: ='45'!L59 -> 39.611403 | K12: ='45'!M59 -> 0 | ... S12: ='45'!U59 -> 0 | T12: =IF(SUM(D12:H12)=0,"— não preenchido",IF(ROUND(SUM(D12:H12)-C12,3)=0,"OK","ERRO — dif. de "&ROUND(SUM(D12:H12)-C12,3)&" km")) -> OK
A13: 46 | B13: RODOVIA TO-164 - TRECHO ENTR. TO-226 - POVOADO DEZENOVE - BERNARDO SAYÃO | C13: ='46'!R62 -> 40.989414 | D13: ='46'!F59 -> 33.989414 | E13: ='46'!G59 -> 0 | F13: ='46'!H59 -> 0 | G13: ='46'!I59 -> 3 | H13: ='46'!J59 -> 4 | I13: ='46'!K59 -> 40.989414 | J13: ='46'!L59 -> 0 | K13: ='46'!M59 -> 9.5030331 | ... S13: ='46'!U59 -> 0 | T13: =IF(SUM(D13:H13)=0,"— não preenchido",IF(ROUND(SUM(D13:H13)-C13,3)=0,"OK","ERRO — dif. de "&ROUND(SUM(D13:H13)-C13,3)&" km")) -> OK
A14: 47 | B14: RODOVIA TO-164 - TRECHO MURICILÂNDIA - ENTR. TO-226 | C14: ='47'!R19 -> 1.8943523 | D14: ='47'!F16 -> 1.8943523 | E14: ='47'!G16 -> 0 | F14: ='47'!H16 -> 0 | G14: ='47'!I16 -> 0 | H14: ='47'!J16 -> 0 | I14: ='47'!K16 -> 0 | J14: ='47'!L16 -> 1.8943523 | K14: ='47'!M16 -> 1.8943523 | ... S14: ='47'!U16 -> 0 | T14: =IF(SUM(D14:H14)=0,"— não preenchido",IF(ROUND(SUM(D14:H14)-C14,3)=0,"OK","ERRO — dif. de "&ROUND(SUM(D14:H14)-C14,3)&" km")) -> OK
A15: 50 | B15: RODOVIA TO-222 - TRECHO ARAGUAÍNA - ENTR. TO-164 (NOVO HORIZONTE) | C15: ='50'!R33 -> 13.381599 | D15: ='50'!F30 -> 6 | E15: ='50'!G30 -> 7.381599 | F15: ='50'!H30 -> 0 | G15: ='50'!I30 -> 0 | H15: ='50'!J30 -> 0 | I15: ='50'!K30 -> 13.381599 | J15: ='50'!L30 -> 0 | K15: ='50'!M30 -> 0 | ... S15: ='50'!U30 -> 0 | T15: =IF(SUM(D15:H15)=0,"— não preenchido",IF(ROUND(SUM(D15:H15)-C15,3)=0,"OK","ERRO — dif. de "&ROUND(SUM(D15:H15)-C15,3)&" km")) -> OK
A16: 51 | B16: RODOVIA TO-222 - TRECHO MURICILÂNDIA - SANTA FÉ DO ARAGUAIA | C16: ='51'!R27 -> 9.7059136 | D16: ='51'!F24 -> 0 | E16: ='51'!G24 -> 6 | F16: ='51'!H24 -> 1.7059136 | G16: ='51'!I24 -> 2 | H16: ='51'!J24 -> 0 | I16: ='51'!K24 -> 0 | J16: ='51'!L24 -> 9.7059136 | K16: ='51'!M24 -> 0 | ... S16: ='51'!U24 -> 0 | T16: =IF(SUM(D16:H16)=0,"— não preenchido",IF(ROUND(SUM(D16:H16)-C16,3)=0,"OK","ERRO — dif. de "&ROUND(SUM(D16:H16)-C16,3)&" km")) -> OK
A17: 52 | B17: RODOVIA TO-222 - TRECHO SANTA FÉ DO ARAGUAIA - DIVISA TO-PA (POVOADO PORTO LEMOS) | C17: ='52'!R77 -> 57.036247 | D17: ='52'!F74 -> 37 | E17: ='52'!G74 -> 10.854742 | F17: ='52'!H74 -> 5.1815049 | G17: ='52'!I74 -> 4 | H17: ='52'!J74 -> 0 | I17: ='52'!K74 -> 0 | J17: ='52'!L74 -> 57.036247 | K17: ='52'!M74 -> 0 | ... S17: ='52'!U74 -> 0 | T17: =IF(SUM(D17:H17)=0,"— não preenchido",IF(ROUND(SUM(D17:H17)-C17,3)=0,"OK","ERRO — dif. de "&ROUND(SUM(D17:H17)-C17,3)&" km")) -> OK
A18: 53 | B18: RODOVIA TO-226 - TRECHO ENTR. BR-153 (POVOADO RIO PRETO) - DIVISA TO-PA (POVOADO GARIMPINHO) | C18: ='53'!R135 -> 102.64502 | D18: ='53'!F132 -> 15.911806 | E18: ='53'!G132 -> 50.32856 | F18: ='53'!H132 -> 36.404655 | G18: ='53'!I132 -> 0 | H18: ='53'!J132 -> 0 | I18: ='53'!K132 -> 102.64502 | J18: ='53'!L132 -> 0 | K18: ='53'!M132 -> 0 | ... S18: ='53'!U132 -> 95.720786 | T18: =IF(SUM(D18:H18)=0,"— não preenchido",IF(ROUND(SUM(D18:H18)-C18,3)=0,"OK","ERRO — dif. de "&ROUND(SUM(D18:H18)-C18,3)&" km")) -> OK
A19: 54 | B19: RODOVIA TO-230 - TRECHO ARAPOEMA - PAU D'ARCO (DIVISA TO-PA) | C19: ='54'!R56 -> 36.534189 | D19: ='54'!F53 -> 16.224302 | E19: ='54'!G53 -> 2 | F19: ='54'!H53 -> 16.309886 | G19: ='54'!I53 -> 0 | H19: ='54'!J53 -> 2 | I19: ='54'!K53 -> 36.534189 | J19: ='54'!L53 -> 0 | K19: ='54'!M53 -> 2 | ... S19: ='54'!U53 -> 5 | T19: =IF(SUM(D19:H19)=0,"— não preenchido",IF(ROUND(SUM(D19:H19)-C19,3)=0,"OK","ERRO — dif. de "&ROUND(SUM(D19:H19)-C19,3)&" km")) -> OK
A20: 55 | B20: RODOVIA TO-230 - TRECHO BANDEIRANTES DO TOCANTINS - ARAPOEMA | C20: ='55'!R90 -> 61.884362 | D20: ='55'!F87 -> 60.884362 | E20: ='55'!G87 -> 1 | F20: ='55'!H87 -> 0 | G20: ='55'!I87 -> 0 | H20: ='55'!J87 -> 0 | I20: ='55'!K87 -> 61.884362 | J20: ='55'!L87 -> 0 | K20: ='55'!M87 -> 0 | ... S20: ='55'!U87 -> 0 | T20: =IF(SUM(D20:H20)=0,"— não preenchido",IF(ROUND(SUM(D20:H20)-C20,3)=0,"OK","ERRO — dif. de "&ROUND(SUM(D20:H20)-C20,3)&" km")) -> OK
A21: 56 | B21: RODOVIA TO-230 - TRECHO ENTR. BR-153 - BANDEIRANTES DO TOCANTINS | C21: ='56'!R33 -> 15.768494 | D21: ='56'!F30 -> 15.768494 | E21: ='56'!G30 -> 0 | F21: ='56'!H30 -> 0 | G21: ='56'!I30 -> 0 | H21: ='56'!J30 -> 0 | I21: ='56'!K30 -> 15.768494 | J21: ='56'!L30 -> 0 | K21: ='56'!M30 -> 0 | ... S21: ='56'!U30 -> 0 | T21: =IF(SUM(D21:H21)=0,"— não preenchido",IF(ROUND(SUM(D21:H21)-C21,3)=0,"OK","ERRO — dif. de "&ROUND(SUM(D21:H21)-C21,3)&" km")) -> OK
A22: 57 | B22: RODOVIA TO-416 - TRECHO ENTR. BR-153 - RIACHINHO | C22: ='57'!R50 -> 32.246741 | D22: ='57'!F47 -> 4 | E22: ='57'!G47 -> 3 | F22: ='57'!H47 -> 4 | G22: ='57'!I47 -> 5 | H22: ='57'!J47 -> 16.246741 | I22: ='57'!K47 -> 32.246741 | J22: ='57'!L47 -> 0 | K22: ='57'!M47 -> 0 | ... S22: ='57'!U47 -> 32.246741 | T22: =IF(SUM(D22:H22)=0,"— não preenchido",IF(ROUND(SUM(D22:H22)-C22,3)=0,"OK","ERRO — dif. de "&ROUND(SUM(D22:H22)-C22,3)&" km")) -> OK
A23: 58 | B23: RODOVIA TO-416 - TRECHO ENTR. TO-222 - POVOADO COCALINHO | C23: ='58'!R21 -> 3.8680293 | D23: ='58'!F18 -> 3.8680293 | E23: ='58'!G18 -> 0 | F23: ='58'!H18 -> 0 | G23: ='58'!I18 -> 0 | H23: ='58'!J18 -> 0 | I23: ='58'!K18 -> 0 | J23: ='58'!L18 -> 3.8680293 | K23: ='58'!M18 -> 0 | ... S23: ='58'!U18 -> 3.8680293 | T23: =IF(SUM(D23:H23)=0,"— não preenchido",IF(ROUND(SUM(D23:H23)-C23,3)=0,"OK","ERRO — dif. de "&ROUND(SUM(D23:H23)-C23,3)&" km")) -> OK
A24: 61 | B24: RODOVIA TO-420 - TRECHO ENTR. BR-153 (POVOADO XAMBERLÂNDIA) - PIRAQUÊ - ENTR. BR-153 | C24: ='61'!R58 -> 38.142042 | D24: ='61'!F55 -> 13.717802 | E24: ='61'!G55 -> 0 | F24: ='61'!H55 -> 0 | G24: ='61'!I55 -> 14.42424 | H24: ='61'!J55 -> 10 | I24: ='61'!K55 -> 38.142042 | J24: ='61'!L55 -> 0 | K24: ='61'!M55 -> 1.4242395 | ... S24: ='61'!U55 -> 3 | T24: =IF(SUM(D24:H24)=0,"— não preenchido",IF(ROUND(SUM(D24:H24)-C24,3)=0,"OK","ERRO — dif. de "&ROUND(SUM(D24:H24)-C24,3)&" km")) -> OK
A25: 63 | B25: RODOVIA TO-427 - TRECHO PAU D'ARCO (DIVISA TO-PA) - ENTR. TO-226 | C25: ='63'!R46 -> 28.990649 | D25: ='63'!F43 -> 0 | E25: ='63'!G43 -> 0 | F25: ='63'!H43 -> 0 | G25: ='63'!I43 -> 0 | H25: ='63'!J43 -> 0 | I25: ='63'!K43 -> 0 | J25: ='63'!L43 -> 28.990649 | K25: ='63'!M43 -> 0 | ... S25: ='63'!U43 -> 28.990649 | T25: =IF(SUM(D25:H25)=0,"— não preenchido",IF(ROUND(SUM(D25:H25)-C25,3)=0,"OK","ERRO — dif. de "&ROUND(SUM(D25:H25)-C25,3)&" km")) -> — não preenchido
B26: TOTAL PERCORRIDO NO MÊS | C26: =SUM(C6:C25) -> 677.61588 | D26: =SUM(D6:D25) -> 357.8146 | E26: =SUM(E6:E25) -> 106.56371 | F26: =SUM(F6:F25) -> 113.95533 | G26: =SUM(G6:G25) -> 30.42424 | H26: =SUM(H6:H25) -> 39.867345 | I26: =SUM(I6:I25) -> 524.3603 | J26: =SUM(J6:J25) -> 153.25558 | ... S26: =SUM(S6:S25) -> 191.56596
B27: % DA EXTENSÃO DA MALHA (677.62 km) | D27: =SUM(D26:H26)/677.62 -> 0.95721087 | I27: (soma do grupo 'CONDIÇÃO DO PAVIMENTO' dividida pela malha)

Sheet 39
A1: PROGRAMA DE MANUTENÇÃO RODOVIÁRIA — FICHA DE INSPEÇÃO — RODOVIAS PAVIMENTADAS | Y1: Valores dos gráficos — troca 0 por N/D para a fatia não aparecer. Não editar.
A2: REGIÃO: 2 — ARAGUAÍNA I | G2: MÊS / ANO: | I2: 46235 | K2: DATA: | P2: TÉCNICO: | R2: ENG. VINICIUS RODRIGUES FERREIRA DE OLIVEIRA | Y2: =IF(F29=0,NA(),F29) -> #N/A | Z2: =IF(G29=0,NA(),G29) -> #N/A | AA2: =IF(H29=0,NA(),H29) -> 10.452807 | AB2: =IF(I29=0,NA(),I29) -> #N/A | AC2: =IF(J29=0,NA(),J29) -> #N/A | AD2: =IF(K29=0,NA(),K29) -> 10.452807 | AE2: =IF(L29=0,NA(),L29) -> #N/A | AF2: =IF(M29=0,NA(),M29) -> #N/A | ... AN2: =IF(U29=0,NA(),U29) -> 2.4295262
A3: TRECHO 39 — RODOVIA TO-010 - TRECHO RIACHINHO - ANANÁS | T3: EXTENSÃO: 10,453 km · 3 S.R.E.
A4: COMO PREENCHER: uma X em UMA coluna de cada grupo, por linha. Se houver mais de um defeito no mesmo km, marque o PREDOMINANTE e escreva o resto em OBSERVAÇÕES. A quilometragem é contada de 0 até o fim de CADA S.R.E. (não é o marco da rodovia).
A6: S.R.E. | B6: SENT. | C6: INÍCIO (KM) | D6: FIM (KM) | E6: EXT. (KM) | F6: CONDIÇÃO DO PAVIMENTO | K6: VEGETAÇÃO | M6: ELEM. DE DRENAGEM | P6: SIN. HORIZ. | S6: SIN. VERTICAL | V6: OBSERVAÇÕES | W6: CONFERÊNCIA (só na tela)
F7: BOM | G7: REM. I. | H7: REM. L. | I7: BUR. I. | J7: BUR. L. | K7: ADEQ. | L7: INAD. | M7: LIMPOS | N7: SUJOS | O7: DAN. | P7: BOM | Q7: REG. | R7: INEXIST. | S7: BOM | T7: POUCAS | U7: INEXIST.
A8: S.R.E. 416ETO0040 | ENTR. TO-010 - RIACHINHO | PPS · Estadual · 2.430 km · início: -6.446327, -48.137832
A9: 416ETO0040 | B9: C | C9: 0 | D9: 1 | E9: =D9-C9 -> 1 | H9: X | K9: X | N9: X | R9: X | U9: X | W9: =IF(COUNTA(F9:U9)=0,"— não preenchido",IF(COUNTIF(F9:J9,"X")<>1,"FALTA/DUPLA: CONDIÇÃO DO PAVIMENTO",IF(COUNTIF(K9:L9,"X")<>1,"FALTA/DUPLA: VEGETAÇÃO",IF(COUNTIF(M9:O9,"X")<>1,"FALTA/DUPLA: ELEM. DE DRENAGEM",IF(COUNTIF(P9:R9,"X")<>1,"FALTA/DUPLA: SIN. HORIZ.",IF(COUNTIF(S9:U9,"X")<>1,"FALTA/DUPLA: SIN. VERTICAL","OK")))))) -> OK
A10: 416ETO0040 | B10: C | C10: 1 | D10: 2 | E10: =D10-C10 -> 1 | H10: X | K10: X | N10: X | R10: X | U10: X | W10: =IF(COUNTA(F10:U10)=0,"— não preenchido",IF(COUNTIF(F10:J10,"X")<>1,"FALTA/DUPLA: CONDIÇÃO DO PAVIMENTO",IF(COUNTIF(K10:L10,"X")<>1,"FALTA/DUPLA: VEGETAÇÃO",IF(COUNTIF(M10:O10,"X")<>1,"FALTA/DUPLA: ELEM. DE DRENAGEM",IF(COUNTIF(P10:R10,"X")<>1,"FALTA/DUPLA: SIN. HORIZ.",IF(COUNTIF(S10:U10,"X")<>1,"FALTA/DUPLA: SIN. VERTICAL","OK")))))) -> OK
A11: 416ETO0040 | B11: C | C11: 2 | D11: 2.4295262 | E11: =D11-C11 -> 0.42952623 | H11: X | K11: X | N11: X | R11: X | U11: X | W11: =IF(COUNTA(F11:U11)=0,"— não preenchido",IF(COUNTIF(F11:J11,"X")<>1,"FALTA/DUPLA: CONDIÇÃO DO PAVIMENTO",IF(COUNTIF(K11:L11,"X")<>1,"FALTA/DUPLA: VEGETAÇÃO",IF(COUNTIF(M11:O11,"X")<>1,"FALTA/DUPLA: ELEM. DE DRENAGEM",IF(COUNTIF(P11:R11,"X")<>1,"FALTA/DUPLA: SIN. HORIZ.",IF(COUNTIF(S11:U11,"X")<>1,"FALTA/DUPLA: SIN. VERTICAL","OK")))))) -> OK
A12: ▲ AQUI HÁ 602.060 km FORA DO ESCOPO DO CONTRATO (perímetro urbano de jurisdição municipal). Você passa por ele, mas NÃO preenche.
A13: S.R.E. 010ETO0500 | ENTR. TO-416 - SÃO RAIMUNDO | PPS · Estadual · 4.267 km · início: -6.433737, -48.12044
A14: 010ETO0500 | B14: C | C14: 0 | D14: 1 | E14: =D14-C14 -> 1 | H14: X | K14: X | N14: X | R14: X | T14: X | W14: =IF(COUNTA(F14:U14)=0,"— não preenchido",IF(COUNTIF(F14:J14,"X")<>1,"FALTA/DUPLA: CONDIÇÃO DO PAVIMENTO",IF(COUNTIF(K14:L14,"X")<>1,"FALTA/DUPLA: VEGETAÇÃO",IF(COUNTIF(M14:O14,"X")<>1,"FALTA/DUPLA: ELEM. DE DRENAGEM",IF(COUNTIF(P14:R14,"X")<>1,"FALTA/DUPLA: SIN. HORIZ.",IF(COUNTIF(S14:U14,"X")<>1,"FALTA/DUPLA: SIN. VERTICAL","OK")))))) -> OK
A15: 010ETO0500 | B15: C | C15: 1 | D15: 2 | E15: =D15-C15 -> 1 | H15: X | K15: X | N15: X | R15: X | T15: X | W15: =IF(COUNTA(F15:U15)=0,"— não preenchido",IF(COUNTIF(F15:J15,"X")<>1,"FALTA/DUPLA: CONDIÇÃO DO PAVIMENTO",IF(COUNTIF(K15:L15,"X")<>1,"FALTA/DUPLA: VEGETAÇÃO",IF(COUNTIF(M15:O15,"X")<>1,"FALTA/DUPLA: ELEM. DE DRENAGEM",IF(COUNTIF(P15:R15,"X")<>1,"FALTA/DUPLA: SIN. HORIZ.",IF(COUNTIF(S15:U15,"X")<>1,"FALTA/DUPLA: SIN. VERTICAL","OK")))))) -> OK
A16: 010ETO0500 | B16: C | C16: 2 | D16: 3 | E16: =D16-C16 -> 1 | H16: X | K16: X | N16: X | R16: X | T16: X | W16: =IF(COUNTA(F16:U16)=0,"— não preenchido",IF(COUNTIF(F16:J16,"X")<>1,"FALTA/DUPLA: CONDIÇÃO DO PAVIMENTO",IF(COUNTIF(K16:L16,"X")<>1,"FALTA/DUPLA: VEGETAÇÃO",IF(COUNTIF(M16:O16,"X")<>1,"FALTA/DUPLA: ELEM. DE DRENAGEM",IF(COUNTIF(P16:R16,"X")<>1,"FALTA/DUPLA: SIN. HORIZ.",IF(COUNTIF(S16:U16,"X")<>1,"FALTA/DUPLA: SIN. VERTICAL","OK")))))) -> OK
A17: 010ETO0500 | B17: C | C17: 3 | D17: 4 | E17: =D17-C17 -> 1 | H17: X | K17: X | N17: X | R17: X | T17: X | W17: =IF(COUNTA(F17:U17)=0,"— não preenchido",IF(COUNTIF(F17:J17,"X")<>1,"FALTA/DUPLA: CONDIÇÃO DO PAVIMENTO",IF(COUNTIF(K17:L17,"X")<>1,"FALTA/DUPLA: VEGETAÇÃO",IF(COUNTIF(M17:O17,"X")<>1,"FALTA/DUPLA: ELEM. DE DRENAGEM",IF(COUNTIF(P17:R17,"X")<>1,"FALTA/DUPLA: SIN. HORIZ.",IF(COUNTIF(S17:U17,"X")<>1,"FALTA/DUPLA: SIN. VERTICAL","OK")))))) -> OK
A18: 010ETO0500 | B18: C | C18: 4 | D18: 4.2669872 | E18: =D18-C18 -> 0.26698723 | H18: X | K18: X | N18: X | R18: X | T18: X | W18: =IF(COUNTA(F18:U18)=0,"— não preenchido",IF(COUNTIF(F18:J18,"X")<>1,"FALTA/DUPLA: CONDIÇÃO DO PAVIMENTO",IF(COUNTIF(K18:L18,"X")<>1,"FALTA/DUPLA: VEGETAÇÃO",IF(COUNTIF(M18:O18,"X")<>1,"FALTA/DUPLA: ELEM. DE DRENAGEM",IF(COUNTIF(P18:R18,"X")<>1,"FALTA/DUPLA: SIN. HORIZ.",IF(COUNTIF(S18:U18,"X")<>1,"FALTA/DUPLA: SIN. VERTICAL","OK")))))) -> OK
A19: S.R.E. 010ETO0510 | SÃO RAIMUNDO - ANANÁS *TRECHO URBANO* | PPS · Estadual · 3.756 km · início: -6.402218, -48.094278
A20: 010ETO0510 | B20: C | C20: 0 | D20: 1 | E20: =D20-C20 -> 1 | H20: X | K20: X | N20: X | R20: X | T20: X | W20: =IF(COUNTA(F20:U20)=0,"— não preenchido",IF(COUNTIF(F20:J20,"X")<>1,"FALTA/DUPLA: CONDIÇÃO DO PAVIMENTO",IF(COUNTIF(K20:L20,"X")<>1,"FALTA/DUPLA: VEGETAÇÃO",IF(COUNTIF(M20:O20,"X")<>1,"FALTA/DUPLA: ELEM. DE DRENAGEM",IF(COUNTIF(P20:R20,"X")<>1,"FALTA/DUPLA: SIN. HORIZ.",IF(COUNTIF(S20:U20,"X")<>1,"FALTA/DUPLA: SIN. VERTICAL","OK")))))) -> OK
A21: 010ETO0510 | B21: C | C21: 1 | D21: 2 | E21: =D21-C21 -> 1 | H21: X | K21: X | N21: X | R21: X | T21: X | W21: =IF(COUNTA(F21:U21)=0,"— não preenchido",IF(COUNTIF(F21:J21,"X")<>1,"FALTA/DUPLA: CONDIÇÃO DO PAVIMENTO",IF(COUNTIF(K21:L21,"X")<>1,"FALTA/DUPLA: VEGETAÇÃO",IF(COUNTIF(M21:O21,"X")<>1,"FALTA/DUPLA: ELEM. DE DRENAGEM",IF(COUNTIF(P21:R21,"X")<>1,"FALTA/DUPLA: SIN. HORIZ.",IF(COUNTIF(S21:U21,"X")<>1,"FALTA/DUPLA: SIN. VERTICAL","OK")))))) -> OK
A22: 010ETO0510 | B22: C | C22: 2 | D22: 3 | E22: =D22-C22 -> 1 | H22: X | K22: X | N22: X | R22: X | T22: X | W22: =IF(COUNTA(F22:U22)=0,"— não preenchido",IF(COUNTIF(F22:J22,"X")<>1,"FALTA/DUPLA: CONDIÇÃO DO PAVIMENTO",IF(COUNTIF(K22:L22,"X")<>1,"FALTA/DUPLA: VEGETAÇÃO",IF(COUNTIF(M22:O22,"X")<>1,"FALTA/DUPLA: ELEM. DE DRENAGEM",IF(COUNTIF(P22:R22,"X")<>1,"FALTA/DUPLA: SIN. HORIZ.",IF(COUNTIF(S22:U22,"X")<>1,"FALTA/DUPLA: SIN. VERTICAL","OK")))))) -> OK
A23: 010ETO0510 | B23: C | C23: 3 | D23: 3.7562933 | E23: =D23-C23 -> 0.75629334 | H23: X | K23: X | N23: X | R23: X | T23: X | W23: =IF(COUNTA(F23:U23)=0,"— não preenchido",IF(COUNTIF(F23:J23,"X")<>1,"FALTA/DUPLA: CONDIÇÃO DO PAVIMENTO",IF(COUNTIF(K23:L23,"X")<>1,"FALTA/DUPLA: VEGETAÇÃO",IF(COUNTIF(M23:O23,"X")<>1,"FALTA/DUPLA: ELEM. DE DRENAGEM",IF(COUNTIF(P23:R23,"X")<>1,"FALTA/DUPLA: SIN. HORIZ.",IF(COUNTIF(S23:U23,"X")<>1,"FALTA/DUPLA: SIN. VERTICAL","OK")))))) -> OK
A25: ____________________________________________ | G25: ____________________________________________
A26: TÉCNICO RESPONSÁVEL PELA INSPEÇÃO | G26: VISTO DA SUPERVISÃO
A28: RESUMO DO TRECHO — KM LANÇADO POR ITEM
A29: KM LANÇADO | F29: =SUMIF(F$9:F$23,"X",$E$9:$E$23) -> 0 | G29: =SUMIF(G$9:G$23,"X",$E$9:$E$23) -> 0 | H29: =SUMIF(H$9:H$23,"X",$E$9:$E$23) -> 10.452807 | I29: =SUMIF(I$9:I$23,"X",$E$9:$E$23) -> 0 | J29: =SUMIF(J$9:J$23,"X",$E$9:$E$23) -> 0 | K29: =SUMIF(K$9:K$23,"X",$E$9:$E$23) -> 10.452807 | L29: =SUMIF(L$9:L$23,"X",$E$9:$E$23) -> 0 | M29: =SUMIF(M$9:M$23,"X",$E$9:$E$23) -> 0 | ... U29: =SUMIF(U$9:U$23,"X",$E$9:$E$23) -> 2.4295262
A30: % DA EXTENSÃO | F30: =IF($R32=0,0,F29/$R32) -> 0 | G30: =IF($R32=0,0,G29/$R32) -> 0 | H30: =IF($R32=0,0,H29/$R32) -> 1 | I30: =IF($R32=0,0,I29/$R32) -> 0 | J30: =IF($R32=0,0,J29/$R32) -> 0 | K30: =IF($R32=0,0,K29/$R32) -> 1 | L30: =IF($R32=0,0,L29/$R32) -> 0 | M30: =IF($R32=0,0,M29/$R32) -> 0 | ... U30: =IF($R32=0,0,U29/$R32) -> 0.23242812
A31: CONFERÊNCIA POR GRUPO | F31: =IF(SUM(F29:J29)=0,"— não preenchido",IF(ROUND(SUM(F29:J29)-$R32,3)=0,"OK — "&ROUND(SUM(F29:J29),3)&" km","ERRO — dif. de "&ROUND(SUM(F29:J29)-$R32,3)&" km")) -> OK — 10,453 km | K31: =IF(SUM(K29:L29)=0,"— não preenchido",IF(ROUND(SUM(K29:L29)-$R32,3)=0,"OK — "&ROUND(SUM(K29:L29),3)&" km","ERRO — dif. de "&ROUND(SUM(K29:L29)-$R32,3)&" km")) -> OK — 10,453 km | M31: =IF(SUM(M29:O29)=0,"— não preenchido",IF(ROUND(SUM(M29:O29)-$R32,3)=0,"OK — "&ROUND(SUM(M29:O29),3)&" km","ERRO — dif. de "&ROUND(SUM(M29:O29)-$R32,3)&" km")) -> OK — 10,453 km | P31: =IF(SUM(P29:R29)=0,"— não preenchido",IF(ROUND(SUM(P29:R29)-$R32,3)=0,"OK — "&ROUND(SUM(P29:R29),3)&" km","ERRO — dif. de "&ROUND(SUM(P29:R29)-$R32,3)&" km")) -> OK — 10,453 km | S31: =IF(SUM(S29:U29)=0,"— não preenchido",IF(ROUND(SUM(S29:U29)-$R32,3)=0,"OK — "&ROUND(SUM(S29:U29),3)&" km","ERRO — dif. de "&ROUND(SUM(S29:U29)-$R32,3)&" km")) -> OK — 10,453 km
A32: EXTENSÃO TOTAL DO TRECHO | R32: =SUM(E9:E23) -> 10.452807 | V32: =COUNTIF(W9:W23,"OK")&" de "&COUNT($E$9:$E$23)&" linhas conferidas" -> 12 de 12 linhas conferidas
A34: LEGENDA
A35: REM. I. / REM. L. | E35: Remendos isolados (até 10 por km) · Remendos ao longo (mais de 10 por km)
A36: BUR. I. / BUR. L. | E36: Buracos isolados (até 5 por km) · Buracos ao longo (mais de 5 por km)
A37: SIT. | E37: PPS = pista simples · PSU = simples urbana · PDU = duplicada
A38: FAIXA AZUL | E38: Cabeçalho de cada S.R.E.: descrição, situação, jurisdição, extensão e coordenada de início.
A39: INÍCIO / FIM (KM) | E39: Contados de 0 até o fim de CADA S.R.E. Não é o marco quilométrico da rodovia.
A40: SENT. | E40: C = crescente · D = decrescente
A41: FAIXA CINZA | E41: Segmento fora do escopo do contrato: você passa por ele, mas não preenche.
A42: CÉLULA VERMELHA | E42: Mais de uma X no mesmo grupo. Apague uma delas.
A43: CONFERÊNCIA | E43: Só na tela, não sai impresso. Fica OK com uma X em cada grupo.

Sheet 40
A1: PROGRAMA DE MANUTENÇÃO RODOVIÁRIA — FICHA DE INSPEÇÃO — RODOVIAS PAVIMENTADAS | Y1: Valores dos gráficos — troca 0 por N/D para a fatia não aparecer. Não editar.
A2: REGIÃO: 2 — ARAGUAÍNA I | G2: MÊS / ANO: | I2: =IF('39'!I2="","",'39'!I2) -> 46235 | K2: DATA: | N2: =IF('39'!N2="","",'39'!N2) | P2: TÉCNICO: | R2: =IF('39'!R2="","",'39'!R2) -> ENG. VINICIUS RODRIGUES FERREIRA DE OLIVEIRA | Y2: =IF(F84=0,NA(),F84) -> 59.674513 | Z2: =IF(G84=0,NA(),G84) -> #N/A | AA2: =IF(H84=0,NA(),H84) -> 1.0743694 | AB2: =IF(I84=0,NA(),I84) -> #N/A | AC2: =IF(J84=0,NA(),J84) -> #N/A | AD2: =IF(K84=0,NA(),K84) -> 60.748882 | AE2: =IF(L84=0,NA(),L84) -> #N/A | AF2: =IF(M84=0,NA(),M84) -> 1.7983511 | ... AN2: =IF(U84=0,NA(),U84) -> 5.8608086
A3: TRECHO 40 — RODOVIA TO-010 - TRECHO WANDERLÂNDIA - RIACHINHO | T3: EXTENSÃO: 60,749 km · 7 S.R.E.
A4: COMO PREENCHER: uma X em UMA coluna de cada grupo, por linha. Se houver mais de um defeito no mesmo km, marque o PREDOMINANTE e escreva o resto em OBSERVAÇÕES. A quilometragem é contada de 0 até o fim de CADA S.R.E. (não é o marco da rodovia).
A6: S.R.E. | B6: SENT. | C6: INÍCIO (KM) | D6: FIM (KM) | E6: EXT. (KM) | F6: CONDIÇÃO DO PAVIMENTO | K6: VEGETAÇÃO | M6: ELEM. DE DRENAGEM | P6: SIN. HORIZ. | S6: SIN. VERTICAL | V6: OBSERVAÇÕES | W6: CONFERÊNCIA (só na tela)
F7: BOM | G7: REM. I. | H7: REM. L. | I7: BUR. I. | J7: BUR. L. | K7: ADEQ. | L7: INAD. | M7: LIMPOS | N7: SUJOS | O7: DAN. | P7: BOM | Q7: REG. | R7: INEXIST. | S7: BOM | T7: POUCAS | U7: INEXIST.
A8: S.R.E. 010ETO0421 | WANDERLÂNDIA *TRECHO URBANO* | PSU · Municipal · 1.084 km · início: -6.849179, -47.964118
A9: 010ETO0421 | B9: C | C9: 0 | D9: 1 | E9: =D9-C9 -> 1 | F9: X | K9: X | M9: X | R9: X | U9: X | W9: =IF(COUNTA(F9:U9)=0,"— não preenchido",IF(COUNTIF(F9:J9,"X")<>1,"FALTA/DUPLA: CONDIÇÃO DO PAVIMENTO",IF(COUNTIF(K9:L9,"X")<>1,"FALTA/DUPLA: VEGETAÇÃO",IF(COUNTIF(M9:O9,"X")<>1,"FALTA/DUPLA: ELEM. DE DRENAGEM",IF(COUNTIF(P9:R9,"X")<>1,"FALTA/DUPLA: SIN. HORIZ.",IF(COUNTIF(S9:U9,"X")<>1,"FALTA/DUPLA: SIN. VERTICAL","OK")))))) -> OK
A10: 010ETO0421 | B10: C | C10: 1 | D10: 1.0835334 | E10: =D10-C10 -> 0.083533375 | F10: X | K10: X | M10: X | R10: X | U10: X | W10: =IF(COUNTA(F10:U10)=0,"— não preenchido",IF(COUNTIF(F10:J10,"X")<>1,"FALTA/DUPLA: CONDIÇÃO DO PAVIMENTO",IF(COUNTIF(K10:L10,"X")<>1,"FALTA/DUPLA: VEGETAÇÃO",IF(COUNTIF(M10:O10,"X")<>1,"FALTA/DUPLA: ELEM. DE DRENAGEM",IF(COUNTIF(P10:R10,"X")<>1,"FALTA/DUPLA: SIN. HORIZ.",IF(COUNTIF(S10:U10,"X")<>1,"FALTA/DUPLA: SIN. VERTICAL","OK")))))) -> OK
A11: S.R.E. 010ETO0422 | WANDERLÂNDIA *TRECHO URBANO* | PSU · Municipal · 0.715 km · sem coordenada no shape
A12: 010ETO0422 | B12: C | C12: 0 | D12: 0.7148177 | E12: =D12-C12 -> 0.7148177 | F12: X | K12: X | M12: X | R12: X | U12: X | W12: =IF(COUNTA(F12:U12)=0,"— não preenchido",IF(COUNTIF(F12:J12,"X")<>1,"FALTA/DUPLA: CONDIÇÃO DO PAVIMENTO",IF(COUNTIF(K12:L12,"X")<>1,"FALTA/DUPLA: VEGETAÇÃO",IF(COUNTIF(M12:O12,"X")<>1,"FALTA/DUPLA: ELEM. DE DRENAGEM",IF(COUNTIF(P12:R12,"X")<>1,"FALTA/DUPLA: SIN. HORIZ.",IF(COUNTIF(S12:U12,"X")<>1,"FALTA/DUPLA: SIN. VERTICAL","OK")))))) -> OK
A13: S.R.E. 010ETO0430 | WANDERLANDIA - ENTR. BR-153 | PPS · Estadual · 1.074 km · início: -6.835071, -47.97269
A14: 010ETO0430 | B14: C | C14: 0 | D14: 1 | E14: =D14-C14 -> 1 | H14: X | K14: X | N14: X | R14: X | U14: X | W14: =IF(COUNTA(F14:U14)=0,"— não preenchido",IF(COUNTIF(F14:J14,"X")<>1,"FALTA/DUPLA: CONDIÇÃO DO PAVIMENTO",IF(COUNTIF(K14:L14,"X")<>1,"FALTA/DUPLA: VEGETAÇÃO",IF(COUNTIF(M14:O14,"X")<>1,"FALTA/DUPLA: ELEM. DE DRENAGEM",IF(COUNTIF(P14:R14,"X")<>1,"FALTA/DUPLA: SIN. HORIZ.",IF(COUNTIF(S14:U14,"X")<>1,"FALTA/DUPLA: SIN. VERTICAL","OK")))))) -> OK
A15: 010ETO0430 | B15: C | C15: 1 | D15: 1.0743694 | E15: =D15-C15 -> 0.074369395 | H15: X | K15: X | N15: X | R15: X | U15: X | W15: =IF(COUNTA(F15:U15)=0,"— não preenchido",IF(COUNTIF(F15:J15,"X")<>1,"FALTA/DUPLA: CONDIÇÃO DO PAVIMENTO",IF(COUNTIF(K15:L15,"X")<>1,"FALTA/DUPLA: VEGETAÇÃO",IF(COUNTIF(M15:O15,"X")<>1,"FALTA/DUPLA: ELEM. DE DRENAGEM",IF(COUNTIF(P15:R15,"X")<>1,"FALTA/DUPLA: SIN. HORIZ.",IF(COUNTIF(S15:U15,"X")<>1,"FALTA/DUPLA: SIN. VERTICAL","OK")))))) -> OK
A16: S.R.E. 010ETO0440 | ENTR. BR-226 - ENTR.BR-153 | PPS · Estadual · 2.988 km · sem coordenada no shape
A17: 010ETO0440 | B17: C | C17: 0 | D17: 1 | E17: =D17-C17 -> 1 | F17: X | K17: X | O17: X | R17: X | U17: X | W17: =IF(COUNTA(F17:U17)=0,"— não preenchido",IF(COUNTIF(F17:J17,"X")<>1,"FALTA/DUPLA: CONDIÇÃO DO PAVIMENTO",IF(COUNTIF(K17:L17,"X")<>1,"FALTA/DUPLA: VEGETAÇÃO",IF(COUNTIF(M17:O17,"X")<>1,"FALTA/DUPLA: ELEM. DE DRENAGEM",IF(COUNTIF(P17:R17,"X")<>1,"FALTA/DUPLA: SIN. HORIZ.",IF(COUNTIF(S17:U17,"X")<>1,"FALTA/DUPLA: SIN. VERTICAL","OK")))))) -> OK
A18: 010ETO0440 | B18: C | C18: 1 | D18: 2 | E18: =D18-C18 -> 1 | F18: X | K18: X | O18: X | R18: X | U18: X | W18: =IF(COUNTA(F18:U18)=0,"— não preenchido",IF(COUNTIF(F18:J18,"X")<>1,"FALTA/DUPLA: CONDIÇÃO DO PAVIMENTO",IF(COUNTIF(K18:L18,"X")<>1,"FALTA/DUPLA: VEGETAÇÃO",IF(COUNTIF(M18:O18,"X")<>1,"FALTA/DUPLA: ELEM. DE DRENAGEM",IF(COUNTIF(P18:R18,"X")<>1,"FALTA/DUPLA: SIN. HORIZ.",IF(COUNTIF(S18:U18,"X")<>1,"FALTA/DUPLA: SIN. VERTICAL","OK")))))) -> OK
A19: 010ETO0440 | B19: C | C19: 2 | D19: 2.9880881 | E19: =D19-C19 -> 0.9880881 | F19: X | K19: X | O19: X | R19: X | U19: X | W19: =IF(COUNTA(F19:U19)=0,"— não preenchido",IF(COUNTIF(F19:J19,"X")<>1,"FALTA/DUPLA: CONDIÇÃO DO PAVIMENTO",IF(COUNTIF(K19:L19,"X")<>1,"FALTA/DUPLA: VEGETAÇÃO",IF(COUNTIF(M19:O19,"X")<>1,"FALTA/DUPLA: ELEM. DE DRENAGEM",IF(COUNTIF(P19:R19,"X")<>1,"FALTA/DUPLA: SIN. HORIZ.",IF(COUNTIF(S19:U19,"X")<>1,"FALTA/DUPLA: SIN. VERTICAL","OK")))))) -> OK
A20: S.R.E. 010ETO0470 | ENTR. BR-153 - CENTRO DOS BORGES | PPS · Estadual · 42.716 km · início: -6.828264, -47.976211
A21: 010ETO0470 | B21: C | C21: 0 | D21: 1 | E21: =D21-C21 -> 1 | F21: X | K21: X | N21: X | P21: X | T21: X | W21: =IF(COUNTA(F21:U21)=0,"— não preenchido",IF(COUNTIF(F21:J21,"X")<>1,"FALTA/DUPLA: CONDIÇÃO DO PAVIMENTO",IF(COUNTIF(K21:L21,"X")<>1,"FALTA/DUPLA: VEGETAÇÃO",IF(COUNTIF(M21:O21,"X")<>1,"FALTA/DUPLA: ELEM. DE DRENAGEM",IF(COUNTIF(P21:R21,"X")<>1,"FALTA/DUPLA: SIN. HORIZ.",IF(COUNTIF(S21:U21,"X")<>1,"FALTA/DUPLA: SIN. VERTICAL","OK")))))) -> OK
A22: 010ETO0470 | B22: C | C22: 1 | D22: 2 | E22: =D22-C22 -> 1 | F22: X | K22: X | N22: X | P22: X | T22: X | W22: =IF(COUNTA(F22:U22)=0,"— não preenchido",IF(COUNTIF(F22:J22,"X")<>1,"FALTA/DUPLA: CONDIÇÃO DO PAVIMENTO",IF(COUNTIF(K22:L22,"X")<>1,"FALTA/DUPLA: VEGETAÇÃO",IF(COUNTIF(M22:O22,"X")<>1,"FALTA/DUPLA: ELEM. DE DRENAGEM",IF(COUNTIF(P22:R22,"X")<>1,"FALTA/DUPLA: SIN. HORIZ.",IF(COUNTIF(S22:U22,"X")<>1,"FALTA/DUPLA: SIN. VERTICAL","OK")))))) -> OK
A23: 010ETO0470 | B23: C | C23: 2 | D23: 3 | E23: =D23-C23 -> 1 | F23: X | K23: X | N23: X | P23: X | T23: X | W23: =IF(COUNTA(F23:U23)=0,"— não preenchido",IF(COUNTIF(F23:J23,"X")<>1,"FALTA/DUPLA: CONDIÇÃO DO PAVIMENTO",IF(COUNTIF(K23:L23,"X")<>1,"FALTA/DUPLA: VEGETAÇÃO",IF(COUNTIF(M23:O23,"X")<>1,"FALTA/DUPLA: ELEM. DE DRENAGEM",IF(COUNTIF(P23:R23,"X")<>1,"FALTA/DUPLA: SIN. HORIZ.",IF(COUNTIF(S23:U23,"X")<>1,"FALTA/DUPLA: SIN. VERTICAL","OK")))))) -> OK
A24: 010ETO0470 | B24: C | C24: 3 | D24: 4 | E24: =D24-C24 -> 1 | F24: X | K24: X | N24: X | P24: X | T24: X | W24: =IF(COUNTA(F24:U24)=0,"— não preenchido",IF(COUNTIF(F24:J24,"X")<>1,"FALTA/DUPLA: CONDIÇÃO DO PAVIMENTO",IF(COUNTIF(K24:L24,"X")<>1,"FALTA/DUPLA: VEGETAÇÃO",IF(COUNTIF(M24:O24,"X")<>1,"FALTA/DUPLA: ELEM. DE DRENAGEM",IF(COUNTIF(P24:R24,"X")<>1,"FALTA/DUPLA: SIN. HORIZ.",IF(COUNTIF(S24:U24,"X")<>1,"FALTA/DUPLA: SIN. VERTICAL","OK")))))) -> OK
A25: 010ETO0470 | B25: C | C25: 4 | D25: 5 | E25: =D25-C25 -> 1 | F25: X | K25: X | N25: X | P25: X | T25: X | W25: =IF(COUNTA(F25:U25)=0,"— não preenchido",IF(COUNTIF(F25:J25,"X")<>1,"FALTA/DUPLA: CONDIÇÃO DO PAVIMENTO",IF(COUNTIF(K25:L25,"X")<>1,"FALTA/DUPLA: VEGETAÇÃO",IF(COUNTIF(M25:O25,"X")<>1,"FALTA/DUPLA: ELEM. DE DRENAGEM",IF(COUNTIF(P25:R25,"X")<>1,"FALTA/DUPLA: SIN. HORIZ.",IF(COUNTIF(S25:U25,"X")<>1,"FALTA/DUPLA: SIN. VERTICAL","OK")))))) -> OK
A26: 010ETO0470 | B26: C | C26: 5 | D26: 6 | E26: =D26-C26 -> 1 | F26: X | K26: X | N26: X | P26: X | T26: X | W26: =IF(COUNTA(F26:U26)=0,"— não preenchido",IF(COUNTIF(F26:J26,"X")<>1,"FALTA/DUPLA: CONDIÇÃO DO PAVIMENTO",IF(COUNTIF(K26:L26,"X")<>1,"FALTA/DUPLA: VEGETAÇÃO",IF(COUNTIF(M26:O26,"X")<>1,"FALTA/DUPLA: ELEM. DE DRENAGEM",IF(COUNTIF(P26:R26,"X")<>1,"FALTA/DUPLA: SIN. HORIZ.",IF(COUNTIF(S26:U26,"X")<>1,"FALTA/DUPLA: SIN. VERTICAL","OK")))))) -> OK
A27: 010ETO0470 | B27: C | C27: 6 | D27: 7 | E27: =D27-C27 -> 1 | F27: X | K27: X | N27: X | P27: X | T27: X | W27: =IF(COUNTA(F27:U27)=0,"— não preenchido",IF(COUNTIF(F27:J27,"X")<>1,"FALTA/DUPLA: CONDIÇÃO DO PAVIMENTO",IF(COUNTIF(K27:L27,"X")<>1,"FALTA/DUPLA: VEGETAÇÃO",IF(COUNTIF(M27:O27,"X")<>1,"FALTA/DUPLA: ELEM. DE DRENAGEM",IF(COUNTIF(P27:R27,"X")<>1,"FALTA/DUPLA: SIN. HORIZ.",IF(COUNTIF(S27:U27,"X")<>1,"FALTA/DUPLA: SIN. VERTICAL","OK")))))) -> OK
A28: 010ETO0470 | B28: C | C28: 7 | D28: 8 | E28: =D28-C28 -> 1 | F28: X | K28: X | N28: X | P28: X | T28: X | W28: =IF(COUNTA(F28:U28)=0,"— não preenchido",IF(COUNTIF(F28:J28,"X")<>1,"FALTA/DUPLA: CONDIÇÃO DO PAVIMENTO",IF(COUNTIF(K28:L28,"X")<>1,"FALTA/DUPLA: VEGETAÇÃO",IF(COUNTIF(M28:O28,"X")<>1,"FALTA/DUPLA: ELEM. DE DRENAGEM",IF(COUNTIF(P28:R28,"X")<>1,"FALTA/DUPLA: SIN. HORIZ.",IF(COUNTIF(S28:U28,"X")<>1,"FALTA/DUPLA: SIN. VERTICAL","OK")))))) -> OK
A29: 010ETO0470 | B29: C | C29: 8 | D29: 9 | E29: =D29-C29 -> 1 | F29: X | K29: X | N29: X | P29: X | T29: X | W29: =IF(COUNTA(F29:U29)=0,"— não preenchido",IF(COUNTIF(F29:J29,"X")<>1,"FALTA/DUPLA: CONDIÇÃO DO PAVIMENTO",IF(COUNTIF(K29:L29,"X")<>1,"FALTA/DUPLA: VEGETAÇÃO",IF(COUNTIF(M29:O29,"X")<>1,"FALTA/DUPLA: ELEM. DE DRENAGEM",IF(COUNTIF(P29:R29,"X")<>1,"FALTA/DUPLA: SIN. HORIZ.",IF(COUNTIF(S29:U29,"X")<>1,"FALTA/DUPLA: SIN. VERTICAL","OK")))))) -> OK
A30: 010ETO0470 | B30: C | C30: 9 | D30: 10 | E30: =D30-C30 -> 1 | F30: X | K30: X | N30: X | P30: X | T30: X | W30: =IF(COUNTA(F30:U30)=0,"— não preenchido",IF(COUNTIF(F30:J30,"X")<>1,"FALTA/DUPLA: CONDIÇÃO DO PAVIMENTO",IF(COUNTIF(K30:L30,"X")<>1,"FALTA/DUPLA: VEGETAÇÃO",IF(COUNTIF(M30:O30,"X")<>1,"FALTA/DUPLA: ELEM. DE DRENAGEM",IF(COUNTIF(P30:R30,"X")<>1,"FALTA/DUPLA: SIN. HORIZ.",IF(COUNTIF(S30:U30,"X")<>1,"FALTA/DUPLA: SIN. VERTICAL","OK")))))) -> OK
A31: 010ETO0470 | B31: C | C31: 10 | D31: 11 | E31: =D31-C31 -> 1 | F31: X | K31: X | N31: X | P31: X | T31: X | W31: =IF(COUNTA(F31:U31)=0,"— não preenchido",IF(COUNTIF(F31:J31,"X")<>1,"FALTA/DUPLA: CONDIÇÃO DO PAVIMENTO",IF(COUNTIF(K31:L31,"X")<>1,"FALTA/DUPLA: VEGETAÇÃO",IF(COUNTIF(M31:O31,"X")<>1,"FALTA/DUPLA: ELEM. DE DRENAGEM",IF(COUNTIF(P31:R31,"X")<>1,"FALTA/DUPLA: SIN. HORIZ.",IF(COUNTIF(S31:U31,"X")<>1,"FALTA/DUPLA: SIN. VERTICAL","OK")))))) -> OK
A32: 010ETO0470 | B32: C | C32: 11 | D32: 12 | E32: =D32-C32 -> 1 | F32: X | K32: X | N32: X | P32: X | T32: X | W32: =IF(COUNTA(F32:U32)=0,"— não preenchido",IF(COUNTIF(F32:J32,"X")<>1,"FALTA/DUPLA: CONDIÇÃO DO PAVIMENTO",IF(COUNTIF(K32:L32,"X")<>1,"FALTA/DUPLA: VEGETAÇÃO",IF(COUNTIF(M32:O32,"X")<>1,"FALTA/DUPLA: ELEM. DE DRENAGEM",IF(COUNTIF(P32:R32,"X")<>1,"FALTA/DUPLA: SIN. HORIZ.",IF(COUNTIF(S32:U32,"X")<>1,"FALTA/DUPLA: SIN. VERTICAL","OK")))))) -> OK
... A63: 010ETO0470 | B63: C | C63: 42 | D63: 42.716102 | E63: =D63-C63 -> 0.71610226 | F63: X | K63: X | N63: X | P63: X | T63: X | W63: =IF(COUNTA(F63:U63)=0,"— não preenchido",IF(COUNTIF(F63:J63,"X")<>1,"FALTA/DUPLA: CONDIÇÃO DO PAVIMENTO",IF(COUNTIF(K63:L63,"X")<>1,"FALTA/DUPLA: VEGETAÇÃO",IF(COUNTIF(M63:O63,"X")<>1,"FALTA/DUPLA: ELEM. DE DRENAGEM",IF(COUNTIF(P63:R63,"X")<>1,"FALTA/DUPLA: SIN. HORIZ.",IF(COUNTIF(S63:U63,"X")<>1,"FALTA/DUPLA: SIN. VERTICAL","OK")))))) -> OK
A64: S.R.E. 010ETO0480 | CENTRO DOS BORGES - SOROROCA | PPS · Estadual · 5.230 km · início: -6.500913, -48.060737
A65: 010ETO0480 | B65: C | C65: 0 | D65: 1 | E65: =D65-C65 -> 1 | F65: X | K65: X | N65: X | P65: X | T65: X | W65: =IF(COUNTA(F65:U65)=0,"— não preenchido",IF(COUNTIF(F65:J65,"X")<>1,"FALTA/DUPLA: CONDIÇÃO DO PAVIMENTO",IF(COUNTIF(K65:L65,"X")<>1,"FALTA/DUPLA: VEGETAÇÃO",IF(COUNTIF(M65:O65,"X")<>1,"FALTA/DUPLA: ELEM. DE DRENAGEM",IF(COUNTIF(P65:R65,"X")<>1,"FALTA/DUPLA: SIN. HORIZ.",IF(COUNTIF(S65:U65,"X")<>1,"FALTA/DUPLA: SIN. VERTICAL","OK")))))) -> OK
A66: 010ETO0480 | B66: C | C66: 1 | D66: 2 | E66: =D66-C66 -> 1 | F66: X | K66: X | N66: X | P66: X | T66: X | W66: =IF(COUNTA(F66:U66)=0,"— não preenchido",IF(COUNTIF(F66:J66,"X")<>1,"FALTA/DUPLA: CONDIÇÃO DO PAVIMENTO",IF(COUNTIF(K66:L66,"X")<>1,"FALTA/DUPLA: VEGETAÇÃO",IF(COUNTIF(M66:O66,"X")<>1,"FALTA/DUPLA: ELEM. DE DRENAGEM",IF(COUNTIF(P66:R66,"X")<>1,"FALTA/DUPLA: SIN. HORIZ.",IF(COUNTIF(S66:U66,"X")<>1,"FALTA/DUPLA: SIN. VERTICAL","OK")))))) -> OK
A67: 010ETO0480 | B67: C | C67: 2 | D67: 3 | E67: =D67-C67 -> 1 | F67: X | K67: X | N67: X | P67: X | T67: X | W67: =IF(COUNTA(F67:U67)=0,"— não preenchido",IF(COUNTIF(F67:J67,"X")<>1,"FALTA/DUPLA: CONDIÇÃO DO PAVIMENTO",IF(COUNTIF(K67:L67,"X")<>1,"FALTA/DUPLA: VEGETAÇÃO",IF(COUNTIF(M67:O67,"X")<>1,"FALTA/DUPLA: ELEM. DE DRENAGEM",IF(COUNTIF(P67:R67,"X")<>1,"FALTA/DUPLA: SIN. HORIZ.",IF(COUNTIF(S67:U67,"X")<>1,"FALTA/DUPLA: SIN. VERTICAL","OK")))))) -> OK
A68: 010ETO0480 | B68: C | C68: 3 | D68: 4 | E68: =D68-C68 -> 1 | F68: X | K68: X | N68: X | P68: X | T68: X | W68: =IF(COUNTA(F68:U68)=0,"— não preenchido",IF(COUNTIF(F68:J68,"X")<>1,"FALTA/DUPLA: CONDIÇÃO DO PAVIMENTO",IF(COUNTIF(K68:L68,"X")<>1,"FALTA/DUPLA: VEGETAÇÃO",IF(COUNTIF(M68:O68,"X")<>1,"FALTA/DUPLA: ELEM. DE DRENAGEM",IF(COUNTIF(P68:R68,"X")<>1,"FALTA/DUPLA: SIN. HORIZ.",IF(COUNTIF(S68:U68,"X")<>1,"FALTA/DUPLA: SIN. VERTICAL","OK")))))) -> OK
A69: 010ETO0480 | B69: C | C69: 4 | D69: 5 | E69: =D69-C69 -> 1 | F69: X | K69: X | N69: X | P69: X | T69: X | W69: =IF(COUNTA(F69:U69)=0,"— não preenchido",IF(COUNTIF(F69:J69,"X")<>1,"FALTA/DUPLA: CONDIÇÃO DO PAVIMENTO",IF(COUNTIF(K69:L69,"X")<>1,"FALTA/DUPLA: VEGETAÇÃO",IF(COUNTIF(M69:O69,"X")<>1,"FALTA/DUPLA: ELEM. DE DRENAGEM",IF(COUNTIF(P69:R69,"X")<>1,"FALTA/DUPLA: SIN. HORIZ.",IF(COUNTIF(S69:U69,"X")<>1,"FALTA/DUPLA: SIN. VERTICAL","OK")))))) -> OK
A70: 010ETO0480 | B70: C | C70: 5 | D70: 5.2299312 | E70: =D70-C70 -> 0.22993118 | F70: X | K70: X | N70: X | P70: X | T70: X | W70: =IF(COUNTA(F70:U70)=0,"— não preenchido",IF(COUNTIF(F70:J70,"X")<>1,"FALTA/DUPLA: CONDIÇÃO DO PAVIMENTO",IF(COUNTIF(K70:L70,"X")<>1,"FALTA/DUPLA: VEGETAÇÃO",IF(COUNTIF(M70:O70,"X")<>1,"FALTA/DUPLA: ELEM. DE DRENAGEM",IF(COUNTIF(P70:R70,"X")<>1,"FALTA/DUPLA: SIN. HORIZ.",IF(COUNTIF(S70:U70,"X")<>1,"FALTA/DUPLA: SIN. VERTICAL","OK")))))) -> OK
A71: S.R.E. 010ETO0490 | SOROROCA - ENTR. TO-416 | PPS · Estadual · 6.942 km · início: -6.482327, -48.092095
...

Sheet 41
A1: PROGRAMA DE MANUTENÇÃO RODOVIÁRIA — FICHA DE INSPEÇÃO — RODOVIAS PAVIMENTADAS | Y1: Valores dos gráficos — troca 0 por N/D para a fatia não aparecer. Não editar.
A2: REGIÃO: 2 — ARAGUAÍNA I | G2: MÊS / ANO: | I2: =IF('39'!I2="","",'39'!I2) -> 46235 | K2: DATA: | N2: =IF('39'!N2="","",'39'!N2) | P2: TÉCNICO: | R2: =IF('39'!R2="","",'39'!R2) -> ENG. VINICIUS RODRIGUES FERREIRA DE OLIVEIRA | Y2: =IF(F43=0,NA(),F43) -> 19.715093 | Z2: =IF(G43=0,NA(),G43) -> 1 | AA2: =IF(H43=0,NA(),H43) -> 4 | AB2: =IF(I43=0,NA(),I43) -> 1 | AC2: =IF(J43=0,NA(),J43) -> #N/A | AD2: =IF(K43=0,NA(),K43) -> 25.715093 | AE2: =IF(L43=0,NA(),L43) -> #N/A | AF2: =IF(M43=0,NA(),M43) -> 2.5646179 | ... AN2: =IF(U43=0,NA(),U43) -> #N/A
A3: TRECHO 41 — RODOVIA TO-164 - TRECHO ENTR. BR-153 (XAMBIOÁ) - ARAGUANÃ | T3: EXTENSÃO: 25,715 km · 3 S.R.E.
A4: COMO PREENCHER: uma X em UMA coluna de cada grupo, por linha. Se houver mais de um defeito no mesmo km, marque o PREDOMINANTE e escreva o resto em OBSERVAÇÕES. A quilometragem é contada de 0 até o fim de CADA S.R.E. (não é o marco da rodovia).
A6: S.R.E. | B6: SENT. | C6: INÍCIO (KM) | D6: FIM (KM) | E6: EXT. (KM) | F6: CONDIÇÃO DO PAVIMENTO | K6: VEGETAÇÃO | M6: ELEM. DE DRENAGEM | P6: SIN. HORIZ. | S6: SIN. VERTICAL | V6: OBSERVAÇÕES | W6: CONFERÊNCIA (só na tela)
F7: BOM | G7: REM. I. | H7: REM. L. | I7: BUR. I. | J7: BUR. L. | K7: ADEQ. | L7: INAD. | M7: LIMPOS | N7: SUJOS | O7: DAN. | P7: BOM | Q7: REG. | R7: INEXIST. | S7: BOM | T7: POUCAS | U7: INEXIST.
A8: S.R.E. 164ETO0095 | ENTR. BR-153 (XAMBIOÁ) - ENTR. TO-418 (XAMBIOAZINHO) | PPS · Estadual · 3.924 km · início: -6.424913, -48.536456
A9: 164ETO0095 | B9: C | C9: 0 | D9: 1 | E9: =D9-C9 -> 1 | F9: X | K9: X | N9: X | P9: X | S9: X | W9: =IF(COUNTA(F9:U9)=0,"— não preenchido",IF(COUNTIF(F9:J9,"X")<>1,"FALTA/DUPLA: CONDIÇÃO DO PAVIMENTO",IF(COUNTIF(K9:L9,"X")<>1,"FALTA/DUPLA: VEGETAÇÃO",IF(COUNTIF(M9:O9,"X")<>1,"FALTA/DUPLA: ELEM. DE DRENAGEM",IF(COUNTIF(P9:R9,"X")<>1,"FALTA/DUPLA: SIN. HORIZ.",IF(COUNTIF(S9:U9,"X")<>1,"FALTA/DUPLA: SIN. VERTICAL","OK")))))) -> OK
A10: 164ETO0095 | B10: C | C10: 1 | D10: 2 | E10: =D10-C10 -> 1 | F10: X | K10: X | N10: X | P10: X | S10: X | W10: =IF(COUNTA(F10:U10)=0,"— não preenchido",IF(COUNTIF(F10:J10,"X")<>1,"FALTA/DUPLA: CONDIÇÃO DO PAVIMENTO",IF(COUNTIF(K10:L10,"X")<>1,"FALTA/DUPLA: VEGETAÇÃO",IF(COUNTIF(M10:O10,"X")<>1,"FALTA/DUPLA: ELEM. DE DRENAGEM",IF(COUNTIF(P10:R10,"X")<>1,"FALTA/DUPLA: SIN. HORIZ.",IF(COUNTIF(S10:U10,"X")<>1,"FALTA/DUPLA: SIN. VERTICAL","OK")))))) -> OK
A11: 164ETO0095 | B11: C | C11: 2 | D11: 3 | E11: =D11-C11 -> 1 | F11: X | K11: X | N11: X | P11: X | S11: X | W11: =IF(COUNTA(F11:U11)=0,"— não preenchido",IF(COUNTIF(F11:J11,"X")<>1,"FALTA/DUPLA: CONDIÇÃO DO PAVIMENTO",IF(COUNTIF(K11:L11,"X")<>1,"FALTA/DUPLA: VEGETAÇÃO",IF(COUNTIF(M11:O11,"X")<>1,"FALTA/DUPLA: ELEM. DE DRENAGEM",IF(COUNTIF(P11:R11,"X")<>1,"FALTA/DUPLA: SIN. HORIZ.",IF(COUNTIF(S11:U11,"X")<>1,"FALTA/DUPLA: SIN. VERTICAL","OK")))))) -> OK
A12: 164ETO0095 | B12: C | C12: 3 | D12: 3.9243314 | E12: =D12-C12 -> 0.92433139 | F12: X | K12: X | N12: X | P12: X | S12: X | W12: =IF(COUNTA(F12:U12)=0,"— não preenchido",IF(COUNTIF(F12:J12,"X")<>1,"FALTA/DUPLA: CONDIÇÃO DO PAVIMENTO",IF(COUNTIF(K12:L12,"X")<>1,"FALTA/DUPLA: VEGETAÇÃO",IF(COUNTIF(M12:O12,"X")<>1,"FALTA/DUPLA: ELEM. DE DRENAGEM",IF(COUNTIF(P12:R12,"X")<>1,"FALTA/DUPLA: SIN. HORIZ.",IF(COUNTIF(S12:U12,"X")<>1,"FALTA/DUPLA: SIN. VERTICAL","OK")))))) -> OK
A13: S.R.E. 164ETO0100 | ENTR. TO-418 (XAMBIOAZINHO) - ARAGUANÃ *TRECHO URBANO* | PPS · Estadual · 19.226 km · início: -6.452376, -48.54098
A14: 164ETO0100 | B14: C | C14: 0 | D14: 1 | E14: =D14-C14 -> 1 | F14: X | K14: X | N14: X | P14: X | S14: X | W14: =IF(COUNTA(F14:U14)=0,"— não preenchido",IF(COUNTIF(F14:J14,"X")<>1,"FALTA/DUPLA: CONDIÇÃO DO PAVIMENTO",IF(COUNTIF(K14:L14,"X")<>1,"FALTA/DUPLA: VEGETAÇÃO",IF(COUNTIF(M14:O14,"X")<>1,"FALTA/DUPLA: ELEM. DE DRENAGEM",IF(COUNTIF(P14:R14,"X")<>1,"FALTA/DUPLA: SIN. HORIZ.",IF(COUNTIF(S14:U14,"X")<>1,"FALTA/DUPLA: SIN. VERTICAL","OK")))))) -> OK
A15: 164ETO0100 | B15: C | C15: 1 | D15: 2 | E15: =D15-C15 -> 1 | F15: X | K15: X | N15: X | P15: X | S15: X | W15: =IF(COUNTA(F15:U15)=0,"— não preenchido",IF(COUNTIF(F15:J15,"X")<>1,"FALTA/DUPLA: CONDIÇÃO DO PAVIMENTO",IF(COUNTIF(K15:L15,"X")<>1,"FALTA/DUPLA: VEGETAÇÃO",IF(COUNTIF(M15:O15,"X")<>1,"FALTA/DUPLA: ELEM. DE DRENAGEM",IF(COUNTIF(P15:R15,"X")<>1,"FALTA/DUPLA: SIN. HORIZ.",IF(COUNTIF(S15:U15,"X")<>1,"FALTA/DUPLA: SIN. VERTICAL","OK")))))) -> OK
A16: 164ETO0100 | B16: C | C16: 2 | D16: 3 | E16: =D16-C16 -> 1 | F16: X | K16: X | N16: X | P16: X | S16: X | W16: =IF(COUNTA(F16:U16)=0,"— não preenchido",IF(COUNTIF(F16:J16,"X")<>1,"FALTA/DUPLA: CONDIÇÃO DO PAVIMENTO",IF(COUNTIF(K16:L16,"X")<>1,"FALTA/DUPLA: VEGETAÇÃO",IF(COUNTIF(M16:O16,"X")<>1,"FALTA/DUPLA: ELEM. DE DRENAGEM",IF(COUNTIF(P16:R16,"X")<>1,"FALTA/DUPLA: SIN. HORIZ.",IF(COUNTIF(S16:U16,"X")<>1,"FALTA/DUPLA: SIN. VERTICAL","OK")))))) -> OK
A17: 164ETO0100 | B17: C | C17: 3 | D17: 4 | E17: =D17-C17 -> 1 | F17: X | K17: X | N17: X | P17: X | S17: X | W17: =IF(COUNTA(F17:U17)=0,"— não preenchido",IF(COUNTIF(F17:J17,"X")<>1,"FALTA/DUPLA: CONDIÇÃO DO PAVIMENTO",IF(COUNTIF(K17:L17,"X")<>1,"FALTA/DUPLA: VEGETAÇÃO",IF(COUNTIF(M17:O17,"X")<>1,"FALTA/DUPLA: ELEM. DE DRENAGEM",IF(COUNTIF(P17:R17,"X")<>1,"FALTA/DUPLA: SIN. HORIZ.",IF(COUNTIF(S17:U17,"X")<>1,"FALTA/DUPLA: SIN. VERTICAL","OK")))))) -> OK
A18: 164ETO0100 | B18: C | C18: 4 | D18: 5 | E18: =D18-C18 -> 1 | F18: X | K18: X | N18: X | P18: X | S18: X | W18: =IF(COUNTA(F18:U18)=0,"— não preenchido",IF(COUNTIF(F18:J18,"X")<>1,"FALTA/DUPLA: CONDIÇÃO DO PAVIMENTO",IF(COUNTIF(K18:L18,"X")<>1,"FALTA/DUPLA: VEGETAÇÃO",IF(COUNTIF(M18:O18,"X")<>1,"FALTA/DUPLA: ELEM. DE DRENAGEM",IF(COUNTIF(P18:R18,"X")<>1,"FALTA/DUPLA: SIN. HORIZ.",IF(COUNTIF(S18:U18,"X")<>1,"FALTA/DUPLA: SIN. VERTICAL","OK")))))) -> OK
A19: 164ETO0100 | B19: C | C19: 5 | D19: 6 | E19: =D19-C19 -> 1 | G19: X | K19: X | N19: X | P19: X | S19: X | W19: =IF(COUNTA(F19:U19)=0,"— não preenchido",IF(COUNTIF(F19:J19,"X")<>1,"FALTA/DUPLA: CONDIÇÃO DO PAVIMENTO",IF(COUNTIF(K19:L19,"X")<>1,"FALTA/DUPLA: VEGETAÇÃO",IF(COUNTIF(M19:O19,"X")<>1,"FALTA/DUPLA: ELEM. DE DRENAGEM",IF(COUNTIF(P19:R19,"X")<>1,"FALTA/DUPLA: SIN. HORIZ.",IF(COUNTIF(S19:U19,"X")<>1,"FALTA/DUPLA: SIN. VERTICAL","OK")))))) -> OK
A20: 164ETO0100 | B20: C | C20: 6 | D20: 7 | E20: =D20-C20 -> 1 | F20: X | K20: X | N20: X | P20: X | S20: X | W20: =IF(COUNTA(F20:U20)=0,"— não preenchido",IF(COUNTIF(F20:J20,"X")<>1,"FALTA/DUPLA: CONDIÇÃO DO PAVIMENTO",IF(COUNTIF(K20:L20,"X")<>1,"FALTA/DUPLA: VEGETAÇÃO",IF(COUNTIF(M20:O20,"X")<>1,"FALTA/DUPLA: ELEM. DE DRENAGEM",IF(COUNTIF(P20:R20,"X")<>1,"FALTA/DUPLA: SIN. HORIZ.",IF(COUNTIF(S20:U20,"X")<>1,"FALTA/DUPLA: SIN. VERTICAL","OK")))))) -> OK
A21: 164ETO0100 | B21: C | C21: 7 | D21: 8 | E21: =D21-C21 -> 1 | F21: X | K21: X | N21: X | P21: X | S21: X | W21: =IF(COUNTA(F21:U21)=0,"— não preenchido",IF(COUNTIF(F21:J21,"X")<>1,"FALTA/DUPLA: CONDIÇÃO DO PAVIMENTO",IF(COUNTIF(K21:L21,"X")<>1,"FALTA/DUPLA: VEGETAÇÃO",IF(COUNTIF(M21:O21,"X")<>1,"FALTA/DUPLA: ELEM. DE DRENAGEM",IF(COUNTIF(P21:R21,"X")<>1,"FALTA/DUPLA: SIN. HORIZ.",IF(COUNTIF(S21:U21,"X")<>1,"FALTA/DUPLA: SIN. VERTICAL","OK")))))) -> OK
A22: 164ETO0100 | B22: C | C22: 8 | D22: 9 | E22: =D22-C22 -> 1 | F22: X | K22: X | N22: X | P22: X | S22: X | W22: =IF(COUNTA(F22:U22)=0,"— não preenchido",IF(COUNTIF(F22:J22,"X")<>1,"FALTA/DUPLA: CONDIÇÃO DO PAVIMENTO",IF(COUNTIF(K22:L22,"X")<>1,"FALTA/DUPLA: VEGETAÇÃO",IF(COUNTIF(M22:O22,"X")<>1,"FALTA/DUPLA: ELEM. DE DRENAGEM",IF(COUNTIF(P22:R22,"X")<>1,"FALTA/DUPLA: SIN. HORIZ.",IF(COUNTIF(S22:U22,"X")<>1,"FALTA/DUPLA: SIN. VERTICAL","OK")))))) -> OK
A23: 164ETO0100 | B23: C | C23: 9 | D23: 10 | E23: =D23-C23 -> 1 | I23: X | K23: X | N23: X | P23: X | S23: X | W23: =IF(COUNTA(F23:U23)=0,"— não preenchido",IF(COUNTIF(F23:J23,"X")<>1,"FALTA/DUPLA: CONDIÇÃO DO PAVIMENTO",IF(COUNTIF(K23:L23,"X")<>1,"FALTA/DUPLA: VEGETAÇÃO",IF(COUNTIF(M23:O23,"X")<>1,"FALTA/DUPLA: ELEM. DE DRENAGEM",IF(COUNTIF(P23:R23,"X")<>1,"FALTA/DUPLA: SIN. HORIZ.",IF(COUNTIF(S23:U23,"X")<>1,"FALTA/DUPLA: SIN. VERTICAL","OK")))))) -> OK
A24: 164ETO0100 | B24: C | C24: 10 | D24: 11 | E24: =D24-C24 -> 1 | H24: X | K24: X | N24: X | P24: X | S24: X | W24: =IF(COUNTA(F24:U24)=0,"— não preenchido",IF(COUNTIF(F24:J24,"X")<>1,"FALTA/DUPLA: CONDIÇÃO DO PAVIMENTO",IF(COUNTIF(K24:L24,"X")<>1,"FALTA/DUPLA: VEGETAÇÃO",IF(COUNTIF(M24:O24,"X")<>1,"FALTA/DUPLA: ELEM. DE DRENAGEM",IF(COUNTIF(P24:R24,"X")<>1,"FALTA/DUPLA: SIN. HORIZ.",IF(COUNTIF(S24:U24,"X")<>1,"FALTA/DUPLA: SIN. VERTICAL","OK")))))) -> OK
A25: 164ETO0100 | B25: C | C25: 11 | D25: 12 | E25: =D25-C25 -> 1 | F25: X | K25: X | N25: X | P25: X | S25: X | W25: =IF(COUNTA(F25:U25)=0,"— não preenchido",IF(COUNTIF(F25:J25,"X")<>1,"FALTA/DUPLA: CONDIÇÃO DO PAVIMENTO",IF(COUNTIF(K25:L25,"X")<>1,"FALTA/DUPLA: VEGETAÇÃO",IF(COUNTIF(M25:O25,"X")<>1,"FALTA/DUPLA: ELEM. DE DRENAGEM",IF(COUNTIF(P25:R25,"X")<>1,"FALTA/DUPLA: SIN. HORIZ.",IF(COUNTIF(S25:U25,"X")<>1,"FALTA/DUPLA: SIN. VERTICAL","OK")))))) -> OK
A26: 164ETO0100 | B26: C | C26: 12 | D26: 13 | E26: =D26-C26 -> 1 | F26: X | K26: X | N26: X | P26: X | S26: X | W26: =IF(COUNTA(F26:U26)=0,"— não preenchido",IF(COUNTIF(F26:J26,"X")<>1,"FALTA/DUPLA: CONDIÇÃO DO PAVIMENTO",IF(COUNTIF(K26:L26,"X")<>1,"FALTA/DUPLA: VEGETAÇÃO",IF(COUNTIF(M26:O26,"X")<>1,"FALTA/DUPLA: ELEM. DE DRENAGEM",IF(COUNTIF(P26:R26,"X")<>1,"FALTA/DUPLA: SIN. HORIZ.",IF(COUNTIF(S26:U26,"X")<>1,"FALTA/DUPLA: SIN. VERTICAL","OK")))))) -> OK
A27: 164ETO0100 | B27: C | C27: 13 | D27: 14 | E27: =D27-C27 -> 1 | F27: X | K27: X | N27: X | P27: X | S27: X | W27: =IF(COUNTA(F27:U27)=0,"— não preenchido",IF(COUNTIF(F27:J27,"X")<>1,"FALTA/DUPLA: CONDIÇÃO DO PAVIMENTO",IF(COUNTIF(K27:L27,"X")<>1,"FALTA/DUPLA: VEGETAÇÃO",IF(COUNTIF(M27:O27,"X")<>1,"FALTA/DUPLA: ELEM. DE DRENAGEM",IF(COUNTIF(P27:R27,"X")<>1,"FALTA/DUPLA: SIN. HORIZ.",IF(COUNTIF(S27:U27,"X")<>1,"FALTA/DUPLA: SIN. VERTICAL","OK")))))) -> OK
A28: 164ETO0100 | B28: C | C28: 14 | D28: 15 | E28: =D28-C28 -> 1 | H28: X | K28: X | N28: X | P28: X | S28: X | W28: =IF(COUNTA(F28:U28)=0,"— não preenchido",IF(COUNTIF(F28:J28,"X")<>1,"FALTA/DUPLA: CONDIÇÃO DO PAVIMENTO",IF(COUNTIF(K28:L28,"X")<>1,"FALTA/DUPLA: VEGETAÇÃO",IF(COUNTIF(M28:O28,"X")<>1,"FALTA/DUPLA: ELEM. DE DRENAGEM",IF(COUNTIF(P28:R28,"X")<>1,"FALTA/DUPLA: SIN. HORIZ.",IF(COUNTIF(S28:U28,"X")<>1,"FALTA/DUPLA: SIN. VERTICAL","OK")))))) -> OK
A29: 164ETO0100 | B29: C | C29: 15 | D29: 16 | E29: =D29-C29 -> 1 | H29: X | K29: X | N29: X | P29: X | S29: X | W29: =IF(COUNTA(F29:U29)=0,"— não preenchido",IF(COUNTIF(F29:J29,"X")<>1,"FALTA/DUPLA: CONDIÇÃO DO PAVIMENTO",IF(COUNTIF(K29:L29,"X")<>1,"FALTA/DUPLA: VEGETAÇÃO",IF(COUNTIF(M29:O29,"X")<>1,"FALTA/DUPLA: ELEM. DE DRENAGEM",IF(COUNTIF(P29:R29,"X")<>1,"FALTA/DUPLA: SIN. HORIZ.",IF(COUNTIF(S29:U29,"X")<>1,"FALTA/DUPLA: SIN. VERTICAL","OK")))))) -> OK
A30: 164ETO0100 | B30: C | C30: 16 | D30: 17 | E30: =D30-C30 -> 1 | H30: X | K30: X | N30: X | P30: X | S30: X | W30: =IF(COUNTA(F30:U30)=0,"— não preenchido",IF(COUNTIF(F30:J30,"X")<>1,"FALTA/DUPLA: CONDIÇÃO DO PAVIMENTO",IF(COUNTIF(K30:L30,"X")<>1,"FALTA/DUPLA: VEGETAÇÃO",IF(COUNTIF(M30:O30,"X")<>1,"FALTA/DUPLA: ELEM. DE DRENAGEM",IF(COUNTIF(P30:R30,"X")<>1,"FALTA/DUPLA: SIN. HORIZ.",IF(COUNTIF(S30:U30,"X")<>1,"FALTA/DUPLA: SIN. VERTICAL","OK")))))) -> OK
A31: 164ETO0100 | B31: C | C31: 17 | D31: 18 | E31: =D31-C31 -> 1 | F31: X | K31: X | N31: X | P31: X | S31: X | W31: =IF(COUNTA(F31:U31)=0,"— não preenchido",IF(COUNTIF(F31:J31,"X")<>1,"FALTA/DUPLA: CONDIÇÃO DO PAVIMENTO",IF(COUNTIF(K31:L31,"X")<>1,"FALTA/DUPLA: VEGETAÇÃO",IF(COUNTIF(M31:O31,"X")<>1,"FALTA/DUPLA: ELEM. DE DRENAGEM",IF(COUNTIF(P31:R31,"X")<>1,"FALTA/DUPLA: SIN. HORIZ.",IF(COUNTIF(S31:U31,"X")<>1,"FALTA/DUPLA: SIN. VERTICAL","OK")))))) -> OK
A32: 164ETO0100 | B32: C | C32: 18 | D32: 19 | E32: =D32-C32 -> 1 | F32: X | K32: X | N32: X | P32: X | S32: X | W32: =IF(COUNTA(F32:U32)=0,"— não preenchido",IF(COUNTIF(F32:J32,"X")<>1,"FALTA/DUPLA: CONDIÇÃO DO PAVIMENTO",IF(COUNTIF(K32:L32,"X")<>1,"FALTA/DUPLA: VEGETAÇÃO",IF(COUNTIF(M32:O32,"X")<>1,"FALTA/DUPLA: ELEM. DE DRENAGEM",IF(COUNTIF(P32:R32,"X")<>1,"FALTA/DUPLA: SIN. HORIZ.",IF(COUNTIF(S32:U32,"X")<>1,"FALTA/DUPLA: SIN. VERTICAL","OK")))))) -> OK
A33: 164ETO0100 | B33: C | C33: 19 | D33: 19.226144 | E33: =D33-C33 -> 0.22614371 | F33: X | K33: X | N33: X | P33: X | S33: X | W33: =IF(COUNTA(F33:U33)=0,"— não preenchido",IF(COUNTIF(F33:J33,"X")<>1,"FALTA/DUPLA: CONDIÇÃO DO PAVIMENTO",IF(COUNTIF(K33:L33,"X")<>1,"FALTA/DUPLA: VEGETAÇÃO",IF(COUNTIF(M33:O33,"X")<>1,"FALTA/DUPLA: ELEM. DE DRENAGEM",IF(COUNTIF(P33:R33,"X")<>1,"FALTA/DUPLA: SIN. HORIZ.",IF(COUNTIF(S33:U33,"X")<>1,"FALTA/DUPLA: SIN. VERTICAL","OK")))))) -> OK
A34: S.R.E. 164ETO0101 | ARAGUANÃ *TRECHO URBANO* | PSU · Municipal · 2.565 km · início: -6.570846, -48.639225
A35: 164ETO0101 | B35: C | C35: 0 | D35: 1 | E35: =D35-C35 -> 1 | F35: X | K35: X | M35: X | P35: X | S35: X | W35: =IF(COUNTA(F35:U35)=0,"— não preenchido",IF(COUNTIF(F35:J35,"X")<>1,"FALTA/DUPLA: CONDIÇÃO DO PAVIMENTO",IF(COUNTIF(K35:L35,"X")<>1,"FALTA/DUPLA: VEGETAÇÃO",IF(COUNTIF(M35:O35,"X")<>1,"FALTA/DUPLA: ELEM. DE DRENAGEM",IF(COUNTIF(P35:R35,"X")<>1,"FALTA/DUPLA: SIN. HORIZ.",IF(COUNTIF(S35:U35,"X")<>1,"FALTA/DUPLA: SIN. VERTICAL","OK")))))) -> OK
A36: 164ETO0101 | B36: C | C36: 1 | D36: 2 | E36: =D36-C36 -> 1 | F36: X | K36: X | M36: X | P36: X | S36: X | W36: =IF(COUNTA(F36:U36)=0,"— não preenchido",IF(COUNTIF(F36:J36,"X")<>1,"FALTA/DUPLA: CONDIÇÃO DO PAVIMENTO",IF(COUNTIF(K36:L36,"X")<>1,"FALTA/DUPLA: VEGETAÇÃO",IF(COUNTIF(M36:O36,"X")<>1,"FALTA/DUPLA: ELEM. DE DRENAGEM",IF(COUNTIF(P36:R36,"X")<>1,"FALTA/DUPLA: SIN. HORIZ.",IF(COUNTIF(S36:U36,"X")<>1,"FALTA/DUPLA: SIN. VERTICAL","OK")))))) -> OK
A37: 164ETO0101 | B37: C | C37: 2 | D37: 2.5646179 | E37: =D37-C37 -> 0.56461789 | F37: X | K37: X | M37: X | P37: X | S37: X | W37: =IF(COUNTA(F37:U37)=0,"— não preenchido",IF(COUNTIF(F37:J37,"X")<>1,"FALTA/DUPLA: CONDIÇÃO DO PAVIMENTO",IF(COUNTIF(K37:L37,"X")<>1,"FALTA/DUPLA: VEGETAÇÃO",IF(COUNTIF(M37:O37,"X")<>1,"FALTA/DUPLA: ELEM. DE DRENAGEM",IF(COUNTIF(P37:R37,"X")<>1,"FALTA/DUPLA: SIN. HORIZ.",IF(COUNTIF(S37:U37,"X")<>1,"FALTA/DUPLA: SIN. VERTICAL","OK")))))) -> OK
A39: ____________________________________________ | G39: ____________________________________________
A40: TÉCNICO RESPONSÁVEL PELA INSPEÇÃO | G40: VISTO DA SUPERVISÃO
A42: RESUMO DO TRECHO — KM LANÇADO POR ITEM
A43: KM LANÇADO | F43: =SUMIF(F$9:F$37,"X",$E$9:$E$37) -> 19.715093 | G43: =SUMIF(G$9:G$37,"X",$E$9:$E$37) -> 1 | H43: =SUMIF(H$9:H$37,"X",$E$9:$E$37) -> 4 | I43: =SUMIF(I$9:I$37,"X",$E$9:$E$37) -> 1 | J43: =SUMIF(J$9:J$37,"X",$E$9:$E$37) -> 0 | K43: =SUMIF(K$9:K$37,"X",$E$9:$E$37) -> 25.715093 | L43: =SUMIF(L$9:L$37,"X",$E$9:$E$37) -> 0 | M43: =SUMIF(M$9:M$37,"X",$E$9:$E$37) -> 2.5646179 | ... U43: =SUMIF(U$9:U$37,"X",$E$9:$E$37) -> 0
...

Sheet 42
A1: PROGRAMA DE MANUTENÇÃO RODOVIÁRIA — FICHA DE INSPEÇÃO — RODOVIAS PAVIMENTADAS | Y1: Valores dos gráficos — troca 0 por N/D para a fatia não aparecer. Não editar.
A2: REGIÃO: 2 — ARAGUAÍNA I | G2: MÊS / ANO: | I2: =IF('39'!I2="","",'39'!I2) -> 46235 | K2: DATA: | N2: =IF('39'!N2="","",'39'!N2) | P2: TÉCNICO: | R2: =IF('39'!R2="","",'39'!R2) -> ENG. VINICIUS RODRIGUES FERREIRA DE OLIVEIRA | Y2: =IF(F30=0,NA(),F30) -> 4.8300059 | Z2: =IF(G30=0,NA(),G30) -> #N/A | AA2: =IF(H30=0,NA(),H30) -> #N/A | AB2: =IF(I30=0,NA(),I30) -> 1 | AC2: =IF(J30=0,NA(),J30) -> 7.6206039 | AD2: =IF(K30=0,NA(),K30) -> 13.45061 | AE2: =IF(L30=0,NA(),L30) -> #N/A | AF2: =IF(M30=0,NA(),M30) -> #N/A | ... AN2: =IF(U30=0,NA(),U30) -> 13.45061
A3: TRECHO 42 — RODOVIA TO-164 - TRECHO FÁBRICA DE CIMENTO - XAMBIOÁ - ENTR. BR-153 | T3: EXTENSÃO: 13,451 km · 3 S.R.E.
A4: COMO PREENCHER: uma X em UMA coluna de cada grupo, por linha. Se houver mais de um defeito no mesmo km, marque o PREDOMINANTE e escreva o resto em OBSERVAÇÕES. A quilometragem é contada de 0 até o fim de CADA S.R.E. (não é o marco da rodovia).
A6: S.R.E. | B6: SENT. | C6: INÍCIO (KM) | D6: FIM (KM) | E6: EXT. (KM) | F6: CONDIÇÃO DO PAVIMENTO | K6: VEGETAÇÃO | M6: ELEM. DE DRENAGEM | P6: SIN. HORIZ. | S6: SIN. VERTICAL | V6: OBSERVAÇÕES | W6: CONFERÊNCIA (só na tela)
F7: BOM | G7: REM. I. | H7: REM. L. | I7: BUR. I. | J7: BUR. L. | K7: ADEQ. | L7: INAD. | M7: LIMPOS | N7: SUJOS | O7: DAN. | P7: BOM | Q7: REG. | R7: INEXIST. | S7: BOM | T7: POUCAS | U7: INEXIST.
A8: S.R.E. 164ETO0070 | FABRICA DE CIMENTO - POV. CHAPADA | PPS · Estadual · 3.924 km · início: -6.428219, -48.429519
A9: 164ETO0070 | B9: C | C9: 0 | D9: 1 | E9: =D9-C9 -> 1 | F9: X | K9: X | N9: X | R9: X | U9: X | W9: =IF(COUNTA(F9:U9)=0,"— não preenchido",IF(COUNTIF(F9:J9,"X")<>1,"FALTA/DUPLA: CONDIÇÃO DO PAVIMENTO",IF(COUNTIF(K9:L9,"X")<>1,"FALTA/DUPLA: VEGETAÇÃO",IF(COUNTIF(M9:O9,"X")<>1,"FALTA/DUPLA: ELEM. DE DRENAGEM",IF(COUNTIF(P9:R9,"X")<>1,"FALTA/DUPLA: SIN. HORIZ.",IF(COUNTIF(S9:U9,"X")<>1,"FALTA/DUPLA: SIN. VERTICAL","OK")))))) -> OK
A10: 164ETO0070 | B10: C | C10: 1 | D10: 2 | E10: =D10-C10 -> 1 | F10: X | K10: X | N10: X | R10: X | U10: X | W10: =IF(COUNTA(F10:U10)=0,"— não preenchido",IF(COUNTIF(F10:J10,"X")<>1,"FALTA/DUPLA: CONDIÇÃO DO PAVIMENTO",IF(COUNTIF(K10:L10,"X")<>1,"FALTA/DUPLA: VEGETAÇÃO",IF(COUNTIF(M10:O10,"X")<>1,"FALTA/DUPLA: ELEM. DE DRENAGEM",IF(COUNTIF(P10:R10,"X")<>1,"FALTA/DUPLA: SIN. HORIZ.",IF(COUNTIF(S10:U10,"X")<>1,"FALTA/DUPLA: SIN. VERTICAL","OK")))))) -> OK
A11: 164ETO0070 | B11: C | C11: 2 | D11: 3 | E11: =D11-C11 -> 1 | I11: X | K11: X | N11: X | R11: X | U11: X | W11: =IF(COUNTA(F11:U11)=0,"— não preenchido",IF(COUNTIF(F11:J11,"X")<>1,"FALTA/DUPLA: CONDIÇÃO DO PAVIMENTO",IF(COUNTIF(K11:L11,"X")<>1,"FALTA/DUPLA: VEGETAÇÃO",IF(COUNTIF(M11:O11,"X")<>1,"FALTA/DUPLA: ELEM. DE DRENAGEM",IF(COUNTIF(P11:R11,"X")<>1,"FALTA/DUPLA: SIN. HORIZ.",IF(COUNTIF(S11:U11,"X")<>1,"FALTA/DUPLA: SIN. VERTICAL","OK")))))) -> OK
A12: 164ETO0070 | B12: C | C12: 3 | D12: 3.9243329 | E12: =D12-C12 -> 0.92433294 | F12: X | K12: X | N12: X | R12: X | U12: X | W12: =IF(COUNTA(F12:U12)=0,"— não preenchido",IF(COUNTIF(F12:J12,"X")<>1,"FALTA/DUPLA: CONDIÇÃO DO PAVIMENTO",IF(COUNTIF(K12:L12,"X")<>1,"FALTA/DUPLA: VEGETAÇÃO",IF(COUNTIF(M12:O12,"X")<>1,"FALTA/DUPLA: ELEM. DE DRENAGEM",IF(COUNTIF(P12:R12,"X")<>1,"FALTA/DUPLA: SIN. HORIZ.",IF(COUNTIF(S12:U12,"X")<>1,"FALTA/DUPLA: SIN. VERTICAL","OK")))))) -> OK
A13: S.R.E. 164ETO0080 | POV. CHAPADA - POV. MANCHAO DO MEIO | PPS · Estadual · 5.906 km · início: -6.416308, -48.453859
A14: 164ETO0080 | B14: C | C14: 0 | D14: 1 | E14: =D14-C14 -> 1 | J14: X | K14: X | N14: X | R14: X | U14: X | W14: =IF(COUNTA(F14:U14)=0,"— não preenchido",IF(COUNTIF(F14:J14,"X")<>1,"FALTA/DUPLA: CONDIÇÃO DO PAVIMENTO",IF(COUNTIF(K14:L14,"X")<>1,"FALTA/DUPLA: VEGETAÇÃO",IF(COUNTIF(M14:O14,"X")<>1,"FALTA/DUPLA: ELEM. DE DRENAGEM",IF(COUNTIF(P14:R14,"X")<>1,"FALTA/DUPLA: SIN. HORIZ.",IF(COUNTIF(S14:U14,"X")<>1,"FALTA/DUPLA: SIN. VERTICAL","OK")))))) -> OK
A15: 164ETO0080 | B15: C | C15: 1 | D15: 2 | E15: =D15-C15 -> 1 | J15: X | K15: X | N15: X | R15: X | U15: X | W15: =IF(COUNTA(F15:U15)=0,"— não preenchido",IF(COUNTIF(F15:J15,"X")<>1,"FALTA/DUPLA: CONDIÇÃO DO PAVIMENTO",IF(COUNTIF(K15:L15,"X")<>1,"FALTA/DUPLA: VEGETAÇÃO",IF(COUNTIF(M15:O15,"X")<>1,"FALTA/DUPLA: ELEM. DE DRENAGEM",IF(COUNTIF(P15:R15,"X")<>1,"FALTA/DUPLA: SIN. HORIZ.",IF(COUNTIF(S15:U15,"X")<>1,"FALTA/DUPLA: SIN. VERTICAL","OK")))))) -> OK
A16: 164ETO0080 | B16: C | C16: 2 | D16: 3 | E16: =D16-C16 -> 1 | J16: X | K16: X | N16: X | R16: X | U16: X | W16: =IF(COUNTA(F16:U16)=0,"— não preenchido",IF(COUNTIF(F16:J16,"X")<>1,"FALTA/DUPLA: CONDIÇÃO DO PAVIMENTO",IF(COUNTIF(K16:L16,"X")<>1,"FALTA/DUPLA: VEGETAÇÃO",IF(COUNTIF(M16:O16,"X")<>1,"FALTA/DUPLA: ELEM. DE DRENAGEM",IF(COUNTIF(P16:R16,"X")<>1,"FALTA/DUPLA: SIN. HORIZ.",IF(COUNTIF(S16:U16,"X")<>1,"FALTA/DUPLA: SIN. VERTICAL","OK")))))) -> OK
A17: 164ETO0080 | B17: C | C17: 3 | D17: 4 | E17: =D17-C17 -> 1 | F17: X | K17: X | N17: X | R17: X | U17: X | W17: =IF(COUNTA(F17:U17)=0,"— não preenchido",IF(COUNTIF(F17:J17,"X")<>1,"FALTA/DUPLA: CONDIÇÃO DO PAVIMENTO",IF(COUNTIF(K17:L17,"X")<>1,"FALTA/DUPLA: VEGETAÇÃO",IF(COUNTIF(M17:O17,"X")<>1,"FALTA/DUPLA: ELEM. DE DRENAGEM",IF(COUNTIF(P17:R17,"X")<>1,"FALTA/DUPLA: SIN. HORIZ.",IF(COUNTIF(S17:U17,"X")<>1,"FALTA/DUPLA: SIN. VERTICAL","OK")))))) -> OK
A18: 164ETO0080 | B18: C | C18: 4 | D18: 5 | E18: =D18-C18 -> 1 | J18: X | K18: X | N18: X | R18: X | U18: X | W18: =IF(COUNTA(F18:U18)=0,"— não preenchido",IF(COUNTIF(F18:J18,"X")<>1,"FALTA/DUPLA: CONDIÇÃO DO PAVIMENTO",IF(COUNTIF(K18:L18,"X")<>1,"FALTA/DUPLA: VEGETAÇÃO",IF(COUNTIF(M18:O18,"X")<>1,"FALTA/DUPLA: ELEM. DE DRENAGEM",IF(COUNTIF(P18:R18,"X")<>1,"FALTA/DUPLA: SIN. HORIZ.",IF(COUNTIF(S18:U18,"X")<>1,"FALTA/DUPLA: SIN. VERTICAL","OK")))))) -> OK
A19: 164ETO0080 | B19: C | C19: 5 | D19: 5.905673 | E19: =D19-C19 -> 0.90567297 | F19: X | K19: X | N19: X | R19: X | U19: X | W19: =IF(COUNTA(F19:U19)=0,"— não preenchido",IF(COUNTIF(F19:J19,"X")<>1,"FALTA/DUPLA: CONDIÇÃO DO PAVIMENTO",IF(COUNTIF(K19:L19,"X")<>1,"FALTA/DUPLA: VEGETAÇÃO",IF(COUNTIF(M19:O19,"X")<>1,"FALTA/DUPLA: ELEM. DE DRENAGEM",IF(COUNTIF(P19:R19,"X")<>1,"FALTA/DUPLA: SIN. HORIZ.",IF(COUNTIF(S19:U19,"X")<>1,"FALTA/DUPLA: SIN. VERTICAL","OK")))))) -> OK
A20: S.R.E. 164ETO0090 | POV. MANCHAO DO MEIO - ENTR. BR-153 (XAMBIOÁ) | PPS · Estadual · 3.621 km · início: -6.410774, -48.505065
A21: 164ETO0090 | B21: C | C21: 0 | D21: 1 | E21: =D21-C21 -> 1 | J21: X | K21: X | N21: X | R21: X | U21: X | W21: =IF(COUNTA(F21:U21)=0,"— não preenchido",IF(COUNTIF(F21:J21,"X")<>1,"FALTA/DUPLA: CONDIÇÃO DO PAVIMENTO",IF(COUNTIF(K21:L21,"X")<>1,"FALTA/DUPLA: VEGETAÇÃO",IF(COUNTIF(M21:O21,"X")<>1,"FALTA/DUPLA: ELEM. DE DRENAGEM",IF(COUNTIF(P21:R21,"X")<>1,"FALTA/DUPLA: SIN. HORIZ.",IF(COUNTIF(S21:U21,"X")<>1,"FALTA/DUPLA: SIN. VERTICAL","OK")))))) -> OK
A22: 164ETO0090 | B22: C | C22: 1 | D22: 2 | E22: =D22-C22 -> 1 | J22: X | K22: X | N22: X | R22: X | U22: X | W22: =IF(COUNTA(F22:U22)=0,"— não preenchido",IF(COUNTIF(F22:J22,"X")<>1,"FALTA/DUPLA: CONDIÇÃO DO PAVIMENTO",IF(COUNTIF(K22:L22,"X")<>1,"FALTA/DUPLA: VEGETAÇÃO",IF(COUNTIF(M22:O22,"X")<>1,"FALTA/DUPLA: ELEM. DE DRENAGEM",IF(COUNTIF(P22:R22,"X")<>1,"FALTA/DUPLA: SIN. HORIZ.",IF(COUNTIF(S22:U22,"X")<>1,"FALTA/DUPLA: SIN. VERTICAL","OK")))))) -> OK
A23: 164ETO0090 | B23: C | C23: 2 | D23: 3 | E23: =D23-C23 -> 1 | J23: X | K23: X | N23: X | R23: X | U23: X | W23: =IF(COUNTA(F23:U23)=0,"— não preenchido",IF(COUNTIF(F23:J23,"X")<>1,"FALTA/DUPLA: CONDIÇÃO DO PAVIMENTO",IF(COUNTIF(K23:L23,"X")<>1,"FALTA/DUPLA: VEGETAÇÃO",IF(COUNTIF(M23:O23,"X")<>1,"FALTA/DUPLA: ELEM. DE DRENAGEM",IF(COUNTIF(P23:R23,"X")<>1,"FALTA/DUPLA: SIN. HORIZ.",IF(COUNTIF(S23:U23,"X")<>1,"FALTA/DUPLA: SIN. VERTICAL","OK")))))) -> OK
A24: 164ETO0090 | B24: C | C24: 3 | D24: 3.6206039 | E24: =D24-C24 -> 0.62060395 | J24: X | K24: X | N24: X | R24: X | U24: X | W24: =IF(COUNTA(F24:U24)=0,"— não preenchido",IF(COUNTIF(F24:J24,"X")<>1,"FALTA/DUPLA: CONDIÇÃO DO PAVIMENTO",IF(COUNTIF(K24:L24,"X")<>1,"FALTA/DUPLA: VEGETAÇÃO",IF(COUNTIF(M24:O24,"X")<>1,"FALTA/DUPLA: ELEM. DE DRENAGEM",IF(COUNTIF(P24:R24,"X")<>1,"FALTA/DUPLA: SIN. HORIZ.",IF(COUNTIF(S24:U24,"X")<>1,"FALTA/DUPLA: SIN. VERTICAL","OK")))))) -> OK
A26: ____________________________________________ | G26: ____________________________________________
A27: TÉCNICO RESPONSÁVEL PELA INSPEÇÃO | G27: VISTO DA SUPERVISÃO
A29: RESUMO DO TRECHO — KM LANÇADO POR ITEM
