Workbook

Sheet RESUMO
A1: RESUMO CONSOLIDADO — REGIÃO 1 — RODOVIAS PAVIMENTADAS | V1: Valores dos gráficos — troca 0 por N/D para a fatia não aparecer. Não editar.
A2: Todos os números vêm das abas dos trechos por referência direta. Não digite nada aqui. A coluna CONFERÊNCIA acusa qualquer trecho em que a soma das marcações não fecha com a extensão. | V2: =IF(D15=0,NA(),D15) -> 339.16628 | W2: =IF(E15=0,NA(),E15) -> 27.811508 | X2: =IF(F15=0,NA(),F15) -> 14.960766 | Y2: =IF(G15=0,NA(),G15) -> 35.147414 | Z2: =IF(H15=0,NA(),H15) -> 5.0115949 | AA2: =IF(I15=0,NA(),I15) -> 307.66766 | AB2: =IF(J15=0,NA(),J15) -> 114.42989 | AC2: =IF(K15=0,NA(),K15) -> 22.553916 | ... AK2: =IF(S15=0,NA(),S15) -> 52.476463
A4: Nº TRECHO | B4: TRECHO | C4: EXTENSÃO (KM) | D4: CONDIÇÃO DO PAVIMENTO | I4: VEGETAÇÃO | K4: ELEM. DE DRENAGEM | N4: SIN. HORIZ. | Q4: SIN. VERTICAL | T4: CONFERÊNCIA
D5: BOM | E5: REM. I. | F5: REM. L. | G5: BUR. I. | H5: BUR. L. | I5: ADEQ. | J5: INAD. | K5: LIMPOS | L5: SUJOS | M5: DAN. | N5: BOM | O5: REG. | P5: INEXIST. | Q5: BOM | R5: POUCAS | S5: INEXIST.
A6: 68 | B6: RODOVIA TO-010 - TRECHO PALMEIRANTE - ENTR. TO-222 (POVOADO BIELÂNDIA) | C6: ='68'!R95 -> 72.431781 | D6: ='68'!F92 -> 53.284367 | E6: ='68'!G92 -> 0 | F6: ='68'!H92 -> 0 | G6: ='68'!I92 -> 19.147414 | H6: ='68'!J92 -> 0 | I6: ='68'!K92 -> 72.431781 | J6: ='68'!L92 -> 0 | K6: ='68'!M92 -> 0 | ... S6: ='68'!U92 -> 0 | T6: =IF(SUM(D6:H6)=0,"— não preenchido",IF(ROUND(SUM(D6:H6)-C6,3)=0,"OK","ERRO — dif. de "&ROUND(SUM(D6:H6)-C6,3)&" km")) -> OK
A7: 70 | B7: RODOVIA TO-010 - TRECHO BABAÇULÂNDIA - WANDERLÂNDIA | C7: ='70'!R72 -> 54.5733 | D7: ='70'!F69 -> 50.5733 | E7: ='70'!G69 -> 0 | F7: ='70'!H69 -> 0 | G7: ='70'!I69 -> 3 | H7: ='70'!J69 -> 1 | I7: ='70'!K69 -> 54.5733 | J7: ='70'!L69 -> 0 | K7: ='70'!M69 -> 0 | ... S7: ='70'!U69 -> 0 | T7: =IF(SUM(D7:H7)=0,"— não preenchido",IF(ROUND(SUM(D7:H7)-C7,3)=0,"OK","ERRO — dif. de "&ROUND(SUM(D7:H7)-C7,3)&" km")) -> OK
A8: 71 | B8: RODOVIA TO-020 - TRECHO RECURSOLÂNDIA - CAMPOS LINDOS | C8: ='71'!R25 -> 5.606921 | D8: ='71'!F22 -> 5.606921 | E8: ='71'!G22 -> 0 | F8: ='71'!H22 -> 0 | G8: ='71'!I22 -> 0 | H8: ='71'!J22 -> 0 | I8: ='71'!K22 -> 0 | J8: ='71'!L22 -> 5.606921 | K8: ='71'!M22 -> 2.708768 | ... S8: ='71'!U22 -> 2.898153 | T8: =IF(SUM(D8:H8)=0,"— não preenchido",IF(ROUND(SUM(D8:H8)-C8,3)=0,"OK","ERRO — dif. de "&ROUND(SUM(D8:H8)-C8,3)&" km")) -> OK
A9: 73 | B9: RODOVIA TO-130 - TRECHO ENTR. TO-010 - TRECHO BARRA DO OURO - ENTR. BR-010 (POVOADO MORRO GRANDE) | C9: ='73'!R70 -> 48.963584 | D9: ='73'!F67 -> 34.951989 | E9: ='73'!G67 -> 0 | F9: ='73'!H67 -> 0 | G9: ='73'!I67 -> 10 | H9: ='73'!J67 -> 4.0115949 | I9: ='73'!K67 -> 48.963584 | J9: ='73'!L67 -> 0 | K9: ='73'!M67 -> 10 | ... S9: ='73'!U67 -> 0 | T9: =IF(SUM(D9:H9)=0,"— não preenchido",IF(ROUND(SUM(D9:H9)-C9,3)=0,"OK","ERRO — dif. de "&ROUND(SUM(D9:H9)-C9,3)&" km")) -> OK
A10: 74 | B10: RODOVIA TO-222 - TRECHO ARAGUAÍNA - FILADÉLFIA | C10: ='74'!R128 -> 101.04536 | D10: ='74'!F125 -> 93.384097 | E10: ='74'!G125 -> 2 | F10: ='74'!H125 -> 2.6612658 | G10: ='74'!I125 -> 3 | H10: ='74'!J125 -> 0 | I10: ='74'!K125 -> 0 | J10: ='74'!L125 -> 101.04536 | K10: ='74'!M125 -> 0 | ... S10: ='74'!U125 -> 0 | T10: =IF(SUM(D10:H10)=0,"— não preenchido",IF(ROUND(SUM(D10:H10)-C10,3)=0,"OK","ERRO — dif. de "&ROUND(SUM(D10:H10)-C10,3)&" km")) -> OK
A11: 75 | B11: RODOVIA TO-226 - TRECHO NOVA OLINDA - ENTR. TO-010 | C11: ='75'!R20 -> 2.154377 | D11: ='75'!F17 -> 0 | E11: ='75'!G17 -> 2.154377 | F11: ='75'!H17 -> 0 | G11: ='75'!I17 -> 0 | H11: ='75'!J17 -> 0 | I11: ='75'!K17 -> 2.154377 | J11: ='75'!L17 -> 0 | K11: ='75'!M17 -> 2.154377 | ... S11: ='75'!U17 -> 1.154377 | T11: =IF(SUM(D11:H11)=0,"— não preenchido",IF(ROUND(SUM(D11:H11)-C11,3)=0,"OK","ERRO — dif. de "&ROUND(SUM(D11:H11)-C11,3)&" km")) -> OK
A12: 77 | B12: RODOVIA TO-226 - TRECHO GOIATINS - CAMPOS LINDOS - DIV TO-MA | C12: ='77'!R119 -> 92.048164 | D12: ='77'!F116 -> 72.748665 | E12: ='77'!G116 -> 7 | F12: ='77'!H116 -> 12.2995 | G12: ='77'!I116 -> 0 | H12: ='77'!J116 -> 0 | I12: ='77'!K116 -> 92.048164 | J12: ='77'!L116 -> 0 | K12: ='77'!M116 -> 7.6907709 | ... S12: ='77'!U116 -> 48.423933 | T12: =IF(SUM(D12:H12)=0,"— não preenchido",IF(ROUND(SUM(D12:H12)-C12,3)=0,"OK","ERRO — dif. de "&ROUND(SUM(D12:H12)-C12,3)&" km")) -> OK
A13: 78 | B13: RODOVIA TO-422 - TRECHO ENTR. BR-153 - TRECHO DISTRITO AGROINDUSTRIAL DE ARAGUAÍNA | C13: ='78'!R25 -> 7.7776106 | D13: ='78'!F22 -> 7.7776106 | E13: ='78'!G22 -> 0 | F13: ='78'!H22 -> 0 | G13: ='78'!I22 -> 0 | H13: ='78'!J22 -> 0 | I13: ='78'!K22 -> 0 | J13: ='78'!L22 -> 7.7776106 | K13: ='78'!M22 -> 0 | ... S13: ='78'!U22 -> 0 | T13: =IF(SUM(D13:H13)=0,"— não preenchido",IF(ROUND(SUM(D13:H13)-C13,3)=0,"OK","ERRO — dif. de "&ROUND(SUM(D13:H13)-C13,3)&" km")) -> OK
A14: 80 | B14: RODOVIA TO-424 - TRECHO ENTR. TO-222 (PLAT. MULTI-MODAL) - BABAÇULÂNDIA | C14: ='80'!R58 -> 37.496458 | D14: ='80'!F55 -> 20.839327 | E14: ='80'!G55 -> 16.657131 | F14: ='80'!H55 -> 0 | G14: ='80'!I55 -> 0 | H14: ='80'!J55 -> 0 | I14: ='80'!K55 -> 37.496458 | J14: ='80'!L55 -> 0 | K14: ='80'!M55 -> 0 | ... S14: ='80'!U55 -> 0 | T14: =IF(SUM(D14:H14)=0,"— não preenchido",IF(ROUND(SUM(D14:H14)-C14,3)=0,"OK","ERRO — dif. de "&ROUND(SUM(D14:H14)-C14,3)&" km")) -> OK
B15: TOTAL PERCORRIDO NO MÊS | C15: =SUM(C6:C14) -> 422.09756 | D15: =SUM(D6:D14) -> 339.16628 | E15: =SUM(E6:E14) -> 27.811508 | F15: =SUM(F6:F14) -> 14.960766 | G15: =SUM(G6:G14) -> 35.147414 | H15: =SUM(H6:H14) -> 5.0115949 | I15: =SUM(I6:I14) -> 307.66766 | J15: =SUM(J6:J14) -> 114.42989 | ... S15: =SUM(S6:S14) -> 52.476463
B16: % DA EXTENSÃO DA MALHA (422.10 km) | D16: =SUM(D15:H15)/422.1 -> 0.99999422 | I16: (soma do grupo 'CONDIÇÃO DO PAVIMENTO' dividida pela malha)

Sheet 68
A1: PROGRAMA DE MANUTENÇÃO RODOVIÁRIA — FICHA DE INSPEÇÃO — RODOVIAS PAVIMENTADAS | Y1: Valores dos gráficos — troca 0 por N/D para a fatia não aparecer. Não editar.
A2: REGIÃO: 3 — ARAGUAÍNA II | G2: MÊS / ANO: | I2: 46235 | K2: DATA: | P2: TÉCNICO: | R2: ENG. VINICIUS RODRIGUES FERREIRA DE OLIVEIRA | Y2: =IF(F92=0,NA(),F92) -> 53.284367 | Z2: =IF(G92=0,NA(),G92) -> #N/A | AA2: =IF(H92=0,NA(),H92) -> #N/A | AB2: =IF(I92=0,NA(),I92) -> 19.147414 | AC2: =IF(J92=0,NA(),J92) -> #N/A | AD2: =IF(K92=0,NA(),K92) -> 72.431781 | AE2: =IF(L92=0,NA(),L92) -> #N/A | AF2: =IF(M92=0,NA(),M92) -> #N/A | ... AN2: =IF(U92=0,NA(),U92) -> #N/A
A3: TRECHO 68 — RODOVIA TO-010 - TRECHO PALMEIRANTE - ENTR. TO-222 (POVOADO BIELÂNDIA) | T3: EXTENSÃO: 72,432 km · 5 S.R.E.
A4: COMO PREENCHER: uma X em UMA coluna de cada grupo, por linha. Se houver mais de um defeito no mesmo km, marque o PREDOMINANTE e escreva o resto em OBSERVAÇÕES. A quilometragem é contada de 0 até o fim de CADA S.R.E. (não é o marco da rodovia).
A6: S.R.E. | B6: SENT. | C6: INÍCIO (KM) | D6: FIM (KM) | E6: EXT. (KM) | F6: CONDIÇÃO DO PAVIMENTO | K6: VEGETAÇÃO | M6: ELEM. DE DRENAGEM | P6: SIN. HORIZ. | S6: SIN. VERTICAL | V6: OBSERVAÇÕES | W6: CONFERÊNCIA (só na tela)
F7: BOM | G7: REM. I. | H7: REM. L. | I7: BUR. I. | J7: BUR. L. | K7: ADEQ. | L7: INAD. | M7: LIMPOS | N7: SUJOS | O7: DAN. | P7: BOM | Q7: REG. | R7: INEXIST. | S7: BOM | T7: POUCAS | U7: INEXIST.
A8: S.R.E. 010ETO0320 | PALMERANTE *TRECHO URBANO* - ENTR. TO-335 | PPS · Estadual · 11.000 km · início: -7.865427, -47.939469
A9: 010ETO0320 | B9: C | C9: 0 | D9: 1 | E9: =D9-C9 -> 1 | F9: X | K9: X | N9: X | P9: X | T9: X | W9: =IF(COUNTA(F9:U9)=0,"— não preenchido",IF(COUNTIF(F9:J9,"X")<>1,"FALTA/DUPLA: CONDIÇÃO DO PAVIMENTO",IF(COUNTIF(K9:L9,"X")<>1,"FALTA/DUPLA: VEGETAÇÃO",IF(COUNTIF(M9:O9,"X")<>1,"FALTA/DUPLA: ELEM. DE DRENAGEM",IF(COUNTIF(P9:R9,"X")<>1,"FALTA/DUPLA: SIN. HORIZ.",IF(COUNTIF(S9:U9,"X")<>1,"FALTA/DUPLA: SIN. VERTICAL","OK")))))) -> OK
A10: 010ETO0320 | B10: C | C10: 1 | D10: 2 | E10: =D10-C10 -> 1 | F10: X | K10: X | N10: X | P10: X | T10: X | W10: =IF(COUNTA(F10:U10)=0,"— não preenchido",IF(COUNTIF(F10:J10,"X")<>1,"FALTA/DUPLA: CONDIÇÃO DO PAVIMENTO",IF(COUNTIF(K10:L10,"X")<>1,"FALTA/DUPLA: VEGETAÇÃO",IF(COUNTIF(M10:O10,"X")<>1,"FALTA/DUPLA: ELEM. DE DRENAGEM",IF(COUNTIF(P10:R10,"X")<>1,"FALTA/DUPLA: SIN. HORIZ.",IF(COUNTIF(S10:U10,"X")<>1,"FALTA/DUPLA: SIN. VERTICAL","OK")))))) -> OK
A11: 010ETO0320 | B11: C | C11: 2 | D11: 3 | E11: =D11-C11 -> 1 | F11: X | K11: X | N11: X | P11: X | T11: X | W11: =IF(COUNTA(F11:U11)=0,"— não preenchido",IF(COUNTIF(F11:J11,"X")<>1,"FALTA/DUPLA: CONDIÇÃO DO PAVIMENTO",IF(COUNTIF(K11:L11,"X")<>1,"FALTA/DUPLA: VEGETAÇÃO",IF(COUNTIF(M11:O11,"X")<>1,"FALTA/DUPLA: ELEM. DE DRENAGEM",IF(COUNTIF(P11:R11,"X")<>1,"FALTA/DUPLA: SIN. HORIZ.",IF(COUNTIF(S11:U11,"X")<>1,"FALTA/DUPLA: SIN. VERTICAL","OK")))))) -> OK
A12: 010ETO0320 | B12: C | C12: 3 | D12: 4 | E12: =D12-C12 -> 1 | I12: X | K12: X | N12: X | P12: X | T12: X | W12: =IF(COUNTA(F12:U12)=0,"— não preenchido",IF(COUNTIF(F12:J12,"X")<>1,"FALTA/DUPLA: CONDIÇÃO DO PAVIMENTO",IF(COUNTIF(K12:L12,"X")<>1,"FALTA/DUPLA: VEGETAÇÃO",IF(COUNTIF(M12:O12,"X")<>1,"FALTA/DUPLA: ELEM. DE DRENAGEM",IF(COUNTIF(P12:R12,"X")<>1,"FALTA/DUPLA: SIN. HORIZ.",IF(COUNTIF(S12:U12,"X")<>1,"FALTA/DUPLA: SIN. VERTICAL","OK")))))) -> OK
A13: 010ETO0320 | B13: C | C13: 4 | D13: 5 | E13: =D13-C13 -> 1 | I13: X | K13: X | N13: X | P13: X | T13: X | W13: =IF(COUNTA(F13:U13)=0,"— não preenchido",IF(COUNTIF(F13:J13,"X")<>1,"FALTA/DUPLA: CONDIÇÃO DO PAVIMENTO",IF(COUNTIF(K13:L13,"X")<>1,"FALTA/DUPLA: VEGETAÇÃO",IF(COUNTIF(M13:O13,"X")<>1,"FALTA/DUPLA: ELEM. DE DRENAGEM",IF(COUNTIF(P13:R13,"X")<>1,"FALTA/DUPLA: SIN. HORIZ.",IF(COUNTIF(S13:U13,"X")<>1,"FALTA/DUPLA: SIN. VERTICAL","OK")))))) -> OK
A14: 010ETO0320 | B14: C | C14: 5 | D14: 6 | E14: =D14-C14 -> 1 | F14: X | K14: X | N14: X | P14: X | T14: X | W14: =IF(COUNTA(F14:U14)=0,"— não preenchido",IF(COUNTIF(F14:J14,"X")<>1,"FALTA/DUPLA: CONDIÇÃO DO PAVIMENTO",IF(COUNTIF(K14:L14,"X")<>1,"FALTA/DUPLA: VEGETAÇÃO",IF(COUNTIF(M14:O14,"X")<>1,"FALTA/DUPLA: ELEM. DE DRENAGEM",IF(COUNTIF(P14:R14,"X")<>1,"FALTA/DUPLA: SIN. HORIZ.",IF(COUNTIF(S14:U14,"X")<>1,"FALTA/DUPLA: SIN. VERTICAL","OK")))))) -> OK
A15: 010ETO0320 | B15: C | C15: 6 | D15: 7 | E15: =D15-C15 -> 1 | F15: X | K15: X | N15: X | P15: X | T15: X | W15: =IF(COUNTA(F15:U15)=0,"— não preenchido",IF(COUNTIF(F15:J15,"X")<>1,"FALTA/DUPLA: CONDIÇÃO DO PAVIMENTO",IF(COUNTIF(K15:L15,"X")<>1,"FALTA/DUPLA: VEGETAÇÃO",IF(COUNTIF(M15:O15,"X")<>1,"FALTA/DUPLA: ELEM. DE DRENAGEM",IF(COUNTIF(P15:R15,"X")<>1,"FALTA/DUPLA: SIN. HORIZ.",IF(COUNTIF(S15:U15,"X")<>1,"FALTA/DUPLA: SIN. VERTICAL","OK")))))) -> OK
A16: 010ETO0320 | B16: C | C16: 7 | D16: 8 | E16: =D16-C16 -> 1 | F16: X | K16: X | N16: X | P16: X | T16: X | W16: =IF(COUNTA(F16:U16)=0,"— não preenchido",IF(COUNTIF(F16:J16,"X")<>1,"FALTA/DUPLA: CONDIÇÃO DO PAVIMENTO",IF(COUNTIF(K16:L16,"X")<>1,"FALTA/DUPLA: VEGETAÇÃO",IF(COUNTIF(M16:O16,"X")<>1,"FALTA/DUPLA: ELEM. DE DRENAGEM",IF(COUNTIF(P16:R16,"X")<>1,"FALTA/DUPLA: SIN. HORIZ.",IF(COUNTIF(S16:U16,"X")<>1,"FALTA/DUPLA: SIN. VERTICAL","OK")))))) -> OK
A17: 010ETO0320 | B17: C | C17: 8 | D17: 9 | E17: =D17-C17 -> 1 | F17: X | K17: X | N17: X | P17: X | T17: X | W17: =IF(COUNTA(F17:U17)=0,"— não preenchido",IF(COUNTIF(F17:J17,"X")<>1,"FALTA/DUPLA: CONDIÇÃO DO PAVIMENTO",IF(COUNTIF(K17:L17,"X")<>1,"FALTA/DUPLA: VEGETAÇÃO",IF(COUNTIF(M17:O17,"X")<>1,"FALTA/DUPLA: ELEM. DE DRENAGEM",IF(COUNTIF(P17:R17,"X")<>1,"FALTA/DUPLA: SIN. HORIZ.",IF(COUNTIF(S17:U17,"X")<>1,"FALTA/DUPLA: SIN. VERTICAL","OK")))))) -> OK
A18: 010ETO0320 | B18: C | C18: 9 | D18: 10 | E18: =D18-C18 -> 1 | F18: X | K18: X | N18: X | P18: X | T18: X | W18: =IF(COUNTA(F18:U18)=0,"— não preenchido",IF(COUNTIF(F18:J18,"X")<>1,"FALTA/DUPLA: CONDIÇÃO DO PAVIMENTO",IF(COUNTIF(K18:L18,"X")<>1,"FALTA/DUPLA: VEGETAÇÃO",IF(COUNTIF(M18:O18,"X")<>1,"FALTA/DUPLA: ELEM. DE DRENAGEM",IF(COUNTIF(P18:R18,"X")<>1,"FALTA/DUPLA: SIN. HORIZ.",IF(COUNTIF(S18:U18,"X")<>1,"FALTA/DUPLA: SIN. VERTICAL","OK")))))) -> OK
A19: 010ETO0320 | B19: C | C19: 10 | D19: 10.999804 | E19: =D19-C19 -> 0.99980397 | F19: X | K19: X | N19: X | P19: X | T19: X | W19: =IF(COUNTA(F19:U19)=0,"— não preenchido",IF(COUNTIF(F19:J19,"X")<>1,"FALTA/DUPLA: CONDIÇÃO DO PAVIMENTO",IF(COUNTIF(K19:L19,"X")<>1,"FALTA/DUPLA: VEGETAÇÃO",IF(COUNTIF(M19:O19,"X")<>1,"FALTA/DUPLA: ELEM. DE DRENAGEM",IF(COUNTIF(P19:R19,"X")<>1,"FALTA/DUPLA: SIN. HORIZ.",IF(COUNTIF(S19:U19,"X")<>1,"FALTA/DUPLA: SIN. VERTICAL","OK")))))) -> OK
A20: S.R.E. 010ETO0330 | ENTR.TO-335 - TRECHO ENTR.TO-226 | PPS · Estadual · 9.147 km · início: -7.847064, -48.019678
A21: 010ETO0330 | B21: C | C21: 0 | D21: 1 | E21: =D21-C21 -> 1 | I21: X | K21: X | N21: X | P21: X | T21: X | W21: =IF(COUNTA(F21:U21)=0,"— não preenchido",IF(COUNTIF(F21:J21,"X")<>1,"FALTA/DUPLA: CONDIÇÃO DO PAVIMENTO",IF(COUNTIF(K21:L21,"X")<>1,"FALTA/DUPLA: VEGETAÇÃO",IF(COUNTIF(M21:O21,"X")<>1,"FALTA/DUPLA: ELEM. DE DRENAGEM",IF(COUNTIF(P21:R21,"X")<>1,"FALTA/DUPLA: SIN. HORIZ.",IF(COUNTIF(S21:U21,"X")<>1,"FALTA/DUPLA: SIN. VERTICAL","OK")))))) -> OK
A22: 010ETO0330 | B22: C | C22: 1 | D22: 2 | E22: =D22-C22 -> 1 | F22: X | K22: X | N22: X | P22: X | T22: X | W22: =IF(COUNTA(F22:U22)=0,"— não preenchido",IF(COUNTIF(F22:J22,"X")<>1,"FALTA/DUPLA: CONDIÇÃO DO PAVIMENTO",IF(COUNTIF(K22:L22,"X")<>1,"FALTA/DUPLA: VEGETAÇÃO",IF(COUNTIF(M22:O22,"X")<>1,"FALTA/DUPLA: ELEM. DE DRENAGEM",IF(COUNTIF(P22:R22,"X")<>1,"FALTA/DUPLA: SIN. HORIZ.",IF(COUNTIF(S22:U22,"X")<>1,"FALTA/DUPLA: SIN. VERTICAL","OK")))))) -> OK
A23: 010ETO0330 | B23: C | C23: 2 | D23: 3 | E23: =D23-C23 -> 1 | F23: X | K23: X | N23: X | P23: X | T23: X | W23: =IF(COUNTA(F23:U23)=0,"— não preenchido",IF(COUNTIF(F23:J23,"X")<>1,"FALTA/DUPLA: CONDIÇÃO DO PAVIMENTO",IF(COUNTIF(K23:L23,"X")<>1,"FALTA/DUPLA: VEGETAÇÃO",IF(COUNTIF(M23:O23,"X")<>1,"FALTA/DUPLA: ELEM. DE DRENAGEM",IF(COUNTIF(P23:R23,"X")<>1,"FALTA/DUPLA: SIN. HORIZ.",IF(COUNTIF(S23:U23,"X")<>1,"FALTA/DUPLA: SIN. VERTICAL","OK")))))) -> OK
A24: 010ETO0330 | B24: C | C24: 3 | D24: 4 | E24: =D24-C24 -> 1 | F24: X | K24: X | N24: X | P24: X | T24: X | W24: =IF(COUNTA(F24:U24)=0,"— não preenchido",IF(COUNTIF(F24:J24,"X")<>1,"FALTA/DUPLA: CONDIÇÃO DO PAVIMENTO",IF(COUNTIF(K24:L24,"X")<>1,"FALTA/DUPLA: VEGETAÇÃO",IF(COUNTIF(M24:O24,"X")<>1,"FALTA/DUPLA: ELEM. DE DRENAGEM",IF(COUNTIF(P24:R24,"X")<>1,"FALTA/DUPLA: SIN. HORIZ.",IF(COUNTIF(S24:U24,"X")<>1,"FALTA/DUPLA: SIN. VERTICAL","OK")))))) -> OK
A25: 010ETO0330 | B25: C | C25: 4 | D25: 5 | E25: =D25-C25 -> 1 | F25: X | K25: X | N25: X | P25: X | T25: X | W25: =IF(COUNTA(F25:U25)=0,"— não preenchido",IF(COUNTIF(F25:J25,"X")<>1,"FALTA/DUPLA: CONDIÇÃO DO PAVIMENTO",IF(COUNTIF(K25:L25,"X")<>1,"FALTA/DUPLA: VEGETAÇÃO",IF(COUNTIF(M25:O25,"X")<>1,"FALTA/DUPLA: ELEM. DE DRENAGEM",IF(COUNTIF(P25:R25,"X")<>1,"FALTA/DUPLA: SIN. HORIZ.",IF(COUNTIF(S25:U25,"X")<>1,"FALTA/DUPLA: SIN. VERTICAL","OK")))))) -> OK
A26: 010ETO0330 | B26: C | C26: 5 | D26: 6 | E26: =D26-C26 -> 1 | F26: X | K26: X | N26: X | P26: X | T26: X | W26: =IF(COUNTA(F26:U26)=0,"— não preenchido",IF(COUNTIF(F26:J26,"X")<>1,"FALTA/DUPLA: CONDIÇÃO DO PAVIMENTO",IF(COUNTIF(K26:L26,"X")<>1,"FALTA/DUPLA: VEGETAÇÃO",IF(COUNTIF(M26:O26,"X")<>1,"FALTA/DUPLA: ELEM. DE DRENAGEM",IF(COUNTIF(P26:R26,"X")<>1,"FALTA/DUPLA: SIN. HORIZ.",IF(COUNTIF(S26:U26,"X")<>1,"FALTA/DUPLA: SIN. VERTICAL","OK")))))) -> OK
A27: 010ETO0330 | B27: C | C27: 6 | D27: 7 | E27: =D27-C27 -> 1 | I27: X | K27: X | N27: X | P27: X | T27: X | W27: =IF(COUNTA(F27:U27)=0,"— não preenchido",IF(COUNTIF(F27:J27,"X")<>1,"FALTA/DUPLA: CONDIÇÃO DO PAVIMENTO",IF(COUNTIF(K27:L27,"X")<>1,"FALTA/DUPLA: VEGETAÇÃO",IF(COUNTIF(M27:O27,"X")<>1,"FALTA/DUPLA: ELEM. DE DRENAGEM",IF(COUNTIF(P27:R27,"X")<>1,"FALTA/DUPLA: SIN. HORIZ.",IF(COUNTIF(S27:U27,"X")<>1,"FALTA/DUPLA: SIN. VERTICAL","OK")))))) -> OK
A28: 010ETO0330 | B28: C | C28: 7 | D28: 8 | E28: =D28-C28 -> 1 | I28: X | K28: X | N28: X | P28: X | T28: X | W28: =IF(COUNTA(F28:U28)=0,"— não preenchido",IF(COUNTIF(F28:J28,"X")<>1,"FALTA/DUPLA: CONDIÇÃO DO PAVIMENTO",IF(COUNTIF(K28:L28,"X")<>1,"FALTA/DUPLA: VEGETAÇÃO",IF(COUNTIF(M28:O28,"X")<>1,"FALTA/DUPLA: ELEM. DE DRENAGEM",IF(COUNTIF(P28:R28,"X")<>1,"FALTA/DUPLA: SIN. HORIZ.",IF(COUNTIF(S28:U28,"X")<>1,"FALTA/DUPLA: SIN. VERTICAL","OK")))))) -> OK
A29: 010ETO0330 | B29: C | C29: 8 | D29: 9 | E29: =D29-C29 -> 1 | I29: X | K29: X | N29: X | P29: X | T29: X | W29: =IF(COUNTA(F29:U29)=0,"— não preenchido",IF(COUNTIF(F29:J29,"X")<>1,"FALTA/DUPLA: CONDIÇÃO DO PAVIMENTO",IF(COUNTIF(K29:L29,"X")<>1,"FALTA/DUPLA: VEGETAÇÃO",IF(COUNTIF(M29:O29,"X")<>1,"FALTA/DUPLA: ELEM. DE DRENAGEM",IF(COUNTIF(P29:R29,"X")<>1,"FALTA/DUPLA: SIN. HORIZ.",IF(COUNTIF(S29:U29,"X")<>1,"FALTA/DUPLA: SIN. VERTICAL","OK")))))) -> OK
A30: 010ETO0330 | B30: C | C30: 9 | D30: 9.147414 | E30: =D30-C30 -> 0.14741401 | I30: X | K30: X | N30: X | P30: X | T30: X | W30: =IF(COUNTA(F30:U30)=0,"— não preenchido",IF(COUNTIF(F30:J30,"X")<>1,"FALTA/DUPLA: CONDIÇÃO DO PAVIMENTO",IF(COUNTIF(K30:L30,"X")<>1,"FALTA/DUPLA: VEGETAÇÃO",IF(COUNTIF(M30:O30,"X")<>1,"FALTA/DUPLA: ELEM. DE DRENAGEM",IF(COUNTIF(P30:R30,"X")<>1,"FALTA/DUPLA: SIN. HORIZ.",IF(COUNTIF(S30:U30,"X")<>1,"FALTA/DUPLA: SIN. VERTICAL","OK")))))) -> OK
A31: S.R.E. 010ETO0340 | ENTR. TO-226 - TRECHO POV. CICILÃNDIA | PPS · Estadual · 11.531 km · início: -7.788551, -48.071722
A32: 010ETO0340 | B32: C | C32: 0 | D32: 1 | E32: =D32-C32 -> 1 | F32: X | K32: X | N32: X | P32: X | T32: X | W32: =IF(COUNTA(F32:U32)=0,"— não preenchido",IF(COUNTIF(F32:J32,"X")<>1,"FALTA/DUPLA: CONDIÇÃO DO PAVIMENTO",IF(COUNTIF(K32:L32,"X")<>1,"FALTA/DUPLA: VEGETAÇÃO",IF(COUNTIF(M32:O32,"X")<>1,"FALTA/DUPLA: ELEM. DE DRENAGEM",IF(COUNTIF(P32:R32,"X")<>1,"FALTA/DUPLA: SIN. HORIZ.",IF(COUNTIF(S32:U32,"X")<>1,"FALTA/DUPLA: SIN. VERTICAL","OK")))))) -> OK
A33: 010ETO0340 | B33: C | C33: 1 | D33: 2 | E33: =D33-C33 -> 1 | F33: X | K33: X | N33: X | P33: X | T33: X | W33: =IF(COUNTA(F33:U33)=0,"— não preenchido",IF(COUNTIF(F33:J33,"X")<>1,"FALTA/DUPLA: CONDIÇÃO DO PAVIMENTO",IF(COUNTIF(K33:L33,"X")<>1,"FALTA/DUPLA: VEGETAÇÃO",IF(COUNTIF(M33:O33,"X")<>1,"FALTA/DUPLA: ELEM. DE DRENAGEM",IF(COUNTIF(P33:R33,"X")<>1,"FALTA/DUPLA: SIN. HORIZ.",IF(COUNTIF(S33:U33,"X")<>1,"FALTA/DUPLA: SIN. VERTICAL","OK")))))) -> OK
A34: 010ETO0340 | B34: C | C34: 2 | D34: 3 | E34: =D34-C34 -> 1 | F34: X | K34: X | N34: X | P34: X | T34: X | W34: =IF(COUNTA(F34:U34)=0,"— não preenchido",IF(COUNTIF(F34:J34,"X")<>1,"FALTA/DUPLA: CONDIÇÃO DO PAVIMENTO",IF(COUNTIF(K34:L34,"X")<>1,"FALTA/DUPLA: VEGETAÇÃO",IF(COUNTIF(M34:O34,"X")<>1,"FALTA/DUPLA: ELEM. DE DRENAGEM",IF(COUNTIF(P34:R34,"X")<>1,"FALTA/DUPLA: SIN. HORIZ.",IF(COUNTIF(S34:U34,"X")<>1,"FALTA/DUPLA: SIN. VERTICAL","OK")))))) -> OK
A35: 010ETO0340 | B35: C | C35: 3 | D35: 4 | E35: =D35-C35 -> 1 | I35: X | K35: X | N35: X | P35: X | T35: X | W35: =IF(COUNTA(F35:U35)=0,"— não preenchido",IF(COUNTIF(F35:J35,"X")<>1,"FALTA/DUPLA: CONDIÇÃO DO PAVIMENTO",IF(COUNTIF(K35:L35,"X")<>1,"FALTA/DUPLA: VEGETAÇÃO",IF(COUNTIF(M35:O35,"X")<>1,"FALTA/DUPLA: ELEM. DE DRENAGEM",IF(COUNTIF(P35:R35,"X")<>1,"FALTA/DUPLA: SIN. HORIZ.",IF(COUNTIF(S35:U35,"X")<>1,"FALTA/DUPLA: SIN. VERTICAL","OK")))))) -> OK
A36: 010ETO0340 | B36: C | C36: 4 | D36: 5 | E36: =D36-C36 -> 1 | I36: X | K36: X | N36: X | P36: X | T36: X | W36: =IF(COUNTA(F36:U36)=0,"— não preenchido",IF(COUNTIF(F36:J36,"X")<>1,"FALTA/DUPLA: CONDIÇÃO DO PAVIMENTO",IF(COUNTIF(K36:L36,"X")<>1,"FALTA/DUPLA: VEGETAÇÃO",IF(COUNTIF(M36:O36,"X")<>1,"FALTA/DUPLA: ELEM. DE DRENAGEM",IF(COUNTIF(P36:R36,"X")<>1,"FALTA/DUPLA: SIN. HORIZ.",IF(COUNTIF(S36:U36,"X")<>1,"FALTA/DUPLA: SIN. VERTICAL","OK")))))) -> OK
A37: 010ETO0340 | B37: C | C37: 5 | D37: 6 | E37: =D37-C37 -> 1 | I37: X | K37: X | N37: X | P37: X | T37: X | W37: =IF(COUNTA(F37:U37)=0,"— não preenchido",IF(COUNTIF(F37:J37,"X")<>1,"FALTA/DUPLA: CONDIÇÃO DO PAVIMENTO",IF(COUNTIF(K37:L37,"X")<>1,"FALTA/DUPLA: VEGETAÇÃO",IF(COUNTIF(M37:O37,"X")<>1,"FALTA/DUPLA: ELEM. DE DRENAGEM",IF(COUNTIF(P37:R37,"X")<>1,"FALTA/DUPLA: SIN. HORIZ.",IF(COUNTIF(S37:U37,"X")<>1,"FALTA/DUPLA: SIN. VERTICAL","OK")))))) -> OK
A38: 010ETO0340 | B38: C | C38: 6 | D38: 7 | E38: =D38-C38 -> 1 | F38: X | K38: X | N38: X | P38: X | T38: X | W38: =IF(COUNTA(F38:U38)=0,"— não preenchido",IF(COUNTIF(F38:J38,"X")<>1,"FALTA/DUPLA: CONDIÇÃO DO PAVIMENTO",IF(COUNTIF(K38:L38,"X")<>1,"FALTA/DUPLA: VEGETAÇÃO",IF(COUNTIF(M38:O38,"X")<>1,"FALTA/DUPLA: ELEM. DE DRENAGEM",IF(COUNTIF(P38:R38,"X")<>1,"FALTA/DUPLA: SIN. HORIZ.",IF(COUNTIF(S38:U38,"X")<>1,"FALTA/DUPLA: SIN. VERTICAL","OK")))))) -> OK
A39: 010ETO0340 | B39: C | C39: 7 | D39: 8 | E39: =D39-C39 -> 1 | F39: X | K39: X | N39: X | P39: X | T39: X | W39: =IF(COUNTA(F39:U39)=0,"— não preenchido",IF(COUNTIF(F39:J39,"X")<>1,"FALTA/DUPLA: CONDIÇÃO DO PAVIMENTO",IF(COUNTIF(K39:L39,"X")<>1,"FALTA/DUPLA: VEGETAÇÃO",IF(COUNTIF(M39:O39,"X")<>1,"FALTA/DUPLA: ELEM. DE DRENAGEM",IF(COUNTIF(P39:R39,"X")<>1,"FALTA/DUPLA: SIN. HORIZ.",IF(COUNTIF(S39:U39,"X")<>1,"FALTA/DUPLA: SIN. VERTICAL","OK")))))) -> OK
A40: 010ETO0340 | B40: C | C40: 8 | D40: 9 | E40: =D40-C40 -> 1 | F40: X | K40: X | N40: X | P40: X | T40: X | W40: =IF(COUNTA(F40:U40)=0,"— não preenchido",IF(COUNTIF(F40:J40,"X")<>1,"FALTA/DUPLA: CONDIÇÃO DO PAVIMENTO",IF(COUNTIF(K40:L40,"X")<>1,"FALTA/DUPLA: VEGETAÇÃO",IF(COUNTIF(M40:O40,"X")<>1,"FALTA/DUPLA: ELEM. DE DRENAGEM",IF(COUNTIF(P40:R40,"X")<>1,"FALTA/DUPLA: SIN. HORIZ.",IF(COUNTIF(S40:U40,"X")<>1,"FALTA/DUPLA: SIN. VERTICAL","OK")))))) -> OK
A41: 010ETO0340 | B41: C | C41: 9 | D41: 10 | E41: =D41-C41 -> 1 | F41: X | K41: X | N41: X | P41: X | T41: X | W41: =IF(COUNTA(F41:U41)=0,"— não preenchido",IF(COUNTIF(F41:J41,"X")<>1,"FALTA/DUPLA: CONDIÇÃO DO PAVIMENTO",IF(COUNTIF(K41:L41,"X")<>1,"FALTA/DUPLA: VEGETAÇÃO",IF(COUNTIF(M41:O41,"X")<>1,"FALTA/DUPLA: ELEM. DE DRENAGEM",IF(COUNTIF(P41:R41,"X")<>1,"FALTA/DUPLA: SIN. HORIZ.",IF(COUNTIF(S41:U41,"X")<>1,"FALTA/DUPLA: SIN. VERTICAL","OK")))))) -> OK
...

Sheet 70
A1: PROGRAMA DE MANUTENÇÃO RODOVIÁRIA — FICHA DE INSPEÇÃO — RODOVIAS PAVIMENTADAS | Y1: Valores dos gráficos — troca 0 por N/D para a fatia não aparecer. Não editar.
A2: REGIÃO: 3 — ARAGUAÍNA II | G2: MÊS / ANO: | I2: =IF('68'!I2="","",'68'!I2) -> 46235 | K2: DATA: | N2: =IF('68'!N2="","",'68'!N2) | P2: TÉCNICO: | R2: ENG. VINICIUS RODRIGUES FERREIRA DE OLIVEIRA | Y2: =IF(F69=0,NA(),F69) -> 50.5733 | Z2: =IF(G69=0,NA(),G69) -> #N/A | AA2: =IF(H69=0,NA(),H69) -> #N/A | AB2: =IF(I69=0,NA(),I69) -> 3 | AC2: =IF(J69=0,NA(),J69) -> 1 | AD2: =IF(K69=0,NA(),K69) -> 54.5733 | AE2: =IF(L69=0,NA(),L69) -> #N/A | AF2: =IF(M69=0,NA(),M69) -> #N/A | ... AN2: =IF(U69=0,NA(),U69) -> #N/A
A3: TRECHO 70 — RODOVIA TO-010 - TRECHO BABAÇULÂNDIA - WANDERLÂNDIA | T3: EXTENSÃO: 54,573 km · 1 S.R.E.
A4: COMO PREENCHER: uma X em UMA coluna de cada grupo, por linha. Se houver mais de um defeito no mesmo km, marque o PREDOMINANTE e escreva o resto em OBSERVAÇÕES. A quilometragem é contada de 0 até o fim de CADA S.R.E. (não é o marco da rodovia).
A6: S.R.E. | B6: SENT. | C6: INÍCIO (KM) | D6: FIM (KM) | E6: EXT. (KM) | F6: CONDIÇÃO DO PAVIMENTO | K6: VEGETAÇÃO | M6: ELEM. DE DRENAGEM | P6: SIN. HORIZ. | S6: SIN. VERTICAL | V6: OBSERVAÇÕES | W6: CONFERÊNCIA (só na tela)
F7: BOM | G7: REM. I. | H7: REM. L. | I7: BUR. I. | J7: BUR. L. | K7: ADEQ. | L7: INAD. | M7: LIMPOS | N7: SUJOS | O7: DAN. | P7: BOM | Q7: REG. | R7: INEXIST. | S7: BOM | T7: POUCAS | U7: INEXIST.
A8: S.R.E. 010ETO0420 | BABAÇULÂNDIA *TRECHO URBANO* - WANDERLÂNDIA *TRECHO URBANO* | PPS · Estadual · 54.573 km · início: -7.191051, -47.784852
A9: 010ETO0420 | B9: C | C9: 0 | D9: 1 | E9: =D9-C9 -> 1 | F9: X | K9: X | N9: X | P9: X | S9: X | W9: =IF(COUNTA(F9:U9)=0,"— não preenchido",IF(COUNTIF(F9:J9,"X")<>1,"FALTA/DUPLA: CONDIÇÃO DO PAVIMENTO",IF(COUNTIF(K9:L9,"X")<>1,"FALTA/DUPLA: VEGETAÇÃO",IF(COUNTIF(M9:O9,"X")<>1,"FALTA/DUPLA: ELEM. DE DRENAGEM",IF(COUNTIF(P9:R9,"X")<>1,"FALTA/DUPLA: SIN. HORIZ.",IF(COUNTIF(S9:U9,"X")<>1,"FALTA/DUPLA: SIN. VERTICAL","OK")))))) -> OK
A10: 010ETO0420 | B10: C | C10: 1 | D10: 2 | E10: =D10-C10 -> 1 | F10: X | K10: X | N10: X | P10: X | S10: X | W10: =IF(COUNTA(F10:U10)=0,"— não preenchido",IF(COUNTIF(F10:J10,"X")<>1,"FALTA/DUPLA: CONDIÇÃO DO PAVIMENTO",IF(COUNTIF(K10:L10,"X")<>1,"FALTA/DUPLA: VEGETAÇÃO",IF(COUNTIF(M10:O10,"X")<>1,"FALTA/DUPLA: ELEM. DE DRENAGEM",IF(COUNTIF(P10:R10,"X")<>1,"FALTA/DUPLA: SIN. HORIZ.",IF(COUNTIF(S10:U10,"X")<>1,"FALTA/DUPLA: SIN. VERTICAL","OK")))))) -> OK
A11: 010ETO0420 | B11: C | C11: 2 | D11: 3 | E11: =D11-C11 -> 1 | F11: X | K11: X | N11: X | P11: X | S11: X | W11: =IF(COUNTA(F11:U11)=0,"— não preenchido",IF(COUNTIF(F11:J11,"X")<>1,"FALTA/DUPLA: CONDIÇÃO DO PAVIMENTO",IF(COUNTIF(K11:L11,"X")<>1,"FALTA/DUPLA: VEGETAÇÃO",IF(COUNTIF(M11:O11,"X")<>1,"FALTA/DUPLA: ELEM. DE DRENAGEM",IF(COUNTIF(P11:R11,"X")<>1,"FALTA/DUPLA: SIN. HORIZ.",IF(COUNTIF(S11:U11,"X")<>1,"FALTA/DUPLA: SIN. VERTICAL","OK")))))) -> OK
A12: 010ETO0420 | B12: C | C12: 3 | D12: 4 | E12: =D12-C12 -> 1 | F12: X | K12: X | N12: X | P12: X | S12: X | W12: =IF(COUNTA(F12:U12)=0,"— não preenchido",IF(COUNTIF(F12:J12,"X")<>1,"FALTA/DUPLA: CONDIÇÃO DO PAVIMENTO",IF(COUNTIF(K12:L12,"X")<>1,"FALTA/DUPLA: VEGETAÇÃO",IF(COUNTIF(M12:O12,"X")<>1,"FALTA/DUPLA: ELEM. DE DRENAGEM",IF(COUNTIF(P12:R12,"X")<>1,"FALTA/DUPLA: SIN. HORIZ.",IF(COUNTIF(S12:U12,"X")<>1,"FALTA/DUPLA: SIN. VERTICAL","OK")))))) -> OK
A13: 010ETO0420 | B13: C | C13: 4 | D13: 5 | E13: =D13-C13 -> 1 | F13: X | K13: X | N13: X | P13: X | S13: X | W13: =IF(COUNTA(F13:U13)=0,"— não preenchido",IF(COUNTIF(F13:J13,"X")<>1,"FALTA/DUPLA: CONDIÇÃO DO PAVIMENTO",IF(COUNTIF(K13:L13,"X")<>1,"FALTA/DUPLA: VEGETAÇÃO",IF(COUNTIF(M13:O13,"X")<>1,"FALTA/DUPLA: ELEM. DE DRENAGEM",IF(COUNTIF(P13:R13,"X")<>1,"FALTA/DUPLA: SIN. HORIZ.",IF(COUNTIF(S13:U13,"X")<>1,"FALTA/DUPLA: SIN. VERTICAL","OK")))))) -> OK
A14: 010ETO0420 | B14: C | C14: 5 | D14: 6 | E14: =D14-C14 -> 1 | F14: X | K14: X | N14: X | P14: X | S14: X | W14: =IF(COUNTA(F14:U14)=0,"— não preenchido",IF(COUNTIF(F14:J14,"X")<>1,"FALTA/DUPLA: CONDIÇÃO DO PAVIMENTO",IF(COUNTIF(K14:L14,"X")<>1,"FALTA/DUPLA: VEGETAÇÃO",IF(COUNTIF(M14:O14,"X")<>1,"FALTA/DUPLA: ELEM. DE DRENAGEM",IF(COUNTIF(P14:R14,"X")<>1,"FALTA/DUPLA: SIN. HORIZ.",IF(COUNTIF(S14:U14,"X")<>1,"FALTA/DUPLA: SIN. VERTICAL","OK")))))) -> OK
A15: 010ETO0420 | B15: C | C15: 6 | D15: 7 | E15: =D15-C15 -> 1 | J15: X | K15: X | N15: X | P15: X | S15: X | W15: =IF(COUNTA(F15:U15)=0,"— não preenchido",IF(COUNTIF(F15:J15,"X")<>1,"FALTA/DUPLA: CONDIÇÃO DO PAVIMENTO",IF(COUNTIF(K15:L15,"X")<>1,"FALTA/DUPLA: VEGETAÇÃO",IF(COUNTIF(M15:O15,"X")<>1,"FALTA/DUPLA: ELEM. DE DRENAGEM",IF(COUNTIF(P15:R15,"X")<>1,"FALTA/DUPLA: SIN. HORIZ.",IF(COUNTIF(S15:U15,"X")<>1,"FALTA/DUPLA: SIN. VERTICAL","OK")))))) -> OK
A16: 010ETO0420 | B16: C | C16: 7 | D16: 8 | E16: =D16-C16 -> 1 | F16: X | K16: X | N16: X | P16: X | S16: X | W16: =IF(COUNTA(F16:U16)=0,"— não preenchido",IF(COUNTIF(F16:J16,"X")<>1,"FALTA/DUPLA: CONDIÇÃO DO PAVIMENTO",IF(COUNTIF(K16:L16,"X")<>1,"FALTA/DUPLA: VEGETAÇÃO",IF(COUNTIF(M16:O16,"X")<>1,"FALTA/DUPLA: ELEM. DE DRENAGEM",IF(COUNTIF(P16:R16,"X")<>1,"FALTA/DUPLA: SIN. HORIZ.",IF(COUNTIF(S16:U16,"X")<>1,"FALTA/DUPLA: SIN. VERTICAL","OK")))))) -> OK
A17: 010ETO0420 | B17: C | C17: 8 | D17: 9 | E17: =D17-C17 -> 1 | F17: X | K17: X | N17: X | P17: X | S17: X | W17: =IF(COUNTA(F17:U17)=0,"— não preenchido",IF(COUNTIF(F17:J17,"X")<>1,"FALTA/DUPLA: CONDIÇÃO DO PAVIMENTO",IF(COUNTIF(K17:L17,"X")<>1,"FALTA/DUPLA: VEGETAÇÃO",IF(COUNTIF(M17:O17,"X")<>1,"FALTA/DUPLA: ELEM. DE DRENAGEM",IF(COUNTIF(P17:R17,"X")<>1,"FALTA/DUPLA: SIN. HORIZ.",IF(COUNTIF(S17:U17,"X")<>1,"FALTA/DUPLA: SIN. VERTICAL","OK")))))) -> OK
A18: 010ETO0420 | B18: C | C18: 9 | D18: 10 | E18: =D18-C18 -> 1 | F18: X | K18: X | N18: X | P18: X | S18: X | W18: =IF(COUNTA(F18:U18)=0,"— não preenchido",IF(COUNTIF(F18:J18,"X")<>1,"FALTA/DUPLA: CONDIÇÃO DO PAVIMENTO",IF(COUNTIF(K18:L18,"X")<>1,"FALTA/DUPLA: VEGETAÇÃO",IF(COUNTIF(M18:O18,"X")<>1,"FALTA/DUPLA: ELEM. DE DRENAGEM",IF(COUNTIF(P18:R18,"X")<>1,"FALTA/DUPLA: SIN. HORIZ.",IF(COUNTIF(S18:U18,"X")<>1,"FALTA/DUPLA: SIN. VERTICAL","OK")))))) -> OK
A19: 010ETO0420 | B19: C | C19: 10 | D19: 11 | E19: =D19-C19 -> 1 | F19: X | K19: X | N19: X | P19: X | S19: X | W19: =IF(COUNTA(F19:U19)=0,"— não preenchido",IF(COUNTIF(F19:J19,"X")<>1,"FALTA/DUPLA: CONDIÇÃO DO PAVIMENTO",IF(COUNTIF(K19:L19,"X")<>1,"FALTA/DUPLA: VEGETAÇÃO",IF(COUNTIF(M19:O19,"X")<>1,"FALTA/DUPLA: ELEM. DE DRENAGEM",IF(COUNTIF(P19:R19,"X")<>1,"FALTA/DUPLA: SIN. HORIZ.",IF(COUNTIF(S19:U19,"X")<>1,"FALTA/DUPLA: SIN. VERTICAL","OK")))))) -> OK
A20: 010ETO0420 | B20: C | C20: 11 | D20: 12 | E20: =D20-C20 -> 1 | F20: X | K20: X | N20: X | P20: X | S20: X | W20: =IF(COUNTA(F20:U20)=0,"— não preenchido",IF(COUNTIF(F20:J20,"X")<>1,"FALTA/DUPLA: CONDIÇÃO DO PAVIMENTO",IF(COUNTIF(K20:L20,"X")<>1,"FALTA/DUPLA: VEGETAÇÃO",IF(COUNTIF(M20:O20,"X")<>1,"FALTA/DUPLA: ELEM. DE DRENAGEM",IF(COUNTIF(P20:R20,"X")<>1,"FALTA/DUPLA: SIN. HORIZ.",IF(COUNTIF(S20:U20,"X")<>1,"FALTA/DUPLA: SIN. VERTICAL","OK")))))) -> OK
A21: 010ETO0420 | B21: C | C21: 12 | D21: 13 | E21: =D21-C21 -> 1 | F21: X | K21: X | N21: X | P21: X | S21: X | W21: =IF(COUNTA(F21:U21)=0,"— não preenchido",IF(COUNTIF(F21:J21,"X")<>1,"FALTA/DUPLA: CONDIÇÃO DO PAVIMENTO",IF(COUNTIF(K21:L21,"X")<>1,"FALTA/DUPLA: VEGETAÇÃO",IF(COUNTIF(M21:O21,"X")<>1,"FALTA/DUPLA: ELEM. DE DRENAGEM",IF(COUNTIF(P21:R21,"X")<>1,"FALTA/DUPLA: SIN. HORIZ.",IF(COUNTIF(S21:U21,"X")<>1,"FALTA/DUPLA: SIN. VERTICAL","OK")))))) -> OK
A22: 010ETO0420 | B22: C | C22: 13 | D22: 14 | E22: =D22-C22 -> 1 | F22: X | K22: X | N22: X | P22: X | S22: X | W22: =IF(COUNTA(F22:U22)=0,"— não preenchido",IF(COUNTIF(F22:J22,"X")<>1,"FALTA/DUPLA: CONDIÇÃO DO PAVIMENTO",IF(COUNTIF(K22:L22,"X")<>1,"FALTA/DUPLA: VEGETAÇÃO",IF(COUNTIF(M22:O22,"X")<>1,"FALTA/DUPLA: ELEM. DE DRENAGEM",IF(COUNTIF(P22:R22,"X")<>1,"FALTA/DUPLA: SIN. HORIZ.",IF(COUNTIF(S22:U22,"X")<>1,"FALTA/DUPLA: SIN. VERTICAL","OK")))))) -> OK
A23: 010ETO0420 | B23: C | C23: 14 | D23: 15 | E23: =D23-C23 -> 1 | I23: X | K23: X | N23: X | P23: X | S23: X | W23: =IF(COUNTA(F23:U23)=0,"— não preenchido",IF(COUNTIF(F23:J23,"X")<>1,"FALTA/DUPLA: CONDIÇÃO DO PAVIMENTO",IF(COUNTIF(K23:L23,"X")<>1,"FALTA/DUPLA: VEGETAÇÃO",IF(COUNTIF(M23:O23,"X")<>1,"FALTA/DUPLA: ELEM. DE DRENAGEM",IF(COUNTIF(P23:R23,"X")<>1,"FALTA/DUPLA: SIN. HORIZ.",IF(COUNTIF(S23:U23,"X")<>1,"FALTA/DUPLA: SIN. VERTICAL","OK")))))) -> OK
A24: 010ETO0420 | B24: C | C24: 15 | D24: 16 | E24: =D24-C24 -> 1 | F24: X | K24: X | N24: X | P24: X | S24: X | W24: =IF(COUNTA(F24:U24)=0,"— não preenchido",IF(COUNTIF(F24:J24,"X")<>1,"FALTA/DUPLA: CONDIÇÃO DO PAVIMENTO",IF(COUNTIF(K24:L24,"X")<>1,"FALTA/DUPLA: VEGETAÇÃO",IF(COUNTIF(M24:O24,"X")<>1,"FALTA/DUPLA: ELEM. DE DRENAGEM",IF(COUNTIF(P24:R24,"X")<>1,"FALTA/DUPLA: SIN. HORIZ.",IF(COUNTIF(S24:U24,"X")<>1,"FALTA/DUPLA: SIN. VERTICAL","OK")))))) -> OK
A25: 010ETO0420 | B25: C | C25: 16 | D25: 17 | E25: =D25-C25 -> 1 | F25: X | K25: X | N25: X | P25: X | S25: X | W25: =IF(COUNTA(F25:U25)=0,"— não preenchido",IF(COUNTIF(F25:J25,"X")<>1,"FALTA/DUPLA: CONDIÇÃO DO PAVIMENTO",IF(COUNTIF(K25:L25,"X")<>1,"FALTA/DUPLA: VEGETAÇÃO",IF(COUNTIF(M25:O25,"X")<>1,"FALTA/DUPLA: ELEM. DE DRENAGEM",IF(COUNTIF(P25:R25,"X")<>1,"FALTA/DUPLA: SIN. HORIZ.",IF(COUNTIF(S25:U25,"X")<>1,"FALTA/DUPLA: SIN. VERTICAL","OK")))))) -> OK
A26: 010ETO0420 | B26: C | C26: 17 | D26: 18 | E26: =D26-C26 -> 1 | F26: X | K26: X | N26: X | P26: X | S26: X | W26: =IF(COUNTA(F26:U26)=0,"— não preenchido",IF(COUNTIF(F26:J26,"X")<>1,"FALTA/DUPLA: CONDIÇÃO DO PAVIMENTO",IF(COUNTIF(K26:L26,"X")<>1,"FALTA/DUPLA: VEGETAÇÃO",IF(COUNTIF(M26:O26,"X")<>1,"FALTA/DUPLA: ELEM. DE DRENAGEM",IF(COUNTIF(P26:R26,"X")<>1,"FALTA/DUPLA: SIN. HORIZ.",IF(COUNTIF(S26:U26,"X")<>1,"FALTA/DUPLA: SIN. VERTICAL","OK")))))) -> OK
A27: 010ETO0420 | B27: C | C27: 18 | D27: 19 | E27: =D27-C27 -> 1 | F27: X | K27: X | N27: X | P27: X | S27: X | W27: =IF(COUNTA(F27:U27)=0,"— não preenchido",IF(COUNTIF(F27:J27,"X")<>1,"FALTA/DUPLA: CONDIÇÃO DO PAVIMENTO",IF(COUNTIF(K27:L27,"X")<>1,"FALTA/DUPLA: VEGETAÇÃO",IF(COUNTIF(M27:O27,"X")<>1,"FALTA/DUPLA: ELEM. DE DRENAGEM",IF(COUNTIF(P27:R27,"X")<>1,"FALTA/DUPLA: SIN. HORIZ.",IF(COUNTIF(S27:U27,"X")<>1,"FALTA/DUPLA: SIN. VERTICAL","OK")))))) -> OK
A28: 010ETO0420 | B28: C | C28: 19 | D28: 20 | E28: =D28-C28 -> 1 | I28: X | K28: X | N28: X | P28: X | S28: X | W28: =IF(COUNTA(F28:U28)=0,"— não preenchido",IF(COUNTIF(F28:J28,"X")<>1,"FALTA/DUPLA: CONDIÇÃO DO PAVIMENTO",IF(COUNTIF(K28:L28,"X")<>1,"FALTA/DUPLA: VEGETAÇÃO",IF(COUNTIF(M28:O28,"X")<>1,"FALTA/DUPLA: ELEM. DE DRENAGEM",IF(COUNTIF(P28:R28,"X")<>1,"FALTA/DUPLA: SIN. HORIZ.",IF(COUNTIF(S28:U28,"X")<>1,"FALTA/DUPLA: SIN. VERTICAL","OK")))))) -> OK
A29: 010ETO0420 | B29: C | C29: 20 | D29: 21 | E29: =D29-C29 -> 1 | F29: X | K29: X | N29: X | P29: X | S29: X | W29: =IF(COUNTA(F29:U29)=0,"— não preenchido",IF(COUNTIF(F29:J29,"X")<>1,"FALTA/DUPLA: CONDIÇÃO DO PAVIMENTO",IF(COUNTIF(K29:L29,"X")<>1,"FALTA/DUPLA: VEGETAÇÃO",IF(COUNTIF(M29:O29,"X")<>1,"FALTA/DUPLA: ELEM. DE DRENAGEM",IF(COUNTIF(P29:R29,"X")<>1,"FALTA/DUPLA: SIN. HORIZ.",IF(COUNTIF(S29:U29,"X")<>1,"FALTA/DUPLA: SIN. VERTICAL","OK")))))) -> OK
A30: 010ETO0420 | B30: C | C30: 21 | D30: 22 | E30: =D30-C30 -> 1 | F30: X | K30: X | N30: X | P30: X | S30: X | W30: =IF(COUNTA(F30:U30)=0,"— não preenchido",IF(COUNTIF(F30:J30,"X")<>1,"FALTA/DUPLA: CONDIÇÃO DO PAVIMENTO",IF(COUNTIF(K30:L30,"X")<>1,"FALTA/DUPLA: VEGETAÇÃO",IF(COUNTIF(M30:O30,"X")<>1,"FALTA/DUPLA: ELEM. DE DRENAGEM",IF(COUNTIF(P30:R30,"X")<>1,"FALTA/DUPLA: SIN. HORIZ.",IF(COUNTIF(S30:U30,"X")<>1,"FALTA/DUPLA: SIN. VERTICAL","OK")))))) -> OK
A31: 010ETO0420 | B31: C | C31: 22 | D31: 23 | E31: =D31-C31 -> 1 | F31: X | K31: X | N31: X | P31: X | S31: X | W31: =IF(COUNTA(F31:U31)=0,"— não preenchido",IF(COUNTIF(F31:J31,"X")<>1,"FALTA/DUPLA: CONDIÇÃO DO PAVIMENTO",IF(COUNTIF(K31:L31,"X")<>1,"FALTA/DUPLA: VEGETAÇÃO",IF(COUNTIF(M31:O31,"X")<>1,"FALTA/DUPLA: ELEM. DE DRENAGEM",IF(COUNTIF(P31:R31,"X")<>1,"FALTA/DUPLA: SIN. HORIZ.",IF(COUNTIF(S31:U31,"X")<>1,"FALTA/DUPLA: SIN. VERTICAL","OK")))))) -> OK
A32: 010ETO0420 | B32: C | C32: 23 | D32: 24 | E32: =D32-C32 -> 1 | F32: X | K32: X | N32: X | P32: X | S32: X | W32: =IF(COUNTA(F32:U32)=0,"— não preenchido",IF(COUNTIF(F32:J32,"X")<>1,"FALTA/DUPLA: CONDIÇÃO DO PAVIMENTO",IF(COUNTIF(K32:L32,"X")<>1,"FALTA/DUPLA: VEGETAÇÃO",IF(COUNTIF(M32:O32,"X")<>1,"FALTA/DUPLA: ELEM. DE DRENAGEM",IF(COUNTIF(P32:R32,"X")<>1,"FALTA/DUPLA: SIN. HORIZ.",IF(COUNTIF(S32:U32,"X")<>1,"FALTA/DUPLA: SIN. VERTICAL","OK")))))) -> OK
A33: 010ETO0420 | B33: C | C33: 24 | D33: 25 | E33: =D33-C33 -> 1 | F33: X | K33: X | N33: X | P33: X | S33: X | W33: =IF(COUNTA(F33:U33)=0,"— não preenchido",IF(COUNTIF(F33:J33,"X")<>1,"FALTA/DUPLA: CONDIÇÃO DO PAVIMENTO",IF(COUNTIF(K33:L33,"X")<>1,"FALTA/DUPLA: VEGETAÇÃO",IF(COUNTIF(M33:O33,"X")<>1,"FALTA/DUPLA: ELEM. DE DRENAGEM",IF(COUNTIF(P33:R33,"X")<>1,"FALTA/DUPLA: SIN. HORIZ.",IF(COUNTIF(S33:U33,"X")<>1,"FALTA/DUPLA: SIN. VERTICAL","OK")))))) -> OK
A34: 010ETO0420 | B34: C | C34: 25 | D34: 26 | E34: =D34-C34 -> 1 | F34: X | K34: X | N34: X | P34: X | S34: X | W34: =IF(COUNTA(F34:U34)=0,"— não preenchido",IF(COUNTIF(F34:J34,"X")<>1,"FALTA/DUPLA: CONDIÇÃO DO PAVIMENTO",IF(COUNTIF(K34:L34,"X")<>1,"FALTA/DUPLA: VEGETAÇÃO",IF(COUNTIF(M34:O34,"X")<>1,"FALTA/DUPLA: ELEM. DE DRENAGEM",IF(COUNTIF(P34:R34,"X")<>1,"FALTA/DUPLA: SIN. HORIZ.",IF(COUNTIF(S34:U34,"X")<>1,"FALTA/DUPLA: SIN. VERTICAL","OK")))))) -> OK
A35: 010ETO0420 | B35: C | C35: 26 | D35: 27 | E35: =D35-C35 -> 1 | F35: X | K35: X | N35: X | P35: X | S35: X | W35: =IF(COUNTA(F35:U35)=0,"— não preenchido",IF(COUNTIF(F35:J35,"X")<>1,"FALTA/DUPLA: CONDIÇÃO DO PAVIMENTO",IF(COUNTIF(K35:L35,"X")<>1,"FALTA/DUPLA: VEGETAÇÃO",IF(COUNTIF(M35:O35,"X")<>1,"FALTA/DUPLA: ELEM. DE DRENAGEM",IF(COUNTIF(P35:R35,"X")<>1,"FALTA/DUPLA: SIN. HORIZ.",IF(COUNTIF(S35:U35,"X")<>1,"FALTA/DUPLA: SIN. VERTICAL","OK")))))) -> OK
A36: 010ETO0420 | B36: C | C36: 27 | D36: 28 | E36: =D36-C36 -> 1 | F36: X | K36: X | N36: X | P36: X | S36: X | W36: =IF(COUNTA(F36:U36)=0,"— não preenchido",IF(COUNTIF(F36:J36,"X")<>1,"FALTA/DUPLA: CONDIÇÃO DO PAVIMENTO",IF(COUNTIF(K36:L36,"X")<>1,"FALTA/DUPLA: VEGETAÇÃO",IF(COUNTIF(M36:O36,"X")<>1,"FALTA/DUPLA: ELEM. DE DRENAGEM",IF(COUNTIF(P36:R36,"X")<>1,"FALTA/DUPLA: SIN. HORIZ.",IF(COUNTIF(S36:U36,"X")<>1,"FALTA/DUPLA: SIN. VERTICAL","OK")))))) -> OK
A37: 010ETO0420 | B37: C | C37: 28 | D37: 29 | E37: =D37-C37 -> 1 | F37: X | K37: X | N37: X | P37: X | S37: X | W37: =IF(COUNTA(F37:U37)=0,"— não preenchido",IF(COUNTIF(F37:J37,"X")<>1,"FALTA/DUPLA: CONDIÇÃO DO PAVIMENTO",IF(COUNTIF(K37:L37,"X")<>1,"FALTA/DUPLA: VEGETAÇÃO",IF(COUNTIF(M37:O37,"X")<>1,"FALTA/DUPLA: ELEM. DE DRENAGEM",IF(COUNTIF(P37:R37,"X")<>1,"FALTA/DUPLA: SIN. HORIZ.",IF(COUNTIF(S37:U37,"X")<>1,"FALTA/DUPLA: SIN. VERTICAL","OK")))))) -> OK
A38: 010ETO0420 | B38: C | C38: 29 | D38: 30 | E38: =D38-C38 -> 1 | F38: X | K38: X | N38: X | P38: X | S38: X | W38: =IF(COUNTA(F38:U38)=0,"— não preenchido",IF(COUNTIF(F38:J38,"X")<>1,"FALTA/DUPLA: CONDIÇÃO DO PAVIMENTO",IF(COUNTIF(K38:L38,"X")<>1,"FALTA/DUPLA: VEGETAÇÃO",IF(COUNTIF(M38:O38,"X")<>1,"FALTA/DUPLA: ELEM. DE DRENAGEM",IF(COUNTIF(P38:R38,"X")<>1,"FALTA/DUPLA: SIN. HORIZ.",IF(COUNTIF(S38:U38,"X")<>1,"FALTA/DUPLA: SIN. VERTICAL","OK")))))) -> OK
A39: 010ETO0420 | B39: C | C39: 30 | D39: 31 | E39: =D39-C39 -> 1 | F39: X | K39: X | N39: X | P39: X | S39: X | W39: =IF(COUNTA(F39:U39)=0,"— não preenchido",IF(COUNTIF(F39:J39,"X")<>1,"FALTA/DUPLA: CONDIÇÃO DO PAVIMENTO",IF(COUNTIF(K39:L39,"X")<>1,"FALTA/DUPLA: VEGETAÇÃO",IF(COUNTIF(M39:O39,"X")<>1,"FALTA/DUPLA: ELEM. DE DRENAGEM",IF(COUNTIF(P39:R39,"X")<>1,"FALTA/DUPLA: SIN. HORIZ.",IF(COUNTIF(S39:U39,"X")<>1,"FALTA/DUPLA: SIN. VERTICAL","OK")))))) -> OK
A40: 010ETO0420 | B40: C | C40: 31 | D40: 32 | E40: =D40-C40 -> 1 | F40: X | K40: X | N40: X | P40: X | S40: X | W40: =IF(COUNTA(F40:U40)=0,"— não preenchido",IF(COUNTIF(F40:J40,"X")<>1,"FALTA/DUPLA: CONDIÇÃO DO PAVIMENTO",IF(COUNTIF(K40:L40,"X")<>1,"FALTA/DUPLA: VEGETAÇÃO",IF(COUNTIF(M40:O40,"X")<>1,"FALTA/DUPLA: ELEM. DE DRENAGEM",IF(COUNTIF(P40:R40,"X")<>1,"FALTA/DUPLA: SIN. HORIZ.",IF(COUNTIF(S40:U40,"X")<>1,"FALTA/DUPLA: SIN. VERTICAL","OK")))))) -> OK
... A42: 010ETO0420 | B42: C | C42: 33 | D42: 34 | E42: =D42-C42 -> 1 | F42: X | K42: X | N42: X | P42: X | S42: X | W42: =IF(COUNTA(F42:U42)=0,"— não preenchido",IF(COUNTIF(F42:J42,"X")<>1,"FALTA/DUPLA: CONDIÇÃO DO PAVIMENTO",IF(COUNTIF(K42:L42,"X")<>1,"FALTA/DUPLA: VEGETAÇÃO",IF(COUNTIF(M42:O42,"X")<>1,"FALTA/DUPLA: ELEM. DE DRENAGEM",IF(COUNTIF(P42:R42,"X")<>1,"FALTA/DUPLA: SIN. HORIZ.",IF(COUNTIF(S42:U42,"X")<>1,"FALTA/DUPLA: SIN. VERTICAL","OK")))))) -> OK
...

Sheet 71
A1: PROGRAMA DE MANUTENÇÃO RODOVIÁRIA — FICHA DE INSPEÇÃO — RODOVIAS PAVIMENTADAS | Y1: Valores dos gráficos — troca 0 por N/D para a fatia não aparecer. Não editar.
A2: REGIÃO: 3 — ARAGUAÍNA II | G2: MÊS / ANO: | I2: =IF('68'!I2="","",'68'!I2) -> 46235 | K2: DATA: | N2: =IF('68'!N2="","",'68'!N2) | P2: TÉCNICO: | R2: ENG. VINICIUS RODRIGUES FERREIRA DE OLIVEIRA | Y2: =IF(F22=0,NA(),F22) -> 5.606921 | Z2: =IF(G22=0,NA(),G22) -> #N/A | AA2: =IF(H22=0,NA(),H22) -> #N/A | AB2: =IF(I22=0,NA(),I22) -> #N/A | AC2: =IF(J22=0,NA(),J22) -> #N/A | AD2: =IF(K22=0,NA(),K22) -> #N/A | AE2: =IF(L22=0,NA(),L22) -> 5.606921 | AF2: =IF(M22=0,NA(),M22) -> 2.708768 | ... AN2: =IF(U22=0,NA(),U22) -> 2.898153
A3: TRECHO 71 — RODOVIA TO-020 - TRECHO RECURSOLÂNDIA - CAMPOS LINDOS | T3: EXTENSÃO: 5,607 km · 2 S.R.E.
A4: COMO PREENCHER: uma X em UMA coluna de cada grupo, por linha. Se houver mais de um defeito no mesmo km, marque o PREDOMINANTE e escreva o resto em OBSERVAÇÕES. A quilometragem é contada de 0 até o fim de CADA S.R.E. (não é o marco da rodovia).
A6: S.R.E. | B6: SENT. | C6: INÍCIO (KM) | D6: FIM (KM) | E6: EXT. (KM) | F6: CONDIÇÃO DO PAVIMENTO | K6: VEGETAÇÃO | M6: ELEM. DE DRENAGEM | P6: SIN. HORIZ. | S6: SIN. VERTICAL | V6: OBSERVAÇÕES | W6: CONFERÊNCIA (só na tela)
F7: BOM | G7: REM. I. | H7: REM. L. | I7: BUR. I. | J7: BUR. L. | K7: ADEQ. | L7: INAD. | M7: LIMPOS | N7: SUJOS | O7: DAN. | P7: BOM | Q7: REG. | R7: INEXIST. | S7: BOM | T7: POUCAS | U7: INEXIST.
A8: S.R.E. 020ETO0200 | RECURSOLÂNDIA *TRECHO URBANO* - FIM PAVIMENTAÇÃO | PPS · Estadual · 2.898 km · sem coordenada no shape
A9: 020ETO0200 | B9: C | C9: 0 | D9: 1 | E9: =D9-C9 -> 1 | F9: X | L9: X | N9: X | R9: X | U9: X | W9: =IF(COUNTA(F9:U9)=0,"— não preenchido",IF(COUNTIF(F9:J9,"X")<>1,"FALTA/DUPLA: CONDIÇÃO DO PAVIMENTO",IF(COUNTIF(K9:L9,"X")<>1,"FALTA/DUPLA: VEGETAÇÃO",IF(COUNTIF(M9:O9,"X")<>1,"FALTA/DUPLA: ELEM. DE DRENAGEM",IF(COUNTIF(P9:R9,"X")<>1,"FALTA/DUPLA: SIN. HORIZ.",IF(COUNTIF(S9:U9,"X")<>1,"FALTA/DUPLA: SIN. VERTICAL","OK")))))) -> OK
A10: 020ETO0200 | B10: C | C10: 1 | D10: 2 | E10: =D10-C10 -> 1 | F10: X | L10: X | N10: X | R10: X | U10: X | W10: =IF(COUNTA(F10:U10)=0,"— não preenchido",IF(COUNTIF(F10:J10,"X")<>1,"FALTA/DUPLA: CONDIÇÃO DO PAVIMENTO",IF(COUNTIF(K10:L10,"X")<>1,"FALTA/DUPLA: VEGETAÇÃO",IF(COUNTIF(M10:O10,"X")<>1,"FALTA/DUPLA: ELEM. DE DRENAGEM",IF(COUNTIF(P10:R10,"X")<>1,"FALTA/DUPLA: SIN. HORIZ.",IF(COUNTIF(S10:U10,"X")<>1,"FALTA/DUPLA: SIN. VERTICAL","OK")))))) -> OK
A11: 020ETO0200 | B11: C | C11: 2 | D11: 2.898153 | E11: =D11-C11 -> 0.89815297 | F11: X | L11: X | N11: X | R11: X | U11: X | W11: =IF(COUNTA(F11:U11)=0,"— não preenchido",IF(COUNTIF(F11:J11,"X")<>1,"FALTA/DUPLA: CONDIÇÃO DO PAVIMENTO",IF(COUNTIF(K11:L11,"X")<>1,"FALTA/DUPLA: VEGETAÇÃO",IF(COUNTIF(M11:O11,"X")<>1,"FALTA/DUPLA: ELEM. DE DRENAGEM",IF(COUNTIF(P11:R11,"X")<>1,"FALTA/DUPLA: SIN. HORIZ.",IF(COUNTIF(S11:U11,"X")<>1,"FALTA/DUPLA: SIN. VERTICAL","OK")))))) -> OK
A12: ▲ AQUI HÁ 148.408 km FORA DO ESCOPO DO CONTRATO (perímetro urbano de jurisdição municipal). Você passa por ele, mas NÃO preenche.
A13: S.R.E. 020ETO0215 | NICIO PAVIMENTACAO (CAMPOS LINDOS) - ENTR. TO-226 | PPS · Estadual · 2.709 km · início: -7.965561, -46.809144
A14: 020ETO0215 | B14: C | C14: 0 | D14: 1 | E14: =D14-C14 -> 1 | F14: X | L14: X | M14: X | Q14: X | T14: X | W14: =IF(COUNTA(F14:U14)=0,"— não preenchido",IF(COUNTIF(F14:J14,"X")<>1,"FALTA/DUPLA: CONDIÇÃO DO PAVIMENTO",IF(COUNTIF(K14:L14,"X")<>1,"FALTA/DUPLA: VEGETAÇÃO",IF(COUNTIF(M14:O14,"X")<>1,"FALTA/DUPLA: ELEM. DE DRENAGEM",IF(COUNTIF(P14:R14,"X")<>1,"FALTA/DUPLA: SIN. HORIZ.",IF(COUNTIF(S14:U14,"X")<>1,"FALTA/DUPLA: SIN. VERTICAL","OK")))))) -> OK
A15: 020ETO0215 | B15: C | C15: 1 | D15: 2 | E15: =D15-C15 -> 1 | F15: X | L15: X | M15: X | Q15: X | T15: X | W15: =IF(COUNTA(F15:U15)=0,"— não preenchido",IF(COUNTIF(F15:J15,"X")<>1,"FALTA/DUPLA: CONDIÇÃO DO PAVIMENTO",IF(COUNTIF(K15:L15,"X")<>1,"FALTA/DUPLA: VEGETAÇÃO",IF(COUNTIF(M15:O15,"X")<>1,"FALTA/DUPLA: ELEM. DE DRENAGEM",IF(COUNTIF(P15:R15,"X")<>1,"FALTA/DUPLA: SIN. HORIZ.",IF(COUNTIF(S15:U15,"X")<>1,"FALTA/DUPLA: SIN. VERTICAL","OK")))))) -> OK
A16: 020ETO0215 | B16: C | C16: 2 | D16: 2.708768 | E16: =D16-C16 -> 0.70876802 | F16: X | L16: X | M16: X | Q16: X | T16: X | W16: =IF(COUNTA(F16:U16)=0,"— não preenchido",IF(COUNTIF(F16:J16,"X")<>1,"FALTA/DUPLA: CONDIÇÃO DO PAVIMENTO",IF(COUNTIF(K16:L16,"X")<>1,"FALTA/DUPLA: VEGETAÇÃO",IF(COUNTIF(M16:O16,"X")<>1,"FALTA/DUPLA: ELEM. DE DRENAGEM",IF(COUNTIF(P16:R16,"X")<>1,"FALTA/DUPLA: SIN. HORIZ.",IF(COUNTIF(S16:U16,"X")<>1,"FALTA/DUPLA: SIN. VERTICAL","OK")))))) -> OK
A18: ____________________________________________ | G18: ____________________________________________
A19: TÉCNICO RESPONSÁVEL PELA INSPEÇÃO | G19: VISTO DA SUPERVISÃO
A21: RESUMO DO TRECHO — KM LANÇADO POR ITEM
A22: KM LANÇADO | F22: =SUMIF(F$9:F$16,"X",$E$9:$E$16) -> 5.606921 | G22: =SUMIF(G$9:G$16,"X",$E$9:$E$16) -> 0 | H22: =SUMIF(H$9:H$16,"X",$E$9:$E$16) -> 0 | I22: =SUMIF(I$9:I$16,"X",$E$9:$E$16) -> 0 | J22: =SUMIF(J$9:J$16,"X",$E$9:$E$16) -> 0 | K22: =SUMIF(K$9:K$16,"X",$E$9:$E$16) -> 0 | L22: =SUMIF(L$9:L$16,"X",$E$9:$E$16) -> 5.606921 | M22: =SUMIF(M$9:M$16,"X",$E$9:$E$16) -> 2.708768 | ... U22: =SUMIF(U$9:U$16,"X",$E$9:$E$16) -> 2.898153
A23: % DA EXTENSÃO | F23: =IF($R25=0,0,F22/$R25) -> 1 | G23: =IF($R25=0,0,G22/$R25) -> 0 | H23: =IF($R25=0,0,H22/$R25) -> 0 | I23: =IF($R25=0,0,I22/$R25) -> 0 | J23: =IF($R25=0,0,J22/$R25) -> 0 | K23: =IF($R25=0,0,K22/$R25) -> 0 | L23: =IF($R25=0,0,L22/$R25) -> 1 | M23: =IF($R25=0,0,M22/$R25) -> 0.4831115 | ... U23: =IF($R25=0,0,U22/$R25) -> 0.5168885
A24: CONFERÊNCIA POR GRUPO | F24: =IF(SUM(F22:J22)=0,"— não preenchido",IF(ROUND(SUM(F22:J22)-$R25,3)=0,"OK — "&ROUND(SUM(F22:J22),3)&" km","ERRO — dif. de "&ROUND(SUM(F22:J22)-$R25,3)&" km")) -> OK — 5,607 km | K24: =IF(SUM(K22:L22)=0,"— não preenchido",IF(ROUND(SUM(K22:L22)-$R25,3)=0,"OK — "&ROUND(SUM(K22:L22),3)&" km","ERRO — dif. de "&ROUND(SUM(K22:L22)-$R25,3)&" km")) -> OK — 5,607 km | M24: =IF(SUM(M22:O22)=0,"— não preenchido",IF(ROUND(SUM(M22:O22)-$R25,3)=0,"OK — "&ROUND(SUM(M22:O22),3)&" km","ERRO — dif. de "&ROUND(SUM(M22:O22)-$R25,3)&" km")) -> OK — 5,607 km | P24: =IF(SUM(P22:R22)=0,"— não preenchido",IF(ROUND(SUM(P22:R22)-$R25,3)=0,"OK — "&ROUND(SUM(P22:R22),3)&" km","ERRO — dif. de "&ROUND(SUM(P22:R22)-$R25,3)&" km")) -> OK — 5,607 km | S24: =IF(SUM(S22:U22)=0,"— não preenchido",IF(ROUND(SUM(S22:U22)-$R25,3)=0,"OK — "&ROUND(SUM(S22:U22),3)&" km","ERRO — dif. de "&ROUND(SUM(S22:U22)-$R25,3)&" km")) -> OK — 5,607 km
A25: EXTENSÃO TOTAL DO TRECHO | R25: =SUM(E9:E16) -> 5.606921 | V25: =COUNTIF(W9:W16,"OK")&" de "&COUNT($E$9:$E$16)&" linhas conferidas" -> 6 de 6 linhas conferidas
A27: LEGENDA
A28: REM. I. / REM. L. | E28: Remendos isolados (até 10 por km) · Remendos ao longo (mais de 10 por km)
A29: BUR. I. / BUR. L. | E29: Buracos isolados (até 5 por km) · Buracos ao longo (mais de 5 por km)
A30: SIT. | E30: PPS = pista simples · PSU = simples urbana · PDU = duplicada
A31: FAIXA AZUL | E31: Cabeçalho de cada S.R.E.: descrição, situação, jurisdição, extensão e coordenada de início.
A32: INÍCIO / FIM (KM) | E32: Contados de 0 até o fim de CADA S.R.E. Não é o marco quilométrico da rodovia.
A33: SENT. | E33: C = crescente · D = decrescente
A34: FAIXA CINZA | E34: Segmento fora do escopo do contrato: você passa por ele, mas não preenche.
A35: CÉLULA VERMELHA | E35: Mais de uma X no mesmo grupo. Apague uma delas.
A36: CONFERÊNCIA | E36: Só na tela, não sai impresso. Fica OK com uma X em cada grupo.

Sheet 73
A1: PROGRAMA DE MANUTENÇÃO RODOVIÁRIA — FICHA DE INSPEÇÃO — RODOVIAS PAVIMENTADAS | Y1: Valores dos gráficos — troca 0 por N/D para a fatia não aparecer. Não editar.
A2: REGIÃO: 3 — ARAGUAÍNA II | G2: MÊS / ANO: | I2: =IF('68'!I2="","",'68'!I2) -> 46235 | K2: DATA: | N2: =IF('68'!N2="","",'68'!N2) | P2: TÉCNICO: | R2: ENG. VINICIUS RODRIGUES FERREIRA DE OLIVEIRA | Y2: =IF(F67=0,NA(),F67) -> 34.951989 | Z2: =IF(G67=0,NA(),G67) -> #N/A | AA2: =IF(H67=0,NA(),H67) -> #N/A | AB2: =IF(I67=0,NA(),I67) -> 10 | AC2: =IF(J67=0,NA(),J67) -> 4.0115949 | AD2: =IF(K67=0,NA(),K67) -> 48.963584 | AE2: =IF(L67=0,NA(),L67) -> #N/A | AF2: =IF(M67=0,NA(),M67) -> 10 | ... AN2: =IF(U67=0,NA(),U67) -> #N/A
A3: TRECHO 73 — RODOVIA TO-130 - TRECHO ENTR. TO-010 - TRECHO BARRA DO OURO - ENTR. BR-010 (POVOADO MORRO GRANDE) | T3: EXTENSÃO: 48,964 km · 3 S.R.E.
A4: COMO PREENCHER: uma X em UMA coluna de cada grupo, por linha. Se houver mais de um defeito no mesmo km, marque o PREDOMINANTE e escreva o resto em OBSERVAÇÕES. A quilometragem é contada de 0 até o fim de CADA S.R.E. (não é o marco da rodovia).
A6: S.R.E. | B6: SENT. | C6: INÍCIO (KM) | D6: FIM (KM) | E6: EXT. (KM) | F6: CONDIÇÃO DO PAVIMENTO | K6: VEGETAÇÃO | M6: ELEM. DE DRENAGEM | P6: SIN. HORIZ. | S6: SIN. VERTICAL | V6: OBSERVAÇÕES | W6: CONFERÊNCIA (só na tela)
F7: BOM | G7: REM. I. | H7: REM. L. | I7: BUR. I. | J7: BUR. L. | K7: ADEQ. | L7: INAD. | M7: LIMPOS | N7: SUJOS | O7: DAN. | P7: BOM | Q7: REG. | R7: INEXIST. | S7: BOM | T7: POUCAS | U7: INEXIST.
A8: S.R.E. 130ETO0040 | ENTR. TO-010 - TRECHO BARRA DO OURO | PPS · Estadual · 25.200 km · início: -7.604511, -47.842373
A9: 130ETO0040 | B9: C | C9: 0 | D9: 1 | E9: =D9-C9 -> 1 | F9: X | K9: X | N9: X | R9: X | T9: X | W9: =IF(COUNTA(F9:U9)=0,"— não preenchido",IF(COUNTIF(F9:J9,"X")<>1,"FALTA/DUPLA: CONDIÇÃO DO PAVIMENTO",IF(COUNTIF(K9:L9,"X")<>1,"FALTA/DUPLA: VEGETAÇÃO",IF(COUNTIF(M9:O9,"X")<>1,"FALTA/DUPLA: ELEM. DE DRENAGEM",IF(COUNTIF(P9:R9,"X")<>1,"FALTA/DUPLA: SIN. HORIZ.",IF(COUNTIF(S9:U9,"X")<>1,"FALTA/DUPLA: SIN. VERTICAL","OK")))))) -> OK
A10: 130ETO0040 | B10: C | C10: 1 | D10: 2 | E10: =D10-C10 -> 1 | F10: X | K10: X | N10: X | R10: X | T10: X | W10: =IF(COUNTA(F10:U10)=0,"— não preenchido",IF(COUNTIF(F10:J10,"X")<>1,"FALTA/DUPLA: CONDIÇÃO DO PAVIMENTO",IF(COUNTIF(K10:L10,"X")<>1,"FALTA/DUPLA: VEGETAÇÃO",IF(COUNTIF(M10:O10,"X")<>1,"FALTA/DUPLA: ELEM. DE DRENAGEM",IF(COUNTIF(P10:R10,"X")<>1,"FALTA/DUPLA: SIN. HORIZ.",IF(COUNTIF(S10:U10,"X")<>1,"FALTA/DUPLA: SIN. VERTICAL","OK")))))) -> OK
A11: 130ETO0040 | B11: C | C11: 2 | D11: 3 | E11: =D11-C11 -> 1 | F11: X | K11: X | N11: X | R11: X | T11: X | W11: =IF(COUNTA(F11:U11)=0,"— não preenchido",IF(COUNTIF(F11:J11,"X")<>1,"FALTA/DUPLA: CONDIÇÃO DO PAVIMENTO",IF(COUNTIF(K11:L11,"X")<>1,"FALTA/DUPLA: VEGETAÇÃO",IF(COUNTIF(M11:O11,"X")<>1,"FALTA/DUPLA: ELEM. DE DRENAGEM",IF(COUNTIF(P11:R11,"X")<>1,"FALTA/DUPLA: SIN. HORIZ.",IF(COUNTIF(S11:U11,"X")<>1,"FALTA/DUPLA: SIN. VERTICAL","OK")))))) -> OK
A12: 130ETO0040 | B12: C | C12: 3 | D12: 4 | E12: =D12-C12 -> 1 | F12: X | K12: X | N12: X | R12: X | T12: X | W12: =IF(COUNTA(F12:U12)=0,"— não preenchido",IF(COUNTIF(F12:J12,"X")<>1,"FALTA/DUPLA: CONDIÇÃO DO PAVIMENTO",IF(COUNTIF(K12:L12,"X")<>1,"FALTA/DUPLA: VEGETAÇÃO",IF(COUNTIF(M12:O12,"X")<>1,"FALTA/DUPLA: ELEM. DE DRENAGEM",IF(COUNTIF(P12:R12,"X")<>1,"FALTA/DUPLA: SIN. HORIZ.",IF(COUNTIF(S12:U12,"X")<>1,"FALTA/DUPLA: SIN. VERTICAL","OK")))))) -> OK
A13: 130ETO0040 | B13: C | C13: 4 | D13: 5 | E13: =D13-C13 -> 1 | F13: X | K13: X | N13: X | R13: X | T13: X | W13: =IF(COUNTA(F13:U13)=0,"— não preenchido",IF(COUNTIF(F13:J13,"X")<>1,"FALTA/DUPLA: CONDIÇÃO DO PAVIMENTO",IF(COUNTIF(K13:L13,"X")<>1,"FALTA/DUPLA: VEGETAÇÃO",IF(COUNTIF(M13:O13,"X")<>1,"FALTA/DUPLA: ELEM. DE DRENAGEM",IF(COUNTIF(P13:R13,"X")<>1,"FALTA/DUPLA: SIN. HORIZ.",IF(COUNTIF(S13:U13,"X")<>1,"FALTA/DUPLA: SIN. VERTICAL","OK")))))) -> OK
A14: 130ETO0040 | B14: C | C14: 5 | D14: 6 | E14: =D14-C14 -> 1 | F14: X | K14: X | N14: X | R14: X | T14: X | W14: =IF(COUNTA(F14:U14)=0,"— não preenchido",IF(COUNTIF(F14:J14,"X")<>1,"FALTA/DUPLA: CONDIÇÃO DO PAVIMENTO",IF(COUNTIF(K14:L14,"X")<>1,"FALTA/DUPLA: VEGETAÇÃO",IF(COUNTIF(M14:O14,"X")<>1,"FALTA/DUPLA: ELEM. DE DRENAGEM",IF(COUNTIF(P14:R14,"X")<>1,"FALTA/DUPLA: SIN. HORIZ.",IF(COUNTIF(S14:U14,"X")<>1,"FALTA/DUPLA: SIN. VERTICAL","OK")))))) -> OK
A15: 130ETO0040 | B15: C | C15: 6 | D15: 7 | E15: =D15-C15 -> 1 | F15: X | K15: X | N15: X | R15: X | T15: X | W15: =IF(COUNTA(F15:U15)=0,"— não preenchido",IF(COUNTIF(F15:J15,"X")<>1,"FALTA/DUPLA: CONDIÇÃO DO PAVIMENTO",IF(COUNTIF(K15:L15,"X")<>1,"FALTA/DUPLA: VEGETAÇÃO",IF(COUNTIF(M15:O15,"X")<>1,"FALTA/DUPLA: ELEM. DE DRENAGEM",IF(COUNTIF(P15:R15,"X")<>1,"FALTA/DUPLA: SIN. HORIZ.",IF(COUNTIF(S15:U15,"X")<>1,"FALTA/DUPLA: SIN. VERTICAL","OK")))))) -> OK
A16: 130ETO0040 | B16: C | C16: 7 | D16: 8 | E16: =D16-C16 -> 1 | F16: X | K16: X | N16: X | R16: X | T16: X | W16: =IF(COUNTA(F16:U16)=0,"— não preenchido",IF(COUNTIF(F16:J16,"X")<>1,"FALTA/DUPLA: CONDIÇÃO DO PAVIMENTO",IF(COUNTIF(K16:L16,"X")<>1,"FALTA/DUPLA: VEGETAÇÃO",IF(COUNTIF(M16:O16,"X")<>1,"FALTA/DUPLA: ELEM. DE DRENAGEM",IF(COUNTIF(P16:R16,"X")<>1,"FALTA/DUPLA: SIN. HORIZ.",IF(COUNTIF(S16:U16,"X")<>1,"FALTA/DUPLA: SIN. VERTICAL","OK")))))) -> OK
A17: 130ETO0040 | B17: C | C17: 8 | D17: 9 | E17: =D17-C17 -> 1 | F17: X | K17: X | N17: X | R17: X | T17: X | W17: =IF(COUNTA(F17:U17)=0,"— não preenchido",IF(COUNTIF(F17:J17,"X")<>1,"FALTA/DUPLA: CONDIÇÃO DO PAVIMENTO",IF(COUNTIF(K17:L17,"X")<>1,"FALTA/DUPLA: VEGETAÇÃO",IF(COUNTIF(M17:O17,"X")<>1,"FALTA/DUPLA: ELEM. DE DRENAGEM",IF(COUNTIF(P17:R17,"X")<>1,"FALTA/DUPLA: SIN. HORIZ.",IF(COUNTIF(S17:U17,"X")<>1,"FALTA/DUPLA: SIN. VERTICAL","OK")))))) -> OK
A18: 130ETO0040 | B18: C | C18: 9 | D18: 10 | E18: =D18-C18 -> 1 | F18: X | K18: X | N18: X | R18: X | T18: X | W18: =IF(COUNTA(F18:U18)=0,"— não preenchido",IF(COUNTIF(F18:J18,"X")<>1,"FALTA/DUPLA: CONDIÇÃO DO PAVIMENTO",IF(COUNTIF(K18:L18,"X")<>1,"FALTA/DUPLA: VEGETAÇÃO",IF(COUNTIF(M18:O18,"X")<>1,"FALTA/DUPLA: ELEM. DE DRENAGEM",IF(COUNTIF(P18:R18,"X")<>1,"FALTA/DUPLA: SIN. HORIZ.",IF(COUNTIF(S18:U18,"X")<>1,"FALTA/DUPLA: SIN. VERTICAL","OK")))))) -> OK
A19: 130ETO0040 | B19: C | C19: 10 | D19: 11 | E19: =D19-C19 -> 1 | F19: X | K19: X | N19: X | R19: X | T19: X | W19: =IF(COUNTA(F19:U19)=0,"— não preenchido",IF(COUNTIF(F19:J19,"X")<>1,"FALTA/DUPLA: CONDIÇÃO DO PAVIMENTO",IF(COUNTIF(K19:L19,"X")<>1,"FALTA/DUPLA: VEGETAÇÃO",IF(COUNTIF(M19:O19,"X")<>1,"FALTA/DUPLA: ELEM. DE DRENAGEM",IF(COUNTIF(P19:R19,"X")<>1,"FALTA/DUPLA: SIN. HORIZ.",IF(COUNTIF(S19:U19,"X")<>1,"FALTA/DUPLA: SIN. VERTICAL","OK")))))) -> OK
A20: 130ETO0040 | B20: C | C20: 11 | D20: 12 | E20: =D20-C20 -> 1 | F20: X | K20: X | N20: X | R20: X | T20: X | W20: =IF(COUNTA(F20:U20)=0,"— não preenchido",IF(COUNTIF(F20:J20,"X")<>1,"FALTA/DUPLA: CONDIÇÃO DO PAVIMENTO",IF(COUNTIF(K20:L20,"X")<>1,"FALTA/DUPLA: VEGETAÇÃO",IF(COUNTIF(M20:O20,"X")<>1,"FALTA/DUPLA: ELEM. DE DRENAGEM",IF(COUNTIF(P20:R20,"X")<>1,"FALTA/DUPLA: SIN. HORIZ.",IF(COUNTIF(S20:U20,"X")<>1,"FALTA/DUPLA: SIN. VERTICAL","OK")))))) -> OK
... A34: 130ETO0040 | B34: C | C34: 25 | D34: 25.199964 | E34: =D34-C34 -> 0.19996404 | F34: X | K34: X | N34: X | R34: X | T34: X | W34: =IF(COUNTA(F34:U34)=0,"— não preenchido",IF(COUNTIF(F34:J34,"X")<>1,"FALTA/DUPLA: CONDIÇÃO DO PAVIMENTO",IF(COUNTIF(K34:L34,"X")<>1,"FALTA/DUPLA: VEGETAÇÃO",IF(COUNTIF(M34:O34,"X")<>1,"FALTA/DUPLA: ELEM. DE DRENAGEM",IF(COUNTIF(P34:R34,"X")<>1,"FALTA/DUPLA: SIN. HORIZ.",IF(COUNTIF(S34:U34,"X")<>1,"FALTA/DUPLA: SIN. VERTICAL","OK")))))) -> OK
A35: S.R.E. 130ETO0060 | BARRA DO OURO - ENTR. TO-425 | PPS · Estadual · 3.752 km · início: -7.713372, -47.65921
A36: 130ETO0060 | B36: C | C36: 0 | D36: 1 | E36: =D36-C36 -> 1 | I36: X | K36: X | N36: X | P36: X | S36: X | W36: =IF(COUNTA(F36:U36)=0,"— não preenchido",IF(COUNTIF(F36:J36,"X")<>1,"FALTA/DUPLA: CONDIÇÃO DO PAVIMENTO",IF(COUNTIF(K36:L36,"X")<>1,"FALTA/DUPLA: VEGETAÇÃO",IF(COUNTIF(M36:O36,"X")<>1,"FALTA/DUPLA: ELEM. DE DRENAGEM",IF(COUNTIF(P36:R36,"X")<>1,"FALTA/DUPLA: SIN. HORIZ.",IF(COUNTIF(S36:U36,"X")<>1,"FALTA/DUPLA: SIN. VERTICAL","OK")))))) -> OK
A37: 130ETO0060 | B37: C | C37: 1 | D37: 2 | E37: =D37-C37 -> 1 | I37: X | K37: X | N37: X | P37: X | S37: X | W37: =IF(COUNTA(F37:U37)=0,"— não preenchido",IF(COUNTIF(F37:J37,"X")<>1,"FALTA/DUPLA: CONDIÇÃO DO PAVIMENTO",IF(COUNTIF(K37:L37,"X")<>1,"FALTA/DUPLA: VEGETAÇÃO",IF(COUNTIF(M37:O37,"X")<>1,"FALTA/DUPLA: ELEM. DE DRENAGEM",IF(COUNTIF(P37:R37,"X")<>1,"FALTA/DUPLA: SIN. HORIZ.",IF(COUNTIF(S37:U37,"X")<>1,"FALTA/DUPLA: SIN. VERTICAL","OK")))))) -> OK
A38: 130ETO0060 | B38: C | C38: 2 | D38: 3 | E38: =D38-C38 -> 1 | F38: X | K38: X | N38: X | P38: X | S38: X | W38: =IF(COUNTA(F38:U38)=0,"— não preenchido",IF(COUNTIF(F38:J38,"X")<>1,"FALTA/DUPLA: CONDIÇÃO DO PAVIMENTO",IF(COUNTIF(K38:L38,"X")<>1,"FALTA/DUPLA: VEGETAÇÃO",IF(COUNTIF(M38:O38,"X")<>1,"FALTA/DUPLA: ELEM. DE DRENAGEM",IF(COUNTIF(P38:R38,"X")<>1,"FALTA/DUPLA: SIN. HORIZ.",IF(COUNTIF(S38:U38,"X")<>1,"FALTA/DUPLA: SIN. VERTICAL","OK")))))) -> OK
A39: 130ETO0060 | B39: C | C39: 3 | D39: 3.7520251 | E39: =D39-C39 -> 0.75202508 | F39: X | K39: X | N39: X | P39: X | S39: X | W39: =IF(COUNTA(F39:U39)=0,"— não preenchido",IF(COUNTIF(F39:J39,"X")<>1,"FALTA/DUPLA: CONDIÇÃO DO PAVIMENTO",IF(COUNTIF(K39:L39,"X")<>1,"FALTA/DUPLA: VEGETAÇÃO",IF(COUNTIF(M39:O39,"X")<>1,"FALTA/DUPLA: ELEM. DE DRENAGEM",IF(COUNTIF(P39:R39,"X")<>1,"FALTA/DUPLA: SIN. HORIZ.",IF(COUNTIF(S39:U39,"X")<>1,"FALTA/DUPLA: SIN. VERTICAL","OK")))))) -> OK
A40: S.R.E. 130ETO0070 | ENTR. TO-425 - TRECHO MORRO GRANDE *TRECHO URBANO* | PPS · Estadual · 20.012 km · início: -7.719866, -47.641908
A41: 130ETO0070 | B41: C | C41: 0 | D41: 1 | E41: =D41-C41 -> 1 | F41: X | K41: X | N41: X | P41: X | S41: X | W41: =IF(COUNTA(F41:U41)=0,"— não preenchido",IF(COUNTIF(F41:J41,"X")<>1,"FALTA/DUPLA: CONDIÇÃO DO PAVIMENTO",IF(COUNTIF(K41:L41,"X")<>1,"FALTA/DUPLA: VEGETAÇÃO",IF(COUNTIF(M41:O41,"X")<>1,"FALTA/DUPLA: ELEM. DE DRENAGEM",IF(COUNTIF(P41:R41,"X")<>1,"FALTA/DUPLA: SIN. HORIZ.",IF(COUNTIF(S41:U41,"X")<>1,"FALTA/DUPLA: SIN. VERTICAL","OK")))))) -> OK
A42: 130ETO0070 | B42: C | C42: 1 | D42: 2 | E42: =D42-C42 -> 1 | I42: X | K42: X | N42: X | P42: X | S42: X | W42: =IF(COUNTA(F42:U42)=0,"— não preenchido",IF(COUNTIF(F42:J42,"X")<>1,"FALTA/DUPLA: CONDIÇÃO DO PAVIMENTO",IF(COUNTIF(K42:L42,"X")<>1,"FALTA/DUPLA: VEGETAÇÃO",IF(COUNTIF(M42:O42,"X")<>1,"FALTA/DUPLA: ELEM. DE DRENAGEM",IF(COUNTIF(P42:R42,"X")<>1,"FALTA/DUPLA: SIN. HORIZ.",IF(COUNTIF(S42:U42,"X")<>1,"FALTA/DUPLA: SIN. VERTICAL","OK")))))) -> OK
A43: 130ETO0070 | B43: C | C43: 2 | D43: 3 | E43: =D43-C43 -> 1 | I43: X | K43: X | N43: X | P43: X | S43: X | W43: =IF(COUNTA(F43:U43)=0,"— não preenchido",IF(COUNTIF(F43:J43,"X")<>1,"FALTA/DUPLA: CONDIÇÃO DO PAVIMENTO",IF(COUNTIF(K43:L43,"X")<>1,"FALTA/DUPLA: VEGETAÇÃO",IF(COUNTIF(M43:O43,"X")<>1,"FALTA/DUPLA: ELEM. DE DRENAGEM",IF(COUNTIF(P43:R43,"X")<>1,"FALTA/DUPLA: SIN. HORIZ.",IF(COUNTIF(S43:U43,"X")<>1,"FALTA/DUPLA: SIN. VERTICAL","OK")))))) -> OK
A44: 130ETO0070 | B44: C | C44: 3 | D44: 4 | E44: =D44-C44 -> 1 | I44: X | K44: X | M44: X | P44: X | S44: X | W44: =IF(COUNTA(F44:U44)=0,"— não preenchido",IF(COUNTIF(F44:J44,"X")<>1,"FALTA/DUPLA: CONDIÇÃO DO PAVIMENTO",IF(COUNTIF(K44:L44,"X")<>1,"FALTA/DUPLA: VEGETAÇÃO",IF(COUNTIF(M44:O44,"X")<>1,"FALTA/DUPLA: ELEM. DE DRENAGEM",IF(COUNTIF(P44:R44,"X")<>1,"FALTA/DUPLA: SIN. HORIZ.",IF(COUNTIF(S44:U44,"X")<>1,"FALTA/DUPLA: SIN. VERTICAL","OK")))))) -> OK
A45: 130ETO0070 | B45: C | C45: 4 | D45: 5 | E45: =D45-C45 -> 1 | J45: X | K45: X | M45: X | P45: X | S45: X | W45: =IF(COUNTA(F45:U45)=0,"— não preenchido",IF(COUNTIF(F45:J45,"X")<>1,"FALTA/DUPLA: CONDIÇÃO DO PAVIMENTO",IF(COUNTIF(K45:L45,"X")<>1,"FALTA/DUPLA: VEGETAÇÃO",IF(COUNTIF(M45:O45,"X")<>1,"FALTA/DUPLA: ELEM. DE DRENAGEM",IF(COUNTIF(P45:R45,"X")<>1,"FALTA/DUPLA: SIN. HORIZ.",IF(COUNTIF(S45:U45,"X")<>1,"FALTA/DUPLA: SIN. VERTICAL","OK")))))) -> OK
A46: 130ETO0070 | B46: C | C46: 5 | D46: 6 | E46: =D46-C46 -> 1 | J46: X | K46: X | M46: X | P46: X | S46: X | W46: =IF(COUNTA(F46:U46)=0,"— não preenchido",IF(COUNTIF(F46:J46,"X")<>1,"FALTA/DUPLA: CONDIÇÃO DO PAVIMENTO",IF(COUNTIF(K46:L46,"X")<>1,"FALTA/DUPLA: VEGETAÇÃO",IF(COUNTIF(M46:O46,"X")<>1,"FALTA/DUPLA: ELEM. DE DRENAGEM",IF(COUNTIF(P46:R46,"X")<>1,"FALTA/DUPLA: SIN. HORIZ.",IF(COUNTIF(S46:U46,"X")<>1,"FALTA/DUPLA: SIN. VERTICAL","OK")))))) -> OK
A47: 130ETO0070 | B47: C | C47: 6 | D47: 7 | E47: =D47-C47 -> 1 | I47: X | K47: X | M47: X | P47: X | S47: X | W47: =IF(COUNTA(F47:U47)=0,"— não preenchido",IF(COUNTIF(F47:J47,"X")<>1,"FALTA/DUPLA: CONDIÇÃO DO PAVIMENTO",IF(COUNTIF(K47:L47,"X")<>1,"FALTA/DUPLA: VEGETAÇÃO",IF(COUNTIF(M47:O47,"X")<>1,"FALTA/DUPLA: ELEM. DE DRENAGEM",IF(COUNTIF(P47:R47,"X")<>1,"FALTA/DUPLA: SIN. HORIZ.",IF(COUNTIF(S47:U47,"X")<>1,"FALTA/DUPLA: SIN. VERTICAL","OK")))))) -> OK
A48: 130ETO0070 | B48: C | C48: 7 | D48: 8 | E48: =D48-C48 -> 1 | F48: X | K48: X | M48: X | P48: X | S48: X | W48: =IF(COUNTA(F48:U48)=0,"— não preenchido",IF(COUNTIF(F48:J48,"X")<>1,"FALTA/DUPLA: CONDIÇÃO DO PAVIMENTO",IF(COUNTIF(K48:L48,"X")<>1,"FALTA/DUPLA: VEGETAÇÃO",IF(COUNTIF(M48:O48,"X")<>1,"FALTA/DUPLA: ELEM. DE DRENAGEM",IF(COUNTIF(P48:R48,"X")<>1,"FALTA/DUPLA: SIN. HORIZ.",IF(COUNTIF(S48:U48,"X")<>1,"FALTA/DUPLA: SIN. VERTICAL","OK")))))) -> OK
