Workbook

Sheet RESUMO
A1: RESUMO CONSOLIDADO — REGIÃO 1 — RODOVIAS PAVIMENTADAS | V1: Valores dos gráficos — troca 0 por N/D para a fatia não aparecer. Não editar.
A2: Todos os números vêm das abas dos trechos por referência direta. Não digite nada aqui. A coluna CONFERÊNCIA acusa qualquer trecho em que a soma das marcações não fecha com a extensão. | V2: =IF(D34=0,NA(),D34) -> 406.77109 | W2: =IF(E34=0,NA(),E34) -> 69.883429 | X2: =IF(F34=0,NA(),F34) -> 83.218724 | Y2: =IF(G34=0,NA(),G34) -> 22.3621 | Z2: =IF(H34=0,NA(),H34) -> 9.2953065 | AA2: =IF(I34=0,NA(),I34) -> 62.445485 | AB2: =IF(J34=0,NA(),J34) -> 529.08517 | AC2: =IF(K34=0,NA(),K34) -> 64.682646 | ... AK2: =IF(S34=0,NA(),S34) -> 103.53129
A4: Nº TRECHO | B4: TRECHO | C4: EXTENSÃO (KM) | D4: CONDIÇÃO DO PAVIMENTO | I4: VEGETAÇÃO | K4: ELEM. DE DRENAGEM | N4: SIN. HORIZ. | Q4: SIN. VERTICAL | T4: CONFERÊNCIA
D5: BOM | E5: REM. I. | F5: REM. L. | G5: BUR. I. | H5: BUR. L. | I5: ADEQ. | J5: INAD. | K5: LIMPOS | L5: SUJOS | M5: DAN. | N5: BOM | O5: REG. | P5: INEXIST. | Q5: BOM | R5: POUCAS | S5: INEXIST.
A6: 1 | B6: RODOVIA TO-010 - TRECHO ANANÁS - ENTR. BR-230 | C6: ='1'!R32 -> 9.697707 | D6: ='1'!F29 -> 9.697707 | E6: ='1'!G29 -> 0 | F6: ='1'!H29 -> 0 | G6: ='1'!I29 -> 0 | H6: ='1'!J29 -> 0 | I6: ='1'!K29 -> 0 | J6: ='1'!L29 -> 9.697707 | K6: ='1'!M29 -> 0 | ... S6: ='1'!U29 -> 6.8309561 | T6: =IF(SUM(D6:H6)=0,"— não preenchido",IF(ROUND(SUM(D6:H6)-C6,3)=0,"OK","ERRO — dif. de "&ROUND(SUM(D6:H6)-C6,3)&" km")) -> OK
A7: 2 | B7: RODOVIA TO-010 - TRECHO ENTR. BR-230 - ARAGUATINS | C7: ='2'!R26 -> 8.6075719 | D7: ='2'!F23 -> 6.6075719 | E7: ='2'!G23 -> 0 | F7: ='2'!H23 -> 2 | G7: ='2'!I23 -> 0 | H7: ='2'!J23 -> 0 | I7: ='2'!K23 -> 4.6075719 | J7: ='2'!L23 -> 4 | K7: ='2'!M23 -> 0 | ... S7: ='2'!U23 -> 0 | T7: =IF(SUM(D7:H7)=0,"— não preenchido",IF(ROUND(SUM(D7:H7)-C7,3)=0,"OK","ERRO — dif. de "&ROUND(SUM(D7:H7)-C7,3)&" km")) -> OK
A8: 3 | B8: RODOVIA TO-010 - TRECHO ARAGUATINS - ENTR. TO-201 | C8: ='3'!R63 -> 41.607009 | D8: ='3'!F60 -> 30.607009 | E8: ='3'!G60 -> 11 | F8: ='3'!H60 -> 0 | G8: ='3'!I60 -> 0 | H8: ='3'!J60 -> 0 | I8: ='3'!K60 -> 5.8518241 | J8: ='3'!L60 -> 35.755185 | K8: ='3'!M60 -> 0 | ... S8: ='3'!U60 -> 0 | T8: =IF(SUM(D8:H8)=0,"— não preenchido",IF(ROUND(SUM(D8:H8)-C8,3)=0,"OK","ERRO — dif. de "&ROUND(SUM(D8:H8)-C8,3)&" km")) -> OK
A9: 4 | B9: RODOVIA TO-010 - TRECHO BURITI DO TOCANTINS (ENTR. TO-201) - SÃO SEBASTIÃO DO TOCANTINS | C9: ='4'!R29 -> 9.2499338 | D9: ='4'!F26 -> 5.589158 | E9: ='4'!G26 -> 3.6607758 | F9: ='4'!H26 -> 0 | G9: ='4'!I26 -> 0 | H9: ='4'!J26 -> 0 | I9: ='4'!K26 -> 0 | J9: ='4'!L26 -> 9.2499338 | K9: ='4'!M26 -> 0 | ... S9: ='4'!U26 -> 0 | T9: =IF(SUM(D9:H9)=0,"— não preenchido",IF(ROUND(SUM(D9:H9)-C9,3)=0,"OK","ERRO — dif. de "&ROUND(SUM(D9:H9)-C9,3)&" km")) -> OK
A10: 5 | B10: RODOVIA TO-126 - TRECHO TOCANTINÓPOLIS - ENTR. BR-230 (AGUIARNÓPOLIS) | C10: ='5'!R52 -> 30.23918 | D10: ='5'!F49 -> 21.142364 | E10: ='5'!G49 -> 1.2344796 | F10: ='5'!H49 -> 7.8623358 | G10: ='5'!I49 -> 0 | H10: ='5'!J49 -> 0 | I10: ='5'!K49 -> 0 | J10: ='5'!L49 -> 30.23918 | K10: ='5'!M49 -> 0 | ... S10: ='5'!U49 -> 0 | T10: =IF(SUM(D10:H10)=0,"— não preenchido",IF(ROUND(SUM(D10:H10)-C10,3)=0,"OK","ERRO — dif. de "&ROUND(SUM(D10:H10)-C10,3)&" km")) -> OK
A11: 6 | B11: RODOVIA TO-126 - TRECHO MAURILÂNDIA - TOCANTINÓPOLIS | C11: ='6'!R27 -> 8.5139277 | D11: ='6'!F24 -> 5.5139277 | E11: ='6'!G24 -> 1 | F11: ='6'!H24 -> 0 | G11: ='6'!I24 -> 2 | H11: ='6'!J24 -> 0 | I11: ='6'!K24 -> 0 | J11: ='6'!L24 -> 8.5139277 | K11: ='6'!M24 -> 0 | ... S11: ='6'!U24 -> 0 | T11: =IF(SUM(D11:H11)=0,"— não preenchido",IF(ROUND(SUM(D11:H11)-C11,3)=0,"OK","ERRO — dif. de "&ROUND(SUM(D11:H11)-C11,3)&" km")) -> OK
A12: 7 | B12: RODOVIA TO-126 - TRECHO ITAGUATINS - MAURILÂNDIA DO TOCANTINS | C12: ='7'!R40 -> 21.660088 | D12: ='7'!F37 -> 13.660088 | E12: ='7'!G37 -> 3 | F12: ='7'!H37 -> 0 | G12: ='7'!I37 -> 5 | H12: ='7'!J37 -> 0 | I12: ='7'!K37 -> 0 | J12: ='7'!L37 -> 21.660088 | K12: ='7'!M37 -> 15.660088 | ... S12: ='7'!U37 -> 0 | T12: =IF(SUM(D12:H12)=0,"— não preenchido",IF(ROUND(SUM(D12:H12)-C12,3)=0,"OK","ERRO — dif. de "&ROUND(SUM(D12:H12)-C12,3)&" km")) -> OK
A13: 8 | B13: RODOVIA TO-126 - TRECHO SÍTIO NOVO DO TOCANTINS - ITAGUATINS | C13: ='8'!R45 -> 25.376613 | D13: ='8'!F42 -> 20.376613 | E13: ='8'!G42 -> 5 | F13: ='8'!H42 -> 0 | G13: ='8'!I42 -> 0 | H13: ='8'!J42 -> 0 | I13: ='8'!K42 -> 0 | J13: ='8'!L42 -> 25.376613 | K13: ='8'!M42 -> 1.0211831 | ... S13: ='8'!U42 -> 10.35543 | T13: =IF(SUM(D13:H13)=0,"— não preenchido",IF(ROUND(SUM(D13:H13)-C13,3)=0,"OK","ERRO — dif. de "&ROUND(SUM(D13:H13)-C13,3)&" km")) -> OK
A14: 9 | B14: RODOVIA TO-126 - TRECHO SUMAUMA - SÍTIO NOVO DO TOCANTINS | C14: ='9'!R37 -> 16.674968 | D14: ='9'!F34 -> 16.674968 | E14: ='9'!G34 -> 0 | F14: ='9'!H34 -> 0 | G14: ='9'!I34 -> 0 | H14: ='9'!J34 -> 0 | I14: ='9'!K34 -> 0 | J14: ='9'!L34 -> 16.674968 | K14: ='9'!M34 -> 0 | ... S14: ='9'!U34 -> 0 | T14: =IF(SUM(D14:H14)=0,"— não preenchido",IF(ROUND(SUM(D14:H14)-C14,3)=0,"OK","ERRO — dif. de "&ROUND(SUM(D14:H14)-C14,3)&" km")) -> OK
A15: 10 | B15: RODOVIA TO-134 - TRECHO ANGICO - DARCINÓPOLIS | C15: ='10'!R64 -> 45.347802 | D15: ='10'!F61 -> 37.347802 | E15: ='10'!G61 -> 4 | F15: ='10'!H61 -> 4 | G15: ='10'!I61 -> 0 | H15: ='10'!J61 -> 0 | I15: ='10'!K61 -> 0 | J15: ='10'!L61 -> 45.347802 | K15: ='10'!M61 -> 0 | ... S15: ='10'!U61 -> 4 | T15: =IF(SUM(D15:H15)=0,"— não preenchido",IF(ROUND(SUM(D15:H15)-C15,3)=0,"OK","ERRO — dif. de "&ROUND(SUM(D15:H15)-C15,3)&" km")) -> OK
A16: 11 | B16: RODOVIA TO-134 - TRECHO LUZINÓPOLIS - ANGICO | C16: ='11'!R46 -> 24.440194 | D16: ='11'!F43 -> 12.635449 | E16: ='11'!G43 -> 0 | F16: ='11'!H43 -> 11.804745 | G16: ='11'!I43 -> 0 | H16: ='11'!J43 -> 0 | I16: ='11'!K43 -> 0 | J16: ='11'!L43 -> 24.440194 | K16: ='11'!M43 -> 0 | ... S16: ='11'!U43 -> 12.221001 | T16: =IF(SUM(D16:H16)=0,"— não preenchido",IF(ROUND(SUM(D16:H16)-C16,3)=0,"OK","ERRO — dif. de "&ROUND(SUM(D16:H16)-C16,3)&" km")) -> OK
A17: 13 | B17: RODOVIA TO-134 - TRECHO AXIXÁ DO TOCANTINS - ENTR. BR-230 | C17: ='13'!R68 -> 46.217171 | D17: ='13'!F65 -> 20.217171 | E17: ='13'!G65 -> 12 | F17: ='13'!H65 -> 14 | G17: ='13'!I65 -> 0 | H17: ='13'!J65 -> 0 | I17: ='13'!K65 -> 0 | J17: ='13'!L65 -> 46.217171 | K17: ='13'!M65 -> 0 | ... S17: ='13'!U65 -> 0 | T17: =IF(SUM(D17:H17)=0,"— não preenchido",IF(ROUND(SUM(D17:H17)-C17,3)=0,"OK","ERRO — dif. de "&ROUND(SUM(D17:H17)-C17,3)&" km")) -> OK
A18: 14 | B18: RODOVIA TO-201 - TRECHO DIV. TO-MA - SÃO MIGUEL DO TOCANTINS | C18: ='14'!R36 -> 15.910658 | D18: ='14'!F33 -> 11.910658 | E18: ='14'!G33 -> 0 | F18: ='14'!H33 -> 2 | G18: ='14'!I33 -> 2 | H18: ='14'!J33 -> 0 | I18: ='14'!K33 -> 0 | J18: ='14'!L33 -> 15.910658 | K18: ='14'!M33 -> 2.3736173 | ... S18: ='14'!U33 -> 0 | T18: =IF(SUM(D18:H18)=0,"— não preenchido",IF(ROUND(SUM(D18:H18)-C18,3)=0,"OK","ERRO — dif. de "&ROUND(SUM(D18:H18)-C18,3)&" km")) -> OK
A19: 15 | B19: RODOVIA TO-201 - TRECHO SÃO MIGUEL DO TOCANTINS - SÍTIO NOVO DO TOCANTINS | C19: ='15'!R27 -> 7.2751425 | D19: ='15'!F24 -> 5.2751425 | E19: ='15'!G24 -> 2 | F19: ='15'!H24 -> 0 | G19: ='15'!I24 -> 0 | H19: ='15'!J24 -> 0 | I19: ='15'!K24 -> 0 | J19: ='15'!L24 -> 7.2751425 | K19: ='15'!M24 -> 0 | ... S19: ='15'!U24 -> 0 | T19: =IF(SUM(D19:H19)=0,"— não preenchido",IF(ROUND(SUM(D19:H19)-C19,3)=0,"OK","ERRO — dif. de "&ROUND(SUM(D19:H19)-C19,3)&" km")) -> OK
A20: 16 | B20: RODOVIA TO-201 - TRECHO SÍTIO NOVO DO TOCANTINS - AXIXÁ DO TOCANTINS | C20: ='16'!R33 -> 14.071587 | D20: ='16'!F30 -> 12.071587 | E20: ='16'!G30 -> 2 | F20: ='16'!H30 -> 0 | G20: ='16'!I30 -> 0 | H20: ='16'!J30 -> 0 | I20: ='16'!K30 -> 0 | J20: ='16'!L30 -> 14.071587 | K20: ='16'!M30 -> 0 | ... S20: ='16'!U30 -> 0 | T20: =IF(SUM(D20:H20)=0,"— não preenchido",IF(ROUND(SUM(D20:H20)-C20,3)=0,"OK","ERRO — dif. de "&ROUND(SUM(D20:H20)-C20,3)&" km")) -> OK
A21: 17 | B21: RODOVIA TO-201 - TRECHO AXIXÁ DO TOCANTINS - AUGUSTINÓPOLIS | C21: ='17'!R39 -> 20.068317 | D21: ='17'!F36 -> 0 | E21: ='17'!G36 -> 0 | F21: ='17'!H36 -> 20.068317 | G21: ='17'!I36 -> 0 | H21: ='17'!J36 -> 0 | I21: ='17'!K36 -> 20.068317 | J21: ='17'!L36 -> 0 | K21: ='17'!M36 -> 20.068317 | ... S21: ='17'!U36 -> 0 | T21: =IF(SUM(D21:H21)=0,"— não preenchido",IF(ROUND(SUM(D21:H21)-C21,3)=0,"OK","ERRO — dif. de "&ROUND(SUM(D21:H21)-C21,3)&" km")) -> OK
A22: 18 | B22: RODOVIA TO-201 - TRECHO AUGUSTINÓPOLIS - BURITI DO TOCANTINS | C22: ='18'!R65 -> 40.314887 | D22: ='18'!F62 -> 37.314887 | E22: ='18'!G62 -> 3 | F22: ='18'!H62 -> 0 | G22: ='18'!I62 -> 0 | H22: ='18'!J62 -> 0 | I22: ='18'!K62 -> 0 | J22: ='18'!L62 -> 40.314887 | K22: ='18'!M62 -> 24.039445 | ... S22: ='18'!U62 -> 0 | T22: =IF(SUM(D22:H22)=0,"— não preenchido",IF(ROUND(SUM(D22:H22)-C22,3)=0,"OK","ERRO — dif. de "&ROUND(SUM(D22:H22)-C22,3)&" km")) -> OK
A23: 19 | B23: RODOVIA TO-201 - TRECHO BURITI DO TOCANTINS - ESPERANTINA | C23: ='19'!R67 -> 43.104487 | D23: ='19'!F64 -> 39.484898 | E23: ='19'!G64 -> 3.6195886 | F23: ='19'!H64 -> 0 | G23: ='19'!I64 -> 0 | H23: ='19'!J64 -> 0 | I23: ='19'!K64 -> 0 | J23: ='19'!L64 -> 43.104487 | K23: ='19'!M64 -> 0 | ... S23: ='19'!U64 -> 34.484898 | T23: =IF(SUM(D23:H23)=0,"— não preenchido",IF(ROUND(SUM(D23:H23)-C23,3)=0,"OK","ERRO — dif. de "&ROUND(SUM(D23:H23)-C23,3)&" km")) -> OK
A24: 23 | B24: RODOVIA TO-210 - TRECHO ANGICO - ANANÁS | C24: ='23'!R46 -> 26.530277 | D24: ='23'!F43 -> 16.184972 | E24: ='23'!G43 -> 6.3453045 | F24: ='23'!H43 -> 0 | G24: ='23'!I43 -> 2 | H24: ='23'!J43 -> 2 | I24: ='23'!K43 -> 0 | J24: ='23'!L43 -> 26.530277 | K24: ='23'!M43 -> 0 | ... S24: ='23'!U43 -> 26.530277 | T24: =IF(SUM(D24:H24)=0,"— não preenchido",IF(ROUND(SUM(D24:H24)-C24,3)=0,"OK","ERRO — dif. de "&ROUND(SUM(D24:H24)-C24,3)&" km")) -> OK
A25: 24 | B25: RODOVIA TO-210 - TRECHO NAZARÉ - ENTR. TO-134 (POVOADO GROTÃO DE NAZARÉ) | C25: ='24'!R52 -> 25.447539 | D25: ='24'!F49 -> 4.6394745 | E25: ='24'!G49 -> 2 | F25: ='24'!H49 -> 9.1506575 | G25: ='24'!I49 -> 2.3621002 | H25: ='24'!J49 -> 7.2953065 | I25: ='24'!K49 -> 0 | J25: ='24'!L49 -> 25.447539 | K25: ='24'!M49 -> 0 | ... S25: ='24'!U49 -> 0 | T25: =IF(SUM(D25:H25)=0,"— não preenchido",IF(ROUND(SUM(D25:H25)-C25,3)=0,"OK","ERRO — dif. de "&ROUND(SUM(D25:H25)-C25,3)&" km")) -> OK
A26: 25 | B26: RODOVIA TO-210 - TRECHO TOCANTINÓPOLIS - NAZARÉ | C26: ='25'!R39 -> 16.825508 | D26: ='25'!F36 -> 12.825508 | E26: ='25'!G36 -> 3 | F26: ='25'!H36 -> 0 | G26: ='25'!I36 -> 1 | H26: ='25'!J36 -> 0 | I26: ='25'!K36 -> 0 | J26: ='25'!L36 -> 16.825508 | K26: ='25'!M36 -> 1.5199948 | ... S26: ='25'!U36 -> 0 | T26: =IF(SUM(D26:H26)=0,"— não preenchido",IF(ROUND(SUM(D26:H26)-C26,3)=0,"OK","ERRO — dif. de "&ROUND(SUM(D26:H26)-C26,3)&" km")) -> OK
A27: 28 | B27: RODOVIA TO-403 - TRECHO SAMPAIO - ENTR. TO-404 (ITAÚBA) | C27: ='28'!R28 -> 9.4504956 | D27: ='28'!F25 -> 9.4504956 | E27: ='28'!G25 -> 0 | F27: ='28'!H25 -> 0 | G27: ='28'!I25 -> 0 | H27: ='28'!J25 -> 0 | I27: ='28'!K25 -> 0 | J27: ='28'!L25 -> 9.4504956 | K27: ='28'!M25 -> 0 | ... S27: ='28'!U25 -> 0 | T27: =IF(SUM(D27:H27)=0,"— não preenchido",IF(ROUND(SUM(D27:H27)-C27,3)=0,"OK","ERRO — dif. de "&ROUND(SUM(D27:H27)-C27,3)&" km")) -> OK
A28: 29 | B28: RODOVIA TO-404 - TRECHO AUGUSTINÓPOLIS - ENTR. TO-010 (POVOADO MATA VELHA) | C28: ='29'!R47 -> 25.842845 | D28: ='29'!F44 -> 13.510177 | E28: ='29'!G44 -> 0 | F28: ='29'!H44 -> 12.332668 | G28: ='29'!I44 -> 0 | H28: ='29'!J44 -> 0 | I28: ='29'!K44 -> 25.842845 | J28: ='29'!L44 -> 0 | K28: ='29'!M44 -> 0 | ... S28: ='29'!U44 -> 0 | T28: =IF(SUM(D28:H28)=0,"— não preenchido",IF(ROUND(SUM(D28:H28)-C28,3)=0,"OK","ERRO — dif. de "&ROUND(SUM(D28:H28)-C28,3)&" km")) -> OK
A29: 30 | B29: RODOVIA TO-404 - TRECHO AUGUSTINÓPOLIS - PRAIA NORTE | C29: ='30'!R32 -> 12.103765 | D29: ='30'!F29 -> 7.1037646 | E29: ='30'!G29 -> 0 | F29: ='30'!H29 -> 0 | G29: ='30'!I29 -> 5 | H29: ='30'!J29 -> 0 | I29: ='30'!K29 -> 6.0749263 | J29: ='30'!L29 -> 6.0288383 | K29: ='30'!M29 -> 0 | ... S29: ='30'!U29 -> 0 | T29: =IF(SUM(D29:H29)=0,"— não preenchido",IF(ROUND(SUM(D29:H29)-C29,3)=0,"OK","ERRO — dif. de "&ROUND(SUM(D29:H29)-C29,3)&" km")) -> OK
A30: 32 | B30: RODOVIA TO-407 - TRECHO CARRASCO BONITO - ENTR. TO-201 (POVOADO CENTRO DOS FIRMINOS) | C30: ='32'!R25 -> 7.687745 | D30: ='32'!F22 -> 7.687745 | E30: ='32'!G22 -> 0 | F30: ='32'!H22 -> 0 | G30: ='32'!I22 -> 0 | H30: ='32'!J22 -> 0 | I30: ='32'!K22 -> 0 | J30: ='32'!L22 -> 7.687745 | K30: ='32'!M22 -> 0 | ... S30: ='32'!U22 -> 0 | T30: =IF(SUM(D30:H30)=0,"— não preenchido",IF(ROUND(SUM(D30:H30)-C30,3)=0,"OK","ERRO — dif. de "&ROUND(SUM(D30:H30)-C30,3)&" km")) -> OK
A31: 35 | B31: RODOVIA TO-415 - TRECHO SANTA TEREZINHA DO TOCANTINS - PALMEIRAS DO TOCANTINS | C31: ='35'!R44 -> 24.997735 | D31: ='35'!F41 -> 21.997735 | E31: ='35'!G41 -> 0 | F31: ='35'!H41 -> 0 | G31: ='35'!I41 -> 3 | H31: ='35'!J41 -> 0 | I31: ='35'!K41 -> 0 | J31: ='35'!L41 -> 24.997735 | K31: ='35'!M41 -> 0 | ... S31: ='35'!U41 -> 1.0854501 | T31: =IF(SUM(D31:H31)=0,"— não preenchido",IF(ROUND(SUM(D31:H31)-C31,3)=0,"OK","ERRO — dif. de "&ROUND(SUM(D31:H31)-C31,3)&" km")) -> OK
A32: 36 | B32: RODOVIA TO-415 - TRECHO NAZARÉ - SANTA TEREZINHA DO TOCANTINS | C32: ='36'!R25 -> 6.2442193 | D32: ='36'!F22 -> 6.2442193 | E32: ='36'!G22 -> 0 | F32: ='36'!H22 -> 0 | G32: ='36'!I22 -> 0 | H32: ='36'!J22 -> 0 | I32: ='36'!K22 -> 0 | J32: ='36'!L22 -> 6.2442193 | K32: ='36'!M22 -> 0 | ... S32: ='36'!U22 -> 0 | T32: =IF(SUM(D32:H32)=0,"— não preenchido",IF(ROUND(SUM(D32:H32)-C32,3)=0,"OK","ERRO — dif. de "&ROUND(SUM(D32:H32)-C32,3)&" km")) -> OK
A33: 38 | B33: RODOVIA TO-416 - TRECHO ANANÁS - ENTR. TO-010 | C33: ='38'!R27 -> 8.0232806 | D33: ='38'!F24 -> 1 | E33: ='38'!G24 -> 7.0232806 | F33: ='38'!H24 -> 0 | G33: ='38'!I24 -> 0 | H33: ='38'!J24 -> 0 | I33: ='38'!K24 -> 0 | J33: ='38'!L24 -> 8.0232806 | K33: ='38'!M24 -> 0 | ... S33: ='38'!U24 -> 8.0232806 | T33: =IF(SUM(D33:H33)=0,"— não preenchido",IF(ROUND(SUM(D33:H33)-C33,3)=0,"OK","ERRO — dif. de "&ROUND(SUM(D33:H33)-C33,3)&" km")) -> OK
B34: TOTAL PERCORRIDO NO MÊS | C34: =SUM(C6:C33) -> 591.53065 | D34: =SUM(D6:D33) -> 406.77109 | E34: =SUM(E6:E33) -> 69.883429 | F34: =SUM(F6:F33) -> 83.218724 | G34: =SUM(G6:G33) -> 22.3621 | H34: =SUM(H6:H33) -> 9.2953065 | I34: =SUM(I6:I33) -> 62.445485 | J34: =SUM(J6:J33) -> 529.08517 | ... S34: =SUM(S6:S33) -> 103.53129
B35: % DA EXTENSÃO DA MALHA (591.53 km) | D35: =SUM(D34:H34)/591.53 -> 1.0000011 | I35: (soma do grupo 'CONDIÇÃO DO PAVIMENTO' dividida pela malha)

Sheet 1
A1: PROGRAMA DE MANUTENÇÃO RODOVIÁRIA — FICHA DE INSPEÇÃO — RODOVIAS PAVIMENTADAS | Y1: Valores dos gráficos — troca 0 por N/D para a fatia não aparecer. Não editar.
A2: REGIÃO: 1 — TOCANTINÓPOLIS | G2: MÊS / ANO: | I2: 46266 | K2: DATA: | P2: TÉCNICO: | R2: ENG. VINICIUS RODRIGUES FERREIRA DE OLIVEIRA | Y2: =IF(F29=0,NA(),F29) -> 9.697707 | Z2: =IF(G29=0,NA(),G29) -> #N/A | AA2: =IF(H29=0,NA(),H29) -> #N/A | AB2: =IF(I29=0,NA(),I29) -> #N/A | AC2: =IF(J29=0,NA(),J29) -> #N/A | AD2: =IF(K29=0,NA(),K29) -> #N/A | AE2: =IF(L29=0,NA(),L29) -> 9.697707 | AF2: =IF(M29=0,NA(),M29) -> #N/A | ... AN2: =IF(U29=0,NA(),U29) -> 6.8309561
A3: TRECHO 1 — RODOVIA TO-010 - TRECHO ANANÁS - ENTR. BR-230 | T3: EXTENSÃO: 9,698 km · 5 S.R.E.
A4: COMO PREENCHER: uma X em UMA coluna de cada grupo, por linha. Se houver mais de um defeito no mesmo km, marque o PREDOMINANTE e escreva o resto em OBSERVAÇÕES. A quilometragem é contada de 0 até o fim de CADA S.R.E. (não é o marco da rodovia).
A6: S.R.E. | B6: SENT. | C6: INÍCIO (KM) | D6: FIM (KM) | E6: EXT. (KM) | F6: CONDIÇÃO DO PAVIMENTO | K6: VEGETAÇÃO | M6: ELEM. DE DRENAGEM | P6: SIN. HORIZ. | S6: SIN. VERTICAL | V6: OBSERVAÇÕES | W6: CONFERÊNCIA (só na tela)
F7: BOM | G7: REM. I. | H7: REM. L. | I7: BUR. I. | J7: BUR. L. | K7: ADEQ. | L7: INAD. | M7: LIMPOS | N7: SUJOS | O7: DAN. | P7: BOM | Q7: REG. | R7: INEXIST. | S7: BOM | T7: POUCAS | U7: INEXIST.
A8: S.R.E. 010ETO0511 | ANANÁS *TRECHO URBANO* | PSU · Municipal · 0.877 km · sem coordenada no shape
A9: 010ETO0511 | B9: C | C9: 0 | D9: 0.87749259 | E9: =D9-C9 -> 0.87749259 | F9: X | L9: X | N9: X | R9: X | T9: X | W9: =IF(COUNTA(F9:U9)=0,"— não preenchido",IF(COUNTIF(F9:J9,"X")<>1,"FALTA/DUPLA: CONDIÇÃO DO PAVIMENTO",IF(COUNTIF(K9:L9,"X")<>1,"FALTA/DUPLA: VEGETAÇÃO",IF(COUNTIF(M9:O9,"X")<>1,"FALTA/DUPLA: ELEM. DE DRENAGEM",IF(COUNTIF(P9:R9,"X")<>1,"FALTA/DUPLA: SIN. HORIZ.",IF(COUNTIF(S9:U9,"X")<>1,"FALTA/DUPLA: SIN. VERTICAL","OK")))))) -> OK
A10: S.R.E. 010ETO0512D | ANANÁS *TRECHO URBANO* (código antigo: 010ETO0512) | PSU · Municipal · 1.989 km · início: -6.372561, -48.068896
A11: 010ETO0512D | B11: C | C11: 0 | D11: 1 | E11: =D11-C11 -> 1 | F11: X | L11: X | N11: X | R11: X | T11: X | W11: =IF(COUNTA(F11:U11)=0,"— não preenchido",IF(COUNTIF(F11:J11,"X")<>1,"FALTA/DUPLA: CONDIÇÃO DO PAVIMENTO",IF(COUNTIF(K11:L11,"X")<>1,"FALTA/DUPLA: VEGETAÇÃO",IF(COUNTIF(M11:O11,"X")<>1,"FALTA/DUPLA: ELEM. DE DRENAGEM",IF(COUNTIF(P11:R11,"X")<>1,"FALTA/DUPLA: SIN. HORIZ.",IF(COUNTIF(S11:U11,"X")<>1,"FALTA/DUPLA: SIN. VERTICAL","OK")))))) -> OK
A12: 010ETO0512D | B12: C | C12: 1 | D12: 1.9892583 | E12: =D12-C12 -> 0.98925833 | F12: X | L12: X | N12: X | R12: X | T12: X | W12: =IF(COUNTA(F12:U12)=0,"— não preenchido",IF(COUNTIF(F12:J12,"X")<>1,"FALTA/DUPLA: CONDIÇÃO DO PAVIMENTO",IF(COUNTIF(K12:L12,"X")<>1,"FALTA/DUPLA: VEGETAÇÃO",IF(COUNTIF(M12:O12,"X")<>1,"FALTA/DUPLA: ELEM. DE DRENAGEM",IF(COUNTIF(P12:R12,"X")<>1,"FALTA/DUPLA: SIN. HORIZ.",IF(COUNTIF(S12:U12,"X")<>1,"FALTA/DUPLA: SIN. VERTICAL","OK")))))) -> OK
A13: S.R.E. 010ETO0540 | ANANÁS *TRECHO URBANO* - ENTR. TO-414(TAPUIO) | PPS · Estadual · 3.810 km · início: -6.358384, -48.076141
A14: 010ETO0540 | B14: C | C14: 0 | D14: 1 | E14: =D14-C14 -> 1 | F14: X | L14: X | O14: x | R14: X | U14: X | W14: =IF(COUNTA(F14:U14)=0,"— não preenchido",IF(COUNTIF(F14:J14,"X")<>1,"FALTA/DUPLA: CONDIÇÃO DO PAVIMENTO",IF(COUNTIF(K14:L14,"X")<>1,"FALTA/DUPLA: VEGETAÇÃO",IF(COUNTIF(M14:O14,"X")<>1,"FALTA/DUPLA: ELEM. DE DRENAGEM",IF(COUNTIF(P14:R14,"X")<>1,"FALTA/DUPLA: SIN. HORIZ.",IF(COUNTIF(S14:U14,"X")<>1,"FALTA/DUPLA: SIN. VERTICAL","OK")))))) -> OK
A15: 010ETO0540 | B15: C | C15: 1 | D15: 2 | E15: =D15-C15 -> 1 | F15: X | L15: X | O15: x | R15: X | U15: X | W15: =IF(COUNTA(F15:U15)=0,"— não preenchido",IF(COUNTIF(F15:J15,"X")<>1,"FALTA/DUPLA: CONDIÇÃO DO PAVIMENTO",IF(COUNTIF(K15:L15,"X")<>1,"FALTA/DUPLA: VEGETAÇÃO",IF(COUNTIF(M15:O15,"X")<>1,"FALTA/DUPLA: ELEM. DE DRENAGEM",IF(COUNTIF(P15:R15,"X")<>1,"FALTA/DUPLA: SIN. HORIZ.",IF(COUNTIF(S15:U15,"X")<>1,"FALTA/DUPLA: SIN. VERTICAL","OK")))))) -> OK
A16: 010ETO0540 | B16: C | C16: 2 | D16: 3 | E16: =D16-C16 -> 1 | F16: X | L16: X | O16: x | R16: X | U16: X | W16: =IF(COUNTA(F16:U16)=0,"— não preenchido",IF(COUNTIF(F16:J16,"X")<>1,"FALTA/DUPLA: CONDIÇÃO DO PAVIMENTO",IF(COUNTIF(K16:L16,"X")<>1,"FALTA/DUPLA: VEGETAÇÃO",IF(COUNTIF(M16:O16,"X")<>1,"FALTA/DUPLA: ELEM. DE DRENAGEM",IF(COUNTIF(P16:R16,"X")<>1,"FALTA/DUPLA: SIN. HORIZ.",IF(COUNTIF(S16:U16,"X")<>1,"FALTA/DUPLA: SIN. VERTICAL","OK")))))) -> OK
A17: 010ETO0540 | B17: C | C17: 3 | D17: 3.8103285 | E17: =D17-C17 -> 0.81032849 | F17: X | L17: X | O17: x | R17: X | U17: X | W17: =IF(COUNTA(F17:U17)=0,"— não preenchido",IF(COUNTIF(F17:J17,"X")<>1,"FALTA/DUPLA: CONDIÇÃO DO PAVIMENTO",IF(COUNTIF(K17:L17,"X")<>1,"FALTA/DUPLA: VEGETAÇÃO",IF(COUNTIF(M17:O17,"X")<>1,"FALTA/DUPLA: ELEM. DE DRENAGEM",IF(COUNTIF(P17:R17,"X")<>1,"FALTA/DUPLA: SIN. HORIZ.",IF(COUNTIF(S17:U17,"X")<>1,"FALTA/DUPLA: SIN. VERTICAL","OK")))))) -> OK
A18: S.R.E. 010ETO0550 | ENTR. TO-414 (TAPUIO) - ENTR. TO-210 | PPS · Estadual · 1.665 km · início: -6.325908, -48.089781
A19: 010ETO0550 | B19: C | C19: 0 | D19: 1 | E19: =D19-C19 -> 1 | F19: x | L19: X | O19: x | R19: X | U19: X | W19: =IF(COUNTA(F19:U19)=0,"— não preenchido",IF(COUNTIF(F19:J19,"X")<>1,"FALTA/DUPLA: CONDIÇÃO DO PAVIMENTO",IF(COUNTIF(K19:L19,"X")<>1,"FALTA/DUPLA: VEGETAÇÃO",IF(COUNTIF(M19:O19,"X")<>1,"FALTA/DUPLA: ELEM. DE DRENAGEM",IF(COUNTIF(P19:R19,"X")<>1,"FALTA/DUPLA: SIN. HORIZ.",IF(COUNTIF(S19:U19,"X")<>1,"FALTA/DUPLA: SIN. VERTICAL","OK")))))) -> OK
A20: 010ETO0550 | B20: C | C20: 1 | D20: 1.6653951 | E20: =D20-C20 -> 0.6653951 | F20: x | L20: X | O20: x | R20: X | U20: X | W20: =IF(COUNTA(F20:U20)=0,"— não preenchido",IF(COUNTIF(F20:J20,"X")<>1,"FALTA/DUPLA: CONDIÇÃO DO PAVIMENTO",IF(COUNTIF(K20:L20,"X")<>1,"FALTA/DUPLA: VEGETAÇÃO",IF(COUNTIF(M20:O20,"X")<>1,"FALTA/DUPLA: ELEM. DE DRENAGEM",IF(COUNTIF(P20:R20,"X")<>1,"FALTA/DUPLA: SIN. HORIZ.",IF(COUNTIF(S20:U20,"X")<>1,"FALTA/DUPLA: SIN. VERTICAL","OK")))))) -> OK
A21: S.R.E. 010ETO0555 | ENTR. TO-210 - FIM PAVIMENTACAO | PPS · Estadual · 1.355 km · início: -6.314958, -48.096642
A22: 010ETO0555 | B22: C | C22: 0 | D22: 1 | E22: =D22-C22 -> 1 | F22: X | L22: X | O22: X | R22: X | U22: X | W22: =IF(COUNTA(F22:U22)=0,"— não preenchido",IF(COUNTIF(F22:J22,"X")<>1,"FALTA/DUPLA: CONDIÇÃO DO PAVIMENTO",IF(COUNTIF(K22:L22,"X")<>1,"FALTA/DUPLA: VEGETAÇÃO",IF(COUNTIF(M22:O22,"X")<>1,"FALTA/DUPLA: ELEM. DE DRENAGEM",IF(COUNTIF(P22:R22,"X")<>1,"FALTA/DUPLA: SIN. HORIZ.",IF(COUNTIF(S22:U22,"X")<>1,"FALTA/DUPLA: SIN. VERTICAL","OK")))))) -> OK
A23: 010ETO0555 | B23: C | C23: 1 | D23: 1.3552325 | E23: =D23-C23 -> 0.35523247 | F23: X | L23: X | O23: X | R23: X | U23: X | W23: =IF(COUNTA(F23:U23)=0,"— não preenchido",IF(COUNTIF(F23:J23,"X")<>1,"FALTA/DUPLA: CONDIÇÃO DO PAVIMENTO",IF(COUNTIF(K23:L23,"X")<>1,"FALTA/DUPLA: VEGETAÇÃO",IF(COUNTIF(M23:O23,"X")<>1,"FALTA/DUPLA: ELEM. DE DRENAGEM",IF(COUNTIF(P23:R23,"X")<>1,"FALTA/DUPLA: SIN. HORIZ.",IF(COUNTIF(S23:U23,"X")<>1,"FALTA/DUPLA: SIN. VERTICAL","OK")))))) -> OK
A25: ____________________________________________ | G25: ____________________________________________
A26: TÉCNICO RESPONSÁVEL PELA INSPEÇÃO | G26: VISTO DA SUPERVISÃO
A28: RESUMO DO TRECHO — KM LANÇADO POR ITEM
A29: KM LANÇADO | F29: =SUMIF(F$9:F$23,"X",$E$9:$E$23) -> 9.697707 | G29: =SUMIF(G$9:G$23,"X",$E$9:$E$23) -> 0 | H29: =SUMIF(H$9:H$23,"X",$E$9:$E$23) -> 0 | I29: =SUMIF(I$9:I$23,"X",$E$9:$E$23) -> 0 | J29: =SUMIF(J$9:J$23,"X",$E$9:$E$23) -> 0 | K29: =SUMIF(K$9:K$23,"X",$E$9:$E$23) -> 0 | L29: =SUMIF(L$9:L$23,"X",$E$9:$E$23) -> 9.697707 | M29: =SUMIF(M$9:M$23,"X",$E$9:$E$23) -> 0 | ... U29: =SUMIF(U$9:U$23,"X",$E$9:$E$23) -> 6.8309561
A30: % DA EXTENSÃO | F30: =IF($R32=0,0,F29/$R32) -> 1 | G30: =IF($R32=0,0,G29/$R32) -> 0 | H30: =IF($R32=0,0,H29/$R32) -> 0 | I30: =IF($R32=0,0,I29/$R32) -> 0 | J30: =IF($R32=0,0,J29/$R32) -> 0 | K30: =IF($R32=0,0,K29/$R32) -> 0 | L30: =IF($R32=0,0,L29/$R32) -> 1 | M30: =IF($R32=0,0,M29/$R32) -> 0 | ... U30: =IF($R32=0,0,U29/$R32) -> 0.70438879
A31: CONFERÊNCIA POR GRUPO | F31: =IF(SUM(F29:J29)=0,"— não preenchido",IF(ROUND(SUM(F29:J29)-$R32,3)=0,"OK — "&ROUND(SUM(F29:J29),3)&" km","ERRO — dif. de "&ROUND(SUM(F29:J29)-$R32,3)&" km")) -> OK — 9,698 km | K31: =IF(SUM(K29:L29)=0,"— não preenchido",IF(ROUND(SUM(K29:L29)-$R32,3)=0,"OK — "&ROUND(SUM(K29:L29),3)&" km","ERRO — dif. de "&ROUND(SUM(K29:L29)-$R32,3)&" km")) -> OK — 9,698 km | M31: =IF(SUM(M29:O29)=0,"— não preenchido",IF(ROUND(SUM(M29:O29)-$R32,3)=0,"OK — "&ROUND(SUM(M29:O29),3)&" km","ERRO — dif. de "&ROUND(SUM(M29:O29)-$R32,3)&" km")) -> OK — 9,698 km | P31: =IF(SUM(P29:R29)=0,"— não preenchido",IF(ROUND(SUM(P29:R29)-$R32,3)=0,"OK — "&ROUND(SUM(P29:R29),3)&" km","ERRO — dif. de "&ROUND(SUM(P29:R29)-$R32,3)&" km")) -> OK — 9,698 km | S31: =IF(SUM(S29:U29)=0,"— não preenchido",IF(ROUND(SUM(S29:U29)-$R32,3)=0,"OK — "&ROUND(SUM(S29:U29),3)&" km","ERRO — dif. de "&ROUND(SUM(S29:U29)-$R32,3)&" km")) -> OK — 9,698 km
A32: EXTENSÃO TOTAL DO TRECHO | R32: =SUM(E9:E23) -> 9.697707 | V32: =COUNTIF(W9:W23,"OK")&" de "&COUNT($E$9:$E$23)&" linhas conferidas" -> 11 de 11 linhas conferidas
A34: LEGENDA
A35: REM. I. / REM. L. | E35: Remendos isolados (até 10 por km) · Remendos ao longo (mais de 10 por km)
A36: BUR. I. / BUR. L. | E36: Buracos isolados (até 5 por km) · Buracos ao longo (mais de 5 por km)
A37: SIT. | E37: PPS = pista simples · PSU = simples urbana · PDU = duplicada
A38: FAIXA AZUL | E38: Cabeçalho de cada S.R.E.: descrição, situação, jurisdição, extensão e coordenada de início.
A39: INÍCIO / FIM (KM) | E39: Contados de 0 até o fim de CADA S.R.E. Não é o marco quilométrico da rodovia.
A40: SENT. | E40: C = crescente · D = decrescente
A41: FAIXA CINZA | E41: Segmento fora do escopo do contrato: você passa por ele, mas não preenche.
A42: CÉLULA VERMELHA | E42: Mais de uma X no mesmo grupo. Apague uma delas.
A43: CONFERÊNCIA | E43: Só na tela, não sai impresso. Fica OK com uma X em cada grupo.

Sheet 2
A1: PROGRAMA DE MANUTENÇÃO RODOVIÁRIA — FICHA DE INSPEÇÃO — RODOVIAS PAVIMENTADAS | Y1: Valores dos gráficos — troca 0 por N/D para a fatia não aparecer. Não editar.
A2: REGIÃO: 1 — TOCANTINÓPOLIS | G2: MÊS / ANO: | I2: =IF('1'!I2="","",'1'!I2) -> 46266 | K2: DATA: | N2: =IF('1'!N2="","",'1'!N2) | P2: TÉCNICO: | R2: ENG. VINICIUS RODRIGUES FERREIRA DE OLIVEIRA | Y2: =IF(F23=0,NA(),F23) -> 6.6075719 | Z2: =IF(G23=0,NA(),G23) -> #N/A | AA2: =IF(H23=0,NA(),H23) -> 2 | AB2: =IF(I23=0,NA(),I23) -> #N/A | AC2: =IF(J23=0,NA(),J23) -> #N/A | AD2: =IF(K23=0,NA(),K23) -> 4.6075719 | AE2: =IF(L23=0,NA(),L23) -> 4 | AF2: =IF(M23=0,NA(),M23) -> #N/A | ... AN2: =IF(U23=0,NA(),U23) -> #N/A
A3: TRECHO 2 — RODOVIA TO-010 - TRECHO ENTR. BR-230 - ARAGUATINS | T3: EXTENSÃO: 8,608 km · 1 S.R.E.
A4: COMO PREENCHER: uma X em UMA coluna de cada grupo, por linha. Se houver mais de um defeito no mesmo km, marque o PREDOMINANTE e escreva o resto em OBSERVAÇÕES. A quilometragem é contada de 0 até o fim de CADA S.R.E. (não é o marco da rodovia).
A6: S.R.E. | B6: SENT. | C6: INÍCIO (KM) | D6: FIM (KM) | E6: EXT. (KM) | F6: CONDIÇÃO DO PAVIMENTO | K6: VEGETAÇÃO | M6: ELEM. DE DRENAGEM | P6: SIN. HORIZ. | S6: SIN. VERTICAL | V6: OBSERVAÇÕES | W6: CONFERÊNCIA (só na tela)
F7: BOM | G7: REM. I. | H7: REM. L. | I7: BUR. I. | J7: BUR. L. | K7: ADEQ. | L7: INAD. | M7: LIMPOS | N7: SUJOS | O7: DAN. | P7: BOM | Q7: REG. | R7: INEXIST. | S7: BOM | T7: POUCAS | U7: INEXIST.
A8: S.R.E. 010ETO0640 | TRANSARAGUAIA (BR-230) - ARAGUATINS | PPS · Estadual · 8.608 km · início: -5.717331, -48.146858
A9: 010ETO0640 | B9: C | C9: 0 | D9: 1 | E9: =D9-C9 -> 1 | F9: X | K9: X | N9: X | Q9: X | T9: X | W9: =IF(COUNTA(F9:U9)=0,"— não preenchido",IF(COUNTIF(F9:J9,"X")<>1,"FALTA/DUPLA: CONDIÇÃO DO PAVIMENTO",IF(COUNTIF(K9:L9,"X")<>1,"FALTA/DUPLA: VEGETAÇÃO",IF(COUNTIF(M9:O9,"X")<>1,"FALTA/DUPLA: ELEM. DE DRENAGEM",IF(COUNTIF(P9:R9,"X")<>1,"FALTA/DUPLA: SIN. HORIZ.",IF(COUNTIF(S9:U9,"X")<>1,"FALTA/DUPLA: SIN. VERTICAL","OK")))))) -> OK
A10: 010ETO0640 | B10: C | C10: 1 | D10: 2 | E10: =D10-C10 -> 1 | F10: X | K10: X | N10: X | Q10: X | T10: X | W10: =IF(COUNTA(F10:U10)=0,"— não preenchido",IF(COUNTIF(F10:J10,"X")<>1,"FALTA/DUPLA: CONDIÇÃO DO PAVIMENTO",IF(COUNTIF(K10:L10,"X")<>1,"FALTA/DUPLA: VEGETAÇÃO",IF(COUNTIF(M10:O10,"X")<>1,"FALTA/DUPLA: ELEM. DE DRENAGEM",IF(COUNTIF(P10:R10,"X")<>1,"FALTA/DUPLA: SIN. HORIZ.",IF(COUNTIF(S10:U10,"X")<>1,"FALTA/DUPLA: SIN. VERTICAL","OK")))))) -> OK
A11: 010ETO0640 | B11: C | C11: 2 | D11: 3 | E11: =D11-C11 -> 1 | F11: X | L11: X | N11: X | R11: X | T11: X | W11: =IF(COUNTA(F11:U11)=0,"— não preenchido",IF(COUNTIF(F11:J11,"X")<>1,"FALTA/DUPLA: CONDIÇÃO DO PAVIMENTO",IF(COUNTIF(K11:L11,"X")<>1,"FALTA/DUPLA: VEGETAÇÃO",IF(COUNTIF(M11:O11,"X")<>1,"FALTA/DUPLA: ELEM. DE DRENAGEM",IF(COUNTIF(P11:R11,"X")<>1,"FALTA/DUPLA: SIN. HORIZ.",IF(COUNTIF(S11:U11,"X")<>1,"FALTA/DUPLA: SIN. VERTICAL","OK")))))) -> OK
A12: 010ETO0640 | B12: C | C12: 3 | D12: 4 | E12: =D12-C12 -> 1 | F12: X | K12: X | N12: X | R12: X | T12: X | W12: =IF(COUNTA(F12:U12)=0,"— não preenchido",IF(COUNTIF(F12:J12,"X")<>1,"FALTA/DUPLA: CONDIÇÃO DO PAVIMENTO",IF(COUNTIF(K12:L12,"X")<>1,"FALTA/DUPLA: VEGETAÇÃO",IF(COUNTIF(M12:O12,"X")<>1,"FALTA/DUPLA: ELEM. DE DRENAGEM",IF(COUNTIF(P12:R12,"X")<>1,"FALTA/DUPLA: SIN. HORIZ.",IF(COUNTIF(S12:U12,"X")<>1,"FALTA/DUPLA: SIN. VERTICAL","OK")))))) -> OK
A13: 010ETO0640 | B13: C | C13: 4 | D13: 5 | E13: =D13-C13 -> 1 | F13: X | L13: X | N13: X | Q13: X | T13: X | W13: =IF(COUNTA(F13:U13)=0,"— não preenchido",IF(COUNTIF(F13:J13,"X")<>1,"FALTA/DUPLA: CONDIÇÃO DO PAVIMENTO",IF(COUNTIF(K13:L13,"X")<>1,"FALTA/DUPLA: VEGETAÇÃO",IF(COUNTIF(M13:O13,"X")<>1,"FALTA/DUPLA: ELEM. DE DRENAGEM",IF(COUNTIF(P13:R13,"X")<>1,"FALTA/DUPLA: SIN. HORIZ.",IF(COUNTIF(S13:U13,"X")<>1,"FALTA/DUPLA: SIN. VERTICAL","OK")))))) -> OK
A14: 010ETO0640 | B14: C | C14: 5 | D14: 6 | E14: =D14-C14 -> 1 | F14: X | L14: X | N14: X | Q14: X | T14: X | W14: =IF(COUNTA(F14:U14)=0,"— não preenchido",IF(COUNTIF(F14:J14,"X")<>1,"FALTA/DUPLA: CONDIÇÃO DO PAVIMENTO",IF(COUNTIF(K14:L14,"X")<>1,"FALTA/DUPLA: VEGETAÇÃO",IF(COUNTIF(M14:O14,"X")<>1,"FALTA/DUPLA: ELEM. DE DRENAGEM",IF(COUNTIF(P14:R14,"X")<>1,"FALTA/DUPLA: SIN. HORIZ.",IF(COUNTIF(S14:U14,"X")<>1,"FALTA/DUPLA: SIN. VERTICAL","OK")))))) -> OK
A15: 010ETO0640 | B15: C | C15: 6 | D15: 7 | E15: =D15-C15 -> 1 | H15: X | L15: X | N15: X | R15: X | T15: X | W15: =IF(COUNTA(F15:U15)=0,"— não preenchido",IF(COUNTIF(F15:J15,"X")<>1,"FALTA/DUPLA: CONDIÇÃO DO PAVIMENTO",IF(COUNTIF(K15:L15,"X")<>1,"FALTA/DUPLA: VEGETAÇÃO",IF(COUNTIF(M15:O15,"X")<>1,"FALTA/DUPLA: ELEM. DE DRENAGEM",IF(COUNTIF(P15:R15,"X")<>1,"FALTA/DUPLA: SIN. HORIZ.",IF(COUNTIF(S15:U15,"X")<>1,"FALTA/DUPLA: SIN. VERTICAL","OK")))))) -> OK
A16: 010ETO0640 | B16: C | C16: 7 | D16: 8 | E16: =D16-C16 -> 1 | H16: X | K16: X | N16: X | R16: X | T16: X | W16: =IF(COUNTA(F16:U16)=0,"— não preenchido",IF(COUNTIF(F16:J16,"X")<>1,"FALTA/DUPLA: CONDIÇÃO DO PAVIMENTO",IF(COUNTIF(K16:L16,"X")<>1,"FALTA/DUPLA: VEGETAÇÃO",IF(COUNTIF(M16:O16,"X")<>1,"FALTA/DUPLA: ELEM. DE DRENAGEM",IF(COUNTIF(P16:R16,"X")<>1,"FALTA/DUPLA: SIN. HORIZ.",IF(COUNTIF(S16:U16,"X")<>1,"FALTA/DUPLA: SIN. VERTICAL","OK")))))) -> OK
A17: 010ETO0640 | B17: C | C17: 8 | D17: 8.6075719 | E17: =D17-C17 -> 0.60757187 | F17: X | K17: X | N17: X | Q17: X | T17: X | W17: =IF(COUNTA(F17:U17)=0,"— não preenchido",IF(COUNTIF(F17:J17,"X")<>1,"FALTA/DUPLA: CONDIÇÃO DO PAVIMENTO",IF(COUNTIF(K17:L17,"X")<>1,"FALTA/DUPLA: VEGETAÇÃO",IF(COUNTIF(M17:O17,"X")<>1,"FALTA/DUPLA: ELEM. DE DRENAGEM",IF(COUNTIF(P17:R17,"X")<>1,"FALTA/DUPLA: SIN. HORIZ.",IF(COUNTIF(S17:U17,"X")<>1,"FALTA/DUPLA: SIN. VERTICAL","OK")))))) -> OK
A19: ____________________________________________ | G19: ____________________________________________
A20: TÉCNICO RESPONSÁVEL PELA INSPEÇÃO | G20: VISTO DA SUPERVISÃO
A22: RESUMO DO TRECHO — KM LANÇADO POR ITEM
A23: KM LANÇADO | F23: =SUMIF(F$9:F$17,"X",$E$9:$E$17) -> 6.6075719 | G23: =SUMIF(G$9:G$17,"X",$E$9:$E$17) -> 0 | H23: =SUMIF(H$9:H$17,"X",$E$9:$E$17) -> 2 | I23: =SUMIF(I$9:I$17,"X",$E$9:$E$17) -> 0 | J23: =SUMIF(J$9:J$17,"X",$E$9:$E$17) -> 0 | K23: =SUMIF(K$9:K$17,"X",$E$9:$E$17) -> 4.6075719 | L23: =SUMIF(L$9:L$17,"X",$E$9:$E$17) -> 4 | M23: =SUMIF(M$9:M$17,"X",$E$9:$E$17) -> 0 | ... U23: =SUMIF(U$9:U$17,"X",$E$9:$E$17) -> 0
A24: % DA EXTENSÃO | F24: =IF($R26=0,0,F23/$R26) -> 0.76764644 | G24: =IF($R26=0,0,G23/$R26) -> 0 | H24: =IF($R26=0,0,H23/$R26) -> 0.23235356 | I24: =IF($R26=0,0,I23/$R26) -> 0 | J24: =IF($R26=0,0,J23/$R26) -> 0 | K24: =IF($R26=0,0,K23/$R26) -> 0.53529287 | L24: =IF($R26=0,0,L23/$R26) -> 0.46470713 | M24: =IF($R26=0,0,M23/$R26) -> 0 | ... U24: =IF($R26=0,0,U23/$R26) -> 0
A25: CONFERÊNCIA POR GRUPO | F25: =IF(SUM(F23:J23)=0,"— não preenchido",IF(ROUND(SUM(F23:J23)-$R26,3)=0,"OK — "&ROUND(SUM(F23:J23),3)&" km","ERRO — dif. de "&ROUND(SUM(F23:J23)-$R26,3)&" km")) -> OK — 8,608 km | K25: =IF(SUM(K23:L23)=0,"— não preenchido",IF(ROUND(SUM(K23:L23)-$R26,3)=0,"OK — "&ROUND(SUM(K23:L23),3)&" km","ERRO — dif. de "&ROUND(SUM(K23:L23)-$R26,3)&" km")) -> OK — 8,608 km | M25: =IF(SUM(M23:O23)=0,"— não preenchido",IF(ROUND(SUM(M23:O23)-$R26,3)=0,"OK — "&ROUND(SUM(M23:O23),3)&" km","ERRO — dif. de "&ROUND(SUM(M23:O23)-$R26,3)&" km")) -> OK — 8,608 km | P25: =IF(SUM(P23:R23)=0,"— não preenchido",IF(ROUND(SUM(P23:R23)-$R26,3)=0,"OK — "&ROUND(SUM(P23:R23),3)&" km","ERRO — dif. de "&ROUND(SUM(P23:R23)-$R26,3)&" km")) -> OK — 8,608 km | S25: =IF(SUM(S23:U23)=0,"— não preenchido",IF(ROUND(SUM(S23:U23)-$R26,3)=0,"OK — "&ROUND(SUM(S23:U23),3)&" km","ERRO — dif. de "&ROUND(SUM(S23:U23)-$R26,3)&" km")) -> OK — 8,608 km
A26: EXTENSÃO TOTAL DO TRECHO | R26: =SUM(E9:E17) -> 8.6075719 | V26: =COUNTIF(W9:W17,"OK")&" de "&COUNT($E$9:$E$17)&" linhas conferidas" -> 9 de 9 linhas conferidas
A28: LEGENDA
A29: REM. I. / REM. L. | E29: Remendos isolados (até 10 por km) · Remendos ao longo (mais de 10 por km)
A30: BUR. I. / BUR. L. | E30: Buracos isolados (até 5 por km) · Buracos ao longo (mais de 5 por km)
A31: SIT. | E31: PPS = pista simples · PSU = simples urbana · PDU = duplicada
A32: FAIXA AZUL | E32: Cabeçalho de cada S.R.E.: descrição, situação, jurisdição, extensão e coordenada de início.
A33: INÍCIO / FIM (KM) | E33: Contados de 0 até o fim de CADA S.R.E. Não é o marco quilométrico da rodovia.
A34: SENT. | E34: C = crescente · D = decrescente
A35: FAIXA CINZA | E35: Segmento fora do escopo do contrato: você passa por ele, mas não preenche.
A36: CÉLULA VERMELHA | E36: Mais de uma X no mesmo grupo. Apague uma delas.
A37: CONFERÊNCIA | E37: Só na tela, não sai impresso. Fica OK com uma X em cada grupo.

Sheet 3
A1: PROGRAMA DE MANUTENÇÃO RODOVIÁRIA — FICHA DE INSPEÇÃO — RODOVIAS PAVIMENTADAS | Y1: Valores dos gráficos — troca 0 por N/D para a fatia não aparecer. Não editar.
A2: REGIÃO: 1 — TOCANTINÓPOLIS | G2: MÊS / ANO: | I2: =IF('1'!I2="","",'1'!I2) -> 46266 | K2: DATA: | N2: =IF('1'!N2="","",'1'!N2) | P2: TÉCNICO: | R2: ENG. VINICIUS RODRIGUES FERREIRA DE OLIVEIRA | Y2: =IF(F60=0,NA(),F60) -> 30.607009 | Z2: =IF(G60=0,NA(),G60) -> 11 | AA2: =IF(H60=0,NA(),H60) -> #N/A | AB2: =IF(I60=0,NA(),I60) -> #N/A | AC2: =IF(J60=0,NA(),J60) -> #N/A | AD2: =IF(K60=0,NA(),K60) -> 5.8518241 | AE2: =IF(L60=0,NA(),L60) -> 35.755185 | AF2: =IF(M60=0,NA(),M60) -> #N/A | ... AN2: =IF(U60=0,NA(),U60) -> #N/A
A3: TRECHO 3 — RODOVIA TO-010 - TRECHO ARAGUATINS - ENTR. TO-201 | T3: EXTENSÃO: 41,607 km · 4 S.R.E.
A4: COMO PREENCHER: uma X em UMA coluna de cada grupo, por linha. Se houver mais de um defeito no mesmo km, marque o PREDOMINANTE e escreva o resto em OBSERVAÇÕES. A quilometragem é contada de 0 até o fim de CADA S.R.E. (não é o marco da rodovia).
A6: S.R.E. | B6: SENT. | C6: INÍCIO (KM) | D6: FIM (KM) | E6: EXT. (KM) | F6: CONDIÇÃO DO PAVIMENTO | K6: VEGETAÇÃO | M6: ELEM. DE DRENAGEM | P6: SIN. HORIZ. | S6: SIN. VERTICAL | V6: OBSERVAÇÕES | W6: CONFERÊNCIA (só na tela)
F7: BOM | G7: REM. I. | H7: REM. L. | I7: BUR. I. | J7: BUR. L. | K7: ADEQ. | L7: INAD. | M7: LIMPOS | N7: SUJOS | O7: DAN. | P7: BOM | Q7: REG. | R7: INEXIST. | S7: BOM | T7: POUCAS | U7: INEXIST.
A8: S.R.E. 010ETO0650 | ARAGUATINS - ENTR. TO-404 | PPS · Estadual · 7.755 km · início: -5.637677, -48.10469
A9: 010ETO0650 | B9: C | C9: 0 | D9: 1 | E9: =D9-C9 -> 1 | F9: X | L9: X | N9: X | P9: X | T9: X | W9: =IF(COUNTA(F9:U9)=0,"— não preenchido",IF(COUNTIF(F9:J9,"X")<>1,"FALTA/DUPLA: CONDIÇÃO DO PAVIMENTO",IF(COUNTIF(K9:L9,"X")<>1,"FALTA/DUPLA: VEGETAÇÃO",IF(COUNTIF(M9:O9,"X")<>1,"FALTA/DUPLA: ELEM. DE DRENAGEM",IF(COUNTIF(P9:R9,"X")<>1,"FALTA/DUPLA: SIN. HORIZ.",IF(COUNTIF(S9:U9,"X")<>1,"FALTA/DUPLA: SIN. VERTICAL","OK")))))) -> OK
A10: 010ETO0650 | B10: C | C10: 1 | D10: 2 | E10: =D10-C10 -> 1 | F10: X | L10: X | N10: X | P10: X | T10: X | W10: =IF(COUNTA(F10:U10)=0,"— não preenchido",IF(COUNTIF(F10:J10,"X")<>1,"FALTA/DUPLA: CONDIÇÃO DO PAVIMENTO",IF(COUNTIF(K10:L10,"X")<>1,"FALTA/DUPLA: VEGETAÇÃO",IF(COUNTIF(M10:O10,"X")<>1,"FALTA/DUPLA: ELEM. DE DRENAGEM",IF(COUNTIF(P10:R10,"X")<>1,"FALTA/DUPLA: SIN. HORIZ.",IF(COUNTIF(S10:U10,"X")<>1,"FALTA/DUPLA: SIN. VERTICAL","OK")))))) -> OK
A11: 010ETO0650 | B11: C | C11: 2 | D11: 3 | E11: =D11-C11 -> 1 | F11: X | L11: X | N11: X | P11: X | T11: X | W11: =IF(COUNTA(F11:U11)=0,"— não preenchido",IF(COUNTIF(F11:J11,"X")<>1,"FALTA/DUPLA: CONDIÇÃO DO PAVIMENTO",IF(COUNTIF(K11:L11,"X")<>1,"FALTA/DUPLA: VEGETAÇÃO",IF(COUNTIF(M11:O11,"X")<>1,"FALTA/DUPLA: ELEM. DE DRENAGEM",IF(COUNTIF(P11:R11,"X")<>1,"FALTA/DUPLA: SIN. HORIZ.",IF(COUNTIF(S11:U11,"X")<>1,"FALTA/DUPLA: SIN. VERTICAL","OK")))))) -> OK
A12: 010ETO0650 | B12: C | C12: 3 | D12: 4 | E12: =D12-C12 -> 1 | G12: X | L12: X | N12: X | P12: X | T12: X | W12: =IF(COUNTA(F12:U12)=0,"— não preenchido",IF(COUNTIF(F12:J12,"X")<>1,"FALTA/DUPLA: CONDIÇÃO DO PAVIMENTO",IF(COUNTIF(K12:L12,"X")<>1,"FALTA/DUPLA: VEGETAÇÃO",IF(COUNTIF(M12:O12,"X")<>1,"FALTA/DUPLA: ELEM. DE DRENAGEM",IF(COUNTIF(P12:R12,"X")<>1,"FALTA/DUPLA: SIN. HORIZ.",IF(COUNTIF(S12:U12,"X")<>1,"FALTA/DUPLA: SIN. VERTICAL","OK")))))) -> OK
A13: 010ETO0650 | B13: C | C13: 4 | D13: 5 | E13: =D13-C13 -> 1 | G13: X | L13: X | N13: X | P13: X | T13: X | W13: =IF(COUNTA(F13:U13)=0,"— não preenchido",IF(COUNTIF(F13:J13,"X")<>1,"FALTA/DUPLA: CONDIÇÃO DO PAVIMENTO",IF(COUNTIF(K13:L13,"X")<>1,"FALTA/DUPLA: VEGETAÇÃO",IF(COUNTIF(M13:O13,"X")<>1,"FALTA/DUPLA: ELEM. DE DRENAGEM",IF(COUNTIF(P13:R13,"X")<>1,"FALTA/DUPLA: SIN. HORIZ.",IF(COUNTIF(S13:U13,"X")<>1,"FALTA/DUPLA: SIN. VERTICAL","OK")))))) -> OK
A14: 010ETO0650 | B14: C | C14: 5 | D14: 6 | E14: =D14-C14 -> 1 | F14: X | L14: X | N14: X | P14: X | T14: X | W14: =IF(COUNTA(F14:U14)=0,"— não preenchido",IF(COUNTIF(F14:J14,"X")<>1,"FALTA/DUPLA: CONDIÇÃO DO PAVIMENTO",IF(COUNTIF(K14:L14,"X")<>1,"FALTA/DUPLA: VEGETAÇÃO",IF(COUNTIF(M14:O14,"X")<>1,"FALTA/DUPLA: ELEM. DE DRENAGEM",IF(COUNTIF(P14:R14,"X")<>1,"FALTA/DUPLA: SIN. HORIZ.",IF(COUNTIF(S14:U14,"X")<>1,"FALTA/DUPLA: SIN. VERTICAL","OK")))))) -> OK
A15: 010ETO0650 | B15: C | C15: 6 | D15: 7 | E15: =D15-C15 -> 1 | F15: X | L15: X | N15: X | P15: X | T15: X | W15: =IF(COUNTA(F15:U15)=0,"— não preenchido",IF(COUNTIF(F15:J15,"X")<>1,"FALTA/DUPLA: CONDIÇÃO DO PAVIMENTO",IF(COUNTIF(K15:L15,"X")<>1,"FALTA/DUPLA: VEGETAÇÃO",IF(COUNTIF(M15:O15,"X")<>1,"FALTA/DUPLA: ELEM. DE DRENAGEM",IF(COUNTIF(P15:R15,"X")<>1,"FALTA/DUPLA: SIN. HORIZ.",IF(COUNTIF(S15:U15,"X")<>1,"FALTA/DUPLA: SIN. VERTICAL","OK")))))) -> OK
A16: 010ETO0650 | B16: C | C16: 7 | D16: 7.7551854 | E16: =D16-C16 -> 0.75518537 | F16: X | L16: X | N16: X | P16: X | T16: X | W16: =IF(COUNTA(F16:U16)=0,"— não preenchido",IF(COUNTIF(F16:J16,"X")<>1,"FALTA/DUPLA: CONDIÇÃO DO PAVIMENTO",IF(COUNTIF(K16:L16,"X")<>1,"FALTA/DUPLA: VEGETAÇÃO",IF(COUNTIF(M16:O16,"X")<>1,"FALTA/DUPLA: ELEM. DE DRENAGEM",IF(COUNTIF(P16:R16,"X")<>1,"FALTA/DUPLA: SIN. HORIZ.",IF(COUNTIF(S16:U16,"X")<>1,"FALTA/DUPLA: SIN. VERTICAL","OK")))))) -> OK
A17: S.R.E. 010ETO0665 | ENTR. TO-404 - POV. CANAÃ | PPS · Estadual · 28.047 km · início: -5.597599, -48.079338
A18: 010ETO0665 | B18: C | C18: 0 | D18: 1 | E18: =D18-C18 -> 1 | F18: X | L18: X | N18: X | P18: X | T18: X | W18: =IF(COUNTA(F18:U18)=0,"— não preenchido",IF(COUNTIF(F18:J18,"X")<>1,"FALTA/DUPLA: CONDIÇÃO DO PAVIMENTO",IF(COUNTIF(K18:L18,"X")<>1,"FALTA/DUPLA: VEGETAÇÃO",IF(COUNTIF(M18:O18,"X")<>1,"FALTA/DUPLA: ELEM. DE DRENAGEM",IF(COUNTIF(P18:R18,"X")<>1,"FALTA/DUPLA: SIN. HORIZ.",IF(COUNTIF(S18:U18,"X")<>1,"FALTA/DUPLA: SIN. VERTICAL","OK")))))) -> OK
A19: 010ETO0665 | B19: C | C19: 1 | D19: 2 | E19: =D19-C19 -> 1 | F19: X | L19: X | N19: X | P19: X | T19: X | W19: =IF(COUNTA(F19:U19)=0,"— não preenchido",IF(COUNTIF(F19:J19,"X")<>1,"FALTA/DUPLA: CONDIÇÃO DO PAVIMENTO",IF(COUNTIF(K19:L19,"X")<>1,"FALTA/DUPLA: VEGETAÇÃO",IF(COUNTIF(M19:O19,"X")<>1,"FALTA/DUPLA: ELEM. DE DRENAGEM",IF(COUNTIF(P19:R19,"X")<>1,"FALTA/DUPLA: SIN. HORIZ.",IF(COUNTIF(S19:U19,"X")<>1,"FALTA/DUPLA: SIN. VERTICAL","OK")))))) -> OK
A20: 010ETO0665 | B20: C | C20: 2 | D20: 3 | E20: =D20-C20 -> 1 | F20: X | L20: X | N20: X | P20: X | T20: X | W20: =IF(COUNTA(F20:U20)=0,"— não preenchido",IF(COUNTIF(F20:J20,"X")<>1,"FALTA/DUPLA: CONDIÇÃO DO PAVIMENTO",IF(COUNTIF(K20:L20,"X")<>1,"FALTA/DUPLA: VEGETAÇÃO",IF(COUNTIF(M20:O20,"X")<>1,"FALTA/DUPLA: ELEM. DE DRENAGEM",IF(COUNTIF(P20:R20,"X")<>1,"FALTA/DUPLA: SIN. HORIZ.",IF(COUNTIF(S20:U20,"X")<>1,"FALTA/DUPLA: SIN. VERTICAL","OK")))))) -> OK
A21: 010ETO0665 | B21: C | C21: 3 | D21: 4 | E21: =D21-C21 -> 1 | G21: X | L21: X | N21: X | P21: X | T21: X | W21: =IF(COUNTA(F21:U21)=0,"— não preenchido",IF(COUNTIF(F21:J21,"X")<>1,"FALTA/DUPLA: CONDIÇÃO DO PAVIMENTO",IF(COUNTIF(K21:L21,"X")<>1,"FALTA/DUPLA: VEGETAÇÃO",IF(COUNTIF(M21:O21,"X")<>1,"FALTA/DUPLA: ELEM. DE DRENAGEM",IF(COUNTIF(P21:R21,"X")<>1,"FALTA/DUPLA: SIN. HORIZ.",IF(COUNTIF(S21:U21,"X")<>1,"FALTA/DUPLA: SIN. VERTICAL","OK")))))) -> OK
A22: 010ETO0665 | B22: C | C22: 4 | D22: 5 | E22: =D22-C22 -> 1 | G22: X | L22: X | N22: X | P22: X | T22: X | W22: =IF(COUNTA(F22:U22)=0,"— não preenchido",IF(COUNTIF(F22:J22,"X")<>1,"FALTA/DUPLA: CONDIÇÃO DO PAVIMENTO",IF(COUNTIF(K22:L22,"X")<>1,"FALTA/DUPLA: VEGETAÇÃO",IF(COUNTIF(M22:O22,"X")<>1,"FALTA/DUPLA: ELEM. DE DRENAGEM",IF(COUNTIF(P22:R22,"X")<>1,"FALTA/DUPLA: SIN. HORIZ.",IF(COUNTIF(S22:U22,"X")<>1,"FALTA/DUPLA: SIN. VERTICAL","OK")))))) -> OK
A23: 010ETO0665 | B23: C | C23: 5 | D23: 6 | E23: =D23-C23 -> 1 | F23: X | L23: X | N23: X | P23: X | T23: X | W23: =IF(COUNTA(F23:U23)=0,"— não preenchido",IF(COUNTIF(F23:J23,"X")<>1,"FALTA/DUPLA: CONDIÇÃO DO PAVIMENTO",IF(COUNTIF(K23:L23,"X")<>1,"FALTA/DUPLA: VEGETAÇÃO",IF(COUNTIF(M23:O23,"X")<>1,"FALTA/DUPLA: ELEM. DE DRENAGEM",IF(COUNTIF(P23:R23,"X")<>1,"FALTA/DUPLA: SIN. HORIZ.",IF(COUNTIF(S23:U23,"X")<>1,"FALTA/DUPLA: SIN. VERTICAL","OK")))))) -> OK
A24: 010ETO0665 | B24: C | C24: 6 | D24: 7 | E24: =D24-C24 -> 1 | F24: X | L24: X | N24: X | P24: X | T24: X | W24: =IF(COUNTA(F24:U24)=0,"— não preenchido",IF(COUNTIF(F24:J24,"X")<>1,"FALTA/DUPLA: CONDIÇÃO DO PAVIMENTO",IF(COUNTIF(K24:L24,"X")<>1,"FALTA/DUPLA: VEGETAÇÃO",IF(COUNTIF(M24:O24,"X")<>1,"FALTA/DUPLA: ELEM. DE DRENAGEM",IF(COUNTIF(P24:R24,"X")<>1,"FALTA/DUPLA: SIN. HORIZ.",IF(COUNTIF(S24:U24,"X")<>1,"FALTA/DUPLA: SIN. VERTICAL","OK")))))) -> OK
A25: 010ETO0665 | B25: C | C25: 7 | D25: 8 | E25: =D25-C25 -> 1 | F25: X | L25: X | N25: X | P25: X | T25: X | W25: =IF(COUNTA(F25:U25)=0,"— não preenchido",IF(COUNTIF(F25:J25,"X")<>1,"FALTA/DUPLA: CONDIÇÃO DO PAVIMENTO",IF(COUNTIF(K25:L25,"X")<>1,"FALTA/DUPLA: VEGETAÇÃO",IF(COUNTIF(M25:O25,"X")<>1,"FALTA/DUPLA: ELEM. DE DRENAGEM",IF(COUNTIF(P25:R25,"X")<>1,"FALTA/DUPLA: SIN. HORIZ.",IF(COUNTIF(S25:U25,"X")<>1,"FALTA/DUPLA: SIN. VERTICAL","OK")))))) -> OK
A26: 010ETO0665 | B26: C | C26: 8 | D26: 9 | E26: =D26-C26 -> 1 | F26: X | L26: X | N26: X | P26: X | T26: X | W26: =IF(COUNTA(F26:U26)=0,"— não preenchido",IF(COUNTIF(F26:J26,"X")<>1,"FALTA/DUPLA: CONDIÇÃO DO PAVIMENTO",IF(COUNTIF(K26:L26,"X")<>1,"FALTA/DUPLA: VEGETAÇÃO",IF(COUNTIF(M26:O26,"X")<>1,"FALTA/DUPLA: ELEM. DE DRENAGEM",IF(COUNTIF(P26:R26,"X")<>1,"FALTA/DUPLA: SIN. HORIZ.",IF(COUNTIF(S26:U26,"X")<>1,"FALTA/DUPLA: SIN. VERTICAL","OK")))))) -> OK
A27: 010ETO0665 | B27: C | C27: 9 | D27: 10 | E27: =D27-C27 -> 1 | G27: X | L27: X | N27: X | P27: X | T27: X | W27: =IF(COUNTA(F27:U27)=0,"— não preenchido",IF(COUNTIF(F27:J27,"X")<>1,"FALTA/DUPLA: CONDIÇÃO DO PAVIMENTO",IF(COUNTIF(K27:L27,"X")<>1,"FALTA/DUPLA: VEGETAÇÃO",IF(COUNTIF(M27:O27,"X")<>1,"FALTA/DUPLA: ELEM. DE DRENAGEM",IF(COUNTIF(P27:R27,"X")<>1,"FALTA/DUPLA: SIN. HORIZ.",IF(COUNTIF(S27:U27,"X")<>1,"FALTA/DUPLA: SIN. VERTICAL","OK")))))) -> OK
A28: 010ETO0665 | B28: C | C28: 10 | D28: 11 | E28: =D28-C28 -> 1 | G28: X | L28: X | N28: X | P28: X | T28: X | W28: =IF(COUNTA(F28:U28)=0,"— não preenchido",IF(COUNTIF(F28:J28,"X")<>1,"FALTA/DUPLA: CONDIÇÃO DO PAVIMENTO",IF(COUNTIF(K28:L28,"X")<>1,"FALTA/DUPLA: VEGETAÇÃO",IF(COUNTIF(M28:O28,"X")<>1,"FALTA/DUPLA: ELEM. DE DRENAGEM",IF(COUNTIF(P28:R28,"X")<>1,"FALTA/DUPLA: SIN. HORIZ.",IF(COUNTIF(S28:U28,"X")<>1,"FALTA/DUPLA: SIN. VERTICAL","OK")))))) -> OK
A29: 010ETO0665 | B29: C | C29: 11 | D29: 12 | E29: =D29-C29 -> 1 | F29: X | L29: X | N29: X | P29: X | T29: X | W29: =IF(COUNTA(F29:U29)=0,"— não preenchido",IF(COUNTIF(F29:J29,"X")<>1,"FALTA/DUPLA: CONDIÇÃO DO PAVIMENTO",IF(COUNTIF(K29:L29,"X")<>1,"FALTA/DUPLA: VEGETAÇÃO",IF(COUNTIF(M29:O29,"X")<>1,"FALTA/DUPLA: ELEM. DE DRENAGEM",IF(COUNTIF(P29:R29,"X")<>1,"FALTA/DUPLA: SIN. HORIZ.",IF(COUNTIF(S29:U29,"X")<>1,"FALTA/DUPLA: SIN. VERTICAL","OK")))))) -> OK
A30: 010ETO0665 | B30: C | C30: 12 | D30: 13 | E30: =D30-C30 -> 1 | F30: X | L30: X | N30: X | P30: X | T30: X | W30: =IF(COUNTA(F30:U30)=0,"— não preenchido",IF(COUNTIF(F30:J30,"X")<>1,"FALTA/DUPLA: CONDIÇÃO DO PAVIMENTO",IF(COUNTIF(K30:L30,"X")<>1,"FALTA/DUPLA: VEGETAÇÃO",IF(COUNTIF(M30:O30,"X")<>1,"FALTA/DUPLA: ELEM. DE DRENAGEM",IF(COUNTIF(P30:R30,"X")<>1,"FALTA/DUPLA: SIN. HORIZ.",IF(COUNTIF(S30:U30,"X")<>1,"FALTA/DUPLA: SIN. VERTICAL","OK")))))) -> OK
A31: 010ETO0665 | B31: C | C31: 13 | D31: 14 | E31: =D31-C31 -> 1 | F31: X | L31: X | N31: X | P31: X | T31: X | W31: =IF(COUNTA(F31:U31)=0,"— não preenchido",IF(COUNTIF(F31:J31,"X")<>1,"FALTA/DUPLA: CONDIÇÃO DO PAVIMENTO",IF(COUNTIF(K31:L31,"X")<>1,"FALTA/DUPLA: VEGETAÇÃO",IF(COUNTIF(M31:O31,"X")<>1,"FALTA/DUPLA: ELEM. DE DRENAGEM",IF(COUNTIF(P31:R31,"X")<>1,"FALTA/DUPLA: SIN. HORIZ.",IF(COUNTIF(S31:U31,"X")<>1,"FALTA/DUPLA: SIN. VERTICAL","OK")))))) -> OK
A32: 010ETO0665 | B32: C | C32: 14 | D32: 15 | E32: =D32-C32 -> 1 | F32: X | L32: X | N32: X | P32: X | T32: X | W32: =IF(COUNTA(F32:U32)=0,"— não preenchido",IF(COUNTIF(F32:J32,"X")<>1,"FALTA/DUPLA: CONDIÇÃO DO PAVIMENTO",IF(COUNTIF(K32:L32,"X")<>1,"FALTA/DUPLA: VEGETAÇÃO",IF(COUNTIF(M32:O32,"X")<>1,"FALTA/DUPLA: ELEM. DE DRENAGEM",IF(COUNTIF(P32:R32,"X")<>1,"FALTA/DUPLA: SIN. HORIZ.",IF(COUNTIF(S32:U32,"X")<>1,"FALTA/DUPLA: SIN. VERTICAL","OK")))))) -> OK
A33: 010ETO0665 | B33: C | C33: 15 | D33: 16 | E33: =D33-C33 -> 1 | G33: X | L33: X | N33: X | P33: X | T33: X | W33: =IF(COUNTA(F33:U33)=0,"— não preenchido",IF(COUNTIF(F33:J33,"X")<>1,"FALTA/DUPLA: CONDIÇÃO DO PAVIMENTO",IF(COUNTIF(K33:L33,"X")<>1,"FALTA/DUPLA: VEGETAÇÃO",IF(COUNTIF(M33:O33,"X")<>1,"FALTA/DUPLA: ELEM. DE DRENAGEM",IF(COUNTIF(P33:R33,"X")<>1,"FALTA/DUPLA: SIN. HORIZ.",IF(COUNTIF(S33:U33,"X")<>1,"FALTA/DUPLA: SIN. VERTICAL","OK")))))) -> OK
A34: 010ETO0665 | B34: C | C34: 16 | D34: 17 | E34: =D34-C34 -> 1 | F34: X | L34: X | N34: X | P34: X | T34: X | W34: =IF(COUNTA(F34:U34)=0,"— não preenchido",IF(COUNTIF(F34:J34,"X")<>1,"FALTA/DUPLA: CONDIÇÃO DO PAVIMENTO",IF(COUNTIF(K34:L34,"X")<>1,"FALTA/DUPLA: VEGETAÇÃO",IF(COUNTIF(M34:O34,"X")<>1,"FALTA/DUPLA: ELEM. DE DRENAGEM",IF(COUNTIF(P34:R34,"X")<>1,"FALTA/DUPLA: SIN. HORIZ.",IF(COUNTIF(S34:U34,"X")<>1,"FALTA/DUPLA: SIN. VERTICAL","OK")))))) -> OK
A35: 010ETO0665 | B35: C | C35: 17 | D35: 18 | E35: =D35-C35 -> 1 | F35: X | L35: X | N35: X | P35: X | T35: X | W35: =IF(COUNTA(F35:U35)=0,"— não preenchido",IF(COUNTIF(F35:J35,"X")<>1,"FALTA/DUPLA: CONDIÇÃO DO PAVIMENTO",IF(COUNTIF(K35:L35,"X")<>1,"FALTA/DUPLA: VEGETAÇÃO",IF(COUNTIF(M35:O35,"X")<>1,"FALTA/DUPLA: ELEM. DE DRENAGEM",IF(COUNTIF(P35:R35,"X")<>1,"FALTA/DUPLA: SIN. HORIZ.",IF(COUNTIF(S35:U35,"X")<>1,"FALTA/DUPLA: SIN. VERTICAL","OK")))))) -> OK
A36: 010ETO0665 | B36: C | C36: 18 | D36: 19 | E36: =D36-C36 -> 1 | F36: X | L36: X | N36: X | P36: X | T36: X | W36: =IF(COUNTA(F36:U36)=0,"— não preenchido",IF(COUNTIF(F36:J36,"X")<>1,"FALTA/DUPLA: CONDIÇÃO DO PAVIMENTO",IF(COUNTIF(K36:L36,"X")<>1,"FALTA/DUPLA: VEGETAÇÃO",IF(COUNTIF(M36:O36,"X")<>1,"FALTA/DUPLA: ELEM. DE DRENAGEM",IF(COUNTIF(P36:R36,"X")<>1,"FALTA/DUPLA: SIN. HORIZ.",IF(COUNTIF(S36:U36,"X")<>1,"FALTA/DUPLA: SIN. VERTICAL","OK")))))) -> OK
A37: 010ETO0665 | B37: C | C37: 19 | D37: 20 | E37: =D37-C37 -> 1 | F37: X | L37: X | N37: X | P37: X | T37: X | W37: =IF(COUNTA(F37:U37)=0,"— não preenchido",IF(COUNTIF(F37:J37,"X")<>1,"FALTA/DUPLA: CONDIÇÃO DO PAVIMENTO",IF(COUNTIF(K37:L37,"X")<>1,"FALTA/DUPLA: VEGETAÇÃO",IF(COUNTIF(M37:O37,"X")<>1,"FALTA/DUPLA: ELEM. DE DRENAGEM",IF(COUNTIF(P37:R37,"X")<>1,"FALTA/DUPLA: SIN. HORIZ.",IF(COUNTIF(S37:U37,"X")<>1,"FALTA/DUPLA: SIN. VERTICAL","OK")))))) -> OK
A38: 010ETO0665 | B38: C | C38: 20 | D38: 21 | E38: =D38-C38 -> 1 | F38: X | L38: X | N38: X | P38: X | T38: X | W38: =IF(COUNTA(F38:U38)=0,"— não preenchido",IF(COUNTIF(F38:J38,"X")<>1,"FALTA/DUPLA: CONDIÇÃO DO PAVIMENTO",IF(COUNTIF(K38:L38,"X")<>1,"FALTA/DUPLA: VEGETAÇÃO",IF(COUNTIF(M38:O38,"X")<>1,"FALTA/DUPLA: ELEM. DE DRENAGEM",IF(COUNTIF(P38:R38,"X")<>1,"FALTA/DUPLA: SIN. HORIZ.",IF(COUNTIF(S38:U38,"X")<>1,"FALTA/DUPLA: SIN. VERTICAL","OK")))))) -> OK
A39: 010ETO0665 | B39: C | C39: 21 | D39: 22 | E39: =D39-C39 -> 1 | F39: X | L39: X | N39: X | P39: X | T39: X | W39: =IF(COUNTA(F39:U39)=0,"— não preenchido",IF(COUNTIF(F39:J39,"X")<>1,"FALTA/DUPLA: CONDIÇÃO DO PAVIMENTO",IF(COUNTIF(K39:L39,"X")<>1,"FALTA/DUPLA: VEGETAÇÃO",IF(COUNTIF(M39:O39,"X")<>1,"FALTA/DUPLA: ELEM. DE DRENAGEM",IF(COUNTIF(P39:R39,"X")<>1,"FALTA/DUPLA: SIN. HORIZ.",IF(COUNTIF(S39:U39,"X")<>1,"FALTA/DUPLA: SIN. VERTICAL","OK")))))) -> OK
A40: 010ETO0665 | B40: C | C40: 22 | D40: 23 | E40: =D40-C40 -> 1 | F40: X | L40: X | N40: X | P40: X | T40: X | W40: =IF(COUNTA(F40:U40)=0,"— não preenchido",IF(COUNTIF(F40:J40,"X")<>1,"FALTA/DUPLA: CONDIÇÃO DO PAVIMENTO",IF(COUNTIF(K40:L40,"X")<>1,"FALTA/DUPLA: VEGETAÇÃO",IF(COUNTIF(M40:O40,"X")<>1,"FALTA/DUPLA: ELEM. DE DRENAGEM",IF(COUNTIF(P40:R40,"X")<>1,"FALTA/DUPLA: SIN. HORIZ.",IF(COUNTIF(S40:U40,"X")<>1,"FALTA/DUPLA: SIN. VERTICAL","OK")))))) -> OK
A41: 010ETO0665 | B41: C | C41: 23 | D41: 24 | E41: =D41-C41 -> 1 | G41: X | L41: X | N41: X | P41: X | T41: X | W41: =IF(COUNTA(F41:U41)=0,"— não preenchido",IF(COUNTIF(F41:J41,"X")<>1,"FALTA/DUPLA: CONDIÇÃO DO PAVIMENTO",IF(COUNTIF(K41:L41,"X")<>1,"FALTA/DUPLA: VEGETAÇÃO",IF(COUNTIF(M41:O41,"X")<>1,"FALTA/DUPLA: ELEM. DE DRENAGEM",IF(COUNTIF(P41:R41,"X")<>1,"FALTA/DUPLA: SIN. HORIZ.",IF(COUNTIF(S41:U41,"X")<>1,"FALTA/DUPLA: SIN. VERTICAL","OK")))))) -> OK
...

Sheet 4
A1: PROGRAMA DE MANUTENÇÃO RODOVIÁRIA — FICHA DE INSPEÇÃO — RODOVIAS PAVIMENTADAS | Y1: Valores dos gráficos — troca 0 por N/D para a fatia não aparecer. Não editar.
A2: REGIÃO: 1 — TOCANTINÓPOLIS | G2: MÊS / ANO: | I2: =IF('1'!I2="","",'1'!I2) -> 46266 | K2: DATA: | N2: =IF('1'!N2="","",'1'!N2) | P2: TÉCNICO: | R2: ENG. VINICIUS RODRIGUES FERREIRA DE OLIVEIRA | Y2: =IF(F26=0,NA(),F26) -> 5.589158 | Z2: =IF(G26=0,NA(),G26) -> 3.6607758 | AA2: =IF(H26=0,NA(),H26) -> #N/A | AB2: =IF(I26=0,NA(),I26) -> #N/A | AC2: =IF(J26=0,NA(),J26) -> #N/A | AD2: =IF(K26=0,NA(),K26) -> #N/A | AE2: =IF(L26=0,NA(),L26) -> 9.2499338 | AF2: =IF(M26=0,NA(),M26) -> #N/A | ... AN2: =IF(U26=0,NA(),U26) -> #N/A
A3: TRECHO 4 — RODOVIA TO-010 - TRECHO BURITI DO TOCANTINS (ENTR. TO-201) - SÃO SEBASTIÃO DO TOCANTINS | T3: EXTENSÃO: 9,250 km · 2 S.R.E.
A4: COMO PREENCHER: uma X em UMA coluna de cada grupo, por linha. Se houver mais de um defeito no mesmo km, marque o PREDOMINANTE e escreva o resto em OBSERVAÇÕES. A quilometragem é contada de 0 até o fim de CADA S.R.E. (não é o marco da rodovia).
A6: S.R.E. | B6: SENT. | C6: INÍCIO (KM) | D6: FIM (KM) | E6: EXT. (KM) | F6: CONDIÇÃO DO PAVIMENTO | K6: VEGETAÇÃO | M6: ELEM. DE DRENAGEM | P6: SIN. HORIZ. | S6: SIN. VERTICAL | V6: OBSERVAÇÕES | W6: CONFERÊNCIA (só na tela)
F7: BOM | G7: REM. I. | H7: REM. L. | I7: BUR. I. | J7: BUR. L. | K7: ADEQ. | L7: INAD. | M7: LIMPOS | N7: SUJOS | O7: DAN. | P7: BOM | Q7: REG. | R7: INEXIST. | S7: BOM | T7: POUCAS | U7: INEXIST.
A8: S.R.E. 010ETO0690 | ENTR. TO-201 - BURITI DO TOCANTINS *TRECHO URBANO* | PPS · Estadual · 3.661 km · início: -5.318513, -48.194133
A9: 010ETO0690 | B9: C | C9: 0 | D9: 1 | E9: =D9-C9 -> 1 | F9: X | L9: X | N9: X | P9: X | T9: X | W9: =IF(COUNTA(F9:U9)=0,"— não preenchido",IF(COUNTIF(F9:J9,"X")<>1,"FALTA/DUPLA: CONDIÇÃO DO PAVIMENTO",IF(COUNTIF(K9:L9,"X")<>1,"FALTA/DUPLA: VEGETAÇÃO",IF(COUNTIF(M9:O9,"X")<>1,"FALTA/DUPLA: ELEM. DE DRENAGEM",IF(COUNTIF(P9:R9,"X")<>1,"FALTA/DUPLA: SIN. HORIZ.",IF(COUNTIF(S9:U9,"X")<>1,"FALTA/DUPLA: SIN. VERTICAL","OK")))))) -> OK
A10: 010ETO0690 | B10: C | C10: 1 | D10: 2 | E10: =D10-C10 -> 1 | F10: X | L10: X | N10: X | P10: X | T10: X | W10: =IF(COUNTA(F10:U10)=0,"— não preenchido",IF(COUNTIF(F10:J10,"X")<>1,"FALTA/DUPLA: CONDIÇÃO DO PAVIMENTO",IF(COUNTIF(K10:L10,"X")<>1,"FALTA/DUPLA: VEGETAÇÃO",IF(COUNTIF(M10:O10,"X")<>1,"FALTA/DUPLA: ELEM. DE DRENAGEM",IF(COUNTIF(P10:R10,"X")<>1,"FALTA/DUPLA: SIN. HORIZ.",IF(COUNTIF(S10:U10,"X")<>1,"FALTA/DUPLA: SIN. VERTICAL","OK")))))) -> OK
A11: 010ETO0690 | B11: C | C11: 2 | D11: 3 | E11: =D11-C11 -> 1 | G11: X | L11: X | N11: X | P11: X | T11: X | W11: =IF(COUNTA(F11:U11)=0,"— não preenchido",IF(COUNTIF(F11:J11,"X")<>1,"FALTA/DUPLA: CONDIÇÃO DO PAVIMENTO",IF(COUNTIF(K11:L11,"X")<>1,"FALTA/DUPLA: VEGETAÇÃO",IF(COUNTIF(M11:O11,"X")<>1,"FALTA/DUPLA: ELEM. DE DRENAGEM",IF(COUNTIF(P11:R11,"X")<>1,"FALTA/DUPLA: SIN. HORIZ.",IF(COUNTIF(S11:U11,"X")<>1,"FALTA/DUPLA: SIN. VERTICAL","OK")))))) -> OK
A12: 010ETO0690 | B12: C | C12: 3 | D12: 3.6607758 | E12: =D12-C12 -> 0.6607758 | G12: X | L12: X | N12: X | P12: X | T12: X | W12: =IF(COUNTA(F12:U12)=0,"— não preenchido",IF(COUNTIF(F12:J12,"X")<>1,"FALTA/DUPLA: CONDIÇÃO DO PAVIMENTO",IF(COUNTIF(K12:L12,"X")<>1,"FALTA/DUPLA: VEGETAÇÃO",IF(COUNTIF(M12:O12,"X")<>1,"FALTA/DUPLA: ELEM. DE DRENAGEM",IF(COUNTIF(P12:R12,"X")<>1,"FALTA/DUPLA: SIN. HORIZ.",IF(COUNTIF(S12:U12,"X")<>1,"FALTA/DUPLA: SIN. VERTICAL","OK")))))) -> OK
A13: ▲ AQUI HÁ 2.168 km FORA DO ESCOPO DO CONTRATO (perímetro urbano de jurisdição municipal). Você passa por ele, mas NÃO preenche.
A14: S.R.E. 010ETO0710D | BURITI DO TOCANTINS *TRECHO URBANO* - SÃO SEBASTIÃO DO TOCANTINS *TRECHO URBANO* (código antigo: 010ETO0710) | PPS · Estadual · 5.589 km · início: -5.304241, -48.227554
A15: 010ETO0710D | B15: C | C15: 0 | D15: 1 | E15: =D15-C15 -> 1 | F15: X | L15: X | N15: X | P15: X | T15: X | W15: =IF(COUNTA(F15:U15)=0,"— não preenchido",IF(COUNTIF(F15:J15,"X")<>1,"FALTA/DUPLA: CONDIÇÃO DO PAVIMENTO",IF(COUNTIF(K15:L15,"X")<>1,"FALTA/DUPLA: VEGETAÇÃO",IF(COUNTIF(M15:O15,"X")<>1,"FALTA/DUPLA: ELEM. DE DRENAGEM",IF(COUNTIF(P15:R15,"X")<>1,"FALTA/DUPLA: SIN. HORIZ.",IF(COUNTIF(S15:U15,"X")<>1,"FALTA/DUPLA: SIN. VERTICAL","OK")))))) -> OK
A16: 010ETO0710D | B16: C | C16: 1 | D16: 2 | E16: =D16-C16 -> 1 | F16: X | L16: X | N16: X | P16: X | T16: X | W16: =IF(COUNTA(F16:U16)=0,"— não preenchido",IF(COUNTIF(F16:J16,"X")<>1,"FALTA/DUPLA: CONDIÇÃO DO PAVIMENTO",IF(COUNTIF(K16:L16,"X")<>1,"FALTA/DUPLA: VEGETAÇÃO",IF(COUNTIF(M16:O16,"X")<>1,"FALTA/DUPLA: ELEM. DE DRENAGEM",IF(COUNTIF(P16:R16,"X")<>1,"FALTA/DUPLA: SIN. HORIZ.",IF(COUNTIF(S16:U16,"X")<>1,"FALTA/DUPLA: SIN. VERTICAL","OK")))))) -> OK
A17: 010ETO0710D | B17: C | C17: 2 | D17: 3 | E17: =D17-C17 -> 1 | G17: X | L17: X | N17: X | P17: X | T17: X | W17: =IF(COUNTA(F17:U17)=0,"— não preenchido",IF(COUNTIF(F17:J17,"X")<>1,"FALTA/DUPLA: CONDIÇÃO DO PAVIMENTO",IF(COUNTIF(K17:L17,"X")<>1,"FALTA/DUPLA: VEGETAÇÃO",IF(COUNTIF(M17:O17,"X")<>1,"FALTA/DUPLA: ELEM. DE DRENAGEM",IF(COUNTIF(P17:R17,"X")<>1,"FALTA/DUPLA: SIN. HORIZ.",IF(COUNTIF(S17:U17,"X")<>1,"FALTA/DUPLA: SIN. VERTICAL","OK")))))) -> OK
A18: 010ETO0710D | B18: C | C18: 3 | D18: 4 | E18: =D18-C18 -> 1 | G18: X | L18: X | N18: X | P18: X | T18: X | W18: =IF(COUNTA(F18:U18)=0,"— não preenchido",IF(COUNTIF(F18:J18,"X")<>1,"FALTA/DUPLA: CONDIÇÃO DO PAVIMENTO",IF(COUNTIF(K18:L18,"X")<>1,"FALTA/DUPLA: VEGETAÇÃO",IF(COUNTIF(M18:O18,"X")<>1,"FALTA/DUPLA: ELEM. DE DRENAGEM",IF(COUNTIF(P18:R18,"X")<>1,"FALTA/DUPLA: SIN. HORIZ.",IF(COUNTIF(S18:U18,"X")<>1,"FALTA/DUPLA: SIN. VERTICAL","OK")))))) -> OK
A19: 010ETO0710D | B19: C | C19: 4 | D19: 5 | E19: =D19-C19 -> 1 | F19: X | L19: X | N19: X | P19: X | T19: X | W19: =IF(COUNTA(F19:U19)=0,"— não preenchido",IF(COUNTIF(F19:J19,"X")<>1,"FALTA/DUPLA: CONDIÇÃO DO PAVIMENTO",IF(COUNTIF(K19:L19,"X")<>1,"FALTA/DUPLA: VEGETAÇÃO",IF(COUNTIF(M19:O19,"X")<>1,"FALTA/DUPLA: ELEM. DE DRENAGEM",IF(COUNTIF(P19:R19,"X")<>1,"FALTA/DUPLA: SIN. HORIZ.",IF(COUNTIF(S19:U19,"X")<>1,"FALTA/DUPLA: SIN. VERTICAL","OK")))))) -> OK
A20: 010ETO0710D | B20: C | C20: 5 | D20: 5.589158 | E20: =D20-C20 -> 0.58915803 | F20: X | L20: X | N20: X | P20: X | T20: X | W20: =IF(COUNTA(F20:U20)=0,"— não preenchido",IF(COUNTIF(F20:J20,"X")<>1,"FALTA/DUPLA: CONDIÇÃO DO PAVIMENTO",IF(COUNTIF(K20:L20,"X")<>1,"FALTA/DUPLA: VEGETAÇÃO",IF(COUNTIF(M20:O20,"X")<>1,"FALTA/DUPLA: ELEM. DE DRENAGEM",IF(COUNTIF(P20:R20,"X")<>1,"FALTA/DUPLA: SIN. HORIZ.",IF(COUNTIF(S20:U20,"X")<>1,"FALTA/DUPLA: SIN. VERTICAL","OK")))))) -> OK
A22: ____________________________________________ | G22: ____________________________________________
A23: TÉCNICO RESPONSÁVEL PELA INSPEÇÃO | G23: VISTO DA SUPERVISÃO
A25: RESUMO DO TRECHO — KM LANÇADO POR ITEM
A26: KM LANÇADO | F26: =SUMIF(F$9:F$20,"X",$E$9:$E$20) -> 5.589158 | G26: =SUMIF(G$9:G$20,"X",$E$9:$E$20) -> 3.6607758 | H26: =SUMIF(H$9:H$20,"X",$E$9:$E$20) -> 0 | I26: =SUMIF(I$9:I$20,"X",$E$9:$E$20) -> 0 | J26: =SUMIF(J$9:J$20,"X",$E$9:$E$20) -> 0 | K26: =SUMIF(K$9:K$20,"X",$E$9:$E$20) -> 0 | L26: =SUMIF(L$9:L$20,"X",$E$9:$E$20) -> 9.2499338 | M26: =SUMIF(M$9:M$20,"X",$E$9:$E$20) -> 0 | ... U26: =SUMIF(U$9:U$20,"X",$E$9:$E$20) -> 0
A27: % DA EXTENSÃO | F27: =IF($R29=0,0,F26/$R29) -> 0.60423762 | G27: =IF($R29=0,0,G26/$R29) -> 0.39576238 | H27: =IF($R29=0,0,H26/$R29) -> 0 | I27: =IF($R29=0,0,I26/$R29) -> 0 | J27: =IF($R29=0,0,J26/$R29) -> 0 | K27: =IF($R29=0,0,K26/$R29) -> 0 | L27: =IF($R29=0,0,L26/$R29) -> 1 | M27: =IF($R29=0,0,M26/$R29) -> 0 | ... U27: =IF($R29=0,0,U26/$R29) -> 0
A28: CONFERÊNCIA POR GRUPO | F28: =IF(SUM(F26:J26)=0,"— não preenchido",IF(ROUND(SUM(F26:J26)-$R29,3)=0,"OK — "&ROUND(SUM(F26:J26),3)&" km","ERRO — dif. de "&ROUND(SUM(F26:J26)-$R29,3)&" km")) -> OK — 9,25 km | K28: =IF(SUM(K26:L26)=0,"— não preenchido",IF(ROUND(SUM(K26:L26)-$R29,3)=0,"OK — "&ROUND(SUM(K26:L26),3)&" km","ERRO — dif. de "&ROUND(SUM(K26:L26)-$R29,3)&" km")) -> OK — 9,25 km | M28: =IF(SUM(M26:O26)=0,"— não preenchido",IF(ROUND(SUM(M26:O26)-$R29,3)=0,"OK — "&ROUND(SUM(M26:O26),3)&" km","ERRO — dif. de "&ROUND(SUM(M26:O26)-$R29,3)&" km")) -> OK — 9,25 km | P28: =IF(SUM(P26:R26)=0,"— não preenchido",IF(ROUND(SUM(P26:R26)-$R29,3)=0,"OK — "&ROUND(SUM(P26:R26),3)&" km","ERRO — dif. de "&ROUND(SUM(P26:R26)-$R29,3)&" km")) -> OK — 9,25 km | S28: =IF(SUM(S26:U26)=0,"— não preenchido",IF(ROUND(SUM(S26:U26)-$R29,3)=0,"OK — "&ROUND(SUM(S26:U26),3)&" km","ERRO — dif. de "&ROUND(SUM(S26:U26)-$R29,3)&" km")) -> OK — 9,25 km
A29: EXTENSÃO TOTAL DO TRECHO | R29: =SUM(E9:E20) -> 9.2499338 | V29: =COUNTIF(W9:W20,"OK")&" de "&COUNT($E$9:$E$20)&" linhas conferidas" -> 10 de 10 linhas conferidas
A31: LEGENDA
A32: REM. I. / REM. L. | E32: Remendos isolados (até 10 por km) · Remendos ao longo (mais de 10 por km)
A33: BUR. I. / BUR. L. | E33: Buracos isolados (até 5 por km) · Buracos ao longo (mais de 5 por km)
A34: SIT. | E34: PPS = pista simples · PSU = simples urbana · PDU = duplicada
A35: FAIXA AZUL | E35: Cabeçalho de cada S.R.E.: descrição, situação, jurisdição, extensão e coordenada de início.
A36: INÍCIO / FIM (KM) | E36: Contados de 0 até o fim de CADA S.R.E. Não é o marco quilométrico da rodovia.
A37: SENT. | E37: C = crescente · D = decrescente
A38: FAIXA CINZA | E38: Segmento fora do escopo do contrato: você passa por ele, mas não preenche.
A39: CÉLULA VERMELHA | E39: Mais de uma X no mesmo grupo. Apague uma delas.
A40: CONFERÊNCIA | E40: Só na tela, não sai impresso. Fica OK com uma X em cada grupo.

Sheet 5
A1: PROGRAMA DE MANUTENÇÃO RODOVIÁRIA — FICHA DE INSPEÇÃO — RODOVIAS PAVIMENTADAS | Y1: Valores dos gráficos — troca 0 por N/D para a fatia não aparecer. Não editar.
A2: REGIÃO: 1 — TOCANTINÓPOLIS | G2: MÊS / ANO: | I2: =IF('1'!I2="","",'1'!I2) -> 46266 | K2: DATA: | N2: =IF('1'!N2="","",'1'!N2) | P2: TÉCNICO: | R2: ENG. VINICIUS RODRIGUES FERREIRA DE OLIVEIRA | Y2: =IF(F49=0,NA(),F49) -> 21.142364 | Z2: =IF(G49=0,NA(),G49) -> 1.2344796 | AA2: =IF(H49=0,NA(),H49) -> 7.8623358 | AB2: =IF(I49=0,NA(),I49) -> #N/A | AC2: =IF(J49=0,NA(),J49) -> #N/A | AD2: =IF(K49=0,NA(),K49) -> #N/A | AE2: =IF(L49=0,NA(),L49) -> 30.23918 | AF2: =IF(M49=0,NA(),M49) -> #N/A | ... AN2: =IF(U49=0,NA(),U49) -> #N/A
