Workbook

Sheet Trechos
A1: RELAÇÃO DE SEGMENTOS PAVIMENTADOS R.12
A2: LOTE | B2: N. | C2: TRECHO | D2: S.R.E | E2: SUBTRECHOS | F2: EXT. (KM) | G2: TIPO | H2: 45839 | I2: 45870
A3: 12 | B3: 224 | C3: RODOVIA TO-141 - TRECHO PALMEIRÓPOLIS - DIVISA TO-GO | D3: 141ETO0110 | E3: PALMEIRÓPOLIS *TRECHO URBANO* - DIV TO-GO | F3: 26.24 | G3: PPS
A4: 12 | B4: 225 | C4: RODOVIA TO-280 - TRECHO NATIVIDADE - ALMAS | D4: 280ETO0150 | E4: ENTR. TO-040 (ALMAS) - ENTR. BR-010-TO-050 | F4: 76.27813 | G4: PPS | I4: X
A5: 12 | B5: 226 | C5: RODOVIA TO-280 - TRECHO SÃO VALÉRIO DE NATIVIDADE - NATIVIDADE | D5: 280ETO0175 | E5: ENTR.TO-050 - BR-010 (NATIVIDADE ACESSO SUL) - ENTR. TO-486 | F5: 3.5915409 | G5: PPS | I5: X
A6: 12 | B6: 226 | C6: RODOVIA TO-280 - TRECHO SÃO VALÉRIO DE NATIVIDADE - NATIVIDADE | D6: 280ETO0180 | E6: ENTR. TO-486 - ENTR. TO-482 | F6: 52.926658 | G6: PPS | I6: X
A7: 12 | B7: 226 | C7: RODOVIA TO-280 - TRECHO SÃO VALÉRIO DE NATIVIDADE - NATIVIDADE | D7: 280ETO0190 | E7: ENTR.TO-482 - SÃO VALÉRIO DA NATIVIDADE *TRECHO URBANO* | F7: 8.5124137 | G7: PPS | I7: X
A8: 12 | B8: 227 | C8: RODOVIA TO-280 - TRECHO ENTR. BR-242 - SÃO VALÉRIO DE NATIVIDADE | D8: 280ETO0191 | E8: SÃO VALÉRIO DA NATIVIDADE *TRECHO URBANO* | F8: 1.8557688 | G8: PSU | I8: X
A9: 12 | B9: 227 | C9: RODOVIA TO-280 - TRECHO ENTR. BR-242 - SÃO VALÉRIO DE NATIVIDADE | D9: 280ETO0200 | E9: SÃO VALÉRIO DA NATIVIDADE *TRECHO URBANO* - ENTR. TO-490 | F9: 1.2413451 | G9: PPS | I9: X
A10: 12 | B10: 227 | C10: RODOVIA TO-280 - TRECHO ENTR. BR-242 - SÃO VALÉRIO DE NATIVIDADE | D10: 280ETO0210 | E10: ENTR. TO-490 - ENTR.TO-373 | F10: 9.5427731 | G10: PPS | I10: X
A11: 12 | B11: 227 | C11: RODOVIA TO-280 - TRECHO ENTR. BR-242 - SÃO VALÉRIO DE NATIVIDADE | D11: 280ETO0220 | E11: ENTR. TO-373 - ENTR. BR-242 | F11: 21.524811 | G11: PPS | I11: X
A12: 12 | B12: 227 | C12: RODOVIA TO-280 - TRECHO ENTR. BR-242 - SÃO VALÉRIO DE NATIVIDADE | D12: ACESSO | E12: ENTR. TO-280 - UHE (PEIXE ANGICAL) | F12: 8.9931637 | G12: PPS
A13: 12 | B13: 228 | C13: RODOVIA TO-296 - TRECHO SÃO SALVADOR DO TOCANTINS - PARANÃ | D13: 296ETO0220 | E13: ENTR. BR-242 (PARANÃ) - SÃO SALVADOR DO TOCANTINS *TRECHO URBANO* | F13: 54.941976 | G13: PPS
A14: 12 | B14: 229 | C14: RODOVIA TO-296 - TRECHO JAÚ DO TOCANTINS - SÃO SALVADOR DO TOCANTINS | D14: 296ETO0230 | E14: SÃO SALVADOR DO TOCANTINS *TRECHO URBANO* - ENTR. TO-387 | F14: 1.9699466 | G14: PPS
A15: 12 | B15: 229 | C15: RODOVIA TO-296 - TRECHO JAÚ DO TOCANTINS - SÃO SALVADOR DO TOCANTINS | D15: 296ETO0261 | E15: JAÚ DO TOCANTINS *TRECHO URBANO* | F15: 0.19788955 | G15: PSU
A16: 12 | B16: 229 | C16: RODOVIA TO-296 - TRECHO JAÚ DO TOCANTINS - SÃO SALVADOR DO TOCANTINS | D16: 296ETO0262 | E16: JAÚ DO TOCANTINS *TRECHO URBANO* | F16: 0.24076975 | G16: PSU
A17: 12 | B17: 230 | C17: RODOVIA TO-296 - TALISMÃ - ENTR. TO-498 (JAÚ DO TOCANTINS) | D17: 296ETO0300 | E17: ENTR. TO-498 - ENTR. TO-495 | F17: 16.519213 | G17: PPS
A18: 12 | B18: 230 | C18: RODOVIA TO-296 - TALISMÃ - ENTR. TO-498 (JAÚ DO TOCANTINS) | D18: 296ETO0310 | E18: ENTR. TO-495 - ENTR. BR-153 | F18: 46.384522 | G18: PPS
A19: 12 | B19: 231 | C19: RODOVIA TO-365 - TRECHO IPUEIRAS - SILVANÓPOLIS | D19: 365ETO0191 | E19: IPUEIRAS *TRECHO URBANO* | F19: 1.125491 | G19: PSU
A20: 12 | B20: 233 | C20: RODOVIA TO-373 - TRECHO ALVORADA - ENTR. BR-242 | D20: 373ETO0190 | E20: ENTR. BR-242 - ENTR. TO-498 (SANTA CRUZ) | F20: 22.788312 | G20: PPS | I20: X
A21: 12 | B21: 233 | C21: RODOVIA TO-373 - TRECHO ALVORADA - ENTR. BR-242 | D21: 373ETO0200 | E21: ENTR. TO-498 (SANTA CRUZ) - VILA UNIÃO | F21: 21.785344 | G21: PPS | I21: X
A22: 12 | B22: 233 | C22: RODOVIA TO-373 - TRECHO ALVORADA - ENTR. BR-242 | D22: 373ETO0210 | E22: VILA UNIÃO - CANA BRAVA | F22: 13.872974 | G22: PPS | I22: X
A23: 12 | B23: 233 | C23: RODOVIA TO-373 - TRECHO ALVORADA - ENTR. BR-242 | D23: 373ETO0220 | E23: CANA BRAVA - ENTR. BR-153 ALVORADA *TRECHO URBANO* | F23: 23.402863 | G23: PPS | I23: X
A24: 12 | B24: 234 | C24: RODOVIA TO-387 - TRECHO PALMEIRÓPOLIS - SÃO SALVADOR DO TOCANTINS | D24: 387ETO0170 | E24: ENTR. TO-296 - PALMEIRÓPOLIS *TRECHO URBANO* | F24: 37.422326 | G24: PPS
A25: 12 | B25: 235 | C25: RODOVIA TO-387 - TRECHO PALMEIRÓPOLIS - DIVISA TO-GO | D25: 387ETO0171 | E25: PERÍMETRO URBANO DE PALMEIRÓPOLIS | F25: 0.64415038 | G25: PSU
A26: 12 | B26: 235 | C26: RODOVIA TO-387 - TRECHO PALMEIRÓPOLIS - DIVISA TO-GO | D26: 387ETO0172 | E26: PERÍMETRO URBANO DE PALMEIRÓPOLIS | F26: 1.3221506 | G26: PSU
A27: 12 | B27: 235 | C27: RODOVIA TO-387 - TRECHO PALMEIRÓPOLIS - DIVISA TO-GO | D27: 387ETO0200 | E27: PALMEIRÓPOLIS *TRECHO URBANO* - ENTR. TO-498 | F27: 16.889369 | G27: PPS
A28: 12 | B28: 235 | C28: RODOVIA TO-387 - TRECHO PALMEIRÓPOLIS - DIVISA TO-GO | D28: 387ETO0210 | E28: ENTR. TO-498 - BARROLÂNDIA | F28: 5.0201754 | G28: PPS
A29: 12 | B29: 235 | C29: RODOVIA TO-387 - TRECHO PALMEIRÓPOLIS - DIVISA TO-GO | D29: 387ETO0220 | E29: BARROLÂNDIA - DIV TO-GO | F29: 6.2417577 | G29: PPS
A30: 12 | B30: 243 | C30: RODOVIA TO-498 - TRECHO JAÚ DO TOCANTINS - ENTR. TO-373 (SANTA CRUZ) | D30: 498ETO0010 | E30: ENTR. TO-373 (SANTA CRUZ) - ENTR. TO-296 | F30: 32.034789 | G30: PPS
A31: 12 | B31: 243 | C31: RODOVIA TO-498 - TRECHO JAÚ DO TOCANTINS - ENTR. TO-373 (SANTA CRUZ) | D31: 296ETO0290 | E31: JAÚ DO TOCANTINS *TRECHO URBANO* - ENTR. TO-498 | F31: 4.0257705 | G31: PPS
A32: 12 | B32: 244 | C32: RODOVIA TO-498 - TRECHO JAÚ DO TOCANTINS - ENTR. TO-387 | D32: 498ETO0050 | E32: JAÚ DO TOCANTINS *TRECHO URBANO* - NOVO HORIZONTE | F32: 20.941915 | G32: PPS
A33: 12 | B33: 244 | C33: RODOVIA TO-498 - TRECHO JAÚ DO TOCANTINS - ENTR. TO-387 | D33: 498ETO0080 | E33: NOVO HORIZONTE - MONTEIRÓPOLIS | F33: 12.101114 | G33: PPS
A34: 12 | B34: 244 | C34: RODOVIA TO-498 - TRECHO JAÚ DO TOCANTINS - ENTR. TO-387 | D34: 498ETO0090 | E34: MONTEIRÓPOLIS - ENTR. TO-387 | F34: 9.0435975 | G34: PPS
F35: =SUM(F3:F34) -> 559.62302

Sheet 224
A1: PROGRAMA DE MANUTENÇÃORODOVIÁRIA
A2: RODOVIAS PAVIMENTADAS | I2: DATA: | J2: 46204 | N2: TÉCNICO RESP. | O2: ENG. THIAGO TORQUATO | T2: REGIÃO: | U2: 12
A3: FICHA DE INSPEÇÃO: | B3: =TT!C4 -> RODOVIA TO-141 - TRECHO PALMEIRÓPOLIS - DIVISA TO-GO
A5: S.R.E. | B5: SENTIDO | C5: INÍCIO (KM) | D5: FIM (KM) | E5: CONDIÇÃO DO PAVIMENTO | J5: VEGETAÇÃO | L5: ELEM. DE DRENAGEM | O5: SIN. HOR. | R5: SIN. VERTICAL | U5: OBSERV.
E6: BOM | F6: REM. I. | G6: REM. L | H6: BUR. I | I6: BUR. L | J6: ADEQ. | K6: INADED. | L6: LIMPOS | M6: SUJOS | N6: DAN. | O6: BOM | P6: REG. | Q6: INEXIST. | R6: BOM | S6: POUCAS | T6: INEXIST.
A7: 387ETO0110 | B7: C | C7: 0 | D7: 0.7 | G7: X | H7: X | J7: X | M7: X | P7: X | S7: X
C8: =D7 -> 0.7 | D8: 2 | E8: X | J8: X | M8: X | P8: X | S8: X
C9: =D8 -> 2 | D9: 4.5 | F9: X | J9: X | M9: X | P9: X | S9: X
C10: =D9 -> 4.5 | D10: 5.2 | F10: X | J10: X | M10: X | P10: X | S10: X
C11: =D10 -> 5.2 | D11: 9.3 | E11: X | J11: X | M11: X | P11: X | S11: X
C12: =D11 -> 9.3 | D12: 10 | F12: X | J12: X | M12: X | P12: X | S12: X
C13: =D12 -> 10 | D13: 10.7 | F13: X | J13: X | M13: X | P13: X | S13: X
C14: =D13 -> 10.7 | D14: 12.5 | F14: X | J14: X | M14: X | P14: X | S14: X
C15: =D14 -> 12.5 | D15: 14.2 | E15: X | J15: X | M15: X | P15: X | S15: X
C16: =D15 -> 14.2 | D16: 16.4 | G16: X | H16: X | J16: X | M16: X | P16: X | S16: X
C17: =D16 -> 16.4 | D17: 18.4 | G17: X | J17: X | M17: X | P17: X | S17: X
C18: =D17 -> 18.4 | D18: 25.4 | E18: X | H18: X | J18: X | M18: X | P18: X | S18: X
C19: =D18 -> 25.4 | D19: 26.2 | F19: X | J19: X | M19: X | P19: X | S19: X
A32: LEGENDA | B32: CONDIÇÃO DO PAVIMENTO
A33: REM. I | B33: REMENDOS ISOLADOS | E33: ATÉ 10 REMENDOS/KM | I33: BUR. I | J33: BURACOS ISOLADOS | M33: ATÉ 5 BURACOS/KM
A34: REM. L | B34: REMENDOS AO LONGO | E34: MAIS DE 10 REMENDOS/KM | I34: BUR. L | J34: BURACOS AO LONGO | M34: MAIS DE 5 BURACOS/KM
E39: =IF(E7="X",(D7-C7),"0") -> 0 | F39: =IF(F7="X",(D7-C7),"0") -> 0 | G39: =IF(G7="X",(D7-C7),"0") -> 0.7 | H39: =IF(H7="X",(D7-C7),"0") -> 0.7 | I39: =IF(I7="X",(D7-C7),"0") -> 0 | J39: =IF(J7="X",(D7-C7),"0") -> 0.7 | K39: =IF(K7="X",(D7-C7),"0") -> 0 | L39: =IF(L7="X",(D7-C7),"0") -> 0 | M39: =IF(M7="X",(D7-C7),"0") -> 0.7 | N39: =IF(N7="X",(D7-C7),"0") -> 0 | O39: =IF(O7="X",(D7-C7),"0") -> 0 | P39: =IF(P7="X",(D7-C7),"0") -> 0.7 | Q39: =IF(Q7="X",(D7-C7),"0") -> 0 | R39: =IF(R7="X",(D7-C7),"0") -> 0 | S39: =IF(S7="X",(D7-C7),"0") -> 0.7 | T39: =IF(T7="X",(D7-C7),"0") -> 0
E40: =IF(E8="X",(D8-C8),"0") -> 1.3 | F40: =IF(F8="X",(D8-C8),"0") -> 0 | G40: =IF(G8="X",(D8-C8),"0") -> 0 | H40: =IF(H8="X",(D8-C8),"0") -> 0 | I40: =IF(I8="X",(D8-C8),"0") -> 0 | J40: =IF(J8="X",(D8-C8),"0") -> 1.3 | K40: =IF(K8="X",(D8-C8),"0") -> 0 | L40: =IF(L8="X",(D8-C8),"0") -> 0 | M40: =IF(M8="X",(D8-C8),"0") -> 1.3 | N40: =IF(N8="X",(D8-C8),"0") -> 0 | O40: =IF(O8="X",(D8-C8),"0") -> 0 | P40: =IF(P8="X",(D8-C8),"0") -> 1.3 | Q40: =IF(Q8="X",(D8-C8),"0") -> 0 | R40: =IF(R8="X",(D8-C8),"0") -> 0 | S40: =IF(S8="X",(D8-C8),"0") -> 1.3 | T40: =IF(T8="X",(D8-C8),"0") -> 0
E41: =IF(E9="X",(D9-C9),"0") -> 0 | F41: =IF(F9="X",(D9-C9),"0") -> 2.5 | G41: =IF(G9="X",(D9-C9),"0") -> 0 | H41: =IF(H9="X",(D9-C9),"0") -> 0 | I41: =IF(I9="X",(D9-C9),"0") -> 0 | J41: =IF(J9="X",(D9-C9),"0") -> 2.5 | K41: =IF(K9="X",(D9-C9),"0") -> 0 | L41: =IF(L9="X",(D9-C9),"0") -> 0 | M41: =IF(M9="X",(D9-C9),"0") -> 2.5 | N41: =IF(N9="X",(D9-C9),"0") -> 0 | O41: =IF(O9="X",(D9-C9),"0") -> 0 | P41: =IF(P9="X",(D9-C9),"0") -> 2.5 | Q41: =IF(Q9="X",(D9-C9),"0") -> 0 | R41: =IF(R9="X",(D9-C9),"0") -> 0 | S41: =IF(S9="X",(D9-C9),"0") -> 2.5 | T41: =IF(T9="X",(D9-C9),"0") -> 0
E42: =IF(E10="X",(D10-C10),"0") -> 0 | F42: =IF(F10="X",(D10-C10),"0") -> 0.7 | G42: =IF(G10="X",(D10-C10),"0") -> 0 | H42: =IF(H10="X",(D10-C10),"0") -> 0 | I42: =IF(I10="X",(D10-C10),"0") -> 0 | J42: =IF(J10="X",(D10-C10),"0") -> 0.7 | K42: =IF(K10="X",(D10-C10),"0") -> 0 | L42: =IF(L10="X",(D10-C10),"0") -> 0 | M42: =IF(M10="X",(D10-C10),"0") -> 0.7 | N42: =IF(N10="X",(D10-C10),"0") -> 0 | O42: =IF(O10="X",(D10-C10),"0") -> 0 | P42: =IF(P10="X",(D10-C10),"0") -> 0.7 | Q42: =IF(Q10="X",(D10-C10),"0") -> 0 | R42: =IF(R10="X",(D10-C10),"0") -> 0 | S42: =IF(S10="X",(D10-C10),"0") -> 0.7 | T42: =IF(T10="X",(D10-C10),"0") -> 0
E43: =IF(E11="X",(D11-C11),"0") -> 4.1 | F43: =IF(F11="X",(D11-C11),"0") -> 0 | G43: =IF(G11="X",(D11-C11),"0") -> 0 | H43: =IF(H11="X",(D11-C11),"0") -> 0 | I43: =IF(I11="X",(D11-C11),"0") -> 0 | J43: =IF(J11="X",(D11-C11),"0") -> 4.1 | K43: =IF(K11="X",(D11-C11),"0") -> 0 | L43: =IF(L11="X",(D11-C11),"0") -> 0 | M43: =IF(M11="X",(D11-C11),"0") -> 4.1 | N43: =IF(N11="X",(D11-C11),"0") -> 0 | O43: =IF(O11="X",(D11-C11),"0") -> 0 | P43: =IF(P11="X",(D11-C11),"0") -> 4.1 | Q43: =IF(Q11="X",(D11-C11),"0") -> 0 | R43: =IF(R11="X",(D11-C11),"0") -> 0 | S43: =IF(S11="X",(D11-C11),"0") -> 4.1 | T43: =IF(T11="X",(D11-C11),"0") -> 0
E44: =IF(E12="X",(D12-C12),"0") -> 0 | F44: =IF(F12="X",(D12-C12),"0") -> 0.7 | G44: =IF(G12="X",(D12-C12),"0") -> 0 | H44: =IF(H12="X",(D12-C12),"0") -> 0 | I44: =IF(I12="X",(D12-C12),"0") -> 0 | J44: =IF(J12="X",(D12-C12),"0") -> 0.7 | K44: =IF(K12="X",(D12-C12),"0") -> 0 | L44: =IF(L12="X",(D12-C12),"0") -> 0 | M44: =IF(M12="X",(D12-C12),"0") -> 0.7 | N44: =IF(N12="X",(D12-C12),"0") -> 0 | O44: =IF(O12="X",(D12-C12),"0") -> 0 | P44: =IF(P12="X",(D12-C12),"0") -> 0.7 | Q44: =IF(Q12="X",(D12-C12),"0") -> 0 | R44: =IF(R12="X",(D12-C12),"0") -> 0 | S44: =IF(S12="X",(D12-C12),"0") -> 0.7 | T44: =IF(T12="X",(D12-C12),"0") -> 0
E45: =IF(E13="X",(D13-C13),"0") -> 0 | F45: =IF(F13="X",(D13-C13),"0") -> 0.7 | G45: =IF(G13="X",(D13-C13),"0") -> 0 | H45: =IF(H13="X",(D13-C13),"0") -> 0 | I45: =IF(I13="X",(D13-C13),"0") -> 0 | J45: =IF(J13="X",(D13-C13),"0") -> 0.7 | K45: =IF(K13="X",(D13-C13),"0") -> 0 | L45: =IF(L13="X",(D13-C13),"0") -> 0 | M45: =IF(M13="X",(D13-C13),"0") -> 0.7 | N45: =IF(N13="X",(D13-C13),"0") -> 0 | O45: =IF(O13="X",(D13-C13),"0") -> 0 | P45: =IF(P13="X",(D13-C13),"0") -> 0.7 | Q45: =IF(Q13="X",(D13-C13),"0") -> 0 | R45: =IF(R13="X",(D13-C13),"0") -> 0 | S45: =IF(S13="X",(D13-C13),"0") -> 0.7 | T45: =IF(T13="X",(D13-C13),"0") -> 0
E46: =IF(E14="X",(D14-C14),"0") -> 0 | F46: =IF(F14="X",(D14-C14),"0") -> 1.8 | G46: =IF(G14="X",(D14-C14),"0") -> 0 | H46: =IF(H14="X",(D14-C14),"0") -> 0 | I46: =IF(I14="X",(D14-C14),"0") -> 0 | J46: =IF(J14="X",(D14-C14),"0") -> 1.8 | K46: =IF(K14="X",(D14-C14),"0") -> 0 | L46: =IF(L14="X",(D14-C14),"0") -> 0 | M46: =IF(M14="X",(D14-C14),"0") -> 1.8 | N46: =IF(N14="X",(D14-C14),"0") -> 0 | O46: =IF(O14="X",(D14-C14),"0") -> 0 | P46: =IF(P14="X",(D14-C14),"0") -> 1.8 | Q46: =IF(Q14="X",(D14-C14),"0") -> 0 | R46: =IF(R14="X",(D14-C14),"0") -> 0 | S46: =IF(S14="X",(D14-C14),"0") -> 1.8 | T46: =IF(T14="X",(D14-C14),"0") -> 0
E47: =IF(E15="X",(D15-C15),"0") -> 1.7 | F47: =IF(F15="X",(D15-C15),"0") -> 0 | G47: =IF(G15="X",(D15-C15),"0") -> 0 | H47: =IF(H15="X",(D15-C15),"0") -> 0 | I47: =IF(I15="X",(D15-C15),"0") -> 0 | J47: =IF(J15="X",(D15-C15),"0") -> 1.7 | K47: =IF(K15="X",(D15-C15),"0") -> 0 | L47: =IF(L15="X",(D15-C15),"0") -> 0 | M47: =IF(M15="X",(D15-C15),"0") -> 1.7 | N47: =IF(N15="X",(D15-C15),"0") -> 0 | O47: =IF(O15="X",(D15-C15),"0") -> 0 | P47: =IF(P15="X",(D15-C15),"0") -> 1.7 | Q47: =IF(Q15="X",(D15-C15),"0") -> 0 | R47: =IF(R15="X",(D15-C15),"0") -> 0 | S47: =IF(S15="X",(D15-C15),"0") -> 1.7 | T47: =IF(T15="X",(D15-C15),"0") -> 0
E48: =IF(E16="X",(D16-C16),"0") -> 0 | F48: =IF(F16="X",(D16-C16),"0") -> 0 | G48: =IF(G16="X",(D16-C16),"0") -> 2.2 | H48: =IF(H16="X",(D16-C16),"0") -> 2.2 | I48: =IF(I16="X",(D16-C16),"0") -> 0 | J48: =IF(J16="X",(D16-C16),"0") -> 2.2 | K48: =IF(K16="X",(D16-C16),"0") -> 0 | L48: =IF(L16="X",(D16-C16),"0") -> 0 | M48: =IF(M16="X",(D16-C16),"0") -> 2.2 | N48: =IF(N16="X",(D16-C16),"0") -> 0 | O48: =IF(O16="X",(D16-C16),"0") -> 0 | P48: =IF(P16="X",(D16-C16),"0") -> 2.2 | Q48: =IF(Q16="X",(D16-C16),"0") -> 0 | R48: =IF(R16="X",(D16-C16),"0") -> 0 | S48: =IF(S16="X",(D16-C16),"0") -> 2.2 | T48: =IF(T16="X",(D16-C16),"0") -> 0
E49: =IF(E17="X",(D17-C17),"0") -> 0 | F49: =IF(F17="X",(D17-C17),"0") -> 0 | G49: =IF(G17="X",(D17-C17),"0") -> 2 | H49: =IF(H17="X",(D17-C17),"0") -> 0 | I49: =IF(I17="X",(D17-C17),"0") -> 0 | J49: =IF(J17="X",(D17-C17),"0") -> 2 | K49: =IF(K17="X",(D17-C17),"0") -> 0 | L49: =IF(L17="X",(D17-C17),"0") -> 0 | M49: =IF(M17="X",(D17-C17),"0") -> 2 | N49: =IF(N17="X",(D17-C17),"0") -> 0 | O49: =IF(O17="X",(D17-C17),"0") -> 0 | P49: =IF(P17="X",(D17-C17),"0") -> 2 | Q49: =IF(Q17="X",(D17-C17),"0") -> 0 | R49: =IF(R17="X",(D17-C17),"0") -> 0 | S49: =IF(S17="X",(D17-C17),"0") -> 2 | T49: =IF(T17="X",(D17-C17),"0") -> 0
E50: =IF(E18="X",(D18-C18),"0") -> 7 | F50: =IF(F18="X",(D18-C18),"0") -> 0 | G50: =IF(G18="X",(D18-C18),"0") -> 0 | H50: =IF(H18="X",(D18-C18),"0") -> 7 | I50: =IF(I18="X",(D18-C18),"0") -> 0 | J50: =IF(J18="X",(D18-C18),"0") -> 7 | K50: =IF(K18="X",(D18-C18),"0") -> 0 | L50: =IF(L18="X",(D18-C18),"0") -> 0 | M50: =IF(M18="X",(D18-C18),"0") -> 7 | N50: =IF(N18="X",(D18-C18),"0") -> 0 | O50: =IF(O18="X",(D18-C18),"0") -> 0 | P50: =IF(P18="X",(D18-C18),"0") -> 7 | Q50: =IF(Q18="X",(D18-C18),"0") -> 0 | R50: =IF(R18="X",(D18-C18),"0") -> 0 | S50: =IF(S18="X",(D18-C18),"0") -> 7 | T50: =IF(T18="X",(D18-C18),"0") -> 0
... E126: =IF(E94="X",(D94-C94),"0") -> 0 | F126: =IF(F94="X",(D94-C94),"0") -> 0 | G126: =IF(G94="X",(D94-C94),"0") -> 0 | H126: =IF(H94="X",(D94-C94),"0") -> 0 | I126: =IF(I94="X",(D94-C94),"0") -> 0 | J126: =IF(J94="X",(D94-C94),"0") -> 0 | K126: =IF(K94="X",(D94-C94),"0") -> 0 | L126: =IF(L94="X",(D94-C94),"0") -> 0 | M126: =IF(M94="X",(D94-C94),"0") -> 0 | N126: =IF(N94="X",(D94-C94),"0") -> 0 | O126: =IF(O94="X",(D94-C94),"0") -> 0 | P126: =IF(P94="X",(D94-C94),"0") -> 0 | Q126: =IF(Q94="X",(D94-C94),"0") -> 0 | R126: =IF(R94="X",(D94-C94),"0") -> 0 | S126: =IF(S94="X",(D94-C94),"0") -> 0 | T126: =IF(T94="X",(D94-C94),"0") -> 0
E127: =SUM(E39:E126) -> 14.1 | F127: =SUM(F39:F126) -> 7.2 | G127: =SUM(G39:G126) -> 4.9 | H127: =SUM(H39:H126) -> 9.9 | I127: =SUM(I39:I126) -> 0 | J127: =SUM(J39:J126) -> 26.2 | K127: =SUM(K39:K126) -> 0 | L127: =SUM(L39:L126) -> 0 | ... T127: =SUM(T39:T126) -> 0

Sheet 225
A1: PROGRAMA DE MANUTENÇÃORODOVIÁRIA
A2: RODOVIAS PAVIMENTADAS | I2: DATA: | J2: ='224'!J2 -> 46204 | N2: TÉCNICO RESP. | O2: ='224'!O2 -> ENG. THIAGO TORQUATO | T2: REGIÃO: | U2: 12
A3: FICHA DE INSPEÇÃO: | B3: =TT!C5 -> RODOVIA TO-280 - TRECHO NATIVIDADE - ALMAS
A5: S.R.E. | B5: SENTIDO | C5: INÍCIO (KM) | D5: FIM (KM) | E5: CONDIÇÃO DO PAVIMENTO | J5: VEGETAÇÃO | L5: ELEM. DE DRENAGEM | O5: SIN. HOR. | R5: SIN. VERTICAL | U5: OBSERV.
E6: BOM | F6: REM. I. | G6: REM. L | H6: BUR. I | I6: BUR. L | J6: ADEQ. | K6: INADED. | L6: LIMPOS | M6: SUJOS | N6: DAN. | O6: BOM | P6: REG. | Q6: INEXIST. | R6: BOM | S6: POUCAS | T6: INEXIST.
A7: 280ETO0150 | B7: D | C7: 0 | D7: 2.4 | F7: X | J7: X | L7: X | P7: X | S7: X
C8: =D7 -> 2.4 | D8: 4 | G8: X | J8: X | P8: X | S8: X
C9: =D8 -> 4 | D9: 8.1 | G9: X | I9: X | J9: X | L9: X | P9: X | S9: X
C10: =D9 -> 8.1 | D10: 14.6 | G10: X | J10: X | M10: X | P10: X | S10: X
C11: =D10 -> 14.6 | D11: 22 | G11: X | I11: X | J11: X | M11: X | P11: X | S11: X
C12: =D11 -> 22 | D12: 22.5 | G12: X | I12: X | J12: X | M12: X | P12: X | S12: X
C13: =D12 -> 22.5 | D13: 25.5 | F13: X | G13: X | J13: X | P13: X | S13: X
C14: =D13 -> 25.5 | D14: 27 | F14: X | G14: X | J14: X | P14: X | S14: X
C15: =D14 -> 27 | D15: 30.5 | F15: X | G15: X | J15: X | P15: X | S15: X
C16: =D15 -> 30.5 | D16: 31.5 | G16: X | J16: X | P16: X | S16: X
C17: =D16 -> 31.5 | D17: 34 | F17: X | G17: X | J17: X | P17: X | S17: X
C18: =D17 -> 34 | D18: 52 | G18: X | J18: X | M18: X | P18: X | S18: X
C19: =D18 -> 52 | D19: 53 | F19: X | G19: X | J19: X | M19: X | P19: X | S19: X
C20: =D19 -> 53 | D20: 65.1 | G20: X | J20: X | M20: X | P20: X | S20: X
C21: =D20 -> 65.1 | D21: 66.7 | F21: X | J21: X | P21: X | S21: X
C22: =D21 -> 66.7 | D22: 67.5 | G22: X | J22: X | P22: X | S22: X
C23: =D22 -> 67.5 | D23: 72.1 | F23: X | J23: X | P23: X | S23: X
C24: =D23 -> 72.1 | D24: 73.1 | G24: X | J24: X | P24: X | S24: X
C25: =D24 -> 73.1 | D25: 76.2 | G25: X | J25: X | P25: X | S25: X
A32: LEGENDA | B32: CONDIÇÃO DO PAVIMENTO
A33: REM. I | B33: REMENDOS ISOLADOS | E33: ATÉ 10 REMENDOS/KM | I33: BUR. I | J33: BURACOS ISOLADOS | M33: ATÉ 5 BURACOS/KM
A34: REM. L | B34: REMENDOS AO LONGO | E34: MAIS DE 10 REMENDOS/KM | I34: BUR. L | J34: BURACOS AO LONGO | M34: MAIS DE 5 BURACOS/KM
E39: =IF(E7="X",(D7-C7),"0") -> 0 | F39: =IF(F7="X",(D7-C7),"0") -> 2.4 | G39: =IF(G7="X",(D7-C7),"0") -> 0 | H39: =IF(H7="X",(D7-C7),"0") -> 0 | I39: =IF(I7="X",(D7-C7),"0") -> 0 | J39: =IF(J7="X",(D7-C7),"0") -> 2.4 | K39: =IF(K7="X",(D7-C7),"0") -> 0 | L39: =IF(L7="X",(D7-C7),"0") -> 2.4 | M39: =IF(M7="X",(D7-C7),"0") -> 0 | N39: =IF(N7="X",(D7-C7),"0") -> 0 | O39: =IF(O7="X",(D7-C7),"0") -> 0 | P39: =IF(P7="X",(D7-C7),"0") -> 2.4 | Q39: =IF(Q7="X",(D7-C7),"0") -> 0 | R39: =IF(R7="X",(D7-C7),"0") -> 0 | S39: =IF(S7="X",(D7-C7),"0") -> 2.4 | T39: =IF(T7="X",(D7-C7),"0") -> 0
E40: =IF(E8="X",(D8-C8),"0") -> 0 | F40: =IF(F8="X",(D8-C8),"0") -> 0 | G40: =IF(G8="X",(D8-C8),"0") -> 1.6 | H40: =IF(H8="X",(D8-C8),"0") -> 0 | I40: =IF(I8="X",(D8-C8),"0") -> 0 | J40: =IF(J8="X",(D8-C8),"0") -> 1.6 | K40: =IF(K8="X",(D8-C8),"0") -> 0 | L40: =IF(L8="X",(D8-C8),"0") -> 0 | M40: =IF(M8="X",(D8-C8),"0") -> 0 | N40: =IF(N8="X",(D8-C8),"0") -> 0 | O40: =IF(O8="X",(D8-C8),"0") -> 0 | P40: =IF(P8="X",(D8-C8),"0") -> 1.6 | Q40: =IF(Q8="X",(D8-C8),"0") -> 0 | R40: =IF(R8="X",(D8-C8),"0") -> 0 | S40: =IF(S8="X",(D8-C8),"0") -> 1.6 | T40: =IF(T8="X",(D8-C8),"0") -> 0
E41: =IF(E9="X",(D9-C9),"0") -> 0 | F41: =IF(F9="X",(D9-C9),"0") -> 0 | G41: =IF(G9="X",(D9-C9),"0") -> 4.1 | H41: =IF(H9="X",(D9-C9),"0") -> 0 | I41: =IF(I9="X",(D9-C9),"0") -> 4.1 | J41: =IF(J9="X",(D9-C9),"0") -> 4.1 | K41: =IF(K9="X",(D9-C9),"0") -> 0 | L41: =IF(L9="X",(D9-C9),"0") -> 4.1 | M41: =IF(M9="X",(D9-C9),"0") -> 0 | N41: =IF(N9="X",(D9-C9),"0") -> 0 | O41: =IF(O9="X",(D9-C9),"0") -> 0 | P41: =IF(P9="X",(D9-C9),"0") -> 4.1 | Q41: =IF(Q9="X",(D9-C9),"0") -> 0 | R41: =IF(R9="X",(D9-C9),"0") -> 0 | S41: =IF(S9="X",(D9-C9),"0") -> 4.1 | T41: =IF(T9="X",(D9-C9),"0") -> 0
E42: =IF(E10="X",(D10-C10),"0") -> 0 | F42: =IF(F10="X",(D10-C10),"0") -> 0 | G42: =IF(G10="X",(D10-C10),"0") -> 6.5 | H42: =IF(H10="X",(D10-C10),"0") -> 0 | I42: =IF(I10="X",(D10-C10),"0") -> 0 | J42: =IF(J10="X",(D10-C10),"0") -> 6.5 | K42: =IF(K10="X",(D10-C10),"0") -> 0 | L42: =IF(L10="X",(D10-C10),"0") -> 0 | M42: =IF(M10="X",(D10-C10),"0") -> 6.5 | N42: =IF(N10="X",(D10-C10),"0") -> 0 | O42: =IF(O10="X",(D10-C10),"0") -> 0 | P42: =IF(P10="X",(D10-C10),"0") -> 6.5 | Q42: =IF(Q10="X",(D10-C10),"0") -> 0 | R42: =IF(R10="X",(D10-C10),"0") -> 0 | S42: =IF(S10="X",(D10-C10),"0") -> 6.5 | T42: =IF(T10="X",(D10-C10),"0") -> 0
E43: =IF(E11="X",(D11-C11),"0") -> 0 | F43: =IF(F11="X",(D11-C11),"0") -> 0 | G43: =IF(G11="X",(D11-C11),"0") -> 7.4 | H43: =IF(H11="X",(D11-C11),"0") -> 0 | I43: =IF(I11="X",(D11-C11),"0") -> 7.4 | J43: =IF(J11="X",(D11-C11),"0") -> 7.4 | K43: =IF(K11="X",(D11-C11),"0") -> 0 | L43: =IF(L11="X",(D11-C11),"0") -> 0 | M43: =IF(M11="X",(D11-C11),"0") -> 7.4 | N43: =IF(N11="X",(D11-C11),"0") -> 0 | O43: =IF(O11="X",(D11-C11),"0") -> 0 | P43: =IF(P11="X",(D11-C11),"0") -> 7.4 | Q43: =IF(Q11="X",(D11-C11),"0") -> 0 | R43: =IF(R11="X",(D11-C11),"0") -> 0 | S43: =IF(S11="X",(D11-C11),"0") -> 7.4 | T43: =IF(T11="X",(D11-C11),"0") -> 0
E44: =IF(E12="X",(D12-C12),"0") -> 0 | F44: =IF(F12="X",(D12-C12),"0") -> 0 | G44: =IF(G12="X",(D12-C12),"0") -> 0.5 | H44: =IF(H12="X",(D12-C12),"0") -> 0 | I44: =IF(I12="X",(D12-C12),"0") -> 0.5 | J44: =IF(J12="X",(D12-C12),"0") -> 0.5 | K44: =IF(K12="X",(D12-C12),"0") -> 0 | L44: =IF(L12="X",(D12-C12),"0") -> 0 | M44: =IF(M12="X",(D12-C12),"0") -> 0.5 | N44: =IF(N12="X",(D12-C12),"0") -> 0 | O44: =IF(O12="X",(D12-C12),"0") -> 0 | P44: =IF(P12="X",(D12-C12),"0") -> 0.5 | Q44: =IF(Q12="X",(D12-C12),"0") -> 0 | R44: =IF(R12="X",(D12-C12),"0") -> 0 | S44: =IF(S12="X",(D12-C12),"0") -> 0.5 | T44: =IF(T12="X",(D12-C12),"0") -> 0
E45: =IF(E13="X",(D13-C13),"0") -> 0 | F45: =IF(F13="X",(D13-C13),"0") -> 3 | G45: =IF(G13="X",(D13-C13),"0") -> 3 | H45: =IF(H13="X",(D13-C13),"0") -> 0 | I45: =IF(I13="X",(D13-C13),"0") -> 0 | J45: =IF(J13="X",(D13-C13),"0") -> 3 | K45: =IF(K13="X",(D13-C13),"0") -> 0 | L45: =IF(L13="X",(D13-C13),"0") -> 0 | M45: =IF(M13="X",(D13-C13),"0") -> 0 | N45: =IF(N13="X",(D13-C13),"0") -> 0 | O45: =IF(O13="X",(D13-C13),"0") -> 0 | P45: =IF(P13="X",(D13-C13),"0") -> 3 | Q45: =IF(Q13="X",(D13-C13),"0") -> 0 | R45: =IF(R13="X",(D13-C13),"0") -> 0 | S45: =IF(S13="X",(D13-C13),"0") -> 3 | T45: =IF(T13="X",(D13-C13),"0") -> 0
E46: =IF(E14="X",(D14-C14),"0") -> 0 | F46: =IF(F14="X",(D14-C14),"0") -> 1.5 | G46: =IF(G14="X",(D14-C14),"0") -> 1.5 | H46: =IF(H14="X",(D14-C14),"0") -> 0 | I46: =IF(I14="X",(D14-C14),"0") -> 0 | J46: =IF(J14="X",(D14-C14),"0") -> 1.5 | K46: =IF(K14="X",(D14-C14),"0") -> 0 | L46: =IF(L14="X",(D14-C14),"0") -> 0 | M46: =IF(M14="X",(D14-C14),"0") -> 0 | N46: =IF(N14="X",(D14-C14),"0") -> 0 | O46: =IF(O14="X",(D14-C14),"0") -> 0 | P46: =IF(P14="X",(D14-C14),"0") -> 1.5 | Q46: =IF(Q14="X",(D14-C14),"0") -> 0 | R46: =IF(R14="X",(D14-C14),"0") -> 0 | S46: =IF(S14="X",(D14-C14),"0") -> 1.5 | T46: =IF(T14="X",(D14-C14),"0") -> 0
E47: =IF(E15="X",(D15-C15),"0") -> 0 | F47: =IF(F15="X",(D15-C15),"0") -> 3.5 | G47: =IF(G15="X",(D15-C15),"0") -> 3.5 | H47: =IF(H15="X",(D15-C15),"0") -> 0 | I47: =IF(I15="X",(D15-C15),"0") -> 0 | J47: =IF(J15="X",(D15-C15),"0") -> 3.5 | K47: =IF(K15="X",(D15-C15),"0") -> 0 | L47: =IF(L15="X",(D15-C15),"0") -> 0 | M47: =IF(M15="X",(D15-C15),"0") -> 0 | N47: =IF(N15="X",(D15-C15),"0") -> 0 | O47: =IF(O15="X",(D15-C15),"0") -> 0 | P47: =IF(P15="X",(D15-C15),"0") -> 3.5 | Q47: =IF(Q15="X",(D15-C15),"0") -> 0 | R47: =IF(R15="X",(D15-C15),"0") -> 0 | S47: =IF(S15="X",(D15-C15),"0") -> 3.5 | T47: =IF(T15="X",(D15-C15),"0") -> 0
E48: =IF(E16="X",(D16-C16),"0") -> 0 | F48: =IF(F16="X",(D16-C16),"0") -> 0 | G48: =IF(G16="X",(D16-C16),"0") -> 1 | H48: =IF(H16="X",(D16-C16),"0") -> 0 | I48: =IF(I16="X",(D16-C16),"0") -> 0 | J48: =IF(J16="X",(D16-C16),"0") -> 1 | K48: =IF(K16="X",(D16-C16),"0") -> 0 | L48: =IF(L16="X",(D16-C16),"0") -> 0 | M48: =IF(M16="X",(D16-C16),"0") -> 0 | N48: =IF(N16="X",(D16-C16),"0") -> 0 | O48: =IF(O16="X",(D16-C16),"0") -> 0 | P48: =IF(P16="X",(D16-C16),"0") -> 1 | Q48: =IF(Q16="X",(D16-C16),"0") -> 0 | R48: =IF(R16="X",(D16-C16),"0") -> 0 | S48: =IF(S16="X",(D16-C16),"0") -> 1 | T48: =IF(T16="X",(D16-C16),"0") -> 0
E49: =IF(E17="X",(D17-C17),"0") -> 0 | F49: =IF(F17="X",(D17-C17),"0") -> 2.5 | G49: =IF(G17="X",(D17-C17),"0") -> 2.5 | H49: =IF(H17="X",(D17-C17),"0") -> 0 | I49: =IF(I17="X",(D17-C17),"0") -> 0 | J49: =IF(J17="X",(D17-C17),"0") -> 2.5 | K49: =IF(K17="X",(D17-C17),"0") -> 0 | L49: =IF(L17="X",(D17-C17),"0") -> 0 | M49: =IF(M17="X",(D17-C17),"0") -> 0 | N49: =IF(N17="X",(D17-C17),"0") -> 0 | O49: =IF(O17="X",(D17-C17),"0") -> 0 | P49: =IF(P17="X",(D17-C17),"0") -> 2.5 | Q49: =IF(Q17="X",(D17-C17),"0") -> 0 | R49: =IF(R17="X",(D17-C17),"0") -> 0 | S49: =IF(S17="X",(D17-C17),"0") -> 2.5 | T49: =IF(T17="X",(D17-C17),"0") -> 0
E50: =IF(E18="X",(D18-C18),"0") -> 0 | F50: =IF(F18="X",(D18-C18),"0") -> 0 | G50: =IF(G18="X",(D18-C18),"0") -> 18 | H50: =IF(H18="X",(D18-C18),"0") -> 0 | I50: =IF(I18="X",(D18-C18),"0") -> 0 | J50: =IF(J18="X",(D18-C18),"0") -> 18 | K50: =IF(K18="X",(D18-C18),"0") -> 0 | L50: =IF(L18="X",(D18-C18),"0") -> 0 | M50: =IF(M18="X",(D18-C18),"0") -> 18 | N50: =IF(N18="X",(D18-C18),"0") -> 0 | O50: =IF(O18="X",(D18-C18),"0") -> 0 | P50: =IF(P18="X",(D18-C18),"0") -> 18 | Q50: =IF(Q18="X",(D18-C18),"0") -> 0 | R50: =IF(R18="X",(D18-C18),"0") -> 0 | S50: =IF(S18="X",(D18-C18),"0") -> 18 | T50: =IF(T18="X",(D18-C18),"0") -> 0
... E126: =IF(E94="X",(D94-C94),"0") -> 0 | F126: =IF(F94="X",(D94-C94),"0") -> 0 | G126: =IF(G94="X",(D94-C94),"0") -> 0 | H126: =IF(H94="X",(D94-C94),"0") -> 0 | I126: =IF(I94="X",(D94-C94),"0") -> 0 | J126: =IF(J94="X",(D94-C94),"0") -> 0 | K126: =IF(K94="X",(D94-C94),"0") -> 0 | L126: =IF(L94="X",(D94-C94),"0") -> 0 | M126: =IF(M94="X",(D94-C94),"0") -> 0 | N126: =IF(N94="X",(D94-C94),"0") -> 0 | O126: =IF(O94="X",(D94-C94),"0") -> 0 | P126: =IF(P94="X",(D94-C94),"0") -> 0 | Q126: =IF(Q94="X",(D94-C94),"0") -> 0 | R126: =IF(R94="X",(D94-C94),"0") -> 0 | S126: =IF(S94="X",(D94-C94),"0") -> 0 | T126: =IF(T94="X",(D94-C94),"0") -> 0
...

Sheet 226
A1: PROGRAMA DE MANUTENÇÃORODOVIÁRIA
A2: RODOVIAS PAVIMENTADAS | I2: DATA: | J2: ='224'!J2 -> 46204 | N2: TÉCNICO RESP. | O2: ='224'!O2 -> ENG. THIAGO TORQUATO | T2: REGIÃO: | U2: 12
A3: FICHA DE INSPEÇÃO: | B3: =TT!C6 -> RODOVIA TO-280 - TRECHO SÃO VALÉRIO DE NATIVIDADE - NATIVIDADE
A5: S.R.E. | B5: SENTIDO | C5: INÍCIO (KM) | D5: FIM (KM) | E5: CONDIÇÃO DO PAVIMENTO | J5: VEGETAÇÃO | L5: ELEM. DE DRENAGEM | O5: SIN. HOR. | R5: SIN. VERTICAL | U5: OBSERV.
E6: BOM | F6: REM. I. | G6: REM. L | H6: BUR. I | I6: BUR. L | J6: ADEQ. | K6: INADED. | L6: LIMPOS | M6: SUJOS | N6: DAN. | O6: BOM | P6: REG. | Q6: INEXIST. | R6: BOM | S6: POUCAS | T6: INEXIST.
A7: 280ETO0190 | B7: D | C7: 0 | D7: 3 | G7: X | I7: X | J7: X | L7: X | P7: X | S7: X
C8: =D7 -> 3 | D8: 6.1 | G8: X | J8: X | M8: X | P8: X | S8: X
C9: =D8 -> 6.1 | D9: 8.51 | F9: X | J9: X | P9: X | S9: X
A10: 280ETO0180 | B10: D | C10: 0 | D10: 1 | F10: X | J10: X | P10: X | S10: X
C11: =D10 -> 1 | D11: 4.5 | G11: X | J11: X | M11: X | P11: X | S11: X
C12: =D11 -> 4.5 | D12: 9.2 | F12: X | J12: X | P12: X | S12: X
C13: =D12 -> 9.2 | D13: 14.1 | G13: X | I13: X | J13: X | L13: X | P13: X | S13: X
C14: =D13 -> 14.1 | D14: 17.7 | F14: X | I14: X | J14: X | L14: X | P14: X | S14: X
C15: =D14 -> 17.7 | D15: 21.6 | F15: X | J15: X | P15: X | S15: X
C16: =D15 -> 21.6 | D16: 22.5 | G16: X | I16: X | J16: X | P16: X | S16: X
C17: =D16 -> 22.5 | D17: 22.8 | G17: X | I17: X | J17: X | M17: X | P17: X | S17: X
C18: =D17 -> 22.8 | D18: 30.1 | F18: X | J18: X | P18: X | S18: X
C19: =D18 -> 30.1 | D19: 45.2 | G19: X | H19: X | I19: X | J19: X | M19: X | P19: X | S19: X
C20: =D19 -> 45.2 | D20: 45.3 | F20: X | I20: X | J20: X | M20: X | P20: X | S20: X
C21: =D20 -> 45.3 | D21: 47.8 | F21: X | H21: X | J21: X | M21: X | P21: X | S21: X
C22: =D21 -> 47.8 | D22: 52.93 | G22: X | I22: X | J22: X | M22: X | P22: X | S22: X
A23: 280ETO0175 | B23: D | C23: 0 | D23: 2 | G23: X | I23: X | J23: X | P23: X | S23: X
C24: =D23 -> 2 | D24: 3.59 | F24: X | H24: X | J24: X | L24: X | P24: X | S24: X
A32: LEGENDA | B32: CONDIÇÃO DO PAVIMENTO
A33: REM. I | B33: REMENDOS ISOLADOS | E33: ATÉ 10 REMENDOS/KM | I33: BUR. I | J33: BURACOS ISOLADOS | M33: ATÉ 5 BURACOS/KM
A34: REM. L | B34: REMENDOS AO LONGO | E34: MAIS DE 10 REMENDOS/KM | I34: BUR. L | J34: BURACOS AO LONGO | M34: MAIS DE 5 BURACOS/KM
E39: =IF(E7="X",(D7-C7),"0") -> 0 | F39: =IF(F7="X",(D7-C7),"0") -> 0 | G39: =IF(G7="X",(D7-C7),"0") -> 3 | H39: =IF(H7="X",(D7-C7),"0") -> 0 | I39: =IF(I7="X",(D7-C7),"0") -> 3 | J39: =IF(J7="X",(D7-C7),"0") -> 3 | K39: =IF(K7="X",(D7-C7),"0") -> 0 | L39: =IF(L7="X",(D7-C7),"0") -> 3 | M39: =IF(M7="X",(D7-C7),"0") -> 0 | N39: =IF(N7="X",(D7-C7),"0") -> 0 | O39: =IF(O7="X",(D7-C7),"0") -> 0 | P39: =IF(P7="X",(D7-C7),"0") -> 3 | Q39: =IF(Q7="X",(D7-C7),"0") -> 0 | R39: =IF(R7="X",(D7-C7),"0") -> 0 | S39: =IF(S7="X",(D7-C7),"0") -> 3 | T39: =IF(T7="X",(D7-C7),"0") -> 0
E40: =IF(E8="X",(D8-C8),"0") -> 0 | F40: =IF(F8="X",(D8-C8),"0") -> 0 | G40: =IF(G8="X",(D8-C8),"0") -> 3.1 | H40: =IF(H8="X",(D8-C8),"0") -> 0 | I40: =IF(I8="X",(D8-C8),"0") -> 0 | J40: =IF(J8="X",(D8-C8),"0") -> 3.1 | K40: =IF(K8="X",(D8-C8),"0") -> 0 | L40: =IF(L8="X",(D8-C8),"0") -> 0 | M40: =IF(M8="X",(D8-C8),"0") -> 3.1 | N40: =IF(N8="X",(D8-C8),"0") -> 0 | O40: =IF(O8="X",(D8-C8),"0") -> 0 | P40: =IF(P8="X",(D8-C8),"0") -> 3.1 | Q40: =IF(Q8="X",(D8-C8),"0") -> 0 | R40: =IF(R8="X",(D8-C8),"0") -> 0 | S40: =IF(S8="X",(D8-C8),"0") -> 3.1 | T40: =IF(T8="X",(D8-C8),"0") -> 0
E41: =IF(E9="X",(D9-C9),"0") -> 0 | F41: =IF(F9="X",(D9-C9),"0") -> 2.41 | G41: =IF(G9="X",(D9-C9),"0") -> 0 | H41: =IF(H9="X",(D9-C9),"0") -> 0 | I41: =IF(I9="X",(D9-C9),"0") -> 0 | J41: =IF(J9="X",(D9-C9),"0") -> 2.41 | K41: =IF(K9="X",(D9-C9),"0") -> 0 | L41: =IF(L9="X",(D9-C9),"0") -> 0 | M41: =IF(M9="X",(D9-C9),"0") -> 0 | N41: =IF(N9="X",(D9-C9),"0") -> 0 | O41: =IF(O9="X",(D9-C9),"0") -> 0 | P41: =IF(P9="X",(D9-C9),"0") -> 2.41 | Q41: =IF(Q9="X",(D9-C9),"0") -> 0 | R41: =IF(R9="X",(D9-C9),"0") -> 0 | S41: =IF(S9="X",(D9-C9),"0") -> 2.41 | T41: =IF(T9="X",(D9-C9),"0") -> 0
E42: =IF(E10="X",(D10-C10),"0") -> 0 | F42: =IF(F10="X",(D10-C10),"0") -> 1 | G42: =IF(G10="X",(D10-C10),"0") -> 0 | H42: =IF(H10="X",(D10-C10),"0") -> 0 | I42: =IF(I10="X",(D10-C10),"0") -> 0 | J42: =IF(J10="X",(D10-C10),"0") -> 1 | K42: =IF(K10="X",(D10-C10),"0") -> 0 | L42: =IF(L10="X",(D10-C10),"0") -> 0 | M42: =IF(M10="X",(D10-C10),"0") -> 0 | N42: =IF(N10="X",(D10-C10),"0") -> 0 | O42: =IF(O10="X",(D10-C10),"0") -> 0 | P42: =IF(P10="X",(D10-C10),"0") -> 1 | Q42: =IF(Q10="X",(D10-C10),"0") -> 0 | R42: =IF(R10="X",(D10-C10),"0") -> 0 | S42: =IF(S10="X",(D10-C10),"0") -> 1 | T42: =IF(T10="X",(D10-C10),"0") -> 0
E43: =IF(E11="X",(D11-C11),"0") -> 0 | F43: =IF(F11="X",(D11-C11),"0") -> 0 | G43: =IF(G11="X",(D11-C11),"0") -> 3.5 | H43: =IF(H11="X",(D11-C11),"0") -> 0 | I43: =IF(I11="X",(D11-C11),"0") -> 0 | J43: =IF(J11="X",(D11-C11),"0") -> 3.5 | K43: =IF(K11="X",(D11-C11),"0") -> 0 | L43: =IF(L11="X",(D11-C11),"0") -> 0 | M43: =IF(M11="X",(D11-C11),"0") -> 3.5 | N43: =IF(N11="X",(D11-C11),"0") -> 0 | O43: =IF(O11="X",(D11-C11),"0") -> 0 | P43: =IF(P11="X",(D11-C11),"0") -> 3.5 | Q43: =IF(Q11="X",(D11-C11),"0") -> 0 | R43: =IF(R11="X",(D11-C11),"0") -> 0 | S43: =IF(S11="X",(D11-C11),"0") -> 3.5 | T43: =IF(T11="X",(D11-C11),"0") -> 0
E44: =IF(E12="X",(D12-C12),"0") -> 0 | F44: =IF(F12="X",(D12-C12),"0") -> 4.7 | G44: =IF(G12="X",(D12-C12),"0") -> 0 | H44: =IF(H12="X",(D12-C12),"0") -> 0 | I44: =IF(I12="X",(D12-C12),"0") -> 0 | J44: =IF(J12="X",(D12-C12),"0") -> 4.7 | K44: =IF(K12="X",(D12-C12),"0") -> 0 | L44: =IF(L12="X",(D12-C12),"0") -> 0 | M44: =IF(M12="X",(D12-C12),"0") -> 0 | N44: =IF(N12="X",(D12-C12),"0") -> 0 | O44: =IF(O12="X",(D12-C12),"0") -> 0 | P44: =IF(P12="X",(D12-C12),"0") -> 4.7 | Q44: =IF(Q12="X",(D12-C12),"0") -> 0 | R44: =IF(R12="X",(D12-C12),"0") -> 0 | S44: =IF(S12="X",(D12-C12),"0") -> 4.7 | T44: =IF(T12="X",(D12-C12),"0") -> 0
E45: =IF(E13="X",(D13-C13),"0") -> 0 | F45: =IF(F13="X",(D13-C13),"0") -> 0 | G45: =IF(G13="X",(D13-C13),"0") -> 4.9 | H45: =IF(H13="X",(D13-C13),"0") -> 0 | I45: =IF(I13="X",(D13-C13),"0") -> 4.9 | J45: =IF(J13="X",(D13-C13),"0") -> 4.9 | K45: =IF(K13="X",(D13-C13),"0") -> 0 | L45: =IF(L13="X",(D13-C13),"0") -> 4.9 | M45: =IF(M13="X",(D13-C13),"0") -> 0 | N45: =IF(N13="X",(D13-C13),"0") -> 0 | O45: =IF(O13="X",(D13-C13),"0") -> 0 | P45: =IF(P13="X",(D13-C13),"0") -> 4.9 | Q45: =IF(Q13="X",(D13-C13),"0") -> 0 | R45: =IF(R13="X",(D13-C13),"0") -> 0 | S45: =IF(S13="X",(D13-C13),"0") -> 4.9 | T45: =IF(T13="X",(D13-C13),"0") -> 0
E46: =IF(E14="X",(D14-C14),"0") -> 0 | F46: =IF(F14="X",(D14-C14),"0") -> 3.6 | G46: =IF(G14="X",(D14-C14),"0") -> 0 | H46: =IF(H14="X",(D14-C14),"0") -> 0 | I46: =IF(I14="X",(D14-C14),"0") -> 3.6 | J46: =IF(J14="X",(D14-C14),"0") -> 3.6 | K46: =IF(K14="X",(D14-C14),"0") -> 0 | L46: =IF(L14="X",(D14-C14),"0") -> 3.6 | M46: =IF(M14="X",(D14-C14),"0") -> 0 | N46: =IF(N14="X",(D14-C14),"0") -> 0 | O46: =IF(O14="X",(D14-C14),"0") -> 0 | P46: =IF(P14="X",(D14-C14),"0") -> 3.6 | Q46: =IF(Q14="X",(D14-C14),"0") -> 0 | R46: =IF(R14="X",(D14-C14),"0") -> 0 | S46: =IF(S14="X",(D14-C14),"0") -> 3.6 | T46: =IF(T14="X",(D14-C14),"0") -> 0
E47: =IF(E15="X",(D15-C15),"0") -> 0 | F47: =IF(F15="X",(D15-C15),"0") -> 3.9 | G47: =IF(G15="X",(D15-C15),"0") -> 0 | H47: =IF(H15="X",(D15-C15),"0") -> 0 | I47: =IF(I15="X",(D15-C15),"0") -> 0 | J47: =IF(J15="X",(D15-C15),"0") -> 3.9 | K47: =IF(K15="X",(D15-C15),"0") -> 0 | L47: =IF(L15="X",(D15-C15),"0") -> 0 | M47: =IF(M15="X",(D15-C15),"0") -> 0 | N47: =IF(N15="X",(D15-C15),"0") -> 0 | O47: =IF(O15="X",(D15-C15),"0") -> 0 | P47: =IF(P15="X",(D15-C15),"0") -> 3.9 | Q47: =IF(Q15="X",(D15-C15),"0") -> 0 | R47: =IF(R15="X",(D15-C15),"0") -> 0 | S47: =IF(S15="X",(D15-C15),"0") -> 3.9 | T47: =IF(T15="X",(D15-C15),"0") -> 0
E48: =IF(E16="X",(D16-C16),"0") -> 0 | F48: =IF(F16="X",(D16-C16),"0") -> 0 | G48: =IF(G16="X",(D16-C16),"0") -> 0.9 | H48: =IF(H16="X",(D16-C16),"0") -> 0 | I48: =IF(I16="X",(D16-C16),"0") -> 0.9 | J48: =IF(J16="X",(D16-C16),"0") -> 0.9 | K48: =IF(K16="X",(D16-C16),"0") -> 0 | L48: =IF(L16="X",(D16-C16),"0") -> 0 | M48: =IF(M16="X",(D16-C16),"0") -> 0 | N48: =IF(N16="X",(D16-C16),"0") -> 0 | O48: =IF(O16="X",(D16-C16),"0") -> 0 | P48: =IF(P16="X",(D16-C16),"0") -> 0.9 | Q48: =IF(Q16="X",(D16-C16),"0") -> 0 | R48: =IF(R16="X",(D16-C16),"0") -> 0 | S48: =IF(S16="X",(D16-C16),"0") -> 0.9 | T48: =IF(T16="X",(D16-C16),"0") -> 0
E49: =IF(E17="X",(D17-C17),"0") -> 0 | F49: =IF(F17="X",(D17-C17),"0") -> 0 | G49: =IF(G17="X",(D17-C17),"0") -> 0.3 | H49: =IF(H17="X",(D17-C17),"0") -> 0 | I49: =IF(I17="X",(D17-C17),"0") -> 0.3 | J49: =IF(J17="X",(D17-C17),"0") -> 0.3 | K49: =IF(K17="X",(D17-C17),"0") -> 0 | L49: =IF(L17="X",(D17-C17),"0") -> 0 | M49: =IF(M17="X",(D17-C17),"0") -> 0.3 | N49: =IF(N17="X",(D17-C17),"0") -> 0 | O49: =IF(O17="X",(D17-C17),"0") -> 0 | P49: =IF(P17="X",(D17-C17),"0") -> 0.3 | Q49: =IF(Q17="X",(D17-C17),"0") -> 0 | R49: =IF(R17="X",(D17-C17),"0") -> 0 | S49: =IF(S17="X",(D17-C17),"0") -> 0.3 | T49: =IF(T17="X",(D17-C17),"0") -> 0
E50: =IF(E18="X",(D18-C18),"0") -> 0 | F50: =IF(F18="X",(D18-C18),"0") -> 7.3 | G50: =IF(G18="X",(D18-C18),"0") -> 0 | H50: =IF(H18="X",(D18-C18),"0") -> 0 | I50: =IF(I18="X",(D18-C18),"0") -> 0 | J50: =IF(J18="X",(D18-C18),"0") -> 7.3 | K50: =IF(K18="X",(D18-C18),"0") -> 0 | L50: =IF(L18="X",(D18-C18),"0") -> 0 | M50: =IF(M18="X",(D18-C18),"0") -> 0 | N50: =IF(N18="X",(D18-C18),"0") -> 0 | O50: =IF(O18="X",(D18-C18),"0") -> 0 | P50: =IF(P18="X",(D18-C18),"0") -> 7.3 | Q50: =IF(Q18="X",(D18-C18),"0") -> 0 | R50: =IF(R18="X",(D18-C18),"0") -> 0 | S50: =IF(S18="X",(D18-C18),"0") -> 7.3 | T50: =IF(T18="X",(D18-C18),"0") -> 0
... E126: =IF(E94="X",(D94-C94),"0") -> 0 | F126: =IF(F94="X",(D94-C94),"0") -> 0 | G126: =IF(G94="X",(D94-C94),"0") -> 0 | H126: =IF(H94="X",(D94-C94),"0") -> 0 | I126: =IF(I94="X",(D94-C94),"0") -> 0 | J126: =IF(J94="X",(D94-C94),"0") -> 0 | K126: =IF(K94="X",(D94-C94),"0") -> 0 | L126: =IF(L94="X",(D94-C94),"0") -> 0 | M126: =IF(M94="X",(D94-C94),"0") -> 0 | N126: =IF(N94="X",(D94-C94),"0") -> 0 | O126: =IF(O94="X",(D94-C94),"0") -> 0 | P126: =IF(P94="X",(D94-C94),"0") -> 0 | Q126: =IF(Q94="X",(D94-C94),"0") -> 0 | R126: =IF(R94="X",(D94-C94),"0") -> 0 | S126: =IF(S94="X",(D94-C94),"0") -> 0 | T126: =IF(T94="X",(D94-C94),"0") -> 0
E127: =SUM(E39:E126) -> 0 | F127: =SUM(F39:F126) -> 27.1 | G127: =SUM(G39:G126) -> 37.93 | H127: =SUM(H39:H126) -> 19.19 | I127: =SUM(I39:I126) -> 35.03 | J127: =SUM(J39:J126) -> 65.03 | K127: =SUM(K39:K126) -> 0 | L127: =SUM(L39:L126) -> 13.09 | ... T127: =SUM(T39:T126) -> 0

Sheet 227
A1: PROGRAMA DE MANUTENÇÃORODOVIÁRIA
A2: RODOVIAS PAVIMENTADAS | I2: DATA: | J2: ='224'!J2 -> 46204 | N2: TÉCNICO RESP. | O2: ='224'!O2 -> ENG. THIAGO TORQUATO | T2: REGIÃO: | U2: 12
A3: FICHA DE INSPEÇÃO: | B3: =TT!C7 -> RODOVIA TO-280 - TRECHO ENTR. BR-242 - SÃO VALÉRIO DE NATIVIDADE
A5: S.R.E. | B5: SENTIDO | C5: INÍCIO (KM) | D5: FIM (KM) | E5: CONDIÇÃO DO PAVIMENTO | J5: VEGETAÇÃO | L5: ELEM. DE DRENAGEM | O5: SIN. HOR. | R5: SIN. VERTICAL | U5: OBSERV.
E6: BOM | F6: REM. I. | G6: REM. L | H6: BUR. I | I6: BUR. L | J6: ADEQ. | K6: INADED. | L6: LIMPOS | M6: SUJOS | N6: DAN. | O6: BOM | P6: REG. | Q6: INEXIST. | R6: BOM | S6: POUCAS | T6: INEXIST.
A7: 280ETO0220 | B7: D | C7: 0 | D7: 1.2 | F7: X | J7: X | L7: X | P7: X | S7: X
C8: =D7 -> 1.2 | D8: 1.4 | F8: X | J8: X | M8: X | P8: X | S8: X
C9: =D8 -> 1.4 | D9: 2.7 | F9: X | J9: X | M9: X | P9: X | S9: X
C10: =D9 -> 2.7 | D10: 4.4 | G10: X | J10: X | M10: X | P10: X | S10: X
C11: =D10 -> 4.4 | D11: 7.4 | F11: X | J11: X | M11: X | P11: X | S11: X
C12: =D11 -> 7.4 | D12: 7.7 | F12: X | J12: X | M12: X | P12: X | S12: X
C13: =D12 -> 7.7 | D13: 8.6 | F13: X | J13: X | M13: X | P13: X | S13: X
C14: =D13 -> 8.6 | D14: 8.8 | F14: X | J14: X | M14: X | P14: X | S14: X
C15: =D14 -> 8.8 | D15: 15.2 | F15: X | H15: X | I15: X | J15: X | P15: X | S15: X
C16: =D15 -> 15.2 | D16: 17.1 | G16: X | H16: X | I16: X | J16: X | M16: X | P16: X | S16: X
C17: =D16 -> 17.1 | D17: 20.3 | F17: X | H17: X | I17: X | J17: X | M17: X | P17: X | S17: X
C18: =D17 -> 20.3 | D18: 21.52 | F18: X | H18: X | I18: X | J18: X | M18: X | P18: X | S18: X
A19: 280ETO0210 | B19: D | C19: 0 | D19: 4.7 | F19: X | H19: X | J19: X | P19: X | S19: X
C20: =D19 -> 4.7 | D20: 4.9 | G20: X | J20: X | P20: X | S20: X
C21: =D20 -> 4.9 | D21: 9.54 | F21: X | H21: X | J21: X | M21: X | P21: X | S21: X
A22: 280ETO0200 | B22: D | C22: 0 | D22: 1.24 | G22: X | I22: X | J22: X | M22: X | P22: X | S22: X
A23: 280ETO0191 | B23: D | C23: 0 | D23: 1.86 | G23: X | I23: X | J23: X | L23: X | Q23: X | S23: X
A24: ACESSO | B24: D | C24: 0 | D24: 8.99 | F24: X | J24: X | M24: X | N24: X | P24: X | R24: X | S24: X
A32: LEGENDA | B32: CONDIÇÃO DO PAVIMENTO
A33: REM. I | B33: REMENDOS ISOLADOS | E33: ATÉ 10 REMENDOS/KM | I33: BUR. I | J33: BURACOS ISOLADOS | M33: ATÉ 5 BURACOS/KM
A34: REM. L | B34: REMENDOS AO LONGO | E34: MAIS DE 10 REMENDOS/KM | I34: BUR. L | J34: BURACOS AO LONGO | M34: MAIS DE 5 BURACOS/KM
E39: =IF(E7="X",(D7-C7),"0") -> 0 | F39: =IF(F7="X",(D7-C7),"0") -> 1.2 | G39: =IF(G7="X",(D7-C7),"0") -> 0 | H39: =IF(H7="X",(D7-C7),"0") -> 0 | I39: =IF(I7="X",(D7-C7),"0") -> 0 | J39: =IF(J7="X",(D7-C7),"0") -> 1.2 | K39: =IF(K7="X",(D7-C7),"0") -> 0 | L39: =IF(L7="X",(D7-C7),"0") -> 1.2 | M39: =IF(M7="X",(D7-C7),"0") -> 0 | N39: =IF(N7="X",(D7-C7),"0") -> 0 | O39: =IF(O7="X",(D7-C7),"0") -> 0 | P39: =IF(P7="X",(D7-C7),"0") -> 1.2 | Q39: =IF(Q7="X",(D7-C7),"0") -> 0 | R39: =IF(R7="X",(D7-C7),"0") -> 0 | S39: =IF(S7="X",(D7-C7),"0") -> 1.2 | T39: =IF(T7="X",(D7-C7),"0") -> 0
E40: =IF(E8="X",(D8-C8),"0") -> 0 | F40: =IF(F8="X",(D8-C8),"0") -> 0.2 | G40: =IF(G8="X",(D8-C8),"0") -> 0 | H40: =IF(H8="X",(D8-C8),"0") -> 0 | I40: =IF(I8="X",(D8-C8),"0") -> 0 | J40: =IF(J8="X",(D8-C8),"0") -> 0.2 | K40: =IF(K8="X",(D8-C8),"0") -> 0 | L40: =IF(L8="X",(D8-C8),"0") -> 0 | M40: =IF(M8="X",(D8-C8),"0") -> 0.2 | N40: =IF(N8="X",(D8-C8),"0") -> 0 | O40: =IF(O8="X",(D8-C8),"0") -> 0 | P40: =IF(P8="X",(D8-C8),"0") -> 0.2 | Q40: =IF(Q8="X",(D8-C8),"0") -> 0 | R40: =IF(R8="X",(D8-C8),"0") -> 0 | S40: =IF(S8="X",(D8-C8),"0") -> 0.2 | T40: =IF(T8="X",(D8-C8),"0") -> 0
E41: =IF(E9="X",(D9-C9),"0") -> 0 | F41: =IF(F9="X",(D9-C9),"0") -> 1.3 | G41: =IF(G9="X",(D9-C9),"0") -> 0 | H41: =IF(H9="X",(D9-C9),"0") -> 0 | I41: =IF(I9="X",(D9-C9),"0") -> 0 | J41: =IF(J9="X",(D9-C9),"0") -> 1.3 | K41: =IF(K9="X",(D9-C9),"0") -> 0 | L41: =IF(L9="X",(D9-C9),"0") -> 0 | M41: =IF(M9="X",(D9-C9),"0") -> 1.3 | N41: =IF(N9="X",(D9-C9),"0") -> 0 | O41: =IF(O9="X",(D9-C9),"0") -> 0 | P41: =IF(P9="X",(D9-C9),"0") -> 1.3 | Q41: =IF(Q9="X",(D9-C9),"0") -> 0 | R41: =IF(R9="X",(D9-C9),"0") -> 0 | S41: =IF(S9="X",(D9-C9),"0") -> 1.3 | T41: =IF(T9="X",(D9-C9),"0") -> 0
E42: =IF(E10="X",(D10-C10),"0") -> 0 | F42: =IF(F10="X",(D10-C10),"0") -> 0 | G42: =IF(G10="X",(D10-C10),"0") -> 1.7 | H42: =IF(H10="X",(D10-C10),"0") -> 0 | I42: =IF(I10="X",(D10-C10),"0") -> 0 | J42: =IF(J10="X",(D10-C10),"0") -> 1.7 | K42: =IF(K10="X",(D10-C10),"0") -> 0 | L42: =IF(L10="X",(D10-C10),"0") -> 0 | M42: =IF(M10="X",(D10-C10),"0") -> 1.7 | N42: =IF(N10="X",(D10-C10),"0") -> 0 | O42: =IF(O10="X",(D10-C10),"0") -> 0 | P42: =IF(P10="X",(D10-C10),"0") -> 1.7 | Q42: =IF(Q10="X",(D10-C10),"0") -> 0 | R42: =IF(R10="X",(D10-C10),"0") -> 0 | S42: =IF(S10="X",(D10-C10),"0") -> 1.7 | T42: =IF(T10="X",(D10-C10),"0") -> 0
E43: =IF(E11="X",(D11-C11),"0") -> 0 | F43: =IF(F11="X",(D11-C11),"0") -> 3 | G43: =IF(G11="X",(D11-C11),"0") -> 0 | H43: =IF(H11="X",(D11-C11),"0") -> 0 | I43: =IF(I11="X",(D11-C11),"0") -> 0 | J43: =IF(J11="X",(D11-C11),"0") -> 3 | K43: =IF(K11="X",(D11-C11),"0") -> 0 | L43: =IF(L11="X",(D11-C11),"0") -> 0 | M43: =IF(M11="X",(D11-C11),"0") -> 3 | N43: =IF(N11="X",(D11-C11),"0") -> 0 | O43: =IF(O11="X",(D11-C11),"0") -> 0 | P43: =IF(P11="X",(D11-C11),"0") -> 3 | Q43: =IF(Q11="X",(D11-C11),"0") -> 0 | R43: =IF(R11="X",(D11-C11),"0") -> 0 | S43: =IF(S11="X",(D11-C11),"0") -> 3 | T43: =IF(T11="X",(D11-C11),"0") -> 0
E44: =IF(E12="X",(D12-C12),"0") -> 0 | F44: =IF(F12="X",(D12-C12),"0") -> 0.3 | G44: =IF(G12="X",(D12-C12),"0") -> 0 | H44: =IF(H12="X",(D12-C12),"0") -> 0 | I44: =IF(I12="X",(D12-C12),"0") -> 0 | J44: =IF(J12="X",(D12-C12),"0") -> 0.3 | K44: =IF(K12="X",(D12-C12),"0") -> 0 | L44: =IF(L12="X",(D12-C12),"0") -> 0 | M44: =IF(M12="X",(D12-C12),"0") -> 0.3 | N44: =IF(N12="X",(D12-C12),"0") -> 0 | O44: =IF(O12="X",(D12-C12),"0") -> 0 | P44: =IF(P12="X",(D12-C12),"0") -> 0.3 | Q44: =IF(Q12="X",(D12-C12),"0") -> 0 | R44: =IF(R12="X",(D12-C12),"0") -> 0 | S44: =IF(S12="X",(D12-C12),"0") -> 0.3 | T44: =IF(T12="X",(D12-C12),"0") -> 0
E45: =IF(E13="X",(D13-C13),"0") -> 0 | F45: =IF(F13="X",(D13-C13),"0") -> 0.9 | G45: =IF(G13="X",(D13-C13),"0") -> 0 | H45: =IF(H13="X",(D13-C13),"0") -> 0 | I45: =IF(I13="X",(D13-C13),"0") -> 0 | J45: =IF(J13="X",(D13-C13),"0") -> 0.9 | K45: =IF(K13="X",(D13-C13),"0") -> 0 | L45: =IF(L13="X",(D13-C13),"0") -> 0 | M45: =IF(M13="X",(D13-C13),"0") -> 0.9 | N45: =IF(N13="X",(D13-C13),"0") -> 0 | O45: =IF(O13="X",(D13-C13),"0") -> 0 | P45: =IF(P13="X",(D13-C13),"0") -> 0.9 | Q45: =IF(Q13="X",(D13-C13),"0") -> 0 | R45: =IF(R13="X",(D13-C13),"0") -> 0 | S45: =IF(S13="X",(D13-C13),"0") -> 0.9 | T45: =IF(T13="X",(D13-C13),"0") -> 0
E46: =IF(E14="X",(D14-C14),"0") -> 0 | F46: =IF(F14="X",(D14-C14),"0") -> 0.2 | G46: =IF(G14="X",(D14-C14),"0") -> 0 | H46: =IF(H14="X",(D14-C14),"0") -> 0 | I46: =IF(I14="X",(D14-C14),"0") -> 0 | J46: =IF(J14="X",(D14-C14),"0") -> 0.2 | K46: =IF(K14="X",(D14-C14),"0") -> 0 | L46: =IF(L14="X",(D14-C14),"0") -> 0 | M46: =IF(M14="X",(D14-C14),"0") -> 0.2 | N46: =IF(N14="X",(D14-C14),"0") -> 0 | O46: =IF(O14="X",(D14-C14),"0") -> 0 | P46: =IF(P14="X",(D14-C14),"0") -> 0.2 | Q46: =IF(Q14="X",(D14-C14),"0") -> 0 | R46: =IF(R14="X",(D14-C14),"0") -> 0 | S46: =IF(S14="X",(D14-C14),"0") -> 0.2 | T46: =IF(T14="X",(D14-C14),"0") -> 0
E47: =IF(E15="X",(D15-C15),"0") -> 0 | F47: =IF(F15="X",(D15-C15),"0") -> 6.4 | G47: =IF(G15="X",(D15-C15),"0") -> 0 | H47: =IF(H15="X",(D15-C15),"0") -> 6.4 | I47: =IF(I15="X",(D15-C15),"0") -> 6.4 | J47: =IF(J15="X",(D15-C15),"0") -> 6.4 | K47: =IF(K15="X",(D15-C15),"0") -> 0 | L47: =IF(L15="X",(D15-C15),"0") -> 0 | M47: =IF(M15="X",(D15-C15),"0") -> 0 | N47: =IF(N15="X",(D15-C15),"0") -> 0 | O47: =IF(O15="X",(D15-C15),"0") -> 0 | P47: =IF(P15="X",(D15-C15),"0") -> 6.4 | Q47: =IF(Q15="X",(D15-C15),"0") -> 0 | R47: =IF(R15="X",(D15-C15),"0") -> 0 | S47: =IF(S15="X",(D15-C15),"0") -> 6.4 | T47: =IF(T15="X",(D15-C15),"0") -> 0
E48: =IF(E16="X",(D16-C16),"0") -> 0 | F48: =IF(F16="X",(D16-C16),"0") -> 0 | G48: =IF(G16="X",(D16-C16),"0") -> 1.9 | H48: =IF(H16="X",(D16-C16),"0") -> 1.9 | I48: =IF(I16="X",(D16-C16),"0") -> 1.9 | J48: =IF(J16="X",(D16-C16),"0") -> 1.9 | K48: =IF(K16="X",(D16-C16),"0") -> 0 | L48: =IF(L16="X",(D16-C16),"0") -> 0 | M48: =IF(M16="X",(D16-C16),"0") -> 1.9 | N48: =IF(N16="X",(D16-C16),"0") -> 0 | O48: =IF(O16="X",(D16-C16),"0") -> 0 | P48: =IF(P16="X",(D16-C16),"0") -> 1.9 | Q48: =IF(Q16="X",(D16-C16),"0") -> 0 | R48: =IF(R16="X",(D16-C16),"0") -> 0 | S48: =IF(S16="X",(D16-C16),"0") -> 1.9 | T48: =IF(T16="X",(D16-C16),"0") -> 0
E49: =IF(E17="X",(D17-C17),"0") -> 0 | F49: =IF(F17="X",(D17-C17),"0") -> 3.2 | G49: =IF(G17="X",(D17-C17),"0") -> 0 | H49: =IF(H17="X",(D17-C17),"0") -> 3.2 | I49: =IF(I17="X",(D17-C17),"0") -> 3.2 | J49: =IF(J17="X",(D17-C17),"0") -> 3.2 | K49: =IF(K17="X",(D17-C17),"0") -> 0 | L49: =IF(L17="X",(D17-C17),"0") -> 0 | M49: =IF(M17="X",(D17-C17),"0") -> 3.2 | N49: =IF(N17="X",(D17-C17),"0") -> 0 | O49: =IF(O17="X",(D17-C17),"0") -> 0 | P49: =IF(P17="X",(D17-C17),"0") -> 3.2 | Q49: =IF(Q17="X",(D17-C17),"0") -> 0 | R49: =IF(R17="X",(D17-C17),"0") -> 0 | S49: =IF(S17="X",(D17-C17),"0") -> 3.2 | T49: =IF(T17="X",(D17-C17),"0") -> 0
E50: =IF(E18="X",(D18-C18),"0") -> 0 | F50: =IF(F18="X",(D18-C18),"0") -> 1.22 | G50: =IF(G18="X",(D18-C18),"0") -> 0 | H50: =IF(H18="X",(D18-C18),"0") -> 1.22 | I50: =IF(I18="X",(D18-C18),"0") -> 1.22 | J50: =IF(J18="X",(D18-C18),"0") -> 1.22 | K50: =IF(K18="X",(D18-C18),"0") -> 0 | L50: =IF(L18="X",(D18-C18),"0") -> 0 | M50: =IF(M18="X",(D18-C18),"0") -> 1.22 | N50: =IF(N18="X",(D18-C18),"0") -> 0 | O50: =IF(O18="X",(D18-C18),"0") -> 0 | P50: =IF(P18="X",(D18-C18),"0") -> 1.22 | Q50: =IF(Q18="X",(D18-C18),"0") -> 0 | R50: =IF(R18="X",(D18-C18),"0") -> 0 | S50: =IF(S18="X",(D18-C18),"0") -> 1.22 | T50: =IF(T18="X",(D18-C18),"0") -> 0
... E126: =IF(E94="X",(D94-C94),"0") -> 0 | F126: =IF(F94="X",(D94-C94),"0") -> 0 | G126: =IF(G94="X",(D94-C94),"0") -> 0 | H126: =IF(H94="X",(D94-C94),"0") -> 0 | I126: =IF(I94="X",(D94-C94),"0") -> 0 | J126: =IF(J94="X",(D94-C94),"0") -> 0 | K126: =IF(K94="X",(D94-C94),"0") -> 0 | L126: =IF(L94="X",(D94-C94),"0") -> 0 | M126: =IF(M94="X",(D94-C94),"0") -> 0 | N126: =IF(N94="X",(D94-C94),"0") -> 0 | O126: =IF(O94="X",(D94-C94),"0") -> 0 | P126: =IF(P94="X",(D94-C94),"0") -> 0 | Q126: =IF(Q94="X",(D94-C94),"0") -> 0 | R126: =IF(R94="X",(D94-C94),"0") -> 0 | S126: =IF(S94="X",(D94-C94),"0") -> 0 | T126: =IF(T94="X",(D94-C94),"0") -> 0
E127: =SUM(E39:E126) -> 0 | F127: =SUM(F39:F126) -> 36.25 | G127: =SUM(G39:G126) -> 6.9 | H127: =SUM(H39:H126) -> 22.06 | I127: =SUM(I39:I126) -> 15.82 | J127: =SUM(J39:J126) -> 43.15 | K127: =SUM(K39:K126) -> 0 | L127: =SUM(L39:L126) -> 3.06 | ... T127: =SUM(T39:T126) -> 0

Sheet 228
A1: PROGRAMA DE MANUTENÇÃORODOVIÁRIA
A2: RODOVIAS PAVIMENTADAS | I2: DATA: | J2: ='224'!J2 -> 46204 | N2: TÉCNICO RESP. | O2: ='224'!O2 -> ENG. THIAGO TORQUATO | T2: REGIÃO: | U2: 12
A3: FICHA DE INSPEÇÃO: | B3: =TT!C8 -> RODOVIA TO-296 - TRECHO SÃO SALVADOR DO TOCANTINS - PARANÃ
A5: S.R.E. | B5: SENTIDO | C5: INÍCIO (KM) | D5: FIM (KM) | E5: CONDIÇÃO DO PAVIMENTO | J5: VEGETAÇÃO | L5: ELEM. DE DRENAGEM | O5: SIN. HOR. | R5: SIN. VERTICAL | U5: OBSERV.
E6: BOM | F6: REM. I. | G6: REM. L | H6: BUR. I | I6: BUR. L | J6: ADEQ. | K6: INADED. | L6: LIMPOS | M6: SUJOS | N6: DAN. | O6: BOM | P6: REG. | Q6: INEXIST. | R6: BOM | S6: POUCAS | T6: INEXIST.
A7: 296ETO0220 | B7: C | C7: 0 | D7: 50.6 | F7: X | H7: X | K7: X | M7: X | N7: X | O7: X | S7: X
C8: 50.6 | D8: 54.94 | E8: X | K8: X | M8: X | N8: X | O8: X | S8: X
A32: LEGENDA | B32: CONDIÇÃO DO PAVIMENTO
A33: REM. I | B33: REMENDOS ISOLADOS | E33: ATÉ 10 REMENDOS/KM | I33: BUR. I | J33: BURACOS ISOLADOS | M33: ATÉ 5 BURACOS/KM
A34: REM. L | B34: REMENDOS AO LONGO | E34: MAIS DE 10 REMENDOS/KM | I34: BUR. L | J34: BURACOS AO LONGO | M34: MAIS DE 5 BURACOS/KM
E39: =IF(E7="X",(D7-C7),"0") -> 0 | F39: =IF(F7="X",(D7-C7),"0") -> 50.6 | G39: =IF(G7="X",(D7-C7),"0") -> 0 | H39: =IF(H7="X",(D7-C7),"0") -> 50.6 | I39: =IF(I7="X",(D7-C7),"0") -> 0 | J39: =IF(J7="X",(D7-C7),"0") -> 0 | K39: =IF(K7="X",(D7-C7),"0") -> 50.6 | L39: =IF(L7="X",(D7-C7),"0") -> 0 | M39: =IF(M7="X",(D7-C7),"0") -> 50.6 | N39: =IF(N7="X",(D7-C7),"0") -> 50.6 | O39: =IF(O7="X",(D7-C7),"0") -> 50.6 | P39: =IF(P7="X",(D7-C7),"0") -> 0 | Q39: =IF(Q7="X",(D7-C7),"0") -> 0 | R39: =IF(R7="X",(D7-C7),"0") -> 0 | S39: =IF(S7="X",(D7-C7),"0") -> 50.6 | T39: =IF(T7="X",(D7-C7),"0") -> 0
E40: =IF(E8="X",(D8-C8),"0") -> 4.34 | F40: =IF(F8="X",(D8-C8),"0") -> 0 | G40: =IF(G8="X",(D8-C8),"0") -> 0 | H40: =IF(H8="X",(D8-C8),"0") -> 0 | I40: =IF(I8="X",(D8-C8),"0") -> 0 | J40: =IF(J8="X",(D8-C8),"0") -> 0 | K40: =IF(K8="X",(D8-C8),"0") -> 4.34 | L40: =IF(L8="X",(D8-C8),"0") -> 0 | M40: =IF(M8="X",(D8-C8),"0") -> 4.34 | N40: =IF(N8="X",(D8-C8),"0") -> 4.34 | O40: =IF(O8="X",(D8-C8),"0") -> 4.34 | P40: =IF(P8="X",(D8-C8),"0") -> 0 | Q40: =IF(Q8="X",(D8-C8),"0") -> 0 | R40: =IF(R8="X",(D8-C8),"0") -> 0 | S40: =IF(S8="X",(D8-C8),"0") -> 4.34 | T40: =IF(T8="X",(D8-C8),"0") -> 0
E41: =IF(E9="X",(D9-C9),"0") -> 0 | F41: =IF(F9="X",(D9-C9),"0") -> 0 | G41: =IF(G9="X",(D9-C9),"0") -> 0 | H41: =IF(H9="X",(D9-C9),"0") -> 0 | I41: =IF(I9="X",(D9-C9),"0") -> 0 | J41: =IF(J9="X",(D9-C9),"0") -> 0 | K41: =IF(K9="X",(D9-C9),"0") -> 0 | L41: =IF(L9="X",(D9-C9),"0") -> 0 | M41: =IF(M9="X",(D9-C9),"0") -> 0 | N41: =IF(N9="X",(D9-C9),"0") -> 0 | O41: =IF(O9="X",(D9-C9),"0") -> 0 | P41: =IF(P9="X",(D9-C9),"0") -> 0 | Q41: =IF(Q9="X",(D9-C9),"0") -> 0 | R41: =IF(R9="X",(D9-C9),"0") -> 0 | S41: =IF(S9="X",(D9-C9),"0") -> 0 | T41: =IF(T9="X",(D9-C9),"0") -> 0
E42: =IF(E10="X",(D10-C10),"0") -> 0 | F42: =IF(F10="X",(D10-C10),"0") -> 0 | G42: =IF(G10="X",(D10-C10),"0") -> 0 | H42: =IF(H10="X",(D10-C10),"0") -> 0 | I42: =IF(I10="X",(D10-C10),"0") -> 0 | J42: =IF(J10="X",(D10-C10),"0") -> 0 | K42: =IF(K10="X",(D10-C10),"0") -> 0 | L42: =IF(L10="X",(D10-C10),"0") -> 0 | M42: =IF(M10="X",(D10-C10),"0") -> 0 | N42: =IF(N10="X",(D10-C10),"0") -> 0 | O42: =IF(O10="X",(D10-C10),"0") -> 0 | P42: =IF(P10="X",(D10-C10),"0") -> 0 | Q42: =IF(Q10="X",(D10-C10),"0") -> 0 | R42: =IF(R10="X",(D10-C10),"0") -> 0 | S42: =IF(S10="X",(D10-C10),"0") -> 0 | T42: =IF(T10="X",(D10-C10),"0") -> 0
E43: =IF(E11="X",(D11-C11),"0") -> 0 | F43: =IF(F11="X",(D11-C11),"0") -> 0 | G43: =IF(G11="X",(D11-C11),"0") -> 0 | H43: =IF(H11="X",(D11-C11),"0") -> 0 | I43: =IF(I11="X",(D11-C11),"0") -> 0 | J43: =IF(J11="X",(D11-C11),"0") -> 0 | K43: =IF(K11="X",(D11-C11),"0") -> 0 | L43: =IF(L11="X",(D11-C11),"0") -> 0 | M43: =IF(M11="X",(D11-C11),"0") -> 0 | N43: =IF(N11="X",(D11-C11),"0") -> 0 | O43: =IF(O11="X",(D11-C11),"0") -> 0 | P43: =IF(P11="X",(D11-C11),"0") -> 0 | Q43: =IF(Q11="X",(D11-C11),"0") -> 0 | R43: =IF(R11="X",(D11-C11),"0") -> 0 | S43: =IF(S11="X",(D11-C11),"0") -> 0 | T43: =IF(T11="X",(D11-C11),"0") -> 0
E44: =IF(E12="X",(D12-C12),"0") -> 0 | F44: =IF(F12="X",(D12-C12),"0") -> 0 | G44: =IF(G12="X",(D12-C12),"0") -> 0 | H44: =IF(H12="X",(D12-C12),"0") -> 0 | I44: =IF(I12="X",(D12-C12),"0") -> 0 | J44: =IF(J12="X",(D12-C12),"0") -> 0 | K44: =IF(K12="X",(D12-C12),"0") -> 0 | L44: =IF(L12="X",(D12-C12),"0") -> 0 | M44: =IF(M12="X",(D12-C12),"0") -> 0 | N44: =IF(N12="X",(D12-C12),"0") -> 0 | O44: =IF(O12="X",(D12-C12),"0") -> 0 | P44: =IF(P12="X",(D12-C12),"0") -> 0 | Q44: =IF(Q12="X",(D12-C12),"0") -> 0 | R44: =IF(R12="X",(D12-C12),"0") -> 0 | S44: =IF(S12="X",(D12-C12),"0") -> 0 | T44: =IF(T12="X",(D12-C12),"0") -> 0
E45: =IF(E13="X",(D13-C13),"0") -> 0 | F45: =IF(F13="X",(D13-C13),"0") -> 0 | G45: =IF(G13="X",(D13-C13),"0") -> 0 | H45: =IF(H13="X",(D13-C13),"0") -> 0 | I45: =IF(I13="X",(D13-C13),"0") -> 0 | J45: =IF(J13="X",(D13-C13),"0") -> 0 | K45: =IF(K13="X",(D13-C13),"0") -> 0 | L45: =IF(L13="X",(D13-C13),"0") -> 0 | M45: =IF(M13="X",(D13-C13),"0") -> 0 | N45: =IF(N13="X",(D13-C13),"0") -> 0 | O45: =IF(O13="X",(D13-C13),"0") -> 0 | P45: =IF(P13="X",(D13-C13),"0") -> 0 | Q45: =IF(Q13="X",(D13-C13),"0") -> 0 | R45: =IF(R13="X",(D13-C13),"0") -> 0 | S45: =IF(S13="X",(D13-C13),"0") -> 0 | T45: =IF(T13="X",(D13-C13),"0") -> 0
E46: =IF(E14="X",(D14-C14),"0") -> 0 | F46: =IF(F14="X",(D14-C14),"0") -> 0 | G46: =IF(G14="X",(D14-C14),"0") -> 0 | H46: =IF(H14="X",(D14-C14),"0") -> 0 | I46: =IF(I14="X",(D14-C14),"0") -> 0 | J46: =IF(J14="X",(D14-C14),"0") -> 0 | K46: =IF(K14="X",(D14-C14),"0") -> 0 | L46: =IF(L14="X",(D14-C14),"0") -> 0 | M46: =IF(M14="X",(D14-C14),"0") -> 0 | N46: =IF(N14="X",(D14-C14),"0") -> 0 | O46: =IF(O14="X",(D14-C14),"0") -> 0 | P46: =IF(P14="X",(D14-C14),"0") -> 0 | Q46: =IF(Q14="X",(D14-C14),"0") -> 0 | R46: =IF(R14="X",(D14-C14),"0") -> 0 | S46: =IF(S14="X",(D14-C14),"0") -> 0 | T46: =IF(T14="X",(D14-C14),"0") -> 0
E47: =IF(E15="X",(D15-C15),"0") -> 0 | F47: =IF(F15="X",(D15-C15),"0") -> 0 | G47: =IF(G15="X",(D15-C15),"0") -> 0 | H47: =IF(H15="X",(D15-C15),"0") -> 0 | I47: =IF(I15="X",(D15-C15),"0") -> 0 | J47: =IF(J15="X",(D15-C15),"0") -> 0 | K47: =IF(K15="X",(D15-C15),"0") -> 0 | L47: =IF(L15="X",(D15-C15),"0") -> 0 | M47: =IF(M15="X",(D15-C15),"0") -> 0 | N47: =IF(N15="X",(D15-C15),"0") -> 0 | O47: =IF(O15="X",(D15-C15),"0") -> 0 | P47: =IF(P15="X",(D15-C15),"0") -> 0 | Q47: =IF(Q15="X",(D15-C15),"0") -> 0 | R47: =IF(R15="X",(D15-C15),"0") -> 0 | S47: =IF(S15="X",(D15-C15),"0") -> 0 | T47: =IF(T15="X",(D15-C15),"0") -> 0
E48: =IF(E16="X",(D16-C16),"0") -> 0 | F48: =IF(F16="X",(D16-C16),"0") -> 0 | G48: =IF(G16="X",(D16-C16),"0") -> 0 | H48: =IF(H16="X",(D16-C16),"0") -> 0 | I48: =IF(I16="X",(D16-C16),"0") -> 0 | J48: =IF(J16="X",(D16-C16),"0") -> 0 | K48: =IF(K16="X",(D16-C16),"0") -> 0 | L48: =IF(L16="X",(D16-C16),"0") -> 0 | M48: =IF(M16="X",(D16-C16),"0") -> 0 | N48: =IF(N16="X",(D16-C16),"0") -> 0 | O48: =IF(O16="X",(D16-C16),"0") -> 0 | P48: =IF(P16="X",(D16-C16),"0") -> 0 | Q48: =IF(Q16="X",(D16-C16),"0") -> 0 | R48: =IF(R16="X",(D16-C16),"0") -> 0 | S48: =IF(S16="X",(D16-C16),"0") -> 0 | T48: =IF(T16="X",(D16-C16),"0") -> 0
E49: =IF(E17="X",(D17-C17),"0") -> 0 | F49: =IF(F17="X",(D17-C17),"0") -> 0 | G49: =IF(G17="X",(D17-C17),"0") -> 0 | H49: =IF(H17="X",(D17-C17),"0") -> 0 | I49: =IF(I17="X",(D17-C17),"0") -> 0 | J49: =IF(J17="X",(D17-C17),"0") -> 0 | K49: =IF(K17="X",(D17-C17),"0") -> 0 | L49: =IF(L17="X",(D17-C17),"0") -> 0 | M49: =IF(M17="X",(D17-C17),"0") -> 0 | N49: =IF(N17="X",(D17-C17),"0") -> 0 | O49: =IF(O17="X",(D17-C17),"0") -> 0 | P49: =IF(P17="X",(D17-C17),"0") -> 0 | Q49: =IF(Q17="X",(D17-C17),"0") -> 0 | R49: =IF(R17="X",(D17-C17),"0") -> 0 | S49: =IF(S17="X",(D17-C17),"0") -> 0 | T49: =IF(T17="X",(D17-C17),"0") -> 0
E50: =IF(E18="X",(D18-C18),"0") -> 0 | F50: =IF(F18="X",(D18-C18),"0") -> 0 | G50: =IF(G18="X",(D18-C18),"0") -> 0 | H50: =IF(H18="X",(D18-C18),"0") -> 0 | I50: =IF(I18="X",(D18-C18),"0") -> 0 | J50: =IF(J18="X",(D18-C18),"0") -> 0 | K50: =IF(K18="X",(D18-C18),"0") -> 0 | L50: =IF(L18="X",(D18-C18),"0") -> 0 | M50: =IF(M18="X",(D18-C18),"0") -> 0 | N50: =IF(N18="X",(D18-C18),"0") -> 0 | O50: =IF(O18="X",(D18-C18),"0") -> 0 | P50: =IF(P18="X",(D18-C18),"0") -> 0 | Q50: =IF(Q18="X",(D18-C18),"0") -> 0 | R50: =IF(R18="X",(D18-C18),"0") -> 0 | S50: =IF(S18="X",(D18-C18),"0") -> 0 | T50: =IF(T18="X",(D18-C18),"0") -> 0
... E126: =IF(E94="X",(D94-C94),"0") -> 0 | F126: =IF(F94="X",(D94-C94),"0") -> 0 | G126: =IF(G94="X",(D94-C94),"0") -> 0 | H126: =IF(H94="X",(D94-C94),"0") -> 0 | I126: =IF(I94="X",(D94-C94),"0") -> 0 | J126: =IF(J94="X",(D94-C94),"0") -> 0 | K126: =IF(K94="X",(D94-C94),"0") -> 0 | L126: =IF(L94="X",(D94-C94),"0") -> 0 | M126: =IF(M94="X",(D94-C94),"0") -> 0 | N126: =IF(N94="X",(D94-C94),"0") -> 0 | O126: =IF(O94="X",(D94-C94),"0") -> 0 | P126: =IF(P94="X",(D94-C94),"0") -> 0 | Q126: =IF(Q94="X",(D94-C94),"0") -> 0 | R126: =IF(R94="X",(D94-C94),"0") -> 0 | S126: =IF(S94="X",(D94-C94),"0") -> 0 | T126: =IF(T94="X",(D94-C94),"0") -> 0
E127: =SUM(E39:E126) -> 4.34 | F127: =SUM(F39:F126) -> 50.6 | G127: =SUM(G39:G126) -> 0 | H127: =SUM(H39:H126) -> 50.6 | I127: =SUM(I39:I126) -> 0 | J127: =SUM(J39:J126) -> 0 | K127: =SUM(K39:K126) -> 54.94 | L127: =SUM(L39:L126) -> 0 | ... T127: =SUM(T39:T126) -> 0

Sheet 229
A1: PROGRAMA DE MANUTENÇÃORODOVIÁRIA
A2: RODOVIAS PAVIMENTADAS | I2: DATA: | J2: ='224'!J2 -> 46204 | N2: TÉCNICO RESP. | O2: ='224'!O2 -> ENG. THIAGO TORQUATO | T2: REGIÃO: | U2: 12
A3: FICHA DE INSPEÇÃO: | B3: =TT!C9 -> RODOVIA TO-296 - TRECHO JAÚ DO TOCANTINS - SÃO SALVADOR DO TOCANTINS
A5: S.R.E. | B5: SENTIDO | C5: INÍCIO (KM) | D5: FIM (KM) | E5: CONDIÇÃO DO PAVIMENTO | J5: VEGETAÇÃO | L5: ELEM. DE DRENAGEM | O5: SIN. HOR. | R5: SIN. VERTICAL | U5: OBSERV.
E6: BOM | F6: REM. I. | G6: REM. L | H6: BUR. I | I6: BUR. L | J6: ADEQ. | K6: INADED. | L6: LIMPOS | M6: SUJOS | N6: DAN. | O6: BOM | P6: REG. | Q6: INEXIST. | R6: BOM | S6: POUCAS | T6: INEXIST.
A7: 296ETO0230 | B7: C | C7: 0 | D7: 1.97 | G7: X | J7: X | M7: X | P7: X | S7: X
J8: X
J9: X
A10: 296ETO0261 | B10: C | C10: 0 | D10: 0.2 | E10: X | J10: X | L10: X | P10: X | S10: X
A11: 296ETO0262 | B11: C | C11: 0 | D11: 0.24 | E11: X | J11: X | L11: X | P11: X | S11: X
A32: LEGENDA | B32: CONDIÇÃO DO PAVIMENTO
A33: REM. I | B33: REMENDOS ISOLADOS | E33: ATÉ 10 REMENDOS/KM | I33: BUR. I | J33: BURACOS ISOLADOS | M33: ATÉ 5 BURACOS/KM
A34: REM. L | B34: REMENDOS AO LONGO | E34: MAIS DE 10 REMENDOS/KM | I34: BUR. L | J34: BURACOS AO LONGO | M34: MAIS DE 5 BURACOS/KM
E39: =IF(E7="X",(D7-C7),"0") -> 0 | F39: =IF(F7="X",(D7-C7),"0") -> 0 | G39: =IF(G7="X",(D7-C7),"0") -> 1.97 | H39: =IF(H7="X",(D7-C7),"0") -> 0 | I39: =IF(I7="X",(D7-C7),"0") -> 0 | J39: =IF(J7="X",(D7-C7),"0") -> 1.97 | K39: =IF(K7="X",(D7-C7),"0") -> 0 | L39: =IF(L7="X",(D7-C7),"0") -> 0 | M39: =IF(M7="X",(D7-C7),"0") -> 1.97 | N39: =IF(N7="X",(D7-C7),"0") -> 0 | O39: =IF(O7="X",(D7-C7),"0") -> 0 | P39: =IF(P7="X",(D7-C7),"0") -> 1.97 | Q39: =IF(Q7="X",(D7-C7),"0") -> 0 | R39: =IF(R7="X",(D7-C7),"0") -> 0 | S39: =IF(S7="X",(D7-C7),"0") -> 1.97 | T39: =IF(T7="X",(D7-C7),"0") -> 0
E40: =IF(E8="X",(D8-C8),"0") -> 0 | F40: =IF(F8="X",(D8-C8),"0") -> 0 | G40: =IF(G8="X",(D8-C8),"0") -> 0 | H40: =IF(H8="X",(D8-C8),"0") -> 0 | I40: =IF(I8="X",(D8-C8),"0") -> 0 | J40: =IF(J8="X",(D8-C8),"0") -> 0 | K40: =IF(K8="X",(D8-C8),"0") -> 0 | L40: =IF(L8="X",(D8-C8),"0") -> 0 | M40: =IF(M8="X",(D8-C8),"0") -> 0 | N40: =IF(N8="X",(D8-C8),"0") -> 0 | O40: =IF(O8="X",(D8-C8),"0") -> 0 | P40: =IF(P8="X",(D8-C8),"0") -> 0 | Q40: =IF(Q8="X",(D8-C8),"0") -> 0 | R40: =IF(R8="X",(D8-C8),"0") -> 0 | S40: =IF(S8="X",(D8-C8),"0") -> 0 | T40: =IF(T8="X",(D8-C8),"0") -> 0
