Workbook

Sheet Trechos
A1: RELAÇÃO DE TRECHOS PAVIMENTDOS R.13
A2: LOTE | B2: N. | C2: TRECHO | D2: S.R.E | E2: SUBTRECHOS | F2: EXT. (KM) | G2: TIPO | H2: 45839 | I2: 45870
A3: 13 | B3: 246 | C3: RODOVIA TO-040 - TRECHO ALMAS - PORTO ALEGRE DO TOCANTINS | D3: 040ETO0150 | E3: ENTR. TO-280 (ALMAS) - ENTR. TO-477 | F3: 1.5702205 | G3: PPS | H3: X
A4: 13 | B4: 246 | C4: RODOVIA TO-040 - TRECHO ALMAS - PORTO ALEGRE DO TOCANTINS | D4: 040ETO0160 | E4: ENTR. TO-477 - PORTO ALEGRE DO TOCANTINS | F4: 13.323392 | G4: PPS | H4: X
A5: 13 | B5: 247 | C5: RODOVIA TO-040 - TRECHO DIANÓPOLIS - NOVO JARDIM | D5: 040ETO0190 | E5: ENTR. TO-476 (DIANÓPOLIS) - ENTR. TO-387-TO-110 | F5: 6.2949204 | G5: PPS | H5: X
A6: 13 | B6: 247 | C6: RODOVIA TO-040 - TRECHO DIANÓPOLIS - NOVO JARDIM | D6: 040ETO0200 | E6: ENTR. TO-387-TO-110 - AMARALINA | F6: 11.481209 | G6: PPS | H6: X
A7: 13 | B7: 247 | C7: RODOVIA TO-040 - TRECHO DIANÓPOLIS - NOVO JARDIM | D7: 040ETO0210 | E7: AMARALINA - NOVO JARDIM | F7: 18.27038 | G7: PPS | H7: X
A8: 13 | B8: 248 | C8: RODOVIA TO-040 - TRECHO NOVO JARDIM - DIVISA TO-BA | D8: 040ETO0220 | E8: NOVO JARDIM - ENTR. TO-110 | F8: 5.8182596 | G8: PPS | H8: X
A9: 13 | B9: 248 | C9: RODOVIA TO-040 - TRECHO NOVO JARDIM - DIVISA TO-BA | D9: 040ETO0230 | E9: ENTR. TO-110 - DIV TO-BA | F9: 37.187731 | G9: PPS | H9: X
A10: 13 | B10: 249 | C10: RODOVIA TO-040 - TRECHO PORTO ALEGRE DO TOCANTINS - DIANÓPOLIS | D10: ACESSO | E10: ENTR. TO-040 - PROJETO MANOEL ALVES | F10: 8.6840399 | G10: PPS | H10: X
A11: 13 | B11: 249 | C11: RODOVIA TO-040 - TRECHO PORTO ALEGRE DO TOCANTINS - DIANÓPOLIS | D11: 040ETO0170 | E11: PORTO ALEGRE DO TOCANTINS - ENTR.TO-387 | F11: 15.045976 | G11: PPS | H11: X
A12: 13 | B12: 249 | C12: RODOVIA TO-040 - TRECHO PORTO ALEGRE DO TOCANTINS - DIANÓPOLIS | D12: 040ETO0180 | E12: ENTR.TO-387 - ENTR.TO-476 (DIANÓPOLIS) | F12: 11.205251 | G12: PPS | H12: X
A13: 13 | B13: 250 | C13: RODOVIA TO-050 - TRECHO ARRAIAS - DIVISA TO-GO | D13: 050ETO0270 | E13: ARRAIAS (ACESSO SUL) - ENTR. TO-499 | F13: 4.9837539 | G13: PPS | H13: X
A14: 13 | B14: 250 | C14: RODOVIA TO-050 - TRECHO ARRAIAS - DIVISA TO-GO | D14: 050ETO0280 | E14: ENTR. TO-499 - ENTR. TO-296 | F14: 1.8568038 | G14: PPS | H14: X
A15: 13 | B15: 250 | C15: RODOVIA TO-050 - TRECHO ARRAIAS - DIVISA TO-GO | D15: 050ETO0290 | E15: ENTR. TO-296 - DIV TO-GO | F15: 8.5478498 | G15: PPS
A16: 13 | B16: 251 | C16: RODOVIA TO-050 - TRECHO CONCEIÇÃO DO TOCANTINS - ARRAIAS | D16: 050ETO0230 | E16: CONCEIÇÃO DO TOCANTINS - ENTR. BR-242 | F16: 33.953785 | G16: PPS | H16: X
A17: 13 | B17: 251 | C17: RODOVIA TO-050 - TRECHO CONCEIÇÃO DO TOCANTINS - ARRAIAS | D17: 050ETO0240 | E17: ENTR. BR-242 - ENTR. TO-296 | F17: 47.950062 | G17: PPS | H17: X
A18: 13 | B18: 251 | C18: RODOVIA TO-050 - TRECHO CONCEIÇÃO DO TOCANTINS - ARRAIAS | D18: 050ETO0250 | E18: ENTR. TO-296 - ARRAIAS (ACESSO NORTE) | F18: 18.959078 | G18: PPS | H18: X
A19: 13 | B19: 251 | C19: RODOVIA TO-050 - TRECHO CONCEIÇÃO DO TOCANTINS - ARRAIAS | D19: 050ETO0260 | E19: ARRAIAS (ACESSO NORTE) - ARRAIAS (ACESSO SUL) | F19: 3.648839 | G19: PPS | H19: X
A20: 13 | B20: 252 | C20: RODOVIA TO-050 - TRECHO ENTR. BR-010 (POVOADO PRÍNCIPE) - CONCEIÇÃO DO TOCANTINS | D20: 387ETO0071 | E20: CONCEIÇÃO DO TOCANTINS *TRECHO URBANO* | F20: 1.4023074 | G20: PSU | H20: X
A21: 13 | B21: 252 | C21: RODOVIA TO-050 - TRECHO ENTR. BR-010 (POVOADO PRÍNCIPE) - CONCEIÇÃO DO TOCANTINS | D21: 050ETO0210 | E21: ENTR. BR-010 (PRÍNCIPE) - ENTR. TO-387 | F21: 45.752332 | G21: PPS | H21: X
A22: 13 | B22: 252 | C22: RODOVIA TO-050 - TRECHO ENTR. BR-010 (POVOADO PRÍNCIPE) - CONCEIÇÃO DO TOCANTINS | D22: 050ETO0220 | E22: ENTR. TO-387 - CONCEIÇÃO DO TOCANTINS | F22: 5.5180318 | G22: PPS | H22: X
A23: 13 | B23: 253 | C23: RODOVIA TO-110 - TRECHO AURORA DO TOCANTINS - LAVANDEIRA | D23: 110ETO0330 | E23: AURORA DO TOCANTINS *TRECHO URBANO* - LAVANDEIRA | F23: 15.560727 | G23: PPS | H23: X
A24: 13 | B24: 254 | C24: RODOVIA TO-110 - TRECHO COMBINADO - NOVO ALEGRE - DIVISA TO-GO | D24: 110ETO0341 | E24: COMBINADO *TRECHO URBANO* | F24: 1.165205 | G24: PSU | H24: X
A25: 13 | B25: 254 | C25: RODOVIA TO-110 - TRECHO COMBINADO - NOVO ALEGRE - DIVISA TO-GO | D25: 110ETO0370 | E25: COMBINADO *TRECHO URBANO* - NOVO ALEGRE *TRECHO URBANO* | F25: 10.290561 | G25: PPS | H25: X
A26: 13 | B26: 254 | C26: RODOVIA TO-110 - TRECHO COMBINADO - NOVO ALEGRE - DIVISA TO-GO | D26: 110ETO0390 | E26: NOVO ALEGRE *TRECHO URBANO* - DIV TO-GO | F26: 6.5224719 | G26: PPS | H26: X
A27: 13 | B27: 255 | C27: RODOVIA TO-110 - TRECHO ENTR. TO-040 (DIANÓPOLIS) - DIVISA TO-BA (GARGANTA) | D27: 110ETO0110 | E27: GARGANTA - ENTR. TO-040-TO-280 | F27: 57.452309 | G27: PPS | H27: X
... A41: 13 | B41: 259 | C41: RODOVIA TO-110 - TRECHO TAGUATINGA - AURORA DO TOCANTINS | D41: ACESSO | E41: ENTR- TO-110 - RIO AZUIS | F41: 1.0864508 | G41: PPS | H41: X
A42: 13 | B42: 265 | C42: RODOVIA TO-387 - TRECHO ENTR. TO-040 - TAIPAS DO TOCANTINS | D42: 387ETO0041 | E42: INÍCIO PU TAIPAS - FIM PU TAIPAS | F42: 1.0866111 | G42: PSU
A43: 13 | B43: 266 | C43: RODOVIA TO-476 - TRECHO RIO DA CONCEIÇÃO - DIANÓPOLIS | D43: 476ETO0060 | E43: RIO DA CONCEIÇÃO *TRECHO URBANO* - CATINGUEIRO | F43: 6.9762043 | G43: PPS | H43: X
A44: 13 | B44: 266 | C44: RODOVIA TO-476 - TRECHO RIO DA CONCEIÇÃO - DIANÓPOLIS | D44: 476ETO0070 | E44: CATINGUEIRO - ENTR. TO-040-TO-280-TO-387 | F44: 19.761116 | G44: PPS | H44: X
F45: =SUM(F3:F44) -> 548.52427

Sheet 246
A1: PROGRAMA DE MANUTENÇÃORODOVIÁRIA
D2: RODOVIAS PAVIMENTADAS | I2: DATA: | J2: 46204 | N2: TÉCNICO RESP. | O2: ENG. THIAGO TORQUATO
A3: FICHA DE INSPEÇÃO: | B3: ='T.T.'!C4 -> RODOVIA TO-040 - TRECHO ALMAS - PORTO ALEGRE DO TOCANTINS | O3: REGIÃO: | P3: 13
A5: S.R.E. | B5: SENTIDO | C5: INÍCIO (KM) | D5: FIM (KM) | E5: CONDIÇÃO DO PAVIMENTO | J5: VEGETAÇÃO | L5: ELEM. DE DRENAGEM | O5: SIN. HOR. | R5: SIN. VERTICAL | U5: OBSERV.
E6: BOM | F6: REM. I. | G6: REM. L | H6: BUR. I | I6: BUR. L | J6: ADEQ. | K6: INADED. | L6: LIMPOS | M6: SUJOS | N6: DAN. | O6: BOM | P6: REG. | Q6: INEXIST. | R6: BOM | S6: POUCAS | T6: INEXIST.
A7: 040ETO0160 | B7: D | C7: 0 | D7: 8 | G7: X | J7: X | M7: X | P7: X | S7: X
C8: 8 | D8: 13.3 | G8: X | J8: X | M8: X | P8: X | S8: X
A9: 040ETO0150 | B9: D | C9: 0 | D9: 1.57 | G9: X | J9: X | M9: X | P9: X | S9: X
A32: LEGENDA | B32: CONDIÇÃO DO PAVIMENTO
A33: REM. I | B33: REMENDOS ISOLADOS | E33: ATÉ 10 REMENDOS/KM | I33: BUR. I | J33: BURACOS ISOLADOS | M33: ATÉ 5 BURACOS/KM
A34: REM. L | B34: REMENDOS AO LONGO | E34: MAIS DE 10 REMENDOS/KM | I34: BUR. L | J34: BURACOS AO LONGO | M34: MAIS DE 5 BURACOS/KM
E39: =IF(E7="X",(D7-C7),"0") -> 0 | F39: =IF(F7="X",(D7-C7),"0") -> 0 | G39: =IF(G7="X",(D7-C7),"0") -> 8 | H39: =IF(H7="X",(D7-C7),"0") -> 0 | I39: =IF(I7="X",(D7-C7),"0") -> 0 | J39: =IF(J7="X",(D7-C7),"0") -> 8 | K39: =IF(K7="X",(D7-C7),"0") -> 0 | L39: =IF(L7="X",(D7-C7),"0") -> 0 | M39: =IF(M7="X",(D7-C7),"0") -> 8 | N39: =IF(N7="X",(D7-C7),"0") -> 0 | O39: =IF(O7="X",(D7-C7),"0") -> 0 | P39: =IF(P7="X",(D7-C7),"0") -> 8 | Q39: =IF(Q7="X",(D7-C7),"0") -> 0 | R39: =IF(R7="X",(D7-C7),"0") -> 0 | S39: =IF(S7="X",(D7-C7),"0") -> 8 | T39: =IF(T7="X",(D7-C7),"0") -> 0
E40: =IF(E8="X",(D8-C8),"0") -> 0 | F40: =IF(F8="X",(D8-C8),"0") -> 0 | G40: =IF(G8="X",(D8-C8),"0") -> 5.3 | H40: =IF(H8="X",(D8-C8),"0") -> 0 | I40: =IF(I8="X",(D8-C8),"0") -> 0 | J40: =IF(J8="X",(D8-C8),"0") -> 5.3 | K40: =IF(K8="X",(D8-C8),"0") -> 0 | L40: =IF(L8="X",(D8-C8),"0") -> 0 | M40: =IF(M8="X",(D8-C8),"0") -> 5.3 | N40: =IF(N8="X",(D8-C8),"0") -> 0 | O40: =IF(O8="X",(D8-C8),"0") -> 0 | P40: =IF(P8="X",(D8-C8),"0") -> 5.3 | Q40: =IF(Q8="X",(D8-C8),"0") -> 0 | R40: =IF(R8="X",(D8-C8),"0") -> 0 | S40: =IF(S8="X",(D8-C8),"0") -> 5.3 | T40: =IF(T8="X",(D8-C8),"0") -> 0
E41: =IF(E9="X",(D9-C9),"0") -> 0 | F41: =IF(F9="X",(D9-C9),"0") -> 0 | G41: =IF(G9="X",(D9-C9),"0") -> 1.57 | H41: =IF(H9="X",(D9-C9),"0") -> 0 | I41: =IF(I9="X",(D9-C9),"0") -> 0 | J41: =IF(J9="X",(D9-C9),"0") -> 1.57 | K41: =IF(K9="X",(D9-C9),"0") -> 0 | L41: =IF(L9="X",(D9-C9),"0") -> 0 | M41: =IF(M9="X",(D9-C9),"0") -> 1.57 | N41: =IF(N9="X",(D9-C9),"0") -> 0 | O41: =IF(O9="X",(D9-C9),"0") -> 0 | P41: =IF(P9="X",(D9-C9),"0") -> 1.57 | Q41: =IF(Q9="X",(D9-C9),"0") -> 0 | R41: =IF(R9="X",(D9-C9),"0") -> 0 | S41: =IF(S9="X",(D9-C9),"0") -> 1.57 | T41: =IF(T9="X",(D9-C9),"0") -> 0
E42: =IF(E10="X",(D10-C10),"0") -> 0 | F42: =IF(F10="X",(D10-C10),"0") -> 0 | G42: =IF(G10="X",(D10-C10),"0") -> 0 | H42: =IF(H10="X",(D10-C10),"0") -> 0 | I42: =IF(I10="X",(D10-C10),"0") -> 0 | J42: =IF(J10="X",(D10-C10),"0") -> 0 | K42: =IF(K10="X",(D10-C10),"0") -> 0 | L42: =IF(L10="X",(D10-C10),"0") -> 0 | M42: =IF(M10="X",(D10-C10),"0") -> 0 | N42: =IF(N10="X",(D10-C10),"0") -> 0 | O42: =IF(O10="X",(D10-C10),"0") -> 0 | P42: =IF(P10="X",(D10-C10),"0") -> 0 | Q42: =IF(Q10="X",(D10-C10),"0") -> 0 | R42: =IF(R10="X",(D10-C10),"0") -> 0 | S42: =IF(S10="X",(D10-C10),"0") -> 0 | T42: =IF(T10="X",(D10-C10),"0") -> 0
E43: =IF(E11="X",(D11-C11),"0") -> 0 | F43: =IF(F11="X",(D11-C11),"0") -> 0 | G43: =IF(G11="X",(D11-C11),"0") -> 0 | H43: =IF(H11="X",(D11-C11),"0") -> 0 | I43: =IF(I11="X",(D11-C11),"0") -> 0 | J43: =IF(J11="X",(D11-C11),"0") -> 0 | K43: =IF(K11="X",(D11-C11),"0") -> 0 | L43: =IF(L11="X",(D11-C11),"0") -> 0 | M43: =IF(M11="X",(D11-C11),"0") -> 0 | N43: =IF(N11="X",(D11-C11),"0") -> 0 | O43: =IF(O11="X",(D11-C11),"0") -> 0 | P43: =IF(P11="X",(D11-C11),"0") -> 0 | Q43: =IF(Q11="X",(D11-C11),"0") -> 0 | R43: =IF(R11="X",(D11-C11),"0") -> 0 | S43: =IF(S11="X",(D11-C11),"0") -> 0 | T43: =IF(T11="X",(D11-C11),"0") -> 0
E44: =IF(E12="X",(D12-C12),"0") -> 0 | F44: =IF(F12="X",(D12-C12),"0") -> 0 | G44: =IF(G12="X",(D12-C12),"0") -> 0 | H44: =IF(H12="X",(D12-C12),"0") -> 0 | I44: =IF(I12="X",(D12-C12),"0") -> 0 | J44: =IF(J12="X",(D12-C12),"0") -> 0 | K44: =IF(K12="X",(D12-C12),"0") -> 0 | L44: =IF(L12="X",(D12-C12),"0") -> 0 | M44: =IF(M12="X",(D12-C12),"0") -> 0 | N44: =IF(N12="X",(D12-C12),"0") -> 0 | O44: =IF(O12="X",(D12-C12),"0") -> 0 | P44: =IF(P12="X",(D12-C12),"0") -> 0 | Q44: =IF(Q12="X",(D12-C12),"0") -> 0 | R44: =IF(R12="X",(D12-C12),"0") -> 0 | S44: =IF(S12="X",(D12-C12),"0") -> 0 | T44: =IF(T12="X",(D12-C12),"0") -> 0
E45: =IF(E13="X",(D13-C13),"0") -> 0 | F45: =IF(F13="X",(D13-C13),"0") -> 0 | G45: =IF(G13="X",(D13-C13),"0") -> 0 | H45: =IF(H13="X",(D13-C13),"0") -> 0 | I45: =IF(I13="X",(D13-C13),"0") -> 0 | J45: =IF(J13="X",(D13-C13),"0") -> 0 | K45: =IF(K13="X",(D13-C13),"0") -> 0 | L45: =IF(L13="X",(D13-C13),"0") -> 0 | M45: =IF(M13="X",(D13-C13),"0") -> 0 | N45: =IF(N13="X",(D13-C13),"0") -> 0 | O45: =IF(O13="X",(D13-C13),"0") -> 0 | P45: =IF(P13="X",(D13-C13),"0") -> 0 | Q45: =IF(Q13="X",(D13-C13),"0") -> 0 | R45: =IF(R13="X",(D13-C13),"0") -> 0 | S45: =IF(S13="X",(D13-C13),"0") -> 0 | T45: =IF(T13="X",(D13-C13),"0") -> 0
E46: =IF(E14="X",(D14-C14),"0") -> 0 | F46: =IF(F14="X",(D14-C14),"0") -> 0 | G46: =IF(G14="X",(D14-C14),"0") -> 0 | H46: =IF(H14="X",(D14-C14),"0") -> 0 | I46: =IF(I14="X",(D14-C14),"0") -> 0 | J46: =IF(J14="X",(D14-C14),"0") -> 0 | K46: =IF(K14="X",(D14-C14),"0") -> 0 | L46: =IF(L14="X",(D14-C14),"0") -> 0 | M46: =IF(M14="X",(D14-C14),"0") -> 0 | N46: =IF(N14="X",(D14-C14),"0") -> 0 | O46: =IF(O14="X",(D14-C14),"0") -> 0 | P46: =IF(P14="X",(D14-C14),"0") -> 0 | Q46: =IF(Q14="X",(D14-C14),"0") -> 0 | R46: =IF(R14="X",(D14-C14),"0") -> 0 | S46: =IF(S14="X",(D14-C14),"0") -> 0 | T46: =IF(T14="X",(D14-C14),"0") -> 0
E47: =IF(E15="X",(D15-C15),"0") -> 0 | F47: =IF(F15="X",(D15-C15),"0") -> 0 | G47: =IF(G15="X",(D15-C15),"0") -> 0 | H47: =IF(H15="X",(D15-C15),"0") -> 0 | I47: =IF(I15="X",(D15-C15),"0") -> 0 | J47: =IF(J15="X",(D15-C15),"0") -> 0 | K47: =IF(K15="X",(D15-C15),"0") -> 0 | L47: =IF(L15="X",(D15-C15),"0") -> 0 | M47: =IF(M15="X",(D15-C15),"0") -> 0 | N47: =IF(N15="X",(D15-C15),"0") -> 0 | O47: =IF(O15="X",(D15-C15),"0") -> 0 | P47: =IF(P15="X",(D15-C15),"0") -> 0 | Q47: =IF(Q15="X",(D15-C15),"0") -> 0 | R47: =IF(R15="X",(D15-C15),"0") -> 0 | S47: =IF(S15="X",(D15-C15),"0") -> 0 | T47: =IF(T15="X",(D15-C15),"0") -> 0
E48: =IF(E16="X",(D16-C16),"0") -> 0 | F48: =IF(F16="X",(D16-C16),"0") -> 0 | G48: =IF(G16="X",(D16-C16),"0") -> 0 | H48: =IF(H16="X",(D16-C16),"0") -> 0 | I48: =IF(I16="X",(D16-C16),"0") -> 0 | J48: =IF(J16="X",(D16-C16),"0") -> 0 | K48: =IF(K16="X",(D16-C16),"0") -> 0 | L48: =IF(L16="X",(D16-C16),"0") -> 0 | M48: =IF(M16="X",(D16-C16),"0") -> 0 | N48: =IF(N16="X",(D16-C16),"0") -> 0 | O48: =IF(O16="X",(D16-C16),"0") -> 0 | P48: =IF(P16="X",(D16-C16),"0") -> 0 | Q48: =IF(Q16="X",(D16-C16),"0") -> 0 | R48: =IF(R16="X",(D16-C16),"0") -> 0 | S48: =IF(S16="X",(D16-C16),"0") -> 0 | T48: =IF(T16="X",(D16-C16),"0") -> 0
E49: =IF(E17="X",(D17-C17),"0") -> 0 | F49: =IF(F17="X",(D17-C17),"0") -> 0 | G49: =IF(G17="X",(D17-C17),"0") -> 0 | H49: =IF(H17="X",(D17-C17),"0") -> 0 | I49: =IF(I17="X",(D17-C17),"0") -> 0 | J49: =IF(J17="X",(D17-C17),"0") -> 0 | K49: =IF(K17="X",(D17-C17),"0") -> 0 | L49: =IF(L17="X",(D17-C17),"0") -> 0 | M49: =IF(M17="X",(D17-C17),"0") -> 0 | N49: =IF(N17="X",(D17-C17),"0") -> 0 | O49: =IF(O17="X",(D17-C17),"0") -> 0 | P49: =IF(P17="X",(D17-C17),"0") -> 0 | Q49: =IF(Q17="X",(D17-C17),"0") -> 0 | R49: =IF(R17="X",(D17-C17),"0") -> 0 | S49: =IF(S17="X",(D17-C17),"0") -> 0 | T49: =IF(T17="X",(D17-C17),"0") -> 0
E50: =IF(E18="X",(D18-C18),"0") -> 0 | F50: =IF(F18="X",(D18-C18),"0") -> 0 | G50: =IF(G18="X",(D18-C18),"0") -> 0 | H50: =IF(H18="X",(D18-C18),"0") -> 0 | I50: =IF(I18="X",(D18-C18),"0") -> 0 | J50: =IF(J18="X",(D18-C18),"0") -> 0 | K50: =IF(K18="X",(D18-C18),"0") -> 0 | L50: =IF(L18="X",(D18-C18),"0") -> 0 | M50: =IF(M18="X",(D18-C18),"0") -> 0 | N50: =IF(N18="X",(D18-C18),"0") -> 0 | O50: =IF(O18="X",(D18-C18),"0") -> 0 | P50: =IF(P18="X",(D18-C18),"0") -> 0 | Q50: =IF(Q18="X",(D18-C18),"0") -> 0 | R50: =IF(R18="X",(D18-C18),"0") -> 0 | S50: =IF(S18="X",(D18-C18),"0") -> 0 | T50: =IF(T18="X",(D18-C18),"0") -> 0
... E126: =IF(E94="X",(D94-C94),"0") -> 0 | F126: =IF(F94="X",(D94-C94),"0") -> 0 | G126: =IF(G94="X",(D94-C94),"0") -> 0 | H126: =IF(H94="X",(D94-C94),"0") -> 0 | I126: =IF(I94="X",(D94-C94),"0") -> 0 | J126: =IF(J94="X",(D94-C94),"0") -> 0 | K126: =IF(K94="X",(D94-C94),"0") -> 0 | L126: =IF(L94="X",(D94-C94),"0") -> 0 | M126: =IF(M94="X",(D94-C94),"0") -> 0 | N126: =IF(N94="X",(D94-C94),"0") -> 0 | O126: =IF(O94="X",(D94-C94),"0") -> 0 | P126: =IF(P94="X",(D94-C94),"0") -> 0 | Q126: =IF(Q94="X",(D94-C94),"0") -> 0 | R126: =IF(R94="X",(D94-C94),"0") -> 0 | S126: =IF(S94="X",(D94-C94),"0") -> 0 | T126: =IF(T94="X",(D94-C94),"0") -> 0
E127: =SUM(E39:E126) -> 0 | F127: =SUM(F39:F126) -> 0 | G127: =SUM(G39:G126) -> 14.87 | H127: =SUM(H39:H126) -> 0 | I127: =SUM(I39:I126) -> 0 | J127: =SUM(J39:J126) -> 14.87 | K127: =SUM(K39:K126) -> 0 | L127: =SUM(L39:L126) -> 0 | ... T127: =SUM(T39:T126) -> 0

Sheet 247
A1: PROGRAMA DE MANUTENÇÃORODOVIÁRIA
D2: RODOVIAS PAVIMENTADAS | I2: DATA: | J2: ='246'!J2 -> 46204 | N2: TÉCNICO RESP. | O2: ='246'!O2 -> ENG. THIAGO TORQUATO
A3: FICHA DE INSPEÇÃO: | B3: ='T.T.'!C5 -> RODOVIA TO-040 - TRECHO DIANÓPOLIS - NOVO JARDIM | O3: REGIÃO: | P3: 13
A5: S.R.E. | B5: SENTIDO | C5: INÍCIO (KM) | D5: FIM (KM) | E5: CONDIÇÃO DO PAVIMENTO | J5: VEGETAÇÃO | L5: ELEM. DE DRENAGEM | O5: SIN. HOR. | R5: SIN. VERTICAL | U5: OBSERV.
E6: BOM | F6: REM. I. | G6: REM. L | H6: BUR. I | I6: BUR. L | J6: ADEQ. | K6: INADED. | L6: LIMPOS | M6: SUJOS | N6: DAN. | O6: BOM | P6: REG. | Q6: INEXIST. | R6: BOM | S6: POUCAS | T6: INEXIST.
A7: 040ETO0210 | B7: D | C7: 0 | D7: 0.1 | G7: X | J7: X | M7: X | P7: X | S7: X
C8: =D7 -> 0.1 | D8: 0.2 | F8: X | J8: X | M8: X | P8: X | S8: X
C9: =D8 -> 0.2 | D9: 0.3 | F9: X | J9: X | M9: X | P9: X | S9: X
C10: =D9 -> 0.3 | D10: 18.27 | G10: X | J10: X | M10: X | P10: X | S10: X
A11: 040ETO0200 | B11: D | C11: 0 | D11: 0.1 | F11: X | J11: X | N11: X | P11: X | S11: X
C12: 0.1 | D12: 11.48 | F12: X | J12: X | M12: X | P12: X | S12: X
A13: 040ETO0190 | B13: D | C13: 0 | D13: 5 | F13: X | J13: X | M13: X | P13: X | S13: X
C14: 5 | D14: 6.29 | G14: X | J14: X | M14: X | P14: X | S14: X
A35: LEGENDA | B35: CONDIÇÃO DO PAVIMENTO
A36: REM. I | B36: REMENDOS ISOLADOS | E36: ATÉ 10 REMENDOS/KM | I36: BUR. I | J36: BURACOS ISOLADOS | M36: ATÉ 5 BURACOS/KM
A37: REM. L | B37: REMENDOS AO LONGO | E37: MAIS DE 10 REMENDOS/KM | I37: BUR. L | J37: BURACOS AO LONGO | M37: MAIS DE 5 BURACOS/KM
E42: =IF(E7="X",(D7-C7),"0") -> 0 | F42: =IF(F7="X",(D7-C7),"0") -> 0 | G42: =IF(G7="X",(D7-C7),"0") -> 0.1 | H42: =IF(H7="X",(D7-C7),"0") -> 0 | I42: =IF(I7="X",(D7-C7),"0") -> 0 | J42: =IF(J7="X",(D7-C7),"0") -> 0.1 | K42: =IF(K7="X",(D7-C7),"0") -> 0 | L42: =IF(L7="X",(D7-C7),"0") -> 0 | M42: =IF(M7="X",(D7-C7),"0") -> 0.1 | N42: =IF(N7="X",(D7-C7),"0") -> 0 | O42: =IF(O7="X",(D7-C7),"0") -> 0 | P42: =IF(P7="X",(D7-C7),"0") -> 0.1 | Q42: =IF(Q7="X",(D7-C7),"0") -> 0 | R42: =IF(R7="X",(D7-C7),"0") -> 0 | S42: =IF(S7="X",(D7-C7),"0") -> 0.1 | T42: =IF(T7="X",(D7-C7),"0") -> 0
E43: =IF(E8="X",(D8-C8),"0") -> 0 | F43: =IF(F8="X",(D8-C8),"0") -> 0.1 | G43: =IF(G8="X",(D8-C8),"0") -> 0 | H43: =IF(H8="X",(D8-C8),"0") -> 0 | I43: =IF(I8="X",(D8-C8),"0") -> 0 | J43: =IF(J8="X",(D8-C8),"0") -> 0.1 | K43: =IF(K8="X",(D8-C8),"0") -> 0 | L43: =IF(L8="X",(D8-C8),"0") -> 0 | M43: =IF(M8="X",(D8-C8),"0") -> 0.1 | N43: =IF(N8="X",(D8-C8),"0") -> 0 | O43: =IF(O8="X",(D8-C8),"0") -> 0 | P43: =IF(P8="X",(D8-C8),"0") -> 0.1 | Q43: =IF(Q8="X",(D8-C8),"0") -> 0 | R43: =IF(R8="X",(D8-C8),"0") -> 0 | S43: =IF(S8="X",(D8-C8),"0") -> 0.1 | T43: =IF(T8="X",(D8-C8),"0") -> 0
E44: =IF(E9="X",(D9-C9),"0") -> 0 | F44: =IF(F9="X",(D9-C9),"0") -> 0.1 | G44: =IF(G9="X",(D9-C9),"0") -> 0 | H44: =IF(H9="X",(D9-C9),"0") -> 0 | I44: =IF(I9="X",(D9-C9),"0") -> 0 | J44: =IF(J9="X",(D9-C9),"0") -> 0.1 | K44: =IF(K9="X",(D9-C9),"0") -> 0 | L44: =IF(L9="X",(D9-C9),"0") -> 0 | M44: =IF(M9="X",(D9-C9),"0") -> 0.1 | N44: =IF(N9="X",(D9-C9),"0") -> 0 | O44: =IF(O9="X",(D9-C9),"0") -> 0 | P44: =IF(P9="X",(D9-C9),"0") -> 0.1 | Q44: =IF(Q9="X",(D9-C9),"0") -> 0 | R44: =IF(R9="X",(D9-C9),"0") -> 0 | S44: =IF(S9="X",(D9-C9),"0") -> 0.1 | T44: =IF(T9="X",(D9-C9),"0") -> 0
E45: =IF(E10="X",(D10-C10),"0") -> 0 | F45: =IF(F10="X",(D10-C10),"0") -> 0 | G45: =IF(G10="X",(D10-C10),"0") -> 17.97 | H45: =IF(H10="X",(D10-C10),"0") -> 0 | I45: =IF(I10="X",(D10-C10),"0") -> 0 | J45: =IF(J10="X",(D10-C10),"0") -> 17.97 | K45: =IF(K10="X",(D10-C10),"0") -> 0 | L45: =IF(L10="X",(D10-C10),"0") -> 0 | M45: =IF(M10="X",(D10-C10),"0") -> 17.97 | N45: =IF(N10="X",(D10-C10),"0") -> 0 | O45: =IF(O10="X",(D10-C10),"0") -> 0 | P45: =IF(P10="X",(D10-C10),"0") -> 17.97 | Q45: =IF(Q10="X",(D10-C10),"0") -> 0 | R45: =IF(R10="X",(D10-C10),"0") -> 0 | S45: =IF(S10="X",(D10-C10),"0") -> 17.97 | T45: =IF(T10="X",(D10-C10),"0") -> 0
E46: =IF(E11="X",(D11-C11),"0") -> 0 | F46: =IF(F11="X",(D11-C11),"0") -> 0.1 | G46: =IF(G11="X",(D11-C11),"0") -> 0 | H46: =IF(H11="X",(D11-C11),"0") -> 0 | I46: =IF(I11="X",(D11-C11),"0") -> 0 | J46: =IF(J11="X",(D11-C11),"0") -> 0.1 | K46: =IF(K11="X",(D11-C11),"0") -> 0 | L46: =IF(L11="X",(D11-C11),"0") -> 0 | M46: =IF(M11="X",(D11-C11),"0") -> 0 | N46: =IF(N11="X",(D11-C11),"0") -> 0.1 | O46: =IF(O11="X",(D11-C11),"0") -> 0 | P46: =IF(P11="X",(D11-C11),"0") -> 0.1 | Q46: =IF(Q11="X",(D11-C11),"0") -> 0 | R46: =IF(R11="X",(D11-C11),"0") -> 0 | S46: =IF(S11="X",(D11-C11),"0") -> 0.1 | T46: =IF(T11="X",(D11-C11),"0") -> 0
E47: =IF(E12="X",(D12-C12),"0") -> 0 | F47: =IF(F12="X",(D12-C12),"0") -> 11.38 | G47: =IF(G12="X",(D12-C12),"0") -> 0 | H47: =IF(H12="X",(D12-C12),"0") -> 0 | I47: =IF(I12="X",(D12-C12),"0") -> 0 | J47: =IF(J12="X",(D12-C12),"0") -> 11.38 | K47: =IF(K12="X",(D12-C12),"0") -> 0 | L47: =IF(L12="X",(D12-C12),"0") -> 0 | M47: =IF(M12="X",(D12-C12),"0") -> 11.38 | N47: =IF(N12="X",(D12-C12),"0") -> 0 | O47: =IF(O12="X",(D12-C12),"0") -> 0 | P47: =IF(P12="X",(D12-C12),"0") -> 11.38 | Q47: =IF(Q12="X",(D12-C12),"0") -> 0 | R47: =IF(R12="X",(D12-C12),"0") -> 0 | S47: =IF(S12="X",(D12-C12),"0") -> 11.38 | T47: =IF(T12="X",(D12-C12),"0") -> 0
E48: =IF(E13="X",(D13-C13),"0") -> 0 | F48: =IF(F13="X",(D13-C13),"0") -> 5 | G48: =IF(G13="X",(D13-C13),"0") -> 0 | H48: =IF(H13="X",(D13-C13),"0") -> 0 | I48: =IF(I13="X",(D13-C13),"0") -> 0 | J48: =IF(J13="X",(D13-C13),"0") -> 5 | K48: =IF(K13="X",(D13-C13),"0") -> 0 | L48: =IF(L13="X",(D13-C13),"0") -> 0 | M48: =IF(M13="X",(D13-C13),"0") -> 5 | N48: =IF(N13="X",(D13-C13),"0") -> 0 | O48: =IF(O13="X",(D13-C13),"0") -> 0 | P48: =IF(P13="X",(D13-C13),"0") -> 5 | Q48: =IF(Q13="X",(D13-C13),"0") -> 0 | R48: =IF(R13="X",(D13-C13),"0") -> 0 | S48: =IF(S13="X",(D13-C13),"0") -> 5 | T48: =IF(T13="X",(D13-C13),"0") -> 0
E49: =IF(E14="X",(D14-C14),"0") -> 0 | F49: =IF(F14="X",(D14-C14),"0") -> 0 | G49: =IF(G14="X",(D14-C14),"0") -> 1.29 | H49: =IF(H14="X",(D14-C14),"0") -> 0 | I49: =IF(I14="X",(D14-C14),"0") -> 0 | J49: =IF(J14="X",(D14-C14),"0") -> 1.29 | K49: =IF(K14="X",(D14-C14),"0") -> 0 | L49: =IF(L14="X",(D14-C14),"0") -> 0 | M49: =IF(M14="X",(D14-C14),"0") -> 1.29 | N49: =IF(N14="X",(D14-C14),"0") -> 0 | O49: =IF(O14="X",(D14-C14),"0") -> 0 | P49: =IF(P14="X",(D14-C14),"0") -> 1.29 | Q49: =IF(Q14="X",(D14-C14),"0") -> 0 | R49: =IF(R14="X",(D14-C14),"0") -> 0 | S49: =IF(S14="X",(D14-C14),"0") -> 1.29 | T49: =IF(T14="X",(D14-C14),"0") -> 0
E50: =IF(E15="X",(D15-C15),"0") -> 0 | F50: =IF(F15="X",(D15-C15),"0") -> 0 | G50: =IF(G15="X",(D15-C15),"0") -> 0 | H50: =IF(H15="X",(D15-C15),"0") -> 0 | I50: =IF(I15="X",(D15-C15),"0") -> 0 | J50: =IF(J15="X",(D15-C15),"0") -> 0 | K50: =IF(K15="X",(D15-C15),"0") -> 0 | L50: =IF(L15="X",(D15-C15),"0") -> 0 | M50: =IF(M15="X",(D15-C15),"0") -> 0 | N50: =IF(N15="X",(D15-C15),"0") -> 0 | O50: =IF(O15="X",(D15-C15),"0") -> 0 | P50: =IF(P15="X",(D15-C15),"0") -> 0 | Q50: =IF(Q15="X",(D15-C15),"0") -> 0 | R50: =IF(R15="X",(D15-C15),"0") -> 0 | S50: =IF(S15="X",(D15-C15),"0") -> 0 | T50: =IF(T15="X",(D15-C15),"0") -> 0
E51: =IF(E16="X",(D16-C16),"0") -> 0 | F51: =IF(F16="X",(D16-C16),"0") -> 0 | G51: =IF(G16="X",(D16-C16),"0") -> 0 | H51: =IF(H16="X",(D16-C16),"0") -> 0 | I51: =IF(I16="X",(D16-C16),"0") -> 0 | J51: =IF(J16="X",(D16-C16),"0") -> 0 | K51: =IF(K16="X",(D16-C16),"0") -> 0 | L51: =IF(L16="X",(D16-C16),"0") -> 0 | M51: =IF(M16="X",(D16-C16),"0") -> 0 | N51: =IF(N16="X",(D16-C16),"0") -> 0 | O51: =IF(O16="X",(D16-C16),"0") -> 0 | P51: =IF(P16="X",(D16-C16),"0") -> 0 | Q51: =IF(Q16="X",(D16-C16),"0") -> 0 | R51: =IF(R16="X",(D16-C16),"0") -> 0 | S51: =IF(S16="X",(D16-C16),"0") -> 0 | T51: =IF(T16="X",(D16-C16),"0") -> 0
E52: =IF(E17="X",(D17-C17),"0") -> 0 | F52: =IF(F17="X",(D17-C17),"0") -> 0 | G52: =IF(G17="X",(D17-C17),"0") -> 0 | H52: =IF(H17="X",(D17-C17),"0") -> 0 | I52: =IF(I17="X",(D17-C17),"0") -> 0 | J52: =IF(J17="X",(D17-C17),"0") -> 0 | K52: =IF(K17="X",(D17-C17),"0") -> 0 | L52: =IF(L17="X",(D17-C17),"0") -> 0 | M52: =IF(M17="X",(D17-C17),"0") -> 0 | N52: =IF(N17="X",(D17-C17),"0") -> 0 | O52: =IF(O17="X",(D17-C17),"0") -> 0 | P52: =IF(P17="X",(D17-C17),"0") -> 0 | Q52: =IF(Q17="X",(D17-C17),"0") -> 0 | R52: =IF(R17="X",(D17-C17),"0") -> 0 | S52: =IF(S17="X",(D17-C17),"0") -> 0 | T52: =IF(T17="X",(D17-C17),"0") -> 0
E53: =IF(E18="X",(D18-C18),"0") -> 0 | F53: =IF(F18="X",(D18-C18),"0") -> 0 | G53: =IF(G18="X",(D18-C18),"0") -> 0 | H53: =IF(H18="X",(D18-C18),"0") -> 0 | I53: =IF(I18="X",(D18-C18),"0") -> 0 | J53: =IF(J18="X",(D18-C18),"0") -> 0 | K53: =IF(K18="X",(D18-C18),"0") -> 0 | L53: =IF(L18="X",(D18-C18),"0") -> 0 | M53: =IF(M18="X",(D18-C18),"0") -> 0 | N53: =IF(N18="X",(D18-C18),"0") -> 0 | O53: =IF(O18="X",(D18-C18),"0") -> 0 | P53: =IF(P18="X",(D18-C18),"0") -> 0 | Q53: =IF(Q18="X",(D18-C18),"0") -> 0 | R53: =IF(R18="X",(D18-C18),"0") -> 0 | S53: =IF(S18="X",(D18-C18),"0") -> 0 | T53: =IF(T18="X",(D18-C18),"0") -> 0
... E129: =IF(E94="X",(D94-C94),"0") -> 0 | F129: =IF(F94="X",(D94-C94),"0") -> 0 | G129: =IF(G94="X",(D94-C94),"0") -> 0 | H129: =IF(H94="X",(D94-C94),"0") -> 0 | I129: =IF(I94="X",(D94-C94),"0") -> 0 | J129: =IF(J94="X",(D94-C94),"0") -> 0 | K129: =IF(K94="X",(D94-C94),"0") -> 0 | L129: =IF(L94="X",(D94-C94),"0") -> 0 | M129: =IF(M94="X",(D94-C94),"0") -> 0 | N129: =IF(N94="X",(D94-C94),"0") -> 0 | O129: =IF(O94="X",(D94-C94),"0") -> 0 | P129: =IF(P94="X",(D94-C94),"0") -> 0 | Q129: =IF(Q94="X",(D94-C94),"0") -> 0 | R129: =IF(R94="X",(D94-C94),"0") -> 0 | S129: =IF(S94="X",(D94-C94),"0") -> 0 | T129: =IF(T94="X",(D94-C94),"0") -> 0
E130: =SUM(E42:E129) -> 0 | F130: =SUM(F42:F129) -> 16.68 | G130: =SUM(G42:G129) -> 19.36 | H130: =SUM(H42:H129) -> 0 | I130: =SUM(I42:I129) -> 0 | J130: =SUM(J42:J129) -> 36.04 | K130: =SUM(K42:K129) -> 0 | L130: =SUM(L42:L129) -> 0 | ... T130: =SUM(T42:T129) -> 0

Sheet 248
A1: PROGRAMA DE MANUTENÇÃORODOVIÁRIA
D2: RODOVIAS PAVIMENTADAS | I2: DATA: | J2: ='247'!J2 -> 46204 | N2: TÉCNICO RESP. | O2: ='247'!O2 -> ENG. THIAGO TORQUATO
A3: FICHA DE INSPEÇÃO: | B3: ='T.T.'!C6 -> RODOVIA TO-040 - TRECHO NOVO JARDIM - DIVISA TO-BA | O3: REGIÃO: | P3: 13
A5: S.R.E. | B5: SENTIDO | C5: INÍCIO (KM) | D5: FIM (KM) | E5: CONDIÇÃO DO PAVIMENTO | J5: VEGETAÇÃO | L5: ELEM. DE DRENAGEM | O5: SIN. HOR. | R5: SIN. VERTICAL | U5: OBSERV.
E6: BOM | F6: REM. I. | G6: REM. L | H6: BUR. I | I6: BUR. L | J6: ADEQ. | K6: INADED. | L6: LIMPOS | M6: SUJOS | N6: DAN. | O6: BOM | P6: REG. | Q6: INEXIST. | R6: BOM | S6: POUCAS | T6: INEXIST.
A7: 040ETO0230 | B7: C | C7: 0 | D7: 3 | E7: X | J7: X | M7: X | P7: X | S7: X | U7: 37,19 km
C8: 3 | D8: 4 | E8: X | J8: X | M8: X | P8: X | S8: X
C9: 4 | D9: 6 | E9: X | J9: X | M9: X | P9: X | S9: X
C10: 6 | D10: 7 | E10: X | J10: X | M10: X | P10: X | S10: X
C11: 7 | D11: 8 | G11: X | J11: X | M11: X | P11: X | S11: X
C12: 8 | D12: 11 | E12: X | J12: X | M12: X | P12: X | S12: X
C13: 11 | D13: 12 | G13: X | J13: X | M13: X | P13: X | S13: X
C14: 12 | D14: 18.5 | E14: X | J14: X | M14: X | P14: X | S14: X
C15: 18.5 | D15: 25.8 | G15: X | J15: X | M15: X | P15: X | S15: X
C16: 25.8 | D16: 37.19 | E16: X | J16: X | M16: X | P16: X | S16: X
A17: 040ETO0220 | B17: D | C17: 0 | D17: 5.81 | F17: X | J17: X | M17: X | P17: X | S17: X
A32: LEGENDA | B32: CONDIÇÃO DO PAVIMENTO
A33: REM. I | B33: REMENDOS ISOLADOS | E33: ATÉ 10 REMENDOS/KM | I33: BUR. I | J33: BURACOS ISOLADOS | M33: ATÉ 5 BURACOS/KM
A34: REM. L | B34: REMENDOS AO LONGO | E34: MAIS DE 10 REMENDOS/KM | I34: BUR. L | J34: BURACOS AO LONGO | M34: MAIS DE 5 BURACOS/KM
E39: =IF(E7="X",(D7-C7),"0") -> 3 | F39: =IF(F7="X",(D7-C7),"0") -> 0 | G39: =IF(G7="X",(D7-C7),"0") -> 0 | H39: =IF(H7="X",(D7-C7),"0") -> 0 | I39: =IF(I7="X",(D7-C7),"0") -> 0 | J39: =IF(J7="X",(D7-C7),"0") -> 3 | K39: =IF(K7="X",(D7-C7),"0") -> 0 | L39: =IF(L7="X",(D7-C7),"0") -> 0 | M39: =IF(M7="X",(D7-C7),"0") -> 3 | N39: =IF(N7="X",(D7-C7),"0") -> 0 | O39: =IF(O7="X",(D7-C7),"0") -> 0 | P39: =IF(P7="X",(D7-C7),"0") -> 3 | Q39: =IF(Q7="X",(D7-C7),"0") -> 0 | R39: =IF(R7="X",(D7-C7),"0") -> 0 | S39: =IF(S7="X",(D7-C7),"0") -> 3 | T39: =IF(T7="X",(D7-C7),"0") -> 0
E40: =IF(E8="X",(D8-C8),"0") -> 1 | F40: =IF(F8="X",(D8-C8),"0") -> 0 | G40: =IF(G8="X",(D8-C8),"0") -> 0 | H40: =IF(H8="X",(D8-C8),"0") -> 0 | I40: =IF(I8="X",(D8-C8),"0") -> 0 | J40: =IF(J8="X",(D8-C8),"0") -> 1 | K40: =IF(K8="X",(D8-C8),"0") -> 0 | L40: =IF(L8="X",(D8-C8),"0") -> 0 | M40: =IF(M8="X",(D8-C8),"0") -> 1 | N40: =IF(N8="X",(D8-C8),"0") -> 0 | O40: =IF(O8="X",(D8-C8),"0") -> 0 | P40: =IF(P8="X",(D8-C8),"0") -> 1 | Q40: =IF(Q8="X",(D8-C8),"0") -> 0 | R40: =IF(R8="X",(D8-C8),"0") -> 0 | S40: =IF(S8="X",(D8-C8),"0") -> 1 | T40: =IF(T8="X",(D8-C8),"0") -> 0
E41: =IF(E9="X",(D9-C9),"0") -> 2 | F41: =IF(F9="X",(D9-C9),"0") -> 0 | G41: =IF(G9="X",(D9-C9),"0") -> 0 | H41: =IF(H9="X",(D9-C9),"0") -> 0 | I41: =IF(I9="X",(D9-C9),"0") -> 0 | J41: =IF(J9="X",(D9-C9),"0") -> 2 | K41: =IF(K9="X",(D9-C9),"0") -> 0 | L41: =IF(L9="X",(D9-C9),"0") -> 0 | M41: =IF(M9="X",(D9-C9),"0") -> 2 | N41: =IF(N9="X",(D9-C9),"0") -> 0 | O41: =IF(O9="X",(D9-C9),"0") -> 0 | P41: =IF(P9="X",(D9-C9),"0") -> 2 | Q41: =IF(Q9="X",(D9-C9),"0") -> 0 | R41: =IF(R9="X",(D9-C9),"0") -> 0 | S41: =IF(S9="X",(D9-C9),"0") -> 2 | T41: =IF(T9="X",(D9-C9),"0") -> 0
E42: =IF(E10="X",(D10-C10),"0") -> 1 | F42: =IF(F10="X",(D10-C10),"0") -> 0 | G42: =IF(G10="X",(D10-C10),"0") -> 0 | H42: =IF(H10="X",(D10-C10),"0") -> 0 | I42: =IF(I10="X",(D10-C10),"0") -> 0 | J42: =IF(J10="X",(D10-C10),"0") -> 1 | K42: =IF(K10="X",(D10-C10),"0") -> 0 | L42: =IF(L10="X",(D10-C10),"0") -> 0 | M42: =IF(M10="X",(D10-C10),"0") -> 1 | N42: =IF(N10="X",(D10-C10),"0") -> 0 | O42: =IF(O10="X",(D10-C10),"0") -> 0 | P42: =IF(P10="X",(D10-C10),"0") -> 1 | Q42: =IF(Q10="X",(D10-C10),"0") -> 0 | R42: =IF(R10="X",(D10-C10),"0") -> 0 | S42: =IF(S10="X",(D10-C10),"0") -> 1 | T42: =IF(T10="X",(D10-C10),"0") -> 0
E43: =IF(E11="X",(D11-C11),"0") -> 0 | F43: =IF(F11="X",(D11-C11),"0") -> 0 | G43: =IF(G11="X",(D11-C11),"0") -> 1 | H43: =IF(H11="X",(D11-C11),"0") -> 0 | I43: =IF(I11="X",(D11-C11),"0") -> 0 | J43: =IF(J11="X",(D11-C11),"0") -> 1 | K43: =IF(K11="X",(D11-C11),"0") -> 0 | L43: =IF(L11="X",(D11-C11),"0") -> 0 | M43: =IF(M11="X",(D11-C11),"0") -> 1 | N43: =IF(N11="X",(D11-C11),"0") -> 0 | O43: =IF(O11="X",(D11-C11),"0") -> 0 | P43: =IF(P11="X",(D11-C11),"0") -> 1 | Q43: =IF(Q11="X",(D11-C11),"0") -> 0 | R43: =IF(R11="X",(D11-C11),"0") -> 0 | S43: =IF(S11="X",(D11-C11),"0") -> 1 | T43: =IF(T11="X",(D11-C11),"0") -> 0
E44: =IF(E12="X",(D12-C12),"0") -> 3 | F44: =IF(F12="X",(D12-C12),"0") -> 0 | G44: =IF(G12="X",(D12-C12),"0") -> 0 | H44: =IF(H12="X",(D12-C12),"0") -> 0 | I44: =IF(I12="X",(D12-C12),"0") -> 0 | J44: =IF(J12="X",(D12-C12),"0") -> 3 | K44: =IF(K12="X",(D12-C12),"0") -> 0 | L44: =IF(L12="X",(D12-C12),"0") -> 0 | M44: =IF(M12="X",(D12-C12),"0") -> 3 | N44: =IF(N12="X",(D12-C12),"0") -> 0 | O44: =IF(O12="X",(D12-C12),"0") -> 0 | P44: =IF(P12="X",(D12-C12),"0") -> 3 | Q44: =IF(Q12="X",(D12-C12),"0") -> 0 | R44: =IF(R12="X",(D12-C12),"0") -> 0 | S44: =IF(S12="X",(D12-C12),"0") -> 3 | T44: =IF(T12="X",(D12-C12),"0") -> 0
E45: =IF(E13="X",(D13-C13),"0") -> 0 | F45: =IF(F13="X",(D13-C13),"0") -> 0 | G45: =IF(G13="X",(D13-C13),"0") -> 1 | H45: =IF(H13="X",(D13-C13),"0") -> 0 | I45: =IF(I13="X",(D13-C13),"0") -> 0 | J45: =IF(J13="X",(D13-C13),"0") -> 1 | K45: =IF(K13="X",(D13-C13),"0") -> 0 | L45: =IF(L13="X",(D13-C13),"0") -> 0 | M45: =IF(M13="X",(D13-C13),"0") -> 1 | N45: =IF(N13="X",(D13-C13),"0") -> 0 | O45: =IF(O13="X",(D13-C13),"0") -> 0 | P45: =IF(P13="X",(D13-C13),"0") -> 1 | Q45: =IF(Q13="X",(D13-C13),"0") -> 0 | R45: =IF(R13="X",(D13-C13),"0") -> 0 | S45: =IF(S13="X",(D13-C13),"0") -> 1 | T45: =IF(T13="X",(D13-C13),"0") -> 0
E46: =IF(E14="X",(D14-C14),"0") -> 6.5 | F46: =IF(F14="X",(D14-C14),"0") -> 0 | G46: =IF(G14="X",(D14-C14),"0") -> 0 | H46: =IF(H14="X",(D14-C14),"0") -> 0 | I46: =IF(I14="X",(D14-C14),"0") -> 0 | J46: =IF(J14="X",(D14-C14),"0") -> 6.5 | K46: =IF(K14="X",(D14-C14),"0") -> 0 | L46: =IF(L14="X",(D14-C14),"0") -> 0 | M46: =IF(M14="X",(D14-C14),"0") -> 6.5 | N46: =IF(N14="X",(D14-C14),"0") -> 0 | O46: =IF(O14="X",(D14-C14),"0") -> 0 | P46: =IF(P14="X",(D14-C14),"0") -> 6.5 | Q46: =IF(Q14="X",(D14-C14),"0") -> 0 | R46: =IF(R14="X",(D14-C14),"0") -> 0 | S46: =IF(S14="X",(D14-C14),"0") -> 6.5 | T46: =IF(T14="X",(D14-C14),"0") -> 0
E47: =IF(E15="X",(D15-C15),"0") -> 0 | F47: =IF(F15="X",(D15-C15),"0") -> 0 | G47: =IF(G15="X",(D15-C15),"0") -> 7.3 | H47: =IF(H15="X",(D15-C15),"0") -> 0 | I47: =IF(I15="X",(D15-C15),"0") -> 0 | J47: =IF(J15="X",(D15-C15),"0") -> 7.3 | K47: =IF(K15="X",(D15-C15),"0") -> 0 | L47: =IF(L15="X",(D15-C15),"0") -> 0 | M47: =IF(M15="X",(D15-C15),"0") -> 7.3 | N47: =IF(N15="X",(D15-C15),"0") -> 0 | O47: =IF(O15="X",(D15-C15),"0") -> 0 | P47: =IF(P15="X",(D15-C15),"0") -> 7.3 | Q47: =IF(Q15="X",(D15-C15),"0") -> 0 | R47: =IF(R15="X",(D15-C15),"0") -> 0 | S47: =IF(S15="X",(D15-C15),"0") -> 7.3 | T47: =IF(T15="X",(D15-C15),"0") -> 0
E48: =IF(E16="X",(D16-C16),"0") -> 11.39 | F48: =IF(F16="X",(D16-C16),"0") -> 0 | G48: =IF(G16="X",(D16-C16),"0") -> 0 | H48: =IF(H16="X",(D16-C16),"0") -> 0 | I48: =IF(I16="X",(D16-C16),"0") -> 0 | J48: =IF(J16="X",(D16-C16),"0") -> 11.39 | K48: =IF(K16="X",(D16-C16),"0") -> 0 | L48: =IF(L16="X",(D16-C16),"0") -> 0 | M48: =IF(M16="X",(D16-C16),"0") -> 11.39 | N48: =IF(N16="X",(D16-C16),"0") -> 0 | O48: =IF(O16="X",(D16-C16),"0") -> 0 | P48: =IF(P16="X",(D16-C16),"0") -> 11.39 | Q48: =IF(Q16="X",(D16-C16),"0") -> 0 | R48: =IF(R16="X",(D16-C16),"0") -> 0 | S48: =IF(S16="X",(D16-C16),"0") -> 11.39 | T48: =IF(T16="X",(D16-C16),"0") -> 0
E49: =IF(E17="X",(D17-C17),"0") -> 0 | F49: =IF(F17="X",(D17-C17),"0") -> 5.81 | G49: =IF(G17="X",(D17-C17),"0") -> 0 | H49: =IF(H17="X",(D17-C17),"0") -> 0 | I49: =IF(I17="X",(D17-C17),"0") -> 0 | J49: =IF(J17="X",(D17-C17),"0") -> 5.81 | K49: =IF(K17="X",(D17-C17),"0") -> 0 | L49: =IF(L17="X",(D17-C17),"0") -> 0 | M49: =IF(M17="X",(D17-C17),"0") -> 5.81 | N49: =IF(N17="X",(D17-C17),"0") -> 0 | O49: =IF(O17="X",(D17-C17),"0") -> 0 | P49: =IF(P17="X",(D17-C17),"0") -> 5.81 | Q49: =IF(Q17="X",(D17-C17),"0") -> 0 | R49: =IF(R17="X",(D17-C17),"0") -> 0 | S49: =IF(S17="X",(D17-C17),"0") -> 5.81 | T49: =IF(T17="X",(D17-C17),"0") -> 0
E50: =IF(E18="X",(D18-C18),"0") -> 0 | F50: =IF(F18="X",(D18-C18),"0") -> 0 | G50: =IF(G18="X",(D18-C18),"0") -> 0 | H50: =IF(H18="X",(D18-C18),"0") -> 0 | I50: =IF(I18="X",(D18-C18),"0") -> 0 | J50: =IF(J18="X",(D18-C18),"0") -> 0 | K50: =IF(K18="X",(D18-C18),"0") -> 0 | L50: =IF(L18="X",(D18-C18),"0") -> 0 | M50: =IF(M18="X",(D18-C18),"0") -> 0 | N50: =IF(N18="X",(D18-C18),"0") -> 0 | O50: =IF(O18="X",(D18-C18),"0") -> 0 | P50: =IF(P18="X",(D18-C18),"0") -> 0 | Q50: =IF(Q18="X",(D18-C18),"0") -> 0 | R50: =IF(R18="X",(D18-C18),"0") -> 0 | S50: =IF(S18="X",(D18-C18),"0") -> 0 | T50: =IF(T18="X",(D18-C18),"0") -> 0
... E126: =IF(E94="X",(D94-C94),"0") -> 0 | F126: =IF(F94="X",(D94-C94),"0") -> 0 | G126: =IF(G94="X",(D94-C94),"0") -> 0 | H126: =IF(H94="X",(D94-C94),"0") -> 0 | I126: =IF(I94="X",(D94-C94),"0") -> 0 | J126: =IF(J94="X",(D94-C94),"0") -> 0 | K126: =IF(K94="X",(D94-C94),"0") -> 0 | L126: =IF(L94="X",(D94-C94),"0") -> 0 | M126: =IF(M94="X",(D94-C94),"0") -> 0 | N126: =IF(N94="X",(D94-C94),"0") -> 0 | O126: =IF(O94="X",(D94-C94),"0") -> 0 | P126: =IF(P94="X",(D94-C94),"0") -> 0 | Q126: =IF(Q94="X",(D94-C94),"0") -> 0 | R126: =IF(R94="X",(D94-C94),"0") -> 0 | S126: =IF(S94="X",(D94-C94),"0") -> 0 | T126: =IF(T94="X",(D94-C94),"0") -> 0
E127: =SUM(E39:E126) -> 27.89 | F127: =SUM(F39:F126) -> 5.81 | G127: =SUM(G39:G126) -> 9.3 | H127: =SUM(H39:H126) -> 0 | I127: =SUM(I39:I126) -> 0 | J127: =SUM(J39:J126) -> 43 | K127: =SUM(K39:K126) -> 0 | L127: =SUM(L39:L126) -> 0 | ... T127: =SUM(T39:T126) -> 0

Sheet 249
A1: PROGRAMA DE MANUTENÇÃORODOVIÁRIA
D2: RODOVIAS PAVIMENTADAS | I2: DATA: | J2: 46204 | N2: TÉCNICO RESP. | O2: ='247'!O2 -> ENG. THIAGO TORQUATO
A3: FICHA DE INSPEÇÃO: | B3: ='T.T.'!C7 -> RODOVIA TO-040 - TRECHO PORTO ALEGRE DO TOCANTINS - DIANÓPOLIS | O3: REGIÃO: | P3: 13
A5: S.R.E. | B5: SENTIDO | C5: INÍCIO (KM) | D5: FIM (KM) | E5: CONDIÇÃO DO PAVIMENTO | J5: VEGETAÇÃO | L5: ELEM. DE DRENAGEM | O5: SIN. HOR. | R5: SIN. VERTICAL | U5: OBSERV.
E6: BOM | F6: REM. I. | G6: REM. L | H6: BUR. I | I6: BUR. L | J6: ADEQ. | K6: INADED. | L6: LIMPOS | M6: SUJOS | N6: DAN. | O6: BOM | P6: REG. | Q6: INEXIST. | R6: BOM | S6: POUCAS | T6: INEXIST.
A7: 040ETO0170 | B7: D | C7: 0 | D7: 6 | G7: X | J7: X | L7: X | P7: X | S7: X
C8: =D7 -> 6 | D8: 12 | G8: X | J8: X | L8: X | P8: X | S8: X
C9: =D8 -> 12 | D9: 15.05 | G9: X | J9: X | L9: X | P9: X | S9: X
A10: 040ETO0180 | B10: D | C10: 0 | D10: 9 | G10: X | J10: X | L10: X | P10: X | S10: X
C11: 7 | D11: 11.21 | G11: X | J11: X | L11: X | P11: X | S11: X
A12: ACESSO | B12: C | C12: 0 | D12: 4.1 | E12: X | J12: X | L12: X | P12: X | S12: X
C13: =D12 -> 4.1 | D13: 7 | E13: X | J13: X | L13: X | P13: X | S13: X
C14: =D13 -> 7 | D14: 8.68 | E14: X | J14: X | L14: X | P14: X | S14: X
A37: LEGENDA | B37: CONDIÇÃO DO PAVIMENTO
A38: REM. I | B38: REMENDOS ISOLADOS | E38: ATÉ 10 REMENDOS/KM | I38: BUR. I | J38: BURACOS ISOLADOS | M38: ATÉ 5 BURACOS/KM
A39: REM. L | B39: REMENDOS AO LONGO | E39: MAIS DE 10 REMENDOS/KM | I39: BUR. L | J39: BURACOS AO LONGO | M39: MAIS DE 5 BURACOS/KM
E44: =IF(E7="X",(D7-C7),"0") -> 0 | F44: =IF(F7="X",(D7-C7),"0") -> 0 | G44: =IF(G7="X",(D7-C7),"0") -> 6 | H44: =IF(H7="X",(D7-C7),"0") -> 0 | I44: =IF(I7="X",(D7-C7),"0") -> 0 | J44: =IF(J7="X",(D7-C7),"0") -> 6 | K44: =IF(K7="X",(D7-C7),"0") -> 0 | L44: =IF(L7="X",(D7-C7),"0") -> 6 | M44: =IF(M7="X",(D7-C7),"0") -> 0 | N44: =IF(N7="X",(D7-C7),"0") -> 0 | O44: =IF(O7="X",(D7-C7),"0") -> 0 | P44: =IF(P7="X",(D7-C7),"0") -> 6 | Q44: =IF(Q7="X",(D7-C7),"0") -> 0 | R44: =IF(R7="X",(D7-C7),"0") -> 0 | S44: =IF(S7="X",(D7-C7),"0") -> 6 | T44: =IF(T7="X",(D7-C7),"0") -> 0
E45: =IF(E8="X",(D8-C8),"0") -> 0 | F45: =IF(F8="X",(D8-C8),"0") -> 0 | G45: =IF(G8="X",(D8-C8),"0") -> 6 | H45: =IF(H8="X",(D8-C8),"0") -> 0 | I45: =IF(I8="X",(D8-C8),"0") -> 0 | J45: =IF(J8="X",(D8-C8),"0") -> 6 | K45: =IF(K8="X",(D8-C8),"0") -> 0 | L45: =IF(L8="X",(D8-C8),"0") -> 6 | M45: =IF(M8="X",(D8-C8),"0") -> 0 | N45: =IF(N8="X",(D8-C8),"0") -> 0 | O45: =IF(O8="X",(D8-C8),"0") -> 0 | P45: =IF(P8="X",(D8-C8),"0") -> 6 | Q45: =IF(Q8="X",(D8-C8),"0") -> 0 | R45: =IF(R8="X",(D8-C8),"0") -> 0 | S45: =IF(S8="X",(D8-C8),"0") -> 6 | T45: =IF(T8="X",(D8-C8),"0") -> 0
E46: =IF(E9="X",(D9-C9),"0") -> 0 | F46: =IF(F9="X",(D9-C9),"0") -> 0 | G46: =IF(G9="X",(D9-C9),"0") -> 3.05 | H46: =IF(H9="X",(D9-C9),"0") -> 0 | I46: =IF(I9="X",(D9-C9),"0") -> 0 | J46: =IF(J9="X",(D9-C9),"0") -> 3.05 | K46: =IF(K9="X",(D9-C9),"0") -> 0 | L46: =IF(L9="X",(D9-C9),"0") -> 3.05 | M46: =IF(M9="X",(D9-C9),"0") -> 0 | N46: =IF(N9="X",(D9-C9),"0") -> 0 | O46: =IF(O9="X",(D9-C9),"0") -> 0 | P46: =IF(P9="X",(D9-C9),"0") -> 3.05 | Q46: =IF(Q9="X",(D9-C9),"0") -> 0 | R46: =IF(R9="X",(D9-C9),"0") -> 0 | S46: =IF(S9="X",(D9-C9),"0") -> 3.05 | T46: =IF(T9="X",(D9-C9),"0") -> 0
E47: =IF(E10="X",(D10-C10),"0") -> 0 | F47: =IF(F10="X",(D10-C10),"0") -> 0 | G47: =IF(G10="X",(D10-C10),"0") -> 9 | H47: =IF(H10="X",(D10-C10),"0") -> 0 | I47: =IF(I10="X",(D10-C10),"0") -> 0 | J47: =IF(J10="X",(D10-C10),"0") -> 9 | K47: =IF(K10="X",(D10-C10),"0") -> 0 | L47: =IF(L10="X",(D10-C10),"0") -> 9 | M47: =IF(M10="X",(D10-C10),"0") -> 0 | N47: =IF(N10="X",(D10-C10),"0") -> 0 | O47: =IF(O10="X",(D10-C10),"0") -> 0 | P47: =IF(P10="X",(D10-C10),"0") -> 9 | Q47: =IF(Q10="X",(D10-C10),"0") -> 0 | R47: =IF(R10="X",(D10-C10),"0") -> 0 | S47: =IF(S10="X",(D10-C10),"0") -> 9 | T47: =IF(T10="X",(D10-C10),"0") -> 0
E48: =IF(E11="X",(D11-C11),"0") -> 0 | F48: =IF(F11="X",(D11-C11),"0") -> 0 | G48: =IF(G11="X",(D11-C11),"0") -> 4.21 | H48: =IF(H11="X",(D11-C11),"0") -> 0 | I48: =IF(I11="X",(D11-C11),"0") -> 0 | J48: =IF(J11="X",(D11-C11),"0") -> 4.21 | K48: =IF(K11="X",(D11-C11),"0") -> 0 | L48: =IF(L11="X",(D11-C11),"0") -> 4.21 | M48: =IF(M11="X",(D11-C11),"0") -> 0 | N48: =IF(N11="X",(D11-C11),"0") -> 0 | O48: =IF(O11="X",(D11-C11),"0") -> 0 | P48: =IF(P11="X",(D11-C11),"0") -> 4.21 | Q48: =IF(Q11="X",(D11-C11),"0") -> 0 | R48: =IF(R11="X",(D11-C11),"0") -> 0 | S48: =IF(S11="X",(D11-C11),"0") -> 4.21 | T48: =IF(T11="X",(D11-C11),"0") -> 0
E49: =IF(E12="X",(D12-C12),"0") -> 4.1 | F49: =IF(F12="X",(D12-C12),"0") -> 0 | G49: =IF(G12="X",(D12-C12),"0") -> 0 | H49: =IF(H12="X",(D12-C12),"0") -> 0 | I49: =IF(I12="X",(D12-C12),"0") -> 0 | J49: =IF(J12="X",(D12-C12),"0") -> 4.1 | K49: =IF(K12="X",(D12-C12),"0") -> 0 | L49: =IF(L12="X",(D12-C12),"0") -> 4.1 | M49: =IF(M12="X",(D12-C12),"0") -> 0 | N49: =IF(N12="X",(D12-C12),"0") -> 0 | O49: =IF(O12="X",(D12-C12),"0") -> 0 | P49: =IF(P12="X",(D12-C12),"0") -> 4.1 | Q49: =IF(Q12="X",(D12-C12),"0") -> 0 | R49: =IF(R12="X",(D12-C12),"0") -> 0 | S49: =IF(S12="X",(D12-C12),"0") -> 4.1 | T49: =IF(T12="X",(D12-C12),"0") -> 0
E50: =IF(E13="X",(D13-C13),"0") -> 2.9 | F50: =IF(F13="X",(D13-C13),"0") -> 0 | G50: =IF(G13="X",(D13-C13),"0") -> 0 | H50: =IF(H13="X",(D13-C13),"0") -> 0 | I50: =IF(I13="X",(D13-C13),"0") -> 0 | J50: =IF(J13="X",(D13-C13),"0") -> 2.9 | K50: =IF(K13="X",(D13-C13),"0") -> 0 | L50: =IF(L13="X",(D13-C13),"0") -> 2.9 | M50: =IF(M13="X",(D13-C13),"0") -> 0 | N50: =IF(N13="X",(D13-C13),"0") -> 0 | O50: =IF(O13="X",(D13-C13),"0") -> 0 | P50: =IF(P13="X",(D13-C13),"0") -> 2.9 | Q50: =IF(Q13="X",(D13-C13),"0") -> 0 | R50: =IF(R13="X",(D13-C13),"0") -> 0 | S50: =IF(S13="X",(D13-C13),"0") -> 2.9 | T50: =IF(T13="X",(D13-C13),"0") -> 0
E51: =IF(E14="X",(D14-C14),"0") -> 1.68 | F51: =IF(F14="X",(D14-C14),"0") -> 0 | G51: =IF(G14="X",(D14-C14),"0") -> 0 | H51: =IF(H14="X",(D14-C14),"0") -> 0 | I51: =IF(I14="X",(D14-C14),"0") -> 0 | J51: =IF(J14="X",(D14-C14),"0") -> 1.68 | K51: =IF(K14="X",(D14-C14),"0") -> 0 | L51: =IF(L14="X",(D14-C14),"0") -> 1.68 | M51: =IF(M14="X",(D14-C14),"0") -> 0 | N51: =IF(N14="X",(D14-C14),"0") -> 0 | O51: =IF(O14="X",(D14-C14),"0") -> 0 | P51: =IF(P14="X",(D14-C14),"0") -> 1.68 | Q51: =IF(Q14="X",(D14-C14),"0") -> 0 | R51: =IF(R14="X",(D14-C14),"0") -> 0 | S51: =IF(S14="X",(D14-C14),"0") -> 1.68 | T51: =IF(T14="X",(D14-C14),"0") -> 0
E52: =IF(E15="X",(D15-C15),"0") -> 0 | F52: =IF(F15="X",(D15-C15),"0") -> 0 | G52: =IF(G15="X",(D15-C15),"0") -> 0 | H52: =IF(H15="X",(D15-C15),"0") -> 0 | I52: =IF(I15="X",(D15-C15),"0") -> 0 | J52: =IF(J15="X",(D15-C15),"0") -> 0 | K52: =IF(K15="X",(D15-C15),"0") -> 0 | L52: =IF(L15="X",(D15-C15),"0") -> 0 | M52: =IF(M15="X",(D15-C15),"0") -> 0 | N52: =IF(N15="X",(D15-C15),"0") -> 0 | O52: =IF(O15="X",(D15-C15),"0") -> 0 | P52: =IF(P15="X",(D15-C15),"0") -> 0 | Q52: =IF(Q15="X",(D15-C15),"0") -> 0 | R52: =IF(R15="X",(D15-C15),"0") -> 0 | S52: =IF(S15="X",(D15-C15),"0") -> 0 | T52: =IF(T15="X",(D15-C15),"0") -> 0
E53: =IF(E16="X",(D16-C16),"0") -> 0 | F53: =IF(F16="X",(D16-C16),"0") -> 0 | G53: =IF(G16="X",(D16-C16),"0") -> 0 | H53: =IF(H16="X",(D16-C16),"0") -> 0 | I53: =IF(I16="X",(D16-C16),"0") -> 0 | J53: =IF(J16="X",(D16-C16),"0") -> 0 | K53: =IF(K16="X",(D16-C16),"0") -> 0 | L53: =IF(L16="X",(D16-C16),"0") -> 0 | M53: =IF(M16="X",(D16-C16),"0") -> 0 | N53: =IF(N16="X",(D16-C16),"0") -> 0 | O53: =IF(O16="X",(D16-C16),"0") -> 0 | P53: =IF(P16="X",(D16-C16),"0") -> 0 | Q53: =IF(Q16="X",(D16-C16),"0") -> 0 | R53: =IF(R16="X",(D16-C16),"0") -> 0 | S53: =IF(S16="X",(D16-C16),"0") -> 0 | T53: =IF(T16="X",(D16-C16),"0") -> 0
E54: =IF(E17="X",(D17-C17),"0") -> 0 | F54: =IF(F17="X",(D17-C17),"0") -> 0 | G54: =IF(G17="X",(D17-C17),"0") -> 0 | H54: =IF(H17="X",(D17-C17),"0") -> 0 | I54: =IF(I17="X",(D17-C17),"0") -> 0 | J54: =IF(J17="X",(D17-C17),"0") -> 0 | K54: =IF(K17="X",(D17-C17),"0") -> 0 | L54: =IF(L17="X",(D17-C17),"0") -> 0 | M54: =IF(M17="X",(D17-C17),"0") -> 0 | N54: =IF(N17="X",(D17-C17),"0") -> 0 | O54: =IF(O17="X",(D17-C17),"0") -> 0 | P54: =IF(P17="X",(D17-C17),"0") -> 0 | Q54: =IF(Q17="X",(D17-C17),"0") -> 0 | R54: =IF(R17="X",(D17-C17),"0") -> 0 | S54: =IF(S17="X",(D17-C17),"0") -> 0 | T54: =IF(T17="X",(D17-C17),"0") -> 0
E55: =IF(E18="X",(D18-C18),"0") -> 0 | F55: =IF(F18="X",(D18-C18),"0") -> 0 | G55: =IF(G18="X",(D18-C18),"0") -> 0 | H55: =IF(H18="X",(D18-C18),"0") -> 0 | I55: =IF(I18="X",(D18-C18),"0") -> 0 | J55: =IF(J18="X",(D18-C18),"0") -> 0 | K55: =IF(K18="X",(D18-C18),"0") -> 0 | L55: =IF(L18="X",(D18-C18),"0") -> 0 | M55: =IF(M18="X",(D18-C18),"0") -> 0 | N55: =IF(N18="X",(D18-C18),"0") -> 0 | O55: =IF(O18="X",(D18-C18),"0") -> 0 | P55: =IF(P18="X",(D18-C18),"0") -> 0 | Q55: =IF(Q18="X",(D18-C18),"0") -> 0 | R55: =IF(R18="X",(D18-C18),"0") -> 0 | S55: =IF(S18="X",(D18-C18),"0") -> 0 | T55: =IF(T18="X",(D18-C18),"0") -> 0
... E131: =IF(E94="X",(D94-C94),"0") -> 0 | F131: =IF(F94="X",(D94-C94),"0") -> 0 | G131: =IF(G94="X",(D94-C94),"0") -> 0 | H131: =IF(H94="X",(D94-C94),"0") -> 0 | I131: =IF(I94="X",(D94-C94),"0") -> 0 | J131: =IF(J94="X",(D94-C94),"0") -> 0 | K131: =IF(K94="X",(D94-C94),"0") -> 0 | L131: =IF(L94="X",(D94-C94),"0") -> 0 | M131: =IF(M94="X",(D94-C94),"0") -> 0 | N131: =IF(N94="X",(D94-C94),"0") -> 0 | O131: =IF(O94="X",(D94-C94),"0") -> 0 | P131: =IF(P94="X",(D94-C94),"0") -> 0 | Q131: =IF(Q94="X",(D94-C94),"0") -> 0 | R131: =IF(R94="X",(D94-C94),"0") -> 0 | S131: =IF(S94="X",(D94-C94),"0") -> 0 | T131: =IF(T94="X",(D94-C94),"0") -> 0
E132: =SUM(E44:E131) -> 8.68 | F132: =SUM(F44:F131) -> 0 | G132: =SUM(G44:G131) -> 28.26 | H132: =SUM(H44:H131) -> 0 | I132: =SUM(I44:I131) -> 0 | J132: =SUM(J44:J131) -> 36.94 | K132: =SUM(K44:K131) -> 0 | L132: =SUM(L44:L131) -> 36.94 | ... T132: =SUM(T44:T131) -> 0

Sheet 250
A1: PROGRAMA DE MANUTENÇÃORODOVIÁRIA
D2: RODOVIAS PAVIMENTADAS | I2: DATA: | J2: 46204 | N2: TÉCNICO RESP. | O2: ='247'!O2 -> ENG. THIAGO TORQUATO
A3: FICHA DE INSPEÇÃO: | B3: ='T.T.'!C8 -> RODOVIA TO-050 - TRECHO ARRAIAS - DIVISA TO-GO | O3: REGIÃO: | P3: 13
A5: S.R.E. | B5: SENTIDO | C5: INÍCIO (KM) | D5: FIM (KM) | E5: CONDIÇÃO DO PAVIMENTO | J5: VEGETAÇÃO | L5: ELEM. DE DRENAGEM | O5: SIN. HOR. | R5: SIN. VERTICAL | U5: OBSERV.
E6: BOM | F6: REM. I. | G6: REM. L | H6: BUR. I | I6: BUR. L | J6: ADEQ. | K6: INADED. | L6: LIMPOS | M6: SUJOS | N6: DAN. | O6: BOM | P6: REG. | Q6: INEXIST. | R6: BOM | S6: POUCAS | T6: INEXIST.
A7: 050ETO0270 | B7: C | C7: 0 | D7: 4.98 | F7: X | J7: X | M7: X | P7: X | R7: X
A8: 050ETO0280 | B8: C | C8: 0 | D8: 1.86 | E8: X | J8: X | M8: X | P8: X | R8: X
A9: 050ETO0290 | B9: c | C9: 0 | D9: 8.5 | F9: X | J9: X | M9: X | P9: X | R9: X
A32: LEGENDA | B32: CONDIÇÃO DO PAVIMENTO
A33: REM. I | B33: REMENDOS ISOLADOS | E33: ATÉ 10 REMENDOS/KM | I33: BUR. I | J33: BURACOS ISOLADOS | M33: ATÉ 5 BURACOS/KM
A34: REM. L | B34: REMENDOS AO LONGO | E34: MAIS DE 10 REMENDOS/KM | I34: BUR. L | J34: BURACOS AO LONGO | M34: MAIS DE 5 BURACOS/KM
E39: =IF(E7="X",(D7-C7),"0") -> 0 | F39: =IF(F7="X",(D7-C7),"0") -> 4.98 | G39: =IF(G7="X",(D7-C7),"0") -> 0 | H39: =IF(H7="X",(D7-C7),"0") -> 0 | I39: =IF(I7="X",(D7-C7),"0") -> 0 | J39: =IF(J7="X",(D7-C7),"0") -> 4.98 | K39: =IF(K7="X",(D7-C7),"0") -> 0 | L39: =IF(L7="X",(D7-C7),"0") -> 0 | M39: =IF(M7="X",(D7-C7),"0") -> 4.98 | N39: =IF(N7="X",(D7-C7),"0") -> 0 | O39: =IF(O7="X",(D7-C7),"0") -> 0 | P39: =IF(P7="X",(D7-C7),"0") -> 4.98 | Q39: =IF(Q7="X",(D7-C7),"0") -> 0 | R39: =IF(R7="X",(D7-C7),"0") -> 4.98 | S39: =IF(S7="X",(D7-C7),"0") -> 0 | T39: =IF(T7="X",(D7-C7),"0") -> 0
E40: =IF(E8="X",(D8-C8),"0") -> 1.86 | F40: =IF(F8="X",(D8-C8),"0") -> 0 | G40: =IF(G8="X",(D8-C8),"0") -> 0 | H40: =IF(H8="X",(D8-C8),"0") -> 0 | I40: =IF(I8="X",(D8-C8),"0") -> 0 | J40: =IF(J8="X",(D8-C8),"0") -> 1.86 | K40: =IF(K8="X",(D8-C8),"0") -> 0 | L40: =IF(L8="X",(D8-C8),"0") -> 0 | M40: =IF(M8="X",(D8-C8),"0") -> 1.86 | N40: =IF(N8="X",(D8-C8),"0") -> 0 | O40: =IF(O8="X",(D8-C8),"0") -> 0 | P40: =IF(P8="X",(D8-C8),"0") -> 1.86 | Q40: =IF(Q8="X",(D8-C8),"0") -> 0 | R40: =IF(R8="X",(D8-C8),"0") -> 1.86 | S40: =IF(S8="X",(D8-C8),"0") -> 0 | T40: =IF(T8="X",(D8-C8),"0") -> 0
E41: =IF(E9="X",(D9-C9),"0") -> 0 | F41: =IF(F9="X",(D9-C9),"0") -> 8.5 | G41: =IF(G9="X",(D9-C9),"0") -> 0 | H41: =IF(H9="X",(D9-C9),"0") -> 0 | I41: =IF(I9="X",(D9-C9),"0") -> 0 | J41: =IF(J9="X",(D9-C9),"0") -> 8.5 | K41: =IF(K9="X",(D9-C9),"0") -> 0 | L41: =IF(L9="X",(D9-C9),"0") -> 0 | M41: =IF(M9="X",(D9-C9),"0") -> 8.5 | N41: =IF(N9="X",(D9-C9),"0") -> 0 | O41: =IF(O9="X",(D9-C9),"0") -> 0 | P41: =IF(P9="X",(D9-C9),"0") -> 8.5 | Q41: =IF(Q9="X",(D9-C9),"0") -> 0 | R41: =IF(R9="X",(D9-C9),"0") -> 8.5 | S41: =IF(S9="X",(D9-C9),"0") -> 0 | T41: =IF(T9="X",(D9-C9),"0") -> 0
E42: =IF(E10="X",(D10-C10),"0") -> 0 | F42: =IF(F10="X",(D10-C10),"0") -> 0 | G42: =IF(G10="X",(D10-C10),"0") -> 0 | H42: =IF(H10="X",(D10-C10),"0") -> 0 | I42: =IF(I10="X",(D10-C10),"0") -> 0 | J42: =IF(J10="X",(D10-C10),"0") -> 0 | K42: =IF(K10="X",(D10-C10),"0") -> 0 | L42: =IF(L10="X",(D10-C10),"0") -> 0 | M42: =IF(M10="X",(D10-C10),"0") -> 0 | N42: =IF(N10="X",(D10-C10),"0") -> 0 | O42: =IF(O10="X",(D10-C10),"0") -> 0 | P42: =IF(P10="X",(D10-C10),"0") -> 0 | Q42: =IF(Q10="X",(D10-C10),"0") -> 0 | R42: =IF(R10="X",(D10-C10),"0") -> 0 | S42: =IF(S10="X",(D10-C10),"0") -> 0 | T42: =IF(T10="X",(D10-C10),"0") -> 0
E43: =IF(E11="X",(D11-C11),"0") -> 0 | F43: =IF(F11="X",(D11-C11),"0") -> 0 | G43: =IF(G11="X",(D11-C11),"0") -> 0 | H43: =IF(H11="X",(D11-C11),"0") -> 0 | I43: =IF(I11="X",(D11-C11),"0") -> 0 | J43: =IF(J11="X",(D11-C11),"0") -> 0 | K43: =IF(K11="X",(D11-C11),"0") -> 0 | L43: =IF(L11="X",(D11-C11),"0") -> 0 | M43: =IF(M11="X",(D11-C11),"0") -> 0 | N43: =IF(N11="X",(D11-C11),"0") -> 0 | O43: =IF(O11="X",(D11-C11),"0") -> 0 | P43: =IF(P11="X",(D11-C11),"0") -> 0 | Q43: =IF(Q11="X",(D11-C11),"0") -> 0 | R43: =IF(R11="X",(D11-C11),"0") -> 0 | S43: =IF(S11="X",(D11-C11),"0") -> 0 | T43: =IF(T11="X",(D11-C11),"0") -> 0
E44: =IF(E12="X",(D12-C12),"0") -> 0 | F44: =IF(F12="X",(D12-C12),"0") -> 0 | G44: =IF(G12="X",(D12-C12),"0") -> 0 | H44: =IF(H12="X",(D12-C12),"0") -> 0 | I44: =IF(I12="X",(D12-C12),"0") -> 0 | J44: =IF(J12="X",(D12-C12),"0") -> 0 | K44: =IF(K12="X",(D12-C12),"0") -> 0 | L44: =IF(L12="X",(D12-C12),"0") -> 0 | M44: =IF(M12="X",(D12-C12),"0") -> 0 | N44: =IF(N12="X",(D12-C12),"0") -> 0 | O44: =IF(O12="X",(D12-C12),"0") -> 0 | P44: =IF(P12="X",(D12-C12),"0") -> 0 | Q44: =IF(Q12="X",(D12-C12),"0") -> 0 | R44: =IF(R12="X",(D12-C12),"0") -> 0 | S44: =IF(S12="X",(D12-C12),"0") -> 0 | T44: =IF(T12="X",(D12-C12),"0") -> 0
E45: =IF(E13="X",(D13-C13),"0") -> 0 | F45: =IF(F13="X",(D13-C13),"0") -> 0 | G45: =IF(G13="X",(D13-C13),"0") -> 0 | H45: =IF(H13="X",(D13-C13),"0") -> 0 | I45: =IF(I13="X",(D13-C13),"0") -> 0 | J45: =IF(J13="X",(D13-C13),"0") -> 0 | K45: =IF(K13="X",(D13-C13),"0") -> 0 | L45: =IF(L13="X",(D13-C13),"0") -> 0 | M45: =IF(M13="X",(D13-C13),"0") -> 0 | N45: =IF(N13="X",(D13-C13),"0") -> 0 | O45: =IF(O13="X",(D13-C13),"0") -> 0 | P45: =IF(P13="X",(D13-C13),"0") -> 0 | Q45: =IF(Q13="X",(D13-C13),"0") -> 0 | R45: =IF(R13="X",(D13-C13),"0") -> 0 | S45: =IF(S13="X",(D13-C13),"0") -> 0 | T45: =IF(T13="X",(D13-C13),"0") -> 0
E46: =IF(E14="X",(D14-C14),"0") -> 0 | F46: =IF(F14="X",(D14-C14),"0") -> 0 | G46: =IF(G14="X",(D14-C14),"0") -> 0 | H46: =IF(H14="X",(D14-C14),"0") -> 0 | I46: =IF(I14="X",(D14-C14),"0") -> 0 | J46: =IF(J14="X",(D14-C14),"0") -> 0 | K46: =IF(K14="X",(D14-C14),"0") -> 0 | L46: =IF(L14="X",(D14-C14),"0") -> 0 | M46: =IF(M14="X",(D14-C14),"0") -> 0 | N46: =IF(N14="X",(D14-C14),"0") -> 0 | O46: =IF(O14="X",(D14-C14),"0") -> 0 | P46: =IF(P14="X",(D14-C14),"0") -> 0 | Q46: =IF(Q14="X",(D14-C14),"0") -> 0 | R46: =IF(R14="X",(D14-C14),"0") -> 0 | S46: =IF(S14="X",(D14-C14),"0") -> 0 | T46: =IF(T14="X",(D14-C14),"0") -> 0
E47: =IF(E15="X",(D15-C15),"0") -> 0 | F47: =IF(F15="X",(D15-C15),"0") -> 0 | G47: =IF(G15="X",(D15-C15),"0") -> 0 | H47: =IF(H15="X",(D15-C15),"0") -> 0 | I47: =IF(I15="X",(D15-C15),"0") -> 0 | J47: =IF(J15="X",(D15-C15),"0") -> 0 | K47: =IF(K15="X",(D15-C15),"0") -> 0 | L47: =IF(L15="X",(D15-C15),"0") -> 0 | M47: =IF(M15="X",(D15-C15),"0") -> 0 | N47: =IF(N15="X",(D15-C15),"0") -> 0 | O47: =IF(O15="X",(D15-C15),"0") -> 0 | P47: =IF(P15="X",(D15-C15),"0") -> 0 | Q47: =IF(Q15="X",(D15-C15),"0") -> 0 | R47: =IF(R15="X",(D15-C15),"0") -> 0 | S47: =IF(S15="X",(D15-C15),"0") -> 0 | T47: =IF(T15="X",(D15-C15),"0") -> 0
E48: =IF(E16="X",(D16-C16),"0") -> 0 | F48: =IF(F16="X",(D16-C16),"0") -> 0 | G48: =IF(G16="X",(D16-C16),"0") -> 0 | H48: =IF(H16="X",(D16-C16),"0") -> 0 | I48: =IF(I16="X",(D16-C16),"0") -> 0 | J48: =IF(J16="X",(D16-C16),"0") -> 0 | K48: =IF(K16="X",(D16-C16),"0") -> 0 | L48: =IF(L16="X",(D16-C16),"0") -> 0 | M48: =IF(M16="X",(D16-C16),"0") -> 0 | N48: =IF(N16="X",(D16-C16),"0") -> 0 | O48: =IF(O16="X",(D16-C16),"0") -> 0 | P48: =IF(P16="X",(D16-C16),"0") -> 0 | Q48: =IF(Q16="X",(D16-C16),"0") -> 0 | R48: =IF(R16="X",(D16-C16),"0") -> 0 | S48: =IF(S16="X",(D16-C16),"0") -> 0 | T48: =IF(T16="X",(D16-C16),"0") -> 0
E49: =IF(E17="X",(D17-C17),"0") -> 0 | F49: =IF(F17="X",(D17-C17),"0") -> 0 | G49: =IF(G17="X",(D17-C17),"0") -> 0 | H49: =IF(H17="X",(D17-C17),"0") -> 0 | I49: =IF(I17="X",(D17-C17),"0") -> 0 | J49: =IF(J17="X",(D17-C17),"0") -> 0 | K49: =IF(K17="X",(D17-C17),"0") -> 0 | L49: =IF(L17="X",(D17-C17),"0") -> 0 | M49: =IF(M17="X",(D17-C17),"0") -> 0 | N49: =IF(N17="X",(D17-C17),"0") -> 0 | O49: =IF(O17="X",(D17-C17),"0") -> 0 | P49: =IF(P17="X",(D17-C17),"0") -> 0 | Q49: =IF(Q17="X",(D17-C17),"0") -> 0 | R49: =IF(R17="X",(D17-C17),"0") -> 0 | S49: =IF(S17="X",(D17-C17),"0") -> 0 | T49: =IF(T17="X",(D17-C17),"0") -> 0
E50: =IF(E18="X",(D18-C18),"0") -> 0 | F50: =IF(F18="X",(D18-C18),"0") -> 0 | G50: =IF(G18="X",(D18-C18),"0") -> 0 | H50: =IF(H18="X",(D18-C18),"0") -> 0 | I50: =IF(I18="X",(D18-C18),"0") -> 0 | J50: =IF(J18="X",(D18-C18),"0") -> 0 | K50: =IF(K18="X",(D18-C18),"0") -> 0 | L50: =IF(L18="X",(D18-C18),"0") -> 0 | M50: =IF(M18="X",(D18-C18),"0") -> 0 | N50: =IF(N18="X",(D18-C18),"0") -> 0 | O50: =IF(O18="X",(D18-C18),"0") -> 0 | P50: =IF(P18="X",(D18-C18),"0") -> 0 | Q50: =IF(Q18="X",(D18-C18),"0") -> 0 | R50: =IF(R18="X",(D18-C18),"0") -> 0 | S50: =IF(S18="X",(D18-C18),"0") -> 0 | T50: =IF(T18="X",(D18-C18),"0") -> 0
... E126: =IF(E94="X",(D94-C94),"0") -> 0 | F126: =IF(F94="X",(D94-C94),"0") -> 0 | G126: =IF(G94="X",(D94-C94),"0") -> 0 | H126: =IF(H94="X",(D94-C94),"0") -> 0 | I126: =IF(I94="X",(D94-C94),"0") -> 0 | J126: =IF(J94="X",(D94-C94),"0") -> 0 | K126: =IF(K94="X",(D94-C94),"0") -> 0 | L126: =IF(L94="X",(D94-C94),"0") -> 0 | M126: =IF(M94="X",(D94-C94),"0") -> 0 | N126: =IF(N94="X",(D94-C94),"0") -> 0 | O126: =IF(O94="X",(D94-C94),"0") -> 0 | P126: =IF(P94="X",(D94-C94),"0") -> 0 | Q126: =IF(Q94="X",(D94-C94),"0") -> 0 | R126: =IF(R94="X",(D94-C94),"0") -> 0 | S126: =IF(S94="X",(D94-C94),"0") -> 0 | T126: =IF(T94="X",(D94-C94),"0") -> 0
E127: =SUM(E39:E126) -> 1.86 | F127: =SUM(F39:F126) -> 13.48 | G127: =SUM(G39:G126) -> 0 | H127: =SUM(H39:H126) -> 0 | I127: =SUM(I39:I126) -> 0 | J127: =SUM(J39:J126) -> 15.34 | K127: =SUM(K39:K126) -> 0 | L127: =SUM(L39:L126) -> 0 | ... T127: =SUM(T39:T126) -> 0

Sheet 251
A1: PROGRAMA DE MANUTENÇÃORODOVIÁRIA
D2: RODOVIAS PAVIMENTADAS | I2: DATA: | J2: 46204 | N2: TÉCNICO RESP. | O2: ='247'!O2 -> ENG. THIAGO TORQUATO
A3: FICHA DE INSPEÇÃO: | B3: ='T.T.'!C9 -> RODOVIA TO-050 - TRECHO CONCEIÇÃO DO TOCANTINS - ARRAIAS | O3: REGIÃO: | P3: 13
A5: S.R.E. | B5: SENTIDO | C5: INÍCIO (KM) | D5: FIM (KM) | E5: CONDIÇÃO DO PAVIMENTO | J5: VEGETAÇÃO | L5: ELEM. DE DRENAGEM | O5: SIN. HOR. | R5: SIN. VERTICAL | U5: OBSERV.
E6: BOM | F6: REM. I. | G6: REM. L | H6: BUR. I | I6: BUR. L | J6: ADEQ. | K6: INADED. | L6: LIMPOS | M6: SUJOS | N6: DAN. | O6: BOM | P6: REG. | Q6: INEXIST. | R6: BOM | S6: POUCAS | T6: INEXIST.
A7: 050ETO0230 | B7: C | C7: 0 | D7: 10 | E7: X | J7: X | M7: X | P7: X | S7: X | U7: 33,95 km
C8: 10 | D8: 11 | F8: X | J8: X | M8: X | P8: X | S8: X
C9: 11 | D9: 19 | E9: X | J9: X | M9: X | P9: X | S9: X
C10: 19 | D10: 20 | G10: X | J10: X | M10: X | P10: X | S10: X
C11: 20 | D11: 30 | E11: X | J11: X | M11: X | P11: X | S11: X
C12: 30 | D12: 33.95 | F12: X | J12: X | M12: X | P12: X | S12: X
A13: 050ETO0240 | B13: C | C13: 0 | D13: 15 | E13: X | J13: X | M13: X | P13: X | S13: X | U13: 47,95 km
C14: 15 | D14: 23 | F14: X | J14: X | N14: X | P14: X | S14: X
C15: 23 | D15: 26 | E15: X | J15: X | M15: X | P15: X | S15: X
C16: 26 | D16: 42 | G16: X | J16: X | M16: X | P16: X | S16: X
C17: 42 | D17: 47.95 | F17: X | J17: X | M17: X | P17: X | S17: X
A18: 050ETO0250 | B18: C | C18: 0 | D18: 3 | E18: X | J18: X | M18: X | P18: X | S18: X
C19: 3 | D19: 5 | F19: X | J19: X | M19: X | P19: X | S19: X
C20: 5 | D20: 7 | E20: X | J20: X | M20: X | P20: X | S20: X
C21: 7 | D21: 10 | G21: X | J21: X | M21: X | P21: X | S21: X
C22: 10 | D22: 15 | E22: X | J22: X | M22: X | P22: X | S22: X
C23: 15 | D23: 18.96 | F23: X | J23: X | M23: X | P23: X | S23: X
A24: 050ETO0260 | B24: C | C24: 0 | D24: 3.65 | E24: X | J24: X | L24: X | P24: X | R24: X | U24: 3,65 km
A32: LEGENDA | B32: CONDIÇÃO DO PAVIMENTO
A33: REM. I | B33: REMENDOS ISOLADOS | E33: ATÉ 10 REMENDOS/KM | I33: BUR. I | J33: BURACOS ISOLADOS | M33: ATÉ 5 BURACOS/KM
A34: REM. L | B34: REMENDOS AO LONGO | E34: MAIS DE 10 REMENDOS/KM | I34: BUR. L | J34: BURACOS AO LONGO | M34: MAIS DE 5 BURACOS/KM
E39: =IF(E7="X",(D7-C7),"0") -> 10 | F39: =IF(F7="X",(D7-C7),"0") -> 0 | G39: =IF(G7="X",(D7-C7),"0") -> 0 | H39: =IF(H7="X",(D7-C7),"0") -> 0 | I39: =IF(I7="X",(D7-C7),"0") -> 0 | J39: =IF(J7="X",(D7-C7),"0") -> 10 | K39: =IF(K7="X",(D7-C7),"0") -> 0 | L39: =IF(L7="X",(D7-C7),"0") -> 0 | M39: =IF(M7="X",(D7-C7),"0") -> 10 | N39: =IF(N7="X",(D7-C7),"0") -> 0 | O39: =IF(O7="X",(D7-C7),"0") -> 0 | P39: =IF(P7="X",(D7-C7),"0") -> 10 | Q39: =IF(Q7="X",(D7-C7),"0") -> 0 | R39: =IF(R7="X",(D7-C7),"0") -> 0 | S39: =IF(S7="X",(D7-C7),"0") -> 10 | T39: =IF(T7="X",(D7-C7),"0") -> 0
E40: =IF(E8="X",(D8-C8),"0") -> 0 | F40: =IF(F8="X",(D8-C8),"0") -> 1 | G40: =IF(G8="X",(D8-C8),"0") -> 0 | H40: =IF(H8="X",(D8-C8),"0") -> 0 | I40: =IF(I8="X",(D8-C8),"0") -> 0 | J40: =IF(J8="X",(D8-C8),"0") -> 1 | K40: =IF(K8="X",(D8-C8),"0") -> 0 | L40: =IF(L8="X",(D8-C8),"0") -> 0 | M40: =IF(M8="X",(D8-C8),"0") -> 1 | N40: =IF(N8="X",(D8-C8),"0") -> 0 | O40: =IF(O8="X",(D8-C8),"0") -> 0 | P40: =IF(P8="X",(D8-C8),"0") -> 1 | Q40: =IF(Q8="X",(D8-C8),"0") -> 0 | R40: =IF(R8="X",(D8-C8),"0") -> 0 | S40: =IF(S8="X",(D8-C8),"0") -> 1 | T40: =IF(T8="X",(D8-C8),"0") -> 0
E41: =IF(E9="X",(D9-C9),"0") -> 8 | F41: =IF(F9="X",(D9-C9),"0") -> 0 | G41: =IF(G9="X",(D9-C9),"0") -> 0 | H41: =IF(H9="X",(D9-C9),"0") -> 0 | I41: =IF(I9="X",(D9-C9),"0") -> 0 | J41: =IF(J9="X",(D9-C9),"0") -> 8 | K41: =IF(K9="X",(D9-C9),"0") -> 0 | L41: =IF(L9="X",(D9-C9),"0") -> 0 | M41: =IF(M9="X",(D9-C9),"0") -> 8 | N41: =IF(N9="X",(D9-C9),"0") -> 0 | O41: =IF(O9="X",(D9-C9),"0") -> 0 | P41: =IF(P9="X",(D9-C9),"0") -> 8 | Q41: =IF(Q9="X",(D9-C9),"0") -> 0 | R41: =IF(R9="X",(D9-C9),"0") -> 0 | S41: =IF(S9="X",(D9-C9),"0") -> 8 | T41: =IF(T9="X",(D9-C9),"0") -> 0
E42: =IF(E10="X",(D10-C10),"0") -> 0 | F42: =IF(F10="X",(D10-C10),"0") -> 0 | G42: =IF(G10="X",(D10-C10),"0") -> 1 | H42: =IF(H10="X",(D10-C10),"0") -> 0 | I42: =IF(I10="X",(D10-C10),"0") -> 0 | J42: =IF(J10="X",(D10-C10),"0") -> 1 | K42: =IF(K10="X",(D10-C10),"0") -> 0 | L42: =IF(L10="X",(D10-C10),"0") -> 0 | M42: =IF(M10="X",(D10-C10),"0") -> 1 | N42: =IF(N10="X",(D10-C10),"0") -> 0 | O42: =IF(O10="X",(D10-C10),"0") -> 0 | P42: =IF(P10="X",(D10-C10),"0") -> 1 | Q42: =IF(Q10="X",(D10-C10),"0") -> 0 | R42: =IF(R10="X",(D10-C10),"0") -> 0 | S42: =IF(S10="X",(D10-C10),"0") -> 1 | T42: =IF(T10="X",(D10-C10),"0") -> 0
E43: =IF(E11="X",(D11-C11),"0") -> 10 | F43: =IF(F11="X",(D11-C11),"0") -> 0 | G43: =IF(G11="X",(D11-C11),"0") -> 0 | H43: =IF(H11="X",(D11-C11),"0") -> 0 | I43: =IF(I11="X",(D11-C11),"0") -> 0 | J43: =IF(J11="X",(D11-C11),"0") -> 10 | K43: =IF(K11="X",(D11-C11),"0") -> 0 | L43: =IF(L11="X",(D11-C11),"0") -> 0 | M43: =IF(M11="X",(D11-C11),"0") -> 10 | N43: =IF(N11="X",(D11-C11),"0") -> 0 | O43: =IF(O11="X",(D11-C11),"0") -> 0 | P43: =IF(P11="X",(D11-C11),"0") -> 10 | Q43: =IF(Q11="X",(D11-C11),"0") -> 0 | R43: =IF(R11="X",(D11-C11),"0") -> 0 | S43: =IF(S11="X",(D11-C11),"0") -> 10 | T43: =IF(T11="X",(D11-C11),"0") -> 0
E44: =IF(E12="X",(D12-C12),"0") -> 0 | F44: =IF(F12="X",(D12-C12),"0") -> 3.95 | G44: =IF(G12="X",(D12-C12),"0") -> 0 | H44: =IF(H12="X",(D12-C12),"0") -> 0 | I44: =IF(I12="X",(D12-C12),"0") -> 0 | J44: =IF(J12="X",(D12-C12),"0") -> 3.95 | K44: =IF(K12="X",(D12-C12),"0") -> 0 | L44: =IF(L12="X",(D12-C12),"0") -> 0 | M44: =IF(M12="X",(D12-C12),"0") -> 3.95 | N44: =IF(N12="X",(D12-C12),"0") -> 0 | O44: =IF(O12="X",(D12-C12),"0") -> 0 | P44: =IF(P12="X",(D12-C12),"0") -> 3.95 | Q44: =IF(Q12="X",(D12-C12),"0") -> 0 | R44: =IF(R12="X",(D12-C12),"0") -> 0 | S44: =IF(S12="X",(D12-C12),"0") -> 3.95 | T44: =IF(T12="X",(D12-C12),"0") -> 0
