Workbook

Sheet Trechos
A1: RELAÇÃO DE TRECHOS NÃO PAVIMENTDOS R.13
A2: LOTE | B2: N. | C2: TRECHO | D2: S.R.E | E2: SUBTRECHOS | F2: EXT. (KM) | G2: TIPO | H2: 45839 | I2: 45870
A3: 13 | B3: 245 | C3: RODOVIA TO-040 - TRECHO ENTR. TO-369 - ENTR. TO-280 (ALMAS) | D3: 040ETO0140 | E3: ENTR. TO-369 - ENTR. TO-280 (ALMAS) | F3: 56.716372 | G3: EOP
A4: 13 | B4: 260 | C4: RODOVIA TO-296 - TRECHO ENTR. TO-050 - ENTR. TO-110 (COMBINADO) | D4: 296ETO0110 | E4: COMBINADO *TRECHO URBANO* - ENTR. TO-497 | F4: 30.279582 | G4: LEN
A5: 13 | B5: 260 | C5: RODOVIA TO-296 - TRECHO ENTR. TO-050 - ENTR. TO-110 (COMBINADO) | D5: 296ETO0120 | E5: ENTR. TO-497 - ENTR. TO-050 | F5: 21.855987 | G5: LEN
A6: 13 | B6: 261 | C6: RODOVIA TO-296 - TRECHO ENTR. BR-242 (POVOADO SÃO BOM JESUS DAS PALMAS) - ENTR. TO-050 | D6: 296ETO0170 | E6: ENTR. TO-050 - ENTR. BR-242 | F6: 50.619704 | G6: LEN
A7: 13 | B7: 262 | C7: RODOVIA TO-369 - TRECHO ENTR. TO-040 - ENTR. TO-476 (FUNIL - RIO SONINHO) | D7: 369ETO0100 | E7: ENTR. TO-476 - ENTR. TO-040 | F7: 23.951037 | G7: LEN
A8: 13 | B8: 263 | C8: RODOVIA TO-387 - TRECHO CONCEIÇÃO DO TOCANTINS - TAIPAS DO TOCANTINS | D8: 387ETO0070 | E8: ENTR. TO-485 (TAIPAS) - CONCEIÇÃO DO TOCANTINS *TRECHO URBANO* | F8: 39.5018 | G8: LEN
A9: 13 | B9: 264 | C9: RODOVIA TO-387 - TRECHO ENTR. BR-010 - ENTR. TO-050 (CONCEIÇÃO DO TOCANTINS) | D9: 387ETO0100 | E9: ENTR. TO-050 - ENTR. TO-130-BR-010 | F9: 42.464393 | G9: LEN
A10: 13 | B10: 265 | C10: RODOVIA TO-387 - TRECHO ENTR. TO-040 - TAIPAS DO TOCANTINS | D10: 387ETO0040 | E10: ENTR. TO-040-TO-280 - TAIPAS DO TOCANTINS *TRECHO URBANO* | F10: 67.817857 | G10: LEN
A11: 13 | B11: 267 | C11: RODOVIA TO-476 - TRECHO RIO DA CONCEIÇÃO - ENTR. TO-477 | D11: 476ETO0030 | E11: ENTR. TO-477 - RIO DA CONCEIÇÃO *TRECHO URBANO* | F11: 14.476203 | G11: LEN
A12: 13 | B12: 268 | C12: RODOVIA TO-477 - TRECHO ALMAS - ENTR. TO-476 | D12: 477ETO0020 | E12: ENTR. TO-476 - ENTR. TO-040-TO-280 (ALMAS) | F12: 34.769106 | G12: LEN
A13: 13 | B13: 269 | C13: RODOVIA TO-477 - TRECHO ENTR. BR-010 (POVOADO BONFIM) - ALMAS | D13: 477ETO0060 | E13: ALMAS *TRECHO URBANO* - BARRA NOVA | F13: 63.074548 | G13: LEN
A14: 13 | B14: 269 | C14: RODOVIA TO-477 - TRECHO ENTR. BR-010 (POVOADO BONFIM) - ALMAS | D14: 477ETO0070 | E14: BARRA NOVA - ENTR. TO-050-BR-010 | F14: 9.9650283 | G14: LEN
... A25: 13 | B25: 273 | C25: RODOVIA TO-499 - TRECHO ENTR. TO-050 - DIVISA TO-GO | D25: 499ETO0010 | E25: ENTR. TO-050 - DIV TO-GO | F25: 11.207917 | G25: LEN
F26: =SUM(F3:F25) -> 662.8707

Sheet 245
A1: PROGRAMA DE MANUTENÇÃORODOVIÁRIA | I1: DATA: | J1: 46204 | L1: TÉCNICO RESP. | N1: ENG. THIAGO TORQUATO
F2: RODOVIAS NÃO PAVIMENTADAS
A3: FICHA DE INSPEÇÃO: | B3: =TT!C4 -> RODOVIA TO-040 - TRECHO ENTR. TO-369 - ENTR. TO-280 (ALMAS) | I3: REGIÃO: | J3: 13
A5: S.R.E. | B5: SENTIDO | C5: INÍCIO (KM) | D5: FIM (KM) | E5: CONDIÇÃO DA PLATAFORMA | I5: DRENAGEM SUPERFICIAL | L5: OBSERV.
E6: BOM | F6: REG. (ATÉ 10 IRR./KM) | G6: RUÍM (+ 10 IRR./KM) | H6: PÉSSIMA (ATOLEIRO/PTO. CRÍTICO) | I6: LIMPA | J6: OBSTRUÍDA | K6: AUSENTE
C7: 0 | D7: 1 | E7: X | I7: X
C8: 1 | D8: 2 | E8: X | J8: X
C9: 2 | D9: 3 | E9: X
C10: 3 | D10: 4 | E10: X | K10: X
C11: 4 | D11: 5 | E11: X
C12: 5 | D12: 56.72 | E12: X
E36: =IF(E7="X",(D7-C7),"0") -> 1 | F36: =IF(F7="X",(D7-C7),"0") -> 0 | G36: =IF(G7="X",(D7-C7),"0") -> 0 | H36: =IF(H7="X",(D7-C7),"0") -> 0 | I36: =IF(I7="X",(D7-C7),"0") -> 1 | J36: =IF(J7="X",(D7-C7),"0") -> 0 | K36: =IF(K7="X",(D7-C7),"0") -> 0
E37: =IF(E8="X",(D8-C8),"0") -> 1 | F37: =IF(F8="X",(D8-C8),"0") -> 0 | G37: =IF(G8="X",(D8-C8),"0") -> 0 | H37: =IF(H8="X",(D8-C8),"0") -> 0 | I37: =IF(I8="X",(D8-C8),"0") -> 0 | J37: =IF(J8="X",(D8-C8),"0") -> 1 | K37: =IF(K8="X",(D8-C8),"0") -> 0
E38: =IF(E9="X",(D9-C9),"0") -> 1 | F38: =IF(F9="X",(D9-C9),"0") -> 0 | G38: =IF(G9="X",(D9-C9),"0") -> 0 | H38: =IF(H9="X",(D9-C9),"0") -> 0 | I38: =IF(I9="X",(D9-C9),"0") -> 0 | J38: =IF(J9="X",(D9-C9),"0") -> 0 | K38: =IF(K9="X",(D9-C9),"0") -> 0
E39: =IF(E10="X",(D10-C10),"0") -> 1 | F39: =IF(F10="X",(D10-C10),"0") -> 0 | G39: =IF(G10="X",(D10-C10),"0") -> 0 | H39: =IF(H10="X",(D10-C10),"0") -> 0 | I39: =IF(I10="X",(D10-C10),"0") -> 0 | J39: =IF(J10="X",(D10-C10),"0") -> 0 | K39: =IF(K10="X",(D10-C10),"0") -> 1
E40: =IF(E11="X",(D11-C11),"0") -> 1 | F40: =IF(F11="X",(D11-C11),"0") -> 0 | G40: =IF(G11="X",(D11-C11),"0") -> 0 | H40: =IF(H11="X",(D11-C11),"0") -> 0 | I40: =IF(I11="X",(D11-C11),"0") -> 0 | J40: =IF(J11="X",(D11-C11),"0") -> 0 | K40: =IF(K11="X",(D11-C11),"0") -> 0
E41: =IF(E12="X",(D12-C12),"0") -> 51.72 | F41: =IF(F12="X",(D12-C12),"0") -> 0 | G41: =IF(G12="X",(D12-C12),"0") -> 0 | H41: =IF(H12="X",(D12-C12),"0") -> 0 | I41: =IF(I12="X",(D12-C12),"0") -> 0 | J41: =IF(J12="X",(D12-C12),"0") -> 0 | K41: =IF(K12="X",(D12-C12),"0") -> 0
E42: =IF(E13="X",(D13-C13),"0") -> 0 | F42: =IF(F13="X",(D13-C13),"0") -> 0 | G42: =IF(G13="X",(D13-C13),"0") -> 0 | H42: =IF(H13="X",(D13-C13),"0") -> 0 | I42: =IF(I13="X",(D13-C13),"0") -> 0 | J42: =IF(J13="X",(D13-C13),"0") -> 0 | K42: =IF(K13="X",(D13-C13),"0") -> 0
E43: =IF(E14="X",(D14-C14),"0") -> 0 | F43: =IF(F14="X",(D14-C14),"0") -> 0 | G43: =IF(G14="X",(D14-C14),"0") -> 0 | H43: =IF(H14="X",(D14-C14),"0") -> 0 | I43: =IF(I14="X",(D14-C14),"0") -> 0 | J43: =IF(J14="X",(D14-C14),"0") -> 0 | K43: =IF(K14="X",(D14-C14),"0") -> 0
E44: =IF(E15="X",(D15-C15),"0") -> 0 | F44: =IF(F15="X",(D15-C15),"0") -> 0 | G44: =IF(G15="X",(D15-C15),"0") -> 0 | H44: =IF(H15="X",(D15-C15),"0") -> 0 | I44: =IF(I15="X",(D15-C15),"0") -> 0 | J44: =IF(J15="X",(D15-C15),"0") -> 0 | K44: =IF(K15="X",(D15-C15),"0") -> 0
E45: =IF(E16="X",(D16-C16),"0") -> 0 | F45: =IF(F16="X",(D16-C16),"0") -> 0 | G45: =IF(G16="X",(D16-C16),"0") -> 0 | H45: =IF(H16="X",(D16-C16),"0") -> 0 | I45: =IF(I16="X",(D16-C16),"0") -> 0 | J45: =IF(J16="X",(D16-C16),"0") -> 0 | K45: =IF(K16="X",(D16-C16),"0") -> 0
E46: =IF(E17="X",(D17-C17),"0") -> 0 | F46: =IF(F17="X",(D17-C17),"0") -> 0 | G46: =IF(G17="X",(D17-C17),"0") -> 0 | H46: =IF(H17="X",(D17-C17),"0") -> 0 | I46: =IF(I17="X",(D17-C17),"0") -> 0 | J46: =IF(J17="X",(D17-C17),"0") -> 0 | K46: =IF(K17="X",(D17-C17),"0") -> 0
E47: =IF(E18="X",(D18-C18),"0") -> 0 | F47: =IF(F18="X",(D18-C18),"0") -> 0 | G47: =IF(G18="X",(D18-C18),"0") -> 0 | H47: =IF(H18="X",(D18-C18),"0") -> 0 | I47: =IF(I18="X",(D18-C18),"0") -> 0 | J47: =IF(J18="X",(D18-C18),"0") -> 0 | K47: =IF(K18="X",(D18-C18),"0") -> 0
... E61: =IF(E32="X",(D32-C32),"0") -> 0 | F61: =IF(F32="X",(D32-C32),"0") -> 0 | G61: =IF(G32="X",(D32-C32),"0") -> 0 | H61: =IF(H32="X",(D32-C32),"0") -> 0 | I61: =IF(I32="X",(D32-C32),"0") -> 0 | J61: =IF(J32="X",(D32-C32),"0") -> 0 | K61: =IF(K32="X",(D32-C32),"0") -> 0
E62: =SUM(E36:E61) -> 56.72 | F62: =SUM(F36:F61) -> 0 | G62: =SUM(G36:G61) -> 0 | H62: =SUM(H36:H61) -> 0 | I62: =SUM(I36:I61) -> 1 | J62: =SUM(J36:J61) -> 1 | K62: =SUM(K36:K61) -> 1

Sheet 260
A1: PROGRAMA DE MANUTENÇÃORODOVIÁRIA | I1: DATA: | J1: ='245'!J1 -> 46204 | L1: TÉCNICO RESP. | N1: ='245'!N1 -> ENG. THIAGO TORQUATO
F2: RODOVIAS NÃO PAVIMENTADAS
A3: FICHA DE INSPEÇÃO: | B3: =TT!C5 -> RODOVIA TO-296 - TRECHO ENTR. TO-050 - ENTR. TO-110 (COMBINADO) | I3: REGIÃO: | J3: 13
A5: S.R.E. | B5: SENTIDO | C5: INÍCIO (KM) | D5: FIM (KM) | E5: CONDIÇÃO DA PLATAFORMA | I5: DRENAGEM SUPERFICIAL | L5: OBSERV.
E6: BOM | F6: REG. (ATÉ 10 IRR./KM) | G6: RUÍM (+ 10 IRR./KM) | H6: PÉSSIMA (ATOLEIRO/PTO. CRÍTICO) | I6: LIMPA | J6: OBSTRUÍDA | K6: AUSENTE
A7: 296ETO0120 | B7: C | C7: 0 | D7: 3.4 | H7: X | K7: X | L7: * (21,86 Km) TRECHO CRÍTICO COM MUITAS PEDRAS AFLORADAS - 07 FOTOS
A8: 296ETO0120 | C8: 3.4 | D8: 3.4 | E8: X | L8: 01 BUEIRO TUBULAR - 02 FOTOS
A9: 296ETO0120 | C9: 3.7 | D9: 3.7 | E9: X | L9: 01 BUEIRO TUBULAR - 01 FOTO
A10: 296ETO0120 | C10: 3.7 | D10: 4.2 | F10: X | K10: X | L10: 01 FOTO
A11: 296ETO0120 | C11: 4.2 | D11: 5.9 | F11: X | K11: X | L11: AMPLIAÇÃO DE UM BUEIRO CELULAR
A12: 296ETO0120 | C12: 5.9 | D12: 6 | H12: X | K12: X | L12: PONTO CRÍTICO + 01 BUEIRO TUBULAR
A13: 296ETO0120 | C13: 6.7 | D13: 20 | F13: X | L13: PONTE
A14: 296ETO0120 | C14: 20 | D14: 20.3 | L14: PONTE - 02 FOTOS
A15: 296ETO0120 | C15: 20.3 | D15: 21.86 | F15: X | K15: X
A16: 296ETO0120 | H16: X | K16: X | L16: PONTO CRÍTICO
A17: 296ETO0120 | K17: X | L17: FINAL DO TRECHO - 02 FOTOS
A18: 296ETO0120
A19: 296ETO0110 | B19: C | C19: 0 | D19: 15 | F19: X | J19: X
A20: 296ETO0110 | C20: 15 | D20: 30.2 | E20: X | J20: X
E36: =IF(E7="X",(D7-C7),"0") -> 0 | F36: =IF(F7="X",(D7-C7),"0") -> 0 | G36: =IF(G7="X",(D7-C7),"0") -> 0 | H36: =IF(H7="X",(D7-C7),"0") -> 3.4 | I36: =IF(I7="X",(D7-C7),"0") -> 0 | J36: =IF(J7="X",(D7-C7),"0") -> 0 | K36: =IF(K7="X",(D7-C7),"0") -> 3.4
E37: =IF(E8="X",(D8-C8),"0") -> 0 | F37: =IF(F8="X",(D8-C8),"0") -> 0 | G37: =IF(G8="X",(D8-C8),"0") -> 0 | H37: =IF(H8="X",(D8-C8),"0") -> 0 | I37: =IF(I8="X",(D8-C8),"0") -> 0 | J37: =IF(J8="X",(D8-C8),"0") -> 0 | K37: =IF(K8="X",(D8-C8),"0") -> 0
E38: =IF(E9="X",(D9-C9),"0") -> 0 | F38: =IF(F9="X",(D9-C9),"0") -> 0 | G38: =IF(G9="X",(D9-C9),"0") -> 0 | H38: =IF(H9="X",(D9-C9),"0") -> 0 | I38: =IF(I9="X",(D9-C9),"0") -> 0 | J38: =IF(J9="X",(D9-C9),"0") -> 0 | K38: =IF(K9="X",(D9-C9),"0") -> 0
E39: =IF(E10="X",(D10-C10),"0") -> 0 | F39: =IF(F10="X",(D10-C10),"0") -> 0.5 | G39: =IF(G10="X",(D10-C10),"0") -> 0 | H39: =IF(H10="X",(D10-C10),"0") -> 0 | I39: =IF(I10="X",(D10-C10),"0") -> 0 | J39: =IF(J10="X",(D10-C10),"0") -> 0 | K39: =IF(K10="X",(D10-C10),"0") -> 0.5
E40: =IF(E11="X",(D11-C11),"0") -> 0 | F40: =IF(F11="X",(D11-C11),"0") -> 1.7 | G40: =IF(G11="X",(D11-C11),"0") -> 0 | H40: =IF(H11="X",(D11-C11),"0") -> 0 | I40: =IF(I11="X",(D11-C11),"0") -> 0 | J40: =IF(J11="X",(D11-C11),"0") -> 0 | K40: =IF(K11="X",(D11-C11),"0") -> 1.7
E41: =IF(E12="X",(D12-C12),"0") -> 0 | F41: =IF(F12="X",(D12-C12),"0") -> 0 | G41: =IF(G12="X",(D12-C12),"0") -> 0 | H41: =IF(H12="X",(D12-C12),"0") -> 0.1 | I41: =IF(I12="X",(D12-C12),"0") -> 0 | J41: =IF(J12="X",(D12-C12),"0") -> 0 | K41: =IF(K12="X",(D12-C12),"0") -> 0.1
E42: =IF(E13="X",(D13-C13),"0") -> 0 | F42: =IF(F13="X",(D13-C13),"0") -> 13.3 | G42: =IF(G13="X",(D13-C13),"0") -> 0 | H42: =IF(H13="X",(D13-C13),"0") -> 0 | I42: =IF(I13="X",(D13-C13),"0") -> 0 | J42: =IF(J13="X",(D13-C13),"0") -> 0 | K42: =IF(K13="X",(D13-C13),"0") -> 0
E43: =IF(E14="X",(D14-C14),"0") -> 0 | F43: =IF(F14="X",(D14-C14),"0") -> 0 | G43: =IF(G14="X",(D14-C14),"0") -> 0 | H43: =IF(H14="X",(D14-C14),"0") -> 0 | I43: =IF(I14="X",(D14-C14),"0") -> 0 | J43: =IF(J14="X",(D14-C14),"0") -> 0 | K43: =IF(K14="X",(D14-C14),"0") -> 0
E44: =IF(E15="X",(D15-C15),"0") -> 0 | F44: =IF(F15="X",(D15-C15),"0") -> 1.56 | G44: =IF(G15="X",(D15-C15),"0") -> 0 | H44: =IF(H15="X",(D15-C15),"0") -> 0 | I44: =IF(I15="X",(D15-C15),"0") -> 0 | J44: =IF(J15="X",(D15-C15),"0") -> 0 | K44: =IF(K15="X",(D15-C15),"0") -> 1.56
E45: =IF(E16="X",(D16-C16),"0") -> 0 | F45: =IF(F16="X",(D16-C16),"0") -> 0 | G45: =IF(G16="X",(D16-C16),"0") -> 0 | H45: =IF(H16="X",(D16-C16),"0") -> 0 | I45: =IF(I16="X",(D16-C16),"0") -> 0 | J45: =IF(J16="X",(D16-C16),"0") -> 0 | K45: =IF(K16="X",(D16-C16),"0") -> 0
E46: =IF(E17="X",(D17-C17),"0") -> 0 | F46: =IF(F17="X",(D17-C17),"0") -> 0 | G46: =IF(G17="X",(D17-C17),"0") -> 0 | H46: =IF(H17="X",(D17-C17),"0") -> 0 | I46: =IF(I17="X",(D17-C17),"0") -> 0 | J46: =IF(J17="X",(D17-C17),"0") -> 0 | K46: =IF(K17="X",(D17-C17),"0") -> 0
E47: =IF(E18="X",(D18-C18),"0") -> 0 | F47: =IF(F18="X",(D18-C18),"0") -> 0 | G47: =IF(G18="X",(D18-C18),"0") -> 0 | H47: =IF(H18="X",(D18-C18),"0") -> 0 | I47: =IF(I18="X",(D18-C18),"0") -> 0 | J47: =IF(J18="X",(D18-C18),"0") -> 0 | K47: =IF(K18="X",(D18-C18),"0") -> 0
... E61: =IF(E32="X",(D32-C32),"0") -> 0 | F61: =IF(F32="X",(D32-C32),"0") -> 0 | G61: =IF(G32="X",(D32-C32),"0") -> 0 | H61: =IF(H32="X",(D32-C32),"0") -> 0 | I61: =IF(I32="X",(D32-C32),"0") -> 0 | J61: =IF(J32="X",(D32-C32),"0") -> 0 | K61: =IF(K32="X",(D32-C32),"0") -> 0
E62: =SUM(E36:E61) -> 15.2 | F62: =SUM(F36:F61) -> 32.06 | G62: =SUM(G36:G61) -> 0 | H62: =SUM(H36:H61) -> 3.5 | I62: =SUM(I36:I61) -> 0 | J62: =SUM(J36:J61) -> 30.2 | K62: =SUM(K36:K61) -> 7.26

Sheet 261
A1: PROGRAMA DE MANUTENÇÃORODOVIÁRIA | I1: DATA: | J1: ='245'!J1 -> 46204 | L1: TÉCNICO RESP. | N1: ='245'!N1 -> ENG. THIAGO TORQUATO
F2: RODOVIAS NÃO PAVIMENTADAS
A3: FICHA DE INSPEÇÃO: | B3: =TT!C6 -> RODOVIA TO-296 - TRECHO ENTR. BR-242 (POVOADO SÃO BOM JESUS DAS PALMAS) - ENTR. TO-050 | I3: REGIÃO: | J3: 13
A5: S.R.E. | B5: SENTIDO | C5: INÍCIO (KM) | D5: FIM (KM) | E5: CONDIÇÃO DA PLATAFORMA | I5: DRENAGEM SUPERFICIAL | L5: OBSERV.
E6: BOM | F6: REG. (ATÉ 10 IRR./KM) | G6: RUÍM (+ 10 IRR./KM) | H6: PÉSSIMA (ATOLEIRO/PTO. CRÍTICO) | I6: LIMPA | J6: OBSTRUÍDA | K6: AUSENTE
A7: 296ETO0170 | B7: D | C7: 0 | D7: 21.6 | F7: X | I7: X
A8: 296ETO0170 | C8: 21.6 | D8: 38.4 | F8: X | J8: X
A9: 296ETO0170 | C9: 38.4 | D9: 50.62 | F9: X | J9: X
E36: =IF(E7="X",(D7-C7),"0") -> 0 | F36: =IF(F7="X",(D7-C7),"0") -> 21.6 | G36: =IF(G7="X",(D7-C7),"0") -> 0 | H36: =IF(H7="X",(D7-C7),"0") -> 0 | I36: =IF(I7="X",(D7-C7),"0") -> 21.6 | J36: =IF(J7="X",(D7-C7),"0") -> 0 | K36: =IF(K7="X",(D7-C7),"0") -> 0
E37: =IF(E8="X",(D8-C8),"0") -> 0 | F37: =IF(F8="X",(D8-C8),"0") -> 16.8 | G37: =IF(G8="X",(D8-C8),"0") -> 0 | H37: =IF(H8="X",(D8-C8),"0") -> 0 | I37: =IF(I8="X",(D8-C8),"0") -> 0 | J37: =IF(J8="X",(D8-C8),"0") -> 16.8 | K37: =IF(K8="X",(D8-C8),"0") -> 0
E38: =IF(E9="X",(D9-C9),"0") -> 0 | F38: =IF(F9="X",(D9-C9),"0") -> 12.22 | G38: =IF(G9="X",(D9-C9),"0") -> 0 | H38: =IF(H9="X",(D9-C9),"0") -> 0 | I38: =IF(I9="X",(D9-C9),"0") -> 0 | J38: =IF(J9="X",(D9-C9),"0") -> 12.22 | K38: =IF(K9="X",(D9-C9),"0") -> 0
E39: =IF(E10="X",(D10-C10),"0") -> 0 | F39: =IF(F10="X",(D10-C10),"0") -> 0 | G39: =IF(G10="X",(D10-C10),"0") -> 0 | H39: =IF(H10="X",(D10-C10),"0") -> 0 | I39: =IF(I10="X",(D10-C10),"0") -> 0 | J39: =IF(J10="X",(D10-C10),"0") -> 0 | K39: =IF(K10="X",(D10-C10),"0") -> 0
E40: =IF(E11="X",(D11-C11),"0") -> 0 | F40: =IF(F11="X",(D11-C11),"0") -> 0 | G40: =IF(G11="X",(D11-C11),"0") -> 0 | H40: =IF(H11="X",(D11-C11),"0") -> 0 | I40: =IF(I11="X",(D11-C11),"0") -> 0 | J40: =IF(J11="X",(D11-C11),"0") -> 0 | K40: =IF(K11="X",(D11-C11),"0") -> 0
E41: =IF(E12="X",(D12-C12),"0") -> 0 | F41: =IF(F12="X",(D12-C12),"0") -> 0 | G41: =IF(G12="X",(D12-C12),"0") -> 0 | H41: =IF(H12="X",(D12-C12),"0") -> 0 | I41: =IF(I12="X",(D12-C12),"0") -> 0 | J41: =IF(J12="X",(D12-C12),"0") -> 0 | K41: =IF(K12="X",(D12-C12),"0") -> 0
E42: =IF(E13="X",(D13-C13),"0") -> 0 | F42: =IF(F13="X",(D13-C13),"0") -> 0 | G42: =IF(G13="X",(D13-C13),"0") -> 0 | H42: =IF(H13="X",(D13-C13),"0") -> 0 | I42: =IF(I13="X",(D13-C13),"0") -> 0 | J42: =IF(J13="X",(D13-C13),"0") -> 0 | K42: =IF(K13="X",(D13-C13),"0") -> 0
E43: =IF(E14="X",(D14-C14),"0") -> 0 | F43: =IF(F14="X",(D14-C14),"0") -> 0 | G43: =IF(G14="X",(D14-C14),"0") -> 0 | H43: =IF(H14="X",(D14-C14),"0") -> 0 | I43: =IF(I14="X",(D14-C14),"0") -> 0 | J43: =IF(J14="X",(D14-C14),"0") -> 0 | K43: =IF(K14="X",(D14-C14),"0") -> 0
E44: =IF(E15="X",(D15-C15),"0") -> 0 | F44: =IF(F15="X",(D15-C15),"0") -> 0 | G44: =IF(G15="X",(D15-C15),"0") -> 0 | H44: =IF(H15="X",(D15-C15),"0") -> 0 | I44: =IF(I15="X",(D15-C15),"0") -> 0 | J44: =IF(J15="X",(D15-C15),"0") -> 0 | K44: =IF(K15="X",(D15-C15),"0") -> 0
E45: =IF(E16="X",(D16-C16),"0") -> 0 | F45: =IF(F16="X",(D16-C16),"0") -> 0 | G45: =IF(G16="X",(D16-C16),"0") -> 0 | H45: =IF(H16="X",(D16-C16),"0") -> 0 | I45: =IF(I16="X",(D16-C16),"0") -> 0 | J45: =IF(J16="X",(D16-C16),"0") -> 0 | K45: =IF(K16="X",(D16-C16),"0") -> 0
E46: =IF(E17="X",(D17-C17),"0") -> 0 | F46: =IF(F17="X",(D17-C17),"0") -> 0 | G46: =IF(G17="X",(D17-C17),"0") -> 0 | H46: =IF(H17="X",(D17-C17),"0") -> 0 | I46: =IF(I17="X",(D17-C17),"0") -> 0 | J46: =IF(J17="X",(D17-C17),"0") -> 0 | K46: =IF(K17="X",(D17-C17),"0") -> 0
E47: =IF(E18="X",(D18-C18),"0") -> 0 | F47: =IF(F18="X",(D18-C18),"0") -> 0 | G47: =IF(G18="X",(D18-C18),"0") -> 0 | H47: =IF(H18="X",(D18-C18),"0") -> 0 | I47: =IF(I18="X",(D18-C18),"0") -> 0 | J47: =IF(J18="X",(D18-C18),"0") -> 0 | K47: =IF(K18="X",(D18-C18),"0") -> 0
... E61: =IF(E32="X",(D32-C32),"0") -> 0 | F61: =IF(F32="X",(D32-C32),"0") -> 0 | G61: =IF(G32="X",(D32-C32),"0") -> 0 | H61: =IF(H32="X",(D32-C32),"0") -> 0 | I61: =IF(I32="X",(D32-C32),"0") -> 0 | J61: =IF(J32="X",(D32-C32),"0") -> 0 | K61: =IF(K32="X",(D32-C32),"0") -> 0
E62: =SUM(E36:E61) -> 0 | F62: =SUM(F36:F61) -> 50.62 | G62: =SUM(G36:G61) -> 0 | H62: =SUM(H36:H61) -> 0 | I62: =SUM(I36:I61) -> 21.6 | J62: =SUM(J36:J61) -> 29.02 | K62: =SUM(K36:K61) -> 0

Sheet 262
A1: PROGRAMA DE MANUTENÇÃORODOVIÁRIA | I1: DATA: | J1: ='245'!J1 -> 46204 | L1: TÉCNICO RESP. | N1: ='245'!N1 -> ENG. THIAGO TORQUATO
F2: RODOVIAS NÃO PAVIMENTADAS
A3: FICHA DE INSPEÇÃO: | B3: =TT!C7 -> RODOVIA TO-369 - TRECHO ENTR. TO-040 - ENTR. TO-476 (FUNIL - RIO SONINHO) | I3: REGIÃO: | J3: 13
A5: S.R.E. | B5: SENTIDO | C5: INÍCIO (KM) | D5: FIM (KM) | E5: CONDIÇÃO DA PLATAFORMA | I5: DRENAGEM SUPERFICIAL | L5: OBSERV.
E6: BOM | F6: REG. (ATÉ 10 IRR./KM) | G6: RUÍM (+ 10 IRR./KM) | H6: PÉSSIMA (ATOLEIRO/PTO. CRÍTICO) | I6: LIMPA | J6: OBSTRUÍDA | K6: AUSENTE
A7: 369ETO0100 | B7: C | C7: 0 | D7: 8.2 | F7: X | I7: X
A8: 369ETO0100 | C8: 8.2 | D8: 17.3 | F8: X | I8: X
A9: 369ETO0100 | C9: 17.3 | D9: 23.95 | F9: X | J9: X
E36: =IF(E7="X",(D7-C7),"0") -> 0 | F36: =IF(F7="X",(D7-C7),"0") -> 8.2 | G36: =IF(G7="X",(D7-C7),"0") -> 0 | H36: =IF(H7="X",(D7-C7),"0") -> 0 | I36: =IF(I7="X",(D7-C7),"0") -> 8.2 | J36: =IF(J7="X",(D7-C7),"0") -> 0 | K36: =IF(K7="X",(D7-C7),"0") -> 0
E37: =IF(E8="X",(D8-C8),"0") -> 0 | F37: =IF(F8="X",(D8-C8),"0") -> 9.1 | G37: =IF(G8="X",(D8-C8),"0") -> 0 | H37: =IF(H8="X",(D8-C8),"0") -> 0 | I37: =IF(I8="X",(D8-C8),"0") -> 9.1 | J37: =IF(J8="X",(D8-C8),"0") -> 0 | K37: =IF(K8="X",(D8-C8),"0") -> 0
E38: =IF(E9="X",(D9-C9),"0") -> 0 | F38: =IF(F9="X",(D9-C9),"0") -> 6.65 | G38: =IF(G9="X",(D9-C9),"0") -> 0 | H38: =IF(H9="X",(D9-C9),"0") -> 0 | I38: =IF(I9="X",(D9-C9),"0") -> 0 | J38: =IF(J9="X",(D9-C9),"0") -> 6.65 | K38: =IF(K9="X",(D9-C9),"0") -> 0
E39: =IF(E10="X",(D10-C10),"0") -> 0 | F39: =IF(F10="X",(D10-C10),"0") -> 0 | G39: =IF(G10="X",(D10-C10),"0") -> 0 | H39: =IF(H10="X",(D10-C10),"0") -> 0 | I39: =IF(I10="X",(D10-C10),"0") -> 0 | J39: =IF(J10="X",(D10-C10),"0") -> 0 | K39: =IF(K10="X",(D10-C10),"0") -> 0
E40: =IF(E11="X",(D11-C11),"0") -> 0 | F40: =IF(F11="X",(D11-C11),"0") -> 0 | G40: =IF(G11="X",(D11-C11),"0") -> 0 | H40: =IF(H11="X",(D11-C11),"0") -> 0 | I40: =IF(I11="X",(D11-C11),"0") -> 0 | J40: =IF(J11="X",(D11-C11),"0") -> 0 | K40: =IF(K11="X",(D11-C11),"0") -> 0
E41: =IF(E12="X",(D12-C12),"0") -> 0 | F41: =IF(F12="X",(D12-C12),"0") -> 0 | G41: =IF(G12="X",(D12-C12),"0") -> 0 | H41: =IF(H12="X",(D12-C12),"0") -> 0 | I41: =IF(I12="X",(D12-C12),"0") -> 0 | J41: =IF(J12="X",(D12-C12),"0") -> 0 | K41: =IF(K12="X",(D12-C12),"0") -> 0
E42: =IF(E13="X",(D13-C13),"0") -> 0 | F42: =IF(F13="X",(D13-C13),"0") -> 0 | G42: =IF(G13="X",(D13-C13),"0") -> 0 | H42: =IF(H13="X",(D13-C13),"0") -> 0 | I42: =IF(I13="X",(D13-C13),"0") -> 0 | J42: =IF(J13="X",(D13-C13),"0") -> 0 | K42: =IF(K13="X",(D13-C13),"0") -> 0
E43: =IF(E14="X",(D14-C14),"0") -> 0 | F43: =IF(F14="X",(D14-C14),"0") -> 0 | G43: =IF(G14="X",(D14-C14),"0") -> 0 | H43: =IF(H14="X",(D14-C14),"0") -> 0 | I43: =IF(I14="X",(D14-C14),"0") -> 0 | J43: =IF(J14="X",(D14-C14),"0") -> 0 | K43: =IF(K14="X",(D14-C14),"0") -> 0
E44: =IF(E15="X",(D15-C15),"0") -> 0 | F44: =IF(F15="X",(D15-C15),"0") -> 0 | G44: =IF(G15="X",(D15-C15),"0") -> 0 | H44: =IF(H15="X",(D15-C15),"0") -> 0 | I44: =IF(I15="X",(D15-C15),"0") -> 0 | J44: =IF(J15="X",(D15-C15),"0") -> 0 | K44: =IF(K15="X",(D15-C15),"0") -> 0
E45: =IF(E16="X",(D16-C16),"0") -> 0 | F45: =IF(F16="X",(D16-C16),"0") -> 0 | G45: =IF(G16="X",(D16-C16),"0") -> 0 | H45: =IF(H16="X",(D16-C16),"0") -> 0 | I45: =IF(I16="X",(D16-C16),"0") -> 0 | J45: =IF(J16="X",(D16-C16),"0") -> 0 | K45: =IF(K16="X",(D16-C16),"0") -> 0
E46: =IF(E17="X",(D17-C17),"0") -> 0 | F46: =IF(F17="X",(D17-C17),"0") -> 0 | G46: =IF(G17="X",(D17-C17),"0") -> 0 | H46: =IF(H17="X",(D17-C17),"0") -> 0 | I46: =IF(I17="X",(D17-C17),"0") -> 0 | J46: =IF(J17="X",(D17-C17),"0") -> 0 | K46: =IF(K17="X",(D17-C17),"0") -> 0
E47: =IF(E18="X",(D18-C18),"0") -> 0 | F47: =IF(F18="X",(D18-C18),"0") -> 0 | G47: =IF(G18="X",(D18-C18),"0") -> 0 | H47: =IF(H18="X",(D18-C18),"0") -> 0 | I47: =IF(I18="X",(D18-C18),"0") -> 0 | J47: =IF(J18="X",(D18-C18),"0") -> 0 | K47: =IF(K18="X",(D18-C18),"0") -> 0
... E61: =IF(E32="X",(D32-C32),"0") -> 0 | F61: =IF(F32="X",(D32-C32),"0") -> 0 | G61: =IF(G32="X",(D32-C32),"0") -> 0 | H61: =IF(H32="X",(D32-C32),"0") -> 0 | I61: =IF(I32="X",(D32-C32),"0") -> 0 | J61: =IF(J32="X",(D32-C32),"0") -> 0 | K61: =IF(K32="X",(D32-C32),"0") -> 0
E62: =SUM(E36:E61) -> 0 | F62: =SUM(F36:F61) -> 23.95 | G62: =SUM(G36:G61) -> 0 | H62: =SUM(H36:H61) -> 0 | I62: =SUM(I36:I61) -> 17.3 | J62: =SUM(J36:J61) -> 6.65 | K62: =SUM(K36:K61) -> 0

Sheet 263
A1: PROGRAMA DE MANUTENÇÃORODOVIÁRIA | I1: DATA: | J1: ='245'!J1 -> 46204 | L1: TÉCNICO RESP. | N1: ='245'!N1 -> ENG. THIAGO TORQUATO
F2: RODOVIAS NÃO PAVIMENTADAS
A3: FICHA DE INSPEÇÃO: | B3: =TT!C8 -> RODOVIA TO-387 - TRECHO CONCEIÇÃO DO TOCANTINS - TAIPAS DO TOCANTINS | I3: REGIÃO: | J3: 13
A5: S.R.E. | B5: SENTIDO | C5: INÍCIO (KM) | D5: FIM (KM) | E5: CONDIÇÃO DA PLATAFORMA | I5: DRENAGEM SUPERFICIAL | L5: OBSERV.
E6: BOM | F6: REG. (ATÉ 10 IRR./KM) | G6: RUÍM (+ 10 IRR./KM) | H6: PÉSSIMA (ATOLEIRO/PTO. CRÍTICO) | I6: LIMPA | J6: OBSTRUÍDA | K6: AUSENTE
A7: 477ETO0020 | B7: D | C7: 0 | D7: 15 | E7: X | I7: X
A8: 477ETO0020 | C8: 15 | D8: 22.1 | E8: X | J8: X
A9: 477ETO0020 | C9: 22.1 | D9: 34 | E9: X | I9: X
A10: 477ETO0020 | C10: 34 | D10: 39.5 | E10: X | I10: X
E37: =IF(E7="X",(D7-C7),"0") -> 15 | F37: =IF(F7="X",(D7-C7),"0") -> 0 | G37: =IF(G7="X",(D7-C7),"0") -> 0 | H37: =IF(H7="X",(D7-C7),"0") -> 0 | I37: =IF(I7="X",(D7-C7),"0") -> 15 | J37: =IF(J7="X",(D7-C7),"0") -> 0 | K37: =IF(K7="X",(D7-C7),"0") -> 0
E38: =IF(E8="X",(D8-C8),"0") -> 7.1 | F38: =IF(F8="X",(D8-C8),"0") -> 0 | G38: =IF(G8="X",(D8-C8),"0") -> 0 | H38: =IF(H8="X",(D8-C8),"0") -> 0 | I38: =IF(I8="X",(D8-C8),"0") -> 0 | J38: =IF(J8="X",(D8-C8),"0") -> 7.1 | K38: =IF(K8="X",(D8-C8),"0") -> 0
E39: =IF(E9="X",(D9-C9),"0") -> 11.9 | F39: =IF(F9="X",(D9-C9),"0") -> 0 | G39: =IF(G9="X",(D9-C9),"0") -> 0 | H39: =IF(H9="X",(D9-C9),"0") -> 0 | I39: =IF(I9="X",(D9-C9),"0") -> 11.9 | J39: =IF(J9="X",(D9-C9),"0") -> 0 | K39: =IF(K9="X",(D9-C9),"0") -> 0
E40: =IF(E10="X",(D10-C10),"0") -> 5.5 | F40: =IF(F10="X",(D10-C10),"0") -> 0 | G40: =IF(G10="X",(D10-C10),"0") -> 0 | H40: =IF(H10="X",(D10-C10),"0") -> 0 | I40: =IF(I10="X",(D10-C10),"0") -> 5.5 | J40: =IF(J10="X",(D10-C10),"0") -> 0 | K40: =IF(K10="X",(D10-C10),"0") -> 0
E41: =IF(E11="X",(D11-C11),"0") -> 0 | F41: =IF(F11="X",(D11-C11),"0") -> 0 | G41: =IF(G11="X",(D11-C11),"0") -> 0 | H41: =IF(H11="X",(D11-C11),"0") -> 0 | I41: =IF(I11="X",(D11-C11),"0") -> 0 | J41: =IF(J11="X",(D11-C11),"0") -> 0 | K41: =IF(K11="X",(D11-C11),"0") -> 0
E42: =IF(E12="X",(D12-C12),"0") -> 0 | F42: =IF(F12="X",(D12-C12),"0") -> 0 | G42: =IF(G12="X",(D12-C12),"0") -> 0 | H42: =IF(H12="X",(D12-C12),"0") -> 0 | I42: =IF(I12="X",(D12-C12),"0") -> 0 | J42: =IF(J12="X",(D12-C12),"0") -> 0 | K42: =IF(K12="X",(D12-C12),"0") -> 0
E43: =IF(E13="X",(D13-C13),"0") -> 0 | F43: =IF(F13="X",(D13-C13),"0") -> 0 | G43: =IF(G13="X",(D13-C13),"0") -> 0 | H43: =IF(H13="X",(D13-C13),"0") -> 0 | I43: =IF(I13="X",(D13-C13),"0") -> 0 | J43: =IF(J13="X",(D13-C13),"0") -> 0 | K43: =IF(K13="X",(D13-C13),"0") -> 0
E44: =IF(E14="X",(D14-C14),"0") -> 0 | F44: =IF(F14="X",(D14-C14),"0") -> 0 | G44: =IF(G14="X",(D14-C14),"0") -> 0 | H44: =IF(H14="X",(D14-C14),"0") -> 0 | I44: =IF(I14="X",(D14-C14),"0") -> 0 | J44: =IF(J14="X",(D14-C14),"0") -> 0 | K44: =IF(K14="X",(D14-C14),"0") -> 0
E45: =IF(E15="X",(D15-C15),"0") -> 0 | F45: =IF(F15="X",(D15-C15),"0") -> 0 | G45: =IF(G15="X",(D15-C15),"0") -> 0 | H45: =IF(H15="X",(D15-C15),"0") -> 0 | I45: =IF(I15="X",(D15-C15),"0") -> 0 | J45: =IF(J15="X",(D15-C15),"0") -> 0 | K45: =IF(K15="X",(D15-C15),"0") -> 0
E46: =IF(E16="X",(D16-C16),"0") -> 0 | F46: =IF(F16="X",(D16-C16),"0") -> 0 | G46: =IF(G16="X",(D16-C16),"0") -> 0 | H46: =IF(H16="X",(D16-C16),"0") -> 0 | I46: =IF(I16="X",(D16-C16),"0") -> 0 | J46: =IF(J16="X",(D16-C16),"0") -> 0 | K46: =IF(K16="X",(D16-C16),"0") -> 0
E47: =IF(E17="X",(D17-C17),"0") -> 0 | F47: =IF(F17="X",(D17-C17),"0") -> 0 | G47: =IF(G17="X",(D17-C17),"0") -> 0 | H47: =IF(H17="X",(D17-C17),"0") -> 0 | I47: =IF(I17="X",(D17-C17),"0") -> 0 | J47: =IF(J17="X",(D17-C17),"0") -> 0 | K47: =IF(K17="X",(D17-C17),"0") -> 0
E48: =IF(E18="X",(D18-C18),"0") -> 0 | F48: =IF(F18="X",(D18-C18),"0") -> 0 | G48: =IF(G18="X",(D18-C18),"0") -> 0 | H48: =IF(H18="X",(D18-C18),"0") -> 0 | I48: =IF(I18="X",(D18-C18),"0") -> 0 | J48: =IF(J18="X",(D18-C18),"0") -> 0 | K48: =IF(K18="X",(D18-C18),"0") -> 0
... E62: =IF(E32="X",(D32-C32),"0") -> 0 | F62: =IF(F32="X",(D32-C32),"0") -> 0 | G62: =IF(G32="X",(D32-C32),"0") -> 0 | H62: =IF(H32="X",(D32-C32),"0") -> 0 | I62: =IF(I32="X",(D32-C32),"0") -> 0 | J62: =IF(J32="X",(D32-C32),"0") -> 0 | K62: =IF(K32="X",(D32-C32),"0") -> 0
E63: =SUM(E37:E62) -> 39.5 | F63: =SUM(F37:F62) -> 0 | G63: =SUM(G37:G62) -> 0 | H63: =SUM(H37:H62) -> 0 | I63: =SUM(I37:I62) -> 32.4 | J63: =SUM(J37:J62) -> 7.1 | K63: =SUM(K37:K62) -> 0

Sheet 264
A1: PROGRAMA DE MANUTENÇÃORODOVIÁRIA | I1: DATA: | J1: ='245'!J1 -> 46204 | L1: TÉCNICO RESP. | N1: ='245'!N1 -> ENG. THIAGO TORQUATO
F2: RODOVIAS NÃO PAVIMENTADAS
A3: FICHA DE INSPEÇÃO: | B3: =TT!C9 -> RODOVIA TO-387 - TRECHO ENTR. BR-010 - ENTR. TO-050 (CONCEIÇÃO DO TOCANTINS) | I3: REGIÃO: | J3: 13
A5: S.R.E. | B5: SENTIDO | C5: INÍCIO (KM) | D5: FIM (KM) | E5: CONDIÇÃO DA PLATAFORMA | I5: DRENAGEM SUPERFICIAL | L5: OBSERV.
E6: BOM | F6: REG. (ATÉ 10 IRR./KM) | G6: RUÍM (+ 10 IRR./KM) | H6: PÉSSIMA (ATOLEIRO/PTO. CRÍTICO) | I6: LIMPA | J6: OBSTRUÍDA | K6: AUSENTE
A7: 387ETO0100 | B7: C | C7: 0 | D7: 9.1 | E7: X | J7: X
A8: 387ETO0100 | C8: =D7 -> 9.1 | D8: 9.9 | E8: X | J8: X
A9: 387ETO0100 | C9: =D8 -> 9.9 | D9: 11.9 | E9: X | J9: X
A10: 387ETO0100 | C10: =D9 -> 11.9 | D10: 13.2 | E10: X | J10: X
A11: 387ETO0100 | C11: =D10 -> 13.2 | D11: 14.3 | E11: X | J11: X
A12: 387ETO0100 | C12: =D11 -> 14.3 | D12: 18.3 | E12: X | J12: X
A13: 387ETO0100 | C13: =D12 -> 18.3 | D13: 20.6 | E13: X | J13: X
A14: 387ETO0100 | C14: =D13 -> 20.6 | D14: 23 | E14: X | J14: X
A15: 387ETO0100 | C15: =D14 -> 23 | D15: 25.1 | E15: X | J15: X
A16: 387ETO0100 | C16: =D15 -> 25.1 | D16: 23.4 | E16: X | J16: X
A17: 387ETO0100 | C17: =D16 -> 23.4 | D17: 28.8 | F17: X | J17: X
A18: 387ETO0100 | C18: =D17 -> 28.8 | D18: 30.1 | F18: X | J18: X
A19: 387ETO0100 | C19: =D18 -> 30.1 | D19: 33.6 | F19: X | J19: X
A20: 387ETO0100 | C20: =D19 -> 33.6 | D20: 36.2 | F20: X | J20: X
A21: 387ETO0100 | C21: =D20 -> 36.2 | D21: 38.8 | F21: X | J21: X
A22: 387ETO0100 | C22: =D21 -> 38.8 | D22: 41.8 | F22: X | J22: X
A23: 387ETO0100 | C23: =D22 -> 41.8 | D23: 42.46 | F23: X | J23: X
E37: =IF(E7="X",(D7-C7),"0") -> 9.1 | F37: =IF(F7="X",(D7-C7),"0") -> 0 | G37: =IF(G7="X",(D7-C7),"0") -> 0 | H37: =IF(H7="X",(D7-C7),"0") -> 0 | I37: =IF(I7="X",(D7-C7),"0") -> 0 | J37: =IF(J7="X",(D7-C7),"0") -> 9.1 | K37: =IF(K7="X",(D7-C7),"0") -> 0
E38: =IF(E8="X",(D8-C8),"0") -> 0.8 | F38: =IF(F8="X",(D8-C8),"0") -> 0 | G38: =IF(G8="X",(D8-C8),"0") -> 0 | H38: =IF(H8="X",(D8-C8),"0") -> 0 | I38: =IF(I8="X",(D8-C8),"0") -> 0 | J38: =IF(J8="X",(D8-C8),"0") -> 0.8 | K38: =IF(K8="X",(D8-C8),"0") -> 0
E39: =IF(E9="X",(D9-C9),"0") -> 2 | F39: =IF(F9="X",(D9-C9),"0") -> 0 | G39: =IF(G9="X",(D9-C9),"0") -> 0 | H39: =IF(H9="X",(D9-C9),"0") -> 0 | I39: =IF(I9="X",(D9-C9),"0") -> 0 | J39: =IF(J9="X",(D9-C9),"0") -> 2 | K39: =IF(K9="X",(D9-C9),"0") -> 0
E40: =IF(E10="X",(D10-C10),"0") -> 1.3 | F40: =IF(F10="X",(D10-C10),"0") -> 0 | G40: =IF(G10="X",(D10-C10),"0") -> 0 | H40: =IF(H10="X",(D10-C10),"0") -> 0 | I40: =IF(I10="X",(D10-C10),"0") -> 0 | J40: =IF(J10="X",(D10-C10),"0") -> 1.3 | K40: =IF(K10="X",(D10-C10),"0") -> 0
E41: =IF(E11="X",(D11-C11),"0") -> 1.1 | F41: =IF(F11="X",(D11-C11),"0") -> 0 | G41: =IF(G11="X",(D11-C11),"0") -> 0 | H41: =IF(H11="X",(D11-C11),"0") -> 0 | I41: =IF(I11="X",(D11-C11),"0") -> 0 | J41: =IF(J11="X",(D11-C11),"0") -> 1.1 | K41: =IF(K11="X",(D11-C11),"0") -> 0
E42: =IF(E12="X",(D12-C12),"0") -> 4 | F42: =IF(F12="X",(D12-C12),"0") -> 0 | G42: =IF(G12="X",(D12-C12),"0") -> 0 | H42: =IF(H12="X",(D12-C12),"0") -> 0 | I42: =IF(I12="X",(D12-C12),"0") -> 0 | J42: =IF(J12="X",(D12-C12),"0") -> 4 | K42: =IF(K12="X",(D12-C12),"0") -> 0
E43: =IF(E13="X",(D13-C13),"0") -> 2.3 | F43: =IF(F13="X",(D13-C13),"0") -> 0 | G43: =IF(G13="X",(D13-C13),"0") -> 0 | H43: =IF(H13="X",(D13-C13),"0") -> 0 | I43: =IF(I13="X",(D13-C13),"0") -> 0 | J43: =IF(J13="X",(D13-C13),"0") -> 2.3 | K43: =IF(K13="X",(D13-C13),"0") -> 0
E44: =IF(E14="X",(D14-C14),"0") -> 2.4 | F44: =IF(F14="X",(D14-C14),"0") -> 0 | G44: =IF(G14="X",(D14-C14),"0") -> 0 | H44: =IF(H14="X",(D14-C14),"0") -> 0 | I44: =IF(I14="X",(D14-C14),"0") -> 0 | J44: =IF(J14="X",(D14-C14),"0") -> 2.4 | K44: =IF(K14="X",(D14-C14),"0") -> 0
E45: =IF(E15="X",(D15-C15),"0") -> 2.1 | F45: =IF(F15="X",(D15-C15),"0") -> 0 | G45: =IF(G15="X",(D15-C15),"0") -> 0 | H45: =IF(H15="X",(D15-C15),"0") -> 0 | I45: =IF(I15="X",(D15-C15),"0") -> 0 | J45: =IF(J15="X",(D15-C15),"0") -> 2.1 | K45: =IF(K15="X",(D15-C15),"0") -> 0
E46: =IF(E16="X",(D16-C16),"0") -> -1.7 | F46: =IF(F16="X",(D16-C16),"0") -> 0 | G46: =IF(G16="X",(D16-C16),"0") -> 0 | H46: =IF(H16="X",(D16-C16),"0") -> 0 | I46: =IF(I16="X",(D16-C16),"0") -> 0 | J46: =IF(J16="X",(D16-C16),"0") -> -1.7 | K46: =IF(K16="X",(D16-C16),"0") -> 0
E47: =IF(E17="X",(D17-C17),"0") -> 0 | F47: =IF(F17="X",(D17-C17),"0") -> 5.4 | G47: =IF(G17="X",(D17-C17),"0") -> 0 | H47: =IF(H17="X",(D17-C17),"0") -> 0 | I47: =IF(I17="X",(D17-C17),"0") -> 0 | J47: =IF(J17="X",(D17-C17),"0") -> 5.4 | K47: =IF(K17="X",(D17-C17),"0") -> 0
E48: =IF(E18="X",(D18-C18),"0") -> 0 | F48: =IF(F18="X",(D18-C18),"0") -> 1.3 | G48: =IF(G18="X",(D18-C18),"0") -> 0 | H48: =IF(H18="X",(D18-C18),"0") -> 0 | I48: =IF(I18="X",(D18-C18),"0") -> 0 | J48: =IF(J18="X",(D18-C18),"0") -> 1.3 | K48: =IF(K18="X",(D18-C18),"0") -> 0
... E62: =IF(E32="X",(D32-C32),"0") -> 0 | F62: =IF(F32="X",(D32-C32),"0") -> 0 | G62: =IF(G32="X",(D32-C32),"0") -> 0 | H62: =IF(H32="X",(D32-C32),"0") -> 0 | I62: =IF(I32="X",(D32-C32),"0") -> 0 | J62: =IF(J32="X",(D32-C32),"0") -> 0 | K62: =IF(K32="X",(D32-C32),"0") -> 0
E63: =SUM(E37:E62) -> 23.4 | F63: =SUM(F37:F62) -> 19.06 | G63: =SUM(G37:G62) -> 0 | H63: =SUM(H37:H62) -> 0 | I63: =SUM(I37:I62) -> 0 | J63: =SUM(J37:J62) -> 42.46 | K63: =SUM(K37:K62) -> 0

Sheet 265
A1: PROGRAMA DE MANUTENÇÃORODOVIÁRIA | I1: DATA: | J1: ='245'!J1 -> 46204 | L1: TÉCNICO RESP. | N1: ='245'!N1 -> ENG. THIAGO TORQUATO
F2: RODOVIAS NÃO PAVIMENTADAS
A3: FICHA DE INSPEÇÃO: | B3: =TT!C10 -> RODOVIA TO-387 - TRECHO ENTR. TO-040 - TAIPAS DO TOCANTINS | I3: REGIÃO: | J3: 13
A5: S.R.E. | B5: SENTIDO | C5: INÍCIO (KM) | D5: FIM (KM) | E5: CONDIÇÃO DA PLATAFORMA | I5: DRENAGEM SUPERFICIAL | L5: OBSERV.
E6: BOM | F6: REG. (ATÉ 10 IRR./KM) | G6: RUÍM (+ 10 IRR./KM) | H6: PÉSSIMA (ATOLEIRO/PTO. CRÍTICO) | I6: LIMPA | J6: OBSTRUÍDA | K6: AUSENTE
A7: 387ETO0040 | B7: D | C7: 0 | D7: 24.3 | E7: X | I7: X
A8: 387ETO0040 | C8: =D7 -> 24.3 | D8: 63.3 | E8: X | I8: X
A9: 387ETO0040 | C9: =D8 -> 63.3 | D9: 67.82 | E9: X | I9: X
E77: =IF(E7="X",(D7-C7),"0") -> 24.3 | F77: =IF(F7="X",(D7-C7),"0") -> 0 | G77: =IF(G7="X",(D7-C7),"0") -> 0 | H77: =IF(H7="X",(D7-C7),"0") -> 0 | I77: =IF(I7="X",(D7-C7),"0") -> 24.3 | J77: =IF(J7="X",(D7-C7),"0") -> 0 | K77: =IF(K7="X",(D7-C7),"0") -> 0
E78: =IF(E8="X",(D8-C8),"0") -> 39 | F78: =IF(F8="X",(D8-C8),"0") -> 0 | G78: =IF(G8="X",(D8-C8),"0") -> 0 | H78: =IF(H8="X",(D8-C8),"0") -> 0 | I78: =IF(I8="X",(D8-C8),"0") -> 39 | J78: =IF(J8="X",(D8-C8),"0") -> 0 | K78: =IF(K8="X",(D8-C8),"0") -> 0
E79: =IF(E9="X",(D9-C9),"0") -> 4.52 | F79: =IF(F9="X",(D9-C9),"0") -> 0 | G79: =IF(G9="X",(D9-C9),"0") -> 0 | H79: =IF(H9="X",(D9-C9),"0") -> 0 | I79: =IF(I9="X",(D9-C9),"0") -> 4.52 | J79: =IF(J9="X",(D9-C9),"0") -> 0 | K79: =IF(K9="X",(D9-C9),"0") -> 0
E80: =IF(E10="X",(D10-C10),"0") -> 0 | F80: =IF(F10="X",(D10-C10),"0") -> 0 | G80: =IF(G10="X",(D10-C10),"0") -> 0 | H80: =IF(H10="X",(D10-C10),"0") -> 0 | I80: =IF(I10="X",(D10-C10),"0") -> 0 | J80: =IF(J10="X",(D10-C10),"0") -> 0 | K80: =IF(K10="X",(D10-C10),"0") -> 0
E81: =IF(E11="X",(D11-C11),"0") -> 0 | F81: =IF(F11="X",(D11-C11),"0") -> 0 | G81: =IF(G11="X",(D11-C11),"0") -> 0 | H81: =IF(H11="X",(D11-C11),"0") -> 0 | I81: =IF(I11="X",(D11-C11),"0") -> 0 | J81: =IF(J11="X",(D11-C11),"0") -> 0 | K81: =IF(K11="X",(D11-C11),"0") -> 0
E82: =IF(E12="X",(D12-C12),"0") -> 0 | F82: =IF(F12="X",(D12-C12),"0") -> 0 | G82: =IF(G12="X",(D12-C12),"0") -> 0 | H82: =IF(H12="X",(D12-C12),"0") -> 0 | I82: =IF(I12="X",(D12-C12),"0") -> 0 | J82: =IF(J12="X",(D12-C12),"0") -> 0 | K82: =IF(K12="X",(D12-C12),"0") -> 0
E83: =IF(E13="X",(D13-C13),"0") -> 0 | F83: =IF(F13="X",(D13-C13),"0") -> 0 | G83: =IF(G13="X",(D13-C13),"0") -> 0 | H83: =IF(H13="X",(D13-C13),"0") -> 0 | I83: =IF(I13="X",(D13-C13),"0") -> 0 | J83: =IF(J13="X",(D13-C13),"0") -> 0 | K83: =IF(K13="X",(D13-C13),"0") -> 0
E84: =IF(E14="X",(D14-C14),"0") -> 0 | F84: =IF(F14="X",(D14-C14),"0") -> 0 | G84: =IF(G14="X",(D14-C14),"0") -> 0 | H84: =IF(H14="X",(D14-C14),"0") -> 0 | I84: =IF(I14="X",(D14-C14),"0") -> 0 | J84: =IF(J14="X",(D14-C14),"0") -> 0 | K84: =IF(K14="X",(D14-C14),"0") -> 0
E85: =IF(E15="X",(D15-C15),"0") -> 0 | F85: =IF(F15="X",(D15-C15),"0") -> 0 | G85: =IF(G15="X",(D15-C15),"0") -> 0 | H85: =IF(H15="X",(D15-C15),"0") -> 0 | I85: =IF(I15="X",(D15-C15),"0") -> 0 | J85: =IF(J15="X",(D15-C15),"0") -> 0 | K85: =IF(K15="X",(D15-C15),"0") -> 0
E86: =IF(E16="X",(D16-C16),"0") -> 0 | F86: =IF(F16="X",(D16-C16),"0") -> 0 | G86: =IF(G16="X",(D16-C16),"0") -> 0 | H86: =IF(H16="X",(D16-C16),"0") -> 0 | I86: =IF(I16="X",(D16-C16),"0") -> 0 | J86: =IF(J16="X",(D16-C16),"0") -> 0 | K86: =IF(K16="X",(D16-C16),"0") -> 0
E87: =IF(E17="X",(D17-C17),"0") -> 0 | F87: =IF(F17="X",(D17-C17),"0") -> 0 | G87: =IF(G17="X",(D17-C17),"0") -> 0 | H87: =IF(H17="X",(D17-C17),"0") -> 0 | I87: =IF(I17="X",(D17-C17),"0") -> 0 | J87: =IF(J17="X",(D17-C17),"0") -> 0 | K87: =IF(K17="X",(D17-C17),"0") -> 0
E88: =IF(E18="X",(D18-C18),"0") -> 0 | F88: =IF(F18="X",(D18-C18),"0") -> 0 | G88: =IF(G18="X",(D18-C18),"0") -> 0 | H88: =IF(H18="X",(D18-C18),"0") -> 0 | I88: =IF(I18="X",(D18-C18),"0") -> 0 | J88: =IF(J18="X",(D18-C18),"0") -> 0 | K88: =IF(K18="X",(D18-C18),"0") -> 0
... E128: =IF(E58="X",(D58-C58),"0") -> 0 | F128: =IF(F58="X",(D58-C58),"0") -> 0 | G128: =IF(G58="X",(D58-C58),"0") -> 0 | H128: =IF(H58="X",(D58-C58),"0") -> 0 | I128: =IF(I58="X",(D58-C58),"0") -> 0 | J128: =IF(J58="X",(D58-C58),"0") -> 0 | K128: =IF(K58="X",(D58-C58),"0") -> 0
E129: =SUM(E77:E128) -> 67.82 | F129: =SUM(F77:F128) -> 0 | G129: =SUM(G77:G128) -> 0 | H129: =SUM(H77:H128) -> 0 | I129: =SUM(I77:I128) -> 67.82 | J129: =SUM(J77:J128) -> 0 | K129: =SUM(K77:K128) -> 0

Sheet 267
A1: PROGRAMA DE MANUTENÇÃORODOVIÁRIA | I1: DATA: | J1: ='245'!J1 -> 46204 | L1: TÉCNICO RESP. | N1: ='245'!N1 -> ENG. THIAGO TORQUATO
F2: RODOVIAS NÃO PAVIMENTADAS
A3: FICHA DE INSPEÇÃO: | B3: =TT!C11 -> RODOVIA TO-476 - TRECHO RIO DA CONCEIÇÃO - ENTR. TO-477 | I3: REGIÃO: | J3: 13
A5: S.R.E. | B5: SENTIDO | C5: INÍCIO (KM) | D5: FIM (KM) | E5: CONDIÇÃO DA PLATAFORMA | I5: DRENAGEM SUPERFICIAL | L5: OBSERV.
E6: BOM | F6: REG. (ATÉ 10 IRR./KM) | G6: RUÍM (+ 10 IRR./KM) | H6: PÉSSIMA (ATOLEIRO/PTO. CRÍTICO) | I6: LIMPA | J6: OBSTRUÍDA | K6: AUSENTE
A7: 476ETO0030 | B7: D | C7: 0 | D7: 5.1 | E7: X | J7: X
A8: 476ETO0030 | C8: =D7 -> 5.1 | D8: 14.3 | F8: X | J8: X
E36: =IF(E7="X",(D7-C7),"0") -> 5.1 | F36: =IF(F7="X",(D7-C7),"0") -> 0 | G36: =IF(G7="X",(D7-C7),"0") -> 0 | H36: =IF(H7="X",(D7-C7),"0") -> 0 | I36: =IF(I7="X",(D7-C7),"0") -> 0 | J36: =IF(J7="X",(D7-C7),"0") -> 5.1 | K36: =IF(K7="X",(D7-C7),"0") -> 0
E37: =IF(E8="X",(D8-C8),"0") -> 0 | F37: =IF(F8="X",(D8-C8),"0") -> 9.2 | G37: =IF(G8="X",(D8-C8),"0") -> 0 | H37: =IF(H8="X",(D8-C8),"0") -> 0 | I37: =IF(I8="X",(D8-C8),"0") -> 0 | J37: =IF(J8="X",(D8-C8),"0") -> 9.2 | K37: =IF(K8="X",(D8-C8),"0") -> 0
E38: =IF(E9="X",(D9-C9),"0") -> 0 | F38: =IF(F9="X",(D9-C9),"0") -> 0 | G38: =IF(G9="X",(D9-C9),"0") -> 0 | H38: =IF(H9="X",(D9-C9),"0") -> 0 | I38: =IF(I9="X",(D9-C9),"0") -> 0 | J38: =IF(J9="X",(D9-C9),"0") -> 0 | K38: =IF(K9="X",(D9-C9),"0") -> 0
E39: =IF(E10="X",(D10-C10),"0") -> 0 | F39: =IF(F10="X",(D10-C10),"0") -> 0 | G39: =IF(G10="X",(D10-C10),"0") -> 0 | H39: =IF(H10="X",(D10-C10),"0") -> 0 | I39: =IF(I10="X",(D10-C10),"0") -> 0 | J39: =IF(J10="X",(D10-C10),"0") -> 0 | K39: =IF(K10="X",(D10-C10),"0") -> 0
E40: =IF(E11="X",(D11-C11),"0") -> 0 | F40: =IF(F11="X",(D11-C11),"0") -> 0 | G40: =IF(G11="X",(D11-C11),"0") -> 0 | H40: =IF(H11="X",(D11-C11),"0") -> 0 | I40: =IF(I11="X",(D11-C11),"0") -> 0 | J40: =IF(J11="X",(D11-C11),"0") -> 0 | K40: =IF(K11="X",(D11-C11),"0") -> 0
E41: =IF(E12="X",(D12-C12),"0") -> 0 | F41: =IF(F12="X",(D12-C12),"0") -> 0 | G41: =IF(G12="X",(D12-C12),"0") -> 0 | H41: =IF(H12="X",(D12-C12),"0") -> 0 | I41: =IF(I12="X",(D12-C12),"0") -> 0 | J41: =IF(J12="X",(D12-C12),"0") -> 0 | K41: =IF(K12="X",(D12-C12),"0") -> 0
E42: =IF(E13="X",(D13-C13),"0") -> 0 | F42: =IF(F13="X",(D13-C13),"0") -> 0 | G42: =IF(G13="X",(D13-C13),"0") -> 0 | H42: =IF(H13="X",(D13-C13),"0") -> 0 | I42: =IF(I13="X",(D13-C13),"0") -> 0 | J42: =IF(J13="X",(D13-C13),"0") -> 0 | K42: =IF(K13="X",(D13-C13),"0") -> 0
E43: =IF(E14="X",(D14-C14),"0") -> 0 | F43: =IF(F14="X",(D14-C14),"0") -> 0 | G43: =IF(G14="X",(D14-C14),"0") -> 0 | H43: =IF(H14="X",(D14-C14),"0") -> 0 | I43: =IF(I14="X",(D14-C14),"0") -> 0 | J43: =IF(J14="X",(D14-C14),"0") -> 0 | K43: =IF(K14="X",(D14-C14),"0") -> 0
E44: =IF(E15="X",(D15-C15),"0") -> 0 | F44: =IF(F15="X",(D15-C15),"0") -> 0 | G44: =IF(G15="X",(D15-C15),"0") -> 0 | H44: =IF(H15="X",(D15-C15),"0") -> 0 | I44: =IF(I15="X",(D15-C15),"0") -> 0 | J44: =IF(J15="X",(D15-C15),"0") -> 0 | K44: =IF(K15="X",(D15-C15),"0") -> 0
E45: =IF(E16="X",(D16-C16),"0") -> 0 | F45: =IF(F16="X",(D16-C16),"0") -> 0 | G45: =IF(G16="X",(D16-C16),"0") -> 0 | H45: =IF(H16="X",(D16-C16),"0") -> 0 | I45: =IF(I16="X",(D16-C16),"0") -> 0 | J45: =IF(J16="X",(D16-C16),"0") -> 0 | K45: =IF(K16="X",(D16-C16),"0") -> 0
E46: =IF(E17="X",(D17-C17),"0") -> 0 | F46: =IF(F17="X",(D17-C17),"0") -> 0 | G46: =IF(G17="X",(D17-C17),"0") -> 0 | H46: =IF(H17="X",(D17-C17),"0") -> 0 | I46: =IF(I17="X",(D17-C17),"0") -> 0 | J46: =IF(J17="X",(D17-C17),"0") -> 0 | K46: =IF(K17="X",(D17-C17),"0") -> 0
E47: =IF(E18="X",(D18-C18),"0") -> 0 | F47: =IF(F18="X",(D18-C18),"0") -> 0 | G47: =IF(G18="X",(D18-C18),"0") -> 0 | H47: =IF(H18="X",(D18-C18),"0") -> 0 | I47: =IF(I18="X",(D18-C18),"0") -> 0 | J47: =IF(J18="X",(D18-C18),"0") -> 0 | K47: =IF(K18="X",(D18-C18),"0") -> 0
... E61: =IF(E32="X",(D32-C32),"0") -> 0 | F61: =IF(F32="X",(D32-C32),"0") -> 0 | G61: =IF(G32="X",(D32-C32),"0") -> 0 | H61: =IF(H32="X",(D32-C32),"0") -> 0 | I61: =IF(I32="X",(D32-C32),"0") -> 0 | J61: =IF(J32="X",(D32-C32),"0") -> 0 | K61: =IF(K32="X",(D32-C32),"0") -> 0
E62: =SUM(E36:E61) -> 5.1 | F62: =SUM(F36:F61) -> 9.2 | G62: =SUM(G36:G61) -> 0 | H62: =SUM(H36:H61) -> 0 | I62: =SUM(I36:I61) -> 0 | J62: =SUM(J36:J61) -> 14.3 | K62: =SUM(K36:K61) -> 0

Sheet 268
A1: PROGRAMA DE MANUTENÇÃORODOVIÁRIA | I1: DATA: | J1: ='245'!J1 -> 46204 | L1: TÉCNICO RESP. | N1: ='245'!N1 -> ENG. THIAGO TORQUATO
F2: RODOVIAS NÃO PAVIMENTADAS
A3: FICHA DE INSPEÇÃO: | B3: =TT!C12 -> RODOVIA TO-477 - TRECHO ALMAS - ENTR. TO-476 | I3: REGIÃO: | J3: 13
A5: S.R.E. | B5: SENTIDO | C5: INÍCIO (KM) | D5: FIM (KM) | E5: CONDIÇÃO DA PLATAFORMA | I5: DRENAGEM SUPERFICIAL | L5: OBSERV.
E6: BOM | F6: REG. (ATÉ 10 IRR./KM) | G6: RUÍM (+ 10 IRR./KM) | H6: PÉSSIMA (ATOLEIRO/PTO. CRÍTICO) | I6: LIMPA | J6: OBSTRUÍDA | K6: AUSENTE
A7: 477ETO0020 | B7: C | C7: 0 | D7: 34.77 | F7: X | I7: X
E36: =IF(E7="X",(D7-C7),"0") -> 0 | F36: =IF(F7="X",(D7-C7),"0") -> 34.77 | G36: =IF(G7="X",(D7-C7),"0") -> 0 | H36: =IF(H7="X",(D7-C7),"0") -> 0 | I36: =IF(I7="X",(D7-C7),"0") -> 34.77 | J36: =IF(J7="X",(D7-C7),"0") -> 0 | K36: =IF(K7="X",(D7-C7),"0") -> 0
E37: =IF(E8="X",(D8-C8),"0") -> 0 | F37: =IF(F8="X",(D8-C8),"0") -> 0 | G37: =IF(G8="X",(D8-C8),"0") -> 0 | H37: =IF(H8="X",(D8-C8),"0") -> 0 | I37: =IF(I8="X",(D8-C8),"0") -> 0 | J37: =IF(J8="X",(D8-C8),"0") -> 0 | K37: =IF(K8="X",(D8-C8),"0") -> 0
E38: =IF(E9="X",(D9-C9),"0") -> 0 | F38: =IF(F9="X",(D9-C9),"0") -> 0 | G38: =IF(G9="X",(D9-C9),"0") -> 0 | H38: =IF(H9="X",(D9-C9),"0") -> 0 | I38: =IF(I9="X",(D9-C9),"0") -> 0 | J38: =IF(J9="X",(D9-C9),"0") -> 0 | K38: =IF(K9="X",(D9-C9),"0") -> 0
E39: =IF(E10="X",(D10-C10),"0") -> 0 | F39: =IF(F10="X",(D10-C10),"0") -> 0 | G39: =IF(G10="X",(D10-C10),"0") -> 0 | H39: =IF(H10="X",(D10-C10),"0") -> 0 | I39: =IF(I10="X",(D10-C10),"0") -> 0 | J39: =IF(J10="X",(D10-C10),"0") -> 0 | K39: =IF(K10="X",(D10-C10),"0") -> 0
E40: =IF(E11="X",(D11-C11),"0") -> 0 | F40: =IF(F11="X",(D11-C11),"0") -> 0 | G40: =IF(G11="X",(D11-C11),"0") -> 0 | H40: =IF(H11="X",(D11-C11),"0") -> 0 | I40: =IF(I11="X",(D11-C11),"0") -> 0 | J40: =IF(J11="X",(D11-C11),"0") -> 0 | K40: =IF(K11="X",(D11-C11),"0") -> 0
E41: =IF(E12="X",(D12-C12),"0") -> 0 | F41: =IF(F12="X",(D12-C12),"0") -> 0 | G41: =IF(G12="X",(D12-C12),"0") -> 0 | H41: =IF(H12="X",(D12-C12),"0") -> 0 | I41: =IF(I12="X",(D12-C12),"0") -> 0 | J41: =IF(J12="X",(D12-C12),"0") -> 0 | K41: =IF(K12="X",(D12-C12),"0") -> 0
E42: =IF(E13="X",(D13-C13),"0") -> 0 | F42: =IF(F13="X",(D13-C13),"0") -> 0 | G42: =IF(G13="X",(D13-C13),"0") -> 0 | H42: =IF(H13="X",(D13-C13),"0") -> 0 | I42: =IF(I13="X",(D13-C13),"0") -> 0 | J42: =IF(J13="X",(D13-C13),"0") -> 0 | K42: =IF(K13="X",(D13-C13),"0") -> 0
E43: =IF(E14="X",(D14-C14),"0") -> 0 | F43: =IF(F14="X",(D14-C14),"0") -> 0 | G43: =IF(G14="X",(D14-C14),"0") -> 0 | H43: =IF(H14="X",(D14-C14),"0") -> 0 | I43: =IF(I14="X",(D14-C14),"0") -> 0 | J43: =IF(J14="X",(D14-C14),"0") -> 0 | K43: =IF(K14="X",(D14-C14),"0") -> 0
E44: =IF(E15="X",(D15-C15),"0") -> 0 | F44: =IF(F15="X",(D15-C15),"0") -> 0 | G44: =IF(G15="X",(D15-C15),"0") -> 0 | H44: =IF(H15="X",(D15-C15),"0") -> 0 | I44: =IF(I15="X",(D15-C15),"0") -> 0 | J44: =IF(J15="X",(D15-C15),"0") -> 0 | K44: =IF(K15="X",(D15-C15),"0") -> 0
E45: =IF(E16="X",(D16-C16),"0") -> 0 | F45: =IF(F16="X",(D16-C16),"0") -> 0 | G45: =IF(G16="X",(D16-C16),"0") -> 0 | H45: =IF(H16="X",(D16-C16),"0") -> 0 | I45: =IF(I16="X",(D16-C16),"0") -> 0 | J45: =IF(J16="X",(D16-C16),"0") -> 0 | K45: =IF(K16="X",(D16-C16),"0") -> 0
E46: =IF(E17="X",(D17-C17),"0") -> 0 | F46: =IF(F17="X",(D17-C17),"0") -> 0 | G46: =IF(G17="X",(D17-C17),"0") -> 0 | H46: =IF(H17="X",(D17-C17),"0") -> 0 | I46: =IF(I17="X",(D17-C17),"0") -> 0 | J46: =IF(J17="X",(D17-C17),"0") -> 0 | K46: =IF(K17="X",(D17-C17),"0") -> 0
E47: =IF(E18="X",(D18-C18),"0") -> 0 | F47: =IF(F18="X",(D18-C18),"0") -> 0 | G47: =IF(G18="X",(D18-C18),"0") -> 0 | H47: =IF(H18="X",(D18-C18),"0") -> 0 | I47: =IF(I18="X",(D18-C18),"0") -> 0 | J47: =IF(J18="X",(D18-C18),"0") -> 0 | K47: =IF(K18="X",(D18-C18),"0") -> 0
... E61: =IF(E32="X",(D32-C32),"0") -> 0 | F61: =IF(F32="X",(D32-C32),"0") -> 0 | G61: =IF(G32="X",(D32-C32),"0") -> 0 | H61: =IF(H32="X",(D32-C32),"0") -> 0 | I61: =IF(I32="X",(D32-C32),"0") -> 0 | J61: =IF(J32="X",(D32-C32),"0") -> 0 | K61: =IF(K32="X",(D32-C32),"0") -> 0
E62: =SUM(E36:E61) -> 0 | F62: =SUM(F36:F61) -> 34.77 | G62: =SUM(G36:G61) -> 0 | H62: =SUM(H36:H61) -> 0 | I62: =SUM(I36:I61) -> 34.77 | J62: =SUM(J36:J61) -> 0 | K62: =SUM(K36:K61) -> 0

Sheet 269
A1: PROGRAMA DE MANUTENÇÃORODOVIÁRIA | I1: DATA: | J1: ='245'!J1 -> 46204 | L1: TÉCNICO RESP. | N1: ='245'!N1 -> ENG. THIAGO TORQUATO
F2: RODOVIAS NÃO PAVIMENTADAS
A3: FICHA DE INSPEÇÃO: | B3: =TT!C13 -> RODOVIA TO-477 - TRECHO ENTR. BR-010 (POVOADO BONFIM) - ALMAS | I3: REGIÃO: | J3: 13
A5: S.R.E. | B5: SENTIDO | C5: INÍCIO (KM) | D5: FIM (KM) | E5: CONDIÇÃO DA PLATAFORMA | I5: DRENAGEM SUPERFICIAL | L5: OBSERV.
E6: BOM | F6: REG. (ATÉ 10 IRR./KM) | G6: RUÍM (+ 10 IRR./KM) | H6: PÉSSIMA (ATOLEIRO/PTO. CRÍTICO) | I6: LIMPA | J6: OBSTRUÍDA | K6: AUSENTE
A7: 477ETO0060 | B7: C | C7: 0 | D7: 11.1 | E7: X | I7: X
C8: =D7 -> 11.1 | D8: 35.4 | E8: X | J8: X
C9: =D8 -> 35.4 | D9: 43 | E9: X | J9: X
C10: =D9 -> 43 | D10: 63.07 | E10: X | J10: X
A11: 477ETO0070 | B11: C | C11: 0 | D11: 9.97 | E11: X | J11: X
E36: =IF(E7="X",(D7-C7),"0") -> 11.1 | F36: =IF(F7="X",(D7-C7),"0") -> 0 | G36: =IF(G7="X",(D7-C7),"0") -> 0 | H36: =IF(H7="X",(D7-C7),"0") -> 0 | I36: =IF(I7="X",(D7-C7),"0") -> 11.1 | J36: =IF(J7="X",(D7-C7),"0") -> 0 | K36: =IF(K7="X",(D7-C7),"0") -> 0
E37: =IF(E8="X",(D8-C8),"0") -> 24.3 | F37: =IF(F8="X",(D8-C8),"0") -> 0 | G37: =IF(G8="X",(D8-C8),"0") -> 0 | H37: =IF(H8="X",(D8-C8),"0") -> 0 | I37: =IF(I8="X",(D8-C8),"0") -> 0 | J37: =IF(J8="X",(D8-C8),"0") -> 24.3 | K37: =IF(K8="X",(D8-C8),"0") -> 0
E38: =IF(E9="X",(D9-C9),"0") -> 7.6 | F38: =IF(F9="X",(D9-C9),"0") -> 0 | G38: =IF(G9="X",(D9-C9),"0") -> 0 | H38: =IF(H9="X",(D9-C9),"0") -> 0 | I38: =IF(I9="X",(D9-C9),"0") -> 0 | J38: =IF(J9="X",(D9-C9),"0") -> 7.6 | K38: =IF(K9="X",(D9-C9),"0") -> 0
E39: =IF(E10="X",(D10-C10),"0") -> 20.07 | F39: =IF(F10="X",(D10-C10),"0") -> 0 | G39: =IF(G10="X",(D10-C10),"0") -> 0 | H39: =IF(H10="X",(D10-C10),"0") -> 0 | I39: =IF(I10="X",(D10-C10),"0") -> 0 | J39: =IF(J10="X",(D10-C10),"0") -> 20.07 | K39: =IF(K10="X",(D10-C10),"0") -> 0
E40: =IF(E11="X",(D11-C11),"0") -> 9.97 | F40: =IF(F11="X",(D11-C11),"0") -> 0 | G40: =IF(G11="X",(D11-C11),"0") -> 0 | H40: =IF(H11="X",(D11-C11),"0") -> 0 | I40: =IF(I11="X",(D11-C11),"0") -> 0 | J40: =IF(J11="X",(D11-C11),"0") -> 9.97 | K40: =IF(K11="X",(D11-C11),"0") -> 0
E41: =IF(E12="X",(D12-C12),"0") -> 0 | F41: =IF(F12="X",(D12-C12),"0") -> 0 | G41: =IF(G12="X",(D12-C12),"0") -> 0 | H41: =IF(H12="X",(D12-C12),"0") -> 0 | I41: =IF(I12="X",(D12-C12),"0") -> 0 | J41: =IF(J12="X",(D12-C12),"0") -> 0 | K41: =IF(K12="X",(D12-C12),"0") -> 0
E42: =IF(E13="X",(D13-C13),"0") -> 0 | F42: =IF(F13="X",(D13-C13),"0") -> 0 | G42: =IF(G13="X",(D13-C13),"0") -> 0 | H42: =IF(H13="X",(D13-C13),"0") -> 0 | I42: =IF(I13="X",(D13-C13),"0") -> 0 | J42: =IF(J13="X",(D13-C13),"0") -> 0 | K42: =IF(K13="X",(D13-C13),"0") -> 0
E43: =IF(E14="X",(D14-C14),"0") -> 0 | F43: =IF(F14="X",(D14-C14),"0") -> 0 | G43: =IF(G14="X",(D14-C14),"0") -> 0 | H43: =IF(H14="X",(D14-C14),"0") -> 0 | I43: =IF(I14="X",(D14-C14),"0") -> 0 | J43: =IF(J14="X",(D14-C14),"0") -> 0 | K43: =IF(K14="X",(D14-C14),"0") -> 0
E44: =IF(E15="X",(D15-C15),"0") -> 0 | F44: =IF(F15="X",(D15-C15),"0") -> 0 | G44: =IF(G15="X",(D15-C15),"0") -> 0 | H44: =IF(H15="X",(D15-C15),"0") -> 0 | I44: =IF(I15="X",(D15-C15),"0") -> 0 | J44: =IF(J15="X",(D15-C15),"0") -> 0 | K44: =IF(K15="X",(D15-C15),"0") -> 0
E45: =IF(E16="X",(D16-C16),"0") -> 0 | F45: =IF(F16="X",(D16-C16),"0") -> 0 | G45: =IF(G16="X",(D16-C16),"0") -> 0 | H45: =IF(H16="X",(D16-C16),"0") -> 0 | I45: =IF(I16="X",(D16-C16),"0") -> 0 | J45: =IF(J16="X",(D16-C16),"0") -> 0 | K45: =IF(K16="X",(D16-C16),"0") -> 0
E46: =IF(E17="X",(D17-C17),"0") -> 0 | F46: =IF(F17="X",(D17-C17),"0") -> 0 | G46: =IF(G17="X",(D17-C17),"0") -> 0 | H46: =IF(H17="X",(D17-C17),"0") -> 0 | I46: =IF(I17="X",(D17-C17),"0") -> 0 | J46: =IF(J17="X",(D17-C17),"0") -> 0 | K46: =IF(K17="X",(D17-C17),"0") -> 0
E47: =IF(E18="X",(D18-C18),"0") -> 0 | F47: =IF(F18="X",(D18-C18),"0") -> 0 | G47: =IF(G18="X",(D18-C18),"0") -> 0 | H47: =IF(H18="X",(D18-C18),"0") -> 0 | I47: =IF(I18="X",(D18-C18),"0") -> 0 | J47: =IF(J18="X",(D18-C18),"0") -> 0 | K47: =IF(K18="X",(D18-C18),"0") -> 0
... E61: =IF(E32="X",(D32-C32),"0") -> 0 | F61: =IF(F32="X",(D32-C32),"0") -> 0 | G61: =IF(G32="X",(D32-C32),"0") -> 0 | H61: =IF(H32="X",(D32-C32),"0") -> 0 | I61: =IF(I32="X",(D32-C32),"0") -> 0 | J61: =IF(J32="X",(D32-C32),"0") -> 0 | K61: =IF(K32="X",(D32-C32),"0") -> 0
E62: =SUM(E36:E61) -> 73.04 | F62: =SUM(F36:F61) -> 0 | G62: =SUM(G36:G61) -> 0 | H62: =SUM(H36:H61) -> 0 | I62: =SUM(I36:I61) -> 11.1 | J62: =SUM(J36:J61) -> 61.94 | K62: =SUM(K36:K61) -> 0

Sheet 270
A1: PROGRAMA DE MANUTENÇÃORODOVIÁRIA | I1: DATA: | J1: ='245'!J1 -> 46204 | L1: TÉCNICO RESP. | N1: ='245'!N1 -> ENG. THIAGO TORQUATO
F2: RODOVIAS NÃO PAVIMENTADAS
A3: FICHA DE INSPEÇÃO: | B3: =TT!C14 -> RODOVIA TO-485 - TRECHO TAIPAS DO TOCANTINS - ENTR. TO-110 | I3: REGIÃO: | J3: 13
A5: S.R.E. | B5: SENTIDO | C5: INÍCIO (KM) | D5: FIM (KM) | E5: CONDIÇÃO DA PLATAFORMA | I5: DRENAGEM SUPERFICIAL | L5: OBSERV.
E6: BOM | F6: REG. (ATÉ 10 IRR./KM) | G6: RUÍM (+ 10 IRR./KM) | H6: PÉSSIMA (ATOLEIRO/PTO. CRÍTICO) | I6: LIMPA | J6: OBSTRUÍDA | K6: AUSENTE
A7: 485ETO0010 | B7: C | C7: 0 | D7: 10.8 | F7: X | I7: X
C8: 10.8 | D8: 21.44 | E8: X | I8: X
A10: 485ETO0020 | B10: C | C10: 0 | D10: 10.9 | E10: X | F10: X | J10: X
A12: 485ETO0030 | B12: C | C12: 0 | D12: 9.6 | E12: X | I12: X
C13: 9.6 | D13: 16.8 | E13: X | I13: X
C14: 16.8 | D14: 18.02 | E14: X | I14: X
A16: 485ETO0040 | B16: C | C16: 0 | D16: 7.5 | E16: X | K16: X
C17: 7.5 | D17: 14.3 | E17: X | I17: X
C18: 14.3 | D18: 24.01 | E18: X | K18: X
A20: 485ETO0050 | B20: C | C20: 0 | D20: 15 | E20: X | I20: X
C21: 15 | D21: 24.7 | E21: X | K21: X
E36: =IF(E7="X",(D7-C7),"0") -> 0 | F36: =IF(F7="X",(D7-C7),"0") -> 10.8 | G36: =IF(G7="X",(D7-C7),"0") -> 0 | H36: =IF(H7="X",(D7-C7),"0") -> 0 | I36: =IF(I7="X",(D7-C7),"0") -> 10.8 | J36: =IF(J7="X",(D7-C7),"0") -> 0 | K36: =IF(K7="X",(D7-C7),"0") -> 0
E37: =IF(E8="X",(D8-C8),"0") -> 10.64 | F37: =IF(F8="X",(D8-C8),"0") -> 0 | G37: =IF(G8="X",(D8-C8),"0") -> 0 | H37: =IF(H8="X",(D8-C8),"0") -> 0 | I37: =IF(I8="X",(D8-C8),"0") -> 10.64 | J37: =IF(J8="X",(D8-C8),"0") -> 0 | K37: =IF(K8="X",(D8-C8),"0") -> 0
E38: =IF(E9="X",(D9-C9),"0") -> 0 | F38: =IF(F9="X",(D9-C9),"0") -> 0 | G38: =IF(G9="X",(D9-C9),"0") -> 0 | H38: =IF(H9="X",(D9-C9),"0") -> 0 | I38: =IF(I9="X",(D9-C9),"0") -> 0 | J38: =IF(J9="X",(D9-C9),"0") -> 0 | K38: =IF(K9="X",(D9-C9),"0") -> 0
E39: =IF(E10="X",(D10-C10),"0") -> 10.9 | F39: =IF(F10="X",(D10-C10),"0") -> 10.9 | G39: =IF(G10="X",(D10-C10),"0") -> 0 | H39: =IF(H10="X",(D10-C10),"0") -> 0 | I39: =IF(I10="X",(D10-C10),"0") -> 0 | J39: =IF(J10="X",(D10-C10),"0") -> 10.9 | K39: =IF(K10="X",(D10-C10),"0") -> 0
E40: =IF(E11="X",(D11-C11),"0") -> 0 | F40: =IF(F11="X",(D11-C11),"0") -> 0 | G40: =IF(G11="X",(D11-C11),"0") -> 0 | H40: =IF(H11="X",(D11-C11),"0") -> 0 | I40: =IF(I11="X",(D11-C11),"0") -> 0 | J40: =IF(J11="X",(D11-C11),"0") -> 0 | K40: =IF(K11="X",(D11-C11),"0") -> 0
E41: =IF(E12="X",(D12-C12),"0") -> 9.6 | F41: =IF(F12="X",(D12-C12),"0") -> 0 | G41: =IF(G12="X",(D12-C12),"0") -> 0 | H41: =IF(H12="X",(D12-C12),"0") -> 0 | I41: =IF(I12="X",(D12-C12),"0") -> 9.6 | J41: =IF(J12="X",(D12-C12),"0") -> 0 | K41: =IF(K12="X",(D12-C12),"0") -> 0
E42: =IF(E13="X",(D13-C13),"0") -> 7.2 | F42: =IF(F13="X",(D13-C13),"0") -> 0 | G42: =IF(G13="X",(D13-C13),"0") -> 0 | H42: =IF(H13="X",(D13-C13),"0") -> 0 | I42: =IF(I13="X",(D13-C13),"0") -> 7.2 | J42: =IF(J13="X",(D13-C13),"0") -> 0 | K42: =IF(K13="X",(D13-C13),"0") -> 0
E43: =IF(E14="X",(D14-C14),"0") -> 1.22 | F43: =IF(F14="X",(D14-C14),"0") -> 0 | G43: =IF(G14="X",(D14-C14),"0") -> 0 | H43: =IF(H14="X",(D14-C14),"0") -> 0 | I43: =IF(I14="X",(D14-C14),"0") -> 1.22 | J43: =IF(J14="X",(D14-C14),"0") -> 0 | K43: =IF(K14="X",(D14-C14),"0") -> 0
E44: =IF(E15="X",(D15-C15),"0") -> 0 | F44: =IF(F15="X",(D15-C15),"0") -> 0 | G44: =IF(G15="X",(D15-C15),"0") -> 0 | H44: =IF(H15="X",(D15-C15),"0") -> 0 | I44: =IF(I15="X",(D15-C15),"0") -> 0 | J44: =IF(J15="X",(D15-C15),"0") -> 0 | K44: =IF(K15="X",(D15-C15),"0") -> 0
E45: =IF(E16="X",(D16-C16),"0") -> 7.5 | F45: =IF(F16="X",(D16-C16),"0") -> 0 | G45: =IF(G16="X",(D16-C16),"0") -> 0 | H45: =IF(H16="X",(D16-C16),"0") -> 0 | I45: =IF(I16="X",(D16-C16),"0") -> 0 | J45: =IF(J16="X",(D16-C16),"0") -> 0 | K45: =IF(K16="X",(D16-C16),"0") -> 7.5
E46: =IF(E17="X",(D17-C17),"0") -> 6.8 | F46: =IF(F17="X",(D17-C17),"0") -> 0 | G46: =IF(G17="X",(D17-C17),"0") -> 0 | H46: =IF(H17="X",(D17-C17),"0") -> 0 | I46: =IF(I17="X",(D17-C17),"0") -> 6.8 | J46: =IF(J17="X",(D17-C17),"0") -> 0 | K46: =IF(K17="X",(D17-C17),"0") -> 0
E47: =IF(E18="X",(D18-C18),"0") -> 9.71 | F47: =IF(F18="X",(D18-C18),"0") -> 0 | G47: =IF(G18="X",(D18-C18),"0") -> 0 | H47: =IF(H18="X",(D18-C18),"0") -> 0 | I47: =IF(I18="X",(D18-C18),"0") -> 0 | J47: =IF(J18="X",(D18-C18),"0") -> 0 | K47: =IF(K18="X",(D18-C18),"0") -> 9.71
... E61: =IF(E32="X",(D32-C32),"0") -> 0 | F61: =IF(F32="X",(D32-C32),"0") -> 0 | G61: =IF(G32="X",(D32-C32),"0") -> 0 | H61: =IF(H32="X",(D32-C32),"0") -> 0 | I61: =IF(I32="X",(D32-C32),"0") -> 0 | J61: =IF(J32="X",(D32-C32),"0") -> 0 | K61: =IF(K32="X",(D32-C32),"0") -> 0
E62: =SUM(E36:E61) -> 88.27 | F62: =SUM(F36:F61) -> 21.7 | G62: =SUM(G36:G61) -> 0 | H62: =SUM(H36:H61) -> 0 | I62: =SUM(I36:I61) -> 61.26 | J62: =SUM(J36:J61) -> 10.9 | K62: =SUM(K36:K61) -> 26.91

Sheet 271
A1: PROGRAMA DE MANUTENÇÃORODOVIÁRIA | I1: DATA: | J1: ='245'!J1 -> 46204 | L1: TÉCNICO RESP. | N1: ='245'!N1 -> ENG. THIAGO TORQUATO
F2: RODOVIAS NÃO PAVIMENTADAS
A3: FICHA DE INSPEÇÃO: | B3: =TT!C15 -> RODOVIA TO-487 - TRECHO ENTR. TO-485 (MIMOSA DOS MARINS) - ENTR. BR-242 | I3: REGIÃO: | J3: 13
A5: S.R.E. | B5: SENTIDO | C5: INÍCIO (KM) | D5: FIM (KM) | E5: CONDIÇÃO DA PLATAFORMA | I5: DRENAGEM SUPERFICIAL | L5: OBSERV.
E6: BOM | F6: REG. (ATÉ 10 IRR./KM) | G6: RUÍM (+ 10 IRR./KM) | H6: PÉSSIMA (ATOLEIRO/PTO. CRÍTICO) | I6: LIMPA | J6: OBSTRUÍDA | K6: AUSENTE
A7: 487ETO0010 | B7: C | C7: 0 | D7: 12.3 | E7: X | J7: X
A8: 487ETO0010 | C8: 12.3 | D8: 18.6 | E8: X | K8: X
A9: 487ETO0010 | C9: 18.6 | D9: 21.2 | E9: X | J9: X
E36: =IF(E7="X",(D7-C7),"0") -> 12.3 | F36: =IF(F7="X",(D7-C7),"0") -> 0 | G36: =IF(G7="X",(D7-C7),"0") -> 0 | H36: =IF(H7="X",(D7-C7),"0") -> 0 | I36: =IF(I7="X",(D7-C7),"0") -> 0 | J36: =IF(J7="X",(D7-C7),"0") -> 12.3 | K36: =IF(K7="X",(D7-C7),"0") -> 0
E37: =IF(E8="X",(D8-C8),"0") -> 6.3 | F37: =IF(F8="X",(D8-C8),"0") -> 0 | G37: =IF(G8="X",(D8-C8),"0") -> 0 | H37: =IF(H8="X",(D8-C8),"0") -> 0 | I37: =IF(I8="X",(D8-C8),"0") -> 0 | J37: =IF(J8="X",(D8-C8),"0") -> 0 | K37: =IF(K8="X",(D8-C8),"0") -> 6.3
E38: =IF(E9="X",(D9-C9),"0") -> 2.6 | F38: =IF(F9="X",(D9-C9),"0") -> 0 | G38: =IF(G9="X",(D9-C9),"0") -> 0 | H38: =IF(H9="X",(D9-C9),"0") -> 0 | I38: =IF(I9="X",(D9-C9),"0") -> 0 | J38: =IF(J9="X",(D9-C9),"0") -> 2.6 | K38: =IF(K9="X",(D9-C9),"0") -> 0
E39: =IF(E10="X",(D10-C10),"0") -> 0 | F39: =IF(F10="X",(D10-C10),"0") -> 0 | G39: =IF(G10="X",(D10-C10),"0") -> 0 | H39: =IF(H10="X",(D10-C10),"0") -> 0 | I39: =IF(I10="X",(D10-C10),"0") -> 0 | J39: =IF(J10="X",(D10-C10),"0") -> 0 | K39: =IF(K10="X",(D10-C10),"0") -> 0
E40: =IF(E11="X",(D11-C11),"0") -> 0 | F40: =IF(F11="X",(D11-C11),"0") -> 0 | G40: =IF(G11="X",(D11-C11),"0") -> 0 | H40: =IF(H11="X",(D11-C11),"0") -> 0 | I40: =IF(I11="X",(D11-C11),"0") -> 0 | J40: =IF(J11="X",(D11-C11),"0") -> 0 | K40: =IF(K11="X",(D11-C11),"0") -> 0
E41: =IF(E12="X",(D12-C12),"0") -> 0 | F41: =IF(F12="X",(D12-C12),"0") -> 0 | G41: =IF(G12="X",(D12-C12),"0") -> 0 | H41: =IF(H12="X",(D12-C12),"0") -> 0 | I41: =IF(I12="X",(D12-C12),"0") -> 0 | J41: =IF(J12="X",(D12-C12),"0") -> 0 | K41: =IF(K12="X",(D12-C12),"0") -> 0
E42: =IF(E13="X",(D13-C13),"0") -> 0 | F42: =IF(F13="X",(D13-C13),"0") -> 0 | G42: =IF(G13="X",(D13-C13),"0") -> 0 | H42: =IF(H13="X",(D13-C13),"0") -> 0 | I42: =IF(I13="X",(D13-C13),"0") -> 0 | J42: =IF(J13="X",(D13-C13),"0") -> 0 | K42: =IF(K13="X",(D13-C13),"0") -> 0
E43: =IF(E14="X",(D14-C14),"0") -> 0 | F43: =IF(F14="X",(D14-C14),"0") -> 0 | G43: =IF(G14="X",(D14-C14),"0") -> 0 | H43: =IF(H14="X",(D14-C14),"0") -> 0 | I43: =IF(I14="X",(D14-C14),"0") -> 0 | J43: =IF(J14="X",(D14-C14),"0") -> 0 | K43: =IF(K14="X",(D14-C14),"0") -> 0
E44: =IF(E15="X",(D15-C15),"0") -> 0 | F44: =IF(F15="X",(D15-C15),"0") -> 0 | G44: =IF(G15="X",(D15-C15),"0") -> 0 | H44: =IF(H15="X",(D15-C15),"0") -> 0 | I44: =IF(I15="X",(D15-C15),"0") -> 0 | J44: =IF(J15="X",(D15-C15),"0") -> 0 | K44: =IF(K15="X",(D15-C15),"0") -> 0
E45: =IF(E16="X",(D16-C16),"0") -> 0 | F45: =IF(F16="X",(D16-C16),"0") -> 0 | G45: =IF(G16="X",(D16-C16),"0") -> 0 | H45: =IF(H16="X",(D16-C16),"0") -> 0 | I45: =IF(I16="X",(D16-C16),"0") -> 0 | J45: =IF(J16="X",(D16-C16),"0") -> 0 | K45: =IF(K16="X",(D16-C16),"0") -> 0
E46: =IF(E17="X",(D17-C17),"0") -> 0 | F46: =IF(F17="X",(D17-C17),"0") -> 0 | G46: =IF(G17="X",(D17-C17),"0") -> 0 | H46: =IF(H17="X",(D17-C17),"0") -> 0 | I46: =IF(I17="X",(D17-C17),"0") -> 0 | J46: =IF(J17="X",(D17-C17),"0") -> 0 | K46: =IF(K17="X",(D17-C17),"0") -> 0
E47: =IF(E18="X",(D18-C18),"0") -> 0 | F47: =IF(F18="X",(D18-C18),"0") -> 0 | G47: =IF(G18="X",(D18-C18),"0") -> 0 | H47: =IF(H18="X",(D18-C18),"0") -> 0 | I47: =IF(I18="X",(D18-C18),"0") -> 0 | J47: =IF(J18="X",(D18-C18),"0") -> 0 | K47: =IF(K18="X",(D18-C18),"0") -> 0
... E61: =IF(E32="X",(D32-C32),"0") -> 0 | F61: =IF(F32="X",(D32-C32),"0") -> 0 | G61: =IF(G32="X",(D32-C32),"0") -> 0 | H61: =IF(H32="X",(D32-C32),"0") -> 0 | I61: =IF(I32="X",(D32-C32),"0") -> 0 | J61: =IF(J32="X",(D32-C32),"0") -> 0 | K61: =IF(K32="X",(D32-C32),"0") -> 0
E62: =SUM(E36:E61) -> 21.2 | F62: =SUM(F36:F61) -> 0 | G62: =SUM(G36:G61) -> 0 | H62: =SUM(H36:H61) -> 0 | I62: =SUM(I36:I61) -> 0 | J62: =SUM(J36:J61) -> 14.9 | K62: =SUM(K36:K61) -> 6.3

Sheet 272
A1: PROGRAMA DE MANUTENÇÃORODOVIÁRIA | I1: DATA: | J1: ='245'!J1 -> 46204 | L1: TÉCNICO RESP. | N1: ='245'!N1 -> ENG. THIAGO TORQUATO
F2: RODOVIAS NÃO PAVIMENTADAS
A3: FICHA DE INSPEÇÃO: | B3: =TT!C16 -> RODOVIA TO-497 - TRECHO ENTR. BR-242 - ENTR. TO-296 (POVOADO JACARÉ) | I3: REGIÃO: | J3: 13
A5: S.R.E. | B5: SENTIDO | C5: INÍCIO (KM) | D5: FIM (KM) | E5: CONDIÇÃO DA PLATAFORMA | I5: DRENAGEM SUPERFICIAL | L5: OBSERV.
E6: BOM | F6: REG. (ATÉ 10 IRR./KM) | G6: RUÍM (+ 10 IRR./KM) | H6: PÉSSIMA (ATOLEIRO/PTO. CRÍTICO) | I6: LIMPA | J6: OBSTRUÍDA | K6: AUSENTE
A7: 497ETO0010 | B7: C | C7: 0 | D7: 1.3 | E7: X | I7: X | L7: * (15,94 Km) 03 FOTOS
A8: 497ETO0010 | C8: 1.3 | D8: 2.3 | E8: X | I8: X | L8: 02 FOTOS
A9: 497ETO0010 | C9: 2.3 | D9: 2.8 | E9: X | I9: X | L9: PONTO BAIXO - POSSÍVEL ATOLEIRO - 02 FOTOS
A10: 497ETO0010 | C10: 2.8 | D10: 6.3 | E10: X | I10: X | L10: PREFEITURA TRABALHANDO NO LOCAL - 07 FOTOS
A11: 497ETO0010 | C11: 6.3 | D11: 15.94 | E11: X | I11: X | L11: PREFEITURA TRABALHOU NO LOCAL - 09 FOTOS
A12: 497ETO0020 | B12: C | C12: 0 | D12: 4 | E12: X | I12: X | L12: * (27,24 Km) TRECHO BASTANTE ESTREITO - 04 FOTOS
A13: 497ETO0020 | C13: 4 | D13: 5 | E13: X | I13: X | L13: TRECHO CRÍTICO - 01 FOTO
A14: 497ETO0020 | C14: 5 | D14: 6 | E14: X | I14: X | L14: TRECHO CRÍTICO, LOCAL COM BASTANTE AREIA NA PISTA - 02 FOTOS
A15: 497ETO0020 | C15: 6 | D15: 8 | E15: X | I15: X | L15: TRECHO CRÍTICO, LOCAL COM BASTANTE AREIA NA PISTA - 01 FOTO
A16: 497ETO0020 | C16: 8 | D16: 10 | E16: X | I16: X
A17: 497ETO0020 | C17: 10 | D17: 10 | E17: X | K17: X | L17: PONTO CRÍTICO - 01 FOTO
A18: 497ETO0020 | C18: 10 | D18: 17 | E18: X | K18: X | L18: TRECHO CRÍTICO, LOCAL COM BASTANTE AREIA, SOB INTERVENÇÃO/PREFEITURA - 04 FOTOS
A19: 497ETO0020 | C19: 17 | D19: 19 | E19: X | K19: X | L19: PONTO CRÍTICO SENDO ATACADO - 02 FOTOS
A20: 497ETO0020 | C20: 19 | D20: 20 | E20: X | K20: X | L20: PONTO CRÍTICO SENDO ATACADO - 01 FOTO
A21: 497ETO0020 | C21: 20 | D21: 22 | E21: X | K21: X | L21: TRECHO CRÍTICO, LOCAL COM BASTANTE AREIA NA PISTA - 04 FOTOS
A22: 497ETO0020 | C22: 22 | D22: 23 | E22: X | K22: X
A23: 497ETO0020 | C23: 23 | D23: 24 | E23: X | K23: X | L23: TRECHO CRÍTICO, LOCAL COM BASTANTE AREIA, SOB INTERVENÇÃO/PREFEITURA - 01 FOTO
A24: 497ETO0020 | C24: 24 | D24: 24 | E24: X | K24: X | L24: PCA RIO PALMAS - 01 FOTO
