Workbook

Sheet Trechos
A1: RELAÇÃO DE TRECHOS NÃO PAVIMENTDOS R.12
A2: LOTE | B2: N. | C2: TRECHO | D2: S.R.E | E2: SEGMENTOS | F2: EXT. (KM) | G2: TIPO | H2: 45839 | I2: 45870
A3: 12 | B3: 228 | C3: RODOVIA TO-296 - TRECHO SÃO SALVADOR DO TOCANTINS - PARANÃ | D3: ACESSO | E3: ENTR. TO-387 - UHE SÃO SALVADOR | F3: 12.317348 | G3: LEN
A4: 12 | B4: 229 | C4: RODOVIA TO-296 - TRECHO JAÚ DO TOCANTINS - SÃO SALVADOR DO TOCANTINS | D4: 296ETO0240 | E4: ENTR. TO-387 - RETIRO | F4: 22.432307 | G4: EOP | I4: X
A5: 12 | B5: 229 | C5: RODOVIA TO-296 - TRECHO JAÚ DO TOCANTINS - SÃO SALVADOR DO TOCANTINS | D5: 296ETO0250 | E5: RETIRO - ENTR. TO-491 | F5: 7.6576128 | G5: EOP | I5: X
A6: 12 | B6: 229 | C6: RODOVIA TO-296 - TRECHO JAÚ DO TOCANTINS - SÃO SALVADOR DO TOCANTINS | D6: 296ETO0260 | E6: ENTR. TO-491 - JAÚ DO TOCANTINS *TRECHO URBANO* | F6: 51.627935 | G6: EOP | I6: X
A7: 12 | B7: 231 | C7: RODOVIA TO-365 - TRECHO IPUEIRAS - SILVANÓPOLIS | D7: 365ETO0170 | E7: ENTR- TO-050-BR-010 (SILVANÓPOLIS) - SURUBIM | F7: 21.354216 | G7: LEN
A8: 12 | B8: 231 | C8: RODOVIA TO-365 - TRECHO IPUEIRAS - SILVANÓPOLIS | D8: 365ETO0180 | E8: SURUBIM - ENTR. TO-458 | F8: 6.2394458 | G8: LEN
A9: 12 | B9: 231 | C9: RODOVIA TO-365 - TRECHO IPUEIRAS - SILVANÓPOLIS | D9: 365ETO0190 | E9: ENTR. TO-458 - IPUEIRAS *TRECHO URBANO* | F9: 5.3298942 | G9: LEN
A10: 12 | B10: 231 | C10: RODOVIA TO-365 - TRECHO IPUEIRAS - SILVANÓPOLIS | D10: 365ETO0210 | E10: ENTR. TO-458 (IPUEIRAS *TRECHO URBANO*) - RIO TOCANTINS( BALSA) | F10: 1.3310602 | G10: LEN
A11: 12 | B11: 232 | C11: RODOVIA TO-373 - TRECHO ENTR. TO-365 (BALSA) - SÃO MIGUEL - LAGOA DO ROMÃO -ENTR. TO-280 | D11: 373ETO0120 | E11: RIO TOCANTINS (BALSA) - SÃO MIGUEL | F11: 25.932627 | G11: LEN
A12: 12 | B12: 232 | C12: RODOVIA TO-373 - TRECHO ENTR. TO-365 (BALSA) - SÃO MIGUEL - LAGOA DO ROMÃO -ENTR. TO-280 | D12: 373ETO0130 | E12: SÃO MIGUEL - LAGOA DO ROMÃO | F12: 39.401208 | G12: LEN
A13: 12 | B13: 232 | C13: RODOVIA TO-373 - TRECHO ENTR. TO-365 (BALSA) - SÃO MIGUEL - LAGOA DO ROMÃO -ENTR. TO-280 | D13: 373ETO0140 | E13: LAGOA DO ROMÃO - ENTR. TO-479 | F13: 1.5518686 | G13: LEN
A14: 12 | B14: 232 | C14: RODOVIA TO-373 - TRECHO ENTR. TO-365 (BALSA) - SÃO MIGUEL - LAGOA DO ROMÃO -ENTR. TO-280 | D14: 373ETO0150 | E14: ENTR.TO- 479 - ENTR. TO-280 | F14: 20.945342 | G14: LEN
A15: 12 | B15: 236 | C15: RODOVIA TO-458 - TRECHO ENTR. TO-365 (IPUEIRAS) - ENTR. BR-010 | D15: 458ETO0050 | E15: ENTR. TO-365 - MORRO DE SÃO JOÃO | F15: 9.4784748 | G15: LEN
A16: 12 | B16: 236 | C16: RODOVIA TO-458 - TRECHO ENTR. TO-365 (IPUEIRAS) - ENTR. BR-010 | D16: 458ETO0060 | E16: MORRO DE SÃO JOÃO - ENTR. TO-482 | F16: 21.460758 | G16: LEN
A17: 12 | B17: 236 | C17: RODOVIA TO-458 - TRECHO ENTR. TO-365 (IPUEIRAS) - ENTR. BR-010 | D17: 458ETO0070 | E17: ENTR. TO-482 - ENTR. TO-050-BR-010 | F17: 3.0274067 | G17: LEN
A18: 12 | B18: 237 | C18: RODOVIA TO-479 - TRECHO PEIXE - POVOADO LAGOA DO ROMÃO (ENTR. TO-373) | D18: 479ETO0010 | E18: ENTROC. TO-373 - PEIXE (RIO TOCANTINS) | F18: 26.043993 | G18: LEN
A19: 12 | B19: 238 | C19: RODOVIA TO-482 - TRECHO: ENTR. TO-280 (SÃO VALÉRIO DE NATIVIDADE) / ENTR. TO-458 | D19: 482ETO0010 | E19: ENTR. TO-458 - POV. APINAJE (BALSA) | F19: 21.698197 | G19: LEN | I19: X
A20: 12 | B20: 238 | C20: RODOVIA TO-482 - TRECHO: ENTR. TO-280 (SÃO VALÉRIO DE NATIVIDADE) / ENTR. TO-458 | D20: 482ETO0020 | E20: POV. APINAJE (BALSA) - POV. SÃO PEDRO | F20: 17.367842 | G20: LEN | I20: X
A21: 12 | B21: 238 | C21: RODOVIA TO-482 - TRECHO: ENTR. TO-280 (SÃO VALÉRIO DE NATIVIDADE) / ENTR. TO-458 | D21: 482ETO0030 | E21: POV. SÃO PEDRO - ENTR. TO-280 | F21: 34.488442 | G21: LEN | I21: X
A22: 12 | B22: 239 | C22: RODOVIA TO-486 - TRECHO SANTA ROSA DO TOCANTINS - ENTR. TO-280 (NATIVIDADE) | D22: 486ETO0010 | E22: SANTA ROSA *TRECHO URBANO* - ENTR. TO-280 (NATIVIDADE) | F22: 63.930071 | G22: LEN | I22: X
A23: 12 | B23: 240 | C23: RODOVIA TO-490 - TRECHO SÃO VALÉRIO DE NATIVIDADE - ENTR. BR-242 | D23: 490ETO0010 | E23: ENTR. TO-280 (SÃO VALÉRIO DA NATIVIDADE) - TIGRE | F23: 34.769174 | G23: LEN
A24: 12 | B24: 240 | C24: RODOVIA TO-490 - TRECHO SÃO VALÉRIO DE NATIVIDADE - ENTR. BR-242 | D24: 490ETO0020 | E24: TIGRE - ENTR. BR-242 | F24: 46.307034 | G24: LEN
A25: 12 | B25: 241 | C25: RODOVIA TO-491 - TRECHO ENTR. BR-242 - ENTR. TO-296 (POVOADO RETIRO) | D25: 491ETO0010 | E25: ENTR. TO-373-BR-242 - ENTR. TO-296 | F25: 60.310113 | G25: LEN | I25: X
A26: 12 | B26: 242 | C26: RODOVIA TO-495 - TRECHO DIVISA TO-GO - LOURENÇO BORGES - ENTR. TO-296 | D26: 495ETO0010 | E26: ENTR. TO-296 - POV LORENÇO BORGES | F26: 16.27242 | G26: LEN
A27: 12 | B27: 242 | C27: RODOVIA TO-495 - TRECHO DIVISA TO-GO - LOURENÇO BORGES - ENTR. TO-296 | D27: 495ETO0020 | E27: POV LORENÇO BORGES - DIVISA TO-GO | F27: 5.4039722 | G27: LEN
F28: =SUM(F3:F27) -> 576.67876

Sheet 228
A1: PROGRAMA DE MANUTENÇÃORODOVIÁRIA | I1: DATA: | J1: 46204 | L1: TÉCNICO RESP. | N1: ENG. THIAGO TORQUATO
A2: RODOVIAS NÃO PAVIMENTADAS
A3: FICHA DE INSPEÇÃO: | B3: =TT!C4 -> RODOVIA TO-296 - TRECHO SÃO SALVADOR DO TOCANTINS - PARANÃ | L3: REGIÃO: | N3: 12
A5: S.R.E. | B5: SENTIDO | C5: INÍCIO (KM) | D5: FIM (KM) | E5: CONDIÇÃO DA PLATAFORMA | I5: DRENAGEM SUPERFICIAL | L5: OBSERV.
E6: BOM | F6: REG. (ATÉ 10 IRR./KM) | G6: RUÍM (+ 10 IRR./KM) | H6: PÉSSIMA (ATOLEIRO/PTO. CRÍTICO) | I6: LIMPA | J6: OBSTRUÍDA | K6: AUSENTE
C7: 0 | D7: 1 | G7: x | J7: x
C8: 1 | D8: 2 | F8: x | K8: x
C9: 2 | D9: 12.32 | G9: x | I9: x | S9: 2
C10: 12.32 | D10: 16.1 | G10: x | J10: x
C11: 16.1 | D11: 32.2 | G11: x | J11: x
C12: 32.2 | D12: 67.26 | F12: x | J12: x
E36: =IF(E7="X",(D7-C7),"0") -> 0 | F36: =IF(F7="X",(D7-C7),"0") -> 0 | G36: =IF(G7="X",(D7-C7),"0") -> 1 | H36: =IF(H7="X",(D7-C7),"0") -> 0 | I36: =IF(I7="X",(D7-C7),"0") -> 0 | J36: =IF(J7="X",(D7-C7),"0") -> 1 | K36: =IF(K7="X",(D7-C7),"0") -> 0
E37: =IF(E8="X",(D8-C8),"0") -> 0 | F37: =IF(F8="X",(D8-C8),"0") -> 1 | G37: =IF(G8="X",(D8-C8),"0") -> 0 | H37: =IF(H8="X",(D8-C8),"0") -> 0 | I37: =IF(I8="X",(D8-C8),"0") -> 0 | J37: =IF(J8="X",(D8-C8),"0") -> 0 | K37: =IF(K8="X",(D8-C8),"0") -> 1
E38: =IF(E9="X",(D9-C9),"0") -> 0 | F38: =IF(F9="X",(D9-C9),"0") -> 0 | G38: =IF(G9="X",(D9-C9),"0") -> 10.32 | H38: =IF(H9="X",(D9-C9),"0") -> 0 | I38: =IF(I9="X",(D9-C9),"0") -> 10.32 | J38: =IF(J9="X",(D9-C9),"0") -> 0 | K38: =IF(K9="X",(D9-C9),"0") -> 0
E39: =IF(E10="X",(D10-C10),"0") -> 0 | F39: =IF(F10="X",(D10-C10),"0") -> 0 | G39: =IF(G10="X",(D10-C10),"0") -> 3.78 | H39: =IF(H10="X",(D10-C10),"0") -> 0 | I39: =IF(I10="X",(D10-C10),"0") -> 0 | J39: =IF(J10="X",(D10-C10),"0") -> 3.78 | K39: =IF(K10="X",(D10-C10),"0") -> 0
E40: =IF(E11="X",(D11-C11),"0") -> 0 | F40: =IF(F11="X",(D11-C11),"0") -> 0 | G40: =IF(G11="X",(D11-C11),"0") -> 16.1 | H40: =IF(H11="X",(D11-C11),"0") -> 0 | I40: =IF(I11="X",(D11-C11),"0") -> 0 | J40: =IF(J11="X",(D11-C11),"0") -> 16.1 | K40: =IF(K11="X",(D11-C11),"0") -> 0
E41: =IF(E12="X",(D12-C12),"0") -> 0 | F41: =IF(F12="X",(D12-C12),"0") -> 35.06 | G41: =IF(G12="X",(D12-C12),"0") -> 0 | H41: =IF(H12="X",(D12-C12),"0") -> 0 | I41: =IF(I12="X",(D12-C12),"0") -> 0 | J41: =IF(J12="X",(D12-C12),"0") -> 35.06 | K41: =IF(K12="X",(D12-C12),"0") -> 0
E42: =IF(E13="X",(D13-C13),"0") -> 0 | F42: =IF(F13="X",(D13-C13),"0") -> 0 | G42: =IF(G13="X",(D13-C13),"0") -> 0 | H42: =IF(H13="X",(D13-C13),"0") -> 0 | I42: =IF(I13="X",(D13-C13),"0") -> 0 | J42: =IF(J13="X",(D13-C13),"0") -> 0 | K42: =IF(K13="X",(D13-C13),"0") -> 0
E43: =IF(E14="X",(D14-C14),"0") -> 0 | F43: =IF(F14="X",(D14-C14),"0") -> 0 | G43: =IF(G14="X",(D14-C14),"0") -> 0 | H43: =IF(H14="X",(D14-C14),"0") -> 0 | I43: =IF(I14="X",(D14-C14),"0") -> 0 | J43: =IF(J14="X",(D14-C14),"0") -> 0 | K43: =IF(K14="X",(D14-C14),"0") -> 0
E44: =IF(E15="X",(D15-C15),"0") -> 0 | F44: =IF(F15="X",(D15-C15),"0") -> 0 | G44: =IF(G15="X",(D15-C15),"0") -> 0 | H44: =IF(H15="X",(D15-C15),"0") -> 0 | I44: =IF(I15="X",(D15-C15),"0") -> 0 | J44: =IF(J15="X",(D15-C15),"0") -> 0 | K44: =IF(K15="X",(D15-C15),"0") -> 0
E45: =IF(E16="X",(D16-C16),"0") -> 0 | F45: =IF(F16="X",(D16-C16),"0") -> 0 | G45: =IF(G16="X",(D16-C16),"0") -> 0 | H45: =IF(H16="X",(D16-C16),"0") -> 0 | I45: =IF(I16="X",(D16-C16),"0") -> 0 | J45: =IF(J16="X",(D16-C16),"0") -> 0 | K45: =IF(K16="X",(D16-C16),"0") -> 0
E46: =IF(E17="X",(D17-C17),"0") -> 0 | F46: =IF(F17="X",(D17-C17),"0") -> 0 | G46: =IF(G17="X",(D17-C17),"0") -> 0 | H46: =IF(H17="X",(D17-C17),"0") -> 0 | I46: =IF(I17="X",(D17-C17),"0") -> 0 | J46: =IF(J17="X",(D17-C17),"0") -> 0 | K46: =IF(K17="X",(D17-C17),"0") -> 0
E47: =IF(E18="X",(D18-C18),"0") -> 0 | F47: =IF(F18="X",(D18-C18),"0") -> 0 | G47: =IF(G18="X",(D18-C18),"0") -> 0 | H47: =IF(H18="X",(D18-C18),"0") -> 0 | I47: =IF(I18="X",(D18-C18),"0") -> 0 | J47: =IF(J18="X",(D18-C18),"0") -> 0 | K47: =IF(K18="X",(D18-C18),"0") -> 0
... E61: =IF(E32="X",(D32-C32),"0") -> 0 | F61: =IF(F32="X",(D32-C32),"0") -> 0 | G61: =IF(G32="X",(D32-C32),"0") -> 0 | H61: =IF(H32="X",(D32-C32),"0") -> 0 | I61: =IF(I32="X",(D32-C32),"0") -> 0 | J61: =IF(J32="X",(D32-C32),"0") -> 0 | K61: =IF(K32="X",(D32-C32),"0") -> 0
E62: =SUM(E36:E61) -> 0 | F62: =SUM(F36:F61) -> 36.06 | G62: =SUM(G36:G61) -> 31.2 | H62: =SUM(H36:H61) -> 0 | I62: =SUM(I36:I61) -> 10.32 | J62: =SUM(J36:J61) -> 55.94 | K62: =SUM(K36:K61) -> 1

Sheet 229
A1: PROGRAMA DE MANUTENÇÃORODOVIÁRIA | I1: DATA: | J1: ='228'!J1 -> 46204 | L1: TÉCNICO RESP. | N1: ='228'!N1 -> ENG. THIAGO TORQUATO
A2: RODOVIAS NÃO PAVIMENTADAS
A3: FICHA DE INSPEÇÃO: | B3: =TT!C5 -> RODOVIA TO-296 - TRECHO JAÚ DO TOCANTINS - SÃO SALVADOR DO TOCANTINS | L3: REGIÃO: | N3: 12
A5: S.R.E. | B5: SENTIDO | C5: INÍCIO (KM) | D5: FIM (KM) | E5: CONDIÇÃO DA PLATAFORMA | I5: DRENAGEM SUPERFICIAL | L5: OBSERV.
E6: BOM | F6: REG. (ATÉ 10 IRR./KM) | G6: RUÍM (+ 10 IRR./KM) | H6: PÉSSIMA (ATOLEIRO/PTO. CRÍTICO) | I6: LIMPA | J6: OBSTRUÍDA | K6: AUSENTE
A7: 296ETO0240 | B7: C | C7: 0 | D7: 6.3 | E7: X | I7: X
C8: 6.3 | D8: 22.4 | E8: X | F8: X | I8: X
A10: 296ETO0250 | B10: C | C10: 0 | D10: 7.66 | E10: X | I10: X
A11: 296ETO0260 | B11: C | C11: 0 | D11: 3.2 | E11: X | I11: X
C12: =D11 -> 3.2 | D12: 26 | E12: X | I12: X
C13: =D12 -> 26 | D13: 27.7 | E13: X | I13: X
C14: =D13 -> 27.7 | D14: 43.1 | I14: X
C15: =D14 -> 43.1 | D15: 51.63 | E15: X | I15: X
E36: =IF(E7="X",(D7-C7),"0") -> 6.3 | F36: =IF(F7="X",(D7-C7),"0") -> 0 | G36: =IF(G7="X",(D7-C7),"0") -> 0 | H36: =IF(H7="X",(D7-C7),"0") -> 0 | I36: =IF(I7="X",(D7-C7),"0") -> 6.3 | J36: =IF(J7="X",(D7-C7),"0") -> 0 | K36: =IF(K7="X",(D7-C7),"0") -> 0
E37: =IF(E8="X",(D8-C8),"0") -> 16.1 | F37: =IF(F8="X",(D8-C8),"0") -> 16.1 | G37: =IF(G8="X",(D8-C8),"0") -> 0 | H37: =IF(H8="X",(D8-C8),"0") -> 0 | I37: =IF(I8="X",(D8-C8),"0") -> 16.1 | J37: =IF(J8="X",(D8-C8),"0") -> 0 | K37: =IF(K8="X",(D8-C8),"0") -> 0
E38: =IF(E9="X",(D9-C9),"0") -> 0 | F38: =IF(F9="X",(D9-C9),"0") -> 0 | G38: =IF(G9="X",(D9-C9),"0") -> 0 | H38: =IF(H9="X",(D9-C9),"0") -> 0 | I38: =IF(I9="X",(D9-C9),"0") -> 0 | J38: =IF(J9="X",(D9-C9),"0") -> 0 | K38: =IF(K9="X",(D9-C9),"0") -> 0
E39: =IF(E10="X",(D10-C10),"0") -> 7.66 | F39: =IF(F10="X",(D10-C10),"0") -> 0 | G39: =IF(G10="X",(D10-C10),"0") -> 0 | H39: =IF(H10="X",(D10-C10),"0") -> 0 | I39: =IF(I10="X",(D10-C10),"0") -> 7.66 | J39: =IF(J10="X",(D10-C10),"0") -> 0 | K39: =IF(K10="X",(D10-C10),"0") -> 0
E40: =IF(E11="X",(D11-C11),"0") -> 3.2 | F40: =IF(F11="X",(D11-C11),"0") -> 0 | G40: =IF(G11="X",(D11-C11),"0") -> 0 | H40: =IF(H11="X",(D11-C11),"0") -> 0 | I40: =IF(I11="X",(D11-C11),"0") -> 3.2 | J40: =IF(J11="X",(D11-C11),"0") -> 0 | K40: =IF(K11="X",(D11-C11),"0") -> 0
E41: =IF(E12="X",(D12-C12),"0") -> 22.8 | F41: =IF(F12="X",(D12-C12),"0") -> 0 | G41: =IF(G12="X",(D12-C12),"0") -> 0 | H41: =IF(H12="X",(D12-C12),"0") -> 0 | I41: =IF(I12="X",(D12-C12),"0") -> 22.8 | J41: =IF(J12="X",(D12-C12),"0") -> 0 | K41: =IF(K12="X",(D12-C12),"0") -> 0
E42: =IF(E13="X",(D13-C13),"0") -> 1.7 | F42: =IF(F13="X",(D13-C13),"0") -> 0 | G42: =IF(G13="X",(D13-C13),"0") -> 0 | H42: =IF(H13="X",(D13-C13),"0") -> 0 | I42: =IF(I13="X",(D13-C13),"0") -> 1.7 | J42: =IF(J13="X",(D13-C13),"0") -> 0 | K42: =IF(K13="X",(D13-C13),"0") -> 0
E43: =IF(E14="X",(D14-C14),"0") -> 0 | F43: =IF(F14="X",(D14-C14),"0") -> 0 | G43: =IF(G14="X",(D14-C14),"0") -> 0 | H43: =IF(H14="X",(D14-C14),"0") -> 0 | I43: =IF(I14="X",(D14-C14),"0") -> 15.4 | J43: =IF(J14="X",(D14-C14),"0") -> 0 | K43: =IF(K14="X",(D14-C14),"0") -> 0
E44: =IF(E15="X",(D15-C15),"0") -> 8.53 | F44: =IF(F15="X",(D15-C15),"0") -> 0 | G44: =IF(G15="X",(D15-C15),"0") -> 0 | H44: =IF(H15="X",(D15-C15),"0") -> 0 | I44: =IF(I15="X",(D15-C15),"0") -> 8.53 | J44: =IF(J15="X",(D15-C15),"0") -> 0 | K44: =IF(K15="X",(D15-C15),"0") -> 0
E45: =IF(E16="X",(D16-C16),"0") -> 0 | F45: =IF(F16="X",(D16-C16),"0") -> 0 | G45: =IF(G16="X",(D16-C16),"0") -> 0 | H45: =IF(H16="X",(D16-C16),"0") -> 0 | I45: =IF(I16="X",(D16-C16),"0") -> 0 | J45: =IF(J16="X",(D16-C16),"0") -> 0 | K45: =IF(K16="X",(D16-C16),"0") -> 0
E46: =IF(E17="X",(D17-C17),"0") -> 0 | F46: =IF(F17="X",(D17-C17),"0") -> 0 | G46: =IF(G17="X",(D17-C17),"0") -> 0 | H46: =IF(H17="X",(D17-C17),"0") -> 0 | I46: =IF(I17="X",(D17-C17),"0") -> 0 | J46: =IF(J17="X",(D17-C17),"0") -> 0 | K46: =IF(K17="X",(D17-C17),"0") -> 0
E47: =IF(E18="X",(D18-C18),"0") -> 0 | F47: =IF(F18="X",(D18-C18),"0") -> 0 | G47: =IF(G18="X",(D18-C18),"0") -> 0 | H47: =IF(H18="X",(D18-C18),"0") -> 0 | I47: =IF(I18="X",(D18-C18),"0") -> 0 | J47: =IF(J18="X",(D18-C18),"0") -> 0 | K47: =IF(K18="X",(D18-C18),"0") -> 0
... E61: =IF(E32="X",(D32-C32),"0") -> 0 | F61: =IF(F32="X",(D32-C32),"0") -> 0 | G61: =IF(G32="X",(D32-C32),"0") -> 0 | H61: =IF(H32="X",(D32-C32),"0") -> 0 | I61: =IF(I32="X",(D32-C32),"0") -> 0 | J61: =IF(J32="X",(D32-C32),"0") -> 0 | K61: =IF(K32="X",(D32-C32),"0") -> 0
E62: =SUM(E36:E61) -> 66.29 | F62: =SUM(F36:F61) -> 16.1 | G62: =SUM(G36:G61) -> 0 | H62: =SUM(H36:H61) -> 0 | I62: =SUM(I36:I61) -> 81.69 | J62: =SUM(J36:J61) -> 0 | K62: =SUM(K36:K61) -> 0

Sheet 231
A1: PROGRAMA DE MANUTENÇÃORODOVIÁRIA | I1: DATA: | J1: ='228'!J1 -> 46204 | L1: TÉCNICO RESP. | N1: ='228'!N1 -> ENG. THIAGO TORQUATO
A2: RODOVIAS NÃO PAVIMENTADAS
A3: FICHA DE INSPEÇÃO: | B3: =TT!C6 -> RODOVIA TO-365 - TRECHO IPUEIRAS - SILVANÓPOLIS | L3: REGIÃO: | N3: 12
A5: S.R.E. | B5: SENTIDO | C5: INÍCIO (KM) | D5: FIM (KM) | E5: CONDIÇÃO DA PLATAFORMA | I5: DRENAGEM SUPERFICIAL | L5: OBSERV.
E6: BOM | F6: REG. (ATÉ 10 IRR./KM) | G6: RUÍM (+ 10 IRR./KM) | H6: PÉSSIMA (ATOLEIRO/PTO. CRÍTICO) | I6: LIMPA | J6: OBSTRUÍDA | K6: AUSENTE
A7: 365ETO0170 | B7: D | C7: 0 | D7: 3.3 | E7: X | I7: X
C8: =D7 -> 3.3 | D8: 3.4 | E8: X | I8: X
C9: =D8 -> 3.4 | D9: 3.9 | E9: X | I9: X
C10: =D9 -> 3.9 | D10: 15.4 | E10: X | I10: X
C11: =D10 -> 15.4 | D11: 15.9 | E11: X | I11: X
C12: =D11 -> 15.9 | D12: 20.3 | E12: X | I12: X
C13: =D12 -> 20.3 | D13: 20.7 | E13: X | I13: X
C14: =D13 -> 20.7 | D14: 21.3 | E14: X | I14: X
C15: =D14 -> 21.3 | D15: 28 | E15: X | I15: X
C16: =D15 -> 28 | D16: 34.25 | E16: X | I16: X
A18: 365ETO0180 | B18: D | C18: 0 | D18: 5.1 | E18: X | I18: X
C19: =D18 -> 5.1 | D19: 5.4 | E19: X | I19: X
C20: =D19 -> 5.4 | D20: 6.2 | E20: X | I20: X
A22: 365ETO0190 | B22: D | C22: 0 | D22: 1.2 | E22: X | I22: X
C23: =D22 -> 1.2 | D23: 5.33 | E23: X | I23: X
E36: =IF(E7="X",(D7-C7),"0") -> 3.3 | F36: =IF(F7="X",(D7-C7),"0") -> 0 | G36: =IF(G7="X",(D7-C7),"0") -> 0 | H36: =IF(H7="X",(D7-C7),"0") -> 0 | I36: =IF(I7="X",(D7-C7),"0") -> 3.3 | J36: =IF(J7="X",(D7-C7),"0") -> 0 | K36: =IF(K7="X",(D7-C7),"0") -> 0
E37: =IF(E8="X",(D8-C8),"0") -> 0.1 | F37: =IF(F8="X",(D8-C8),"0") -> 0 | G37: =IF(G8="X",(D8-C8),"0") -> 0 | H37: =IF(H8="X",(D8-C8),"0") -> 0 | I37: =IF(I8="X",(D8-C8),"0") -> 0.1 | J37: =IF(J8="X",(D8-C8),"0") -> 0 | K37: =IF(K8="X",(D8-C8),"0") -> 0
E38: =IF(E9="X",(D9-C9),"0") -> 0.5 | F38: =IF(F9="X",(D9-C9),"0") -> 0 | G38: =IF(G9="X",(D9-C9),"0") -> 0 | H38: =IF(H9="X",(D9-C9),"0") -> 0 | I38: =IF(I9="X",(D9-C9),"0") -> 0.5 | J38: =IF(J9="X",(D9-C9),"0") -> 0 | K38: =IF(K9="X",(D9-C9),"0") -> 0
E39: =IF(E10="X",(D10-C10),"0") -> 11.5 | F39: =IF(F10="X",(D10-C10),"0") -> 0 | G39: =IF(G10="X",(D10-C10),"0") -> 0 | H39: =IF(H10="X",(D10-C10),"0") -> 0 | I39: =IF(I10="X",(D10-C10),"0") -> 11.5 | J39: =IF(J10="X",(D10-C10),"0") -> 0 | K39: =IF(K10="X",(D10-C10),"0") -> 0
E40: =IF(E11="X",(D11-C11),"0") -> 0.5 | F40: =IF(F11="X",(D11-C11),"0") -> 0 | G40: =IF(G11="X",(D11-C11),"0") -> 0 | H40: =IF(H11="X",(D11-C11),"0") -> 0 | I40: =IF(I11="X",(D11-C11),"0") -> 0.5 | J40: =IF(J11="X",(D11-C11),"0") -> 0 | K40: =IF(K11="X",(D11-C11),"0") -> 0
E41: =IF(E12="X",(D12-C12),"0") -> 4.4 | F41: =IF(F12="X",(D12-C12),"0") -> 0 | G41: =IF(G12="X",(D12-C12),"0") -> 0 | H41: =IF(H12="X",(D12-C12),"0") -> 0 | I41: =IF(I12="X",(D12-C12),"0") -> 4.4 | J41: =IF(J12="X",(D12-C12),"0") -> 0 | K41: =IF(K12="X",(D12-C12),"0") -> 0
E42: =IF(E13="X",(D13-C13),"0") -> 0.4 | F42: =IF(F13="X",(D13-C13),"0") -> 0 | G42: =IF(G13="X",(D13-C13),"0") -> 0 | H42: =IF(H13="X",(D13-C13),"0") -> 0 | I42: =IF(I13="X",(D13-C13),"0") -> 0.4 | J42: =IF(J13="X",(D13-C13),"0") -> 0 | K42: =IF(K13="X",(D13-C13),"0") -> 0
E43: =IF(E14="X",(D14-C14),"0") -> 0.6 | F43: =IF(F14="X",(D14-C14),"0") -> 0 | G43: =IF(G14="X",(D14-C14),"0") -> 0 | H43: =IF(H14="X",(D14-C14),"0") -> 0 | I43: =IF(I14="X",(D14-C14),"0") -> 0.6 | J43: =IF(J14="X",(D14-C14),"0") -> 0 | K43: =IF(K14="X",(D14-C14),"0") -> 0
E44: =IF(E15="X",(D15-C15),"0") -> 6.7 | F44: =IF(F15="X",(D15-C15),"0") -> 0 | G44: =IF(G15="X",(D15-C15),"0") -> 0 | H44: =IF(H15="X",(D15-C15),"0") -> 0 | I44: =IF(I15="X",(D15-C15),"0") -> 6.7 | J44: =IF(J15="X",(D15-C15),"0") -> 0 | K44: =IF(K15="X",(D15-C15),"0") -> 0
E45: =IF(E16="X",(D16-C16),"0") -> 6.25 | F45: =IF(F16="X",(D16-C16),"0") -> 0 | G45: =IF(G16="X",(D16-C16),"0") -> 0 | H45: =IF(H16="X",(D16-C16),"0") -> 0 | I45: =IF(I16="X",(D16-C16),"0") -> 6.25 | J45: =IF(J16="X",(D16-C16),"0") -> 0 | K45: =IF(K16="X",(D16-C16),"0") -> 0
E46: =IF(E17="X",(D17-C17),"0") -> 0 | F46: =IF(F17="X",(D17-C17),"0") -> 0 | G46: =IF(G17="X",(D17-C17),"0") -> 0 | H46: =IF(H17="X",(D17-C17),"0") -> 0 | I46: =IF(I17="X",(D17-C17),"0") -> 0 | J46: =IF(J17="X",(D17-C17),"0") -> 0 | K46: =IF(K17="X",(D17-C17),"0") -> 0
E47: =IF(E18="X",(D18-C18),"0") -> 5.1 | F47: =IF(F18="X",(D18-C18),"0") -> 0 | G47: =IF(G18="X",(D18-C18),"0") -> 0 | H47: =IF(H18="X",(D18-C18),"0") -> 0 | I47: =IF(I18="X",(D18-C18),"0") -> 5.1 | J47: =IF(J18="X",(D18-C18),"0") -> 0 | K47: =IF(K18="X",(D18-C18),"0") -> 0
... E61: =IF(E32="X",(D32-C32),"0") -> 0 | F61: =IF(F32="X",(D32-C32),"0") -> 0 | G61: =IF(G32="X",(D32-C32),"0") -> 0 | H61: =IF(H32="X",(D32-C32),"0") -> 0 | I61: =IF(I32="X",(D32-C32),"0") -> 0 | J61: =IF(J32="X",(D32-C32),"0") -> 0 | K61: =IF(K32="X",(D32-C32),"0") -> 0
E62: =SUM(E36:E61) -> 45.78 | F62: =SUM(F36:F61) -> 0 | G62: =SUM(G36:G61) -> 0 | H62: =SUM(H36:H61) -> 0 | I62: =SUM(I36:I61) -> 45.78 | J62: =SUM(J36:J61) -> 0 | K62: =SUM(K36:K61) -> 0

Sheet 232
A1: PROGRAMA DE MANUTENÇÃORODOVIÁRIA | I1: DATA: | J1: ='228'!J1 -> 46204 | L1: TÉCNICO RESP. | N1: ='228'!N1 -> ENG. THIAGO TORQUATO
A2: RODOVIAS NÃO PAVIMENTADAS
A3: FICHA DE INSPEÇÃO: | B3: =TT!C7 -> RODOVIA TO-373 - TRECHO ENTR. TO-365 (BALSA) - SÃO MIGUEL - LAGOA DO ROMÃO -ENTR. TO-280 | L3: REGIÃO: | N3: 12
A5: S.R.E. | B5: SENTIDO | C5: INÍCIO (KM) | D5: FIM (KM) | E5: CONDIÇÃO DA PLATAFORMA | I5: DRENAGEM SUPERFICIAL | L5: OBSERV.
E6: BOM | F6: REG. (ATÉ 10 IRR./KM) | G6: RUÍM (+ 10 IRR./KM) | H6: PÉSSIMA (ATOLEIRO/PTO. CRÍTICO) | I6: LIMPA | J6: OBSTRUÍDA | K6: AUSENTE
A7: 373ETO0120 | B7: D | C7: 0 | D7: 25.93 | E7: X | K7: X
A9: 373ETO0130 | B9: D | C9: 0 | D9: 39.1 | E9: X | K9: X
A13: 373ETO0140 | B13: D | C13: 0 | D13: 1.55 | E13: X | K13: X
A16: 373ETO0150 | B16: D | C16: 0 | D16: 20.95 | E16: X | I16: X
E36: =IF(E7="X",(D7-C7),"0") -> 25.93 | F36: =IF(F7="X",(D7-C7),"0") -> 0 | G36: =IF(G7="X",(D7-C7),"0") -> 0 | H36: =IF(H7="X",(D7-C7),"0") -> 0 | I36: =IF(I7="X",(D7-C7),"0") -> 0 | J36: =IF(J7="X",(D7-C7),"0") -> 0 | K36: =IF(K7="X",(D7-C7),"0") -> 25.93
E37: =IF(E8="X",(D8-C8),"0") -> 0 | F37: =IF(F8="X",(D8-C8),"0") -> 0 | G37: =IF(G8="X",(D8-C8),"0") -> 0 | H37: =IF(H8="X",(D8-C8),"0") -> 0 | I37: =IF(I8="X",(D8-C8),"0") -> 0 | J37: =IF(J8="X",(D8-C8),"0") -> 0 | K37: =IF(K8="X",(D8-C8),"0") -> 0
E38: =IF(E9="X",(D9-C9),"0") -> 39.1 | F38: =IF(F9="X",(D9-C9),"0") -> 0 | G38: =IF(G9="X",(D9-C9),"0") -> 0 | H38: =IF(H9="X",(D9-C9),"0") -> 0 | I38: =IF(I9="X",(D9-C9),"0") -> 0 | J38: =IF(J9="X",(D9-C9),"0") -> 0 | K38: =IF(K9="X",(D9-C9),"0") -> 39.1
E39: =IF(E10="X",(D10-C10),"0") -> 0 | F39: =IF(F10="X",(D10-C10),"0") -> 0 | G39: =IF(G10="X",(D10-C10),"0") -> 0 | H39: =IF(H10="X",(D10-C10),"0") -> 0 | I39: =IF(I10="X",(D10-C10),"0") -> 0 | J39: =IF(J10="X",(D10-C10),"0") -> 0 | K39: =IF(K10="X",(D10-C10),"0") -> 0
E40: =IF(E11="X",(D11-C11),"0") -> 0 | F40: =IF(F11="X",(D11-C11),"0") -> 0 | G40: =IF(G11="X",(D11-C11),"0") -> 0 | H40: =IF(H11="X",(D11-C11),"0") -> 0 | I40: =IF(I11="X",(D11-C11),"0") -> 0 | J40: =IF(J11="X",(D11-C11),"0") -> 0 | K40: =IF(K11="X",(D11-C11),"0") -> 0
E41: =IF(E12="X",(D12-C12),"0") -> 0 | F41: =IF(F12="X",(D12-C12),"0") -> 0 | G41: =IF(G12="X",(D12-C12),"0") -> 0 | H41: =IF(H12="X",(D12-C12),"0") -> 0 | I41: =IF(I12="X",(D12-C12),"0") -> 0 | J41: =IF(J12="X",(D12-C12),"0") -> 0 | K41: =IF(K12="X",(D12-C12),"0") -> 0
E42: =IF(E13="X",(D13-C13),"0") -> 1.55 | F42: =IF(F13="X",(D13-C13),"0") -> 0 | G42: =IF(G13="X",(D13-C13),"0") -> 0 | H42: =IF(H13="X",(D13-C13),"0") -> 0 | I42: =IF(I13="X",(D13-C13),"0") -> 0 | J42: =IF(J13="X",(D13-C13),"0") -> 0 | K42: =IF(K13="X",(D13-C13),"0") -> 1.55
E43: =IF(E14="X",(D14-C14),"0") -> 0 | F43: =IF(F14="X",(D14-C14),"0") -> 0 | G43: =IF(G14="X",(D14-C14),"0") -> 0 | H43: =IF(H14="X",(D14-C14),"0") -> 0 | I43: =IF(I14="X",(D14-C14),"0") -> 0 | J43: =IF(J14="X",(D14-C14),"0") -> 0 | K43: =IF(K14="X",(D14-C14),"0") -> 0
E44: =IF(E15="X",(D15-C15),"0") -> 0 | F44: =IF(F15="X",(D15-C15),"0") -> 0 | G44: =IF(G15="X",(D15-C15),"0") -> 0 | H44: =IF(H15="X",(D15-C15),"0") -> 0 | I44: =IF(I15="X",(D15-C15),"0") -> 0 | J44: =IF(J15="X",(D15-C15),"0") -> 0 | K44: =IF(K15="X",(D15-C15),"0") -> 0
E45: =IF(E16="X",(D16-C16),"0") -> 20.95 | F45: =IF(F16="X",(D16-C16),"0") -> 0 | G45: =IF(G16="X",(D16-C16),"0") -> 0 | H45: =IF(H16="X",(D16-C16),"0") -> 0 | I45: =IF(I16="X",(D16-C16),"0") -> 20.95 | J45: =IF(J16="X",(D16-C16),"0") -> 0 | K45: =IF(K16="X",(D16-C16),"0") -> 0
E46: =IF(E17="X",(D17-C17),"0") -> 0 | F46: =IF(F17="X",(D17-C17),"0") -> 0 | G46: =IF(G17="X",(D17-C17),"0") -> 0 | H46: =IF(H17="X",(D17-C17),"0") -> 0 | I46: =IF(I17="X",(D17-C17),"0") -> 0 | J46: =IF(J17="X",(D17-C17),"0") -> 0 | K46: =IF(K17="X",(D17-C17),"0") -> 0
E47: =IF(E18="X",(D18-C18),"0") -> 0 | F47: =IF(F18="X",(D18-C18),"0") -> 0 | G47: =IF(G18="X",(D18-C18),"0") -> 0 | H47: =IF(H18="X",(D18-C18),"0") -> 0 | I47: =IF(I18="X",(D18-C18),"0") -> 0 | J47: =IF(J18="X",(D18-C18),"0") -> 0 | K47: =IF(K18="X",(D18-C18),"0") -> 0
... E61: =IF(E32="X",(D32-C32),"0") -> 0 | F61: =IF(F32="X",(D32-C32),"0") -> 0 | G61: =IF(G32="X",(D32-C32),"0") -> 0 | H61: =IF(H32="X",(D32-C32),"0") -> 0 | I61: =IF(I32="X",(D32-C32),"0") -> 0 | J61: =IF(J32="X",(D32-C32),"0") -> 0 | K61: =IF(K32="X",(D32-C32),"0") -> 0
E62: =SUM(E36:E61) -> 87.53 | F62: =SUM(F36:F61) -> 0 | G62: =SUM(G36:G61) -> 0 | H62: =SUM(H36:H61) -> 0 | I62: =SUM(I36:I61) -> 20.95 | J62: =SUM(J36:J61) -> 0 | K62: =SUM(K36:K61) -> 66.58

Sheet 236
A1: PROGRAMA DE MANUTENÇÃORODOVIÁRIA | I1: DATA: | J1: ='228'!J1 -> 46204 | L1: TÉCNICO RESP. | N1: ='228'!N1 -> ENG. THIAGO TORQUATO
A2: RODOVIAS NÃO PAVIMENTADAS
A3: FICHA DE INSPEÇÃO: | B3: =TT!C8 -> RODOVIA TO-458 - TRECHO ENTR. TO-365 (IPUEIRAS) - ENTR. BR-010 | L3: REGIÃO: | N3: 12
A5: S.R.E. | B5: SENTIDO | C5: INÍCIO (KM) | D5: FIM (KM) | E5: CONDIÇÃO DA PLATAFORMA | I5: DRENAGEM SUPERFICIAL | L5: OBSERV.
E6: BOM | F6: REG. (ATÉ 10 IRR./KM) | G6: RUÍM (+ 10 IRR./KM) | H6: PÉSSIMA (ATOLEIRO/PTO. CRÍTICO) | I6: LIMPA | J6: OBSTRUÍDA | K6: AUSENTE
A7: 458ETO0070 | B7: D | C7: 0 | D7: =C8 -> 0.3 | F7: X | I7: X
C8: 0.3 | D8: =C9 -> 1.4 | F8: X | I8: X
C9: 1.4 | D9: =C10 -> 2.1 | G9: X | I9: X
C10: 2.1 | D10: 3 | F10: X | I10: X
A12: 458ETO0060 | B12: D | C12: 0 | D12: 2.7 | F12: X | I12: X
C13: =D12 -> 2.7 | D13: 3.2 | F13: X | I13: X
C14: =D13 -> 3.2 | D14: 4.9 | F14: X | I14: X
C15: =D14 -> 4.9 | D15: 5.1 | F15: X | I15: X
C16: =D15 -> 5.1 | D16: =C17 -> 6.6 | G16: X | I16: X
C17: 6.6 | D17: =C18 -> 6.9 | F17: X | I17: X
C18: 6.9 | D18: =C19 -> 9.8 | G18: X | I18: X
C19: 9.8 | D19: =C20 -> 9.9 | G19: X | I19: X
C20: 9.9 | D20: =C21 -> 10.9 | F20: X | I20: X
C21: 10.9 | D21: 16.3 | G21: X | I21: X
C22: 16.2 | D22: 16.4 | F22: X | I22: X
C23: 16.4 | D23: 21.46 | F23: X | I23: X
C24: 21.6 | D24: =C25 -> 21.7 | G24: X | I24: X
C25: 21.7 | D25: 22 | G25: X | I25: X
A27: 458ETO0050 | B27: D | C27: 0 | D27: 6.2 | F27: X | I27: X
C28: =D27 -> 6.2 | D28: 6.3 | F28: X
C29: =D28 -> 6.3 | D29: 8.4 | G29: X | I29: X
C30: =D29 -> 8.4 | D30: 8.5 | G30: X | I30: X
C31: =D30 -> 8.5 | D31: 9.48 | F31: X | I31: X
E36: =IF(E7="X",(D7-C7),"0") -> 0 | F36: =IF(F7="X",(D7-C7),"0") -> 0.3 | G36: =IF(G7="X",(D7-C7),"0") -> 0 | H36: =IF(H7="X",(D7-C7),"0") -> 0 | I36: =IF(I7="X",(D7-C7),"0") -> 0.3 | J36: =IF(J7="X",(D7-C7),"0") -> 0 | K36: =IF(K7="X",(D7-C7),"0") -> 0
E37: =IF(E8="X",(D8-C8),"0") -> 0 | F37: =IF(F8="X",(D8-C8),"0") -> 1.1 | G37: =IF(G8="X",(D8-C8),"0") -> 0 | H37: =IF(H8="X",(D8-C8),"0") -> 0 | I37: =IF(I8="X",(D8-C8),"0") -> 1.1 | J37: =IF(J8="X",(D8-C8),"0") -> 0 | K37: =IF(K8="X",(D8-C8),"0") -> 0
E38: =IF(E9="X",(D9-C9),"0") -> 0 | F38: =IF(F9="X",(D9-C9),"0") -> 0 | G38: =IF(G9="X",(D9-C9),"0") -> 0.7 | H38: =IF(H9="X",(D9-C9),"0") -> 0 | I38: =IF(I9="X",(D9-C9),"0") -> 0.7 | J38: =IF(J9="X",(D9-C9),"0") -> 0 | K38: =IF(K9="X",(D9-C9),"0") -> 0
E39: =IF(E10="X",(D10-C10),"0") -> 0 | F39: =IF(F10="X",(D10-C10),"0") -> 0.9 | G39: =IF(G10="X",(D10-C10),"0") -> 0 | H39: =IF(H10="X",(D10-C10),"0") -> 0 | I39: =IF(I10="X",(D10-C10),"0") -> 0.9 | J39: =IF(J10="X",(D10-C10),"0") -> 0 | K39: =IF(K10="X",(D10-C10),"0") -> 0
E40: =IF(E11="X",(D11-C11),"0") -> 0 | F40: =IF(F11="X",(D11-C11),"0") -> 0 | G40: =IF(G11="X",(D11-C11),"0") -> 0 | H40: =IF(H11="X",(D11-C11),"0") -> 0 | I40: =IF(I11="X",(D11-C11),"0") -> 0 | J40: =IF(J11="X",(D11-C11),"0") -> 0 | K40: =IF(K11="X",(D11-C11),"0") -> 0
E41: =IF(E12="X",(D12-C12),"0") -> 0 | F41: =IF(F12="X",(D12-C12),"0") -> 2.7 | G41: =IF(G12="X",(D12-C12),"0") -> 0 | H41: =IF(H12="X",(D12-C12),"0") -> 0 | I41: =IF(I12="X",(D12-C12),"0") -> 2.7 | J41: =IF(J12="X",(D12-C12),"0") -> 0 | K41: =IF(K12="X",(D12-C12),"0") -> 0
E42: =IF(E13="X",(D13-C13),"0") -> 0 | F42: =IF(F13="X",(D13-C13),"0") -> 0.5 | G42: =IF(G13="X",(D13-C13),"0") -> 0 | H42: =IF(H13="X",(D13-C13),"0") -> 0 | I42: =IF(I13="X",(D13-C13),"0") -> 0.5 | J42: =IF(J13="X",(D13-C13),"0") -> 0 | K42: =IF(K13="X",(D13-C13),"0") -> 0
E43: =IF(E14="X",(D14-C14),"0") -> 0 | F43: =IF(F14="X",(D14-C14),"0") -> 1.7 | G43: =IF(G14="X",(D14-C14),"0") -> 0 | H43: =IF(H14="X",(D14-C14),"0") -> 0 | I43: =IF(I14="X",(D14-C14),"0") -> 1.7 | J43: =IF(J14="X",(D14-C14),"0") -> 0 | K43: =IF(K14="X",(D14-C14),"0") -> 0
E44: =IF(E15="X",(D15-C15),"0") -> 0 | F44: =IF(F15="X",(D15-C15),"0") -> 0.2 | G44: =IF(G15="X",(D15-C15),"0") -> 0 | H44: =IF(H15="X",(D15-C15),"0") -> 0 | I44: =IF(I15="X",(D15-C15),"0") -> 0.2 | J44: =IF(J15="X",(D15-C15),"0") -> 0 | K44: =IF(K15="X",(D15-C15),"0") -> 0
E45: =IF(E16="X",(D16-C16),"0") -> 0 | F45: =IF(F16="X",(D16-C16),"0") -> 0 | G45: =IF(G16="X",(D16-C16),"0") -> 1.5 | H45: =IF(H16="X",(D16-C16),"0") -> 0 | I45: =IF(I16="X",(D16-C16),"0") -> 1.5 | J45: =IF(J16="X",(D16-C16),"0") -> 0 | K45: =IF(K16="X",(D16-C16),"0") -> 0
E46: =IF(E17="X",(D17-C17),"0") -> 0 | F46: =IF(F17="X",(D17-C17),"0") -> 0.3 | G46: =IF(G17="X",(D17-C17),"0") -> 0 | H46: =IF(H17="X",(D17-C17),"0") -> 0 | I46: =IF(I17="X",(D17-C17),"0") -> 0.3 | J46: =IF(J17="X",(D17-C17),"0") -> 0 | K46: =IF(K17="X",(D17-C17),"0") -> 0
E47: =IF(E18="X",(D18-C18),"0") -> 0 | F47: =IF(F18="X",(D18-C18),"0") -> 0 | G47: =IF(G18="X",(D18-C18),"0") -> 2.9 | H47: =IF(H18="X",(D18-C18),"0") -> 0 | I47: =IF(I18="X",(D18-C18),"0") -> 2.9 | J47: =IF(J18="X",(D18-C18),"0") -> 0 | K47: =IF(K18="X",(D18-C18),"0") -> 0
...

Sheet 238
A1: PROGRAMA DE MANUTENÇÃORODOVIÁRIA | I1: DATA: | J1: ='228'!J1 -> 46204 | L1: TÉCNICO RESP. | N1: ='228'!N1 -> ENG. THIAGO TORQUATO
A2: RODOVIAS NÃO PAVIMENTADAS
A3: FICHA DE INSPEÇÃO: | B3: =TT!C10 -> RODOVIA TO-482 - TRECHO: ENTR. TO-280 (SÃO VALÉRIO DE NATIVIDADE) / ENTR. TO-458 | L3: REGIÃO: | N3: 12
A5: S.R.E. | B5: SENTIDO | C5: INÍCIO (KM) | D5: FIM (KM) | E5: CONDIÇÃO DA PLATAFORMA | I5: DRENAGEM SUPERFICIAL | L5: OBSERV.
E6: BOM | F6: REG. (ATÉ 10 IRR./KM) | G6: RUÍM (+ 10 IRR./KM) | H6: PÉSSIMA (ATOLEIRO/PTO. CRÍTICO) | I6: LIMPA | J6: OBSTRUÍDA | K6: AUSENTE
A7: 482ETO0010 | B7: D | C7: 0 | D7: 4 | E7: X | I7: X
C8: =D7 -> 4 | D8: 4.8 | E8: X | I8: X
C9: =D8 -> 4.8 | D9: 7.4 | E9: X | I9: X
C10: =D9 -> 7.4 | D10: 7.8 | E10: X | I10: X
C11: =D10 -> 7.8 | D11: 8.3 | E11: X | I11: X
C12: =D11 -> 8.3 | D12: 9.2 | E12: X | I12: X
C13: =D12 -> 9.2 | D13: 9.4 | E13: X | I13: X
C14: =D13 -> 9.4 | D14: 12.3 | E14: X | I14: X
C15: =D14 -> 12.3 | D15: 14.2 | E15: X | I15: X
C16: =D15 -> 14.2 | D16: 15.1 | E16: X | I16: X
C17: =D16 -> 15.1 | D17: 18.2 | E17: X | I17: X
C18: =D17 -> 18.2 | D18: 20.3 | E18: X | I18: X
C19: =D18 -> 20.3 | D19: 21.7 | E19: X | I19: X
A21: 482ETO0020 | B21: D | C21: 0 | D21: 0.8 | I21: X
C22: =D21 -> 0.8 | D22: 1.8 | E22: X | I22: X
C23: =D22 -> 1.8 | D23: 3.1 | E23: X | I23: X
C24: =D23 -> 3.1 | D24: 3.8 | E24: X | I24: X
C25: =D24 -> 3.8 | D25: 13 | E25: X | I25: X
C26: =D25 -> 13 | D26: 13.5 | E26: X | I26: X
C27: =D26 -> 13.5 | D27: 13.6 | E27: X | I27: X
C28: =D27 -> 13.6 | D28: 13.7 | E28: X | I28: X
C29: =D28 -> 13.7 | D29: 14.4 | E29: X | I29: X
C30: =D29 -> 14.4 | D30: 17.37 | E30: X | I30: X
A32: 482ETO0030 | B32: D | C32: 0 | D32: 1 | E32: X | I32: X
C33: =D32 -> 1 | D33: 1.5 | E33: X | I33: X
C34: =D33 -> 1.5 | D34: 10.5 | E34: X | I34: X
C35: =D34 -> 10.5 | D35: 16.6 | E35: X | I35: X
C36: =D35 -> 16.6 | D36: 17.7 | E36: X | I36: X
C37: =D36 -> 17.7 | D37: 33.4 | E37: X | I37: X
C38: =D37 -> 33.4 | D38: 34.49 | E38: X | I38: X
E41: =IF(E7="X",(D7-C7),"0") -> 4 | F41: =IF(F7="X",(D7-C7),"0") -> 0 | G41: =IF(G7="X",(D7-C7),"0") -> 0 | H41: =IF(H7="X",(D7-C7),"0") -> 0 | I41: =IF(I7="X",(D7-C7),"0") -> 4 | J41: =IF(J7="X",(D7-C7),"0") -> 0 | K41: =IF(K7="X",(D7-C7),"0") -> 0
E42: =IF(E8="X",(D8-C8),"0") -> 0.8 | F42: =IF(F8="X",(D8-C8),"0") -> 0 | G42: =IF(G8="X",(D8-C8),"0") -> 0 | H42: =IF(H8="X",(D8-C8),"0") -> 0 | I42: =IF(I8="X",(D8-C8),"0") -> 0.8 | J42: =IF(J8="X",(D8-C8),"0") -> 0 | K42: =IF(K8="X",(D8-C8),"0") -> 0
E43: =IF(E9="X",(D9-C9),"0") -> 2.6 | F43: =IF(F9="X",(D9-C9),"0") -> 0 | G43: =IF(G9="X",(D9-C9),"0") -> 0 | H43: =IF(H9="X",(D9-C9),"0") -> 0 | I43: =IF(I9="X",(D9-C9),"0") -> 2.6 | J43: =IF(J9="X",(D9-C9),"0") -> 0 | K43: =IF(K9="X",(D9-C9),"0") -> 0
E44: =IF(E10="X",(D10-C10),"0") -> 0.4 | F44: =IF(F10="X",(D10-C10),"0") -> 0 | G44: =IF(G10="X",(D10-C10),"0") -> 0 | H44: =IF(H10="X",(D10-C10),"0") -> 0 | I44: =IF(I10="X",(D10-C10),"0") -> 0.4 | J44: =IF(J10="X",(D10-C10),"0") -> 0 | K44: =IF(K10="X",(D10-C10),"0") -> 0
E45: =IF(E11="X",(D11-C11),"0") -> 0.5 | F45: =IF(F11="X",(D11-C11),"0") -> 0 | G45: =IF(G11="X",(D11-C11),"0") -> 0 | H45: =IF(H11="X",(D11-C11),"0") -> 0 | I45: =IF(I11="X",(D11-C11),"0") -> 0.5 | J45: =IF(J11="X",(D11-C11),"0") -> 0 | K45: =IF(K11="X",(D11-C11),"0") -> 0
...

Sheet 237
A1: PROGRAMA DE MANUTENÇÃORODOVIÁRIA | I1: DATA: | J1: ='228'!J1 -> 46204 | L1: TÉCNICO RESP. | N1: ='228'!N1 -> ENG. THIAGO TORQUATO
A2: RODOVIAS NÃO PAVIMENTADAS
A3: FICHA DE INSPEÇÃO: | B3: =TT!C9 -> RODOVIA TO-479 - TRECHO PEIXE - POVOADO LAGOA DO ROMÃO (ENTR. TO-373) | L3: REGIÃO: | N3: 12
A5: S.R.E. | B5: SENTIDO | C5: INÍCIO (KM) | D5: FIM (KM) | E5: CONDIÇÃO DA PLATAFORMA | I5: DRENAGEM SUPERFICIAL | L5: OBSERV.
E6: BOM | F6: REG. (ATÉ 10 IRR./KM) | G6: RUÍM (+ 10 IRR./KM) | H6: PÉSSIMA (ATOLEIRO/PTO. CRÍTICO) | I6: LIMPA | J6: OBSTRUÍDA | K6: AUSENTE
A7: 479ETO0010 | B7: C | C7: 0 | D7: 26.04 | E7: X | I7: X
E36: =IF(E7="X",(D7-C7),"0") -> 26.04 | F36: =IF(F7="X",(D7-C7),"0") -> 0 | G36: =IF(G7="X",(D7-C7),"0") -> 0 | H36: =IF(H7="X",(D7-C7),"0") -> 0 | I36: =IF(I7="X",(D7-C7),"0") -> 26.04 | J36: =IF(J7="X",(D7-C7),"0") -> 0 | K36: =IF(K7="X",(D7-C7),"0") -> 0
E37: =IF(E8="X",(D8-C8),"0") -> 0 | F37: =IF(F8="X",(D8-C8),"0") -> 0 | G37: =IF(G8="X",(D8-C8),"0") -> 0 | H37: =IF(H8="X",(D8-C8),"0") -> 0 | I37: =IF(I8="X",(D8-C8),"0") -> 0 | J37: =IF(J8="X",(D8-C8),"0") -> 0 | K37: =IF(K8="X",(D8-C8),"0") -> 0
E38: =IF(E9="X",(D9-C9),"0") -> 0 | F38: =IF(F9="X",(D9-C9),"0") -> 0 | G38: =IF(G9="X",(D9-C9),"0") -> 0 | H38: =IF(H9="X",(D9-C9),"0") -> 0 | I38: =IF(I9="X",(D9-C9),"0") -> 0 | J38: =IF(J9="X",(D9-C9),"0") -> 0 | K38: =IF(K9="X",(D9-C9),"0") -> 0
E39: =IF(E10="X",(D10-C10),"0") -> 0 | F39: =IF(F10="X",(D10-C10),"0") -> 0 | G39: =IF(G10="X",(D10-C10),"0") -> 0 | H39: =IF(H10="X",(D10-C10),"0") -> 0 | I39: =IF(I10="X",(D10-C10),"0") -> 0 | J39: =IF(J10="X",(D10-C10),"0") -> 0 | K39: =IF(K10="X",(D10-C10),"0") -> 0
E40: =IF(E11="X",(D11-C11),"0") -> 0 | F40: =IF(F11="X",(D11-C11),"0") -> 0 | G40: =IF(G11="X",(D11-C11),"0") -> 0 | H40: =IF(H11="X",(D11-C11),"0") -> 0 | I40: =IF(I11="X",(D11-C11),"0") -> 0 | J40: =IF(J11="X",(D11-C11),"0") -> 0 | K40: =IF(K11="X",(D11-C11),"0") -> 0
E41: =IF(E12="X",(D12-C12),"0") -> 0 | F41: =IF(F12="X",(D12-C12),"0") -> 0 | G41: =IF(G12="X",(D12-C12),"0") -> 0 | H41: =IF(H12="X",(D12-C12),"0") -> 0 | I41: =IF(I12="X",(D12-C12),"0") -> 0 | J41: =IF(J12="X",(D12-C12),"0") -> 0 | K41: =IF(K12="X",(D12-C12),"0") -> 0
E42: =IF(E13="X",(D13-C13),"0") -> 0 | F42: =IF(F13="X",(D13-C13),"0") -> 0 | G42: =IF(G13="X",(D13-C13),"0") -> 0 | H42: =IF(H13="X",(D13-C13),"0") -> 0 | I42: =IF(I13="X",(D13-C13),"0") -> 0 | J42: =IF(J13="X",(D13-C13),"0") -> 0 | K42: =IF(K13="X",(D13-C13),"0") -> 0
E43: =IF(E14="X",(D14-C14),"0") -> 0 | F43: =IF(F14="X",(D14-C14),"0") -> 0 | G43: =IF(G14="X",(D14-C14),"0") -> 0 | H43: =IF(H14="X",(D14-C14),"0") -> 0 | I43: =IF(I14="X",(D14-C14),"0") -> 0 | J43: =IF(J14="X",(D14-C14),"0") -> 0 | K43: =IF(K14="X",(D14-C14),"0") -> 0
E44: =IF(E15="X",(D15-C15),"0") -> 0 | F44: =IF(F15="X",(D15-C15),"0") -> 0 | G44: =IF(G15="X",(D15-C15),"0") -> 0 | H44: =IF(H15="X",(D15-C15),"0") -> 0 | I44: =IF(I15="X",(D15-C15),"0") -> 0 | J44: =IF(J15="X",(D15-C15),"0") -> 0 | K44: =IF(K15="X",(D15-C15),"0") -> 0
E45: =IF(E16="X",(D16-C16),"0") -> 0 | F45: =IF(F16="X",(D16-C16),"0") -> 0 | G45: =IF(G16="X",(D16-C16),"0") -> 0 | H45: =IF(H16="X",(D16-C16),"0") -> 0 | I45: =IF(I16="X",(D16-C16),"0") -> 0 | J45: =IF(J16="X",(D16-C16),"0") -> 0 | K45: =IF(K16="X",(D16-C16),"0") -> 0
E46: =IF(E17="X",(D17-C17),"0") -> 0 | F46: =IF(F17="X",(D17-C17),"0") -> 0 | G46: =IF(G17="X",(D17-C17),"0") -> 0 | H46: =IF(H17="X",(D17-C17),"0") -> 0 | I46: =IF(I17="X",(D17-C17),"0") -> 0 | J46: =IF(J17="X",(D17-C17),"0") -> 0 | K46: =IF(K17="X",(D17-C17),"0") -> 0
E47: =IF(E18="X",(D18-C18),"0") -> 0 | F47: =IF(F18="X",(D18-C18),"0") -> 0 | G47: =IF(G18="X",(D18-C18),"0") -> 0 | H47: =IF(H18="X",(D18-C18),"0") -> 0 | I47: =IF(I18="X",(D18-C18),"0") -> 0 | J47: =IF(J18="X",(D18-C18),"0") -> 0 | K47: =IF(K18="X",(D18-C18),"0") -> 0
... E61: =IF(E32="X",(D32-C32),"0") -> 0 | F61: =IF(F32="X",(D32-C32),"0") -> 0 | G61: =IF(G32="X",(D32-C32),"0") -> 0 | H61: =IF(H32="X",(D32-C32),"0") -> 0 | I61: =IF(I32="X",(D32-C32),"0") -> 0 | J61: =IF(J32="X",(D32-C32),"0") -> 0 | K61: =IF(K32="X",(D32-C32),"0") -> 0
E62: =SUM(E36:E61) -> 26.04 | F62: =SUM(F36:F61) -> 0 | G62: =SUM(G36:G61) -> 0 | H62: =SUM(H36:H61) -> 0 | I62: =SUM(I36:I61) -> 26.04 | J62: =SUM(J36:J61) -> 0 | K62: =SUM(K36:K61) -> 0

Sheet 239
A1: PROGRAMA DE MANUTENÇÃORODOVIÁRIA | I1: DATA: | J1: ='228'!J1 -> 46204 | L1: TÉCNICO RESP. | N1: ='228'!N1 -> ENG. THIAGO TORQUATO
A2: RODOVIAS NÃO PAVIMENTADAS
A3: FICHA DE INSPEÇÃO: | B3: =TT!C11 -> RODOVIA TO-486 - TRECHO SANTA ROSA DO TOCANTINS - ENTR. TO-280 (NATIVIDADE) | L3: REGIÃO: | N3: 12
A5: S.R.E. | B5: SENTIDO | C5: INÍCIO (KM) | D5: FIM (KM) | E5: CONDIÇÃO DA PLATAFORMA | I5: DRENAGEM SUPERFICIAL | L5: OBSERV.
E6: BOM | F6: REG. (ATÉ 10 IRR./KM) | G6: RUÍM (+ 10 IRR./KM) | H6: PÉSSIMA (ATOLEIRO/PTO. CRÍTICO) | I6: LIMPA | J6: OBSTRUÍDA | K6: AUSENTE
A7: 486ETO0010 | B7: C | C7: 0 | D7: 0.6 | E7: X | I7: X
C8: =D7 -> 0.6 | D8: 1 | E8: X | I8: X
C9: =D8 -> 1 | D9: 1.5 | E9: X | I9: X
C10: =D9 -> 1.5 | D10: 1.8 | E10: X | I10: X
C11: =D10 -> 1.8 | D11: 3.7 | E11: X | I11: X
C12: =D11 -> 3.7 | D12: 6.4 | E12: X | I12: X
C13: =D12 -> 6.4 | D13: 15.7 | E13: X | I13: X
C14: =D13 -> 15.7 | D14: 15.3 | E14: X | I14: X
C15: =D14 -> 15.3 | D15: 15.6 | E15: X | I15: X
C16: =D15 -> 15.6 | D16: 61.3 | E16: X | G16: X | I16: X
C17: =D16 -> 61.3 | D17: 62.3 | E17: X | I17: X
C18: =D17 -> 62.3 | D18: 63.93 | E18: X | I18: X
E36: =IF(E7="X",(D7-C7),"0") -> 0.6 | F36: =IF(F7="X",(D7-C7),"0") -> 0 | G36: =IF(G7="X",(D7-C7),"0") -> 0 | H36: =IF(H7="X",(D7-C7),"0") -> 0 | I36: =IF(I7="X",(D7-C7),"0") -> 0.6 | J36: =IF(J7="X",(D7-C7),"0") -> 0 | K36: =IF(K7="X",(D7-C7),"0") -> 0
E37: =IF(E8="X",(D8-C8),"0") -> 0.4 | F37: =IF(F8="X",(D8-C8),"0") -> 0 | G37: =IF(G8="X",(D8-C8),"0") -> 0 | H37: =IF(H8="X",(D8-C8),"0") -> 0 | I37: =IF(I8="X",(D8-C8),"0") -> 0.4 | J37: =IF(J8="X",(D8-C8),"0") -> 0 | K37: =IF(K8="X",(D8-C8),"0") -> 0
E38: =IF(E9="X",(D9-C9),"0") -> 0.5 | F38: =IF(F9="X",(D9-C9),"0") -> 0 | G38: =IF(G9="X",(D9-C9),"0") -> 0 | H38: =IF(H9="X",(D9-C9),"0") -> 0 | I38: =IF(I9="X",(D9-C9),"0") -> 0.5 | J38: =IF(J9="X",(D9-C9),"0") -> 0 | K38: =IF(K9="X",(D9-C9),"0") -> 0
E39: =IF(E10="X",(D10-C10),"0") -> 0.3 | F39: =IF(F10="X",(D10-C10),"0") -> 0 | G39: =IF(G10="X",(D10-C10),"0") -> 0 | H39: =IF(H10="X",(D10-C10),"0") -> 0 | I39: =IF(I10="X",(D10-C10),"0") -> 0.3 | J39: =IF(J10="X",(D10-C10),"0") -> 0 | K39: =IF(K10="X",(D10-C10),"0") -> 0
E40: =IF(E11="X",(D11-C11),"0") -> 1.9 | F40: =IF(F11="X",(D11-C11),"0") -> 0 | G40: =IF(G11="X",(D11-C11),"0") -> 0 | H40: =IF(H11="X",(D11-C11),"0") -> 0 | I40: =IF(I11="X",(D11-C11),"0") -> 1.9 | J40: =IF(J11="X",(D11-C11),"0") -> 0 | K40: =IF(K11="X",(D11-C11),"0") -> 0
E41: =IF(E12="X",(D12-C12),"0") -> 2.7 | F41: =IF(F12="X",(D12-C12),"0") -> 0 | G41: =IF(G12="X",(D12-C12),"0") -> 0 | H41: =IF(H12="X",(D12-C12),"0") -> 0 | I41: =IF(I12="X",(D12-C12),"0") -> 2.7 | J41: =IF(J12="X",(D12-C12),"0") -> 0 | K41: =IF(K12="X",(D12-C12),"0") -> 0
E42: =IF(E13="X",(D13-C13),"0") -> 9.3 | F42: =IF(F13="X",(D13-C13),"0") -> 0 | G42: =IF(G13="X",(D13-C13),"0") -> 0 | H42: =IF(H13="X",(D13-C13),"0") -> 0 | I42: =IF(I13="X",(D13-C13),"0") -> 9.3 | J42: =IF(J13="X",(D13-C13),"0") -> 0 | K42: =IF(K13="X",(D13-C13),"0") -> 0
E43: =IF(E14="X",(D14-C14),"0") -> -0.4 | F43: =IF(F14="X",(D14-C14),"0") -> 0 | G43: =IF(G14="X",(D14-C14),"0") -> 0 | H43: =IF(H14="X",(D14-C14),"0") -> 0 | I43: =IF(I14="X",(D14-C14),"0") -> -0.4 | J43: =IF(J14="X",(D14-C14),"0") -> 0 | K43: =IF(K14="X",(D14-C14),"0") -> 0
E44: =IF(E15="X",(D15-C15),"0") -> 0.3 | F44: =IF(F15="X",(D15-C15),"0") -> 0 | G44: =IF(G15="X",(D15-C15),"0") -> 0 | H44: =IF(H15="X",(D15-C15),"0") -> 0 | I44: =IF(I15="X",(D15-C15),"0") -> 0.3 | J44: =IF(J15="X",(D15-C15),"0") -> 0 | K44: =IF(K15="X",(D15-C15),"0") -> 0
E45: =IF(E16="X",(D16-C16),"0") -> 45.7 | F45: =IF(F16="X",(D16-C16),"0") -> 0 | G45: =IF(G16="X",(D16-C16),"0") -> 45.7 | H45: =IF(H16="X",(D16-C16),"0") -> 0 | I45: =IF(I16="X",(D16-C16),"0") -> 45.7 | J45: =IF(J16="X",(D16-C16),"0") -> 0 | K45: =IF(K16="X",(D16-C16),"0") -> 0
E46: =IF(E17="X",(D17-C17),"0") -> 1 | F46: =IF(F17="X",(D17-C17),"0") -> 0 | G46: =IF(G17="X",(D17-C17),"0") -> 0 | H46: =IF(H17="X",(D17-C17),"0") -> 0 | I46: =IF(I17="X",(D17-C17),"0") -> 1 | J46: =IF(J17="X",(D17-C17),"0") -> 0 | K46: =IF(K17="X",(D17-C17),"0") -> 0
E47: =IF(E18="X",(D18-C18),"0") -> 1.63 | F47: =IF(F18="X",(D18-C18),"0") -> 0 | G47: =IF(G18="X",(D18-C18),"0") -> 0 | H47: =IF(H18="X",(D18-C18),"0") -> 0 | I47: =IF(I18="X",(D18-C18),"0") -> 1.63 | J47: =IF(J18="X",(D18-C18),"0") -> 0 | K47: =IF(K18="X",(D18-C18),"0") -> 0
... E61: =IF(E32="X",(D32-C32),"0") -> 0 | F61: =IF(F32="X",(D32-C32),"0") -> 0 | G61: =IF(G32="X",(D32-C32),"0") -> 0 | H61: =IF(H32="X",(D32-C32),"0") -> 0 | I61: =IF(I32="X",(D32-C32),"0") -> 0 | J61: =IF(J32="X",(D32-C32),"0") -> 0 | K61: =IF(K32="X",(D32-C32),"0") -> 0
E62: =SUM(E36:E61) -> 63.93 | F62: =SUM(F36:F61) -> 0 | G62: =SUM(G36:G61) -> 45.7 | H62: =SUM(H36:H61) -> 0 | I62: =SUM(I36:I61) -> 63.93 | J62: =SUM(J36:J61) -> 0 | K62: =SUM(K36:K61) -> 0

Sheet 240
A1: PROGRAMA DE MANUTENÇÃORODOVIÁRIA | I1: DATA: | J1: ='228'!J1 -> 46204 | L1: TÉCNICO RESP. | N1: ='228'!N1 -> ENG. THIAGO TORQUATO
A2: RODOVIAS NÃO PAVIMENTADAS
A3: FICHA DE INSPEÇÃO: | B3: =TT!C12 -> RODOVIA TO-490 - TRECHO SÃO VALÉRIO DE NATIVIDADE - ENTR. BR-242 | L3: REGIÃO: | N3: 12
A5: S.R.E. | B5: SENTIDO | C5: INÍCIO (KM) | D5: FIM (KM) | E5: CONDIÇÃO DA PLATAFORMA | I5: DRENAGEM SUPERFICIAL | L5: OBSERV.
E6: BOM | F6: REG. (ATÉ 10 IRR./KM) | G6: RUÍM (+ 10 IRR./KM) | H6: PÉSSIMA (ATOLEIRO/PTO. CRÍTICO) | I6: LIMPA | J6: OBSTRUÍDA | K6: AUSENTE
A7: 490ETO0020 | B7: D | C7: 0 | D7: 46.3 | G7: X | J7: X
A9: 490ETO0010 | B9: D | C9: 0 | D9: 34.7 | G9: X | J9: X
E36: =IF(E7="X",(D7-C7),"0") -> 0 | F36: =IF(F7="X",(D7-C7),"0") -> 0 | G36: =IF(G7="X",(D7-C7),"0") -> 46.3 | H36: =IF(H7="X",(D7-C7),"0") -> 0 | I36: =IF(I7="X",(D7-C7),"0") -> 0 | J36: =IF(J7="X",(D7-C7),"0") -> 46.3 | K36: =IF(K7="X",(D7-C7),"0") -> 0
E37: =IF(E8="X",(D8-C8),"0") -> 0 | F37: =IF(F8="X",(D8-C8),"0") -> 0 | G37: =IF(G8="X",(D8-C8),"0") -> 0 | H37: =IF(H8="X",(D8-C8),"0") -> 0 | I37: =IF(I8="X",(D8-C8),"0") -> 0 | J37: =IF(J8="X",(D8-C8),"0") -> 0 | K37: =IF(K8="X",(D8-C8),"0") -> 0
E38: =IF(E9="X",(D9-C9),"0") -> 0 | F38: =IF(F9="X",(D9-C9),"0") -> 0 | G38: =IF(G9="X",(D9-C9),"0") -> 34.7 | H38: =IF(H9="X",(D9-C9),"0") -> 0 | I38: =IF(I9="X",(D9-C9),"0") -> 0 | J38: =IF(J9="X",(D9-C9),"0") -> 34.7 | K38: =IF(K9="X",(D9-C9),"0") -> 0
E39: =IF(E10="X",(D10-C10),"0") -> 0 | F39: =IF(F10="X",(D10-C10),"0") -> 0 | G39: =IF(G10="X",(D10-C10),"0") -> 0 | H39: =IF(H10="X",(D10-C10),"0") -> 0 | I39: =IF(I10="X",(D10-C10),"0") -> 0 | J39: =IF(J10="X",(D10-C10),"0") -> 0 | K39: =IF(K10="X",(D10-C10),"0") -> 0
E40: =IF(E11="X",(D11-C11),"0") -> 0 | F40: =IF(F11="X",(D11-C11),"0") -> 0 | G40: =IF(G11="X",(D11-C11),"0") -> 0 | H40: =IF(H11="X",(D11-C11),"0") -> 0 | I40: =IF(I11="X",(D11-C11),"0") -> 0 | J40: =IF(J11="X",(D11-C11),"0") -> 0 | K40: =IF(K11="X",(D11-C11),"0") -> 0
E41: =IF(E12="X",(D12-C12),"0") -> 0 | F41: =IF(F12="X",(D12-C12),"0") -> 0 | G41: =IF(G12="X",(D12-C12),"0") -> 0 | H41: =IF(H12="X",(D12-C12),"0") -> 0 | I41: =IF(I12="X",(D12-C12),"0") -> 0 | J41: =IF(J12="X",(D12-C12),"0") -> 0 | K41: =IF(K12="X",(D12-C12),"0") -> 0
E42: =IF(E13="X",(D13-C13),"0") -> 0 | F42: =IF(F13="X",(D13-C13),"0") -> 0 | G42: =IF(G13="X",(D13-C13),"0") -> 0 | H42: =IF(H13="X",(D13-C13),"0") -> 0 | I42: =IF(I13="X",(D13-C13),"0") -> 0 | J42: =IF(J13="X",(D13-C13),"0") -> 0 | K42: =IF(K13="X",(D13-C13),"0") -> 0
E43: =IF(E14="X",(D14-C14),"0") -> 0 | F43: =IF(F14="X",(D14-C14),"0") -> 0 | G43: =IF(G14="X",(D14-C14),"0") -> 0 | H43: =IF(H14="X",(D14-C14),"0") -> 0 | I43: =IF(I14="X",(D14-C14),"0") -> 0 | J43: =IF(J14="X",(D14-C14),"0") -> 0 | K43: =IF(K14="X",(D14-C14),"0") -> 0
E44: =IF(E15="X",(D15-C15),"0") -> 0 | F44: =IF(F15="X",(D15-C15),"0") -> 0 | G44: =IF(G15="X",(D15-C15),"0") -> 0 | H44: =IF(H15="X",(D15-C15),"0") -> 0 | I44: =IF(I15="X",(D15-C15),"0") -> 0 | J44: =IF(J15="X",(D15-C15),"0") -> 0 | K44: =IF(K15="X",(D15-C15),"0") -> 0
E45: =IF(E16="X",(D16-C16),"0") -> 0 | F45: =IF(F16="X",(D16-C16),"0") -> 0 | G45: =IF(G16="X",(D16-C16),"0") -> 0 | H45: =IF(H16="X",(D16-C16),"0") -> 0 | I45: =IF(I16="X",(D16-C16),"0") -> 0 | J45: =IF(J16="X",(D16-C16),"0") -> 0 | K45: =IF(K16="X",(D16-C16),"0") -> 0
E46: =IF(E17="X",(D17-C17),"0") -> 0 | F46: =IF(F17="X",(D17-C17),"0") -> 0 | G46: =IF(G17="X",(D17-C17),"0") -> 0 | H46: =IF(H17="X",(D17-C17),"0") -> 0 | I46: =IF(I17="X",(D17-C17),"0") -> 0 | J46: =IF(J17="X",(D17-C17),"0") -> 0 | K46: =IF(K17="X",(D17-C17),"0") -> 0
E47: =IF(E18="X",(D18-C18),"0") -> 0 | F47: =IF(F18="X",(D18-C18),"0") -> 0 | G47: =IF(G18="X",(D18-C18),"0") -> 0 | H47: =IF(H18="X",(D18-C18),"0") -> 0 | I47: =IF(I18="X",(D18-C18),"0") -> 0 | J47: =IF(J18="X",(D18-C18),"0") -> 0 | K47: =IF(K18="X",(D18-C18),"0") -> 0
... E61: =IF(E32="X",(D32-C32),"0") -> 0 | F61: =IF(F32="X",(D32-C32),"0") -> 0 | G61: =IF(G32="X",(D32-C32),"0") -> 0 | H61: =IF(H32="X",(D32-C32),"0") -> 0 | I61: =IF(I32="X",(D32-C32),"0") -> 0 | J61: =IF(J32="X",(D32-C32),"0") -> 0 | K61: =IF(K32="X",(D32-C32),"0") -> 0
E62: =SUM(E36:E61) -> 0 | F62: =SUM(F36:F61) -> 0 | G62: =SUM(G36:G61) -> 81 | H62: =SUM(H36:H61) -> 0 | I62: =SUM(I36:I61) -> 0 | J62: =SUM(J36:J61) -> 81 | K62: =SUM(K36:K61) -> 0

Sheet 241
A1: PROGRAMA DE MANUTENÇÃORODOVIÁRIA | I1: DATA: | J1: ='228'!J1 -> 46204 | L1: TÉCNICO RESP. | N1: ='228'!N1 -> ENG. THIAGO TORQUATO
A2: RODOVIAS NÃO PAVIMENTADAS
A3: FICHA DE INSPEÇÃO: | B3: =TT!C13 -> RODOVIA TO-491 - TRECHO ENTR. BR-242 - ENTR. TO-296 (POVOADO RETIRO) | L3: REGIÃO: | N3: 12
A5: S.R.E. | B5: SENTIDO | C5: INÍCIO (KM) | D5: FIM (KM) | E5: CONDIÇÃO DA PLATAFORMA | I5: DRENAGEM SUPERFICIAL | L5: OBSERV.
E6: BOM | F6: REG. (ATÉ 10 IRR./KM) | G6: RUÍM (+ 10 IRR./KM) | H6: PÉSSIMA (ATOLEIRO/PTO. CRÍTICO) | I6: LIMPA | J6: OBSTRUÍDA | K6: AUSENTE
A7: 491ETO0010 | B7: C | C7: 0 | D7: 36.5 | E7: X | I7: X
C8: =D7 -> 36.5 | D8: 42.4 | F8: X | G8: X | I8: X
C9: =D8 -> 42.4 | D9: 60.31 | E9: X | I9: X
E36: =IF(E7="X",(D7-C7),"0") -> 36.5 | F36: =IF(F7="X",(D7-C7),"0") -> 0 | G36: =IF(G7="X",(D7-C7),"0") -> 0 | H36: =IF(H7="X",(D7-C7),"0") -> 0 | I36: =IF(I7="X",(D7-C7),"0") -> 36.5 | J36: =IF(J7="X",(D7-C7),"0") -> 0 | K36: =IF(K7="X",(D7-C7),"0") -> 0
E37: =IF(E8="X",(D8-C8),"0") -> 0 | F37: =IF(F8="X",(D8-C8),"0") -> 5.9 | G37: =IF(G8="X",(D8-C8),"0") -> 5.9 | H37: =IF(H8="X",(D8-C8),"0") -> 0 | I37: =IF(I8="X",(D8-C8),"0") -> 5.9 | J37: =IF(J8="X",(D8-C8),"0") -> 0 | K37: =IF(K8="X",(D8-C8),"0") -> 0
E38: =IF(E9="X",(D9-C9),"0") -> 17.91 | F38: =IF(F9="X",(D9-C9),"0") -> 0 | G38: =IF(G9="X",(D9-C9),"0") -> 0 | H38: =IF(H9="X",(D9-C9),"0") -> 0 | I38: =IF(I9="X",(D9-C9),"0") -> 17.91 | J38: =IF(J9="X",(D9-C9),"0") -> 0 | K38: =IF(K9="X",(D9-C9),"0") -> 0
E39: =IF(E10="X",(D10-C10),"0") -> 0 | F39: =IF(F10="X",(D10-C10),"0") -> 0 | G39: =IF(G10="X",(D10-C10),"0") -> 0 | H39: =IF(H10="X",(D10-C10),"0") -> 0 | I39: =IF(I10="X",(D10-C10),"0") -> 0 | J39: =IF(J10="X",(D10-C10),"0") -> 0 | K39: =IF(K10="X",(D10-C10),"0") -> 0
E40: =IF(E11="X",(D11-C11),"0") -> 0 | F40: =IF(F11="X",(D11-C11),"0") -> 0 | G40: =IF(G11="X",(D11-C11),"0") -> 0 | H40: =IF(H11="X",(D11-C11),"0") -> 0 | I40: =IF(I11="X",(D11-C11),"0") -> 0 | J40: =IF(J11="X",(D11-C11),"0") -> 0 | K40: =IF(K11="X",(D11-C11),"0") -> 0
E41: =IF(E12="X",(D12-C12),"0") -> 0 | F41: =IF(F12="X",(D12-C12),"0") -> 0 | G41: =IF(G12="X",(D12-C12),"0") -> 0 | H41: =IF(H12="X",(D12-C12),"0") -> 0 | I41: =IF(I12="X",(D12-C12),"0") -> 0 | J41: =IF(J12="X",(D12-C12),"0") -> 0 | K41: =IF(K12="X",(D12-C12),"0") -> 0
E42: =IF(E13="X",(D13-C13),"0") -> 0 | F42: =IF(F13="X",(D13-C13),"0") -> 0 | G42: =IF(G13="X",(D13-C13),"0") -> 0 | H42: =IF(H13="X",(D13-C13),"0") -> 0 | I42: =IF(I13="X",(D13-C13),"0") -> 0 | J42: =IF(J13="X",(D13-C13),"0") -> 0 | K42: =IF(K13="X",(D13-C13),"0") -> 0
E43: =IF(E14="X",(D14-C14),"0") -> 0 | F43: =IF(F14="X",(D14-C14),"0") -> 0 | G43: =IF(G14="X",(D14-C14),"0") -> 0 | H43: =IF(H14="X",(D14-C14),"0") -> 0 | I43: =IF(I14="X",(D14-C14),"0") -> 0 | J43: =IF(J14="X",(D14-C14),"0") -> 0 | K43: =IF(K14="X",(D14-C14),"0") -> 0
E44: =IF(E15="X",(D15-C15),"0") -> 0 | F44: =IF(F15="X",(D15-C15),"0") -> 0 | G44: =IF(G15="X",(D15-C15),"0") -> 0 | H44: =IF(H15="X",(D15-C15),"0") -> 0 | I44: =IF(I15="X",(D15-C15),"0") -> 0 | J44: =IF(J15="X",(D15-C15),"0") -> 0 | K44: =IF(K15="X",(D15-C15),"0") -> 0
E45: =IF(E16="X",(D16-C16),"0") -> 0 | F45: =IF(F16="X",(D16-C16),"0") -> 0 | G45: =IF(G16="X",(D16-C16),"0") -> 0 | H45: =IF(H16="X",(D16-C16),"0") -> 0 | I45: =IF(I16="X",(D16-C16),"0") -> 0 | J45: =IF(J16="X",(D16-C16),"0") -> 0 | K45: =IF(K16="X",(D16-C16),"0") -> 0
E46: =IF(E17="X",(D17-C17),"0") -> 0 | F46: =IF(F17="X",(D17-C17),"0") -> 0 | G46: =IF(G17="X",(D17-C17),"0") -> 0 | H46: =IF(H17="X",(D17-C17),"0") -> 0 | I46: =IF(I17="X",(D17-C17),"0") -> 0 | J46: =IF(J17="X",(D17-C17),"0") -> 0 | K46: =IF(K17="X",(D17-C17),"0") -> 0
E47: =IF(E18="X",(D18-C18),"0") -> 0 | F47: =IF(F18="X",(D18-C18),"0") -> 0 | G47: =IF(G18="X",(D18-C18),"0") -> 0 | H47: =IF(H18="X",(D18-C18),"0") -> 0 | I47: =IF(I18="X",(D18-C18),"0") -> 0 | J47: =IF(J18="X",(D18-C18),"0") -> 0 | K47: =IF(K18="X",(D18-C18),"0") -> 0
... E61: =IF(E32="X",(D32-C32),"0") -> 0 | F61: =IF(F32="X",(D32-C32),"0") -> 0 | G61: =IF(G32="X",(D32-C32),"0") -> 0 | H61: =IF(H32="X",(D32-C32),"0") -> 0 | I61: =IF(I32="X",(D32-C32),"0") -> 0 | J61: =IF(J32="X",(D32-C32),"0") -> 0 | K61: =IF(K32="X",(D32-C32),"0") -> 0
E62: =SUM(E36:E61) -> 54.41 | F62: =SUM(F36:F61) -> 5.9 | G62: =SUM(G36:G61) -> 5.9 | H62: =SUM(H36:H61) -> 0 | I62: =SUM(I36:I61) -> 60.31 | J62: =SUM(J36:J61) -> 0 | K62: =SUM(K36:K61) -> 0

Sheet 242
A1: PROGRAMA DE MANUTENÇÃORODOVIÁRIA | I1: DATA: | J1: ='228'!J1 -> 46204 | L1: TÉCNICO RESP. | N1: ='228'!N1 -> ENG. THIAGO TORQUATO
A2: RODOVIAS NÃO PAVIMENTADAS
A3: FICHA DE INSPEÇÃO: | B3: =TT!C14 -> RODOVIA TO-495 - TRECHO DIVISA TO-GO - LOURENÇO BORGES - ENTR. TO-296 | L3: REGIÃO: | N3: 12
A5: S.R.E. | B5: SENTIDO | C5: INÍCIO (KM) | D5: FIM (KM) | E5: CONDIÇÃO DA PLATAFORMA | I5: DRENAGEM SUPERFICIAL | L5: OBSERV.
E6: BOM | F6: REG. (ATÉ 10 IRR./KM) | G6: RUÍM (+ 10 IRR./KM) | H6: PÉSSIMA (ATOLEIRO/PTO. CRÍTICO) | I6: LIMPA | J6: OBSTRUÍDA | K6: AUSENTE
A7: 495ETO0010 | B7: C | C7: 0 | D7: 16.27 | E7: X | I7: X
A9: 495ETO0010 | B9: C | C9: 0 | D9: 5.4 | E9: X | K9: X
E36: =IF(E7="X",(D7-C7),"0") -> 16.27 | F36: =IF(F7="X",(D7-C7),"0") -> 0 | G36: =IF(G7="X",(D7-C7),"0") -> 0 | H36: =IF(H7="X",(D7-C7),"0") -> 0 | I36: =IF(I7="X",(D7-C7),"0") -> 16.27 | J36: =IF(J7="X",(D7-C7),"0") -> 0 | K36: =IF(K7="X",(D7-C7),"0") -> 0
E37: =IF(E8="X",(D8-C8),"0") -> 0 | F37: =IF(F8="X",(D8-C8),"0") -> 0 | G37: =IF(G8="X",(D8-C8),"0") -> 0 | H37: =IF(H8="X",(D8-C8),"0") -> 0 | I37: =IF(I8="X",(D8-C8),"0") -> 0 | J37: =IF(J8="X",(D8-C8),"0") -> 0 | K37: =IF(K8="X",(D8-C8),"0") -> 0
E38: =IF(E9="X",(D9-C9),"0") -> 5.4 | F38: =IF(F9="X",(D9-C9),"0") -> 0 | G38: =IF(G9="X",(D9-C9),"0") -> 0 | H38: =IF(H9="X",(D9-C9),"0") -> 0 | I38: =IF(I9="X",(D9-C9),"0") -> 0 | J38: =IF(J9="X",(D9-C9),"0") -> 0 | K38: =IF(K9="X",(D9-C9),"0") -> 5.4
E39: =IF(E10="X",(D10-C10),"0") -> 0 | F39: =IF(F10="X",(D10-C10),"0") -> 0 | G39: =IF(G10="X",(D10-C10),"0") -> 0 | H39: =IF(H10="X",(D10-C10),"0") -> 0 | I39: =IF(I10="X",(D10-C10),"0") -> 0 | J39: =IF(J10="X",(D10-C10),"0") -> 0 | K39: =IF(K10="X",(D10-C10),"0") -> 0
E40: =IF(E11="X",(D11-C11),"0") -> 0 | F40: =IF(F11="X",(D11-C11),"0") -> 0 | G40: =IF(G11="X",(D11-C11),"0") -> 0 | H40: =IF(H11="X",(D11-C11),"0") -> 0 | I40: =IF(I11="X",(D11-C11),"0") -> 0 | J40: =IF(J11="X",(D11-C11),"0") -> 0 | K40: =IF(K11="X",(D11-C11),"0") -> 0
E41: =IF(E12="X",(D12-C12),"0") -> 0 | F41: =IF(F12="X",(D12-C12),"0") -> 0 | G41: =IF(G12="X",(D12-C12),"0") -> 0 | H41: =IF(H12="X",(D12-C12),"0") -> 0 | I41: =IF(I12="X",(D12-C12),"0") -> 0 | J41: =IF(J12="X",(D12-C12),"0") -> 0 | K41: =IF(K12="X",(D12-C12),"0") -> 0
E42: =IF(E13="X",(D13-C13),"0") -> 0 | F42: =IF(F13="X",(D13-C13),"0") -> 0 | G42: =IF(G13="X",(D13-C13),"0") -> 0 | H42: =IF(H13="X",(D13-C13),"0") -> 0 | I42: =IF(I13="X",(D13-C13),"0") -> 0 | J42: =IF(J13="X",(D13-C13),"0") -> 0 | K42: =IF(K13="X",(D13-C13),"0") -> 0
E43: =IF(E14="X",(D14-C14),"0") -> 0 | F43: =IF(F14="X",(D14-C14),"0") -> 0 | G43: =IF(G14="X",(D14-C14),"0") -> 0 | H43: =IF(H14="X",(D14-C14),"0") -> 0 | I43: =IF(I14="X",(D14-C14),"0") -> 0 | J43: =IF(J14="X",(D14-C14),"0") -> 0 | K43: =IF(K14="X",(D14-C14),"0") -> 0
E44: =IF(E15="X",(D15-C15),"0") -> 0 | F44: =IF(F15="X",(D15-C15),"0") -> 0 | G44: =IF(G15="X",(D15-C15),"0") -> 0 | H44: =IF(H15="X",(D15-C15),"0") -> 0 | I44: =IF(I15="X",(D15-C15),"0") -> 0 | J44: =IF(J15="X",(D15-C15),"0") -> 0 | K44: =IF(K15="X",(D15-C15),"0") -> 0
E45: =IF(E16="X",(D16-C16),"0") -> 0 | F45: =IF(F16="X",(D16-C16),"0") -> 0 | G45: =IF(G16="X",(D16-C16),"0") -> 0 | H45: =IF(H16="X",(D16-C16),"0") -> 0 | I45: =IF(I16="X",(D16-C16),"0") -> 0 | J45: =IF(J16="X",(D16-C16),"0") -> 0 | K45: =IF(K16="X",(D16-C16),"0") -> 0
E46: =IF(E17="X",(D17-C17),"0") -> 0 | F46: =IF(F17="X",(D17-C17),"0") -> 0 | G46: =IF(G17="X",(D17-C17),"0") -> 0 | H46: =IF(H17="X",(D17-C17),"0") -> 0 | I46: =IF(I17="X",(D17-C17),"0") -> 0 | J46: =IF(J17="X",(D17-C17),"0") -> 0 | K46: =IF(K17="X",(D17-C17),"0") -> 0
E47: =IF(E18="X",(D18-C18),"0") -> 0 | F47: =IF(F18="X",(D18-C18),"0") -> 0 | G47: =IF(G18="X",(D18-C18),"0") -> 0 | H47: =IF(H18="X",(D18-C18),"0") -> 0 | I47: =IF(I18="X",(D18-C18),"0") -> 0 | J47: =IF(J18="X",(D18-C18),"0") -> 0 | K47: =IF(K18="X",(D18-C18),"0") -> 0
... E61: =IF(E32="X",(D32-C32),"0") -> 0 | F61: =IF(F32="X",(D32-C32),"0") -> 0 | G61: =IF(G32="X",(D32-C32),"0") -> 0 | H61: =IF(H32="X",(D32-C32),"0") -> 0 | I61: =IF(I32="X",(D32-C32),"0") -> 0 | J61: =IF(J32="X",(D32-C32),"0") -> 0 | K61: =IF(K32="X",(D32-C32),"0") -> 0
E62: =SUM(E36:E61) -> 21.67 | F62: =SUM(F36:F61) -> 0 | G62: =SUM(G36:G61) -> 0 | H62: =SUM(H36:H61) -> 0 | I62: =SUM(I36:I61) -> 16.27 | J62: =SUM(J36:J61) -> 0 | K62: =SUM(K36:K61) -> 5.4

Sheet TT
D1: RESUMO
B2: Nº DO TRECHO | C2: TRECHO | D2: CONDIÇÃO DA PLATAFORMA | H2: DRENAGEM SUPERFICIAL
D3: BOM | E3: REG. (ATÉ 10 IRR./KM) | F3: RUÍM (+ 10 IRR./KM) | G3: PÉSSIMA (ATOLEIRO/PTO. CRÍTICO) | H3: LIMPA | I3: OBSTRUÍDA | J3: AUSENTE
B4: 228 | C4: RODOVIA TO-296 - TRECHO SÃO SALVADOR DO TOCANTINS - PARANÃ | D4: ='228'!E62 -> 0 | E4: ='228'!F62 -> 36.06 | F4: ='228'!G62 -> 31.2 | G4: ='228'!H62 -> 0 | H4: ='228'!I62 -> 10.32 | I4: ='228'!J62 -> 55.94 | J4: ='228'!K62 -> 1
B5: 229 | C5: RODOVIA TO-296 - TRECHO JAÚ DO TOCANTINS - SÃO SALVADOR DO TOCANTINS | D5: ='229'!E62 -> 66.29 | E5: ='229'!F62 -> 16.1 | F5: ='229'!G62 -> 0 | G5: ='229'!H62 -> 0 | H5: ='229'!I62 -> 81.69 | I5: ='229'!J62 -> 0 | J5: ='229'!K62 -> 0
B6: 231 | C6: RODOVIA TO-365 - TRECHO IPUEIRAS - SILVANÓPOLIS | D6: ='231'!E62 -> 45.78 | E6: ='231'!F62 -> 0 | F6: ='231'!G62 -> 0 | G6: ='231'!H62 -> 0 | H6: ='231'!I62 -> 45.78 | I6: ='231'!J62 -> 0 | J6: ='231'!K62 -> 0
B7: 232 | C7: RODOVIA TO-373 - TRECHO ENTR. TO-365 (BALSA) - SÃO MIGUEL - LAGOA DO ROMÃO -ENTR. TO-280 | D7: ='232'!E62 -> 87.53 | E7: ='232'!F62 -> 0 | F7: ='232'!G62 -> 0 | G7: ='232'!H62 -> 0 | H7: ='232'!I62 -> 20.95 | I7: ='232'!J62 -> 0 | J7: ='232'!K62 -> 66.58
B8: 236 | C8: RODOVIA TO-458 - TRECHO ENTR. TO-365 (IPUEIRAS) - ENTR. BR-010 | D8: ='236'!E62 -> 0 | E8: ='236'!F62 -> 21.24 | F8: ='236'!G62 -> 13.2 | G8: ='236'!H62 -> 0 | H8: ='236'!I62 -> 34.34 | I8: ='236'!J62 -> 0 | J8: ='236'!K62 -> 0
B9: 237 | C9: RODOVIA TO-479 - TRECHO PEIXE - POVOADO LAGOA DO ROMÃO (ENTR. TO-373) | D9: ='237'!E62 -> 26.04 | E9: ='237'!F62 -> 0 | F9: ='237'!G62 -> 0 | G9: ='237'!H62 -> 0 | H9: ='237'!I62 -> 26.04 | I9: ='237'!J62 -> 0 | J9: ='237'!K62 -> 0
B10: 238 | C10: RODOVIA TO-482 - TRECHO: ENTR. TO-280 (SÃO VALÉRIO DE NATIVIDADE) / ENTR. TO-458 | D10: ='238'!E76 -> 72.76 | E10: ='238'!F76 -> 0 | F10: ='238'!G76 -> 0 | G10: ='238'!H76 -> 0 | H10: ='238'!I76 -> 73.56 | I10: ='238'!J76 -> 0 | J10: ='238'!K76 -> 0
B11: 239 | C11: RODOVIA TO-486 - TRECHO SANTA ROSA DO TOCANTINS - ENTR. TO-280 (NATIVIDADE) | D11: ='239'!E62 -> 63.93 | E11: ='239'!F62 -> 0 | F11: ='239'!G62 -> 45.7 | G11: ='239'!H62 -> 0 | H11: ='239'!I62 -> 63.93 | I11: ='239'!J62 -> 0 | J11: ='239'!K62 -> 0
B12: 240 | C12: RODOVIA TO-490 - TRECHO SÃO VALÉRIO DE NATIVIDADE - ENTR. BR-242 | D12: ='240'!E62 -> 0 | E12: ='240'!F62 -> 0 | F12: ='240'!G62 -> 81 | G12: ='240'!H62 -> 0 | H12: ='240'!I62 -> 0 | I12: ='240'!J62 -> 81 | J12: ='240'!K62 -> 0
B13: 241 | C13: RODOVIA TO-491 - TRECHO ENTR. BR-242 - ENTR. TO-296 (POVOADO RETIRO) | D13: ='241'!E62 -> 54.41 | E13: ='241'!F62 -> 5.9 | F13: ='241'!G62 -> 5.9 | G13: ='241'!H62 -> 0 | H13: ='241'!I62 -> 60.31 | I13: ='241'!J62 -> 0 | J13: ='241'!K62 -> 0
B14: 242 | C14: RODOVIA TO-495 - TRECHO DIVISA TO-GO - LOURENÇO BORGES - ENTR. TO-296 | D14: ='242'!E62 -> 21.67 | E14: ='242'!F62 -> 0 | F14: ='242'!G62 -> 0 | G14: ='242'!H62 -> 0 | H14: ='242'!I62 -> 16.27 | I14: ='242'!J62 -> 0 | J14: ='242'!K62 -> 5.4
B16: PERCORRIDO NO MÊS: | D16: =SUM(D4:D14) -> 438.41 | E16: =SUM(E4:E14) -> 79.3 | F16: =SUM(F4:F14) -> 177 | G16: =SUM(G4:G14) -> 0 | H16: =SUM(H4:H14) -> 433.19 | I16: =SUM(I4:I14) -> 136.94 | J16: =SUM(J4:J14) -> 72.98
B17: TOTAL: | G17: =SUM(D16:G16) -> 694.71
B18: % DA EXTENSÃO DA MALHA: | G18: =G17/Trechos!F28 -> 1.2046742
