Workbook

Sheet OS SETEMBRO
A1: ORDENS DE SERVIÇO MEDIDAS EM SETEMBRO/2026
A2: REGIÃO 13 — RODOVIAS PAVIMENTADAS · Fonte: Geoportal RTA-MSI (geoportal-ordens-servico.vercel.app), consultado em 02/10/2026
A3: Os trechos abaixo estão com a ABA EM LARANJA e uma nota no título do trecho (A3). As condições desta ficha foram copiadas de AGOSTO/2026: atualizar em campo, com atenção especial a estes trechos.
A5: TRECHO (ABA) | B5: RODOVIA / TRECHO | C5: OSP | D5: CONTRATO | E5: TIPO | F5: SERVIÇOS (resumo do geoportal) | G5: SITUAÇÃO | H5: MEDIÇÃO DO MÊS | I5: VALOR MEDIDO NO MÊS | J5: % EXEC. DA OS | K5: PRAZO LIMITE
A6: 246 | B6: RODOVIA TO-040 - TRECHO ALMAS - PORTO ALEGRE DO TOCANTINS | C6: 155 | D6: 051.2024 | E6: Manutenção | F6: Roçada com roçadeira costal (Segmentos Rod... / Roçada mecanizada com roçadeira articulada... (+18 itens) | G6: Em andamento | H6: nº 19 — 01/09/2026 a 30/09/2026 | I6: 73574.55 | J6: 83.4 | K6: Dezembro/2026
A7: 247 | B7: RODOVIA TO-040 - TRECHO DIANÓPOLIS - NOVO JARDIM | C7: 156 | D7: 051.2024 | E7: Manutenção | F7: Roçada com roçadeira costal (Segmentos Rod... / Limpeza de valeta (Segmentos Urbanos e Rod... | G7: Concluída | H7: nº 19 — 01/09/2026 a 30/09/2026 | I7: 18908.43 | J7: 96.6 | K7: Novembro/2026
A8: 249 | B8: RODOVIA TO-040 - TRECHO PORTO ALEGRE DO TOCANTINS - DIANÓPOLIS | C8: 144 | D8: 051.2024 | E8: Manutenção | F8: Roçada mecanizada com roçadeira articulada... / Limpeza manual de Bueiro (Segmentos Urbano... (+2 itens) | G8: Em andamento | H8: nº 19 — 01/09/2026 a 30/09/2026 | I8: 45206.94 | J8: 69.8 | K8: Novembro/2026
A9: 249 | B9: RODOVIA TO-040 - TRECHO PORTO ALEGRE DO TOCANTINS - DIANÓPOLIS | C9: 157 | D9: 051.2024 | E9: Manutenção | F9: Roçada com roçadeira costal (Segmentos Rod... / G2 - Tapa Buraco PMF Classe 1 e 2 (Segment... (+20 itens) | G9: Concluída | H9: nº 19 — 01/09/2026 a 30/09/2026 | I9: 18331.12 | J9: 99.6 | K9: Novembro/2026
A10: 252 | B10: RODOVIA TO-050 - TRECHO ENTR. BR-010 (POVOADO PRÍNCIPE) - CONCEIÇÃO DO TOCANTINS | C10: 151 | D10: 051.2024 | E10: Manutenção | F10: Roçada com roçadeira costal (Segmentos Rod... / Limpeza de valeta (Segmentos Urbanos e Rod... (+17 itens) | G10: Em andamento | H10: nº 19 — 01/09/2026 a 30/09/2026 | I10: 26900.47 | J10: 52.3 | K10: Dezembro/2026
A11: 253 | B11: RODOVIA TO-110 - TRECHO AURORA DO TOCANTINS - LAVANDEIRA | C11: 3 | D11: 1151.2026 | E11: Restauração | F11: Reciclagem com adição de brita comercial e... / Brita 1 (+26 itens) | G11: Concluída | H11: nº 3 — 01/09/2026 a 30/09/2026 | I11: 1747140.4 | J11: 98.2 | K11: Dezembro/2026
A12: 253 | B12: RODOVIA TO-110 - TRECHO AURORA DO TOCANTINS - LAVANDEIRA | C12: 142 | D12: 051.2024 | E12: Manutenção | F12: Roçada com roçadeira costal (Segmentos Rod... / Limpeza de valeta (Segmentos Urbanos e Rod... (+17 itens) | G12: Concluída | H12: nº 19 — 01/09/2026 a 30/09/2026 | I12: 36542.98 | J12: 99.4 | K12: Outubro/2026
A13: 254 | B13: RODOVIA TO-110 - TRECHO COMBINADO - NOVO ALEGRE - DIVISA TO-GO | C13: 5 | D13: 1151.2026 | E13: Restauração | F13: Reciclagem com adição de brita comercial e... / Brita 1 (+26 itens) | G13: Em andamento | H13: nº 3 — 01/09/2026 a 30/09/2026 | I13: 4044134.2 | J13: 65.3 | K13: Novembro/2026
A14: 254 | B14: RODOVIA TO-110 - TRECHO COMBINADO - NOVO ALEGRE - DIVISA TO-GO | C14: 143 | D14: 051.2024 | E14: Manutenção | F14: Roçada com roçadeira costal (Segmentos Rod... / Limpeza de valeta (Segmentos Urbanos e Rod... (+16 itens) | G14: Concluída | H14: nº 19 — 01/09/2026 a 30/09/2026 | I14: 47267.48 | J14: 99.4 | K14: Outubro/2026
A15: 255 | B15: RODOVIA TO-110 - TRECHO ENTR. TO-040 (DIANÓPOLIS) - DIVISA TO-BA (GARGANTA) | C15: 152 | D15: 051.2024 | E15: Manutenção | F15: Roçada com roçadeira costal (Segmentos Rod... | G15: Concluída | H15: nº 19 — 01/09/2026 a 30/09/2026 | I15: 30147.05 | J15: 100 | K15: Dezembro/2026
A16: 257 | B16: RODOVIA TO-110 - TRECHO LAVANDEIRA - COMBINADO | C16: 141 | D16: 051.2024 | E16: Manutenção | F16: Roçada com roçadeira costal (Segmentos Rod... / Limpeza de valeta (Segmentos Urbanos e Rod... (+17 itens) | G16: Concluída | H16: nº 19 — 01/09/2026 a 30/09/2026 | I16: 17807.28 | J16: 98.6 | K16: Outubro/2026
A17: 259 | B17: RODOVIA TO-110 - TRECHO TAGUATINGA - AURORA DO TOCANTINS | C17: 6 | D17: 1151.2026 | E17: Restauração | F17: Carga, manobra e descarga de agregados ou... / Carga, manobra e descarga de cimento ou ca... (+4 itens) | G17: Concluída | H17: nº 3 — 01/09/2026 a 30/09/2026 | I17: 208176.32 | J17: 100 | K17: Outubro/2026
... A19: 266 | B19: RODOVIA TO-476 - TRECHO RIO DA CONCEIÇÃO - DIANÓPOLIS | C19: 148 | D19: 051.2024 | E19: Manutenção | F19: Roçada com roçadeira costal (Segmentos Rod... / Roçada mecanizada com roçadeira articulada... (+3 itens) | G19: Em andamento | H19: nº 19 — 01/09/2026 a 30/09/2026 | I19: 31346.65 | J19: 71.2 | K19: Dezembro/2026
H20: TOTAL MEDIDO NO MÊS | I20: =SUM(I6:I19) -> 6526469.2

Sheet RESUMO
A1: RESUMO CONSOLIDADO — REGIÃO 1 — RODOVIAS PAVIMENTADAS | V1: Valores dos gráficos — troca 0 por N/D para a fatia não aparecer. Não editar.
A2: Todos os números vêm das abas dos trechos por referência direta. Não digite nada aqui. A coluna CONFERÊNCIA acusa qualquer trecho em que a soma das marcações não fecha com a extensão. | V2: =IF(D22=0,NA(),D22) -> 226.57299 | W2: =IF(E22=0,NA(),E22) -> 173.01589 | X2: =IF(F22=0,NA(),F22) -> 134.93539 | Y2: =IF(G22=0,NA(),G22) -> 10 | Z2: =IF(H22=0,NA(),H22) -> 4 | AA2: =IF(I22=0,NA(),I22) -> 533.52427 | AB2: =IF(J22=0,NA(),J22) -> 15 | AC2: =IF(K22=0,NA(),K22) -> 127.13179 | ... AK2: =IF(S22=0,NA(),S22) -> #N/A
A4: Nº TRECHO | B4: TRECHO | C4: EXTENSÃO (KM) | D4: CONDIÇÃO DO PAVIMENTO | I4: VEGETAÇÃO | K4: ELEM. DE DRENAGEM | N4: SIN. HORIZ. | Q4: SIN. VERTICAL | T4: CONFERÊNCIA
D5: BOM | E5: REM. I. | F5: REM. L. | G5: BUR. I. | H5: BUR. L. | I5: ADEQ. | J5: INAD. | K5: LIMPOS | L5: SUJOS | M5: DAN. | N5: BOM | O5: REG. | P5: INEXIST. | Q5: BOM | R5: POUCAS | S5: INEXIST.
A6: 246 | B6: RODOVIA TO-040 - TRECHO ALMAS - PORTO ALEGRE DO TOCANTINS | C6: ='246'!R34 -> 14.893612 | D6: ='246'!F31 -> 4 | E6: ='246'!G31 -> 0 | F6: ='246'!H31 -> 10.893612 | G6: ='246'!I31 -> 0 | H6: ='246'!J31 -> 0 | I6: ='246'!K31 -> 14.893612 | J6: ='246'!L31 -> 0 | K6: ='246'!M31 -> 4 | ... S6: ='246'!U31 -> 0 | T6: =IF(SUM(D6:H6)=0,"— não preenchido",IF(ROUND(SUM(D6:H6)-C6,3)=0,"OK","ERRO — dif. de "&ROUND(SUM(D6:H6)-C6,3)&" km")) -> OK
A7: 247 | B7: RODOVIA TO-040 - TRECHO DIANÓPOLIS - NOVO JARDIM | C7: ='247'!R57 -> 36.046509 | D7: ='247'!F54 -> 0 | E7: ='247'!G54 -> 16.481209 | F7: ='247'!H54 -> 19.5653 | G7: ='247'!I54 -> 0 | H7: ='247'!J54 -> 0 | I7: ='247'!K54 -> 36.046509 | J7: ='247'!L54 -> 0 | K7: ='247'!M54 -> 6.4812088 | ... S7: ='247'!U54 -> 0 | T7: =IF(SUM(D7:H7)=0,"— não preenchido",IF(ROUND(SUM(D7:H7)-C7,3)=0,"OK","ERRO — dif. de "&ROUND(SUM(D7:H7)-C7,3)&" km")) -> OK
A8: 248 | B8: RODOVIA TO-040 - TRECHO NOVO JARDIM - DIVISA TO-BA | C8: ='248'!R62 -> 43.005991 | D8: ='248'!F59 -> 28.187731 | E8: ='248'!G59 -> 5.8182596 | F8: ='248'!H59 -> 9 | G8: ='248'!I59 -> 0 | H8: ='248'!J59 -> 0 | I8: ='248'!K59 -> 43.005991 | J8: ='248'!L59 -> 0 | K8: ='248'!M59 -> 0 | ... S8: ='248'!U59 -> 0 | T8: =IF(SUM(D8:H8)=0,"— não preenchido",IF(ROUND(SUM(D8:H8)-C8,3)=0,"OK","ERRO — dif. de "&ROUND(SUM(D8:H8)-C8,3)&" km")) -> OK
A9: 249 | B9: RODOVIA TO-040 - TRECHO PORTO ALEGRE DO TOCANTINS - DIANÓPOLIS | C9: ='249'!R56 -> 34.935267 | D9: ='249'!F53 -> 12.68404 | E9: ='249'!G53 -> 0 | F9: ='249'!H53 -> 22.251227 | G9: ='249'!I53 -> 0 | H9: ='249'!J53 -> 0 | I9: ='249'!K53 -> 34.935267 | J9: ='249'!L53 -> 0 | K9: ='249'!M53 -> 34.935267 | ... S9: ='249'!U53 -> 0 | T9: =IF(SUM(D9:H9)=0,"— não preenchido",IF(ROUND(SUM(D9:H9)-C9,3)=0,"OK","ERRO — dif. de "&ROUND(SUM(D9:H9)-C9,3)&" km")) -> OK
A10: 250 | B10: RODOVIA TO-050 - TRECHO ARRAIAS - DIVISA TO-GO | C10: ='250'!R35 -> 15.388408 | D10: ='250'!F32 -> 1.8568038 | E10: ='250'!G32 -> 13.531604 | F10: ='250'!H32 -> 0 | G10: ='250'!I32 -> 0 | H10: ='250'!J32 -> 0 | I10: ='250'!K32 -> 15.388408 | J10: ='250'!L32 -> 0 | K10: ='250'!M32 -> 0 | ... S10: ='250'!U32 -> 0 | T10: =IF(SUM(D10:H10)=0,"— não preenchido",IF(ROUND(SUM(D10:H10)-C10,3)=0,"OK","ERRO — dif. de "&ROUND(SUM(D10:H10)-C10,3)&" km")) -> OK
A11: 251 | B11: RODOVIA TO-050 - TRECHO CONCEIÇÃO DO TOCANTINS - ARRAIAS | C11: ='251'!R125 -> 104.51176 | D11: ='251'!F122 -> 59.648839 | E11: ='251'!G122 -> 24.862925 | F11: ='251'!H122 -> 20 | G11: ='251'!I122 -> 0 | H11: ='251'!J122 -> 0 | I11: ='251'!K122 -> 104.51176 | J11: ='251'!L122 -> 0 | K11: ='251'!M122 -> 3.648839 | ... S11: ='251'!U122 -> 0 | T11: =IF(SUM(D11:H11)=0,"— não preenchido",IF(ROUND(SUM(D11:H11)-C11,3)=0,"OK","ERRO — dif. de "&ROUND(SUM(D11:H11)-C11,3)&" km")) -> OK
A12: 252 | B12: RODOVIA TO-050 - TRECHO ENTR. BR-010 (POVOADO PRÍNCIPE) - CONCEIÇÃO DO TOCANTINS | C12: ='252'!R74 -> 52.672671 | D12: ='252'!F71 -> 6.9203392 | E12: ='252'!G71 -> 22.752332 | F12: ='252'!H71 -> 23 | G12: ='252'!I71 -> 0 | H12: ='252'!J71 -> 0 | I12: ='252'!K71 -> 52.672671 | J12: ='252'!L71 -> 0 | K12: ='252'!M71 -> 27.402307 | ... S12: ='252'!U71 -> 0 | T12: =IF(SUM(D12:H12)=0,"— não preenchido",IF(ROUND(SUM(D12:H12)-C12,3)=0,"OK","ERRO — dif. de "&ROUND(SUM(D12:H12)-C12,3)&" km")) -> OK
A13: 253 | B13: RODOVIA TO-110 - TRECHO AURORA DO TOCANTINS - LAVANDEIRA | C13: ='253'!R33 -> 15.560727 | D13: ='253'!F30 -> 15.560727 | E13: ='253'!G30 -> 0 | F13: ='253'!H30 -> 0 | G13: ='253'!I30 -> 0 | H13: ='253'!J30 -> 0 | I13: ='253'!K30 -> 15.560727 | J13: ='253'!L30 -> 0 | K13: ='253'!M30 -> 11 | ... S13: ='253'!U30 -> 0 | T13: =IF(SUM(D13:H13)=0,"— não preenchido",IF(ROUND(SUM(D13:H13)-C13,3)=0,"OK","ERRO — dif. de "&ROUND(SUM(D13:H13)-C13,3)&" km")) -> OK
A14: 254 | B14: RODOVIA TO-110 - TRECHO COMBINADO - NOVO ALEGRE - DIVISA TO-GO | C14: ='254'!R40 -> 17.978238 | D14: ='254'!F37 -> 17.978238 | E14: ='254'!G37 -> 0 | F14: ='254'!H37 -> 0 | G14: ='254'!I37 -> 0 | H14: ='254'!J37 -> 0 | I14: ='254'!K37 -> 17.978238 | J14: ='254'!L37 -> 0 | K14: ='254'!M37 -> 2.4557659 | ... S14: ='254'!U37 -> 0 | T14: =IF(SUM(D14:H14)=0,"— não preenchido",IF(ROUND(SUM(D14:H14)-C14,3)=0,"OK","ERRO — dif. de "&ROUND(SUM(D14:H14)-C14,3)&" km")) -> OK
A15: 255 | B15: RODOVIA TO-110 - TRECHO ENTR. TO-040 (DIANÓPOLIS) - DIVISA TO-BA (GARGANTA) | C15: ='255'!R75 -> 57.452309 | D15: ='255'!F72 -> 10 | E15: ='255'!G72 -> 42.452309 | F15: ='255'!H72 -> 5 | G15: ='255'!I72 -> 0 | H15: ='255'!J72 -> 0 | I15: ='255'!K72 -> 57.452309 | J15: ='255'!L72 -> 0 | K15: ='255'!M72 -> 8 | ... S15: ='255'!U72 -> 0 | T15: =IF(SUM(D15:H15)=0,"— não preenchido",IF(ROUND(SUM(D15:H15)-C15,3)=0,"OK","ERRO — dif. de "&ROUND(SUM(D15:H15)-C15,3)&" km")) -> OK
A16: 256 | B16: RODOVIA TO-110 - TRECHO ENTR. TO-040 - PONTE ALTA DO BOM JESUS | C16: ='256'!R61 -> 38.006085 | D16: ='256'!F58 -> 11 | E16: ='256'!G58 -> 8.235733 | F16: ='256'!H58 -> 8.7703519 | G16: ='256'!I58 -> 10 | H16: ='256'!J58 -> 0 | I16: ='256'!K58 -> 28.006085 | J16: ='256'!L58 -> 10 | K16: ='256'!M58 -> 0 | ... S16: ='256'!U58 -> 0 | T16: =IF(SUM(D16:H16)=0,"— não preenchido",IF(ROUND(SUM(D16:H16)-C16,3)=0,"OK","ERRO — dif. de "&ROUND(SUM(D16:H16)-C16,3)&" km")) -> OK
A17: 257 | B17: RODOVIA TO-110 - TRECHO LAVANDEIRA - COMBINADO | C17: ='257'!R24 -> 6.3844721 | D17: ='257'!F21 -> 4 | E17: ='257'!G21 -> 2.3844721 | F17: ='257'!H21 -> 0 | G17: ='257'!I21 -> 0 | H17: ='257'!J21 -> 0 | I17: ='257'!K21 -> 6.3844721 | J17: ='257'!L21 -> 0 | K17: ='257'!M21 -> 1.3844721 | ... S17: ='257'!U21 -> 0 | T17: =IF(SUM(D17:H17)=0,"— não preenchido",IF(ROUND(SUM(D17:H17)-C17,3)=0,"OK","ERRO — dif. de "&ROUND(SUM(D17:H17)-C17,3)&" km")) -> OK
A18: 258 | B18: RODOVIA TO-110 - TRECHO PONTE ALTA DO BOM JESUS - ENTR. BR-242(TAGUATINGA) | C18: ='258'!R57 -> 35.496799 | D18: ='258'!F54 -> 25 | E18: ='258'!G54 -> 2.0180993 | F18: ='258'!H54 -> 6.4786997 | G18: ='258'!I54 -> 0 | H18: ='258'!J54 -> 2 | I18: ='258'!K54 -> 35.496799 | J18: ='258'!L54 -> 0 | K18: ='258'!M54 -> 0 | ... S18: ='258'!U54 -> 0 | T18: =IF(SUM(D18:H18)=0,"— não preenchido",IF(ROUND(SUM(D18:H18)-C18,3)=0,"OK","ERRO — dif. de "&ROUND(SUM(D18:H18)-C18,3)&" km")) -> OK
A19: 259 | B19: RODOVIA TO-110 - TRECHO TAGUATINGA - AURORA DO TOCANTINS | C19: ='259'!R73 -> 48.367488 | D19: ='259'!F70 -> 29.73627 | E19: ='259'!G70 -> 9.6312181 | F19: ='259'!H70 -> 7 | G19: ='259'!I70 -> 0 | H19: ='259'!J70 -> 2 | I19: ='259'!K70 -> 48.367488 | J19: ='259'!L70 -> 0 | K19: ='259'!M70 -> 0 | ... S19: ='259'!U70 -> 0 | T19: =IF(SUM(D19:H19)=0,"— não preenchido",IF(ROUND(SUM(D19:H19)-C19,3)=0,"OK","ERRO — dif. de "&ROUND(SUM(D19:H19)-C19,3)&" km")) -> OK
A20: 265 | B20: RODOVIA TO-387 - TRECHO ENTR. TO-040 - TAIPAS DO TOCANTINS | C20: ='265'!R19 -> 1.0866111 | D20: ='265'!F16 -> 0 | E20: ='265'!G16 -> 1.0866111 | F20: ='265'!H16 -> 0 | G20: ='265'!I16 -> 0 | H20: ='265'!J16 -> 0 | I20: ='265'!K16 -> 1.0866111 | J20: ='265'!L16 -> 0 | K20: ='265'!M16 -> 1.0866111 | ... S20: ='265'!U16 -> 0 | T20: =IF(SUM(D20:H20)=0,"— não preenchido",IF(ROUND(SUM(D20:H20)-C20,3)=0,"OK","ERRO — dif. de "&ROUND(SUM(D20:H20)-C20,3)&" km")) -> OK
A21: 266 | B21: RODOVIA TO-476 - TRECHO RIO DA CONCEIÇÃO - DIANÓPOLIS | C21: ='266'!R45 -> 26.737321 | D21: ='266'!F42 -> 0 | E21: ='266'!G42 -> 23.761116 | F21: ='266'!H42 -> 2.9762043 | G21: ='266'!I42 -> 0 | H21: ='266'!J42 -> 0 | I21: ='266'!K42 -> 21.737321 | J21: ='266'!L42 -> 5 | K21: ='266'!M42 -> 26.737321 | ... S21: ='266'!U42 -> 0 | T21: =IF(SUM(D21:H21)=0,"— não preenchido",IF(ROUND(SUM(D21:H21)-C21,3)=0,"OK","ERRO — dif. de "&ROUND(SUM(D21:H21)-C21,3)&" km")) -> OK
B22: TOTAL PERCORRIDO NO MÊS | C22: =SUM(C6:C21) -> 548.52427 | D22: =SUM(D6:D21) -> 226.57299 | E22: =SUM(E6:E21) -> 173.01589 | F22: =SUM(F6:F21) -> 134.93539 | G22: =SUM(G6:G21) -> 10 | H22: =SUM(H6:H21) -> 4 | I22: =SUM(I6:I21) -> 533.52427 | J22: =SUM(J6:J21) -> 15 | ... S22: =SUM(S6:S21) -> 0
B23: % DA EXTENSÃO DA MALHA (548.52 km) | D23: =SUM(D22:H22)/548.52 -> 1.0000078 | I23: (soma do grupo 'CONDIÇÃO DO PAVIMENTO' dividida pela malha)

Sheet 246
A1: PROGRAMA DE MANUTENÇÃO RODOVIÁRIA — FICHA DE INSPEÇÃO — RODOVIAS PAVIMENTADAS | Y1: Valores dos gráficos — troca 0 por N/D para a fatia não aparecer. Não editar.
A2: REGIÃO: 13 — DIANÓPOLIS | G2: MÊS / ANO: | I2: 46266 | K2: DATA: | P2: TÉCNICO: | R2: ENG. THIAGO BORGES TORQUATO | Y2: =IF(F31=0,NA(),F31) -> 4 | Z2: =IF(G31=0,NA(),G31) -> #N/A | AA2: =IF(H31=0,NA(),H31) -> 10.893612 | AB2: =IF(I31=0,NA(),I31) -> #N/A | AC2: =IF(J31=0,NA(),J31) -> #N/A | AD2: =IF(K31=0,NA(),K31) -> 14.893612 | AE2: =IF(L31=0,NA(),L31) -> #N/A | AF2: =IF(M31=0,NA(),M31) -> 4 | ... AN2: =IF(U31=0,NA(),U31) -> #N/A
A3: TRECHO 246 — RODOVIA TO-040 - TRECHO ALMAS - PORTO ALEGRE DO TOCANTINS | T3: EXTENSÃO: 14,894 km · 2 S.R.E.
A4: COMO PREENCHER: uma X em UMA coluna de cada grupo, por linha. Se houver mais de um defeito no mesmo km, marque o PREDOMINANTE e escreva o resto em OBSERVAÇÕES. A quilometragem é contada de 0 até o fim de CADA S.R.E. (não é o marco da rodovia).
A6: S.R.E. | B6: SENT. | C6: INÍCIO (KM) | D6: FIM (KM) | E6: EXT. (KM) | F6: CONDIÇÃO DO PAVIMENTO | K6: VEGETAÇÃO | M6: ELEM. DE DRENAGEM | P6: SIN. HORIZ. | S6: SIN. VERTICAL | V6: OBSERVAÇÕES | W6: CONFERÊNCIA (só na tela)
F7: BOM | G7: REM. I. | H7: REM. L. | I7: BUR. I. | J7: BUR. L. | K7: ADEQ. | L7: INAD. | M7: LIMPOS | N7: SUJOS | O7: DAN. | P7: BOM | Q7: REG. | R7: INEXIST. | S7: BOM | T7: POUCAS | U7: INEXIST.
A8: S.R.E. 040ETO0150 | ENTR. TO-280 (ALMAS) - ENTR. TO-477 | PPS · Estadual · 1.570 km · início: -11.560857, -47.168445
A9: 040ETO0150 | B9: C | C9: 0 | D9: 1 | E9: =D9-C9 -> 1 | H9: X | K9: X | N9: X | Q9: X | T9: X | W9: =IF(COUNTA(F9:U9)=0,"— não preenchido",IF(COUNTIF(F9:J9,"X")<>1,"FALTA/DUPLA: CONDIÇÃO DO PAVIMENTO",IF(COUNTIF(K9:L9,"X")<>1,"FALTA/DUPLA: VEGETAÇÃO",IF(COUNTIF(M9:O9,"X")<>1,"FALTA/DUPLA: ELEM. DE DRENAGEM",IF(COUNTIF(P9:R9,"X")<>1,"FALTA/DUPLA: SIN. HORIZ.",IF(COUNTIF(S9:U9,"X")<>1,"FALTA/DUPLA: SIN. VERTICAL","OK")))))) -> OK
A10: 040ETO0150 | B10: C | C10: 1 | D10: 1.5702205 | E10: =D10-C10 -> 0.57022047 | H10: X | K10: X | N10: X | Q10: X | T10: X | W10: =IF(COUNTA(F10:U10)=0,"— não preenchido",IF(COUNTIF(F10:J10,"X")<>1,"FALTA/DUPLA: CONDIÇÃO DO PAVIMENTO",IF(COUNTIF(K10:L10,"X")<>1,"FALTA/DUPLA: VEGETAÇÃO",IF(COUNTIF(M10:O10,"X")<>1,"FALTA/DUPLA: ELEM. DE DRENAGEM",IF(COUNTIF(P10:R10,"X")<>1,"FALTA/DUPLA: SIN. HORIZ.",IF(COUNTIF(S10:U10,"X")<>1,"FALTA/DUPLA: SIN. VERTICAL","OK")))))) -> OK
A11: S.R.E. 040ETO0160 | ENTR. TO-477 - PORTO ALEGRE DO TOCANTINS | PPS · Estadual · 13.323 km · início: -11.562467, -47.154838
A12: 040ETO0160 | B12: C | C12: 0 | D12: 1 | E12: =D12-C12 -> 1 | H12: X | K12: X | N12: X | Q12: X | T12: X | W12: =IF(COUNTA(F12:U12)=0,"— não preenchido",IF(COUNTIF(F12:J12,"X")<>1,"FALTA/DUPLA: CONDIÇÃO DO PAVIMENTO",IF(COUNTIF(K12:L12,"X")<>1,"FALTA/DUPLA: VEGETAÇÃO",IF(COUNTIF(M12:O12,"X")<>1,"FALTA/DUPLA: ELEM. DE DRENAGEM",IF(COUNTIF(P12:R12,"X")<>1,"FALTA/DUPLA: SIN. HORIZ.",IF(COUNTIF(S12:U12,"X")<>1,"FALTA/DUPLA: SIN. VERTICAL","OK")))))) -> OK
A13: 040ETO0160 | B13: C | C13: 1 | D13: 2 | E13: =D13-C13 -> 1 | H13: X | K13: X | M13: X | Q13: X | T13: X | W13: =IF(COUNTA(F13:U13)=0,"— não preenchido",IF(COUNTIF(F13:J13,"X")<>1,"FALTA/DUPLA: CONDIÇÃO DO PAVIMENTO",IF(COUNTIF(K13:L13,"X")<>1,"FALTA/DUPLA: VEGETAÇÃO",IF(COUNTIF(M13:O13,"X")<>1,"FALTA/DUPLA: ELEM. DE DRENAGEM",IF(COUNTIF(P13:R13,"X")<>1,"FALTA/DUPLA: SIN. HORIZ.",IF(COUNTIF(S13:U13,"X")<>1,"FALTA/DUPLA: SIN. VERTICAL","OK")))))) -> OK
A14: 040ETO0160 | B14: C | C14: 2 | D14: 3 | E14: =D14-C14 -> 1 | F14: X | K14: X | M14: X | Q14: X | T14: X | W14: =IF(COUNTA(F14:U14)=0,"— não preenchido",IF(COUNTIF(F14:J14,"X")<>1,"FALTA/DUPLA: CONDIÇÃO DO PAVIMENTO",IF(COUNTIF(K14:L14,"X")<>1,"FALTA/DUPLA: VEGETAÇÃO",IF(COUNTIF(M14:O14,"X")<>1,"FALTA/DUPLA: ELEM. DE DRENAGEM",IF(COUNTIF(P14:R14,"X")<>1,"FALTA/DUPLA: SIN. HORIZ.",IF(COUNTIF(S14:U14,"X")<>1,"FALTA/DUPLA: SIN. VERTICAL","OK")))))) -> OK
A15: 040ETO0160 | B15: C | C15: 3 | D15: 4 | E15: =D15-C15 -> 1 | F15: X | K15: X | M15: X | Q15: X | T15: X | W15: =IF(COUNTA(F15:U15)=0,"— não preenchido",IF(COUNTIF(F15:J15,"X")<>1,"FALTA/DUPLA: CONDIÇÃO DO PAVIMENTO",IF(COUNTIF(K15:L15,"X")<>1,"FALTA/DUPLA: VEGETAÇÃO",IF(COUNTIF(M15:O15,"X")<>1,"FALTA/DUPLA: ELEM. DE DRENAGEM",IF(COUNTIF(P15:R15,"X")<>1,"FALTA/DUPLA: SIN. HORIZ.",IF(COUNTIF(S15:U15,"X")<>1,"FALTA/DUPLA: SIN. VERTICAL","OK")))))) -> OK
A16: 040ETO0160 | B16: C | C16: 4 | D16: 5 | E16: =D16-C16 -> 1 | F16: X | K16: X | M16: X | Q16: X | T16: X | W16: =IF(COUNTA(F16:U16)=0,"— não preenchido",IF(COUNTIF(F16:J16,"X")<>1,"FALTA/DUPLA: CONDIÇÃO DO PAVIMENTO",IF(COUNTIF(K16:L16,"X")<>1,"FALTA/DUPLA: VEGETAÇÃO",IF(COUNTIF(M16:O16,"X")<>1,"FALTA/DUPLA: ELEM. DE DRENAGEM",IF(COUNTIF(P16:R16,"X")<>1,"FALTA/DUPLA: SIN. HORIZ.",IF(COUNTIF(S16:U16,"X")<>1,"FALTA/DUPLA: SIN. VERTICAL","OK")))))) -> OK
A17: 040ETO0160 | B17: C | C17: 5 | D17: 6 | E17: =D17-C17 -> 1 | F17: X | K17: X | N17: X | Q17: X | T17: X | W17: =IF(COUNTA(F17:U17)=0,"— não preenchido",IF(COUNTIF(F17:J17,"X")<>1,"FALTA/DUPLA: CONDIÇÃO DO PAVIMENTO",IF(COUNTIF(K17:L17,"X")<>1,"FALTA/DUPLA: VEGETAÇÃO",IF(COUNTIF(M17:O17,"X")<>1,"FALTA/DUPLA: ELEM. DE DRENAGEM",IF(COUNTIF(P17:R17,"X")<>1,"FALTA/DUPLA: SIN. HORIZ.",IF(COUNTIF(S17:U17,"X")<>1,"FALTA/DUPLA: SIN. VERTICAL","OK")))))) -> OK
A18: 040ETO0160 | B18: C | C18: 6 | D18: 7 | E18: =D18-C18 -> 1 | H18: X | K18: X | N18: X | Q18: X | T18: X | W18: =IF(COUNTA(F18:U18)=0,"— não preenchido",IF(COUNTIF(F18:J18,"X")<>1,"FALTA/DUPLA: CONDIÇÃO DO PAVIMENTO",IF(COUNTIF(K18:L18,"X")<>1,"FALTA/DUPLA: VEGETAÇÃO",IF(COUNTIF(M18:O18,"X")<>1,"FALTA/DUPLA: ELEM. DE DRENAGEM",IF(COUNTIF(P18:R18,"X")<>1,"FALTA/DUPLA: SIN. HORIZ.",IF(COUNTIF(S18:U18,"X")<>1,"FALTA/DUPLA: SIN. VERTICAL","OK")))))) -> OK
A19: 040ETO0160 | B19: C | C19: 7 | D19: 8 | E19: =D19-C19 -> 1 | H19: X | K19: X | N19: X | Q19: X | T19: X | W19: =IF(COUNTA(F19:U19)=0,"— não preenchido",IF(COUNTIF(F19:J19,"X")<>1,"FALTA/DUPLA: CONDIÇÃO DO PAVIMENTO",IF(COUNTIF(K19:L19,"X")<>1,"FALTA/DUPLA: VEGETAÇÃO",IF(COUNTIF(M19:O19,"X")<>1,"FALTA/DUPLA: ELEM. DE DRENAGEM",IF(COUNTIF(P19:R19,"X")<>1,"FALTA/DUPLA: SIN. HORIZ.",IF(COUNTIF(S19:U19,"X")<>1,"FALTA/DUPLA: SIN. VERTICAL","OK")))))) -> OK
A20: 040ETO0160 | B20: C | C20: 8 | D20: 9 | E20: =D20-C20 -> 1 | H20: X | K20: X | N20: X | Q20: X | T20: X | W20: =IF(COUNTA(F20:U20)=0,"— não preenchido",IF(COUNTIF(F20:J20,"X")<>1,"FALTA/DUPLA: CONDIÇÃO DO PAVIMENTO",IF(COUNTIF(K20:L20,"X")<>1,"FALTA/DUPLA: VEGETAÇÃO",IF(COUNTIF(M20:O20,"X")<>1,"FALTA/DUPLA: ELEM. DE DRENAGEM",IF(COUNTIF(P20:R20,"X")<>1,"FALTA/DUPLA: SIN. HORIZ.",IF(COUNTIF(S20:U20,"X")<>1,"FALTA/DUPLA: SIN. VERTICAL","OK")))))) -> OK
A21: 040ETO0160 | B21: C | C21: 9 | D21: 10 | E21: =D21-C21 -> 1 | H21: X | K21: X | N21: X | Q21: X | T21: X | W21: =IF(COUNTA(F21:U21)=0,"— não preenchido",IF(COUNTIF(F21:J21,"X")<>1,"FALTA/DUPLA: CONDIÇÃO DO PAVIMENTO",IF(COUNTIF(K21:L21,"X")<>1,"FALTA/DUPLA: VEGETAÇÃO",IF(COUNTIF(M21:O21,"X")<>1,"FALTA/DUPLA: ELEM. DE DRENAGEM",IF(COUNTIF(P21:R21,"X")<>1,"FALTA/DUPLA: SIN. HORIZ.",IF(COUNTIF(S21:U21,"X")<>1,"FALTA/DUPLA: SIN. VERTICAL","OK")))))) -> OK
A22: 040ETO0160 | B22: C | C22: 10 | D22: 11 | E22: =D22-C22 -> 1 | H22: X | K22: X | N22: X | Q22: X | T22: X | W22: =IF(COUNTA(F22:U22)=0,"— não preenchido",IF(COUNTIF(F22:J22,"X")<>1,"FALTA/DUPLA: CONDIÇÃO DO PAVIMENTO",IF(COUNTIF(K22:L22,"X")<>1,"FALTA/DUPLA: VEGETAÇÃO",IF(COUNTIF(M22:O22,"X")<>1,"FALTA/DUPLA: ELEM. DE DRENAGEM",IF(COUNTIF(P22:R22,"X")<>1,"FALTA/DUPLA: SIN. HORIZ.",IF(COUNTIF(S22:U22,"X")<>1,"FALTA/DUPLA: SIN. VERTICAL","OK")))))) -> OK
A23: 040ETO0160 | B23: C | C23: 11 | D23: 12 | E23: =D23-C23 -> 1 | H23: X | K23: X | N23: X | Q23: X | T23: X | W23: =IF(COUNTA(F23:U23)=0,"— não preenchido",IF(COUNTIF(F23:J23,"X")<>1,"FALTA/DUPLA: CONDIÇÃO DO PAVIMENTO",IF(COUNTIF(K23:L23,"X")<>1,"FALTA/DUPLA: VEGETAÇÃO",IF(COUNTIF(M23:O23,"X")<>1,"FALTA/DUPLA: ELEM. DE DRENAGEM",IF(COUNTIF(P23:R23,"X")<>1,"FALTA/DUPLA: SIN. HORIZ.",IF(COUNTIF(S23:U23,"X")<>1,"FALTA/DUPLA: SIN. VERTICAL","OK")))))) -> OK
A24: 040ETO0160 | B24: C | C24: 12 | D24: 13 | E24: =D24-C24 -> 1 | H24: X | K24: X | N24: X | Q24: X | T24: X | W24: =IF(COUNTA(F24:U24)=0,"— não preenchido",IF(COUNTIF(F24:J24,"X")<>1,"FALTA/DUPLA: CONDIÇÃO DO PAVIMENTO",IF(COUNTIF(K24:L24,"X")<>1,"FALTA/DUPLA: VEGETAÇÃO",IF(COUNTIF(M24:O24,"X")<>1,"FALTA/DUPLA: ELEM. DE DRENAGEM",IF(COUNTIF(P24:R24,"X")<>1,"FALTA/DUPLA: SIN. HORIZ.",IF(COUNTIF(S24:U24,"X")<>1,"FALTA/DUPLA: SIN. VERTICAL","OK")))))) -> OK
A25: 040ETO0160 | B25: C | C25: 13 | D25: 13.323392 | E25: =D25-C25 -> 0.3233917 | H25: X | K25: X | N25: X | Q25: X | T25: X | W25: =IF(COUNTA(F25:U25)=0,"— não preenchido",IF(COUNTIF(F25:J25,"X")<>1,"FALTA/DUPLA: CONDIÇÃO DO PAVIMENTO",IF(COUNTIF(K25:L25,"X")<>1,"FALTA/DUPLA: VEGETAÇÃO",IF(COUNTIF(M25:O25,"X")<>1,"FALTA/DUPLA: ELEM. DE DRENAGEM",IF(COUNTIF(P25:R25,"X")<>1,"FALTA/DUPLA: SIN. HORIZ.",IF(COUNTIF(S25:U25,"X")<>1,"FALTA/DUPLA: SIN. VERTICAL","OK")))))) -> OK
A27: ____________________________________________ | G27: ____________________________________________
A28: TÉCNICO RESPONSÁVEL PELA INSPEÇÃO | G28: VISTO DA SUPERVISÃO
A30: RESUMO DO TRECHO — KM LANÇADO POR ITEM
A31: KM LANÇADO | F31: =SUMIF(F$9:F$25,"X",$E$9:$E$25) -> 4 | G31: =SUMIF(G$9:G$25,"X",$E$9:$E$25) -> 0 | H31: =SUMIF(H$9:H$25,"X",$E$9:$E$25) -> 10.893612 | I31: =SUMIF(I$9:I$25,"X",$E$9:$E$25) -> 0 | J31: =SUMIF(J$9:J$25,"X",$E$9:$E$25) -> 0 | K31: =SUMIF(K$9:K$25,"X",$E$9:$E$25) -> 14.893612 | L31: =SUMIF(L$9:L$25,"X",$E$9:$E$25) -> 0 | M31: =SUMIF(M$9:M$25,"X",$E$9:$E$25) -> 4 | ... U31: =SUMIF(U$9:U$25,"X",$E$9:$E$25) -> 0
A32: % DA EXTENSÃO | F32: =IF($R34=0,0,F31/$R34) -> 0.26857152 | G32: =IF($R34=0,0,G31/$R34) -> 0 | H32: =IF($R34=0,0,H31/$R34) -> 0.73142848 | I32: =IF($R34=0,0,I31/$R34) -> 0 | J32: =IF($R34=0,0,J31/$R34) -> 0 | K32: =IF($R34=0,0,K31/$R34) -> 1 | L32: =IF($R34=0,0,L31/$R34) -> 0 | M32: =IF($R34=0,0,M31/$R34) -> 0.26857152 | ... U32: =IF($R34=0,0,U31/$R34) -> 0
A33: CONFERÊNCIA POR GRUPO | F33: =IF(SUM(F31:J31)=0,"— não preenchido",IF(ROUND(SUM(F31:J31)-$R34,3)=0,"OK — "&ROUND(SUM(F31:J31),3)&" km","ERRO — dif. de "&ROUND(SUM(F31:J31)-$R34,3)&" km")) -> OK — 14,894 km | K33: =IF(SUM(K31:L31)=0,"— não preenchido",IF(ROUND(SUM(K31:L31)-$R34,3)=0,"OK — "&ROUND(SUM(K31:L31),3)&" km","ERRO — dif. de "&ROUND(SUM(K31:L31)-$R34,3)&" km")) -> OK — 14,894 km | M33: =IF(SUM(M31:O31)=0,"— não preenchido",IF(ROUND(SUM(M31:O31)-$R34,3)=0,"OK — "&ROUND(SUM(M31:O31),3)&" km","ERRO — dif. de "&ROUND(SUM(M31:O31)-$R34,3)&" km")) -> OK — 14,894 km | P33: =IF(SUM(P31:R31)=0,"— não preenchido",IF(ROUND(SUM(P31:R31)-$R34,3)=0,"OK — "&ROUND(SUM(P31:R31),3)&" km","ERRO — dif. de "&ROUND(SUM(P31:R31)-$R34,3)&" km")) -> OK — 14,894 km | S33: =IF(SUM(S31:U31)=0,"— não preenchido",IF(ROUND(SUM(S31:U31)-$R34,3)=0,"OK — "&ROUND(SUM(S31:U31),3)&" km","ERRO — dif. de "&ROUND(SUM(S31:U31)-$R34,3)&" km")) -> OK — 14,894 km
A34: EXTENSÃO TOTAL DO TRECHO | R34: =SUM(E9:E25) -> 14.893612 | V34: =COUNTIF(W9:W25,"OK")&" de "&COUNT($E$9:$E$25)&" linhas conferidas" -> 16 de 16 linhas conferidas
A36: LEGENDA
A37: REM. I. / REM. L. | E37: Remendos isolados (até 10 por km) · Remendos ao longo (mais de 10 por km)
A38: BUR. I. / BUR. L. | E38: Buracos isolados (até 5 por km) · Buracos ao longo (mais de 5 por km)
A39: SIT. | E39: PPS = pista simples · PSU = simples urbana · PDU = duplicada
A40: FAIXA AZUL | E40: Cabeçalho de cada S.R.E.: descrição, situação, jurisdição, extensão e coordenada de início.
A41: INÍCIO / FIM (KM) | E41: Contados de 0 até o fim de CADA S.R.E. Não é o marco quilométrico da rodovia.
A42: SENT. | E42: C = crescente · D = decrescente
A43: FAIXA CINZA | E43: Segmento fora do escopo do contrato: você passa por ele, mas não preenche.
A44: CÉLULA VERMELHA | E44: Mais de uma X no mesmo grupo. Apague uma delas.
...

Sheet 247
A1: PROGRAMA DE MANUTENÇÃO RODOVIÁRIA — FICHA DE INSPEÇÃO — RODOVIAS PAVIMENTADAS | Y1: Valores dos gráficos — troca 0 por N/D para a fatia não aparecer. Não editar.
A2: REGIÃO: 13 — DIANÓPOLIS | G2: MÊS / ANO: | I2: 46266 | K2: DATA: | P2: TÉCNICO: | R2: ENG. THIAGO BORGES TORQUATO | Y2: =IF(F54=0,NA(),F54) -> #N/A | Z2: =IF(G54=0,NA(),G54) -> 16.481209 | AA2: =IF(H54=0,NA(),H54) -> 19.5653 | AB2: =IF(I54=0,NA(),I54) -> #N/A | AC2: =IF(J54=0,NA(),J54) -> #N/A | AD2: =IF(K54=0,NA(),K54) -> 36.046509 | AE2: =IF(L54=0,NA(),L54) -> #N/A | AF2: =IF(M54=0,NA(),M54) -> 6.4812088 | ... AN2: =IF(U54=0,NA(),U54) -> #N/A
A3: TRECHO 247 — RODOVIA TO-040 - TRECHO DIANÓPOLIS - NOVO JARDIM | T3: EXTENSÃO: 36,047 km · 3 S.R.E.
A4: COMO PREENCHER: uma X em UMA coluna de cada grupo, por linha. Se houver mais de um defeito no mesmo km, marque o PREDOMINANTE e escreva o resto em OBSERVAÇÕES. A quilometragem é contada de 0 até o fim de CADA S.R.E. (não é o marco da rodovia).
A6: S.R.E. | B6: SENT. | C6: INÍCIO (KM) | D6: FIM (KM) | E6: EXT. (KM) | F6: CONDIÇÃO DO PAVIMENTO | K6: VEGETAÇÃO | M6: ELEM. DE DRENAGEM | P6: SIN. HORIZ. | S6: SIN. VERTICAL | V6: OBSERVAÇÕES | W6: CONFERÊNCIA (só na tela)
F7: BOM | G7: REM. I. | H7: REM. L. | I7: BUR. I. | J7: BUR. L. | K7: ADEQ. | L7: INAD. | M7: LIMPOS | N7: SUJOS | O7: DAN. | P7: BOM | Q7: REG. | R7: INEXIST. | S7: BOM | T7: POUCAS | U7: INEXIST.
A8: S.R.E. 040ETO0190 | ENTR. TO-476 (DIANÓPOLIS) - ENTR. TO-387-TO-110 | PPS · Estadual · 6.295 km · início: -11.613246, -46.82411
A9: 040ETO0190 | B9: C | C9: 0 | D9: 1 | E9: =D9-C9 -> 1 | G9: X | K9: X | N9: X | Q9: X | T9: X | W9: =IF(COUNTA(F9:U9)=0,"— não preenchido",IF(COUNTIF(F9:J9,"X")<>1,"FALTA/DUPLA: CONDIÇÃO DO PAVIMENTO",IF(COUNTIF(K9:L9,"X")<>1,"FALTA/DUPLA: VEGETAÇÃO",IF(COUNTIF(M9:O9,"X")<>1,"FALTA/DUPLA: ELEM. DE DRENAGEM",IF(COUNTIF(P9:R9,"X")<>1,"FALTA/DUPLA: SIN. HORIZ.",IF(COUNTIF(S9:U9,"X")<>1,"FALTA/DUPLA: SIN. VERTICAL","OK")))))) -> OK
A10: 040ETO0190 | B10: C | C10: 1 | D10: 2 | E10: =D10-C10 -> 1 | G10: X | K10: X | N10: X | Q10: X | T10: X | W10: =IF(COUNTA(F10:U10)=0,"— não preenchido",IF(COUNTIF(F10:J10,"X")<>1,"FALTA/DUPLA: CONDIÇÃO DO PAVIMENTO",IF(COUNTIF(K10:L10,"X")<>1,"FALTA/DUPLA: VEGETAÇÃO",IF(COUNTIF(M10:O10,"X")<>1,"FALTA/DUPLA: ELEM. DE DRENAGEM",IF(COUNTIF(P10:R10,"X")<>1,"FALTA/DUPLA: SIN. HORIZ.",IF(COUNTIF(S10:U10,"X")<>1,"FALTA/DUPLA: SIN. VERTICAL","OK")))))) -> OK
A11: 040ETO0190 | B11: C | C11: 2 | D11: 3 | E11: =D11-C11 -> 1 | G11: X | K11: X | M11: X | Q11: X | T11: X | W11: =IF(COUNTA(F11:U11)=0,"— não preenchido",IF(COUNTIF(F11:J11,"X")<>1,"FALTA/DUPLA: CONDIÇÃO DO PAVIMENTO",IF(COUNTIF(K11:L11,"X")<>1,"FALTA/DUPLA: VEGETAÇÃO",IF(COUNTIF(M11:O11,"X")<>1,"FALTA/DUPLA: ELEM. DE DRENAGEM",IF(COUNTIF(P11:R11,"X")<>1,"FALTA/DUPLA: SIN. HORIZ.",IF(COUNTIF(S11:U11,"X")<>1,"FALTA/DUPLA: SIN. VERTICAL","OK")))))) -> OK
A12: 040ETO0190 | B12: C | C12: 3 | D12: 4 | E12: =D12-C12 -> 1 | G12: X | K12: X | M12: X | Q12: X | T12: X | W12: =IF(COUNTA(F12:U12)=0,"— não preenchido",IF(COUNTIF(F12:J12,"X")<>1,"FALTA/DUPLA: CONDIÇÃO DO PAVIMENTO",IF(COUNTIF(K12:L12,"X")<>1,"FALTA/DUPLA: VEGETAÇÃO",IF(COUNTIF(M12:O12,"X")<>1,"FALTA/DUPLA: ELEM. DE DRENAGEM",IF(COUNTIF(P12:R12,"X")<>1,"FALTA/DUPLA: SIN. HORIZ.",IF(COUNTIF(S12:U12,"X")<>1,"FALTA/DUPLA: SIN. VERTICAL","OK")))))) -> OK
A13: 040ETO0190 | B13: C | C13: 4 | D13: 5 | E13: =D13-C13 -> 1 | G13: X | K13: X | N13: X | Q13: X | T13: X | W13: =IF(COUNTA(F13:U13)=0,"— não preenchido",IF(COUNTIF(F13:J13,"X")<>1,"FALTA/DUPLA: CONDIÇÃO DO PAVIMENTO",IF(COUNTIF(K13:L13,"X")<>1,"FALTA/DUPLA: VEGETAÇÃO",IF(COUNTIF(M13:O13,"X")<>1,"FALTA/DUPLA: ELEM. DE DRENAGEM",IF(COUNTIF(P13:R13,"X")<>1,"FALTA/DUPLA: SIN. HORIZ.",IF(COUNTIF(S13:U13,"X")<>1,"FALTA/DUPLA: SIN. VERTICAL","OK")))))) -> OK
A14: 040ETO0190 | B14: C | C14: 5 | D14: 6 | E14: =D14-C14 -> 1 | H14: X | K14: X | N14: X | Q14: X | T14: X | W14: =IF(COUNTA(F14:U14)=0,"— não preenchido",IF(COUNTIF(F14:J14,"X")<>1,"FALTA/DUPLA: CONDIÇÃO DO PAVIMENTO",IF(COUNTIF(K14:L14,"X")<>1,"FALTA/DUPLA: VEGETAÇÃO",IF(COUNTIF(M14:O14,"X")<>1,"FALTA/DUPLA: ELEM. DE DRENAGEM",IF(COUNTIF(P14:R14,"X")<>1,"FALTA/DUPLA: SIN. HORIZ.",IF(COUNTIF(S14:U14,"X")<>1,"FALTA/DUPLA: SIN. VERTICAL","OK")))))) -> OK
A15: 040ETO0190 | B15: C | C15: 6 | D15: 6.2949204 | E15: =D15-C15 -> 0.29492043 | H15: X | K15: X | N15: X | Q15: X | T15: X | W15: =IF(COUNTA(F15:U15)=0,"— não preenchido",IF(COUNTIF(F15:J15,"X")<>1,"FALTA/DUPLA: CONDIÇÃO DO PAVIMENTO",IF(COUNTIF(K15:L15,"X")<>1,"FALTA/DUPLA: VEGETAÇÃO",IF(COUNTIF(M15:O15,"X")<>1,"FALTA/DUPLA: ELEM. DE DRENAGEM",IF(COUNTIF(P15:R15,"X")<>1,"FALTA/DUPLA: SIN. HORIZ.",IF(COUNTIF(S15:U15,"X")<>1,"FALTA/DUPLA: SIN. VERTICAL","OK")))))) -> OK
A16: S.R.E. 040ETO0200 | ENTR. TO-387-TO-110 - AMARALINA | PPS · Estadual · 11.481 km · início: -11.627861, -46.77819
A17: 040ETO0200 | B17: C | C17: 0 | D17: 1 | E17: =D17-C17 -> 1 | G17: X | K17: X | N17: X | Q17: X | T17: X | W17: =IF(COUNTA(F17:U17)=0,"— não preenchido",IF(COUNTIF(F17:J17,"X")<>1,"FALTA/DUPLA: CONDIÇÃO DO PAVIMENTO",IF(COUNTIF(K17:L17,"X")<>1,"FALTA/DUPLA: VEGETAÇÃO",IF(COUNTIF(M17:O17,"X")<>1,"FALTA/DUPLA: ELEM. DE DRENAGEM",IF(COUNTIF(P17:R17,"X")<>1,"FALTA/DUPLA: SIN. HORIZ.",IF(COUNTIF(S17:U17,"X")<>1,"FALTA/DUPLA: SIN. VERTICAL","OK")))))) -> OK
A18: 040ETO0200 | B18: C | C18: 1 | D18: 2 | E18: =D18-C18 -> 1 | G18: X | K18: X | N18: X | Q18: X | T18: X | W18: =IF(COUNTA(F18:U18)=0,"— não preenchido",IF(COUNTIF(F18:J18,"X")<>1,"FALTA/DUPLA: CONDIÇÃO DO PAVIMENTO",IF(COUNTIF(K18:L18,"X")<>1,"FALTA/DUPLA: VEGETAÇÃO",IF(COUNTIF(M18:O18,"X")<>1,"FALTA/DUPLA: ELEM. DE DRENAGEM",IF(COUNTIF(P18:R18,"X")<>1,"FALTA/DUPLA: SIN. HORIZ.",IF(COUNTIF(S18:U18,"X")<>1,"FALTA/DUPLA: SIN. VERTICAL","OK")))))) -> OK
A19: 040ETO0200 | B19: C | C19: 2 | D19: 3 | E19: =D19-C19 -> 1 | G19: X | K19: X | N19: X | Q19: X | T19: X | W19: =IF(COUNTA(F19:U19)=0,"— não preenchido",IF(COUNTIF(F19:J19,"X")<>1,"FALTA/DUPLA: CONDIÇÃO DO PAVIMENTO",IF(COUNTIF(K19:L19,"X")<>1,"FALTA/DUPLA: VEGETAÇÃO",IF(COUNTIF(M19:O19,"X")<>1,"FALTA/DUPLA: ELEM. DE DRENAGEM",IF(COUNTIF(P19:R19,"X")<>1,"FALTA/DUPLA: SIN. HORIZ.",IF(COUNTIF(S19:U19,"X")<>1,"FALTA/DUPLA: SIN. VERTICAL","OK")))))) -> OK
A20: 040ETO0200 | B20: C | C20: 3 | D20: 4 | E20: =D20-C20 -> 1 | G20: X | K20: X | N20: X | Q20: X | T20: X | W20: =IF(COUNTA(F20:U20)=0,"— não preenchido",IF(COUNTIF(F20:J20,"X")<>1,"FALTA/DUPLA: CONDIÇÃO DO PAVIMENTO",IF(COUNTIF(K20:L20,"X")<>1,"FALTA/DUPLA: VEGETAÇÃO",IF(COUNTIF(M20:O20,"X")<>1,"FALTA/DUPLA: ELEM. DE DRENAGEM",IF(COUNTIF(P20:R20,"X")<>1,"FALTA/DUPLA: SIN. HORIZ.",IF(COUNTIF(S20:U20,"X")<>1,"FALTA/DUPLA: SIN. VERTICAL","OK")))))) -> OK
A21: 040ETO0200 | B21: C | C21: 4 | D21: 5 | E21: =D21-C21 -> 1 | G21: X | K21: X | N21: X | Q21: X | T21: X | W21: =IF(COUNTA(F21:U21)=0,"— não preenchido",IF(COUNTIF(F21:J21,"X")<>1,"FALTA/DUPLA: CONDIÇÃO DO PAVIMENTO",IF(COUNTIF(K21:L21,"X")<>1,"FALTA/DUPLA: VEGETAÇÃO",IF(COUNTIF(M21:O21,"X")<>1,"FALTA/DUPLA: ELEM. DE DRENAGEM",IF(COUNTIF(P21:R21,"X")<>1,"FALTA/DUPLA: SIN. HORIZ.",IF(COUNTIF(S21:U21,"X")<>1,"FALTA/DUPLA: SIN. VERTICAL","OK")))))) -> OK
A22: 040ETO0200 | B22: C | C22: 5 | D22: 6 | E22: =D22-C22 -> 1 | G22: X | K22: X | N22: X | Q22: X | T22: X | W22: =IF(COUNTA(F22:U22)=0,"— não preenchido",IF(COUNTIF(F22:J22,"X")<>1,"FALTA/DUPLA: CONDIÇÃO DO PAVIMENTO",IF(COUNTIF(K22:L22,"X")<>1,"FALTA/DUPLA: VEGETAÇÃO",IF(COUNTIF(M22:O22,"X")<>1,"FALTA/DUPLA: ELEM. DE DRENAGEM",IF(COUNTIF(P22:R22,"X")<>1,"FALTA/DUPLA: SIN. HORIZ.",IF(COUNTIF(S22:U22,"X")<>1,"FALTA/DUPLA: SIN. VERTICAL","OK")))))) -> OK
A23: 040ETO0200 | B23: C | C23: 6 | D23: 7 | E23: =D23-C23 -> 1 | G23: X | K23: X | N23: X | Q23: X | T23: X | W23: =IF(COUNTA(F23:U23)=0,"— não preenchido",IF(COUNTIF(F23:J23,"X")<>1,"FALTA/DUPLA: CONDIÇÃO DO PAVIMENTO",IF(COUNTIF(K23:L23,"X")<>1,"FALTA/DUPLA: VEGETAÇÃO",IF(COUNTIF(M23:O23,"X")<>1,"FALTA/DUPLA: ELEM. DE DRENAGEM",IF(COUNTIF(P23:R23,"X")<>1,"FALTA/DUPLA: SIN. HORIZ.",IF(COUNTIF(S23:U23,"X")<>1,"FALTA/DUPLA: SIN. VERTICAL","OK")))))) -> OK
A24: 040ETO0200 | B24: C | C24: 7 | D24: 8 | E24: =D24-C24 -> 1 | G24: X | K24: X | M24: X | Q24: X | T24: X | W24: =IF(COUNTA(F24:U24)=0,"— não preenchido",IF(COUNTIF(F24:J24,"X")<>1,"FALTA/DUPLA: CONDIÇÃO DO PAVIMENTO",IF(COUNTIF(K24:L24,"X")<>1,"FALTA/DUPLA: VEGETAÇÃO",IF(COUNTIF(M24:O24,"X")<>1,"FALTA/DUPLA: ELEM. DE DRENAGEM",IF(COUNTIF(P24:R24,"X")<>1,"FALTA/DUPLA: SIN. HORIZ.",IF(COUNTIF(S24:U24,"X")<>1,"FALTA/DUPLA: SIN. VERTICAL","OK")))))) -> OK
A25: 040ETO0200 | B25: C | C25: 8 | D25: 9 | E25: =D25-C25 -> 1 | G25: X | K25: X | M25: X | Q25: X | T25: X | W25: =IF(COUNTA(F25:U25)=0,"— não preenchido",IF(COUNTIF(F25:J25,"X")<>1,"FALTA/DUPLA: CONDIÇÃO DO PAVIMENTO",IF(COUNTIF(K25:L25,"X")<>1,"FALTA/DUPLA: VEGETAÇÃO",IF(COUNTIF(M25:O25,"X")<>1,"FALTA/DUPLA: ELEM. DE DRENAGEM",IF(COUNTIF(P25:R25,"X")<>1,"FALTA/DUPLA: SIN. HORIZ.",IF(COUNTIF(S25:U25,"X")<>1,"FALTA/DUPLA: SIN. VERTICAL","OK")))))) -> OK
A26: 040ETO0200 | B26: C | C26: 9 | D26: 10 | E26: =D26-C26 -> 1 | G26: X | K26: X | M26: X | Q26: X | T26: X | W26: =IF(COUNTA(F26:U26)=0,"— não preenchido",IF(COUNTIF(F26:J26,"X")<>1,"FALTA/DUPLA: CONDIÇÃO DO PAVIMENTO",IF(COUNTIF(K26:L26,"X")<>1,"FALTA/DUPLA: VEGETAÇÃO",IF(COUNTIF(M26:O26,"X")<>1,"FALTA/DUPLA: ELEM. DE DRENAGEM",IF(COUNTIF(P26:R26,"X")<>1,"FALTA/DUPLA: SIN. HORIZ.",IF(COUNTIF(S26:U26,"X")<>1,"FALTA/DUPLA: SIN. VERTICAL","OK")))))) -> OK
A27: 040ETO0200 | B27: C | C27: 10 | D27: 11 | E27: =D27-C27 -> 1 | G27: X | K27: X | M27: X | Q27: X | T27: X | W27: =IF(COUNTA(F27:U27)=0,"— não preenchido",IF(COUNTIF(F27:J27,"X")<>1,"FALTA/DUPLA: CONDIÇÃO DO PAVIMENTO",IF(COUNTIF(K27:L27,"X")<>1,"FALTA/DUPLA: VEGETAÇÃO",IF(COUNTIF(M27:O27,"X")<>1,"FALTA/DUPLA: ELEM. DE DRENAGEM",IF(COUNTIF(P27:R27,"X")<>1,"FALTA/DUPLA: SIN. HORIZ.",IF(COUNTIF(S27:U27,"X")<>1,"FALTA/DUPLA: SIN. VERTICAL","OK")))))) -> OK
A28: 040ETO0200 | B28: C | C28: 11 | D28: 11.481209 | E28: =D28-C28 -> 0.48120884 | G28: X | K28: X | M28: X | Q28: X | T28: X | W28: =IF(COUNTA(F28:U28)=0,"— não preenchido",IF(COUNTIF(F28:J28,"X")<>1,"FALTA/DUPLA: CONDIÇÃO DO PAVIMENTO",IF(COUNTIF(K28:L28,"X")<>1,"FALTA/DUPLA: VEGETAÇÃO",IF(COUNTIF(M28:O28,"X")<>1,"FALTA/DUPLA: ELEM. DE DRENAGEM",IF(COUNTIF(P28:R28,"X")<>1,"FALTA/DUPLA: SIN. HORIZ.",IF(COUNTIF(S28:U28,"X")<>1,"FALTA/DUPLA: SIN. VERTICAL","OK")))))) -> OK
A29: S.R.E. 040ETO0210 | AMARALINA - NOVO JARDIM | PPS · Estadual · 18.270 km · início: -11.720146, -46.741074
A30: 040ETO0210 | B30: C | C30: 0 | D30: 1 | E30: =D30-C30 -> 1 | H30: X | K30: X | N30: X | Q30: X | T30: X | W30: =IF(COUNTA(F30:U30)=0,"— não preenchido",IF(COUNTIF(F30:J30,"X")<>1,"FALTA/DUPLA: CONDIÇÃO DO PAVIMENTO",IF(COUNTIF(K30:L30,"X")<>1,"FALTA/DUPLA: VEGETAÇÃO",IF(COUNTIF(M30:O30,"X")<>1,"FALTA/DUPLA: ELEM. DE DRENAGEM",IF(COUNTIF(P30:R30,"X")<>1,"FALTA/DUPLA: SIN. HORIZ.",IF(COUNTIF(S30:U30,"X")<>1,"FALTA/DUPLA: SIN. VERTICAL","OK")))))) -> OK
A31: 040ETO0210 | B31: C | C31: 1 | D31: 2 | E31: =D31-C31 -> 1 | H31: X | K31: X | N31: X | Q31: X | T31: X | W31: =IF(COUNTA(F31:U31)=0,"— não preenchido",IF(COUNTIF(F31:J31,"X")<>1,"FALTA/DUPLA: CONDIÇÃO DO PAVIMENTO",IF(COUNTIF(K31:L31,"X")<>1,"FALTA/DUPLA: VEGETAÇÃO",IF(COUNTIF(M31:O31,"X")<>1,"FALTA/DUPLA: ELEM. DE DRENAGEM",IF(COUNTIF(P31:R31,"X")<>1,"FALTA/DUPLA: SIN. HORIZ.",IF(COUNTIF(S31:U31,"X")<>1,"FALTA/DUPLA: SIN. VERTICAL","OK")))))) -> OK
A32: 040ETO0210 | B32: C | C32: 2 | D32: 3 | E32: =D32-C32 -> 1 | H32: X | K32: X | N32: X | Q32: X | T32: X | W32: =IF(COUNTA(F32:U32)=0,"— não preenchido",IF(COUNTIF(F32:J32,"X")<>1,"FALTA/DUPLA: CONDIÇÃO DO PAVIMENTO",IF(COUNTIF(K32:L32,"X")<>1,"FALTA/DUPLA: VEGETAÇÃO",IF(COUNTIF(M32:O32,"X")<>1,"FALTA/DUPLA: ELEM. DE DRENAGEM",IF(COUNTIF(P32:R32,"X")<>1,"FALTA/DUPLA: SIN. HORIZ.",IF(COUNTIF(S32:U32,"X")<>1,"FALTA/DUPLA: SIN. VERTICAL","OK")))))) -> OK
A33: 040ETO0210 | B33: C | C33: 3 | D33: 4 | E33: =D33-C33 -> 1 | H33: X | K33: X | N33: X | Q33: X | T33: X | W33: =IF(COUNTA(F33:U33)=0,"— não preenchido",IF(COUNTIF(F33:J33,"X")<>1,"FALTA/DUPLA: CONDIÇÃO DO PAVIMENTO",IF(COUNTIF(K33:L33,"X")<>1,"FALTA/DUPLA: VEGETAÇÃO",IF(COUNTIF(M33:O33,"X")<>1,"FALTA/DUPLA: ELEM. DE DRENAGEM",IF(COUNTIF(P33:R33,"X")<>1,"FALTA/DUPLA: SIN. HORIZ.",IF(COUNTIF(S33:U33,"X")<>1,"FALTA/DUPLA: SIN. VERTICAL","OK")))))) -> OK
A34: 040ETO0210 | B34: C | C34: 4 | D34: 5 | E34: =D34-C34 -> 1 | H34: X | K34: X | N34: X | Q34: X | T34: X | W34: =IF(COUNTA(F34:U34)=0,"— não preenchido",IF(COUNTIF(F34:J34,"X")<>1,"FALTA/DUPLA: CONDIÇÃO DO PAVIMENTO",IF(COUNTIF(K34:L34,"X")<>1,"FALTA/DUPLA: VEGETAÇÃO",IF(COUNTIF(M34:O34,"X")<>1,"FALTA/DUPLA: ELEM. DE DRENAGEM",IF(COUNTIF(P34:R34,"X")<>1,"FALTA/DUPLA: SIN. HORIZ.",IF(COUNTIF(S34:U34,"X")<>1,"FALTA/DUPLA: SIN. VERTICAL","OK")))))) -> OK
A35: 040ETO0210 | B35: C | C35: 5 | D35: 6 | E35: =D35-C35 -> 1 | H35: X | K35: X | N35: X | Q35: X | T35: X | W35: =IF(COUNTA(F35:U35)=0,"— não preenchido",IF(COUNTIF(F35:J35,"X")<>1,"FALTA/DUPLA: CONDIÇÃO DO PAVIMENTO",IF(COUNTIF(K35:L35,"X")<>1,"FALTA/DUPLA: VEGETAÇÃO",IF(COUNTIF(M35:O35,"X")<>1,"FALTA/DUPLA: ELEM. DE DRENAGEM",IF(COUNTIF(P35:R35,"X")<>1,"FALTA/DUPLA: SIN. HORIZ.",IF(COUNTIF(S35:U35,"X")<>1,"FALTA/DUPLA: SIN. VERTICAL","OK")))))) -> OK
A36: 040ETO0210 | B36: C | C36: 6 | D36: 7 | E36: =D36-C36 -> 1 | H36: X | K36: X | N36: X | Q36: X | T36: X | W36: =IF(COUNTA(F36:U36)=0,"— não preenchido",IF(COUNTIF(F36:J36,"X")<>1,"FALTA/DUPLA: CONDIÇÃO DO PAVIMENTO",IF(COUNTIF(K36:L36,"X")<>1,"FALTA/DUPLA: VEGETAÇÃO",IF(COUNTIF(M36:O36,"X")<>1,"FALTA/DUPLA: ELEM. DE DRENAGEM",IF(COUNTIF(P36:R36,"X")<>1,"FALTA/DUPLA: SIN. HORIZ.",IF(COUNTIF(S36:U36,"X")<>1,"FALTA/DUPLA: SIN. VERTICAL","OK")))))) -> OK
A37: 040ETO0210 | B37: C | C37: 7 | D37: 8 | E37: =D37-C37 -> 1 | H37: X | K37: X | N37: X | Q37: X | T37: X | W37: =IF(COUNTA(F37:U37)=0,"— não preenchido",IF(COUNTIF(F37:J37,"X")<>1,"FALTA/DUPLA: CONDIÇÃO DO PAVIMENTO",IF(COUNTIF(K37:L37,"X")<>1,"FALTA/DUPLA: VEGETAÇÃO",IF(COUNTIF(M37:O37,"X")<>1,"FALTA/DUPLA: ELEM. DE DRENAGEM",IF(COUNTIF(P37:R37,"X")<>1,"FALTA/DUPLA: SIN. HORIZ.",IF(COUNTIF(S37:U37,"X")<>1,"FALTA/DUPLA: SIN. VERTICAL","OK")))))) -> OK
A38: 040ETO0210 | B38: C | C38: 8 | D38: 9 | E38: =D38-C38 -> 1 | H38: X | K38: X | N38: X | Q38: X | T38: X | W38: =IF(COUNTA(F38:U38)=0,"— não preenchido",IF(COUNTIF(F38:J38,"X")<>1,"FALTA/DUPLA: CONDIÇÃO DO PAVIMENTO",IF(COUNTIF(K38:L38,"X")<>1,"FALTA/DUPLA: VEGETAÇÃO",IF(COUNTIF(M38:O38,"X")<>1,"FALTA/DUPLA: ELEM. DE DRENAGEM",IF(COUNTIF(P38:R38,"X")<>1,"FALTA/DUPLA: SIN. HORIZ.",IF(COUNTIF(S38:U38,"X")<>1,"FALTA/DUPLA: SIN. VERTICAL","OK")))))) -> OK
A39: 040ETO0210 | B39: C | C39: 9 | D39: 10 | E39: =D39-C39 -> 1 | H39: X | K39: X | N39: X | Q39: X | T39: X | W39: =IF(COUNTA(F39:U39)=0,"— não preenchido",IF(COUNTIF(F39:J39,"X")<>1,"FALTA/DUPLA: CONDIÇÃO DO PAVIMENTO",IF(COUNTIF(K39:L39,"X")<>1,"FALTA/DUPLA: VEGETAÇÃO",IF(COUNTIF(M39:O39,"X")<>1,"FALTA/DUPLA: ELEM. DE DRENAGEM",IF(COUNTIF(P39:R39,"X")<>1,"FALTA/DUPLA: SIN. HORIZ.",IF(COUNTIF(S39:U39,"X")<>1,"FALTA/DUPLA: SIN. VERTICAL","OK")))))) -> OK
A40: 040ETO0210 | B40: C | C40: 10 | D40: 11 | E40: =D40-C40 -> 1 | H40: X | K40: X | N40: X | Q40: X | T40: X | W40: =IF(COUNTA(F40:U40)=0,"— não preenchido",IF(COUNTIF(F40:J40,"X")<>1,"FALTA/DUPLA: CONDIÇÃO DO PAVIMENTO",IF(COUNTIF(K40:L40,"X")<>1,"FALTA/DUPLA: VEGETAÇÃO",IF(COUNTIF(M40:O40,"X")<>1,"FALTA/DUPLA: ELEM. DE DRENAGEM",IF(COUNTIF(P40:R40,"X")<>1,"FALTA/DUPLA: SIN. HORIZ.",IF(COUNTIF(S40:U40,"X")<>1,"FALTA/DUPLA: SIN. VERTICAL","OK")))))) -> OK
A41: 040ETO0210 | B41: C | C41: 11 | D41: 12 | E41: =D41-C41 -> 1 | H41: X | K41: X | N41: X | Q41: X | T41: X | W41: =IF(COUNTA(F41:U41)=0,"— não preenchido",IF(COUNTIF(F41:J41,"X")<>1,"FALTA/DUPLA: CONDIÇÃO DO PAVIMENTO",IF(COUNTIF(K41:L41,"X")<>1,"FALTA/DUPLA: VEGETAÇÃO",IF(COUNTIF(M41:O41,"X")<>1,"FALTA/DUPLA: ELEM. DE DRENAGEM",IF(COUNTIF(P41:R41,"X")<>1,"FALTA/DUPLA: SIN. HORIZ.",IF(COUNTIF(S41:U41,"X")<>1,"FALTA/DUPLA: SIN. VERTICAL","OK")))))) -> OK
...

Sheet 248
A1: PROGRAMA DE MANUTENÇÃO RODOVIÁRIA — FICHA DE INSPEÇÃO — RODOVIAS PAVIMENTADAS | Y1: Valores dos gráficos — troca 0 por N/D para a fatia não aparecer. Não editar.
A2: REGIÃO: 13 — DIANÓPOLIS | G2: MÊS / ANO: | I2: 46266 | K2: DATA: | P2: TÉCNICO: | R2: ENG. THIAGO BORGES TORQUATO | Y2: =IF(F59=0,NA(),F59) -> 28.187731 | Z2: =IF(G59=0,NA(),G59) -> 5.8182596 | AA2: =IF(H59=0,NA(),H59) -> 9 | AB2: =IF(I59=0,NA(),I59) -> #N/A | AC2: =IF(J59=0,NA(),J59) -> #N/A | AD2: =IF(K59=0,NA(),K59) -> 43.005991 | AE2: =IF(L59=0,NA(),L59) -> #N/A | AF2: =IF(M59=0,NA(),M59) -> #N/A | ... AN2: =IF(U59=0,NA(),U59) -> #N/A
A3: TRECHO 248 — RODOVIA TO-040 - TRECHO NOVO JARDIM - DIVISA TO-BA | T3: EXTENSÃO: 43,006 km · 2 S.R.E.
A4: COMO PREENCHER: uma X em UMA coluna de cada grupo, por linha. Se houver mais de um defeito no mesmo km, marque o PREDOMINANTE e escreva o resto em OBSERVAÇÕES. A quilometragem é contada de 0 até o fim de CADA S.R.E. (não é o marco da rodovia).
A6: S.R.E. | B6: SENT. | C6: INÍCIO (KM) | D6: FIM (KM) | E6: EXT. (KM) | F6: CONDIÇÃO DO PAVIMENTO | K6: VEGETAÇÃO | M6: ELEM. DE DRENAGEM | P6: SIN. HORIZ. | S6: SIN. VERTICAL | V6: OBSERVAÇÕES | W6: CONFERÊNCIA (só na tela)
F7: BOM | G7: REM. I. | H7: REM. L. | I7: BUR. I. | J7: BUR. L. | K7: ADEQ. | L7: INAD. | M7: LIMPOS | N7: SUJOS | O7: DAN. | P7: BOM | Q7: REG. | R7: INEXIST. | S7: BOM | T7: POUCAS | U7: INEXIST.
A8: S.R.E. 040ETO0220 | NOVO JARDIM - ENTR. TO-110 | PPS · Estadual · 5.818 km · início: -11.821038, -46.621003
A9: 040ETO0220 | B9: C | C9: 0 | D9: 1 | E9: =D9-C9 -> 1 | G9: X | K9: X | N9: X | Q9: X | T9: X | W9: =IF(COUNTA(F9:U9)=0,"— não preenchido",IF(COUNTIF(F9:J9,"X")<>1,"FALTA/DUPLA: CONDIÇÃO DO PAVIMENTO",IF(COUNTIF(K9:L9,"X")<>1,"FALTA/DUPLA: VEGETAÇÃO",IF(COUNTIF(M9:O9,"X")<>1,"FALTA/DUPLA: ELEM. DE DRENAGEM",IF(COUNTIF(P9:R9,"X")<>1,"FALTA/DUPLA: SIN. HORIZ.",IF(COUNTIF(S9:U9,"X")<>1,"FALTA/DUPLA: SIN. VERTICAL","OK")))))) -> OK
A10: 040ETO0220 | B10: C | C10: 1 | D10: 2 | E10: =D10-C10 -> 1 | G10: X | K10: X | N10: X | Q10: X | T10: X | W10: =IF(COUNTA(F10:U10)=0,"— não preenchido",IF(COUNTIF(F10:J10,"X")<>1,"FALTA/DUPLA: CONDIÇÃO DO PAVIMENTO",IF(COUNTIF(K10:L10,"X")<>1,"FALTA/DUPLA: VEGETAÇÃO",IF(COUNTIF(M10:O10,"X")<>1,"FALTA/DUPLA: ELEM. DE DRENAGEM",IF(COUNTIF(P10:R10,"X")<>1,"FALTA/DUPLA: SIN. HORIZ.",IF(COUNTIF(S10:U10,"X")<>1,"FALTA/DUPLA: SIN. VERTICAL","OK")))))) -> OK
A11: 040ETO0220 | B11: C | C11: 2 | D11: 3 | E11: =D11-C11 -> 1 | G11: X | K11: X | N11: X | Q11: X | T11: X | W11: =IF(COUNTA(F11:U11)=0,"— não preenchido",IF(COUNTIF(F11:J11,"X")<>1,"FALTA/DUPLA: CONDIÇÃO DO PAVIMENTO",IF(COUNTIF(K11:L11,"X")<>1,"FALTA/DUPLA: VEGETAÇÃO",IF(COUNTIF(M11:O11,"X")<>1,"FALTA/DUPLA: ELEM. DE DRENAGEM",IF(COUNTIF(P11:R11,"X")<>1,"FALTA/DUPLA: SIN. HORIZ.",IF(COUNTIF(S11:U11,"X")<>1,"FALTA/DUPLA: SIN. VERTICAL","OK")))))) -> OK
A12: 040ETO0220 | B12: C | C12: 3 | D12: 4 | E12: =D12-C12 -> 1 | G12: X | K12: X | N12: X | Q12: X | T12: X | W12: =IF(COUNTA(F12:U12)=0,"— não preenchido",IF(COUNTIF(F12:J12,"X")<>1,"FALTA/DUPLA: CONDIÇÃO DO PAVIMENTO",IF(COUNTIF(K12:L12,"X")<>1,"FALTA/DUPLA: VEGETAÇÃO",IF(COUNTIF(M12:O12,"X")<>1,"FALTA/DUPLA: ELEM. DE DRENAGEM",IF(COUNTIF(P12:R12,"X")<>1,"FALTA/DUPLA: SIN. HORIZ.",IF(COUNTIF(S12:U12,"X")<>1,"FALTA/DUPLA: SIN. VERTICAL","OK")))))) -> OK
A13: 040ETO0220 | B13: C | C13: 4 | D13: 5 | E13: =D13-C13 -> 1 | G13: X | K13: X | N13: X | Q13: X | T13: X | W13: =IF(COUNTA(F13:U13)=0,"— não preenchido",IF(COUNTIF(F13:J13,"X")<>1,"FALTA/DUPLA: CONDIÇÃO DO PAVIMENTO",IF(COUNTIF(K13:L13,"X")<>1,"FALTA/DUPLA: VEGETAÇÃO",IF(COUNTIF(M13:O13,"X")<>1,"FALTA/DUPLA: ELEM. DE DRENAGEM",IF(COUNTIF(P13:R13,"X")<>1,"FALTA/DUPLA: SIN. HORIZ.",IF(COUNTIF(S13:U13,"X")<>1,"FALTA/DUPLA: SIN. VERTICAL","OK")))))) -> OK
A14: 040ETO0220 | B14: C | C14: 5 | D14: 5.8182596 | E14: =D14-C14 -> 0.81825962 | G14: X | K14: X | N14: X | Q14: X | T14: X | W14: =IF(COUNTA(F14:U14)=0,"— não preenchido",IF(COUNTIF(F14:J14,"X")<>1,"FALTA/DUPLA: CONDIÇÃO DO PAVIMENTO",IF(COUNTIF(K14:L14,"X")<>1,"FALTA/DUPLA: VEGETAÇÃO",IF(COUNTIF(M14:O14,"X")<>1,"FALTA/DUPLA: ELEM. DE DRENAGEM",IF(COUNTIF(P14:R14,"X")<>1,"FALTA/DUPLA: SIN. HORIZ.",IF(COUNTIF(S14:U14,"X")<>1,"FALTA/DUPLA: SIN. VERTICAL","OK")))))) -> OK
A15: S.R.E. 040ETO0230 | ENTR. TO-110 - DIV TO-BA | PPS · Estadual · 37.188 km · início: -11.832466, -46.580968
A16: 040ETO0230 | B16: C | C16: 0 | D16: 1 | E16: =D16-C16 -> 1 | F16: X | K16: X | N16: X | Q16: X | T16: X | V16: 37,19 km | W16: =IF(COUNTA(F16:U16)=0,"— não preenchido",IF(COUNTIF(F16:J16,"X")<>1,"FALTA/DUPLA: CONDIÇÃO DO PAVIMENTO",IF(COUNTIF(K16:L16,"X")<>1,"FALTA/DUPLA: VEGETAÇÃO",IF(COUNTIF(M16:O16,"X")<>1,"FALTA/DUPLA: ELEM. DE DRENAGEM",IF(COUNTIF(P16:R16,"X")<>1,"FALTA/DUPLA: SIN. HORIZ.",IF(COUNTIF(S16:U16,"X")<>1,"FALTA/DUPLA: SIN. VERTICAL","OK")))))) -> OK
A17: 040ETO0230 | B17: C | C17: 1 | D17: 2 | E17: =D17-C17 -> 1 | F17: X | K17: X | N17: X | Q17: X | T17: X | V17: 37,19 km | W17: =IF(COUNTA(F17:U17)=0,"— não preenchido",IF(COUNTIF(F17:J17,"X")<>1,"FALTA/DUPLA: CONDIÇÃO DO PAVIMENTO",IF(COUNTIF(K17:L17,"X")<>1,"FALTA/DUPLA: VEGETAÇÃO",IF(COUNTIF(M17:O17,"X")<>1,"FALTA/DUPLA: ELEM. DE DRENAGEM",IF(COUNTIF(P17:R17,"X")<>1,"FALTA/DUPLA: SIN. HORIZ.",IF(COUNTIF(S17:U17,"X")<>1,"FALTA/DUPLA: SIN. VERTICAL","OK")))))) -> OK
A18: 040ETO0230 | B18: C | C18: 2 | D18: 3 | E18: =D18-C18 -> 1 | F18: X | K18: X | N18: X | Q18: X | T18: X | V18: 37,19 km | W18: =IF(COUNTA(F18:U18)=0,"— não preenchido",IF(COUNTIF(F18:J18,"X")<>1,"FALTA/DUPLA: CONDIÇÃO DO PAVIMENTO",IF(COUNTIF(K18:L18,"X")<>1,"FALTA/DUPLA: VEGETAÇÃO",IF(COUNTIF(M18:O18,"X")<>1,"FALTA/DUPLA: ELEM. DE DRENAGEM",IF(COUNTIF(P18:R18,"X")<>1,"FALTA/DUPLA: SIN. HORIZ.",IF(COUNTIF(S18:U18,"X")<>1,"FALTA/DUPLA: SIN. VERTICAL","OK")))))) -> OK
A19: 040ETO0230 | B19: C | C19: 3 | D19: 4 | E19: =D19-C19 -> 1 | F19: X | K19: X | N19: X | Q19: X | T19: X | W19: =IF(COUNTA(F19:U19)=0,"— não preenchido",IF(COUNTIF(F19:J19,"X")<>1,"FALTA/DUPLA: CONDIÇÃO DO PAVIMENTO",IF(COUNTIF(K19:L19,"X")<>1,"FALTA/DUPLA: VEGETAÇÃO",IF(COUNTIF(M19:O19,"X")<>1,"FALTA/DUPLA: ELEM. DE DRENAGEM",IF(COUNTIF(P19:R19,"X")<>1,"FALTA/DUPLA: SIN. HORIZ.",IF(COUNTIF(S19:U19,"X")<>1,"FALTA/DUPLA: SIN. VERTICAL","OK")))))) -> OK
A20: 040ETO0230 | B20: C | C20: 4 | D20: 5 | E20: =D20-C20 -> 1 | F20: X | K20: X | N20: X | Q20: X | T20: X | W20: =IF(COUNTA(F20:U20)=0,"— não preenchido",IF(COUNTIF(F20:J20,"X")<>1,"FALTA/DUPLA: CONDIÇÃO DO PAVIMENTO",IF(COUNTIF(K20:L20,"X")<>1,"FALTA/DUPLA: VEGETAÇÃO",IF(COUNTIF(M20:O20,"X")<>1,"FALTA/DUPLA: ELEM. DE DRENAGEM",IF(COUNTIF(P20:R20,"X")<>1,"FALTA/DUPLA: SIN. HORIZ.",IF(COUNTIF(S20:U20,"X")<>1,"FALTA/DUPLA: SIN. VERTICAL","OK")))))) -> OK
A21: 040ETO0230 | B21: C | C21: 5 | D21: 6 | E21: =D21-C21 -> 1 | F21: X | K21: X | N21: X | Q21: X | T21: X | W21: =IF(COUNTA(F21:U21)=0,"— não preenchido",IF(COUNTIF(F21:J21,"X")<>1,"FALTA/DUPLA: CONDIÇÃO DO PAVIMENTO",IF(COUNTIF(K21:L21,"X")<>1,"FALTA/DUPLA: VEGETAÇÃO",IF(COUNTIF(M21:O21,"X")<>1,"FALTA/DUPLA: ELEM. DE DRENAGEM",IF(COUNTIF(P21:R21,"X")<>1,"FALTA/DUPLA: SIN. HORIZ.",IF(COUNTIF(S21:U21,"X")<>1,"FALTA/DUPLA: SIN. VERTICAL","OK")))))) -> OK
A22: 040ETO0230 | B22: C | C22: 6 | D22: 7 | E22: =D22-C22 -> 1 | F22: X | K22: X | N22: X | Q22: X | T22: X | W22: =IF(COUNTA(F22:U22)=0,"— não preenchido",IF(COUNTIF(F22:J22,"X")<>1,"FALTA/DUPLA: CONDIÇÃO DO PAVIMENTO",IF(COUNTIF(K22:L22,"X")<>1,"FALTA/DUPLA: VEGETAÇÃO",IF(COUNTIF(M22:O22,"X")<>1,"FALTA/DUPLA: ELEM. DE DRENAGEM",IF(COUNTIF(P22:R22,"X")<>1,"FALTA/DUPLA: SIN. HORIZ.",IF(COUNTIF(S22:U22,"X")<>1,"FALTA/DUPLA: SIN. VERTICAL","OK")))))) -> OK
A23: 040ETO0230 | B23: C | C23: 7 | D23: 8 | E23: =D23-C23 -> 1 | H23: X | K23: X | N23: X | Q23: X | T23: X | W23: =IF(COUNTA(F23:U23)=0,"— não preenchido",IF(COUNTIF(F23:J23,"X")<>1,"FALTA/DUPLA: CONDIÇÃO DO PAVIMENTO",IF(COUNTIF(K23:L23,"X")<>1,"FALTA/DUPLA: VEGETAÇÃO",IF(COUNTIF(M23:O23,"X")<>1,"FALTA/DUPLA: ELEM. DE DRENAGEM",IF(COUNTIF(P23:R23,"X")<>1,"FALTA/DUPLA: SIN. HORIZ.",IF(COUNTIF(S23:U23,"X")<>1,"FALTA/DUPLA: SIN. VERTICAL","OK")))))) -> OK
A24: 040ETO0230 | B24: C | C24: 8 | D24: 9 | E24: =D24-C24 -> 1 | F24: X | K24: X | N24: X | Q24: X | T24: X | W24: =IF(COUNTA(F24:U24)=0,"— não preenchido",IF(COUNTIF(F24:J24,"X")<>1,"FALTA/DUPLA: CONDIÇÃO DO PAVIMENTO",IF(COUNTIF(K24:L24,"X")<>1,"FALTA/DUPLA: VEGETAÇÃO",IF(COUNTIF(M24:O24,"X")<>1,"FALTA/DUPLA: ELEM. DE DRENAGEM",IF(COUNTIF(P24:R24,"X")<>1,"FALTA/DUPLA: SIN. HORIZ.",IF(COUNTIF(S24:U24,"X")<>1,"FALTA/DUPLA: SIN. VERTICAL","OK")))))) -> OK
A25: 040ETO0230 | B25: C | C25: 9 | D25: 10 | E25: =D25-C25 -> 1 | F25: X | K25: X | N25: X | Q25: X | T25: X | W25: =IF(COUNTA(F25:U25)=0,"— não preenchido",IF(COUNTIF(F25:J25,"X")<>1,"FALTA/DUPLA: CONDIÇÃO DO PAVIMENTO",IF(COUNTIF(K25:L25,"X")<>1,"FALTA/DUPLA: VEGETAÇÃO",IF(COUNTIF(M25:O25,"X")<>1,"FALTA/DUPLA: ELEM. DE DRENAGEM",IF(COUNTIF(P25:R25,"X")<>1,"FALTA/DUPLA: SIN. HORIZ.",IF(COUNTIF(S25:U25,"X")<>1,"FALTA/DUPLA: SIN. VERTICAL","OK")))))) -> OK
A26: 040ETO0230 | B26: C | C26: 10 | D26: 11 | E26: =D26-C26 -> 1 | F26: X | K26: X | N26: X | Q26: X | T26: X | W26: =IF(COUNTA(F26:U26)=0,"— não preenchido",IF(COUNTIF(F26:J26,"X")<>1,"FALTA/DUPLA: CONDIÇÃO DO PAVIMENTO",IF(COUNTIF(K26:L26,"X")<>1,"FALTA/DUPLA: VEGETAÇÃO",IF(COUNTIF(M26:O26,"X")<>1,"FALTA/DUPLA: ELEM. DE DRENAGEM",IF(COUNTIF(P26:R26,"X")<>1,"FALTA/DUPLA: SIN. HORIZ.",IF(COUNTIF(S26:U26,"X")<>1,"FALTA/DUPLA: SIN. VERTICAL","OK")))))) -> OK
A27: 040ETO0230 | B27: C | C27: 11 | D27: 12 | E27: =D27-C27 -> 1 | H27: X | K27: X | N27: X | Q27: X | T27: X | W27: =IF(COUNTA(F27:U27)=0,"— não preenchido",IF(COUNTIF(F27:J27,"X")<>1,"FALTA/DUPLA: CONDIÇÃO DO PAVIMENTO",IF(COUNTIF(K27:L27,"X")<>1,"FALTA/DUPLA: VEGETAÇÃO",IF(COUNTIF(M27:O27,"X")<>1,"FALTA/DUPLA: ELEM. DE DRENAGEM",IF(COUNTIF(P27:R27,"X")<>1,"FALTA/DUPLA: SIN. HORIZ.",IF(COUNTIF(S27:U27,"X")<>1,"FALTA/DUPLA: SIN. VERTICAL","OK")))))) -> OK
A28: 040ETO0230 | B28: C | C28: 12 | D28: 13 | E28: =D28-C28 -> 1 | F28: X | K28: X | N28: X | Q28: X | T28: X | W28: =IF(COUNTA(F28:U28)=0,"— não preenchido",IF(COUNTIF(F28:J28,"X")<>1,"FALTA/DUPLA: CONDIÇÃO DO PAVIMENTO",IF(COUNTIF(K28:L28,"X")<>1,"FALTA/DUPLA: VEGETAÇÃO",IF(COUNTIF(M28:O28,"X")<>1,"FALTA/DUPLA: ELEM. DE DRENAGEM",IF(COUNTIF(P28:R28,"X")<>1,"FALTA/DUPLA: SIN. HORIZ.",IF(COUNTIF(S28:U28,"X")<>1,"FALTA/DUPLA: SIN. VERTICAL","OK")))))) -> OK
A29: 040ETO0230 | B29: C | C29: 13 | D29: 14 | E29: =D29-C29 -> 1 | F29: X | K29: X | N29: X | Q29: X | T29: X | W29: =IF(COUNTA(F29:U29)=0,"— não preenchido",IF(COUNTIF(F29:J29,"X")<>1,"FALTA/DUPLA: CONDIÇÃO DO PAVIMENTO",IF(COUNTIF(K29:L29,"X")<>1,"FALTA/DUPLA: VEGETAÇÃO",IF(COUNTIF(M29:O29,"X")<>1,"FALTA/DUPLA: ELEM. DE DRENAGEM",IF(COUNTIF(P29:R29,"X")<>1,"FALTA/DUPLA: SIN. HORIZ.",IF(COUNTIF(S29:U29,"X")<>1,"FALTA/DUPLA: SIN. VERTICAL","OK")))))) -> OK
A30: 040ETO0230 | B30: C | C30: 14 | D30: 15 | E30: =D30-C30 -> 1 | F30: X | K30: X | N30: X | Q30: X | T30: X | W30: =IF(COUNTA(F30:U30)=0,"— não preenchido",IF(COUNTIF(F30:J30,"X")<>1,"FALTA/DUPLA: CONDIÇÃO DO PAVIMENTO",IF(COUNTIF(K30:L30,"X")<>1,"FALTA/DUPLA: VEGETAÇÃO",IF(COUNTIF(M30:O30,"X")<>1,"FALTA/DUPLA: ELEM. DE DRENAGEM",IF(COUNTIF(P30:R30,"X")<>1,"FALTA/DUPLA: SIN. HORIZ.",IF(COUNTIF(S30:U30,"X")<>1,"FALTA/DUPLA: SIN. VERTICAL","OK")))))) -> OK
A31: 040ETO0230 | B31: C | C31: 15 | D31: 16 | E31: =D31-C31 -> 1 | F31: X | K31: X | N31: X | Q31: X | T31: X | W31: =IF(COUNTA(F31:U31)=0,"— não preenchido",IF(COUNTIF(F31:J31,"X")<>1,"FALTA/DUPLA: CONDIÇÃO DO PAVIMENTO",IF(COUNTIF(K31:L31,"X")<>1,"FALTA/DUPLA: VEGETAÇÃO",IF(COUNTIF(M31:O31,"X")<>1,"FALTA/DUPLA: ELEM. DE DRENAGEM",IF(COUNTIF(P31:R31,"X")<>1,"FALTA/DUPLA: SIN. HORIZ.",IF(COUNTIF(S31:U31,"X")<>1,"FALTA/DUPLA: SIN. VERTICAL","OK")))))) -> OK
A32: 040ETO0230 | B32: C | C32: 16 | D32: 17 | E32: =D32-C32 -> 1 | F32: X | K32: X | N32: X | Q32: X | T32: X | W32: =IF(COUNTA(F32:U32)=0,"— não preenchido",IF(COUNTIF(F32:J32,"X")<>1,"FALTA/DUPLA: CONDIÇÃO DO PAVIMENTO",IF(COUNTIF(K32:L32,"X")<>1,"FALTA/DUPLA: VEGETAÇÃO",IF(COUNTIF(M32:O32,"X")<>1,"FALTA/DUPLA: ELEM. DE DRENAGEM",IF(COUNTIF(P32:R32,"X")<>1,"FALTA/DUPLA: SIN. HORIZ.",IF(COUNTIF(S32:U32,"X")<>1,"FALTA/DUPLA: SIN. VERTICAL","OK")))))) -> OK
A33: 040ETO0230 | B33: C | C33: 17 | D33: 18 | E33: =D33-C33 -> 1 | F33: X | K33: X | N33: X | Q33: X | T33: X | W33: =IF(COUNTA(F33:U33)=0,"— não preenchido",IF(COUNTIF(F33:J33,"X")<>1,"FALTA/DUPLA: CONDIÇÃO DO PAVIMENTO",IF(COUNTIF(K33:L33,"X")<>1,"FALTA/DUPLA: VEGETAÇÃO",IF(COUNTIF(M33:O33,"X")<>1,"FALTA/DUPLA: ELEM. DE DRENAGEM",IF(COUNTIF(P33:R33,"X")<>1,"FALTA/DUPLA: SIN. HORIZ.",IF(COUNTIF(S33:U33,"X")<>1,"FALTA/DUPLA: SIN. VERTICAL","OK")))))) -> OK
A34: 040ETO0230 | B34: C | C34: 18 | D34: 19 | E34: =D34-C34 -> 1 | F34: X | K34: X | N34: X | Q34: X | T34: X | W34: =IF(COUNTA(F34:U34)=0,"— não preenchido",IF(COUNTIF(F34:J34,"X")<>1,"FALTA/DUPLA: CONDIÇÃO DO PAVIMENTO",IF(COUNTIF(K34:L34,"X")<>1,"FALTA/DUPLA: VEGETAÇÃO",IF(COUNTIF(M34:O34,"X")<>1,"FALTA/DUPLA: ELEM. DE DRENAGEM",IF(COUNTIF(P34:R34,"X")<>1,"FALTA/DUPLA: SIN. HORIZ.",IF(COUNTIF(S34:U34,"X")<>1,"FALTA/DUPLA: SIN. VERTICAL","OK")))))) -> OK
A35: 040ETO0230 | B35: C | C35: 19 | D35: 20 | E35: =D35-C35 -> 1 | H35: X | K35: X | N35: X | Q35: X | T35: X | W35: =IF(COUNTA(F35:U35)=0,"— não preenchido",IF(COUNTIF(F35:J35,"X")<>1,"FALTA/DUPLA: CONDIÇÃO DO PAVIMENTO",IF(COUNTIF(K35:L35,"X")<>1,"FALTA/DUPLA: VEGETAÇÃO",IF(COUNTIF(M35:O35,"X")<>1,"FALTA/DUPLA: ELEM. DE DRENAGEM",IF(COUNTIF(P35:R35,"X")<>1,"FALTA/DUPLA: SIN. HORIZ.",IF(COUNTIF(S35:U35,"X")<>1,"FALTA/DUPLA: SIN. VERTICAL","OK")))))) -> OK
A36: 040ETO0230 | B36: C | C36: 20 | D36: 21 | E36: =D36-C36 -> 1 | H36: X | K36: X | N36: X | Q36: X | T36: X | W36: =IF(COUNTA(F36:U36)=0,"— não preenchido",IF(COUNTIF(F36:J36,"X")<>1,"FALTA/DUPLA: CONDIÇÃO DO PAVIMENTO",IF(COUNTIF(K36:L36,"X")<>1,"FALTA/DUPLA: VEGETAÇÃO",IF(COUNTIF(M36:O36,"X")<>1,"FALTA/DUPLA: ELEM. DE DRENAGEM",IF(COUNTIF(P36:R36,"X")<>1,"FALTA/DUPLA: SIN. HORIZ.",IF(COUNTIF(S36:U36,"X")<>1,"FALTA/DUPLA: SIN. VERTICAL","OK")))))) -> OK
A37: 040ETO0230 | B37: C | C37: 21 | D37: 22 | E37: =D37-C37 -> 1 | H37: X | K37: X | N37: X | Q37: X | T37: X | W37: =IF(COUNTA(F37:U37)=0,"— não preenchido",IF(COUNTIF(F37:J37,"X")<>1,"FALTA/DUPLA: CONDIÇÃO DO PAVIMENTO",IF(COUNTIF(K37:L37,"X")<>1,"FALTA/DUPLA: VEGETAÇÃO",IF(COUNTIF(M37:O37,"X")<>1,"FALTA/DUPLA: ELEM. DE DRENAGEM",IF(COUNTIF(P37:R37,"X")<>1,"FALTA/DUPLA: SIN. HORIZ.",IF(COUNTIF(S37:U37,"X")<>1,"FALTA/DUPLA: SIN. VERTICAL","OK")))))) -> OK
A38: 040ETO0230 | B38: C | C38: 22 | D38: 23 | E38: =D38-C38 -> 1 | H38: X | K38: X | N38: X | Q38: X | T38: X | W38: =IF(COUNTA(F38:U38)=0,"— não preenchido",IF(COUNTIF(F38:J38,"X")<>1,"FALTA/DUPLA: CONDIÇÃO DO PAVIMENTO",IF(COUNTIF(K38:L38,"X")<>1,"FALTA/DUPLA: VEGETAÇÃO",IF(COUNTIF(M38:O38,"X")<>1,"FALTA/DUPLA: ELEM. DE DRENAGEM",IF(COUNTIF(P38:R38,"X")<>1,"FALTA/DUPLA: SIN. HORIZ.",IF(COUNTIF(S38:U38,"X")<>1,"FALTA/DUPLA: SIN. VERTICAL","OK")))))) -> OK
A39: 040ETO0230 | B39: C | C39: 23 | D39: 24 | E39: =D39-C39 -> 1 | H39: X | K39: X | N39: X | Q39: X | T39: X | W39: =IF(COUNTA(F39:U39)=0,"— não preenchido",IF(COUNTIF(F39:J39,"X")<>1,"FALTA/DUPLA: CONDIÇÃO DO PAVIMENTO",IF(COUNTIF(K39:L39,"X")<>1,"FALTA/DUPLA: VEGETAÇÃO",IF(COUNTIF(M39:O39,"X")<>1,"FALTA/DUPLA: ELEM. DE DRENAGEM",IF(COUNTIF(P39:R39,"X")<>1,"FALTA/DUPLA: SIN. HORIZ.",IF(COUNTIF(S39:U39,"X")<>1,"FALTA/DUPLA: SIN. VERTICAL","OK")))))) -> OK
A40: 040ETO0230 | B40: C | C40: 24 | D40: 25 | E40: =D40-C40 -> 1 | H40: X | K40: X | N40: X | Q40: X | T40: X | W40: =IF(COUNTA(F40:U40)=0,"— não preenchido",IF(COUNTIF(F40:J40,"X")<>1,"FALTA/DUPLA: CONDIÇÃO DO PAVIMENTO",IF(COUNTIF(K40:L40,"X")<>1,"FALTA/DUPLA: VEGETAÇÃO",IF(COUNTIF(M40:O40,"X")<>1,"FALTA/DUPLA: ELEM. DE DRENAGEM",IF(COUNTIF(P40:R40,"X")<>1,"FALTA/DUPLA: SIN. HORIZ.",IF(COUNTIF(S40:U40,"X")<>1,"FALTA/DUPLA: SIN. VERTICAL","OK")))))) -> OK
A41: 040ETO0230 | B41: C | C41: 25 | D41: 26 | E41: =D41-C41 -> 1 | H41: X | K41: X | N41: X | Q41: X | T41: X | W41: =IF(COUNTA(F41:U41)=0,"— não preenchido",IF(COUNTIF(F41:J41,"X")<>1,"FALTA/DUPLA: CONDIÇÃO DO PAVIMENTO",IF(COUNTIF(K41:L41,"X")<>1,"FALTA/DUPLA: VEGETAÇÃO",IF(COUNTIF(M41:O41,"X")<>1,"FALTA/DUPLA: ELEM. DE DRENAGEM",IF(COUNTIF(P41:R41,"X")<>1,"FALTA/DUPLA: SIN. HORIZ.",IF(COUNTIF(S41:U41,"X")<>1,"FALTA/DUPLA: SIN. VERTICAL","OK")))))) -> OK
...

Sheet 249
A1: PROGRAMA DE MANUTENÇÃO RODOVIÁRIA — FICHA DE INSPEÇÃO — RODOVIAS PAVIMENTADAS | Y1: Valores dos gráficos — troca 0 por N/D para a fatia não aparecer. Não editar.
A2: REGIÃO: 13 — DIANÓPOLIS | G2: MÊS / ANO: | I2: 46266 | K2: DATA: | P2: TÉCNICO: | R2: ENG. THIAGO BORGES TORQUATO | Y2: =IF(F53=0,NA(),F53) -> 12.68404 | Z2: =IF(G53=0,NA(),G53) -> #N/A | AA2: =IF(H53=0,NA(),H53) -> 22.251227 | AB2: =IF(I53=0,NA(),I53) -> #N/A | AC2: =IF(J53=0,NA(),J53) -> #N/A | AD2: =IF(K53=0,NA(),K53) -> 34.935267 | AE2: =IF(L53=0,NA(),L53) -> #N/A | AF2: =IF(M53=0,NA(),M53) -> 34.935267 | ... AN2: =IF(U53=0,NA(),U53) -> #N/A
A3: TRECHO 249 — RODOVIA TO-040 - TRECHO PORTO ALEGRE DO TOCANTINS - DIANÓPOLIS | T3: EXTENSÃO: 34,935 km · 3 S.R.E.
A4: COMO PREENCHER: uma X em UMA coluna de cada grupo, por linha. Se houver mais de um defeito no mesmo km, marque o PREDOMINANTE e escreva o resto em OBSERVAÇÕES. A quilometragem é contada de 0 até o fim de CADA S.R.E. (não é o marco da rodovia).
A6: S.R.E. | B6: SENT. | C6: INÍCIO (KM) | D6: FIM (KM) | E6: EXT. (KM) | F6: CONDIÇÃO DO PAVIMENTO | K6: VEGETAÇÃO | M6: ELEM. DE DRENAGEM | P6: SIN. HORIZ. | S6: SIN. VERTICAL | V6: OBSERVAÇÕES | W6: CONFERÊNCIA (só na tela)
F7: BOM | G7: REM. I. | H7: REM. L. | I7: BUR. I. | J7: BUR. L. | K7: ADEQ. | L7: INAD. | M7: LIMPOS | N7: SUJOS | O7: DAN. | P7: BOM | Q7: REG. | R7: INEXIST. | S7: BOM | T7: POUCAS | U7: INEXIST.
A8: S.R.E. 040ETO0170 | PORTO ALEGRE DO TOCANTINS - ENTR.TO-387 | PPS · Estadual · 15.046 km · início: -11.617986, -47.012691
