Workbook

Sheet OS SETEMBRO
A1: ORDENS DE SERVIÇO MEDIDAS EM SETEMBRO/2026
A2: REGIÃO 11 — RODOVIAS PAVIMENTADAS · Fonte: Geoportal RTA-MSI (geoportal-ordens-servico.vercel.app), consultado em 02/10/2026
A3: Os trechos abaixo estão com a ABA EM LARANJA e uma nota no título do trecho (A3). As condições desta ficha foram copiadas de AGOSTO/2026: atualizar em campo, com atenção especial a estes trechos.
A5: TRECHO (ABA) | B5: RODOVIA / TRECHO | C5: OSP | D5: CONTRATO | E5: TIPO | F5: SERVIÇOS (resumo do geoportal) | G5: SITUAÇÃO | H5: MEDIÇÃO DO MÊS | I5: VALOR MEDIDO NO MÊS | J5: % EXEC. DA OS | K5: PRAZO LIMITE
A6: 209 | B6: RODOVIA TO-181 - TRECHO FAZENDA COBRAPE - ENTR. BR-242 | C6: 6 | D6: 042.2025 | E6: Restauração | F6: Reciclagem com adição de brita comercial e... / Brita 1 (+23 itens) | G6: Em andamento | H6: nº 4 — 01/09/2026 a 30/09/2026 | I6: 3030639.6 | J6: 36.3 | K6: Novembro/2026
H7: TOTAL MEDIDO NO MÊS | I7: =SUM(I6:I6) -> 3030639.6

Sheet RESUMO
A1: RESUMO CONSOLIDADO — REGIÃO 1 — RODOVIAS PAVIMENTADAS | V1: Valores dos gráficos — troca 0 por N/D para a fatia não aparecer. Não editar.
A2: Todos os números vêm das abas dos trechos por referência direta. Não digite nada aqui. A coluna CONFERÊNCIA acusa qualquer trecho em que a soma das marcações não fecha com a extensão. | V2: =IF(D19=0,NA(),D19) -> 210.44531 | W2: =IF(E19=0,NA(),E19) -> 258.41381 | X2: =IF(F19=0,NA(),F19) -> 88.536188 | Y2: =IF(G19=0,NA(),G19) -> 6 | Z2: =IF(H19=0,NA(),H19) -> #N/A | AA2: =IF(I19=0,NA(),I19) -> 485.17607 | AB2: =IF(J19=0,NA(),J19) -> 78.21924 | AC2: =IF(K19=0,NA(),K19) -> 23.666004 | ... AK2: =IF(S19=0,NA(),S19) -> 137.21243
A4: Nº TRECHO | B4: TRECHO | C4: EXTENSÃO (KM) | D4: CONDIÇÃO DO PAVIMENTO | I4: VEGETAÇÃO | K4: ELEM. DE DRENAGEM | N4: SIN. HORIZ. | Q4: SIN. VERTICAL | T4: CONFERÊNCIA
D5: BOM | E5: REM. I. | F5: REM. L. | G5: BUR. I. | H5: BUR. L. | I5: ADEQ. | J5: INAD. | K5: LIMPOS | L5: SUJOS | M5: DAN. | N5: BOM | O5: REG. | P5: INEXIST. | Q5: BOM | R5: POUCAS | S5: INEXIST.
A6: 202 | B6: RODOVIA TO-070 - TRECHO SANDOLÂNDIA - FORMOSO DO ARAGUAIA | C6: ='202'!R126 -> 102.39693 | D6: ='202'!F123 -> 0 | E6: ='202'!G123 -> 81.396931 | F6: ='202'!H123 -> 19 | G6: ='202'!I123 -> 2 | H6: ='202'!J123 -> 0 | I6: ='202'!K123 -> 25.15782 | J6: ='202'!L123 -> 77.239111 | K6: ='202'!M123 -> 0 | ... S6: ='202'!U123 -> 0 | T6: =IF(SUM(D6:H6)=0,"— não preenchido",IF(ROUND(SUM(D6:H6)-C6,3)=0,"OK","ERRO — dif. de "&ROUND(SUM(D6:H6)-C6,3)&" km")) -> OK
A7: 203 | B7: RODOVIA TO-373 - TRECHO ALVORADA - ARAGUAÇU - PERÍMETRO URBANO | C7: ='203'!R18 -> 0.99985589 | D7: ='203'!F15 -> 0 | E7: ='203'!G15 -> 0 | F7: ='203'!H15 -> 0.99985589 | G7: ='203'!I15 -> 0 | H7: ='203'!J15 -> 0 | I7: ='203'!K15 -> 0.99985589 | J7: ='203'!L15 -> 0 | K7: ='203'!M15 -> 0.99985589 | ... S7: ='203'!U15 -> 0 | T7: =IF(SUM(D7:H7)=0,"— não preenchido",IF(ROUND(SUM(D7:H7)-C7,3)=0,"OK","ERRO — dif. de "&ROUND(SUM(D7:H7)-C7,3)&" km")) -> OK
A8: 204 | B8: RODOVIA TO-070 - TRECHO ALIANÇA DO TOCANTINS - BREJINHO DE NAZARÉ | C8: ='204'!R78 -> 59.745612 | D8: ='204'!F75 -> 0 | E8: ='204'!G75 -> 56 | F8: ='204'!H75 -> 3.7456118 | G8: ='204'!I75 -> 0 | H8: ='204'!J75 -> 0 | I8: ='204'!K75 -> 59.745612 | J8: ='204'!L75 -> 0 | K8: ='204'!M75 -> 0.99026288 | ... S8: ='204'!U75 -> 0 | T8: =IF(SUM(D8:H8)=0,"— não preenchido",IF(ROUND(SUM(D8:H8)-C8,3)=0,"OK","ERRO — dif. de "&ROUND(SUM(D8:H8)-C8,3)&" km")) -> OK
A9: 205 | B9: RODOVIA TO-070 - TRECHO DUERÉ - ALIANÇA DO TOCANTINS | C9: ='205'!R67 -> 46.836116 | D9: ='205'!F64 -> 27.836116 | E9: ='205'!G64 -> 9 | F9: ='205'!H64 -> 10 | G9: ='205'!I64 -> 0 | H9: ='205'!J64 -> 0 | I9: ='205'!K64 -> 46.836116 | J9: ='205'!L64 -> 0 | K9: ='205'!M64 -> 0 | ... S9: ='205'!U64 -> 0 | T9: =IF(SUM(D9:H9)=0,"— não preenchido",IF(ROUND(SUM(D9:H9)-C9,3)=0,"OK","ERRO — dif. de "&ROUND(SUM(D9:H9)-C9,3)&" km")) -> OK
A10: 206 | B10: RODOVIA TO-070 - TRECHO FORMOSO DO ARAGUAIA - DUERÉ | C10: ='206'!R86 -> 64.925691 | D10: ='206'!F83 -> 6 | E10: ='206'!G83 -> 48.790985 | F10: ='206'!H83 -> 10.134706 | G10: ='206'!I83 -> 0 | H10: ='206'!J83 -> 0 | I10: ='206'!K83 -> 64.925691 | J10: ='206'!L83 -> 0 | K10: ='206'!M83 -> 0 | ... S10: ='206'!U83 -> 3.1347063 | T10: =IF(SUM(D10:H10)=0,"— não preenchido",IF(ROUND(SUM(D10:H10)-C10,3)=0,"OK","ERRO — dif. de "&ROUND(SUM(D10:H10)-C10,3)&" km")) -> OK
A11: 209 | B11: RODOVIA TO-181 - TRECHO FAZENDA COBRAPE - ENTR. BR-242 | C11: ='209'!R55 -> 35.675885 | D11: ='209'!F52 -> 13 | E11: ='209'!G52 -> 6 | F11: ='209'!H52 -> 16.675885 | G11: ='209'!I52 -> 0 | H11: ='209'!J52 -> 0 | I11: ='209'!K52 -> 35.675885 | J11: ='209'!L52 -> 0 | K11: ='209'!M52 -> 19.675885 | ... S11: ='209'!U52 -> 35.675885 | T11: =IF(SUM(D11:H11)=0,"— não preenchido",IF(ROUND(SUM(D11:H11)-C11,3)=0,"OK","ERRO — dif. de "&ROUND(SUM(D11:H11)-C11,3)&" km")) -> OK
A12: 210 | B12: RODOVIA TO-181 - TRECHO ENTR. BR-242 - FUNDAÇÃO BRADESCO | C12: ='210'!R44 -> 26.160325 | D12: ='210'!F41 -> 1 | E12: ='210'!G41 -> 9.1603248 | F12: ='210'!H41 -> 16 | G12: ='210'!I41 -> 0 | H12: ='210'!J41 -> 0 | I12: ='210'!K41 -> 26.160325 | J12: ='210'!L41 -> 0 | K12: ='210'!M41 -> 1 | ... S12: ='210'!U41 -> 25 | T12: =IF(SUM(D12:H12)=0,"— não preenchido",IF(ROUND(SUM(D12:H12)-C12,3)=0,"OK","ERRO — dif. de "&ROUND(SUM(D12:H12)-C12,3)&" km")) -> OK
A13: 212 | B13: RODOVIA TO-181 - TRECHO ARAGUAÇU - SANDOLÂNDIA | C13: ='212'!R66 -> 48.649724 | D13: ='212'!F63 -> 0 | E13: ='212'!G63 -> 35.649724 | F13: ='212'!H63 -> 9 | G13: ='212'!I63 -> 4 | H13: ='212'!J63 -> 0 | I13: ='212'!K63 -> 48.649724 | J13: ='212'!L63 -> 0 | K13: ='212'!M63 -> 0 | ... S13: ='212'!U63 -> 0 | T13: =IF(SUM(D13:H13)=0,"— não preenchido",IF(ROUND(SUM(D13:H13)-C13,3)=0,"OK","ERRO — dif. de "&ROUND(SUM(D13:H13)-C13,3)&" km")) -> OK
A14: 214 | B14: RODOVIA TO-362 - TRECHO SANTA RITA DO TOCANTINS - BREJINHO DE NAZARÉ | C14: ='214'!R18 -> 0.37470222 | D14: ='214'!F15 -> 0 | E14: ='214'!G15 -> 0.37470222 | F14: ='214'!H15 -> 0 | G14: ='214'!I15 -> 0 | H14: ='214'!J15 -> 0 | I14: ='214'!K15 -> 0.37470222 | J14: ='214'!L15 -> 0 | K14: ='214'!M15 -> 0 | ... S14: ='214'!U15 -> 0 | T14: =IF(SUM(D14:H14)=0,"— não preenchido",IF(ROUND(SUM(D14:H14)-C14,3)=0,"OK","ERRO — dif. de "&ROUND(SUM(D14:H14)-C14,3)&" km")) -> OK
A15: 218 | B15: RODOVIA TO-373 - TRECHO ALVORADA - ARAGUAÇU - DIVISA TO-GO | C15: ='218'!R133 -> 112.30914 | D15: ='218'!F130 -> 112.30914 | E15: ='218'!G130 -> 0 | F15: ='218'!H130 -> 0 | G15: ='218'!I130 -> 0 | H15: ='218'!J130 -> 0 | I15: ='218'!K130 -> 112.30914 | J15: ='218'!L130 -> 0 | K15: ='218'!M130 -> 0 | ... S15: ='218'!U130 -> 17.060642 | T15: =IF(SUM(D15:H15)=0,"— não preenchido",IF(ROUND(SUM(D15:H15)-C15,3)=0,"OK","ERRO — dif. de "&ROUND(SUM(D15:H15)-C15,3)&" km")) -> OK
A16: 219 | B16: RODOVIA TO-374 - TRECHO DUERÉ - GURUPI | C16: ='219'!R68 -> 50.300052 | D16: ='219'!F65 -> 50.300052 | E16: ='219'!G65 -> 0 | F16: ='219'!H65 -> 0 | G16: ='219'!I65 -> 0 | H16: ='219'!J65 -> 0 | I16: ='219'!K65 -> 50.300052 | J16: ='219'!L65 -> 0 | K16: ='219'!M65 -> 0 | ... S16: ='219'!U65 -> 46.300052 | T16: =IF(SUM(D16:H16)=0,"— não preenchido",IF(ROUND(SUM(D16:H16)-C16,3)=0,"OK","ERRO — dif. de "&ROUND(SUM(D16:H16)-C16,3)&" km")) -> OK
A17: 220 | B17: RODOVIA TO-460 - TRECHO BR-242 (VILA QUIXABA) - SUCUPIRA | C17: ='220'!R32 -> 14.041142 | D17: ='220'!F29 -> 0 | E17: ='220'!G29 -> 12.041142 | F17: ='220'!H29 -> 2 | G17: ='220'!I29 -> 0 | H17: ='220'!J29 -> 0 | I17: ='220'!K29 -> 14.041142 | J17: ='220'!L29 -> 0 | K17: ='220'!M29 -> 1 | ... S17: ='220'!U29 -> 10.041142 | T17: =IF(SUM(D17:H17)=0,"— não preenchido",IF(ROUND(SUM(D17:H17)-C17,3)=0,"OK","ERRO — dif. de "&ROUND(SUM(D17:H17)-C17,3)&" km")) -> OK
A18: 222 | B18: RODOVIA TO-483 - TRECHO SUCUPIRA - FIGUEIRÓPOLIS | C18: ='222'!R18 -> 0.98012925 | D18: ='222'!F15 -> 0 | E18: ='222'!G15 -> 0 | F18: ='222'!H15 -> 0.98012925 | G18: ='222'!I15 -> 0 | H18: ='222'!J15 -> 0 | I18: ='222'!K15 -> 0 | J18: ='222'!L15 -> 0.98012925 | K18: ='222'!M15 -> 0 | ... S18: ='222'!U15 -> 0 | T18: =IF(SUM(D18:H18)=0,"— não preenchido",IF(ROUND(SUM(D18:H18)-C18,3)=0,"OK","ERRO — dif. de "&ROUND(SUM(D18:H18)-C18,3)&" km")) -> OK
B19: TOTAL PERCORRIDO NO MÊS | C19: =SUM(C6:C18) -> 563.39531 | D19: =SUM(D6:D18) -> 210.44531 | E19: =SUM(E6:E18) -> 258.41381 | F19: =SUM(F6:F18) -> 88.536188 | G19: =SUM(G6:G18) -> 6 | H19: =SUM(H6:H18) -> 0 | I19: =SUM(I6:I18) -> 485.17607 | J19: =SUM(J6:J18) -> 78.21924 | ... S19: =SUM(S6:S18) -> 137.21243
B20: % DA EXTENSÃO DA MALHA (563.40 km) | D20: =SUM(D19:H19)/563.4 -> 0.99999168 | I20: (soma do grupo 'CONDIÇÃO DO PAVIMENTO' dividida pela malha)

Sheet 202
A1: PROGRAMA DE MANUTENÇÃO RODOVIÁRIA — FICHA DE INSPEÇÃO — RODOVIAS PAVIMENTADAS | Y1: Valores dos gráficos — troca 0 por N/D para a fatia não aparecer. Não editar.
A2: REGIÃO: 11 — GURUPI | G2: MÊS / ANO: | I2: 46266 | K2: DATA: | P2: TÉCNICO: | R2: ENG. THIAGO BORGES TORQUATO | Y2: =IF(F123=0,NA(),F123) -> #N/A | Z2: =IF(G123=0,NA(),G123) -> 81.396931 | AA2: =IF(H123=0,NA(),H123) -> 19 | AB2: =IF(I123=0,NA(),I123) -> 2 | AC2: =IF(J123=0,NA(),J123) -> #N/A | AD2: =IF(K123=0,NA(),K123) -> 25.15782 | AE2: =IF(L123=0,NA(),L123) -> 77.239111 | AF2: =IF(M123=0,NA(),M123) -> #N/A | ... AN2: =IF(U123=0,NA(),U123) -> #N/A
A3: TRECHO 202 — RODOVIA TO-070 - TRECHO SANDOLÂNDIA - FORMOSO DO ARAGUAIA | T3: EXTENSÃO: 102,397 km · 4 S.R.E.
A4: COMO PREENCHER: uma X em UMA coluna de cada grupo, por linha. Se houver mais de um defeito no mesmo km, marque o PREDOMINANTE e escreva o resto em OBSERVAÇÕES. A quilometragem é contada de 0 até o fim de CADA S.R.E. (não é o marco da rodovia).
A6: S.R.E. | B6: SENT. | C6: INÍCIO (KM) | D6: FIM (KM) | E6: EXT. (KM) | F6: CONDIÇÃO DO PAVIMENTO | K6: VEGETAÇÃO | M6: ELEM. DE DRENAGEM | P6: SIN. HORIZ. | S6: SIN. VERTICAL | V6: OBSERVAÇÕES | W6: CONFERÊNCIA (só na tela)
F7: BOM | G7: REM. I. | H7: REM. L. | I7: BUR. I. | J7: BUR. L. | K7: ADEQ. | L7: INAD. | M7: LIMPOS | N7: SUJOS | O7: DAN. | P7: BOM | Q7: REG. | R7: INEXIST. | S7: BOM | T7: POUCAS | U7: INEXIST.
A8: S.R.E. 181ETO0171 | PERÍMETRO URBANO DE SANDOLÂNDIA | PSU · Municipal · 1.147 km · sem coordenada no shape
A9: 181ETO0171 | B9: C | C9: 0 | D9: 1 | E9: =D9-C9 -> 1 | G9: X | K9: X | N9: X | Q9: X | T9: X | W9: =IF(COUNTA(F9:U9)=0,"— não preenchido",IF(COUNTIF(F9:J9,"X")<>1,"FALTA/DUPLA: CONDIÇÃO DO PAVIMENTO",IF(COUNTIF(K9:L9,"X")<>1,"FALTA/DUPLA: VEGETAÇÃO",IF(COUNTIF(M9:O9,"X")<>1,"FALTA/DUPLA: ELEM. DE DRENAGEM",IF(COUNTIF(P9:R9,"X")<>1,"FALTA/DUPLA: SIN. HORIZ.",IF(COUNTIF(S9:U9,"X")<>1,"FALTA/DUPLA: SIN. VERTICAL","OK")))))) -> OK
A10: 181ETO0171 | B10: C | C10: 1 | D10: 1.1468163 | E10: =D10-C10 -> 0.14681629 | G10: X | K10: X | N10: X | Q10: X | T10: X | W10: =IF(COUNTA(F10:U10)=0,"— não preenchido",IF(COUNTIF(F10:J10,"X")<>1,"FALTA/DUPLA: CONDIÇÃO DO PAVIMENTO",IF(COUNTIF(K10:L10,"X")<>1,"FALTA/DUPLA: VEGETAÇÃO",IF(COUNTIF(M10:O10,"X")<>1,"FALTA/DUPLA: ELEM. DE DRENAGEM",IF(COUNTIF(P10:R10,"X")<>1,"FALTA/DUPLA: SIN. HORIZ.",IF(COUNTIF(S10:U10,"X")<>1,"FALTA/DUPLA: SIN. VERTICAL","OK")))))) -> OK
A11: ▲ AQUI HÁ 5.577 km FORA DO ESCOPO DO CONTRATO (perímetro urbano de jurisdição municipal). Você passa por ele, mas NÃO preenche.
A12: S.R.E. 070ETO0230 | ENTR. BR-242 (FORMOSO DO ARAGUAIA ) - DORILÂNDIA | PPS · Estadual · 59.748 km · início: -11.809321, -49.533811
A13: 070ETO0230 | B13: C | C13: 0 | D13: 1 | E13: =D13-C13 -> 1 | G13: X | L13: X | N13: X | Q13: X | T13: X | W13: =IF(COUNTA(F13:U13)=0,"— não preenchido",IF(COUNTIF(F13:J13,"X")<>1,"FALTA/DUPLA: CONDIÇÃO DO PAVIMENTO",IF(COUNTIF(K13:L13,"X")<>1,"FALTA/DUPLA: VEGETAÇÃO",IF(COUNTIF(M13:O13,"X")<>1,"FALTA/DUPLA: ELEM. DE DRENAGEM",IF(COUNTIF(P13:R13,"X")<>1,"FALTA/DUPLA: SIN. HORIZ.",IF(COUNTIF(S13:U13,"X")<>1,"FALTA/DUPLA: SIN. VERTICAL","OK")))))) -> OK
A14: 070ETO0230 | B14: C | C14: 1 | D14: 2 | E14: =D14-C14 -> 1 | G14: X | L14: X | N14: X | Q14: X | T14: X | W14: =IF(COUNTA(F14:U14)=0,"— não preenchido",IF(COUNTIF(F14:J14,"X")<>1,"FALTA/DUPLA: CONDIÇÃO DO PAVIMENTO",IF(COUNTIF(K14:L14,"X")<>1,"FALTA/DUPLA: VEGETAÇÃO",IF(COUNTIF(M14:O14,"X")<>1,"FALTA/DUPLA: ELEM. DE DRENAGEM",IF(COUNTIF(P14:R14,"X")<>1,"FALTA/DUPLA: SIN. HORIZ.",IF(COUNTIF(S14:U14,"X")<>1,"FALTA/DUPLA: SIN. VERTICAL","OK")))))) -> OK
A15: 070ETO0230 | B15: C | C15: 2 | D15: 3 | E15: =D15-C15 -> 1 | H15: X | L15: X | N15: X | Q15: X | T15: X | W15: =IF(COUNTA(F15:U15)=0,"— não preenchido",IF(COUNTIF(F15:J15,"X")<>1,"FALTA/DUPLA: CONDIÇÃO DO PAVIMENTO",IF(COUNTIF(K15:L15,"X")<>1,"FALTA/DUPLA: VEGETAÇÃO",IF(COUNTIF(M15:O15,"X")<>1,"FALTA/DUPLA: ELEM. DE DRENAGEM",IF(COUNTIF(P15:R15,"X")<>1,"FALTA/DUPLA: SIN. HORIZ.",IF(COUNTIF(S15:U15,"X")<>1,"FALTA/DUPLA: SIN. VERTICAL","OK")))))) -> OK
A16: 070ETO0230 | B16: C | C16: 3 | D16: 4 | E16: =D16-C16 -> 1 | G16: X | L16: X | N16: X | Q16: X | T16: X | W16: =IF(COUNTA(F16:U16)=0,"— não preenchido",IF(COUNTIF(F16:J16,"X")<>1,"FALTA/DUPLA: CONDIÇÃO DO PAVIMENTO",IF(COUNTIF(K16:L16,"X")<>1,"FALTA/DUPLA: VEGETAÇÃO",IF(COUNTIF(M16:O16,"X")<>1,"FALTA/DUPLA: ELEM. DE DRENAGEM",IF(COUNTIF(P16:R16,"X")<>1,"FALTA/DUPLA: SIN. HORIZ.",IF(COUNTIF(S16:U16,"X")<>1,"FALTA/DUPLA: SIN. VERTICAL","OK")))))) -> OK
A17: 070ETO0230 | B17: C | C17: 4 | D17: 5 | E17: =D17-C17 -> 1 | H17: X | L17: X | N17: X | Q17: X | T17: X | W17: =IF(COUNTA(F17:U17)=0,"— não preenchido",IF(COUNTIF(F17:J17,"X")<>1,"FALTA/DUPLA: CONDIÇÃO DO PAVIMENTO",IF(COUNTIF(K17:L17,"X")<>1,"FALTA/DUPLA: VEGETAÇÃO",IF(COUNTIF(M17:O17,"X")<>1,"FALTA/DUPLA: ELEM. DE DRENAGEM",IF(COUNTIF(P17:R17,"X")<>1,"FALTA/DUPLA: SIN. HORIZ.",IF(COUNTIF(S17:U17,"X")<>1,"FALTA/DUPLA: SIN. VERTICAL","OK")))))) -> OK
A18: 070ETO0230 | B18: C | C18: 5 | D18: 6 | E18: =D18-C18 -> 1 | G18: X | L18: X | N18: X | Q18: X | T18: X | W18: =IF(COUNTA(F18:U18)=0,"— não preenchido",IF(COUNTIF(F18:J18,"X")<>1,"FALTA/DUPLA: CONDIÇÃO DO PAVIMENTO",IF(COUNTIF(K18:L18,"X")<>1,"FALTA/DUPLA: VEGETAÇÃO",IF(COUNTIF(M18:O18,"X")<>1,"FALTA/DUPLA: ELEM. DE DRENAGEM",IF(COUNTIF(P18:R18,"X")<>1,"FALTA/DUPLA: SIN. HORIZ.",IF(COUNTIF(S18:U18,"X")<>1,"FALTA/DUPLA: SIN. VERTICAL","OK")))))) -> OK
A19: 070ETO0230 | B19: C | C19: 6 | D19: 7 | E19: =D19-C19 -> 1 | G19: X | L19: X | N19: X | Q19: X | T19: X | W19: =IF(COUNTA(F19:U19)=0,"— não preenchido",IF(COUNTIF(F19:J19,"X")<>1,"FALTA/DUPLA: CONDIÇÃO DO PAVIMENTO",IF(COUNTIF(K19:L19,"X")<>1,"FALTA/DUPLA: VEGETAÇÃO",IF(COUNTIF(M19:O19,"X")<>1,"FALTA/DUPLA: ELEM. DE DRENAGEM",IF(COUNTIF(P19:R19,"X")<>1,"FALTA/DUPLA: SIN. HORIZ.",IF(COUNTIF(S19:U19,"X")<>1,"FALTA/DUPLA: SIN. VERTICAL","OK")))))) -> OK
A20: 070ETO0230 | B20: C | C20: 7 | D20: 8 | E20: =D20-C20 -> 1 | I20: X | L20: X | N20: X | Q20: X | T20: X | W20: =IF(COUNTA(F20:U20)=0,"— não preenchido",IF(COUNTIF(F20:J20,"X")<>1,"FALTA/DUPLA: CONDIÇÃO DO PAVIMENTO",IF(COUNTIF(K20:L20,"X")<>1,"FALTA/DUPLA: VEGETAÇÃO",IF(COUNTIF(M20:O20,"X")<>1,"FALTA/DUPLA: ELEM. DE DRENAGEM",IF(COUNTIF(P20:R20,"X")<>1,"FALTA/DUPLA: SIN. HORIZ.",IF(COUNTIF(S20:U20,"X")<>1,"FALTA/DUPLA: SIN. VERTICAL","OK")))))) -> OK
A21: 070ETO0230 | B21: C | C21: 8 | D21: 9 | E21: =D21-C21 -> 1 | G21: X | L21: X | N21: X | Q21: X | T21: X | W21: =IF(COUNTA(F21:U21)=0,"— não preenchido",IF(COUNTIF(F21:J21,"X")<>1,"FALTA/DUPLA: CONDIÇÃO DO PAVIMENTO",IF(COUNTIF(K21:L21,"X")<>1,"FALTA/DUPLA: VEGETAÇÃO",IF(COUNTIF(M21:O21,"X")<>1,"FALTA/DUPLA: ELEM. DE DRENAGEM",IF(COUNTIF(P21:R21,"X")<>1,"FALTA/DUPLA: SIN. HORIZ.",IF(COUNTIF(S21:U21,"X")<>1,"FALTA/DUPLA: SIN. VERTICAL","OK")))))) -> OK
A22: 070ETO0230 | B22: C | C22: 9 | D22: 10 | E22: =D22-C22 -> 1 | G22: X | L22: X | N22: X | Q22: X | T22: X | W22: =IF(COUNTA(F22:U22)=0,"— não preenchido",IF(COUNTIF(F22:J22,"X")<>1,"FALTA/DUPLA: CONDIÇÃO DO PAVIMENTO",IF(COUNTIF(K22:L22,"X")<>1,"FALTA/DUPLA: VEGETAÇÃO",IF(COUNTIF(M22:O22,"X")<>1,"FALTA/DUPLA: ELEM. DE DRENAGEM",IF(COUNTIF(P22:R22,"X")<>1,"FALTA/DUPLA: SIN. HORIZ.",IF(COUNTIF(S22:U22,"X")<>1,"FALTA/DUPLA: SIN. VERTICAL","OK")))))) -> OK
A23: 070ETO0230 | B23: C | C23: 10 | D23: 11 | E23: =D23-C23 -> 1 | G23: X | L23: X | N23: X | Q23: X | T23: X | W23: =IF(COUNTA(F23:U23)=0,"— não preenchido",IF(COUNTIF(F23:J23,"X")<>1,"FALTA/DUPLA: CONDIÇÃO DO PAVIMENTO",IF(COUNTIF(K23:L23,"X")<>1,"FALTA/DUPLA: VEGETAÇÃO",IF(COUNTIF(M23:O23,"X")<>1,"FALTA/DUPLA: ELEM. DE DRENAGEM",IF(COUNTIF(P23:R23,"X")<>1,"FALTA/DUPLA: SIN. HORIZ.",IF(COUNTIF(S23:U23,"X")<>1,"FALTA/DUPLA: SIN. VERTICAL","OK")))))) -> OK
A24: 070ETO0230 | B24: C | C24: 11 | D24: 12 | E24: =D24-C24 -> 1 | I24: X | L24: X | N24: X | Q24: X | T24: X | W24: =IF(COUNTA(F24:U24)=0,"— não preenchido",IF(COUNTIF(F24:J24,"X")<>1,"FALTA/DUPLA: CONDIÇÃO DO PAVIMENTO",IF(COUNTIF(K24:L24,"X")<>1,"FALTA/DUPLA: VEGETAÇÃO",IF(COUNTIF(M24:O24,"X")<>1,"FALTA/DUPLA: ELEM. DE DRENAGEM",IF(COUNTIF(P24:R24,"X")<>1,"FALTA/DUPLA: SIN. HORIZ.",IF(COUNTIF(S24:U24,"X")<>1,"FALTA/DUPLA: SIN. VERTICAL","OK")))))) -> OK
A25: 070ETO0230 | B25: C | C25: 12 | D25: 13 | E25: =D25-C25 -> 1 | G25: X | L25: X | N25: X | Q25: X | T25: X | W25: =IF(COUNTA(F25:U25)=0,"— não preenchido",IF(COUNTIF(F25:J25,"X")<>1,"FALTA/DUPLA: CONDIÇÃO DO PAVIMENTO",IF(COUNTIF(K25:L25,"X")<>1,"FALTA/DUPLA: VEGETAÇÃO",IF(COUNTIF(M25:O25,"X")<>1,"FALTA/DUPLA: ELEM. DE DRENAGEM",IF(COUNTIF(P25:R25,"X")<>1,"FALTA/DUPLA: SIN. HORIZ.",IF(COUNTIF(S25:U25,"X")<>1,"FALTA/DUPLA: SIN. VERTICAL","OK")))))) -> OK
A26: 070ETO0230 | B26: C | C26: 13 | D26: 14 | E26: =D26-C26 -> 1 | G26: X | L26: X | N26: X | Q26: X | T26: X | W26: =IF(COUNTA(F26:U26)=0,"— não preenchido",IF(COUNTIF(F26:J26,"X")<>1,"FALTA/DUPLA: CONDIÇÃO DO PAVIMENTO",IF(COUNTIF(K26:L26,"X")<>1,"FALTA/DUPLA: VEGETAÇÃO",IF(COUNTIF(M26:O26,"X")<>1,"FALTA/DUPLA: ELEM. DE DRENAGEM",IF(COUNTIF(P26:R26,"X")<>1,"FALTA/DUPLA: SIN. HORIZ.",IF(COUNTIF(S26:U26,"X")<>1,"FALTA/DUPLA: SIN. VERTICAL","OK")))))) -> OK
A27: 070ETO0230 | B27: C | C27: 14 | D27: 15 | E27: =D27-C27 -> 1 | G27: X | L27: X | N27: X | Q27: X | T27: X | W27: =IF(COUNTA(F27:U27)=0,"— não preenchido",IF(COUNTIF(F27:J27,"X")<>1,"FALTA/DUPLA: CONDIÇÃO DO PAVIMENTO",IF(COUNTIF(K27:L27,"X")<>1,"FALTA/DUPLA: VEGETAÇÃO",IF(COUNTIF(M27:O27,"X")<>1,"FALTA/DUPLA: ELEM. DE DRENAGEM",IF(COUNTIF(P27:R27,"X")<>1,"FALTA/DUPLA: SIN. HORIZ.",IF(COUNTIF(S27:U27,"X")<>1,"FALTA/DUPLA: SIN. VERTICAL","OK")))))) -> OK
A28: 070ETO0230 | B28: C | C28: 15 | D28: 16 | E28: =D28-C28 -> 1 | G28: X | L28: X | N28: X | Q28: X | T28: X | W28: =IF(COUNTA(F28:U28)=0,"— não preenchido",IF(COUNTIF(F28:J28,"X")<>1,"FALTA/DUPLA: CONDIÇÃO DO PAVIMENTO",IF(COUNTIF(K28:L28,"X")<>1,"FALTA/DUPLA: VEGETAÇÃO",IF(COUNTIF(M28:O28,"X")<>1,"FALTA/DUPLA: ELEM. DE DRENAGEM",IF(COUNTIF(P28:R28,"X")<>1,"FALTA/DUPLA: SIN. HORIZ.",IF(COUNTIF(S28:U28,"X")<>1,"FALTA/DUPLA: SIN. VERTICAL","OK")))))) -> OK
A29: 070ETO0230 | B29: C | C29: 16 | D29: 17 | E29: =D29-C29 -> 1 | G29: X | L29: X | N29: X | Q29: X | T29: X | W29: =IF(COUNTA(F29:U29)=0,"— não preenchido",IF(COUNTIF(F29:J29,"X")<>1,"FALTA/DUPLA: CONDIÇÃO DO PAVIMENTO",IF(COUNTIF(K29:L29,"X")<>1,"FALTA/DUPLA: VEGETAÇÃO",IF(COUNTIF(M29:O29,"X")<>1,"FALTA/DUPLA: ELEM. DE DRENAGEM",IF(COUNTIF(P29:R29,"X")<>1,"FALTA/DUPLA: SIN. HORIZ.",IF(COUNTIF(S29:U29,"X")<>1,"FALTA/DUPLA: SIN. VERTICAL","OK")))))) -> OK
A30: 070ETO0230 | B30: C | C30: 17 | D30: 18 | E30: =D30-C30 -> 1 | G30: X | L30: X | N30: X | Q30: X | T30: X | W30: =IF(COUNTA(F30:U30)=0,"— não preenchido",IF(COUNTIF(F30:J30,"X")<>1,"FALTA/DUPLA: CONDIÇÃO DO PAVIMENTO",IF(COUNTIF(K30:L30,"X")<>1,"FALTA/DUPLA: VEGETAÇÃO",IF(COUNTIF(M30:O30,"X")<>1,"FALTA/DUPLA: ELEM. DE DRENAGEM",IF(COUNTIF(P30:R30,"X")<>1,"FALTA/DUPLA: SIN. HORIZ.",IF(COUNTIF(S30:U30,"X")<>1,"FALTA/DUPLA: SIN. VERTICAL","OK")))))) -> OK
A31: 070ETO0230 | B31: C | C31: 18 | D31: 19 | E31: =D31-C31 -> 1 | G31: X | L31: X | N31: X | Q31: X | T31: X | W31: =IF(COUNTA(F31:U31)=0,"— não preenchido",IF(COUNTIF(F31:J31,"X")<>1,"FALTA/DUPLA: CONDIÇÃO DO PAVIMENTO",IF(COUNTIF(K31:L31,"X")<>1,"FALTA/DUPLA: VEGETAÇÃO",IF(COUNTIF(M31:O31,"X")<>1,"FALTA/DUPLA: ELEM. DE DRENAGEM",IF(COUNTIF(P31:R31,"X")<>1,"FALTA/DUPLA: SIN. HORIZ.",IF(COUNTIF(S31:U31,"X")<>1,"FALTA/DUPLA: SIN. VERTICAL","OK")))))) -> OK
A32: 070ETO0230 | B32: C | C32: 19 | D32: 20 | E32: =D32-C32 -> 1 | G32: X | L32: X | N32: X | Q32: X | T32: X | W32: =IF(COUNTA(F32:U32)=0,"— não preenchido",IF(COUNTIF(F32:J32,"X")<>1,"FALTA/DUPLA: CONDIÇÃO DO PAVIMENTO",IF(COUNTIF(K32:L32,"X")<>1,"FALTA/DUPLA: VEGETAÇÃO",IF(COUNTIF(M32:O32,"X")<>1,"FALTA/DUPLA: ELEM. DE DRENAGEM",IF(COUNTIF(P32:R32,"X")<>1,"FALTA/DUPLA: SIN. HORIZ.",IF(COUNTIF(S32:U32,"X")<>1,"FALTA/DUPLA: SIN. VERTICAL","OK")))))) -> OK
A33: 070ETO0230 | B33: C | C33: 20 | D33: 21 | E33: =D33-C33 -> 1 | G33: X | L33: X | N33: X | Q33: X | T33: X | W33: =IF(COUNTA(F33:U33)=0,"— não preenchido",IF(COUNTIF(F33:J33,"X")<>1,"FALTA/DUPLA: CONDIÇÃO DO PAVIMENTO",IF(COUNTIF(K33:L33,"X")<>1,"FALTA/DUPLA: VEGETAÇÃO",IF(COUNTIF(M33:O33,"X")<>1,"FALTA/DUPLA: ELEM. DE DRENAGEM",IF(COUNTIF(P33:R33,"X")<>1,"FALTA/DUPLA: SIN. HORIZ.",IF(COUNTIF(S33:U33,"X")<>1,"FALTA/DUPLA: SIN. VERTICAL","OK")))))) -> OK
A34: 070ETO0230 | B34: C | C34: 21 | D34: 22 | E34: =D34-C34 -> 1 | G34: X | L34: X | N34: X | Q34: X | T34: X | W34: =IF(COUNTA(F34:U34)=0,"— não preenchido",IF(COUNTIF(F34:J34,"X")<>1,"FALTA/DUPLA: CONDIÇÃO DO PAVIMENTO",IF(COUNTIF(K34:L34,"X")<>1,"FALTA/DUPLA: VEGETAÇÃO",IF(COUNTIF(M34:O34,"X")<>1,"FALTA/DUPLA: ELEM. DE DRENAGEM",IF(COUNTIF(P34:R34,"X")<>1,"FALTA/DUPLA: SIN. HORIZ.",IF(COUNTIF(S34:U34,"X")<>1,"FALTA/DUPLA: SIN. VERTICAL","OK")))))) -> OK
A35: 070ETO0230 | B35: C | C35: 22 | D35: 23 | E35: =D35-C35 -> 1 | G35: X | L35: X | N35: X | Q35: X | T35: X | W35: =IF(COUNTA(F35:U35)=0,"— não preenchido",IF(COUNTIF(F35:J35,"X")<>1,"FALTA/DUPLA: CONDIÇÃO DO PAVIMENTO",IF(COUNTIF(K35:L35,"X")<>1,"FALTA/DUPLA: VEGETAÇÃO",IF(COUNTIF(M35:O35,"X")<>1,"FALTA/DUPLA: ELEM. DE DRENAGEM",IF(COUNTIF(P35:R35,"X")<>1,"FALTA/DUPLA: SIN. HORIZ.",IF(COUNTIF(S35:U35,"X")<>1,"FALTA/DUPLA: SIN. VERTICAL","OK")))))) -> OK
A36: 070ETO0230 | B36: C | C36: 23 | D36: 24 | E36: =D36-C36 -> 1 | G36: X | L36: X | N36: X | Q36: X | T36: X | W36: =IF(COUNTA(F36:U36)=0,"— não preenchido",IF(COUNTIF(F36:J36,"X")<>1,"FALTA/DUPLA: CONDIÇÃO DO PAVIMENTO",IF(COUNTIF(K36:L36,"X")<>1,"FALTA/DUPLA: VEGETAÇÃO",IF(COUNTIF(M36:O36,"X")<>1,"FALTA/DUPLA: ELEM. DE DRENAGEM",IF(COUNTIF(P36:R36,"X")<>1,"FALTA/DUPLA: SIN. HORIZ.",IF(COUNTIF(S36:U36,"X")<>1,"FALTA/DUPLA: SIN. VERTICAL","OK")))))) -> OK
... A45: 070ETO0230 | B45: C | C45: 32 | D45: 33 | E45: =D45-C45 -> 1 | G45: X | L45: X | N45: X | Q45: X | T45: X | W45: =IF(COUNTA(F45:U45)=0,"— não preenchido",IF(COUNTIF(F45:J45,"X")<>1,"FALTA/DUPLA: CONDIÇÃO DO PAVIMENTO",IF(COUNTIF(K45:L45,"X")<>1,"FALTA/DUPLA: VEGETAÇÃO",IF(COUNTIF(M45:O45,"X")<>1,"FALTA/DUPLA: ELEM. DE DRENAGEM",IF(COUNTIF(P45:R45,"X")<>1,"FALTA/DUPLA: SIN. HORIZ.",IF(COUNTIF(S45:U45,"X")<>1,"FALTA/DUPLA: SIN. VERTICAL","OK")))))) -> OK
A46: 070ETO0230 | B46: C | C46: 33 | D46: 34 | E46: =D46-C46 -> 1 | H46: X | L46: X | N46: X | Q46: X | T46: X | W46: =IF(COUNTA(F46:U46)=0,"— não preenchido",IF(COUNTIF(F46:J46,"X")<>1,"FALTA/DUPLA: CONDIÇÃO DO PAVIMENTO",IF(COUNTIF(K46:L46,"X")<>1,"FALTA/DUPLA: VEGETAÇÃO",IF(COUNTIF(M46:O46,"X")<>1,"FALTA/DUPLA: ELEM. DE DRENAGEM",IF(COUNTIF(P46:R46,"X")<>1,"FALTA/DUPLA: SIN. HORIZ.",IF(COUNTIF(S46:U46,"X")<>1,"FALTA/DUPLA: SIN. VERTICAL","OK")))))) -> OK
A47: 070ETO0230 | B47: C | C47: 34 | D47: 35 | E47: =D47-C47 -> 1 | G47: X | L47: X | N47: X | Q47: X | T47: X | W47: =IF(COUNTA(F47:U47)=0,"— não preenchido",IF(COUNTIF(F47:J47,"X")<>1,"FALTA/DUPLA: CONDIÇÃO DO PAVIMENTO",IF(COUNTIF(K47:L47,"X")<>1,"FALTA/DUPLA: VEGETAÇÃO",IF(COUNTIF(M47:O47,"X")<>1,"FALTA/DUPLA: ELEM. DE DRENAGEM",IF(COUNTIF(P47:R47,"X")<>1,"FALTA/DUPLA: SIN. HORIZ.",IF(COUNTIF(S47:U47,"X")<>1,"FALTA/DUPLA: SIN. VERTICAL","OK")))))) -> OK
A48: 070ETO0230 | B48: C | C48: 35 | D48: 36 | E48: =D48-C48 -> 1 | G48: X | L48: X | N48: X | Q48: X | T48: X | W48: =IF(COUNTA(F48:U48)=0,"— não preenchido",IF(COUNTIF(F48:J48,"X")<>1,"FALTA/DUPLA: CONDIÇÃO DO PAVIMENTO",IF(COUNTIF(K48:L48,"X")<>1,"FALTA/DUPLA: VEGETAÇÃO",IF(COUNTIF(M48:O48,"X")<>1,"FALTA/DUPLA: ELEM. DE DRENAGEM",IF(COUNTIF(P48:R48,"X")<>1,"FALTA/DUPLA: SIN. HORIZ.",IF(COUNTIF(S48:U48,"X")<>1,"FALTA/DUPLA: SIN. VERTICAL","OK")))))) -> OK
A49: 070ETO0230 | B49: C | C49: 36 | D49: 37 | E49: =D49-C49 -> 1 | G49: X | L49: X | N49: X | Q49: X | T49: X | W49: =IF(COUNTA(F49:U49)=0,"— não preenchido",IF(COUNTIF(F49:J49,"X")<>1,"FALTA/DUPLA: CONDIÇÃO DO PAVIMENTO",IF(COUNTIF(K49:L49,"X")<>1,"FALTA/DUPLA: VEGETAÇÃO",IF(COUNTIF(M49:O49,"X")<>1,"FALTA/DUPLA: ELEM. DE DRENAGEM",IF(COUNTIF(P49:R49,"X")<>1,"FALTA/DUPLA: SIN. HORIZ.",IF(COUNTIF(S49:U49,"X")<>1,"FALTA/DUPLA: SIN. VERTICAL","OK")))))) -> OK
...

Sheet 203
A1: PROGRAMA DE MANUTENÇÃO RODOVIÁRIA — FICHA DE INSPEÇÃO — RODOVIAS PAVIMENTADAS | Y1: Valores dos gráficos — troca 0 por N/D para a fatia não aparecer. Não editar.
A2: REGIÃO: 11 — GURUPI | G2: MÊS / ANO: | I2: 46266 | K2: DATA: | P2: TÉCNICO: | R2: ENG. THIAGO BORGES TORQUATO | Y2: =IF(F15=0,NA(),F15) -> #N/A | Z2: =IF(G15=0,NA(),G15) -> #N/A | AA2: =IF(H15=0,NA(),H15) -> 0.99985589 | AB2: =IF(I15=0,NA(),I15) -> #N/A | AC2: =IF(J15=0,NA(),J15) -> #N/A | AD2: =IF(K15=0,NA(),K15) -> 0.99985589 | AE2: =IF(L15=0,NA(),L15) -> #N/A | AF2: =IF(M15=0,NA(),M15) -> 0.99985589 | ... AN2: =IF(U15=0,NA(),U15) -> #N/A
A3: TRECHO 203 — RODOVIA TO-373 - TRECHO ALVORADA - ARAGUAÇU - PERÍMETRO URBANO | T3: EXTENSÃO: 1,000 km · 1 S.R.E.
A4: COMO PREENCHER: uma X em UMA coluna de cada grupo, por linha. Se houver mais de um defeito no mesmo km, marque o PREDOMINANTE e escreva o resto em OBSERVAÇÕES. A quilometragem é contada de 0 até o fim de CADA S.R.E. (não é o marco da rodovia).
A6: S.R.E. | B6: SENT. | C6: INÍCIO (KM) | D6: FIM (KM) | E6: EXT. (KM) | F6: CONDIÇÃO DO PAVIMENTO | K6: VEGETAÇÃO | M6: ELEM. DE DRENAGEM | P6: SIN. HORIZ. | S6: SIN. VERTICAL | V6: OBSERVAÇÕES | W6: CONFERÊNCIA (só na tela)
F7: BOM | G7: REM. I. | H7: REM. L. | I7: BUR. I. | J7: BUR. L. | K7: ADEQ. | L7: INAD. | M7: LIMPOS | N7: SUJOS | O7: DAN. | P7: BOM | Q7: REG. | R7: INEXIST. | S7: BOM | T7: POUCAS | U7: INEXIST.
A8: S.R.E. 373ETO0221 | ALVORADA *TRECHO URBANO* | PSU · Municipal · 1.000 km · início: -12.4898, -49.12822
A9: 373ETO0221 | B9: C | C9: 0 | D9: 0.99985589 | E9: =D9-C9 -> 0.99985589 | H9: X | K9: X | M9: X | Q9: X | T9: X | W9: =IF(COUNTA(F9:U9)=0,"— não preenchido",IF(COUNTIF(F9:J9,"X")<>1,"FALTA/DUPLA: CONDIÇÃO DO PAVIMENTO",IF(COUNTIF(K9:L9,"X")<>1,"FALTA/DUPLA: VEGETAÇÃO",IF(COUNTIF(M9:O9,"X")<>1,"FALTA/DUPLA: ELEM. DE DRENAGEM",IF(COUNTIF(P9:R9,"X")<>1,"FALTA/DUPLA: SIN. HORIZ.",IF(COUNTIF(S9:U9,"X")<>1,"FALTA/DUPLA: SIN. VERTICAL","OK")))))) -> OK
A11: ____________________________________________ | G11: ____________________________________________
A12: TÉCNICO RESPONSÁVEL PELA INSPEÇÃO | G12: VISTO DA SUPERVISÃO
A14: RESUMO DO TRECHO — KM LANÇADO POR ITEM
A15: KM LANÇADO | F15: =SUMIF(F$9:F$9,"X",$E$9:$E$9) -> 0 | G15: =SUMIF(G$9:G$9,"X",$E$9:$E$9) -> 0 | H15: =SUMIF(H$9:H$9,"X",$E$9:$E$9) -> 0.99985589 | I15: =SUMIF(I$9:I$9,"X",$E$9:$E$9) -> 0 | J15: =SUMIF(J$9:J$9,"X",$E$9:$E$9) -> 0 | K15: =SUMIF(K$9:K$9,"X",$E$9:$E$9) -> 0.99985589 | L15: =SUMIF(L$9:L$9,"X",$E$9:$E$9) -> 0 | M15: =SUMIF(M$9:M$9,"X",$E$9:$E$9) -> 0.99985589 | ... U15: =SUMIF(U$9:U$9,"X",$E$9:$E$9) -> 0
A16: % DA EXTENSÃO | F16: =IF($R18=0,0,F15/$R18) -> 0 | G16: =IF($R18=0,0,G15/$R18) -> 0 | H16: =IF($R18=0,0,H15/$R18) -> 1 | I16: =IF($R18=0,0,I15/$R18) -> 0 | J16: =IF($R18=0,0,J15/$R18) -> 0 | K16: =IF($R18=0,0,K15/$R18) -> 1 | L16: =IF($R18=0,0,L15/$R18) -> 0 | M16: =IF($R18=0,0,M15/$R18) -> 1 | ... U16: =IF($R18=0,0,U15/$R18) -> 0
A17: CONFERÊNCIA POR GRUPO | F17: =IF(SUM(F15:J15)=0,"— não preenchido",IF(ROUND(SUM(F15:J15)-$R18,3)=0,"OK — "&ROUND(SUM(F15:J15),3)&" km","ERRO — dif. de "&ROUND(SUM(F15:J15)-$R18,3)&" km")) -> OK — 1 km | K17: =IF(SUM(K15:L15)=0,"— não preenchido",IF(ROUND(SUM(K15:L15)-$R18,3)=0,"OK — "&ROUND(SUM(K15:L15),3)&" km","ERRO — dif. de "&ROUND(SUM(K15:L15)-$R18,3)&" km")) -> OK — 1 km | M17: =IF(SUM(M15:O15)=0,"— não preenchido",IF(ROUND(SUM(M15:O15)-$R18,3)=0,"OK — "&ROUND(SUM(M15:O15),3)&" km","ERRO — dif. de "&ROUND(SUM(M15:O15)-$R18,3)&" km")) -> OK — 1 km | P17: =IF(SUM(P15:R15)=0,"— não preenchido",IF(ROUND(SUM(P15:R15)-$R18,3)=0,"OK — "&ROUND(SUM(P15:R15),3)&" km","ERRO — dif. de "&ROUND(SUM(P15:R15)-$R18,3)&" km")) -> OK — 1 km | S17: =IF(SUM(S15:U15)=0,"— não preenchido",IF(ROUND(SUM(S15:U15)-$R18,3)=0,"OK — "&ROUND(SUM(S15:U15),3)&" km","ERRO — dif. de "&ROUND(SUM(S15:U15)-$R18,3)&" km")) -> OK — 1 km
A18: EXTENSÃO TOTAL DO TRECHO | R18: =SUM(E9:E9) -> 0.99985589 | V18: =COUNTIF(W9:W9,"OK")&" de "&COUNT($E$9:$E$9)&" linhas conferidas" -> 1 de 1 linhas conferidas
A20: LEGENDA
A21: REM. I. / REM. L. | E21: Remendos isolados (até 10 por km) · Remendos ao longo (mais de 10 por km)
A22: BUR. I. / BUR. L. | E22: Buracos isolados (até 5 por km) · Buracos ao longo (mais de 5 por km)
A23: SIT. | E23: PPS = pista simples · PSU = simples urbana · PDU = duplicada
A24: FAIXA AZUL | E24: Cabeçalho de cada S.R.E.: descrição, situação, jurisdição, extensão e coordenada de início.
A25: INÍCIO / FIM (KM) | E25: Contados de 0 até o fim de CADA S.R.E. Não é o marco quilométrico da rodovia.
A26: SENT. | E26: C = crescente · D = decrescente
A27: FAIXA CINZA | E27: Segmento fora do escopo do contrato: você passa por ele, mas não preenche.
A28: CÉLULA VERMELHA | E28: Mais de uma X no mesmo grupo. Apague uma delas.
A29: CONFERÊNCIA | E29: Só na tela, não sai impresso. Fica OK com uma X em cada grupo.

Sheet 204
A1: PROGRAMA DE MANUTENÇÃO RODOVIÁRIA — FICHA DE INSPEÇÃO — RODOVIAS PAVIMENTADAS | Y1: Valores dos gráficos — troca 0 por N/D para a fatia não aparecer. Não editar.
A2: REGIÃO: 11 — GURUPI | G2: MÊS / ANO: | I2: 46266 | K2: DATA: | P2: TÉCNICO: | R2: ENG. THIAGO BORGES TORQUATO | Y2: =IF(F75=0,NA(),F75) -> #N/A | Z2: =IF(G75=0,NA(),G75) -> 56 | AA2: =IF(H75=0,NA(),H75) -> 3.7456118 | AB2: =IF(I75=0,NA(),I75) -> #N/A | AC2: =IF(J75=0,NA(),J75) -> #N/A | AD2: =IF(K75=0,NA(),K75) -> 59.745612 | AE2: =IF(L75=0,NA(),L75) -> #N/A | AF2: =IF(M75=0,NA(),M75) -> 0.99026288 | ... AN2: =IF(U75=0,NA(),U75) -> #N/A
A3: TRECHO 204 — RODOVIA TO-070 - TRECHO ALIANÇA DO TOCANTINS - BREJINHO DE NAZARÉ | T3: EXTENSÃO: 59,746 km · 2 S.R.E.
A4: COMO PREENCHER: uma X em UMA coluna de cada grupo, por linha. Se houver mais de um defeito no mesmo km, marque o PREDOMINANTE e escreva o resto em OBSERVAÇÕES. A quilometragem é contada de 0 até o fim de CADA S.R.E. (não é o marco da rodovia).
A6: S.R.E. | B6: SENT. | C6: INÍCIO (KM) | D6: FIM (KM) | E6: EXT. (KM) | F6: CONDIÇÃO DO PAVIMENTO | K6: VEGETAÇÃO | M6: ELEM. DE DRENAGEM | P6: SIN. HORIZ. | S6: SIN. VERTICAL | V6: OBSERVAÇÕES | W6: CONFERÊNCIA (só na tela)
F7: BOM | G7: REM. I. | H7: REM. L. | I7: BUR. I. | J7: BUR. L. | K7: ADEQ. | L7: INAD. | M7: LIMPOS | N7: SUJOS | O7: DAN. | P7: BOM | Q7: REG. | R7: INEXIST. | S7: BOM | T7: POUCAS | U7: INEXIST.
A8: S.R.E. 070ETO0120 | BREJINHO DE NAZARÉ *TRECHO URBANO* - ALIANCA *TRECHO URBANO* | PPS · Estadual · 58.755 km · início: -11.015083, -48.579912
A9: 070ETO0120 | B9: C | C9: 0 | D9: 1 | E9: =D9-C9 -> 1 | G9: X | K9: X | N9: X | Q9: X | T9: X | W9: =IF(COUNTA(F9:U9)=0,"— não preenchido",IF(COUNTIF(F9:J9,"X")<>1,"FALTA/DUPLA: CONDIÇÃO DO PAVIMENTO",IF(COUNTIF(K9:L9,"X")<>1,"FALTA/DUPLA: VEGETAÇÃO",IF(COUNTIF(M9:O9,"X")<>1,"FALTA/DUPLA: ELEM. DE DRENAGEM",IF(COUNTIF(P9:R9,"X")<>1,"FALTA/DUPLA: SIN. HORIZ.",IF(COUNTIF(S9:U9,"X")<>1,"FALTA/DUPLA: SIN. VERTICAL","OK")))))) -> OK
A10: 070ETO0120 | B10: C | C10: 1 | D10: 2 | E10: =D10-C10 -> 1 | G10: X | K10: X | N10: X | Q10: X | T10: X | W10: =IF(COUNTA(F10:U10)=0,"— não preenchido",IF(COUNTIF(F10:J10,"X")<>1,"FALTA/DUPLA: CONDIÇÃO DO PAVIMENTO",IF(COUNTIF(K10:L10,"X")<>1,"FALTA/DUPLA: VEGETAÇÃO",IF(COUNTIF(M10:O10,"X")<>1,"FALTA/DUPLA: ELEM. DE DRENAGEM",IF(COUNTIF(P10:R10,"X")<>1,"FALTA/DUPLA: SIN. HORIZ.",IF(COUNTIF(S10:U10,"X")<>1,"FALTA/DUPLA: SIN. VERTICAL","OK")))))) -> OK
A11: 070ETO0120 | B11: C | C11: 2 | D11: 3 | E11: =D11-C11 -> 1 | G11: X | K11: X | N11: X | Q11: X | T11: X | W11: =IF(COUNTA(F11:U11)=0,"— não preenchido",IF(COUNTIF(F11:J11,"X")<>1,"FALTA/DUPLA: CONDIÇÃO DO PAVIMENTO",IF(COUNTIF(K11:L11,"X")<>1,"FALTA/DUPLA: VEGETAÇÃO",IF(COUNTIF(M11:O11,"X")<>1,"FALTA/DUPLA: ELEM. DE DRENAGEM",IF(COUNTIF(P11:R11,"X")<>1,"FALTA/DUPLA: SIN. HORIZ.",IF(COUNTIF(S11:U11,"X")<>1,"FALTA/DUPLA: SIN. VERTICAL","OK")))))) -> OK
A12: 070ETO0120 | B12: C | C12: 3 | D12: 4 | E12: =D12-C12 -> 1 | G12: X | K12: X | N12: X | Q12: X | T12: X | W12: =IF(COUNTA(F12:U12)=0,"— não preenchido",IF(COUNTIF(F12:J12,"X")<>1,"FALTA/DUPLA: CONDIÇÃO DO PAVIMENTO",IF(COUNTIF(K12:L12,"X")<>1,"FALTA/DUPLA: VEGETAÇÃO",IF(COUNTIF(M12:O12,"X")<>1,"FALTA/DUPLA: ELEM. DE DRENAGEM",IF(COUNTIF(P12:R12,"X")<>1,"FALTA/DUPLA: SIN. HORIZ.",IF(COUNTIF(S12:U12,"X")<>1,"FALTA/DUPLA: SIN. VERTICAL","OK")))))) -> OK
A13: 070ETO0120 | B13: C | C13: 4 | D13: 5 | E13: =D13-C13 -> 1 | G13: X | K13: X | N13: X | Q13: X | T13: X | W13: =IF(COUNTA(F13:U13)=0,"— não preenchido",IF(COUNTIF(F13:J13,"X")<>1,"FALTA/DUPLA: CONDIÇÃO DO PAVIMENTO",IF(COUNTIF(K13:L13,"X")<>1,"FALTA/DUPLA: VEGETAÇÃO",IF(COUNTIF(M13:O13,"X")<>1,"FALTA/DUPLA: ELEM. DE DRENAGEM",IF(COUNTIF(P13:R13,"X")<>1,"FALTA/DUPLA: SIN. HORIZ.",IF(COUNTIF(S13:U13,"X")<>1,"FALTA/DUPLA: SIN. VERTICAL","OK")))))) -> OK
A14: 070ETO0120 | B14: C | C14: 5 | D14: 6 | E14: =D14-C14 -> 1 | G14: X | K14: X | N14: X | Q14: X | T14: X | W14: =IF(COUNTA(F14:U14)=0,"— não preenchido",IF(COUNTIF(F14:J14,"X")<>1,"FALTA/DUPLA: CONDIÇÃO DO PAVIMENTO",IF(COUNTIF(K14:L14,"X")<>1,"FALTA/DUPLA: VEGETAÇÃO",IF(COUNTIF(M14:O14,"X")<>1,"FALTA/DUPLA: ELEM. DE DRENAGEM",IF(COUNTIF(P14:R14,"X")<>1,"FALTA/DUPLA: SIN. HORIZ.",IF(COUNTIF(S14:U14,"X")<>1,"FALTA/DUPLA: SIN. VERTICAL","OK")))))) -> OK
A15: 070ETO0120 | B15: C | C15: 6 | D15: 7 | E15: =D15-C15 -> 1 | G15: X | K15: X | N15: X | Q15: X | T15: X | W15: =IF(COUNTA(F15:U15)=0,"— não preenchido",IF(COUNTIF(F15:J15,"X")<>1,"FALTA/DUPLA: CONDIÇÃO DO PAVIMENTO",IF(COUNTIF(K15:L15,"X")<>1,"FALTA/DUPLA: VEGETAÇÃO",IF(COUNTIF(M15:O15,"X")<>1,"FALTA/DUPLA: ELEM. DE DRENAGEM",IF(COUNTIF(P15:R15,"X")<>1,"FALTA/DUPLA: SIN. HORIZ.",IF(COUNTIF(S15:U15,"X")<>1,"FALTA/DUPLA: SIN. VERTICAL","OK")))))) -> OK
A16: 070ETO0120 | B16: C | C16: 7 | D16: 8 | E16: =D16-C16 -> 1 | G16: X | K16: X | N16: X | Q16: X | T16: X | W16: =IF(COUNTA(F16:U16)=0,"— não preenchido",IF(COUNTIF(F16:J16,"X")<>1,"FALTA/DUPLA: CONDIÇÃO DO PAVIMENTO",IF(COUNTIF(K16:L16,"X")<>1,"FALTA/DUPLA: VEGETAÇÃO",IF(COUNTIF(M16:O16,"X")<>1,"FALTA/DUPLA: ELEM. DE DRENAGEM",IF(COUNTIF(P16:R16,"X")<>1,"FALTA/DUPLA: SIN. HORIZ.",IF(COUNTIF(S16:U16,"X")<>1,"FALTA/DUPLA: SIN. VERTICAL","OK")))))) -> OK
A17: 070ETO0120 | B17: C | C17: 8 | D17: 9 | E17: =D17-C17 -> 1 | G17: X | K17: X | N17: X | Q17: X | T17: X | W17: =IF(COUNTA(F17:U17)=0,"— não preenchido",IF(COUNTIF(F17:J17,"X")<>1,"FALTA/DUPLA: CONDIÇÃO DO PAVIMENTO",IF(COUNTIF(K17:L17,"X")<>1,"FALTA/DUPLA: VEGETAÇÃO",IF(COUNTIF(M17:O17,"X")<>1,"FALTA/DUPLA: ELEM. DE DRENAGEM",IF(COUNTIF(P17:R17,"X")<>1,"FALTA/DUPLA: SIN. HORIZ.",IF(COUNTIF(S17:U17,"X")<>1,"FALTA/DUPLA: SIN. VERTICAL","OK")))))) -> OK
A18: 070ETO0120 | B18: C | C18: 9 | D18: 10 | E18: =D18-C18 -> 1 | G18: X | K18: X | N18: X | Q18: X | T18: X | W18: =IF(COUNTA(F18:U18)=0,"— não preenchido",IF(COUNTIF(F18:J18,"X")<>1,"FALTA/DUPLA: CONDIÇÃO DO PAVIMENTO",IF(COUNTIF(K18:L18,"X")<>1,"FALTA/DUPLA: VEGETAÇÃO",IF(COUNTIF(M18:O18,"X")<>1,"FALTA/DUPLA: ELEM. DE DRENAGEM",IF(COUNTIF(P18:R18,"X")<>1,"FALTA/DUPLA: SIN. HORIZ.",IF(COUNTIF(S18:U18,"X")<>1,"FALTA/DUPLA: SIN. VERTICAL","OK")))))) -> OK
A19: 070ETO0120 | B19: C | C19: 10 | D19: 11 | E19: =D19-C19 -> 1 | G19: X | K19: X | N19: X | Q19: X | T19: X | W19: =IF(COUNTA(F19:U19)=0,"— não preenchido",IF(COUNTIF(F19:J19,"X")<>1,"FALTA/DUPLA: CONDIÇÃO DO PAVIMENTO",IF(COUNTIF(K19:L19,"X")<>1,"FALTA/DUPLA: VEGETAÇÃO",IF(COUNTIF(M19:O19,"X")<>1,"FALTA/DUPLA: ELEM. DE DRENAGEM",IF(COUNTIF(P19:R19,"X")<>1,"FALTA/DUPLA: SIN. HORIZ.",IF(COUNTIF(S19:U19,"X")<>1,"FALTA/DUPLA: SIN. VERTICAL","OK")))))) -> OK
A20: 070ETO0120 | B20: C | C20: 11 | D20: 12 | E20: =D20-C20 -> 1 | H20: X | K20: X | N20: X | Q20: X | T20: X | W20: =IF(COUNTA(F20:U20)=0,"— não preenchido",IF(COUNTIF(F20:J20,"X")<>1,"FALTA/DUPLA: CONDIÇÃO DO PAVIMENTO",IF(COUNTIF(K20:L20,"X")<>1,"FALTA/DUPLA: VEGETAÇÃO",IF(COUNTIF(M20:O20,"X")<>1,"FALTA/DUPLA: ELEM. DE DRENAGEM",IF(COUNTIF(P20:R20,"X")<>1,"FALTA/DUPLA: SIN. HORIZ.",IF(COUNTIF(S20:U20,"X")<>1,"FALTA/DUPLA: SIN. VERTICAL","OK")))))) -> OK
A21: 070ETO0120 | B21: C | C21: 12 | D21: 13 | E21: =D21-C21 -> 1 | G21: X | K21: X | N21: X | Q21: X | T21: X | W21: =IF(COUNTA(F21:U21)=0,"— não preenchido",IF(COUNTIF(F21:J21,"X")<>1,"FALTA/DUPLA: CONDIÇÃO DO PAVIMENTO",IF(COUNTIF(K21:L21,"X")<>1,"FALTA/DUPLA: VEGETAÇÃO",IF(COUNTIF(M21:O21,"X")<>1,"FALTA/DUPLA: ELEM. DE DRENAGEM",IF(COUNTIF(P21:R21,"X")<>1,"FALTA/DUPLA: SIN. HORIZ.",IF(COUNTIF(S21:U21,"X")<>1,"FALTA/DUPLA: SIN. VERTICAL","OK")))))) -> OK
A22: 070ETO0120 | B22: C | C22: 13 | D22: 14 | E22: =D22-C22 -> 1 | G22: X | K22: X | N22: X | Q22: X | T22: X | W22: =IF(COUNTA(F22:U22)=0,"— não preenchido",IF(COUNTIF(F22:J22,"X")<>1,"FALTA/DUPLA: CONDIÇÃO DO PAVIMENTO",IF(COUNTIF(K22:L22,"X")<>1,"FALTA/DUPLA: VEGETAÇÃO",IF(COUNTIF(M22:O22,"X")<>1,"FALTA/DUPLA: ELEM. DE DRENAGEM",IF(COUNTIF(P22:R22,"X")<>1,"FALTA/DUPLA: SIN. HORIZ.",IF(COUNTIF(S22:U22,"X")<>1,"FALTA/DUPLA: SIN. VERTICAL","OK")))))) -> OK
A23: 070ETO0120 | B23: C | C23: 14 | D23: 15 | E23: =D23-C23 -> 1 | G23: X | K23: X | N23: X | Q23: X | T23: X | W23: =IF(COUNTA(F23:U23)=0,"— não preenchido",IF(COUNTIF(F23:J23,"X")<>1,"FALTA/DUPLA: CONDIÇÃO DO PAVIMENTO",IF(COUNTIF(K23:L23,"X")<>1,"FALTA/DUPLA: VEGETAÇÃO",IF(COUNTIF(M23:O23,"X")<>1,"FALTA/DUPLA: ELEM. DE DRENAGEM",IF(COUNTIF(P23:R23,"X")<>1,"FALTA/DUPLA: SIN. HORIZ.",IF(COUNTIF(S23:U23,"X")<>1,"FALTA/DUPLA: SIN. VERTICAL","OK")))))) -> OK
A24: 070ETO0120 | B24: C | C24: 15 | D24: 16 | E24: =D24-C24 -> 1 | G24: X | K24: X | N24: X | R24: X | T24: X | W24: =IF(COUNTA(F24:U24)=0,"— não preenchido",IF(COUNTIF(F24:J24,"X")<>1,"FALTA/DUPLA: CONDIÇÃO DO PAVIMENTO",IF(COUNTIF(K24:L24,"X")<>1,"FALTA/DUPLA: VEGETAÇÃO",IF(COUNTIF(M24:O24,"X")<>1,"FALTA/DUPLA: ELEM. DE DRENAGEM",IF(COUNTIF(P24:R24,"X")<>1,"FALTA/DUPLA: SIN. HORIZ.",IF(COUNTIF(S24:U24,"X")<>1,"FALTA/DUPLA: SIN. VERTICAL","OK")))))) -> OK
A25: 070ETO0120 | B25: C | C25: 16 | D25: 17 | E25: =D25-C25 -> 1 | G25: X | K25: X | N25: X | Q25: X | T25: X | W25: =IF(COUNTA(F25:U25)=0,"— não preenchido",IF(COUNTIF(F25:J25,"X")<>1,"FALTA/DUPLA: CONDIÇÃO DO PAVIMENTO",IF(COUNTIF(K25:L25,"X")<>1,"FALTA/DUPLA: VEGETAÇÃO",IF(COUNTIF(M25:O25,"X")<>1,"FALTA/DUPLA: ELEM. DE DRENAGEM",IF(COUNTIF(P25:R25,"X")<>1,"FALTA/DUPLA: SIN. HORIZ.",IF(COUNTIF(S25:U25,"X")<>1,"FALTA/DUPLA: SIN. VERTICAL","OK")))))) -> OK
A26: 070ETO0120 | B26: C | C26: 17 | D26: 18 | E26: =D26-C26 -> 1 | G26: X | K26: X | N26: X | Q26: X | T26: X | W26: =IF(COUNTA(F26:U26)=0,"— não preenchido",IF(COUNTIF(F26:J26,"X")<>1,"FALTA/DUPLA: CONDIÇÃO DO PAVIMENTO",IF(COUNTIF(K26:L26,"X")<>1,"FALTA/DUPLA: VEGETAÇÃO",IF(COUNTIF(M26:O26,"X")<>1,"FALTA/DUPLA: ELEM. DE DRENAGEM",IF(COUNTIF(P26:R26,"X")<>1,"FALTA/DUPLA: SIN. HORIZ.",IF(COUNTIF(S26:U26,"X")<>1,"FALTA/DUPLA: SIN. VERTICAL","OK")))))) -> OK
A27: 070ETO0120 | B27: C | C27: 18 | D27: 19 | E27: =D27-C27 -> 1 | G27: X | K27: X | N27: X | Q27: X | T27: X | W27: =IF(COUNTA(F27:U27)=0,"— não preenchido",IF(COUNTIF(F27:J27,"X")<>1,"FALTA/DUPLA: CONDIÇÃO DO PAVIMENTO",IF(COUNTIF(K27:L27,"X")<>1,"FALTA/DUPLA: VEGETAÇÃO",IF(COUNTIF(M27:O27,"X")<>1,"FALTA/DUPLA: ELEM. DE DRENAGEM",IF(COUNTIF(P27:R27,"X")<>1,"FALTA/DUPLA: SIN. HORIZ.",IF(COUNTIF(S27:U27,"X")<>1,"FALTA/DUPLA: SIN. VERTICAL","OK")))))) -> OK
A28: 070ETO0120 | B28: C | C28: 19 | D28: 20 | E28: =D28-C28 -> 1 | G28: X | K28: X | N28: X | Q28: X | T28: X | W28: =IF(COUNTA(F28:U28)=0,"— não preenchido",IF(COUNTIF(F28:J28,"X")<>1,"FALTA/DUPLA: CONDIÇÃO DO PAVIMENTO",IF(COUNTIF(K28:L28,"X")<>1,"FALTA/DUPLA: VEGETAÇÃO",IF(COUNTIF(M28:O28,"X")<>1,"FALTA/DUPLA: ELEM. DE DRENAGEM",IF(COUNTIF(P28:R28,"X")<>1,"FALTA/DUPLA: SIN. HORIZ.",IF(COUNTIF(S28:U28,"X")<>1,"FALTA/DUPLA: SIN. VERTICAL","OK")))))) -> OK
A29: 070ETO0120 | B29: C | C29: 20 | D29: 21 | E29: =D29-C29 -> 1 | G29: X | K29: X | N29: X | Q29: X | T29: X | W29: =IF(COUNTA(F29:U29)=0,"— não preenchido",IF(COUNTIF(F29:J29,"X")<>1,"FALTA/DUPLA: CONDIÇÃO DO PAVIMENTO",IF(COUNTIF(K29:L29,"X")<>1,"FALTA/DUPLA: VEGETAÇÃO",IF(COUNTIF(M29:O29,"X")<>1,"FALTA/DUPLA: ELEM. DE DRENAGEM",IF(COUNTIF(P29:R29,"X")<>1,"FALTA/DUPLA: SIN. HORIZ.",IF(COUNTIF(S29:U29,"X")<>1,"FALTA/DUPLA: SIN. VERTICAL","OK")))))) -> OK
A30: 070ETO0120 | B30: C | C30: 21 | D30: 22 | E30: =D30-C30 -> 1 | G30: X | K30: X | N30: X | Q30: X | T30: X | W30: =IF(COUNTA(F30:U30)=0,"— não preenchido",IF(COUNTIF(F30:J30,"X")<>1,"FALTA/DUPLA: CONDIÇÃO DO PAVIMENTO",IF(COUNTIF(K30:L30,"X")<>1,"FALTA/DUPLA: VEGETAÇÃO",IF(COUNTIF(M30:O30,"X")<>1,"FALTA/DUPLA: ELEM. DE DRENAGEM",IF(COUNTIF(P30:R30,"X")<>1,"FALTA/DUPLA: SIN. HORIZ.",IF(COUNTIF(S30:U30,"X")<>1,"FALTA/DUPLA: SIN. VERTICAL","OK")))))) -> OK
A31: 070ETO0120 | B31: C | C31: 22 | D31: 23 | E31: =D31-C31 -> 1 | H31: X | K31: X | N31: X | Q31: X | T31: X | W31: =IF(COUNTA(F31:U31)=0,"— não preenchido",IF(COUNTIF(F31:J31,"X")<>1,"FALTA/DUPLA: CONDIÇÃO DO PAVIMENTO",IF(COUNTIF(K31:L31,"X")<>1,"FALTA/DUPLA: VEGETAÇÃO",IF(COUNTIF(M31:O31,"X")<>1,"FALTA/DUPLA: ELEM. DE DRENAGEM",IF(COUNTIF(P31:R31,"X")<>1,"FALTA/DUPLA: SIN. HORIZ.",IF(COUNTIF(S31:U31,"X")<>1,"FALTA/DUPLA: SIN. VERTICAL","OK")))))) -> OK
A32: 070ETO0120 | B32: C | C32: 23 | D32: 24 | E32: =D32-C32 -> 1 | G32: X | K32: X | N32: X | Q32: X | T32: X | W32: =IF(COUNTA(F32:U32)=0,"— não preenchido",IF(COUNTIF(F32:J32,"X")<>1,"FALTA/DUPLA: CONDIÇÃO DO PAVIMENTO",IF(COUNTIF(K32:L32,"X")<>1,"FALTA/DUPLA: VEGETAÇÃO",IF(COUNTIF(M32:O32,"X")<>1,"FALTA/DUPLA: ELEM. DE DRENAGEM",IF(COUNTIF(P32:R32,"X")<>1,"FALTA/DUPLA: SIN. HORIZ.",IF(COUNTIF(S32:U32,"X")<>1,"FALTA/DUPLA: SIN. VERTICAL","OK")))))) -> OK
A33: 070ETO0120 | B33: C | C33: 24 | D33: 25 | E33: =D33-C33 -> 1 | G33: X | K33: X | N33: X | Q33: X | T33: X | W33: =IF(COUNTA(F33:U33)=0,"— não preenchido",IF(COUNTIF(F33:J33,"X")<>1,"FALTA/DUPLA: CONDIÇÃO DO PAVIMENTO",IF(COUNTIF(K33:L33,"X")<>1,"FALTA/DUPLA: VEGETAÇÃO",IF(COUNTIF(M33:O33,"X")<>1,"FALTA/DUPLA: ELEM. DE DRENAGEM",IF(COUNTIF(P33:R33,"X")<>1,"FALTA/DUPLA: SIN. HORIZ.",IF(COUNTIF(S33:U33,"X")<>1,"FALTA/DUPLA: SIN. VERTICAL","OK")))))) -> OK
A34: 070ETO0120 | B34: C | C34: 25 | D34: 26 | E34: =D34-C34 -> 1 | G34: X | K34: X | N34: X | Q34: X | T34: X | W34: =IF(COUNTA(F34:U34)=0,"— não preenchido",IF(COUNTIF(F34:J34,"X")<>1,"FALTA/DUPLA: CONDIÇÃO DO PAVIMENTO",IF(COUNTIF(K34:L34,"X")<>1,"FALTA/DUPLA: VEGETAÇÃO",IF(COUNTIF(M34:O34,"X")<>1,"FALTA/DUPLA: ELEM. DE DRENAGEM",IF(COUNTIF(P34:R34,"X")<>1,"FALTA/DUPLA: SIN. HORIZ.",IF(COUNTIF(S34:U34,"X")<>1,"FALTA/DUPLA: SIN. VERTICAL","OK")))))) -> OK
A35: 070ETO0120 | B35: C | C35: 26 | D35: 27 | E35: =D35-C35 -> 1 | G35: X | K35: X | N35: X | Q35: X | T35: X | W35: =IF(COUNTA(F35:U35)=0,"— não preenchido",IF(COUNTIF(F35:J35,"X")<>1,"FALTA/DUPLA: CONDIÇÃO DO PAVIMENTO",IF(COUNTIF(K35:L35,"X")<>1,"FALTA/DUPLA: VEGETAÇÃO",IF(COUNTIF(M35:O35,"X")<>1,"FALTA/DUPLA: ELEM. DE DRENAGEM",IF(COUNTIF(P35:R35,"X")<>1,"FALTA/DUPLA: SIN. HORIZ.",IF(COUNTIF(S35:U35,"X")<>1,"FALTA/DUPLA: SIN. VERTICAL","OK")))))) -> OK
A36: 070ETO0120 | B36: C | C36: 27 | D36: 28 | E36: =D36-C36 -> 1 | G36: X | K36: X | N36: X | Q36: X | T36: X | W36: =IF(COUNTA(F36:U36)=0,"— não preenchido",IF(COUNTIF(F36:J36,"X")<>1,"FALTA/DUPLA: CONDIÇÃO DO PAVIMENTO",IF(COUNTIF(K36:L36,"X")<>1,"FALTA/DUPLA: VEGETAÇÃO",IF(COUNTIF(M36:O36,"X")<>1,"FALTA/DUPLA: ELEM. DE DRENAGEM",IF(COUNTIF(P36:R36,"X")<>1,"FALTA/DUPLA: SIN. HORIZ.",IF(COUNTIF(S36:U36,"X")<>1,"FALTA/DUPLA: SIN. VERTICAL","OK")))))) -> OK
A37: 070ETO0120 | B37: C | C37: 28 | D37: 29 | E37: =D37-C37 -> 1 | G37: X | K37: X | N37: X | Q37: X | T37: X | W37: =IF(COUNTA(F37:U37)=0,"— não preenchido",IF(COUNTIF(F37:J37,"X")<>1,"FALTA/DUPLA: CONDIÇÃO DO PAVIMENTO",IF(COUNTIF(K37:L37,"X")<>1,"FALTA/DUPLA: VEGETAÇÃO",IF(COUNTIF(M37:O37,"X")<>1,"FALTA/DUPLA: ELEM. DE DRENAGEM",IF(COUNTIF(P37:R37,"X")<>1,"FALTA/DUPLA: SIN. HORIZ.",IF(COUNTIF(S37:U37,"X")<>1,"FALTA/DUPLA: SIN. VERTICAL","OK")))))) -> OK
A38: 070ETO0120 | B38: C | C38: 29 | D38: 30 | E38: =D38-C38 -> 1 | G38: X | K38: X | N38: X | Q38: X | T38: X | W38: =IF(COUNTA(F38:U38)=0,"— não preenchido",IF(COUNTIF(F38:J38,"X")<>1,"FALTA/DUPLA: CONDIÇÃO DO PAVIMENTO",IF(COUNTIF(K38:L38,"X")<>1,"FALTA/DUPLA: VEGETAÇÃO",IF(COUNTIF(M38:O38,"X")<>1,"FALTA/DUPLA: ELEM. DE DRENAGEM",IF(COUNTIF(P38:R38,"X")<>1,"FALTA/DUPLA: SIN. HORIZ.",IF(COUNTIF(S38:U38,"X")<>1,"FALTA/DUPLA: SIN. VERTICAL","OK")))))) -> OK
A39: 070ETO0120 | B39: C | C39: 30 | D39: 31 | E39: =D39-C39 -> 1 | G39: X | K39: X | N39: X | Q39: X | T39: X | W39: =IF(COUNTA(F39:U39)=0,"— não preenchido",IF(COUNTIF(F39:J39,"X")<>1,"FALTA/DUPLA: CONDIÇÃO DO PAVIMENTO",IF(COUNTIF(K39:L39,"X")<>1,"FALTA/DUPLA: VEGETAÇÃO",IF(COUNTIF(M39:O39,"X")<>1,"FALTA/DUPLA: ELEM. DE DRENAGEM",IF(COUNTIF(P39:R39,"X")<>1,"FALTA/DUPLA: SIN. HORIZ.",IF(COUNTIF(S39:U39,"X")<>1,"FALTA/DUPLA: SIN. VERTICAL","OK")))))) -> OK
A40: 070ETO0120 | B40: C | C40: 31 | D40: 32 | E40: =D40-C40 -> 1 | G40: X | K40: X | N40: X | Q40: X | T40: X | W40: =IF(COUNTA(F40:U40)=0,"— não preenchido",IF(COUNTIF(F40:J40,"X")<>1,"FALTA/DUPLA: CONDIÇÃO DO PAVIMENTO",IF(COUNTIF(K40:L40,"X")<>1,"FALTA/DUPLA: VEGETAÇÃO",IF(COUNTIF(M40:O40,"X")<>1,"FALTA/DUPLA: ELEM. DE DRENAGEM",IF(COUNTIF(P40:R40,"X")<>1,"FALTA/DUPLA: SIN. HORIZ.",IF(COUNTIF(S40:U40,"X")<>1,"FALTA/DUPLA: SIN. VERTICAL","OK")))))) -> OK
A41: 070ETO0120 | B41: C | C41: 32 | D41: 33 | E41: =D41-C41 -> 1 | G41: X | K41: X | N41: X | Q41: X | T41: X | W41: =IF(COUNTA(F41:U41)=0,"— não preenchido",IF(COUNTIF(F41:J41,"X")<>1,"FALTA/DUPLA: CONDIÇÃO DO PAVIMENTO",IF(COUNTIF(K41:L41,"X")<>1,"FALTA/DUPLA: VEGETAÇÃO",IF(COUNTIF(M41:O41,"X")<>1,"FALTA/DUPLA: ELEM. DE DRENAGEM",IF(COUNTIF(P41:R41,"X")<>1,"FALTA/DUPLA: SIN. HORIZ.",IF(COUNTIF(S41:U41,"X")<>1,"FALTA/DUPLA: SIN. VERTICAL","OK")))))) -> OK
...

Sheet 205
A1: PROGRAMA DE MANUTENÇÃO RODOVIÁRIA — FICHA DE INSPEÇÃO — RODOVIAS PAVIMENTADAS | Y1: Valores dos gráficos — troca 0 por N/D para a fatia não aparecer. Não editar.
A2: REGIÃO: 11 — GURUPI | G2: MÊS / ANO: | I2: 46266 | K2: DATA: | P2: TÉCNICO: | R2: ENG. THIAGO BORGES TORQUATO | Y2: =IF(F64=0,NA(),F64) -> 27.836116 | Z2: =IF(G64=0,NA(),G64) -> 9 | AA2: =IF(H64=0,NA(),H64) -> 10 | AB2: =IF(I64=0,NA(),I64) -> #N/A | AC2: =IF(J64=0,NA(),J64) -> #N/A | AD2: =IF(K64=0,NA(),K64) -> 46.836116 | AE2: =IF(L64=0,NA(),L64) -> #N/A | AF2: =IF(M64=0,NA(),M64) -> #N/A | ... AN2: =IF(U64=0,NA(),U64) -> #N/A
A3: TRECHO 205 — RODOVIA TO-070 - TRECHO DUERÉ - ALIANÇA DO TOCANTINS | T3: EXTENSÃO: 46,836 km · 3 S.R.E.
A4: COMO PREENCHER: uma X em UMA coluna de cada grupo, por linha. Se houver mais de um defeito no mesmo km, marque o PREDOMINANTE e escreva o resto em OBSERVAÇÕES. A quilometragem é contada de 0 até o fim de CADA S.R.E. (não é o marco da rodovia).
A6: S.R.E. | B6: SENT. | C6: INÍCIO (KM) | D6: FIM (KM) | E6: EXT. (KM) | F6: CONDIÇÃO DO PAVIMENTO | K6: VEGETAÇÃO | M6: ELEM. DE DRENAGEM | P6: SIN. HORIZ. | S6: SIN. VERTICAL | V6: OBSERVAÇÕES | W6: CONFERÊNCIA (só na tela)
F7: BOM | G7: REM. I. | H7: REM. L. | I7: BUR. I. | J7: BUR. L. | K7: ADEQ. | L7: INAD. | M7: LIMPOS | N7: SUJOS | O7: DAN. | P7: BOM | Q7: REG. | R7: INEXIST. | S7: BOM | T7: POUCAS | U7: INEXIST.
A8: S.R.E. 070ETO0140 | ENTR. BR-153 (B) - ENTR. TO-164 | PPS · Estadual · 26.907 km · início: -11.297987, -48.939857
A9: 070ETO0140 | B9: C | C9: 0 | D9: 1 | E9: =D9-C9 -> 1 | F9: X | K9: X | N9: X | P9: X | T9: X | W9: =IF(COUNTA(F9:U9)=0,"— não preenchido",IF(COUNTIF(F9:J9,"X")<>1,"FALTA/DUPLA: CONDIÇÃO DO PAVIMENTO",IF(COUNTIF(K9:L9,"X")<>1,"FALTA/DUPLA: VEGETAÇÃO",IF(COUNTIF(M9:O9,"X")<>1,"FALTA/DUPLA: ELEM. DE DRENAGEM",IF(COUNTIF(P9:R9,"X")<>1,"FALTA/DUPLA: SIN. HORIZ.",IF(COUNTIF(S9:U9,"X")<>1,"FALTA/DUPLA: SIN. VERTICAL","OK")))))) -> OK
A10: 070ETO0140 | B10: C | C10: 1 | D10: 2 | E10: =D10-C10 -> 1 | F10: X | K10: X | N10: X | P10: X | T10: X | W10: =IF(COUNTA(F10:U10)=0,"— não preenchido",IF(COUNTIF(F10:J10,"X")<>1,"FALTA/DUPLA: CONDIÇÃO DO PAVIMENTO",IF(COUNTIF(K10:L10,"X")<>1,"FALTA/DUPLA: VEGETAÇÃO",IF(COUNTIF(M10:O10,"X")<>1,"FALTA/DUPLA: ELEM. DE DRENAGEM",IF(COUNTIF(P10:R10,"X")<>1,"FALTA/DUPLA: SIN. HORIZ.",IF(COUNTIF(S10:U10,"X")<>1,"FALTA/DUPLA: SIN. VERTICAL","OK")))))) -> OK
A11: 070ETO0140 | B11: C | C11: 2 | D11: 3 | E11: =D11-C11 -> 1 | F11: X | K11: X | N11: X | P11: X | T11: X | W11: =IF(COUNTA(F11:U11)=0,"— não preenchido",IF(COUNTIF(F11:J11,"X")<>1,"FALTA/DUPLA: CONDIÇÃO DO PAVIMENTO",IF(COUNTIF(K11:L11,"X")<>1,"FALTA/DUPLA: VEGETAÇÃO",IF(COUNTIF(M11:O11,"X")<>1,"FALTA/DUPLA: ELEM. DE DRENAGEM",IF(COUNTIF(P11:R11,"X")<>1,"FALTA/DUPLA: SIN. HORIZ.",IF(COUNTIF(S11:U11,"X")<>1,"FALTA/DUPLA: SIN. VERTICAL","OK")))))) -> OK
A12: 070ETO0140 | B12: C | C12: 3 | D12: 4 | E12: =D12-C12 -> 1 | F12: X | K12: X | N12: X | P12: X | T12: X | W12: =IF(COUNTA(F12:U12)=0,"— não preenchido",IF(COUNTIF(F12:J12,"X")<>1,"FALTA/DUPLA: CONDIÇÃO DO PAVIMENTO",IF(COUNTIF(K12:L12,"X")<>1,"FALTA/DUPLA: VEGETAÇÃO",IF(COUNTIF(M12:O12,"X")<>1,"FALTA/DUPLA: ELEM. DE DRENAGEM",IF(COUNTIF(P12:R12,"X")<>1,"FALTA/DUPLA: SIN. HORIZ.",IF(COUNTIF(S12:U12,"X")<>1,"FALTA/DUPLA: SIN. VERTICAL","OK")))))) -> OK
A13: 070ETO0140 | B13: C | C13: 4 | D13: 5 | E13: =D13-C13 -> 1 | F13: X | K13: X | N13: X | P13: X | T13: X | W13: =IF(COUNTA(F13:U13)=0,"— não preenchido",IF(COUNTIF(F13:J13,"X")<>1,"FALTA/DUPLA: CONDIÇÃO DO PAVIMENTO",IF(COUNTIF(K13:L13,"X")<>1,"FALTA/DUPLA: VEGETAÇÃO",IF(COUNTIF(M13:O13,"X")<>1,"FALTA/DUPLA: ELEM. DE DRENAGEM",IF(COUNTIF(P13:R13,"X")<>1,"FALTA/DUPLA: SIN. HORIZ.",IF(COUNTIF(S13:U13,"X")<>1,"FALTA/DUPLA: SIN. VERTICAL","OK")))))) -> OK
A14: 070ETO0140 | B14: C | C14: 5 | D14: 6 | E14: =D14-C14 -> 1 | F14: X | K14: X | N14: X | P14: X | T14: X | W14: =IF(COUNTA(F14:U14)=0,"— não preenchido",IF(COUNTIF(F14:J14,"X")<>1,"FALTA/DUPLA: CONDIÇÃO DO PAVIMENTO",IF(COUNTIF(K14:L14,"X")<>1,"FALTA/DUPLA: VEGETAÇÃO",IF(COUNTIF(M14:O14,"X")<>1,"FALTA/DUPLA: ELEM. DE DRENAGEM",IF(COUNTIF(P14:R14,"X")<>1,"FALTA/DUPLA: SIN. HORIZ.",IF(COUNTIF(S14:U14,"X")<>1,"FALTA/DUPLA: SIN. VERTICAL","OK")))))) -> OK
A15: 070ETO0140 | B15: C | C15: 6 | D15: 7 | E15: =D15-C15 -> 1 | F15: X | K15: X | N15: X | P15: X | T15: X | W15: =IF(COUNTA(F15:U15)=0,"— não preenchido",IF(COUNTIF(F15:J15,"X")<>1,"FALTA/DUPLA: CONDIÇÃO DO PAVIMENTO",IF(COUNTIF(K15:L15,"X")<>1,"FALTA/DUPLA: VEGETAÇÃO",IF(COUNTIF(M15:O15,"X")<>1,"FALTA/DUPLA: ELEM. DE DRENAGEM",IF(COUNTIF(P15:R15,"X")<>1,"FALTA/DUPLA: SIN. HORIZ.",IF(COUNTIF(S15:U15,"X")<>1,"FALTA/DUPLA: SIN. VERTICAL","OK")))))) -> OK
A16: 070ETO0140 | B16: C | C16: 7 | D16: 8 | E16: =D16-C16 -> 1 | H16: X | K16: X | N16: X | P16: X | T16: X | W16: =IF(COUNTA(F16:U16)=0,"— não preenchido",IF(COUNTIF(F16:J16,"X")<>1,"FALTA/DUPLA: CONDIÇÃO DO PAVIMENTO",IF(COUNTIF(K16:L16,"X")<>1,"FALTA/DUPLA: VEGETAÇÃO",IF(COUNTIF(M16:O16,"X")<>1,"FALTA/DUPLA: ELEM. DE DRENAGEM",IF(COUNTIF(P16:R16,"X")<>1,"FALTA/DUPLA: SIN. HORIZ.",IF(COUNTIF(S16:U16,"X")<>1,"FALTA/DUPLA: SIN. VERTICAL","OK")))))) -> OK
A17: 070ETO0140 | B17: C | C17: 8 | D17: 9 | E17: =D17-C17 -> 1 | H17: X | K17: X | N17: X | P17: X | T17: X | W17: =IF(COUNTA(F17:U17)=0,"— não preenchido",IF(COUNTIF(F17:J17,"X")<>1,"FALTA/DUPLA: CONDIÇÃO DO PAVIMENTO",IF(COUNTIF(K17:L17,"X")<>1,"FALTA/DUPLA: VEGETAÇÃO",IF(COUNTIF(M17:O17,"X")<>1,"FALTA/DUPLA: ELEM. DE DRENAGEM",IF(COUNTIF(P17:R17,"X")<>1,"FALTA/DUPLA: SIN. HORIZ.",IF(COUNTIF(S17:U17,"X")<>1,"FALTA/DUPLA: SIN. VERTICAL","OK")))))) -> OK
A18: 070ETO0140 | B18: C | C18: 9 | D18: 10 | E18: =D18-C18 -> 1 | H18: X | K18: X | N18: X | P18: X | T18: X | W18: =IF(COUNTA(F18:U18)=0,"— não preenchido",IF(COUNTIF(F18:J18,"X")<>1,"FALTA/DUPLA: CONDIÇÃO DO PAVIMENTO",IF(COUNTIF(K18:L18,"X")<>1,"FALTA/DUPLA: VEGETAÇÃO",IF(COUNTIF(M18:O18,"X")<>1,"FALTA/DUPLA: ELEM. DE DRENAGEM",IF(COUNTIF(P18:R18,"X")<>1,"FALTA/DUPLA: SIN. HORIZ.",IF(COUNTIF(S18:U18,"X")<>1,"FALTA/DUPLA: SIN. VERTICAL","OK")))))) -> OK
A19: 070ETO0140 | B19: C | C19: 10 | D19: 11 | E19: =D19-C19 -> 1 | H19: X | K19: X | N19: X | P19: X | T19: X | W19: =IF(COUNTA(F19:U19)=0,"— não preenchido",IF(COUNTIF(F19:J19,"X")<>1,"FALTA/DUPLA: CONDIÇÃO DO PAVIMENTO",IF(COUNTIF(K19:L19,"X")<>1,"FALTA/DUPLA: VEGETAÇÃO",IF(COUNTIF(M19:O19,"X")<>1,"FALTA/DUPLA: ELEM. DE DRENAGEM",IF(COUNTIF(P19:R19,"X")<>1,"FALTA/DUPLA: SIN. HORIZ.",IF(COUNTIF(S19:U19,"X")<>1,"FALTA/DUPLA: SIN. VERTICAL","OK")))))) -> OK
A20: 070ETO0140 | B20: C | C20: 11 | D20: 12 | E20: =D20-C20 -> 1 | H20: X | K20: X | N20: X | P20: X | T20: X | W20: =IF(COUNTA(F20:U20)=0,"— não preenchido",IF(COUNTIF(F20:J20,"X")<>1,"FALTA/DUPLA: CONDIÇÃO DO PAVIMENTO",IF(COUNTIF(K20:L20,"X")<>1,"FALTA/DUPLA: VEGETAÇÃO",IF(COUNTIF(M20:O20,"X")<>1,"FALTA/DUPLA: ELEM. DE DRENAGEM",IF(COUNTIF(P20:R20,"X")<>1,"FALTA/DUPLA: SIN. HORIZ.",IF(COUNTIF(S20:U20,"X")<>1,"FALTA/DUPLA: SIN. VERTICAL","OK")))))) -> OK
A21: 070ETO0140 | B21: C | C21: 12 | D21: 13 | E21: =D21-C21 -> 1 | H21: X | K21: X | N21: X | P21: X | T21: X | W21: =IF(COUNTA(F21:U21)=0,"— não preenchido",IF(COUNTIF(F21:J21,"X")<>1,"FALTA/DUPLA: CONDIÇÃO DO PAVIMENTO",IF(COUNTIF(K21:L21,"X")<>1,"FALTA/DUPLA: VEGETAÇÃO",IF(COUNTIF(M21:O21,"X")<>1,"FALTA/DUPLA: ELEM. DE DRENAGEM",IF(COUNTIF(P21:R21,"X")<>1,"FALTA/DUPLA: SIN. HORIZ.",IF(COUNTIF(S21:U21,"X")<>1,"FALTA/DUPLA: SIN. VERTICAL","OK")))))) -> OK
A22: 070ETO0140 | B22: C | C22: 13 | D22: 14 | E22: =D22-C22 -> 1 | H22: X | K22: X | N22: X | P22: X | T22: X | W22: =IF(COUNTA(F22:U22)=0,"— não preenchido",IF(COUNTIF(F22:J22,"X")<>1,"FALTA/DUPLA: CONDIÇÃO DO PAVIMENTO",IF(COUNTIF(K22:L22,"X")<>1,"FALTA/DUPLA: VEGETAÇÃO",IF(COUNTIF(M22:O22,"X")<>1,"FALTA/DUPLA: ELEM. DE DRENAGEM",IF(COUNTIF(P22:R22,"X")<>1,"FALTA/DUPLA: SIN. HORIZ.",IF(COUNTIF(S22:U22,"X")<>1,"FALTA/DUPLA: SIN. VERTICAL","OK")))))) -> OK
A23: 070ETO0140 | B23: C | C23: 14 | D23: 15 | E23: =D23-C23 -> 1 | H23: X | K23: X | N23: X | P23: X | T23: X | W23: =IF(COUNTA(F23:U23)=0,"— não preenchido",IF(COUNTIF(F23:J23,"X")<>1,"FALTA/DUPLA: CONDIÇÃO DO PAVIMENTO",IF(COUNTIF(K23:L23,"X")<>1,"FALTA/DUPLA: VEGETAÇÃO",IF(COUNTIF(M23:O23,"X")<>1,"FALTA/DUPLA: ELEM. DE DRENAGEM",IF(COUNTIF(P23:R23,"X")<>1,"FALTA/DUPLA: SIN. HORIZ.",IF(COUNTIF(S23:U23,"X")<>1,"FALTA/DUPLA: SIN. VERTICAL","OK")))))) -> OK
A24: 070ETO0140 | B24: C | C24: 15 | D24: 16 | E24: =D24-C24 -> 1 | H24: X | K24: X | N24: X | P24: X | T24: X | W24: =IF(COUNTA(F24:U24)=0,"— não preenchido",IF(COUNTIF(F24:J24,"X")<>1,"FALTA/DUPLA: CONDIÇÃO DO PAVIMENTO",IF(COUNTIF(K24:L24,"X")<>1,"FALTA/DUPLA: VEGETAÇÃO",IF(COUNTIF(M24:O24,"X")<>1,"FALTA/DUPLA: ELEM. DE DRENAGEM",IF(COUNTIF(P24:R24,"X")<>1,"FALTA/DUPLA: SIN. HORIZ.",IF(COUNTIF(S24:U24,"X")<>1,"FALTA/DUPLA: SIN. VERTICAL","OK")))))) -> OK
A25: 070ETO0140 | B25: C | C25: 16 | D25: 17 | E25: =D25-C25 -> 1 | F25: X | K25: X | N25: X | P25: X | T25: X | W25: =IF(COUNTA(F25:U25)=0,"— não preenchido",IF(COUNTIF(F25:J25,"X")<>1,"FALTA/DUPLA: CONDIÇÃO DO PAVIMENTO",IF(COUNTIF(K25:L25,"X")<>1,"FALTA/DUPLA: VEGETAÇÃO",IF(COUNTIF(M25:O25,"X")<>1,"FALTA/DUPLA: ELEM. DE DRENAGEM",IF(COUNTIF(P25:R25,"X")<>1,"FALTA/DUPLA: SIN. HORIZ.",IF(COUNTIF(S25:U25,"X")<>1,"FALTA/DUPLA: SIN. VERTICAL","OK")))))) -> OK
A26: 070ETO0140 | B26: C | C26: 17 | D26: 18 | E26: =D26-C26 -> 1 | F26: X | K26: X | N26: X | P26: X | T26: X | W26: =IF(COUNTA(F26:U26)=0,"— não preenchido",IF(COUNTIF(F26:J26,"X")<>1,"FALTA/DUPLA: CONDIÇÃO DO PAVIMENTO",IF(COUNTIF(K26:L26,"X")<>1,"FALTA/DUPLA: VEGETAÇÃO",IF(COUNTIF(M26:O26,"X")<>1,"FALTA/DUPLA: ELEM. DE DRENAGEM",IF(COUNTIF(P26:R26,"X")<>1,"FALTA/DUPLA: SIN. HORIZ.",IF(COUNTIF(S26:U26,"X")<>1,"FALTA/DUPLA: SIN. VERTICAL","OK")))))) -> OK
A27: 070ETO0140 | B27: C | C27: 18 | D27: 19 | E27: =D27-C27 -> 1 | F27: X | K27: X | N27: X | P27: X | T27: X | W27: =IF(COUNTA(F27:U27)=0,"— não preenchido",IF(COUNTIF(F27:J27,"X")<>1,"FALTA/DUPLA: CONDIÇÃO DO PAVIMENTO",IF(COUNTIF(K27:L27,"X")<>1,"FALTA/DUPLA: VEGETAÇÃO",IF(COUNTIF(M27:O27,"X")<>1,"FALTA/DUPLA: ELEM. DE DRENAGEM",IF(COUNTIF(P27:R27,"X")<>1,"FALTA/DUPLA: SIN. HORIZ.",IF(COUNTIF(S27:U27,"X")<>1,"FALTA/DUPLA: SIN. VERTICAL","OK")))))) -> OK
A28: 070ETO0140 | B28: C | C28: 19 | D28: 20 | E28: =D28-C28 -> 1 | F28: X | K28: X | N28: X | P28: X | T28: X | W28: =IF(COUNTA(F28:U28)=0,"— não preenchido",IF(COUNTIF(F28:J28,"X")<>1,"FALTA/DUPLA: CONDIÇÃO DO PAVIMENTO",IF(COUNTIF(K28:L28,"X")<>1,"FALTA/DUPLA: VEGETAÇÃO",IF(COUNTIF(M28:O28,"X")<>1,"FALTA/DUPLA: ELEM. DE DRENAGEM",IF(COUNTIF(P28:R28,"X")<>1,"FALTA/DUPLA: SIN. HORIZ.",IF(COUNTIF(S28:U28,"X")<>1,"FALTA/DUPLA: SIN. VERTICAL","OK")))))) -> OK
A29: 070ETO0140 | B29: C | C29: 20 | D29: 21 | E29: =D29-C29 -> 1 | F29: X | K29: X | N29: X | P29: X | T29: X | W29: =IF(COUNTA(F29:U29)=0,"— não preenchido",IF(COUNTIF(F29:J29,"X")<>1,"FALTA/DUPLA: CONDIÇÃO DO PAVIMENTO",IF(COUNTIF(K29:L29,"X")<>1,"FALTA/DUPLA: VEGETAÇÃO",IF(COUNTIF(M29:O29,"X")<>1,"FALTA/DUPLA: ELEM. DE DRENAGEM",IF(COUNTIF(P29:R29,"X")<>1,"FALTA/DUPLA: SIN. HORIZ.",IF(COUNTIF(S29:U29,"X")<>1,"FALTA/DUPLA: SIN. VERTICAL","OK")))))) -> OK
A30: 070ETO0140 | B30: C | C30: 21 | D30: 22 | E30: =D30-C30 -> 1 | F30: X | K30: X | N30: X | P30: X | T30: X | W30: =IF(COUNTA(F30:U30)=0,"— não preenchido",IF(COUNTIF(F30:J30,"X")<>1,"FALTA/DUPLA: CONDIÇÃO DO PAVIMENTO",IF(COUNTIF(K30:L30,"X")<>1,"FALTA/DUPLA: VEGETAÇÃO",IF(COUNTIF(M30:O30,"X")<>1,"FALTA/DUPLA: ELEM. DE DRENAGEM",IF(COUNTIF(P30:R30,"X")<>1,"FALTA/DUPLA: SIN. HORIZ.",IF(COUNTIF(S30:U30,"X")<>1,"FALTA/DUPLA: SIN. VERTICAL","OK")))))) -> OK
A31: 070ETO0140 | B31: C | C31: 22 | D31: 23 | E31: =D31-C31 -> 1 | F31: X | K31: X | N31: X | P31: X | T31: X | W31: =IF(COUNTA(F31:U31)=0,"— não preenchido",IF(COUNTIF(F31:J31,"X")<>1,"FALTA/DUPLA: CONDIÇÃO DO PAVIMENTO",IF(COUNTIF(K31:L31,"X")<>1,"FALTA/DUPLA: VEGETAÇÃO",IF(COUNTIF(M31:O31,"X")<>1,"FALTA/DUPLA: ELEM. DE DRENAGEM",IF(COUNTIF(P31:R31,"X")<>1,"FALTA/DUPLA: SIN. HORIZ.",IF(COUNTIF(S31:U31,"X")<>1,"FALTA/DUPLA: SIN. VERTICAL","OK")))))) -> OK
A32: 070ETO0140 | B32: C | C32: 23 | D32: 24 | E32: =D32-C32 -> 1 | F32: X | K32: X | N32: X | P32: X | T32: X | W32: =IF(COUNTA(F32:U32)=0,"— não preenchido",IF(COUNTIF(F32:J32,"X")<>1,"FALTA/DUPLA: CONDIÇÃO DO PAVIMENTO",IF(COUNTIF(K32:L32,"X")<>1,"FALTA/DUPLA: VEGETAÇÃO",IF(COUNTIF(M32:O32,"X")<>1,"FALTA/DUPLA: ELEM. DE DRENAGEM",IF(COUNTIF(P32:R32,"X")<>1,"FALTA/DUPLA: SIN. HORIZ.",IF(COUNTIF(S32:U32,"X")<>1,"FALTA/DUPLA: SIN. VERTICAL","OK")))))) -> OK
A33: 070ETO0140 | B33: C | C33: 24 | D33: 25 | E33: =D33-C33 -> 1 | F33: X | K33: X | N33: X | P33: X | T33: X | W33: =IF(COUNTA(F33:U33)=0,"— não preenchido",IF(COUNTIF(F33:J33,"X")<>1,"FALTA/DUPLA: CONDIÇÃO DO PAVIMENTO",IF(COUNTIF(K33:L33,"X")<>1,"FALTA/DUPLA: VEGETAÇÃO",IF(COUNTIF(M33:O33,"X")<>1,"FALTA/DUPLA: ELEM. DE DRENAGEM",IF(COUNTIF(P33:R33,"X")<>1,"FALTA/DUPLA: SIN. HORIZ.",IF(COUNTIF(S33:U33,"X")<>1,"FALTA/DUPLA: SIN. VERTICAL","OK")))))) -> OK
A34: 070ETO0140 | B34: C | C34: 25 | D34: 26 | E34: =D34-C34 -> 1 | F34: X | K34: X | N34: X | P34: X | T34: X | W34: =IF(COUNTA(F34:U34)=0,"— não preenchido",IF(COUNTIF(F34:J34,"X")<>1,"FALTA/DUPLA: CONDIÇÃO DO PAVIMENTO",IF(COUNTIF(K34:L34,"X")<>1,"FALTA/DUPLA: VEGETAÇÃO",IF(COUNTIF(M34:O34,"X")<>1,"FALTA/DUPLA: ELEM. DE DRENAGEM",IF(COUNTIF(P34:R34,"X")<>1,"FALTA/DUPLA: SIN. HORIZ.",IF(COUNTIF(S34:U34,"X")<>1,"FALTA/DUPLA: SIN. VERTICAL","OK")))))) -> OK
