Workbook

Sheet RESUMO
A1: RESUMO CONSOLIDADO — REGIÃO 1 — RODOVIAS PAVIMENTADAS | V1: Valores dos gráficos — troca 0 por N/D para a fatia não aparecer. Não editar.
A2: Todos os números vêm das abas dos trechos por referência direta. Não digite nada aqui. A coluna CONFERÊNCIA acusa qualquer trecho em que a soma das marcações não fecha com a extensão. | V2: =IF(D19=0,NA(),D19) -> 72.925619 | W2: =IF(E19=0,NA(),E19) -> 290.6705 | X2: =IF(F19=0,NA(),F19) -> 162.832 | Y2: =IF(G19=0,NA(),G19) -> 3 | Z2: =IF(H19=0,NA(),H19) -> 11 | AA2: =IF(I19=0,NA(),I19) -> 385.16008 | AB2: =IF(J19=0,NA(),J19) -> 154.26804 | AC2: =IF(K19=0,NA(),K19) -> 46.884434 | ... AK2: =IF(S19=0,NA(),S19) -> #N/A
A4: Nº TRECHO | B4: TRECHO | C4: EXTENSÃO (KM) | D4: CONDIÇÃO DO PAVIMENTO | I4: VEGETAÇÃO | K4: ELEM. DE DRENAGEM | N4: SIN. HORIZ. | Q4: SIN. VERTICAL | T4: CONFERÊNCIA
D5: BOM | E5: REM. I. | F5: REM. L. | G5: BUR. I. | H5: BUR. L. | I5: ADEQ. | J5: INAD. | K5: LIMP. | L5: SUJO | M5: DANIF. | N5: BOM | O5: REG. | P5: INEX. | Q5: BOM | R5: POUC. | S5: INEX.
A6: 224 | B6: RODOVIA TO-141 - TRECHO PALMEIRÓPOLIS - DIVISA TO-GO | C6: ='224'!R44 -> 26.24 | D6: ='224'!F41 -> 13 | E6: ='224'!G41 -> 8.24 | F6: ='224'!H41 -> 5 | G6: ='224'!I41 -> 0 | H6: ='224'!J41 -> 0 | I6: ='224'!K41 -> 26.24 | J6: ='224'!L41 -> 0 | K6: ='224'!M41 -> 0 | ... S6: ='224'!U41 -> 0 | T6: =IF(SUM(D6:H6)=0,"— não preenchido",IF(ROUND(SUM(D6:H6)-C6,3)=0,"OK","ERRO — dif. de "&ROUND(SUM(D6:H6)-C6,3)&" km")) -> OK
A7: 225 | B7: RODOVIA TO-280 - TRECHO NATIVIDADE - ALMAS | C7: ='225'!R94 -> 76.27813 | D7: ='225'!F91 -> 0 | E7: ='225'!G91 -> 19 | F7: ='225'!H91 -> 57.27813 | G7: ='225'!I91 -> 0 | H7: ='225'!J91 -> 0 | I7: ='225'!K91 -> 76.27813 | J7: ='225'!L91 -> 0 | K7: ='225'!M91 -> 6 | ... S7: ='225'!U91 -> 0 | T7: =IF(SUM(D7:H7)=0,"— não preenchido",IF(ROUND(SUM(D7:H7)-C7,3)=0,"OK","ERRO — dif. de "&ROUND(SUM(D7:H7)-C7,3)&" km")) -> OK
A8: 226 | B8: RODOVIA TO-280 - TRECHO SÃO VALÉRIO DE NATIVIDADE - NATIVIDADE | C8: ='226'!R85 -> 65.030612 | D8: ='226'!F82 -> 0 | E8: ='226'!G82 -> 27.103955 | F8: ='226'!H82 -> 37.926658 | G8: ='226'!I82 -> 0 | H8: ='226'!J82 -> 0 | I8: ='226'!K82 -> 65.030612 | J8: ='226'!L82 -> 0 | K8: ='226'!M82 -> 13.591541 | ... S8: ='226'!U82 -> 0 | T8: =IF(SUM(D8:H8)=0,"— não preenchido",IF(ROUND(SUM(D8:H8)-C8,3)=0,"OK","ERRO — dif. de "&ROUND(SUM(D8:H8)-C8,3)&" km")) -> OK
A9: 227 | B9: RODOVIA TO-280 - TRECHO ENTR. BR-242 - SÃO VALÉRIO DE NATIVIDADE | C9: ='227'!R66 -> 43.157861 | D9: ='227'!F63 -> 0 | E9: ='227'!G63 -> 37.060747 | F9: ='227'!H63 -> 6.0971139 | G9: ='227'!I63 -> 0 | H9: ='227'!J63 -> 0 | I9: ='227'!K63 -> 43.157861 | J9: ='227'!L63 -> 0 | K9: ='227'!M63 -> 2.8557688 | ... S9: ='227'!U63 -> 0 | T9: =IF(SUM(D9:H9)=0,"— não preenchido",IF(ROUND(SUM(D9:H9)-C9,3)=0,"OK","ERRO — dif. de "&ROUND(SUM(D9:H9)-C9,3)&" km")) -> OK
A10: 228 | B10: RODOVIA TO-296 - TRECHO SÃO SALVADOR DO TOCANTINS - PARANÃ | C10: ='228'!R72 -> 54.941976 | D10: ='228'!F69 -> 3.9419763 | E10: ='228'!G69 -> 51 | F10: ='228'!H69 -> 0 | G10: ='228'!I69 -> 0 | H10: ='228'!J69 -> 0 | I10: ='228'!K69 -> 0 | J10: ='228'!L69 -> 54.941976 | K10: ='228'!M69 -> 0 | ... S10: ='228'!U69 -> 0 | T10: =IF(SUM(D10:H10)=0,"— não preenchido",IF(ROUND(SUM(D10:H10)-C10,3)=0,"OK","ERRO — dif. de "&ROUND(SUM(D10:H10)-C10,3)&" km")) -> OK
A11: 229 | B11: RODOVIA TO-296 - TRECHO JAÚ DO TOCANTINS - SÃO SALVADOR DO TOCANTINS | C11: ='229'!R24 -> 2.4086059 | D11: ='229'!F21 -> 0.4386593 | E11: ='229'!G21 -> 0 | F11: ='229'!H21 -> 1.9699466 | G11: ='229'!I21 -> 0 | H11: ='229'!J21 -> 0 | I11: ='229'!K21 -> 2.4086059 | J11: ='229'!L21 -> 0 | K11: ='229'!M21 -> 0.4386593 | ... S11: ='229'!U21 -> 0 | T11: =IF(SUM(D11:H11)=0,"— não preenchido",IF(ROUND(SUM(D11:H11)-C11,3)=0,"OK","ERRO — dif. de "&ROUND(SUM(D11:H11)-C11,3)&" km")) -> OK
A12: 230 | B12: RODOVIA TO-296 - TALISMÃ - ENTR. TO-498 (JAÚ DO TOCANTINS) | C12: ='230'!R82 -> 62.903735 | D12: ='230'!F79 -> 13.519213 | E12: ='230'!G79 -> 28.384522 | F12: ='230'!H79 -> 10 | G12: ='230'!I79 -> 0 | H12: ='230'!J79 -> 11 | I12: ='230'!K79 -> 1 | J12: ='230'!L79 -> 61.903735 | K12: ='230'!M79 -> 0 | ... S12: ='230'!U79 -> 0 | T12: =IF(SUM(D12:H12)=0,"— não preenchido",IF(ROUND(SUM(D12:H12)-C12,3)=0,"OK","ERRO — dif. de "&ROUND(SUM(D12:H12)-C12,3)&" km")) -> OK
A13: 231 | B13: RODOVIA TO-365 - TRECHO IPUEIRAS - SILVANÓPOLIS | C13: ='231'!R19 -> 1.125491 | D13: ='231'!F16 -> 0 | E13: ='231'!G16 -> 1.125491 | F13: ='231'!H16 -> 0 | G13: ='231'!I16 -> 0 | H13: ='231'!J16 -> 0 | I13: ='231'!K16 -> 1.125491 | J13: ='231'!L16 -> 0 | K13: ='231'!M16 -> 1.125491 | ... S13: ='231'!U16 -> 0 | T13: =IF(SUM(D13:H13)=0,"— não preenchido",IF(ROUND(SUM(D13:H13)-C13,3)=0,"OK","ERRO — dif. de "&ROUND(SUM(D13:H13)-C13,3)&" km")) -> OK
A14: 233 | B14: RODOVIA TO-373 - TRECHO ALVORADA - ENTR. BR-242 | C14: ='233'!R103 -> 81.849492 | D14: ='233'!F100 -> 9 | E14: ='233'!G100 -> 49.976519 | F14: ='233'!H100 -> 22.872974 | G14: ='233'!I100 -> 0 | H14: ='233'!J100 -> 0 | I14: ='233'!K100 -> 80.849492 | J14: ='233'!L100 -> 0 | K14: ='233'!M100 -> 9.8729737 | ... S14: ='233'!U100 -> 0 | T14: =IF(SUM(D14:H14)=0,"— não preenchido",IF(ROUND(SUM(D14:H14)-C14,3)=0,"OK","ERRO — dif. de "&ROUND(SUM(D14:H14)-C14,3)&" km")) -> OK
A15: 234 | B15: RODOVIA TO-387 - TRECHO PALMEIRÓPOLIS - SÃO SALVADOR DO TOCANTINS | C15: ='234'!R55 -> 37.422326 | D15: ='234'!F52 -> 3 | E15: ='234'!G52 -> 33.422326 | F15: ='234'!H52 -> 1 | G15: ='234'!I52 -> 0 | H15: ='234'!J52 -> 0 | I15: ='234'!K52 -> 0 | J15: ='234'!L52 -> 37.422326 | K15: ='234'!M52 -> 0 | ... S15: ='234'!U52 -> 0 | T15: =IF(SUM(D15:H15)=0,"— não preenchido",IF(ROUND(SUM(D15:H15)-C15,3)=0,"OK","ERRO — dif. de "&ROUND(SUM(D15:H15)-C15,3)&" km")) -> OK
A16: 235 | B16: RODOVIA TO-387 - TRECHO PALMEIRÓPOLIS - DIVISA TO-GO | C16: ='235'!R54 -> 30.117603 | D16: ='235'!F51 -> 3 | E16: ='235'!G51 -> 5.3221506 | F16: ='235'!H51 -> 0.64415038 | G16: ='235'!I51 -> 2 | H16: ='235'!J51 -> 0 | I16: ='235'!K51 -> 10.966301 | J16: ='235'!L51 -> 0 | K16: ='235'!M51 -> 0 | ... S16: ='235'!U51 -> 0 | T16: =IF(SUM(D16:H16)=0,"— não preenchido",IF(ROUND(SUM(D16:H16)-C16,3)=0,"OK","ERRO — dif. de "&ROUND(SUM(D16:H16)-C16,3)&" km")) -> ERRO — dif. de -19,151 km
A17: 243 | B17: RODOVIA TO-498 - TRECHO JAÚ DO TOCANTINS - ENTR. TO-373 (SANTA CRUZ) | C17: ='243'!R57 -> 36.06056 | D17: ='243'!F54 -> 25.025771 | E17: ='243'!G54 -> 10.034789 | F17: ='243'!H54 -> 0 | G17: ='243'!I54 -> 1 | H17: ='243'!J54 -> 0 | I17: ='243'!K54 -> 36.06056 | J17: ='243'!L54 -> 0 | K17: ='243'!M54 -> 13 | ... S17: ='243'!U54 -> 0 | T17: =IF(SUM(D17:H17)=0,"— não preenchido",IF(ROUND(SUM(D17:H17)-C17,3)=0,"OK","ERRO — dif. de "&ROUND(SUM(D17:H17)-C17,3)&" km")) -> OK
A18: 244 | B18: RODOVIA TO-498 - TRECHO JAÚ DO TOCANTINS - ENTR. TO-387 | C18: ='244'!R63 -> 42.086627 | D18: ='244'!F60 -> 2 | E18: ='244'!G60 -> 20 | F18: ='244'!H60 -> 20.043029 | G18: ='244'!I60 -> 0 | H18: ='244'!J60 -> 0 | I18: ='244'!K60 -> 42.043029 | J18: ='244'!L60 -> 0 | K18: ='244'!M60 -> 0 | ... S18: ='244'!U60 -> 0 | T18: =IF(SUM(D18:H18)=0,"— não preenchido",IF(ROUND(SUM(D18:H18)-C18,3)=0,"OK","ERRO — dif. de "&ROUND(SUM(D18:H18)-C18,3)&" km")) -> ERRO — dif. de -0,044 km
B19: TOTAL PERCORRIDO NO MÊS | C19: =SUM(C6:C18) -> 559.62302 | D19: =SUM(D6:D18) -> 72.925619 | E19: =SUM(E6:E18) -> 290.6705 | F19: =SUM(F6:F18) -> 162.832 | G19: =SUM(G6:G18) -> 3 | H19: =SUM(H6:H18) -> 11 | I19: =SUM(I6:I18) -> 385.16008 | J19: =SUM(J6:J18) -> 154.26804 | ... S19: =SUM(S6:S18) -> 0
B20: % DA EXTENSÃO DA MALHA (559.62 km) | D20: =SUM(D19:H19)/559.62 -> 0.96570551 | I20: (soma do grupo 'CONDIÇÃO DO PAVIMENTO' dividida pela malha)

Sheet 224
A1: PROGRAMA DE MANUTENÇÃO RODOVIÁRIA — FICHA DE INSPEÇÃO — RODOVIAS PAVIMENTADAS | Y1: Valores dos gráficos — troca 0 por N/D para a fatia não aparecer. Não editar.
A2: REGIÃO: 12 — PEIXE | G2: MÊS / ANO: | K2: DATA: | P2: TÉCNICO: | Y2: =IF(F41=0,NA(),F41) -> 13 | Z2: =IF(G41=0,NA(),G41) -> 8.24 | AA2: =IF(H41=0,NA(),H41) -> 5 | AB2: =IF(I41=0,NA(),I41) -> #N/A | AC2: =IF(J41=0,NA(),J41) -> #N/A | AD2: =IF(K41=0,NA(),K41) -> 26.24 | AE2: =IF(L41=0,NA(),L41) -> #N/A | AF2: =IF(M41=0,NA(),M41) -> #N/A | ... AN2: =IF(U41=0,NA(),U41) -> #N/A
A3: TRECHO 224 — RODOVIA TO-141 - TRECHO PALMEIRÓPOLIS - DIVISA TO-GO | T3: EXTENSÃO: 26,240 km · 1 S.R.E.
A4: COMO PREENCHER: uma X em UMA coluna de cada grupo, por linha. Se houver mais de um defeito no mesmo km, marque o PREDOMINANTE e escreva o resto em OBSERVAÇÕES. A quilometragem é contada de 0 até o fim de CADA S.R.E. (não é o marco da rodovia).
A6: S.R.E. | B6: SENT. | C6: INÍCIO (KM) | D6: FIM (KM) | E6: EXT. (KM) | F6: CONDIÇÃO DO PAVIMENTO | K6: VEGETAÇÃO | M6: ELEM. DE DRENAGEM | P6: SIN. HORIZ. | S6: SIN. VERTICAL | V6: OBSERVAÇÕES | W6: CONFERÊNCIA (só na tela)
F7: BOM | G7: REM. I. | H7: REM. L. | I7: BUR. I. | J7: BUR. L. | K7: ADEQ. | L7: INAD. | M7: LIMP. | N7: SUJO | O7: DANIF. | P7: BOM | Q7: REG. | R7: INEX. | S7: BOM | T7: POUC. | U7: INEX.
A8: S.R.E. 141ETO0110 | PALMEIRÓPOLIS *TRECHO URBANO* - DIV TO-GO | PPS · Estadual · 26.240 km · início: -13.052051, -48.391649
A9: 141ETO0110 | B9: C | C9: 0 | D9: 1 | E9: =D9-C9 -> 1 | H9: X | K9: X | N9: X | Q9: X | T9: X | W9: =IF(COUNTA(F9:U9)=0,"— não preenchido",IF(COUNTIF(F9:J9,"X")<>1,"FALTA/DUPLA: CONDIÇÃO DO PAVIMENTO",IF(COUNTIF(K9:L9,"X")<>1,"FALTA/DUPLA: VEGETAÇÃO",IF(COUNTIF(M9:O9,"X")<>1,"FALTA/DUPLA: ELEM. DE DRENAGEM",IF(COUNTIF(P9:R9,"X")<>1,"FALTA/DUPLA: SIN. HORIZ.",IF(COUNTIF(S9:U9,"X")<>1,"FALTA/DUPLA: SIN. VERTICAL","OK")))))) -> OK
A10: 141ETO0110 | B10: C | C10: 1 | D10: 2 | E10: =D10-C10 -> 1 | F10: X | K10: X | N10: X | Q10: X | T10: X | W10: =IF(COUNTA(F10:U10)=0,"— não preenchido",IF(COUNTIF(F10:J10,"X")<>1,"FALTA/DUPLA: CONDIÇÃO DO PAVIMENTO",IF(COUNTIF(K10:L10,"X")<>1,"FALTA/DUPLA: VEGETAÇÃO",IF(COUNTIF(M10:O10,"X")<>1,"FALTA/DUPLA: ELEM. DE DRENAGEM",IF(COUNTIF(P10:R10,"X")<>1,"FALTA/DUPLA: SIN. HORIZ.",IF(COUNTIF(S10:U10,"X")<>1,"FALTA/DUPLA: SIN. VERTICAL","OK")))))) -> OK
A11: 141ETO0110 | B11: C | C11: 2 | D11: 3 | E11: =D11-C11 -> 1 | G11: X | K11: X | N11: X | Q11: X | T11: X | W11: =IF(COUNTA(F11:U11)=0,"— não preenchido",IF(COUNTIF(F11:J11,"X")<>1,"FALTA/DUPLA: CONDIÇÃO DO PAVIMENTO",IF(COUNTIF(K11:L11,"X")<>1,"FALTA/DUPLA: VEGETAÇÃO",IF(COUNTIF(M11:O11,"X")<>1,"FALTA/DUPLA: ELEM. DE DRENAGEM",IF(COUNTIF(P11:R11,"X")<>1,"FALTA/DUPLA: SIN. HORIZ.",IF(COUNTIF(S11:U11,"X")<>1,"FALTA/DUPLA: SIN. VERTICAL","OK")))))) -> OK
A12: 141ETO0110 | B12: C | C12: 3 | D12: 4 | E12: =D12-C12 -> 1 | G12: X | K12: X | N12: X | Q12: X | T12: X | W12: =IF(COUNTA(F12:U12)=0,"— não preenchido",IF(COUNTIF(F12:J12,"X")<>1,"FALTA/DUPLA: CONDIÇÃO DO PAVIMENTO",IF(COUNTIF(K12:L12,"X")<>1,"FALTA/DUPLA: VEGETAÇÃO",IF(COUNTIF(M12:O12,"X")<>1,"FALTA/DUPLA: ELEM. DE DRENAGEM",IF(COUNTIF(P12:R12,"X")<>1,"FALTA/DUPLA: SIN. HORIZ.",IF(COUNTIF(S12:U12,"X")<>1,"FALTA/DUPLA: SIN. VERTICAL","OK")))))) -> OK
A13: 141ETO0110 | B13: C | C13: 4 | D13: 5 | E13: =D13-C13 -> 1 | G13: X | K13: X | N13: X | Q13: X | T13: X | W13: =IF(COUNTA(F13:U13)=0,"— não preenchido",IF(COUNTIF(F13:J13,"X")<>1,"FALTA/DUPLA: CONDIÇÃO DO PAVIMENTO",IF(COUNTIF(K13:L13,"X")<>1,"FALTA/DUPLA: VEGETAÇÃO",IF(COUNTIF(M13:O13,"X")<>1,"FALTA/DUPLA: ELEM. DE DRENAGEM",IF(COUNTIF(P13:R13,"X")<>1,"FALTA/DUPLA: SIN. HORIZ.",IF(COUNTIF(S13:U13,"X")<>1,"FALTA/DUPLA: SIN. VERTICAL","OK")))))) -> OK
A14: 141ETO0110 | B14: C | C14: 5 | D14: 6 | E14: =D14-C14 -> 1 | F14: X | K14: X | N14: X | Q14: X | T14: X | W14: =IF(COUNTA(F14:U14)=0,"— não preenchido",IF(COUNTIF(F14:J14,"X")<>1,"FALTA/DUPLA: CONDIÇÃO DO PAVIMENTO",IF(COUNTIF(K14:L14,"X")<>1,"FALTA/DUPLA: VEGETAÇÃO",IF(COUNTIF(M14:O14,"X")<>1,"FALTA/DUPLA: ELEM. DE DRENAGEM",IF(COUNTIF(P14:R14,"X")<>1,"FALTA/DUPLA: SIN. HORIZ.",IF(COUNTIF(S14:U14,"X")<>1,"FALTA/DUPLA: SIN. VERTICAL","OK")))))) -> OK
A15: 141ETO0110 | B15: C | C15: 6 | D15: 7 | E15: =D15-C15 -> 1 | F15: X | K15: X | N15: X | Q15: X | T15: X | W15: =IF(COUNTA(F15:U15)=0,"— não preenchido",IF(COUNTIF(F15:J15,"X")<>1,"FALTA/DUPLA: CONDIÇÃO DO PAVIMENTO",IF(COUNTIF(K15:L15,"X")<>1,"FALTA/DUPLA: VEGETAÇÃO",IF(COUNTIF(M15:O15,"X")<>1,"FALTA/DUPLA: ELEM. DE DRENAGEM",IF(COUNTIF(P15:R15,"X")<>1,"FALTA/DUPLA: SIN. HORIZ.",IF(COUNTIF(S15:U15,"X")<>1,"FALTA/DUPLA: SIN. VERTICAL","OK")))))) -> OK
A16: 141ETO0110 | B16: C | C16: 7 | D16: 8 | E16: =D16-C16 -> 1 | F16: X | K16: X | N16: X | Q16: X | T16: X | W16: =IF(COUNTA(F16:U16)=0,"— não preenchido",IF(COUNTIF(F16:J16,"X")<>1,"FALTA/DUPLA: CONDIÇÃO DO PAVIMENTO",IF(COUNTIF(K16:L16,"X")<>1,"FALTA/DUPLA: VEGETAÇÃO",IF(COUNTIF(M16:O16,"X")<>1,"FALTA/DUPLA: ELEM. DE DRENAGEM",IF(COUNTIF(P16:R16,"X")<>1,"FALTA/DUPLA: SIN. HORIZ.",IF(COUNTIF(S16:U16,"X")<>1,"FALTA/DUPLA: SIN. VERTICAL","OK")))))) -> OK
A17: 141ETO0110 | B17: C | C17: 8 | D17: 9 | E17: =D17-C17 -> 1 | F17: X | K17: X | N17: X | Q17: X | T17: X | W17: =IF(COUNTA(F17:U17)=0,"— não preenchido",IF(COUNTIF(F17:J17,"X")<>1,"FALTA/DUPLA: CONDIÇÃO DO PAVIMENTO",IF(COUNTIF(K17:L17,"X")<>1,"FALTA/DUPLA: VEGETAÇÃO",IF(COUNTIF(M17:O17,"X")<>1,"FALTA/DUPLA: ELEM. DE DRENAGEM",IF(COUNTIF(P17:R17,"X")<>1,"FALTA/DUPLA: SIN. HORIZ.",IF(COUNTIF(S17:U17,"X")<>1,"FALTA/DUPLA: SIN. VERTICAL","OK")))))) -> OK
A18: 141ETO0110 | B18: C | C18: 9 | D18: 10 | E18: =D18-C18 -> 1 | G18: X | K18: X | N18: X | Q18: X | T18: X | W18: =IF(COUNTA(F18:U18)=0,"— não preenchido",IF(COUNTIF(F18:J18,"X")<>1,"FALTA/DUPLA: CONDIÇÃO DO PAVIMENTO",IF(COUNTIF(K18:L18,"X")<>1,"FALTA/DUPLA: VEGETAÇÃO",IF(COUNTIF(M18:O18,"X")<>1,"FALTA/DUPLA: ELEM. DE DRENAGEM",IF(COUNTIF(P18:R18,"X")<>1,"FALTA/DUPLA: SIN. HORIZ.",IF(COUNTIF(S18:U18,"X")<>1,"FALTA/DUPLA: SIN. VERTICAL","OK")))))) -> OK
A19: 141ETO0110 | B19: C | C19: 10 | D19: 11 | E19: =D19-C19 -> 1 | G19: X | K19: X | N19: X | Q19: X | T19: X | W19: =IF(COUNTA(F19:U19)=0,"— não preenchido",IF(COUNTIF(F19:J19,"X")<>1,"FALTA/DUPLA: CONDIÇÃO DO PAVIMENTO",IF(COUNTIF(K19:L19,"X")<>1,"FALTA/DUPLA: VEGETAÇÃO",IF(COUNTIF(M19:O19,"X")<>1,"FALTA/DUPLA: ELEM. DE DRENAGEM",IF(COUNTIF(P19:R19,"X")<>1,"FALTA/DUPLA: SIN. HORIZ.",IF(COUNTIF(S19:U19,"X")<>1,"FALTA/DUPLA: SIN. VERTICAL","OK")))))) -> OK
A20: 141ETO0110 | B20: C | C20: 11 | D20: 12 | E20: =D20-C20 -> 1 | G20: X | K20: X | N20: X | Q20: X | T20: X | W20: =IF(COUNTA(F20:U20)=0,"— não preenchido",IF(COUNTIF(F20:J20,"X")<>1,"FALTA/DUPLA: CONDIÇÃO DO PAVIMENTO",IF(COUNTIF(K20:L20,"X")<>1,"FALTA/DUPLA: VEGETAÇÃO",IF(COUNTIF(M20:O20,"X")<>1,"FALTA/DUPLA: ELEM. DE DRENAGEM",IF(COUNTIF(P20:R20,"X")<>1,"FALTA/DUPLA: SIN. HORIZ.",IF(COUNTIF(S20:U20,"X")<>1,"FALTA/DUPLA: SIN. VERTICAL","OK")))))) -> OK
A21: 141ETO0110 | B21: C | C21: 12 | D21: 13 | E21: =D21-C21 -> 1 | G21: X | K21: X | N21: X | Q21: X | T21: X | W21: =IF(COUNTA(F21:U21)=0,"— não preenchido",IF(COUNTIF(F21:J21,"X")<>1,"FALTA/DUPLA: CONDIÇÃO DO PAVIMENTO",IF(COUNTIF(K21:L21,"X")<>1,"FALTA/DUPLA: VEGETAÇÃO",IF(COUNTIF(M21:O21,"X")<>1,"FALTA/DUPLA: ELEM. DE DRENAGEM",IF(COUNTIF(P21:R21,"X")<>1,"FALTA/DUPLA: SIN. HORIZ.",IF(COUNTIF(S21:U21,"X")<>1,"FALTA/DUPLA: SIN. VERTICAL","OK")))))) -> OK
A22: 141ETO0110 | B22: C | C22: 13 | D22: 14 | E22: =D22-C22 -> 1 | F22: X | K22: X | N22: X | Q22: X | T22: X | W22: =IF(COUNTA(F22:U22)=0,"— não preenchido",IF(COUNTIF(F22:J22,"X")<>1,"FALTA/DUPLA: CONDIÇÃO DO PAVIMENTO",IF(COUNTIF(K22:L22,"X")<>1,"FALTA/DUPLA: VEGETAÇÃO",IF(COUNTIF(M22:O22,"X")<>1,"FALTA/DUPLA: ELEM. DE DRENAGEM",IF(COUNTIF(P22:R22,"X")<>1,"FALTA/DUPLA: SIN. HORIZ.",IF(COUNTIF(S22:U22,"X")<>1,"FALTA/DUPLA: SIN. VERTICAL","OK")))))) -> OK
A23: 141ETO0110 | B23: C | C23: 14 | D23: 15 | E23: =D23-C23 -> 1 | H23: X | K23: X | N23: X | Q23: X | T23: X | W23: =IF(COUNTA(F23:U23)=0,"— não preenchido",IF(COUNTIF(F23:J23,"X")<>1,"FALTA/DUPLA: CONDIÇÃO DO PAVIMENTO",IF(COUNTIF(K23:L23,"X")<>1,"FALTA/DUPLA: VEGETAÇÃO",IF(COUNTIF(M23:O23,"X")<>1,"FALTA/DUPLA: ELEM. DE DRENAGEM",IF(COUNTIF(P23:R23,"X")<>1,"FALTA/DUPLA: SIN. HORIZ.",IF(COUNTIF(S23:U23,"X")<>1,"FALTA/DUPLA: SIN. VERTICAL","OK")))))) -> OK
A24: 141ETO0110 | B24: C | C24: 15 | D24: 16 | E24: =D24-C24 -> 1 | H24: X | K24: X | N24: X | Q24: X | T24: X | W24: =IF(COUNTA(F24:U24)=0,"— não preenchido",IF(COUNTIF(F24:J24,"X")<>1,"FALTA/DUPLA: CONDIÇÃO DO PAVIMENTO",IF(COUNTIF(K24:L24,"X")<>1,"FALTA/DUPLA: VEGETAÇÃO",IF(COUNTIF(M24:O24,"X")<>1,"FALTA/DUPLA: ELEM. DE DRENAGEM",IF(COUNTIF(P24:R24,"X")<>1,"FALTA/DUPLA: SIN. HORIZ.",IF(COUNTIF(S24:U24,"X")<>1,"FALTA/DUPLA: SIN. VERTICAL","OK")))))) -> OK
A25: 141ETO0110 | B25: C | C25: 16 | D25: 17 | E25: =D25-C25 -> 1 | H25: X | K25: X | N25: X | Q25: X | T25: X | W25: =IF(COUNTA(F25:U25)=0,"— não preenchido",IF(COUNTIF(F25:J25,"X")<>1,"FALTA/DUPLA: CONDIÇÃO DO PAVIMENTO",IF(COUNTIF(K25:L25,"X")<>1,"FALTA/DUPLA: VEGETAÇÃO",IF(COUNTIF(M25:O25,"X")<>1,"FALTA/DUPLA: ELEM. DE DRENAGEM",IF(COUNTIF(P25:R25,"X")<>1,"FALTA/DUPLA: SIN. HORIZ.",IF(COUNTIF(S25:U25,"X")<>1,"FALTA/DUPLA: SIN. VERTICAL","OK")))))) -> OK
A26: 141ETO0110 | B26: C | C26: 17 | D26: 18 | E26: =D26-C26 -> 1 | H26: X | K26: X | N26: X | Q26: X | T26: X | W26: =IF(COUNTA(F26:U26)=0,"— não preenchido",IF(COUNTIF(F26:J26,"X")<>1,"FALTA/DUPLA: CONDIÇÃO DO PAVIMENTO",IF(COUNTIF(K26:L26,"X")<>1,"FALTA/DUPLA: VEGETAÇÃO",IF(COUNTIF(M26:O26,"X")<>1,"FALTA/DUPLA: ELEM. DE DRENAGEM",IF(COUNTIF(P26:R26,"X")<>1,"FALTA/DUPLA: SIN. HORIZ.",IF(COUNTIF(S26:U26,"X")<>1,"FALTA/DUPLA: SIN. VERTICAL","OK")))))) -> OK
A27: 141ETO0110 | B27: C | C27: 18 | D27: 19 | E27: =D27-C27 -> 1 | F27: X | K27: X | N27: X | Q27: X | T27: X | W27: =IF(COUNTA(F27:U27)=0,"— não preenchido",IF(COUNTIF(F27:J27,"X")<>1,"FALTA/DUPLA: CONDIÇÃO DO PAVIMENTO",IF(COUNTIF(K27:L27,"X")<>1,"FALTA/DUPLA: VEGETAÇÃO",IF(COUNTIF(M27:O27,"X")<>1,"FALTA/DUPLA: ELEM. DE DRENAGEM",IF(COUNTIF(P27:R27,"X")<>1,"FALTA/DUPLA: SIN. HORIZ.",IF(COUNTIF(S27:U27,"X")<>1,"FALTA/DUPLA: SIN. VERTICAL","OK")))))) -> OK
A28: 141ETO0110 | B28: C | C28: 19 | D28: 20 | E28: =D28-C28 -> 1 | F28: X | K28: X | N28: X | Q28: X | T28: X | W28: =IF(COUNTA(F28:U28)=0,"— não preenchido",IF(COUNTIF(F28:J28,"X")<>1,"FALTA/DUPLA: CONDIÇÃO DO PAVIMENTO",IF(COUNTIF(K28:L28,"X")<>1,"FALTA/DUPLA: VEGETAÇÃO",IF(COUNTIF(M28:O28,"X")<>1,"FALTA/DUPLA: ELEM. DE DRENAGEM",IF(COUNTIF(P28:R28,"X")<>1,"FALTA/DUPLA: SIN. HORIZ.",IF(COUNTIF(S28:U28,"X")<>1,"FALTA/DUPLA: SIN. VERTICAL","OK")))))) -> OK
A29: 141ETO0110 | B29: C | C29: 20 | D29: 21 | E29: =D29-C29 -> 1 | F29: X | K29: X | N29: X | Q29: X | T29: X | W29: =IF(COUNTA(F29:U29)=0,"— não preenchido",IF(COUNTIF(F29:J29,"X")<>1,"FALTA/DUPLA: CONDIÇÃO DO PAVIMENTO",IF(COUNTIF(K29:L29,"X")<>1,"FALTA/DUPLA: VEGETAÇÃO",IF(COUNTIF(M29:O29,"X")<>1,"FALTA/DUPLA: ELEM. DE DRENAGEM",IF(COUNTIF(P29:R29,"X")<>1,"FALTA/DUPLA: SIN. HORIZ.",IF(COUNTIF(S29:U29,"X")<>1,"FALTA/DUPLA: SIN. VERTICAL","OK")))))) -> OK
A30: 141ETO0110 | B30: C | C30: 21 | D30: 22 | E30: =D30-C30 -> 1 | F30: X | K30: X | N30: X | Q30: X | T30: X | W30: =IF(COUNTA(F30:U30)=0,"— não preenchido",IF(COUNTIF(F30:J30,"X")<>1,"FALTA/DUPLA: CONDIÇÃO DO PAVIMENTO",IF(COUNTIF(K30:L30,"X")<>1,"FALTA/DUPLA: VEGETAÇÃO",IF(COUNTIF(M30:O30,"X")<>1,"FALTA/DUPLA: ELEM. DE DRENAGEM",IF(COUNTIF(P30:R30,"X")<>1,"FALTA/DUPLA: SIN. HORIZ.",IF(COUNTIF(S30:U30,"X")<>1,"FALTA/DUPLA: SIN. VERTICAL","OK")))))) -> OK
A31: 141ETO0110 | B31: C | C31: 22 | D31: 23 | E31: =D31-C31 -> 1 | F31: X | K31: X | N31: X | Q31: X | T31: X | W31: =IF(COUNTA(F31:U31)=0,"— não preenchido",IF(COUNTIF(F31:J31,"X")<>1,"FALTA/DUPLA: CONDIÇÃO DO PAVIMENTO",IF(COUNTIF(K31:L31,"X")<>1,"FALTA/DUPLA: VEGETAÇÃO",IF(COUNTIF(M31:O31,"X")<>1,"FALTA/DUPLA: ELEM. DE DRENAGEM",IF(COUNTIF(P31:R31,"X")<>1,"FALTA/DUPLA: SIN. HORIZ.",IF(COUNTIF(S31:U31,"X")<>1,"FALTA/DUPLA: SIN. VERTICAL","OK")))))) -> OK
A32: 141ETO0110 | B32: C | C32: 23 | D32: 24 | E32: =D32-C32 -> 1 | F32: X | K32: X | N32: X | Q32: X | T32: X | W32: =IF(COUNTA(F32:U32)=0,"— não preenchido",IF(COUNTIF(F32:J32,"X")<>1,"FALTA/DUPLA: CONDIÇÃO DO PAVIMENTO",IF(COUNTIF(K32:L32,"X")<>1,"FALTA/DUPLA: VEGETAÇÃO",IF(COUNTIF(M32:O32,"X")<>1,"FALTA/DUPLA: ELEM. DE DRENAGEM",IF(COUNTIF(P32:R32,"X")<>1,"FALTA/DUPLA: SIN. HORIZ.",IF(COUNTIF(S32:U32,"X")<>1,"FALTA/DUPLA: SIN. VERTICAL","OK")))))) -> OK
A33: 141ETO0110 | B33: C | C33: 24 | D33: 25 | E33: =D33-C33 -> 1 | F33: X | K33: X | N33: X | Q33: X | T33: X | W33: =IF(COUNTA(F33:U33)=0,"— não preenchido",IF(COUNTIF(F33:J33,"X")<>1,"FALTA/DUPLA: CONDIÇÃO DO PAVIMENTO",IF(COUNTIF(K33:L33,"X")<>1,"FALTA/DUPLA: VEGETAÇÃO",IF(COUNTIF(M33:O33,"X")<>1,"FALTA/DUPLA: ELEM. DE DRENAGEM",IF(COUNTIF(P33:R33,"X")<>1,"FALTA/DUPLA: SIN. HORIZ.",IF(COUNTIF(S33:U33,"X")<>1,"FALTA/DUPLA: SIN. VERTICAL","OK")))))) -> OK
A34: 141ETO0110 | B34: C | C34: 25 | D34: 26 | E34: =D34-C34 -> 1 | G34: X | K34: X | N34: X | Q34: X | T34: X | W34: =IF(COUNTA(F34:U34)=0,"— não preenchido",IF(COUNTIF(F34:J34,"X")<>1,"FALTA/DUPLA: CONDIÇÃO DO PAVIMENTO",IF(COUNTIF(K34:L34,"X")<>1,"FALTA/DUPLA: VEGETAÇÃO",IF(COUNTIF(M34:O34,"X")<>1,"FALTA/DUPLA: ELEM. DE DRENAGEM",IF(COUNTIF(P34:R34,"X")<>1,"FALTA/DUPLA: SIN. HORIZ.",IF(COUNTIF(S34:U34,"X")<>1,"FALTA/DUPLA: SIN. VERTICAL","OK")))))) -> OK
A35: 141ETO0110 | B35: C | C35: 26 | D35: 26.24 | E35: =D35-C35 -> 0.24 | G35: X | K35: X | N35: X | Q35: X | T35: X | W35: =IF(COUNTA(F35:U35)=0,"— não preenchido",IF(COUNTIF(F35:J35,"X")<>1,"FALTA/DUPLA: CONDIÇÃO DO PAVIMENTO",IF(COUNTIF(K35:L35,"X")<>1,"FALTA/DUPLA: VEGETAÇÃO",IF(COUNTIF(M35:O35,"X")<>1,"FALTA/DUPLA: ELEM. DE DRENAGEM",IF(COUNTIF(P35:R35,"X")<>1,"FALTA/DUPLA: SIN. HORIZ.",IF(COUNTIF(S35:U35,"X")<>1,"FALTA/DUPLA: SIN. VERTICAL","OK")))))) -> OK
A37: ____________________________________________ | G37: ____________________________________________
A38: TÉCNICO RESPONSÁVEL PELA INSPEÇÃO | G38: VISTO DA SUPERVISÃO
A40: RESUMO DO TRECHO — KM LANÇADO POR ITEM
A41: KM LANÇADO | F41: =SUMIF(F$9:F$35,"X",$E$9:$E$35) -> 13 | G41: =SUMIF(G$9:G$35,"X",$E$9:$E$35) -> 8.24 | H41: =SUMIF(H$9:H$35,"X",$E$9:$E$35) -> 5 | I41: =SUMIF(I$9:I$35,"X",$E$9:$E$35) -> 0 | J41: =SUMIF(J$9:J$35,"X",$E$9:$E$35) -> 0 | K41: =SUMIF(K$9:K$35,"X",$E$9:$E$35) -> 26.24 | L41: =SUMIF(L$9:L$35,"X",$E$9:$E$35) -> 0 | M41: =SUMIF(M$9:M$35,"X",$E$9:$E$35) -> 0 | ... U41: =SUMIF(U$9:U$35,"X",$E$9:$E$35) -> 0
A42: % DA EXTENSÃO | F42: =IF($R44=0,0,F41/$R44) -> 0.49542683 | G42: =IF($R44=0,0,G41/$R44) -> 0.31402439 | H42: =IF($R44=0,0,H41/$R44) -> 0.19054878 | I42: =IF($R44=0,0,I41/$R44) -> 0 | J42: =IF($R44=0,0,J41/$R44) -> 0 | K42: =IF($R44=0,0,K41/$R44) -> 1 | L42: =IF($R44=0,0,L41/$R44) -> 0 | M42: =IF($R44=0,0,M41/$R44) -> 0 | ... U42: =IF($R44=0,0,U41/$R44) -> 0
A43: CONFERÊNCIA POR GRUPO | F43: =IF(SUM(F41:J41)=0,"— não preenchido",IF(ROUND(SUM(F41:J41)-$R44,3)=0,"OK — "&ROUND(SUM(F41:J41),3)&" km","ERRO — dif. de "&ROUND(SUM(F41:J41)-$R44,3)&" km")) -> OK — 26,24 km | K43: =IF(SUM(K41:L41)=0,"— não preenchido",IF(ROUND(SUM(K41:L41)-$R44,3)=0,"OK — "&ROUND(SUM(K41:L41),3)&" km","ERRO — dif. de "&ROUND(SUM(K41:L41)-$R44,3)&" km")) -> OK — 26,24 km | M43: =IF(SUM(M41:O41)=0,"— não preenchido",IF(ROUND(SUM(M41:O41)-$R44,3)=0,"OK — "&ROUND(SUM(M41:O41),3)&" km","ERRO — dif. de "&ROUND(SUM(M41:O41)-$R44,3)&" km")) -> OK — 26,24 km | P43: =IF(SUM(P41:R41)=0,"— não preenchido",IF(ROUND(SUM(P41:R41)-$R44,3)=0,"OK — "&ROUND(SUM(P41:R41),3)&" km","ERRO — dif. de "&ROUND(SUM(P41:R41)-$R44,3)&" km")) -> OK — 26,24 km | S43: =IF(SUM(S41:U41)=0,"— não preenchido",IF(ROUND(SUM(S41:U41)-$R44,3)=0,"OK — "&ROUND(SUM(S41:U41),3)&" km","ERRO — dif. de "&ROUND(SUM(S41:U41)-$R44,3)&" km")) -> OK — 26,24 km
...

Sheet 225
A1: PROGRAMA DE MANUTENÇÃO RODOVIÁRIA — FICHA DE INSPEÇÃO — RODOVIAS PAVIMENTADAS | Y1: Valores dos gráficos — troca 0 por N/D para a fatia não aparecer. Não editar.
A2: REGIÃO: 12 — PEIXE | G2: MÊS / ANO: | K2: DATA: | P2: TÉCNICO: | Y2: =IF(F91=0,NA(),F91) -> #N/A | Z2: =IF(G91=0,NA(),G91) -> 19 | AA2: =IF(H91=0,NA(),H91) -> 57.27813 | AB2: =IF(I91=0,NA(),I91) -> #N/A | AC2: =IF(J91=0,NA(),J91) -> #N/A | AD2: =IF(K91=0,NA(),K91) -> 76.27813 | AE2: =IF(L91=0,NA(),L91) -> #N/A | AF2: =IF(M91=0,NA(),M91) -> 6 | ... AN2: =IF(U91=0,NA(),U91) -> #N/A
A3: TRECHO 225 — RODOVIA TO-280 - TRECHO NATIVIDADE - ALMAS | T3: EXTENSÃO: 76,278 km · 1 S.R.E.
A4: COMO PREENCHER: uma X em UMA coluna de cada grupo, por linha. Se houver mais de um defeito no mesmo km, marque o PREDOMINANTE e escreva o resto em OBSERVAÇÕES. A quilometragem é contada de 0 até o fim de CADA S.R.E. (não é o marco da rodovia).
A6: S.R.E. | B6: SENT. | C6: INÍCIO (KM) | D6: FIM (KM) | E6: EXT. (KM) | F6: CONDIÇÃO DO PAVIMENTO | K6: VEGETAÇÃO | M6: ELEM. DE DRENAGEM | P6: SIN. HORIZ. | S6: SIN. VERTICAL | V6: OBSERVAÇÕES | W6: CONFERÊNCIA (só na tela)
F7: BOM | G7: REM. I. | H7: REM. L. | I7: BUR. I. | J7: BUR. L. | K7: ADEQ. | L7: INAD. | M7: LIMP. | N7: SUJO | O7: DANIF. | P7: BOM | Q7: REG. | R7: INEX. | S7: BOM | T7: POUC. | U7: INEX.
A8: S.R.E. 280ETO0150 | ENTR. TO-040 (ALMAS) - ENTR. BR-010-TO-050 | PPS · Estadual · 76.278 km · início: -11.572979, -47.185779
A9: 280ETO0150 | B9: C | C9: 0 | D9: 1 | E9: =D9-C9 -> 1 | G9: X | K9: X | M9: X | Q9: X | T9: X | W9: =IF(COUNTA(F9:U9)=0,"— não preenchido",IF(COUNTIF(F9:J9,"X")<>1,"FALTA/DUPLA: CONDIÇÃO DO PAVIMENTO",IF(COUNTIF(K9:L9,"X")<>1,"FALTA/DUPLA: VEGETAÇÃO",IF(COUNTIF(M9:O9,"X")<>1,"FALTA/DUPLA: ELEM. DE DRENAGEM",IF(COUNTIF(P9:R9,"X")<>1,"FALTA/DUPLA: SIN. HORIZ.",IF(COUNTIF(S9:U9,"X")<>1,"FALTA/DUPLA: SIN. VERTICAL","OK")))))) -> OK
A10: 280ETO0150 | B10: C | C10: 1 | D10: 2 | E10: =D10-C10 -> 1 | G10: X | K10: X | M10: X | Q10: X | T10: X | W10: =IF(COUNTA(F10:U10)=0,"— não preenchido",IF(COUNTIF(F10:J10,"X")<>1,"FALTA/DUPLA: CONDIÇÃO DO PAVIMENTO",IF(COUNTIF(K10:L10,"X")<>1,"FALTA/DUPLA: VEGETAÇÃO",IF(COUNTIF(M10:O10,"X")<>1,"FALTA/DUPLA: ELEM. DE DRENAGEM",IF(COUNTIF(P10:R10,"X")<>1,"FALTA/DUPLA: SIN. HORIZ.",IF(COUNTIF(S10:U10,"X")<>1,"FALTA/DUPLA: SIN. VERTICAL","OK")))))) -> OK
A11: 280ETO0150 | B11: C | C11: 2 | D11: 3 | E11: =D11-C11 -> 1 | H11: X | K11: X | Q11: X | T11: X | W11: =IF(COUNTA(F11:U11)=0,"— não preenchido",IF(COUNTIF(F11:J11,"X")<>1,"FALTA/DUPLA: CONDIÇÃO DO PAVIMENTO",IF(COUNTIF(K11:L11,"X")<>1,"FALTA/DUPLA: VEGETAÇÃO",IF(COUNTIF(M11:O11,"X")<>1,"FALTA/DUPLA: ELEM. DE DRENAGEM",IF(COUNTIF(P11:R11,"X")<>1,"FALTA/DUPLA: SIN. HORIZ.",IF(COUNTIF(S11:U11,"X")<>1,"FALTA/DUPLA: SIN. VERTICAL","OK")))))) -> FALTA/DUPLA: ELEM. DE DRENAGEM
A12: 280ETO0150 | B12: C | C12: 3 | D12: 4 | E12: =D12-C12 -> 1 | H12: X | K12: X | Q12: X | T12: X | W12: =IF(COUNTA(F12:U12)=0,"— não preenchido",IF(COUNTIF(F12:J12,"X")<>1,"FALTA/DUPLA: CONDIÇÃO DO PAVIMENTO",IF(COUNTIF(K12:L12,"X")<>1,"FALTA/DUPLA: VEGETAÇÃO",IF(COUNTIF(M12:O12,"X")<>1,"FALTA/DUPLA: ELEM. DE DRENAGEM",IF(COUNTIF(P12:R12,"X")<>1,"FALTA/DUPLA: SIN. HORIZ.",IF(COUNTIF(S12:U12,"X")<>1,"FALTA/DUPLA: SIN. VERTICAL","OK")))))) -> FALTA/DUPLA: ELEM. DE DRENAGEM
A13: 280ETO0150 | B13: C | C13: 4 | D13: 5 | E13: =D13-C13 -> 1 | H13: X | K13: X | M13: X | Q13: X | T13: X | W13: =IF(COUNTA(F13:U13)=0,"— não preenchido",IF(COUNTIF(F13:J13,"X")<>1,"FALTA/DUPLA: CONDIÇÃO DO PAVIMENTO",IF(COUNTIF(K13:L13,"X")<>1,"FALTA/DUPLA: VEGETAÇÃO",IF(COUNTIF(M13:O13,"X")<>1,"FALTA/DUPLA: ELEM. DE DRENAGEM",IF(COUNTIF(P13:R13,"X")<>1,"FALTA/DUPLA: SIN. HORIZ.",IF(COUNTIF(S13:U13,"X")<>1,"FALTA/DUPLA: SIN. VERTICAL","OK")))))) -> OK
A14: 280ETO0150 | B14: C | C14: 5 | D14: 6 | E14: =D14-C14 -> 1 | H14: X | K14: X | M14: X | Q14: X | T14: X | W14: =IF(COUNTA(F14:U14)=0,"— não preenchido",IF(COUNTIF(F14:J14,"X")<>1,"FALTA/DUPLA: CONDIÇÃO DO PAVIMENTO",IF(COUNTIF(K14:L14,"X")<>1,"FALTA/DUPLA: VEGETAÇÃO",IF(COUNTIF(M14:O14,"X")<>1,"FALTA/DUPLA: ELEM. DE DRENAGEM",IF(COUNTIF(P14:R14,"X")<>1,"FALTA/DUPLA: SIN. HORIZ.",IF(COUNTIF(S14:U14,"X")<>1,"FALTA/DUPLA: SIN. VERTICAL","OK")))))) -> OK
A15: 280ETO0150 | B15: C | C15: 6 | D15: 7 | E15: =D15-C15 -> 1 | H15: X | K15: X | M15: X | Q15: X | T15: X | W15: =IF(COUNTA(F15:U15)=0,"— não preenchido",IF(COUNTIF(F15:J15,"X")<>1,"FALTA/DUPLA: CONDIÇÃO DO PAVIMENTO",IF(COUNTIF(K15:L15,"X")<>1,"FALTA/DUPLA: VEGETAÇÃO",IF(COUNTIF(M15:O15,"X")<>1,"FALTA/DUPLA: ELEM. DE DRENAGEM",IF(COUNTIF(P15:R15,"X")<>1,"FALTA/DUPLA: SIN. HORIZ.",IF(COUNTIF(S15:U15,"X")<>1,"FALTA/DUPLA: SIN. VERTICAL","OK")))))) -> OK
A16: 280ETO0150 | B16: C | C16: 7 | D16: 8 | E16: =D16-C16 -> 1 | H16: X | K16: X | M16: X | Q16: X | T16: X | W16: =IF(COUNTA(F16:U16)=0,"— não preenchido",IF(COUNTIF(F16:J16,"X")<>1,"FALTA/DUPLA: CONDIÇÃO DO PAVIMENTO",IF(COUNTIF(K16:L16,"X")<>1,"FALTA/DUPLA: VEGETAÇÃO",IF(COUNTIF(M16:O16,"X")<>1,"FALTA/DUPLA: ELEM. DE DRENAGEM",IF(COUNTIF(P16:R16,"X")<>1,"FALTA/DUPLA: SIN. HORIZ.",IF(COUNTIF(S16:U16,"X")<>1,"FALTA/DUPLA: SIN. VERTICAL","OK")))))) -> OK
A17: 280ETO0150 | B17: C | C17: 8 | D17: 9 | E17: =D17-C17 -> 1 | H17: X | K17: X | N17: X | Q17: X | T17: X | W17: =IF(COUNTA(F17:U17)=0,"— não preenchido",IF(COUNTIF(F17:J17,"X")<>1,"FALTA/DUPLA: CONDIÇÃO DO PAVIMENTO",IF(COUNTIF(K17:L17,"X")<>1,"FALTA/DUPLA: VEGETAÇÃO",IF(COUNTIF(M17:O17,"X")<>1,"FALTA/DUPLA: ELEM. DE DRENAGEM",IF(COUNTIF(P17:R17,"X")<>1,"FALTA/DUPLA: SIN. HORIZ.",IF(COUNTIF(S17:U17,"X")<>1,"FALTA/DUPLA: SIN. VERTICAL","OK")))))) -> OK
A18: 280ETO0150 | B18: C | C18: 9 | D18: 10 | E18: =D18-C18 -> 1 | H18: X | K18: X | N18: X | Q18: X | T18: X | W18: =IF(COUNTA(F18:U18)=0,"— não preenchido",IF(COUNTIF(F18:J18,"X")<>1,"FALTA/DUPLA: CONDIÇÃO DO PAVIMENTO",IF(COUNTIF(K18:L18,"X")<>1,"FALTA/DUPLA: VEGETAÇÃO",IF(COUNTIF(M18:O18,"X")<>1,"FALTA/DUPLA: ELEM. DE DRENAGEM",IF(COUNTIF(P18:R18,"X")<>1,"FALTA/DUPLA: SIN. HORIZ.",IF(COUNTIF(S18:U18,"X")<>1,"FALTA/DUPLA: SIN. VERTICAL","OK")))))) -> OK
A19: 280ETO0150 | B19: C | C19: 10 | D19: 11 | E19: =D19-C19 -> 1 | H19: X | K19: X | N19: X | Q19: X | T19: X | W19: =IF(COUNTA(F19:U19)=0,"— não preenchido",IF(COUNTIF(F19:J19,"X")<>1,"FALTA/DUPLA: CONDIÇÃO DO PAVIMENTO",IF(COUNTIF(K19:L19,"X")<>1,"FALTA/DUPLA: VEGETAÇÃO",IF(COUNTIF(M19:O19,"X")<>1,"FALTA/DUPLA: ELEM. DE DRENAGEM",IF(COUNTIF(P19:R19,"X")<>1,"FALTA/DUPLA: SIN. HORIZ.",IF(COUNTIF(S19:U19,"X")<>1,"FALTA/DUPLA: SIN. VERTICAL","OK")))))) -> OK
A20: 280ETO0150 | B20: C | C20: 11 | D20: 12 | E20: =D20-C20 -> 1 | H20: X | K20: X | N20: X | Q20: X | T20: X | W20: =IF(COUNTA(F20:U20)=0,"— não preenchido",IF(COUNTIF(F20:J20,"X")<>1,"FALTA/DUPLA: CONDIÇÃO DO PAVIMENTO",IF(COUNTIF(K20:L20,"X")<>1,"FALTA/DUPLA: VEGETAÇÃO",IF(COUNTIF(M20:O20,"X")<>1,"FALTA/DUPLA: ELEM. DE DRENAGEM",IF(COUNTIF(P20:R20,"X")<>1,"FALTA/DUPLA: SIN. HORIZ.",IF(COUNTIF(S20:U20,"X")<>1,"FALTA/DUPLA: SIN. VERTICAL","OK")))))) -> OK
A21: 280ETO0150 | B21: C | C21: 12 | D21: 13 | E21: =D21-C21 -> 1 | H21: X | K21: X | N21: X | Q21: X | T21: X | W21: =IF(COUNTA(F21:U21)=0,"— não preenchido",IF(COUNTIF(F21:J21,"X")<>1,"FALTA/DUPLA: CONDIÇÃO DO PAVIMENTO",IF(COUNTIF(K21:L21,"X")<>1,"FALTA/DUPLA: VEGETAÇÃO",IF(COUNTIF(M21:O21,"X")<>1,"FALTA/DUPLA: ELEM. DE DRENAGEM",IF(COUNTIF(P21:R21,"X")<>1,"FALTA/DUPLA: SIN. HORIZ.",IF(COUNTIF(S21:U21,"X")<>1,"FALTA/DUPLA: SIN. VERTICAL","OK")))))) -> OK
A22: 280ETO0150 | B22: C | C22: 13 | D22: 14 | E22: =D22-C22 -> 1 | H22: X | K22: X | N22: X | Q22: X | T22: X | W22: =IF(COUNTA(F22:U22)=0,"— não preenchido",IF(COUNTIF(F22:J22,"X")<>1,"FALTA/DUPLA: CONDIÇÃO DO PAVIMENTO",IF(COUNTIF(K22:L22,"X")<>1,"FALTA/DUPLA: VEGETAÇÃO",IF(COUNTIF(M22:O22,"X")<>1,"FALTA/DUPLA: ELEM. DE DRENAGEM",IF(COUNTIF(P22:R22,"X")<>1,"FALTA/DUPLA: SIN. HORIZ.",IF(COUNTIF(S22:U22,"X")<>1,"FALTA/DUPLA: SIN. VERTICAL","OK")))))) -> OK
A23: 280ETO0150 | B23: C | C23: 14 | D23: 15 | E23: =D23-C23 -> 1 | H23: X | K23: X | N23: X | Q23: X | T23: X | W23: =IF(COUNTA(F23:U23)=0,"— não preenchido",IF(COUNTIF(F23:J23,"X")<>1,"FALTA/DUPLA: CONDIÇÃO DO PAVIMENTO",IF(COUNTIF(K23:L23,"X")<>1,"FALTA/DUPLA: VEGETAÇÃO",IF(COUNTIF(M23:O23,"X")<>1,"FALTA/DUPLA: ELEM. DE DRENAGEM",IF(COUNTIF(P23:R23,"X")<>1,"FALTA/DUPLA: SIN. HORIZ.",IF(COUNTIF(S23:U23,"X")<>1,"FALTA/DUPLA: SIN. VERTICAL","OK")))))) -> OK
A24: 280ETO0150 | B24: C | C24: 15 | D24: 16 | E24: =D24-C24 -> 1 | H24: X | K24: X | N24: X | Q24: X | T24: X | W24: =IF(COUNTA(F24:U24)=0,"— não preenchido",IF(COUNTIF(F24:J24,"X")<>1,"FALTA/DUPLA: CONDIÇÃO DO PAVIMENTO",IF(COUNTIF(K24:L24,"X")<>1,"FALTA/DUPLA: VEGETAÇÃO",IF(COUNTIF(M24:O24,"X")<>1,"FALTA/DUPLA: ELEM. DE DRENAGEM",IF(COUNTIF(P24:R24,"X")<>1,"FALTA/DUPLA: SIN. HORIZ.",IF(COUNTIF(S24:U24,"X")<>1,"FALTA/DUPLA: SIN. VERTICAL","OK")))))) -> OK
A25: 280ETO0150 | B25: C | C25: 16 | D25: 17 | E25: =D25-C25 -> 1 | H25: X | K25: X | N25: X | Q25: X | T25: X | W25: =IF(COUNTA(F25:U25)=0,"— não preenchido",IF(COUNTIF(F25:J25,"X")<>1,"FALTA/DUPLA: CONDIÇÃO DO PAVIMENTO",IF(COUNTIF(K25:L25,"X")<>1,"FALTA/DUPLA: VEGETAÇÃO",IF(COUNTIF(M25:O25,"X")<>1,"FALTA/DUPLA: ELEM. DE DRENAGEM",IF(COUNTIF(P25:R25,"X")<>1,"FALTA/DUPLA: SIN. HORIZ.",IF(COUNTIF(S25:U25,"X")<>1,"FALTA/DUPLA: SIN. VERTICAL","OK")))))) -> OK
A26: 280ETO0150 | B26: C | C26: 17 | D26: 18 | E26: =D26-C26 -> 1 | H26: X | K26: X | N26: X | Q26: X | T26: X | W26: =IF(COUNTA(F26:U26)=0,"— não preenchido",IF(COUNTIF(F26:J26,"X")<>1,"FALTA/DUPLA: CONDIÇÃO DO PAVIMENTO",IF(COUNTIF(K26:L26,"X")<>1,"FALTA/DUPLA: VEGETAÇÃO",IF(COUNTIF(M26:O26,"X")<>1,"FALTA/DUPLA: ELEM. DE DRENAGEM",IF(COUNTIF(P26:R26,"X")<>1,"FALTA/DUPLA: SIN. HORIZ.",IF(COUNTIF(S26:U26,"X")<>1,"FALTA/DUPLA: SIN. VERTICAL","OK")))))) -> OK
A27: 280ETO0150 | B27: C | C27: 18 | D27: 19 | E27: =D27-C27 -> 1 | H27: X | K27: X | N27: X | Q27: X | T27: X | W27: =IF(COUNTA(F27:U27)=0,"— não preenchido",IF(COUNTIF(F27:J27,"X")<>1,"FALTA/DUPLA: CONDIÇÃO DO PAVIMENTO",IF(COUNTIF(K27:L27,"X")<>1,"FALTA/DUPLA: VEGETAÇÃO",IF(COUNTIF(M27:O27,"X")<>1,"FALTA/DUPLA: ELEM. DE DRENAGEM",IF(COUNTIF(P27:R27,"X")<>1,"FALTA/DUPLA: SIN. HORIZ.",IF(COUNTIF(S27:U27,"X")<>1,"FALTA/DUPLA: SIN. VERTICAL","OK")))))) -> OK
A28: 280ETO0150 | B28: C | C28: 19 | D28: 20 | E28: =D28-C28 -> 1 | H28: X | K28: X | N28: X | Q28: X | T28: X | W28: =IF(COUNTA(F28:U28)=0,"— não preenchido",IF(COUNTIF(F28:J28,"X")<>1,"FALTA/DUPLA: CONDIÇÃO DO PAVIMENTO",IF(COUNTIF(K28:L28,"X")<>1,"FALTA/DUPLA: VEGETAÇÃO",IF(COUNTIF(M28:O28,"X")<>1,"FALTA/DUPLA: ELEM. DE DRENAGEM",IF(COUNTIF(P28:R28,"X")<>1,"FALTA/DUPLA: SIN. HORIZ.",IF(COUNTIF(S28:U28,"X")<>1,"FALTA/DUPLA: SIN. VERTICAL","OK")))))) -> OK
... A31: 280ETO0150 | B31: C | C31: 22 | D31: 23 | E31: =D31-C31 -> 1 | H31: X | K31: X | N31: X | Q31: X | T31: X | W31: =IF(COUNTA(F31:U31)=0,"— não preenchido",IF(COUNTIF(F31:J31,"X")<>1,"FALTA/DUPLA: CONDIÇÃO DO PAVIMENTO",IF(COUNTIF(K31:L31,"X")<>1,"FALTA/DUPLA: VEGETAÇÃO",IF(COUNTIF(M31:O31,"X")<>1,"FALTA/DUPLA: ELEM. DE DRENAGEM",IF(COUNTIF(P31:R31,"X")<>1,"FALTA/DUPLA: SIN. HORIZ.",IF(COUNTIF(S31:U31,"X")<>1,"FALTA/DUPLA: SIN. VERTICAL","OK")))))) -> OK
A32: 280ETO0150 | B32: C | C32: 23 | D32: 24 | E32: =D32-C32 -> 1 | G32: X | K32: X | Q32: X | T32: X | W32: =IF(COUNTA(F32:U32)=0,"— não preenchido",IF(COUNTIF(F32:J32,"X")<>1,"FALTA/DUPLA: CONDIÇÃO DO PAVIMENTO",IF(COUNTIF(K32:L32,"X")<>1,"FALTA/DUPLA: VEGETAÇÃO",IF(COUNTIF(M32:O32,"X")<>1,"FALTA/DUPLA: ELEM. DE DRENAGEM",IF(COUNTIF(P32:R32,"X")<>1,"FALTA/DUPLA: SIN. HORIZ.",IF(COUNTIF(S32:U32,"X")<>1,"FALTA/DUPLA: SIN. VERTICAL","OK")))))) -> FALTA/DUPLA: ELEM. DE DRENAGEM
A33: 280ETO0150 | B33: C | C33: 24 | D33: 25 | E33: =D33-C33 -> 1 | G33: X | K33: X | Q33: X | T33: X | W33: =IF(COUNTA(F33:U33)=0,"— não preenchido",IF(COUNTIF(F33:J33,"X")<>1,"FALTA/DUPLA: CONDIÇÃO DO PAVIMENTO",IF(COUNTIF(K33:L33,"X")<>1,"FALTA/DUPLA: VEGETAÇÃO",IF(COUNTIF(M33:O33,"X")<>1,"FALTA/DUPLA: ELEM. DE DRENAGEM",IF(COUNTIF(P33:R33,"X")<>1,"FALTA/DUPLA: SIN. HORIZ.",IF(COUNTIF(S33:U33,"X")<>1,"FALTA/DUPLA: SIN. VERTICAL","OK")))))) -> FALTA/DUPLA: ELEM. DE DRENAGEM
A34: 280ETO0150 | B34: C | C34: 25 | D34: 26 | E34: =D34-C34 -> 1 | G34: X | K34: X | Q34: X | T34: X | W34: =IF(COUNTA(F34:U34)=0,"— não preenchido",IF(COUNTIF(F34:J34,"X")<>1,"FALTA/DUPLA: CONDIÇÃO DO PAVIMENTO",IF(COUNTIF(K34:L34,"X")<>1,"FALTA/DUPLA: VEGETAÇÃO",IF(COUNTIF(M34:O34,"X")<>1,"FALTA/DUPLA: ELEM. DE DRENAGEM",IF(COUNTIF(P34:R34,"X")<>1,"FALTA/DUPLA: SIN. HORIZ.",IF(COUNTIF(S34:U34,"X")<>1,"FALTA/DUPLA: SIN. VERTICAL","OK")))))) -> FALTA/DUPLA: ELEM. DE DRENAGEM
A35: 280ETO0150 | B35: C | C35: 26 | D35: 27 | E35: =D35-C35 -> 1 | G35: X | K35: X | Q35: X | T35: X | W35: =IF(COUNTA(F35:U35)=0,"— não preenchido",IF(COUNTIF(F35:J35,"X")<>1,"FALTA/DUPLA: CONDIÇÃO DO PAVIMENTO",IF(COUNTIF(K35:L35,"X")<>1,"FALTA/DUPLA: VEGETAÇÃO",IF(COUNTIF(M35:O35,"X")<>1,"FALTA/DUPLA: ELEM. DE DRENAGEM",IF(COUNTIF(P35:R35,"X")<>1,"FALTA/DUPLA: SIN. HORIZ.",IF(COUNTIF(S35:U35,"X")<>1,"FALTA/DUPLA: SIN. VERTICAL","OK")))))) -> FALTA/DUPLA: ELEM. DE DRENAGEM
A36: 280ETO0150 | B36: C | C36: 27 | D36: 28 | E36: =D36-C36 -> 1 | G36: X | K36: X | Q36: X | T36: X | W36: =IF(COUNTA(F36:U36)=0,"— não preenchido",IF(COUNTIF(F36:J36,"X")<>1,"FALTA/DUPLA: CONDIÇÃO DO PAVIMENTO",IF(COUNTIF(K36:L36,"X")<>1,"FALTA/DUPLA: VEGETAÇÃO",IF(COUNTIF(M36:O36,"X")<>1,"FALTA/DUPLA: ELEM. DE DRENAGEM",IF(COUNTIF(P36:R36,"X")<>1,"FALTA/DUPLA: SIN. HORIZ.",IF(COUNTIF(S36:U36,"X")<>1,"FALTA/DUPLA: SIN. VERTICAL","OK")))))) -> FALTA/DUPLA: ELEM. DE DRENAGEM
A37: 280ETO0150 | B37: C | C37: 28 | D37: 29 | E37: =D37-C37 -> 1 | G37: X | K37: X | Q37: X | T37: X | W37: =IF(COUNTA(F37:U37)=0,"— não preenchido",IF(COUNTIF(F37:J37,"X")<>1,"FALTA/DUPLA: CONDIÇÃO DO PAVIMENTO",IF(COUNTIF(K37:L37,"X")<>1,"FALTA/DUPLA: VEGETAÇÃO",IF(COUNTIF(M37:O37,"X")<>1,"FALTA/DUPLA: ELEM. DE DRENAGEM",IF(COUNTIF(P37:R37,"X")<>1,"FALTA/DUPLA: SIN. HORIZ.",IF(COUNTIF(S37:U37,"X")<>1,"FALTA/DUPLA: SIN. VERTICAL","OK")))))) -> FALTA/DUPLA: ELEM. DE DRENAGEM
A38: 280ETO0150 | B38: C | C38: 29 | D38: 30 | E38: =D38-C38 -> 1 | G38: X | K38: X | Q38: X | T38: X | W38: =IF(COUNTA(F38:U38)=0,"— não preenchido",IF(COUNTIF(F38:J38,"X")<>1,"FALTA/DUPLA: CONDIÇÃO DO PAVIMENTO",IF(COUNTIF(K38:L38,"X")<>1,"FALTA/DUPLA: VEGETAÇÃO",IF(COUNTIF(M38:O38,"X")<>1,"FALTA/DUPLA: ELEM. DE DRENAGEM",IF(COUNTIF(P38:R38,"X")<>1,"FALTA/DUPLA: SIN. HORIZ.",IF(COUNTIF(S38:U38,"X")<>1,"FALTA/DUPLA: SIN. VERTICAL","OK")))))) -> FALTA/DUPLA: ELEM. DE DRENAGEM
A39: 280ETO0150 | B39: C | C39: 30 | D39: 31 | E39: =D39-C39 -> 1 | G39: X | K39: X | Q39: X | T39: X | W39: =IF(COUNTA(F39:U39)=0,"— não preenchido",IF(COUNTIF(F39:J39,"X")<>1,"FALTA/DUPLA: CONDIÇÃO DO PAVIMENTO",IF(COUNTIF(K39:L39,"X")<>1,"FALTA/DUPLA: VEGETAÇÃO",IF(COUNTIF(M39:O39,"X")<>1,"FALTA/DUPLA: ELEM. DE DRENAGEM",IF(COUNTIF(P39:R39,"X")<>1,"FALTA/DUPLA: SIN. HORIZ.",IF(COUNTIF(S39:U39,"X")<>1,"FALTA/DUPLA: SIN. VERTICAL","OK")))))) -> FALTA/DUPLA: ELEM. DE DRENAGEM
A40: 280ETO0150 | B40: C | C40: 31 | D40: 32 | E40: =D40-C40 -> 1 | H40: X | K40: X | Q40: X | T40: X | W40: =IF(COUNTA(F40:U40)=0,"— não preenchido",IF(COUNTIF(F40:J40,"X")<>1,"FALTA/DUPLA: CONDIÇÃO DO PAVIMENTO",IF(COUNTIF(K40:L40,"X")<>1,"FALTA/DUPLA: VEGETAÇÃO",IF(COUNTIF(M40:O40,"X")<>1,"FALTA/DUPLA: ELEM. DE DRENAGEM",IF(COUNTIF(P40:R40,"X")<>1,"FALTA/DUPLA: SIN. HORIZ.",IF(COUNTIF(S40:U40,"X")<>1,"FALTA/DUPLA: SIN. VERTICAL","OK")))))) -> FALTA/DUPLA: ELEM. DE DRENAGEM
A41: 280ETO0150 | B41: C | C41: 32 | D41: 33 | E41: =D41-C41 -> 1 | G41: X | K41: X | Q41: X | T41: X | W41: =IF(COUNTA(F41:U41)=0,"— não preenchido",IF(COUNTIF(F41:J41,"X")<>1,"FALTA/DUPLA: CONDIÇÃO DO PAVIMENTO",IF(COUNTIF(K41:L41,"X")<>1,"FALTA/DUPLA: VEGETAÇÃO",IF(COUNTIF(M41:O41,"X")<>1,"FALTA/DUPLA: ELEM. DE DRENAGEM",IF(COUNTIF(P41:R41,"X")<>1,"FALTA/DUPLA: SIN. HORIZ.",IF(COUNTIF(S41:U41,"X")<>1,"FALTA/DUPLA: SIN. VERTICAL","OK")))))) -> FALTA/DUPLA: ELEM. DE DRENAGEM
A42: 280ETO0150 | B42: C | C42: 33 | D42: 34 | E42: =D42-C42 -> 1 | G42: X | K42: X | Q42: X | T42: X | W42: =IF(COUNTA(F42:U42)=0,"— não preenchido",IF(COUNTIF(F42:J42,"X")<>1,"FALTA/DUPLA: CONDIÇÃO DO PAVIMENTO",IF(COUNTIF(K42:L42,"X")<>1,"FALTA/DUPLA: VEGETAÇÃO",IF(COUNTIF(M42:O42,"X")<>1,"FALTA/DUPLA: ELEM. DE DRENAGEM",IF(COUNTIF(P42:R42,"X")<>1,"FALTA/DUPLA: SIN. HORIZ.",IF(COUNTIF(S42:U42,"X")<>1,"FALTA/DUPLA: SIN. VERTICAL","OK")))))) -> FALTA/DUPLA: ELEM. DE DRENAGEM
A43: 280ETO0150 | B43: C | C43: 34 | D43: 35 | E43: =D43-C43 -> 1 | H43: X | K43: X | N43: X | Q43: X | T43: X | W43: =IF(COUNTA(F43:U43)=0,"— não preenchido",IF(COUNTIF(F43:J43,"X")<>1,"FALTA/DUPLA: CONDIÇÃO DO PAVIMENTO",IF(COUNTIF(K43:L43,"X")<>1,"FALTA/DUPLA: VEGETAÇÃO",IF(COUNTIF(M43:O43,"X")<>1,"FALTA/DUPLA: ELEM. DE DRENAGEM",IF(COUNTIF(P43:R43,"X")<>1,"FALTA/DUPLA: SIN. HORIZ.",IF(COUNTIF(S43:U43,"X")<>1,"FALTA/DUPLA: SIN. VERTICAL","OK")))))) -> OK
...

Sheet 226
A1: PROGRAMA DE MANUTENÇÃO RODOVIÁRIA — FICHA DE INSPEÇÃO — RODOVIAS PAVIMENTADAS | Y1: Valores dos gráficos — troca 0 por N/D para a fatia não aparecer. Não editar.
A2: REGIÃO: 12 — PEIXE | G2: MÊS / ANO: | K2: DATA: | P2: TÉCNICO: | Y2: =IF(F82=0,NA(),F82) -> #N/A | Z2: =IF(G82=0,NA(),G82) -> 27.103955 | AA2: =IF(H82=0,NA(),H82) -> 37.926658 | AB2: =IF(I82=0,NA(),I82) -> #N/A | AC2: =IF(J82=0,NA(),J82) -> #N/A | AD2: =IF(K82=0,NA(),K82) -> 65.030612 | AE2: =IF(L82=0,NA(),L82) -> #N/A | AF2: =IF(M82=0,NA(),M82) -> 13.591541 | ... AN2: =IF(U82=0,NA(),U82) -> #N/A
A3: TRECHO 226 — RODOVIA TO-280 - TRECHO SÃO VALÉRIO DE NATIVIDADE - NATIVIDADE | T3: EXTENSÃO: 65,031 km · 3 S.R.E.
A4: COMO PREENCHER: uma X em UMA coluna de cada grupo, por linha. Se houver mais de um defeito no mesmo km, marque o PREDOMINANTE e escreva o resto em OBSERVAÇÕES. A quilometragem é contada de 0 até o fim de CADA S.R.E. (não é o marco da rodovia).
A6: S.R.E. | B6: SENT. | C6: INÍCIO (KM) | D6: FIM (KM) | E6: EXT. (KM) | F6: CONDIÇÃO DO PAVIMENTO | K6: VEGETAÇÃO | M6: ELEM. DE DRENAGEM | P6: SIN. HORIZ. | S6: SIN. VERTICAL | V6: OBSERVAÇÕES | W6: CONFERÊNCIA (só na tela)
F7: BOM | G7: REM. I. | H7: REM. L. | I7: BUR. I. | J7: BUR. L. | K7: ADEQ. | L7: INAD. | M7: LIMP. | N7: SUJO | O7: DANIF. | P7: BOM | Q7: REG. | R7: INEX. | S7: BOM | T7: POUC. | U7: INEX.
A8: S.R.E. 280ETO0175 | ENTR.TO-050 - BR-010 (NATIVIDADE ACESSO SUL) - ENTR. TO-486 | PPS · Estadual · 3.592 km · início: -11.715129, -47.74155
A9: 280ETO0175 | B9: C | C9: 0 | D9: 1 | E9: =D9-C9 -> 1 | H9: X | K9: X | Q9: X | T9: X | W9: =IF(COUNTA(F9:U9)=0,"— não preenchido",IF(COUNTIF(F9:J9,"X")<>1,"FALTA/DUPLA: CONDIÇÃO DO PAVIMENTO",IF(COUNTIF(K9:L9,"X")<>1,"FALTA/DUPLA: VEGETAÇÃO",IF(COUNTIF(M9:O9,"X")<>1,"FALTA/DUPLA: ELEM. DE DRENAGEM",IF(COUNTIF(P9:R9,"X")<>1,"FALTA/DUPLA: SIN. HORIZ.",IF(COUNTIF(S9:U9,"X")<>1,"FALTA/DUPLA: SIN. VERTICAL","OK")))))) -> FALTA/DUPLA: ELEM. DE DRENAGEM
A10: 280ETO0175 | B10: C | C10: 1 | D10: 2 | E10: =D10-C10 -> 1 | H10: X | K10: X | Q10: X | T10: X | W10: =IF(COUNTA(F10:U10)=0,"— não preenchido",IF(COUNTIF(F10:J10,"X")<>1,"FALTA/DUPLA: CONDIÇÃO DO PAVIMENTO",IF(COUNTIF(K10:L10,"X")<>1,"FALTA/DUPLA: VEGETAÇÃO",IF(COUNTIF(M10:O10,"X")<>1,"FALTA/DUPLA: ELEM. DE DRENAGEM",IF(COUNTIF(P10:R10,"X")<>1,"FALTA/DUPLA: SIN. HORIZ.",IF(COUNTIF(S10:U10,"X")<>1,"FALTA/DUPLA: SIN. VERTICAL","OK")))))) -> FALTA/DUPLA: ELEM. DE DRENAGEM
A11: 280ETO0175 | B11: C | C11: 2 | D11: 3 | E11: =D11-C11 -> 1 | G11: X | K11: X | M11: X | Q11: X | T11: X | W11: =IF(COUNTA(F11:U11)=0,"— não preenchido",IF(COUNTIF(F11:J11,"X")<>1,"FALTA/DUPLA: CONDIÇÃO DO PAVIMENTO",IF(COUNTIF(K11:L11,"X")<>1,"FALTA/DUPLA: VEGETAÇÃO",IF(COUNTIF(M11:O11,"X")<>1,"FALTA/DUPLA: ELEM. DE DRENAGEM",IF(COUNTIF(P11:R11,"X")<>1,"FALTA/DUPLA: SIN. HORIZ.",IF(COUNTIF(S11:U11,"X")<>1,"FALTA/DUPLA: SIN. VERTICAL","OK")))))) -> OK
A12: 280ETO0175 | B12: C | C12: 3 | D12: 3.5915409 | E12: =D12-C12 -> 0.59154086 | G12: X | K12: X | M12: X | Q12: X | T12: X | W12: =IF(COUNTA(F12:U12)=0,"— não preenchido",IF(COUNTIF(F12:J12,"X")<>1,"FALTA/DUPLA: CONDIÇÃO DO PAVIMENTO",IF(COUNTIF(K12:L12,"X")<>1,"FALTA/DUPLA: VEGETAÇÃO",IF(COUNTIF(M12:O12,"X")<>1,"FALTA/DUPLA: ELEM. DE DRENAGEM",IF(COUNTIF(P12:R12,"X")<>1,"FALTA/DUPLA: SIN. HORIZ.",IF(COUNTIF(S12:U12,"X")<>1,"FALTA/DUPLA: SIN. VERTICAL","OK")))))) -> OK
A13: S.R.E. 280ETO0180 | ENTR. TO-486 - ENTR. TO-482 | PPS · Estadual · 52.927 km · início: -11.721811, -47.762698
A14: 280ETO0180 | B14: C | C14: 0 | D14: 1 | E14: =D14-C14 -> 1 | G14: X | K14: X | Q14: X | T14: X | W14: =IF(COUNTA(F14:U14)=0,"— não preenchido",IF(COUNTIF(F14:J14,"X")<>1,"FALTA/DUPLA: CONDIÇÃO DO PAVIMENTO",IF(COUNTIF(K14:L14,"X")<>1,"FALTA/DUPLA: VEGETAÇÃO",IF(COUNTIF(M14:O14,"X")<>1,"FALTA/DUPLA: ELEM. DE DRENAGEM",IF(COUNTIF(P14:R14,"X")<>1,"FALTA/DUPLA: SIN. HORIZ.",IF(COUNTIF(S14:U14,"X")<>1,"FALTA/DUPLA: SIN. VERTICAL","OK")))))) -> FALTA/DUPLA: ELEM. DE DRENAGEM
A15: 280ETO0180 | B15: C | C15: 1 | D15: 2 | E15: =D15-C15 -> 1 | H15: X | K15: X | N15: X | Q15: X | T15: X | W15: =IF(COUNTA(F15:U15)=0,"— não preenchido",IF(COUNTIF(F15:J15,"X")<>1,"FALTA/DUPLA: CONDIÇÃO DO PAVIMENTO",IF(COUNTIF(K15:L15,"X")<>1,"FALTA/DUPLA: VEGETAÇÃO",IF(COUNTIF(M15:O15,"X")<>1,"FALTA/DUPLA: ELEM. DE DRENAGEM",IF(COUNTIF(P15:R15,"X")<>1,"FALTA/DUPLA: SIN. HORIZ.",IF(COUNTIF(S15:U15,"X")<>1,"FALTA/DUPLA: SIN. VERTICAL","OK")))))) -> OK
A16: 280ETO0180 | B16: C | C16: 2 | D16: 3 | E16: =D16-C16 -> 1 | H16: X | K16: X | N16: X | Q16: X | T16: X | W16: =IF(COUNTA(F16:U16)=0,"— não preenchido",IF(COUNTIF(F16:J16,"X")<>1,"FALTA/DUPLA: CONDIÇÃO DO PAVIMENTO",IF(COUNTIF(K16:L16,"X")<>1,"FALTA/DUPLA: VEGETAÇÃO",IF(COUNTIF(M16:O16,"X")<>1,"FALTA/DUPLA: ELEM. DE DRENAGEM",IF(COUNTIF(P16:R16,"X")<>1,"FALTA/DUPLA: SIN. HORIZ.",IF(COUNTIF(S16:U16,"X")<>1,"FALTA/DUPLA: SIN. VERTICAL","OK")))))) -> OK
A17: 280ETO0180 | B17: C | C17: 3 | D17: 4 | E17: =D17-C17 -> 1 | H17: X | K17: X | N17: X | Q17: X | T17: X | W17: =IF(COUNTA(F17:U17)=0,"— não preenchido",IF(COUNTIF(F17:J17,"X")<>1,"FALTA/DUPLA: CONDIÇÃO DO PAVIMENTO",IF(COUNTIF(K17:L17,"X")<>1,"FALTA/DUPLA: VEGETAÇÃO",IF(COUNTIF(M17:O17,"X")<>1,"FALTA/DUPLA: ELEM. DE DRENAGEM",IF(COUNTIF(P17:R17,"X")<>1,"FALTA/DUPLA: SIN. HORIZ.",IF(COUNTIF(S17:U17,"X")<>1,"FALTA/DUPLA: SIN. VERTICAL","OK")))))) -> OK
A18: 280ETO0180 | B18: C | C18: 4 | D18: 5 | E18: =D18-C18 -> 1 | H18: X | K18: X | N18: X | Q18: X | T18: X | W18: =IF(COUNTA(F18:U18)=0,"— não preenchido",IF(COUNTIF(F18:J18,"X")<>1,"FALTA/DUPLA: CONDIÇÃO DO PAVIMENTO",IF(COUNTIF(K18:L18,"X")<>1,"FALTA/DUPLA: VEGETAÇÃO",IF(COUNTIF(M18:O18,"X")<>1,"FALTA/DUPLA: ELEM. DE DRENAGEM",IF(COUNTIF(P18:R18,"X")<>1,"FALTA/DUPLA: SIN. HORIZ.",IF(COUNTIF(S18:U18,"X")<>1,"FALTA/DUPLA: SIN. VERTICAL","OK")))))) -> OK
A19: 280ETO0180 | B19: C | C19: 5 | D19: 6 | E19: =D19-C19 -> 1 | G19: X | K19: X | Q19: X | T19: X | W19: =IF(COUNTA(F19:U19)=0,"— não preenchido",IF(COUNTIF(F19:J19,"X")<>1,"FALTA/DUPLA: CONDIÇÃO DO PAVIMENTO",IF(COUNTIF(K19:L19,"X")<>1,"FALTA/DUPLA: VEGETAÇÃO",IF(COUNTIF(M19:O19,"X")<>1,"FALTA/DUPLA: ELEM. DE DRENAGEM",IF(COUNTIF(P19:R19,"X")<>1,"FALTA/DUPLA: SIN. HORIZ.",IF(COUNTIF(S19:U19,"X")<>1,"FALTA/DUPLA: SIN. VERTICAL","OK")))))) -> FALTA/DUPLA: ELEM. DE DRENAGEM
A20: 280ETO0180 | B20: C | C20: 6 | D20: 7 | E20: =D20-C20 -> 1 | G20: X | K20: X | Q20: X | T20: X | W20: =IF(COUNTA(F20:U20)=0,"— não preenchido",IF(COUNTIF(F20:J20,"X")<>1,"FALTA/DUPLA: CONDIÇÃO DO PAVIMENTO",IF(COUNTIF(K20:L20,"X")<>1,"FALTA/DUPLA: VEGETAÇÃO",IF(COUNTIF(M20:O20,"X")<>1,"FALTA/DUPLA: ELEM. DE DRENAGEM",IF(COUNTIF(P20:R20,"X")<>1,"FALTA/DUPLA: SIN. HORIZ.",IF(COUNTIF(S20:U20,"X")<>1,"FALTA/DUPLA: SIN. VERTICAL","OK")))))) -> FALTA/DUPLA: ELEM. DE DRENAGEM
A21: 280ETO0180 | B21: C | C21: 7 | D21: 8 | E21: =D21-C21 -> 1 | G21: X | K21: X | Q21: X | T21: X | W21: =IF(COUNTA(F21:U21)=0,"— não preenchido",IF(COUNTIF(F21:J21,"X")<>1,"FALTA/DUPLA: CONDIÇÃO DO PAVIMENTO",IF(COUNTIF(K21:L21,"X")<>1,"FALTA/DUPLA: VEGETAÇÃO",IF(COUNTIF(M21:O21,"X")<>1,"FALTA/DUPLA: ELEM. DE DRENAGEM",IF(COUNTIF(P21:R21,"X")<>1,"FALTA/DUPLA: SIN. HORIZ.",IF(COUNTIF(S21:U21,"X")<>1,"FALTA/DUPLA: SIN. VERTICAL","OK")))))) -> FALTA/DUPLA: ELEM. DE DRENAGEM
A22: 280ETO0180 | B22: C | C22: 8 | D22: 9 | E22: =D22-C22 -> 1 | G22: X | K22: X | Q22: X | T22: X | W22: =IF(COUNTA(F22:U22)=0,"— não preenchido",IF(COUNTIF(F22:J22,"X")<>1,"FALTA/DUPLA: CONDIÇÃO DO PAVIMENTO",IF(COUNTIF(K22:L22,"X")<>1,"FALTA/DUPLA: VEGETAÇÃO",IF(COUNTIF(M22:O22,"X")<>1,"FALTA/DUPLA: ELEM. DE DRENAGEM",IF(COUNTIF(P22:R22,"X")<>1,"FALTA/DUPLA: SIN. HORIZ.",IF(COUNTIF(S22:U22,"X")<>1,"FALTA/DUPLA: SIN. VERTICAL","OK")))))) -> FALTA/DUPLA: ELEM. DE DRENAGEM
A23: 280ETO0180 | B23: C | C23: 9 | D23: 10 | E23: =D23-C23 -> 1 | H23: X | K23: X | M23: X | Q23: X | T23: X | W23: =IF(COUNTA(F23:U23)=0,"— não preenchido",IF(COUNTIF(F23:J23,"X")<>1,"FALTA/DUPLA: CONDIÇÃO DO PAVIMENTO",IF(COUNTIF(K23:L23,"X")<>1,"FALTA/DUPLA: VEGETAÇÃO",IF(COUNTIF(M23:O23,"X")<>1,"FALTA/DUPLA: ELEM. DE DRENAGEM",IF(COUNTIF(P23:R23,"X")<>1,"FALTA/DUPLA: SIN. HORIZ.",IF(COUNTIF(S23:U23,"X")<>1,"FALTA/DUPLA: SIN. VERTICAL","OK")))))) -> OK
A24: 280ETO0180 | B24: C | C24: 10 | D24: 11 | E24: =D24-C24 -> 1 | H24: X | K24: X | M24: X | Q24: X | T24: X | W24: =IF(COUNTA(F24:U24)=0,"— não preenchido",IF(COUNTIF(F24:J24,"X")<>1,"FALTA/DUPLA: CONDIÇÃO DO PAVIMENTO",IF(COUNTIF(K24:L24,"X")<>1,"FALTA/DUPLA: VEGETAÇÃO",IF(COUNTIF(M24:O24,"X")<>1,"FALTA/DUPLA: ELEM. DE DRENAGEM",IF(COUNTIF(P24:R24,"X")<>1,"FALTA/DUPLA: SIN. HORIZ.",IF(COUNTIF(S24:U24,"X")<>1,"FALTA/DUPLA: SIN. VERTICAL","OK")))))) -> OK
A25: 280ETO0180 | B25: C | C25: 11 | D25: 12 | E25: =D25-C25 -> 1 | H25: X | K25: X | M25: X | Q25: X | T25: X | W25: =IF(COUNTA(F25:U25)=0,"— não preenchido",IF(COUNTIF(F25:J25,"X")<>1,"FALTA/DUPLA: CONDIÇÃO DO PAVIMENTO",IF(COUNTIF(K25:L25,"X")<>1,"FALTA/DUPLA: VEGETAÇÃO",IF(COUNTIF(M25:O25,"X")<>1,"FALTA/DUPLA: ELEM. DE DRENAGEM",IF(COUNTIF(P25:R25,"X")<>1,"FALTA/DUPLA: SIN. HORIZ.",IF(COUNTIF(S25:U25,"X")<>1,"FALTA/DUPLA: SIN. VERTICAL","OK")))))) -> OK
A26: 280ETO0180 | B26: C | C26: 12 | D26: 13 | E26: =D26-C26 -> 1 | H26: X | K26: X | M26: X | Q26: X | T26: X | W26: =IF(COUNTA(F26:U26)=0,"— não preenchido",IF(COUNTIF(F26:J26,"X")<>1,"FALTA/DUPLA: CONDIÇÃO DO PAVIMENTO",IF(COUNTIF(K26:L26,"X")<>1,"FALTA/DUPLA: VEGETAÇÃO",IF(COUNTIF(M26:O26,"X")<>1,"FALTA/DUPLA: ELEM. DE DRENAGEM",IF(COUNTIF(P26:R26,"X")<>1,"FALTA/DUPLA: SIN. HORIZ.",IF(COUNTIF(S26:U26,"X")<>1,"FALTA/DUPLA: SIN. VERTICAL","OK")))))) -> OK
A27: 280ETO0180 | B27: C | C27: 13 | D27: 14 | E27: =D27-C27 -> 1 | H27: X | K27: X | M27: X | Q27: X | T27: X | W27: =IF(COUNTA(F27:U27)=0,"— não preenchido",IF(COUNTIF(F27:J27,"X")<>1,"FALTA/DUPLA: CONDIÇÃO DO PAVIMENTO",IF(COUNTIF(K27:L27,"X")<>1,"FALTA/DUPLA: VEGETAÇÃO",IF(COUNTIF(M27:O27,"X")<>1,"FALTA/DUPLA: ELEM. DE DRENAGEM",IF(COUNTIF(P27:R27,"X")<>1,"FALTA/DUPLA: SIN. HORIZ.",IF(COUNTIF(S27:U27,"X")<>1,"FALTA/DUPLA: SIN. VERTICAL","OK")))))) -> OK
A28: 280ETO0180 | B28: C | C28: 14 | D28: 15 | E28: =D28-C28 -> 1 | G28: X | K28: X | M28: X | Q28: X | T28: X | W28: =IF(COUNTA(F28:U28)=0,"— não preenchido",IF(COUNTIF(F28:J28,"X")<>1,"FALTA/DUPLA: CONDIÇÃO DO PAVIMENTO",IF(COUNTIF(K28:L28,"X")<>1,"FALTA/DUPLA: VEGETAÇÃO",IF(COUNTIF(M28:O28,"X")<>1,"FALTA/DUPLA: ELEM. DE DRENAGEM",IF(COUNTIF(P28:R28,"X")<>1,"FALTA/DUPLA: SIN. HORIZ.",IF(COUNTIF(S28:U28,"X")<>1,"FALTA/DUPLA: SIN. VERTICAL","OK")))))) -> OK
A29: 280ETO0180 | B29: C | C29: 15 | D29: 16 | E29: =D29-C29 -> 1 | G29: X | K29: X | M29: X | Q29: X | T29: X | W29: =IF(COUNTA(F29:U29)=0,"— não preenchido",IF(COUNTIF(F29:J29,"X")<>1,"FALTA/DUPLA: CONDIÇÃO DO PAVIMENTO",IF(COUNTIF(K29:L29,"X")<>1,"FALTA/DUPLA: VEGETAÇÃO",IF(COUNTIF(M29:O29,"X")<>1,"FALTA/DUPLA: ELEM. DE DRENAGEM",IF(COUNTIF(P29:R29,"X")<>1,"FALTA/DUPLA: SIN. HORIZ.",IF(COUNTIF(S29:U29,"X")<>1,"FALTA/DUPLA: SIN. VERTICAL","OK")))))) -> OK
A30: 280ETO0180 | B30: C | C30: 16 | D30: 17 | E30: =D30-C30 -> 1 | G30: X | K30: X | M30: X | Q30: X | T30: X | W30: =IF(COUNTA(F30:U30)=0,"— não preenchido",IF(COUNTIF(F30:J30,"X")<>1,"FALTA/DUPLA: CONDIÇÃO DO PAVIMENTO",IF(COUNTIF(K30:L30,"X")<>1,"FALTA/DUPLA: VEGETAÇÃO",IF(COUNTIF(M30:O30,"X")<>1,"FALTA/DUPLA: ELEM. DE DRENAGEM",IF(COUNTIF(P30:R30,"X")<>1,"FALTA/DUPLA: SIN. HORIZ.",IF(COUNTIF(S30:U30,"X")<>1,"FALTA/DUPLA: SIN. VERTICAL","OK")))))) -> OK
A31: 280ETO0180 | B31: C | C31: 17 | D31: 18 | E31: =D31-C31 -> 1 | G31: X | K31: X | M31: X | Q31: X | T31: X | W31: =IF(COUNTA(F31:U31)=0,"— não preenchido",IF(COUNTIF(F31:J31,"X")<>1,"FALTA/DUPLA: CONDIÇÃO DO PAVIMENTO",IF(COUNTIF(K31:L31,"X")<>1,"FALTA/DUPLA: VEGETAÇÃO",IF(COUNTIF(M31:O31,"X")<>1,"FALTA/DUPLA: ELEM. DE DRENAGEM",IF(COUNTIF(P31:R31,"X")<>1,"FALTA/DUPLA: SIN. HORIZ.",IF(COUNTIF(S31:U31,"X")<>1,"FALTA/DUPLA: SIN. VERTICAL","OK")))))) -> OK
A32: 280ETO0180 | B32: C | C32: 18 | D32: 19 | E32: =D32-C32 -> 1 | G32: X | K32: X | Q32: X | T32: X | W32: =IF(COUNTA(F32:U32)=0,"— não preenchido",IF(COUNTIF(F32:J32,"X")<>1,"FALTA/DUPLA: CONDIÇÃO DO PAVIMENTO",IF(COUNTIF(K32:L32,"X")<>1,"FALTA/DUPLA: VEGETAÇÃO",IF(COUNTIF(M32:O32,"X")<>1,"FALTA/DUPLA: ELEM. DE DRENAGEM",IF(COUNTIF(P32:R32,"X")<>1,"FALTA/DUPLA: SIN. HORIZ.",IF(COUNTIF(S32:U32,"X")<>1,"FALTA/DUPLA: SIN. VERTICAL","OK")))))) -> FALTA/DUPLA: ELEM. DE DRENAGEM
A33: 280ETO0180 | B33: C | C33: 19 | D33: 20 | E33: =D33-C33 -> 1 | G33: X | K33: X | Q33: X | T33: X | W33: =IF(COUNTA(F33:U33)=0,"— não preenchido",IF(COUNTIF(F33:J33,"X")<>1,"FALTA/DUPLA: CONDIÇÃO DO PAVIMENTO",IF(COUNTIF(K33:L33,"X")<>1,"FALTA/DUPLA: VEGETAÇÃO",IF(COUNTIF(M33:O33,"X")<>1,"FALTA/DUPLA: ELEM. DE DRENAGEM",IF(COUNTIF(P33:R33,"X")<>1,"FALTA/DUPLA: SIN. HORIZ.",IF(COUNTIF(S33:U33,"X")<>1,"FALTA/DUPLA: SIN. VERTICAL","OK")))))) -> FALTA/DUPLA: ELEM. DE DRENAGEM
A34: 280ETO0180 | B34: C | C34: 20 | D34: 21 | E34: =D34-C34 -> 1 | G34: X | K34: X | Q34: X | T34: X | W34: =IF(COUNTA(F34:U34)=0,"— não preenchido",IF(COUNTIF(F34:J34,"X")<>1,"FALTA/DUPLA: CONDIÇÃO DO PAVIMENTO",IF(COUNTIF(K34:L34,"X")<>1,"FALTA/DUPLA: VEGETAÇÃO",IF(COUNTIF(M34:O34,"X")<>1,"FALTA/DUPLA: ELEM. DE DRENAGEM",IF(COUNTIF(P34:R34,"X")<>1,"FALTA/DUPLA: SIN. HORIZ.",IF(COUNTIF(S34:U34,"X")<>1,"FALTA/DUPLA: SIN. VERTICAL","OK")))))) -> FALTA/DUPLA: ELEM. DE DRENAGEM
A35: 280ETO0180 | B35: C | C35: 21 | D35: 22 | E35: =D35-C35 -> 1 | G35: X | K35: X | Q35: X | T35: X | W35: =IF(COUNTA(F35:U35)=0,"— não preenchido",IF(COUNTIF(F35:J35,"X")<>1,"FALTA/DUPLA: CONDIÇÃO DO PAVIMENTO",IF(COUNTIF(K35:L35,"X")<>1,"FALTA/DUPLA: VEGETAÇÃO",IF(COUNTIF(M35:O35,"X")<>1,"FALTA/DUPLA: ELEM. DE DRENAGEM",IF(COUNTIF(P35:R35,"X")<>1,"FALTA/DUPLA: SIN. HORIZ.",IF(COUNTIF(S35:U35,"X")<>1,"FALTA/DUPLA: SIN. VERTICAL","OK")))))) -> FALTA/DUPLA: ELEM. DE DRENAGEM
A36: 280ETO0180 | B36: C | C36: 22 | D36: 23 | E36: =D36-C36 -> 1 | H36: X | K36: X | Q36: X | T36: X | W36: =IF(COUNTA(F36:U36)=0,"— não preenchido",IF(COUNTIF(F36:J36,"X")<>1,"FALTA/DUPLA: CONDIÇÃO DO PAVIMENTO",IF(COUNTIF(K36:L36,"X")<>1,"FALTA/DUPLA: VEGETAÇÃO",IF(COUNTIF(M36:O36,"X")<>1,"FALTA/DUPLA: ELEM. DE DRENAGEM",IF(COUNTIF(P36:R36,"X")<>1,"FALTA/DUPLA: SIN. HORIZ.",IF(COUNTIF(S36:U36,"X")<>1,"FALTA/DUPLA: SIN. VERTICAL","OK")))))) -> FALTA/DUPLA: ELEM. DE DRENAGEM
A37: 280ETO0180 | B37: C | C37: 23 | D37: 24 | E37: =D37-C37 -> 1 | G37: X | K37: X | Q37: X | T37: X | W37: =IF(COUNTA(F37:U37)=0,"— não preenchido",IF(COUNTIF(F37:J37,"X")<>1,"FALTA/DUPLA: CONDIÇÃO DO PAVIMENTO",IF(COUNTIF(K37:L37,"X")<>1,"FALTA/DUPLA: VEGETAÇÃO",IF(COUNTIF(M37:O37,"X")<>1,"FALTA/DUPLA: ELEM. DE DRENAGEM",IF(COUNTIF(P37:R37,"X")<>1,"FALTA/DUPLA: SIN. HORIZ.",IF(COUNTIF(S37:U37,"X")<>1,"FALTA/DUPLA: SIN. VERTICAL","OK")))))) -> FALTA/DUPLA: ELEM. DE DRENAGEM
A38: 280ETO0180 | B38: C | C38: 24 | D38: 25 | E38: =D38-C38 -> 1 | G38: X | K38: X | Q38: X | T38: X | W38: =IF(COUNTA(F38:U38)=0,"— não preenchido",IF(COUNTIF(F38:J38,"X")<>1,"FALTA/DUPLA: CONDIÇÃO DO PAVIMENTO",IF(COUNTIF(K38:L38,"X")<>1,"FALTA/DUPLA: VEGETAÇÃO",IF(COUNTIF(M38:O38,"X")<>1,"FALTA/DUPLA: ELEM. DE DRENAGEM",IF(COUNTIF(P38:R38,"X")<>1,"FALTA/DUPLA: SIN. HORIZ.",IF(COUNTIF(S38:U38,"X")<>1,"FALTA/DUPLA: SIN. VERTICAL","OK")))))) -> FALTA/DUPLA: ELEM. DE DRENAGEM
A39: 280ETO0180 | B39: C | C39: 25 | D39: 26 | E39: =D39-C39 -> 1 | G39: X | K39: X | Q39: X | T39: X | W39: =IF(COUNTA(F39:U39)=0,"— não preenchido",IF(COUNTIF(F39:J39,"X")<>1,"FALTA/DUPLA: CONDIÇÃO DO PAVIMENTO",IF(COUNTIF(K39:L39,"X")<>1,"FALTA/DUPLA: VEGETAÇÃO",IF(COUNTIF(M39:O39,"X")<>1,"FALTA/DUPLA: ELEM. DE DRENAGEM",IF(COUNTIF(P39:R39,"X")<>1,"FALTA/DUPLA: SIN. HORIZ.",IF(COUNTIF(S39:U39,"X")<>1,"FALTA/DUPLA: SIN. VERTICAL","OK")))))) -> FALTA/DUPLA: ELEM. DE DRENAGEM
A40: 280ETO0180 | B40: C | C40: 26 | D40: 27 | E40: =D40-C40 -> 1 | G40: X | K40: X | Q40: X | T40: X | W40: =IF(COUNTA(F40:U40)=0,"— não preenchido",IF(COUNTIF(F40:J40,"X")<>1,"FALTA/DUPLA: CONDIÇÃO DO PAVIMENTO",IF(COUNTIF(K40:L40,"X")<>1,"FALTA/DUPLA: VEGETAÇÃO",IF(COUNTIF(M40:O40,"X")<>1,"FALTA/DUPLA: ELEM. DE DRENAGEM",IF(COUNTIF(P40:R40,"X")<>1,"FALTA/DUPLA: SIN. HORIZ.",IF(COUNTIF(S40:U40,"X")<>1,"FALTA/DUPLA: SIN. VERTICAL","OK")))))) -> FALTA/DUPLA: ELEM. DE DRENAGEM
A41: 280ETO0180 | B41: C | C41: 27 | D41: 28 | E41: =D41-C41 -> 1 | G41: X | K41: X | Q41: X | T41: X | W41: =IF(COUNTA(F41:U41)=0,"— não preenchido",IF(COUNTIF(F41:J41,"X")<>1,"FALTA/DUPLA: CONDIÇÃO DO PAVIMENTO",IF(COUNTIF(K41:L41,"X")<>1,"FALTA/DUPLA: VEGETAÇÃO",IF(COUNTIF(M41:O41,"X")<>1,"FALTA/DUPLA: ELEM. DE DRENAGEM",IF(COUNTIF(P41:R41,"X")<>1,"FALTA/DUPLA: SIN. HORIZ.",IF(COUNTIF(S41:U41,"X")<>1,"FALTA/DUPLA: SIN. VERTICAL","OK")))))) -> FALTA/DUPLA: ELEM. DE DRENAGEM
...

Sheet 227
A1: PROGRAMA DE MANUTENÇÃO RODOVIÁRIA — FICHA DE INSPEÇÃO — RODOVIAS PAVIMENTADAS | Y1: Valores dos gráficos — troca 0 por N/D para a fatia não aparecer. Não editar.
A2: REGIÃO: 12 — PEIXE | G2: MÊS / ANO: | K2: DATA: | P2: TÉCNICO: | Y2: =IF(F63=0,NA(),F63) -> #N/A | Z2: =IF(G63=0,NA(),G63) -> 37.060747 | AA2: =IF(H63=0,NA(),H63) -> 6.0971139 | AB2: =IF(I63=0,NA(),I63) -> #N/A | AC2: =IF(J63=0,NA(),J63) -> #N/A | AD2: =IF(K63=0,NA(),K63) -> 43.157861 | AE2: =IF(L63=0,NA(),L63) -> #N/A | AF2: =IF(M63=0,NA(),M63) -> 2.8557688 | ... AN2: =IF(U63=0,NA(),U63) -> #N/A
A3: TRECHO 227 — RODOVIA TO-280 - TRECHO ENTR. BR-242 - SÃO VALÉRIO DE NATIVIDADE | T3: EXTENSÃO: 43,158 km · 5 S.R.E.
A4: COMO PREENCHER: uma X em UMA coluna de cada grupo, por linha. Se houver mais de um defeito no mesmo km, marque o PREDOMINANTE e escreva o resto em OBSERVAÇÕES. A quilometragem é contada de 0 até o fim de CADA S.R.E. (não é o marco da rodovia).
A6: S.R.E. | B6: SENT. | C6: INÍCIO (KM) | D6: FIM (KM) | E6: EXT. (KM) | F6: CONDIÇÃO DO PAVIMENTO | K6: VEGETAÇÃO | M6: ELEM. DE DRENAGEM | P6: SIN. HORIZ. | S6: SIN. VERTICAL | V6: OBSERVAÇÕES | W6: CONFERÊNCIA (só na tela)
F7: BOM | G7: REM. I. | H7: REM. L. | I7: BUR. I. | J7: BUR. L. | K7: ADEQ. | L7: INAD. | M7: LIMP. | N7: SUJO | O7: DANIF. | P7: BOM | Q7: REG. | R7: INEX. | S7: BOM | T7: POUC. | U7: INEX.
A8: S.R.E. 280ETO0191 | SÃO VALÉRIO DA NATIVIDADE *TRECHO URBANO* | PSU · Municipal · 1.856 km · início: -11.964667, -48.230608
A9: 280ETO0191 | B9: C | C9: 0 | D9: 1 | E9: =D9-C9 -> 1 | H9: X | K9: X | M9: X | R9: X | T9: X | W9: =IF(COUNTA(F9:U9)=0,"— não preenchido",IF(COUNTIF(F9:J9,"X")<>1,"FALTA/DUPLA: CONDIÇÃO DO PAVIMENTO",IF(COUNTIF(K9:L9,"X")<>1,"FALTA/DUPLA: VEGETAÇÃO",IF(COUNTIF(M9:O9,"X")<>1,"FALTA/DUPLA: ELEM. DE DRENAGEM",IF(COUNTIF(P9:R9,"X")<>1,"FALTA/DUPLA: SIN. HORIZ.",IF(COUNTIF(S9:U9,"X")<>1,"FALTA/DUPLA: SIN. VERTICAL","OK")))))) -> OK
A10: 280ETO0191 | B10: C | C10: 1 | D10: 1.8557688 | E10: =D10-C10 -> 0.85576881 | H10: X | K10: X | M10: X | R10: X | T10: X | W10: =IF(COUNTA(F10:U10)=0,"— não preenchido",IF(COUNTIF(F10:J10,"X")<>1,"FALTA/DUPLA: CONDIÇÃO DO PAVIMENTO",IF(COUNTIF(K10:L10,"X")<>1,"FALTA/DUPLA: VEGETAÇÃO",IF(COUNTIF(M10:O10,"X")<>1,"FALTA/DUPLA: ELEM. DE DRENAGEM",IF(COUNTIF(P10:R10,"X")<>1,"FALTA/DUPLA: SIN. HORIZ.",IF(COUNTIF(S10:U10,"X")<>1,"FALTA/DUPLA: SIN. VERTICAL","OK")))))) -> OK
A11: S.R.E. 280ETO0200 | SÃO VALÉRIO DA NATIVIDADE *TRECHO URBANO* - ENTR. TO-490 | PPS · Estadual · 1.241 km · início: -11.984004, -48.236722
