Workbook

Sheet RESUMO
A1: RESUMO CONSOLIDADO — REGIÃO 1 — RODOVIAS NÃO PAVIMENTADAS | M1: Valores dos gráficos — troca 0 por N/D para a fatia não aparecer. Não editar.
A2: Todos os números vêm das abas dos trechos por referência direta. Não digite nada aqui. A coluna CONFERÊNCIA acusa qualquer trecho em que a soma das marcações não fecha com a extensão. | M2: =IF(D19=0,NA(),D19) -> 158.78004 | N2: =IF(E19=0,NA(),E19) -> 205.3054 | O2: =IF(F19=0,NA(),F19) -> 32.436808 | P2: =IF(G19=0,NA(),G19) -> #N/A | Q2: =IF(H19=0,NA(),H19) -> 243.50815 | R2: =IF(I19=0,NA(),I19) -> 132.35151 | S2: =IF(J19=0,NA(),J19) -> 20.662584
A4: Nº TRECHO | B4: TRECHO | C4: EXTENSÃO (KM) | D4: CONDIÇÃO DA PLATAFORMA | H4: DRENAGEM SUPERFICIAL | K4: CONFERÊNCIA
D5: BOM | E5: REGULAR | F5: RUIM | G5: PÉSSIMA | H5: LIMPA | I5: OBSTRUÍDA | J5: AUSENTE
A6: 1 | B6: RODOVIA TO-010 - TRECHO ANANÁS - ENTR. BR-230 | C6: ='1'!I103 -> 75.631722 | D6: ='1'!F100 -> 27.234346 | E6: ='1'!G100 -> 48.397376 | F6: ='1'!H100 -> 0 | G6: ='1'!I100 -> 0 | H6: ='1'!J100 -> 69.631722 | I6: ='1'!K100 -> 0 | J6: ='1'!L100 -> 6 | K6: =IF(SUM(D6:G6)=0,"— não preenchido",IF(ROUND(SUM(D6:G6)-C6,3)=0,"OK","ERRO — dif. de "&ROUND(SUM(D6:G6)-C6,3)&" km")) -> OK
A7: 6 | B7: RODOVIA TO-126 - TRECHO MAURILÂNDIA - TOCANTINÓPOLIS | C7: ='6'!I53 -> 35.479669 | D7: ='6'!F50 -> 22 | E7: ='6'!G50 -> 13.479669 | F7: ='6'!H50 -> 0 | G7: ='6'!I50 -> 0 | H7: ='6'!J50 -> 29.479669 | I7: ='6'!K50 -> 0 | J7: ='6'!L50 -> 6 | K7: =IF(SUM(D7:G7)=0,"— não preenchido",IF(ROUND(SUM(D7:G7)-C7,3)=0,"OK","ERRO — dif. de "&ROUND(SUM(D7:G7)-C7,3)&" km")) -> OK
A8: 12 | B8: RODOVIA TO-134 - TRECHO RIO TOCANTINS (JATOBAL) - AXIXÁ DO TOCANTINS | C8: ='12'!I52 -> 26.301108 | D8: ='12'!F49 -> 0 | E8: ='12'!G49 -> 0 | F8: ='12'!H49 -> 26.301108 | G8: ='12'!I49 -> 0 | H8: ='12'!J49 -> 0 | I8: ='12'!K49 -> 26.301108 | J8: ='12'!L49 -> 0 | K8: =IF(SUM(D8:G8)=0,"— não preenchido",IF(ROUND(SUM(D8:G8)-C8,3)=0,"OK","ERRO — dif. de "&ROUND(SUM(D8:G8)-C8,3)&" km")) -> OK
A9: 20 | B9: RODOVIA TO-201 - TRECHO ESPERANTINA - DIVISA TO-MA | C9: ='20'!I43 -> 22.698015 | D9: ='20'!F40 -> 8 | E9: ='20'!G40 -> 13.209234 | F9: ='20'!H40 -> 0 | G9: ='20'!I40 -> 0 | H9: ='20'!J40 -> 3.6392069 | I9: ='20'!K40 -> 17.570027 | J9: ='20'!L40 -> 0 | K9: =IF(SUM(D9:G9)=0,"— não preenchido",IF(ROUND(SUM(D9:G9)-C9,3)=0,"OK","ERRO — dif. de "&ROUND(SUM(D9:G9)-C9,3)&" km")) -> ERRO — dif. de -1,489 km
A10: 21 | B10: RODOVIA TO-205 - TRECHO SÃO BENTO DO TOCANTINS - ENTR. TO-010 | C10: ='21'!I43 -> 25.673932 | D10: ='21'!F40 -> 16.673932 | E10: ='21'!G40 -> 9 | F10: ='21'!H40 -> 0 | G10: ='21'!I40 -> 0 | H10: ='21'!J40 -> 14.673932 | I10: ='21'!K40 -> 11 | J10: ='21'!L40 -> 0 | K10: =IF(SUM(D10:G10)=0,"— não preenchido",IF(ROUND(SUM(D10:G10)-C10,3)=0,"OK","ERRO — dif. de "&ROUND(SUM(D10:G10)-C10,3)&" km")) -> OK
A11: 22 | B11: RODOVIA TO-210 - TRECHO ENTR. TO-010 - DIVISA TO-PA (VILA ANTONINA) | C11: ='22'!I56 -> 38.250855 | D11: ='22'!F53 -> 10.250855 | E11: ='22'!G53 -> 28 | F11: ='22'!H53 -> 0 | G11: ='22'!I53 -> 0 | H11: ='22'!J53 -> 33 | I11: ='22'!K53 -> 3.2508546 | J11: ='22'!L53 -> 2 | K11: =IF(SUM(D11:G11)=0,"— não preenchido",IF(ROUND(SUM(D11:G11)-C11,3)=0,"OK","ERRO — dif. de "&ROUND(SUM(D11:G11)-C11,3)&" km")) -> OK
A12: 25 | B12: RODOVIA TO-210 - TRECHO TOCANTINÓPOLIS - NAZARÉ | C12: ='25'!I35 -> 16.24209 | D12: ='25'!F32 -> 15.497344 | E12: ='25'!G32 -> 0 | F12: ='25'!H32 -> 0 | G12: ='25'!I32 -> 0 | H12: ='25'!J32 -> 15.497344 | I12: ='25'!K32 -> 0 | J12: ='25'!L32 -> 0 | K12: =IF(SUM(D12:G12)=0,"— não preenchido",IF(ROUND(SUM(D12:G12)-C12,3)=0,"OK","ERRO — dif. de "&ROUND(SUM(D12:G12)-C12,3)&" km")) -> ERRO — dif. de -0,745 km
A13: 26 | B13: RODOVIA TO-402 - TRECHO DIVISA TO-MA (VILA JURANDIR BELIZARIO) - ENTR. TO-201 | C13: ='26'!I32 -> 14.274653 | D13: ='26'!F29 -> 3 | E13: ='26'!G29 -> 11.274653 | F13: ='26'!H29 -> 0 | G13: ='26'!I29 -> 0 | H13: ='26'!J29 -> 0 | I13: ='26'!K29 -> 14.274653 | J13: ='26'!L29 -> 0 | K13: =IF(SUM(D13:G13)=0,"— não preenchido",IF(ROUND(SUM(D13:G13)-C13,3)=0,"OK","ERRO — dif. de "&ROUND(SUM(D13:G13)-C13,3)&" km")) -> OK
A14: 27 | B14: RODOVIA TO-403 - TRECHO CARRASCO BONITO - SAMPAIO | C14: ='27'!I38 -> 19.219656 | D14: ='27'!F35 -> 6 | E14: ='27'!G35 -> 11.219656 | F14: ='27'!H35 -> 2 | G14: ='27'!I35 -> 0 | H14: ='27'!J35 -> 10.557072 | I14: ='27'!K35 -> 6 | J14: ='27'!L35 -> 2.6625836 | K14: =IF(SUM(D14:G14)=0,"— não preenchido",IF(ROUND(SUM(D14:G14)-C14,3)=0,"OK","ERRO — dif. de "&ROUND(SUM(D14:G14)-C14,3)&" km")) -> OK
A15: 31 | B15: RODOVIA TO-405 - TRECHO AXIXÁ DO TOCANTINS - ENTR. BR-230 | C15: ='31'!I58 -> 35.95559 | D15: ='31'!F55 -> 4.6401054 | E15: ='31'!G55 -> 31.315485 | F15: ='31'!H55 -> 0 | G15: ='31'!I55 -> 0 | H15: ='31'!J55 -> 22.545751 | I15: ='31'!K55 -> 13.409839 | J15: ='31'!L55 -> 0 | K15: =IF(SUM(D15:G15)=0,"— não preenchido",IF(ROUND(SUM(D15:G15)-C15,3)=0,"OK","ERRO — dif. de "&ROUND(SUM(D15:G15)-C15,3)&" km")) -> OK
A16: 33 | B16: RODOVIA TO-409 - TRECHO MAURILÂNDIA - ENTR. TO-134 | C16: ='33'!I64 -> 44.892781 | D16: ='33'!F61 -> 33.483453 | E16: ='33'!G61 -> 11.409328 | F16: ='33'!H61 -> 0 | G16: ='33'!I61 -> 0 | H16: ='33'!J61 -> 24.483453 | I16: ='33'!K61 -> 20.409328 | J16: ='33'!L61 -> 0 | K16: =IF(SUM(D16:G16)=0,"— não preenchido",IF(ROUND(SUM(D16:G16)-C16,3)=0,"OK","ERRO — dif. de "&ROUND(SUM(D16:G16)-C16,3)&" km")) -> OK
A17: 34 | B17: RODOVIA TO-414 - TRECHO CACHOEIRINHA - ENTR. TO-010 (TAPUIO) | C17: ='34'!I50 -> 32.812789 | D17: ='34'!F47 -> 12 | E17: ='34'!G47 -> 20 | F17: ='34'!H47 -> 0 | G17: ='34'!I47 -> 0 | H17: ='34'!J47 -> 16 | I17: ='34'!K47 -> 12 | J17: ='34'!L47 -> 4 | K17: =IF(SUM(D17:G17)=0,"— não preenchido",IF(ROUND(SUM(D17:G17)-C17,3)=0,"OK","ERRO — dif. de "&ROUND(SUM(D17:G17)-C17,3)&" km")) -> ERRO — dif. de -0,813 km
A18: 37 | B18: RODOVIA TO-415 - TRECHO ENTR. RODOVIA VICINAL - NAZARÉ | C18: ='37'!I30 -> 12.1357 | D18: ='37'!F27 -> 0 | E18: ='37'!G27 -> 8 | F18: ='37'!H27 -> 4.1357005 | G18: ='37'!I27 -> 0 | H18: ='37'!J27 -> 4 | I18: ='37'!K27 -> 8.1357005 | J18: ='37'!L27 -> 0 | K18: =IF(SUM(D18:G18)=0,"— não preenchido",IF(ROUND(SUM(D18:G18)-C18,3)=0,"OK","ERRO — dif. de "&ROUND(SUM(D18:G18)-C18,3)&" km")) -> OK
B19: TOTAL PERCORRIDO NO MÊS | C19: =SUM(C6:C18) -> 399.56856 | D19: =SUM(D6:D18) -> 158.78004 | E19: =SUM(E6:E18) -> 205.3054 | F19: =SUM(F6:F18) -> 32.436808 | G19: =SUM(G6:G18) -> 0 | H19: =SUM(H6:H18) -> 243.50815 | I19: =SUM(I6:I18) -> 132.35151 | J19: =SUM(J6:J18) -> 20.662584
B20: % DA EXTENSÃO DA MALHA (399.57 km) | D20: =SUM(D19:G19)/399.57 -> 0.99237241 | H20: (soma do grupo 'CONDIÇÃO DA PLATAFORMA' dividida pela malha)

Sheet 1
A1: PROGRAMA DE MANUTENÇÃO RODOVIÁRIA — FICHA DE INSPEÇÃO — RODOVIAS NÃO PAVIMENTADAS | P1: Valores dos gráficos — troca 0 por N/D para a fatia não aparecer. Não editar.
A2: REGIÃO: 1 — TOCANTINÓPOLIS | D2: MÊS / ANO: | G2: DATA: | J2: TÉCNICO: | P2: =IF(F100=0,NA(),F100) -> 27.234346 | Q2: =IF(G100=0,NA(),G100) -> 48.397376 | R2: =IF(H100=0,NA(),H100) -> #N/A | S2: =IF(I100=0,NA(),I100) -> #N/A | T2: =IF(J100=0,NA(),J100) -> 69.631722 | U2: =IF(K100=0,NA(),K100) -> #N/A | V2: =IF(L100=0,NA(),L100) -> 6
A3: TRECHO 1 — RODOVIA TO-010 - TRECHO ANANÁS - ENTR. BR-230 | K3: EXTENSÃO: 75,632 km · 7 S.R.E.
A4: COMO PREENCHER: uma X em UMA coluna de cada grupo, por linha. Se houver mais de um defeito no mesmo km, marque o PREDOMINANTE e escreva o resto em OBSERVAÇÕES. A quilometragem é contada de 0 até o fim de CADA S.R.E. (não é o marco da rodovia).
A6: S.R.E. | B6: SENT. | C6: INÍCIO (KM) | D6: FIM (KM) | E6: EXT. (KM) | F6: CONDIÇÃO DA PLATAFORMA | J6: DRENAGEM SUPERFICIAL | M6: OBSERVAÇÕES | N6: CONFERÊNCIA (só na tela)
F7: BOM | G7: REGULAR | H7: RUIM | I7: PÉSSIMA | J7: LIMPA | K7: OBSTRUÍDA | L7: AUSENTE
A8: S.R.E. 010ETO0560 | FIM PAVIMENTACAO - ENTR. TO-205 | EOP · Estadual · 32.188 km · início: -6.303139, -48.100065
A9: 010ETO0560 | B9: C | C9: 0 | D9: 1 | E9: =D9-C9 -> 1 | G9: X | L9: X | N9: =IF(COUNTA(F9:L9)=0,"— não preenchido",IF(COUNTIF(F9:I9,"X")<>1,"FALTA/DUPLA: CONDIÇÃO DA PLATAFORMA",IF(COUNTIF(J9:L9,"X")<>1,"FALTA/DUPLA: DRENAGEM SUPERFICIAL","OK"))) -> OK
A10: 010ETO0560 | B10: C | C10: 1 | D10: 2 | E10: =D10-C10 -> 1 | G10: X | L10: X | N10: =IF(COUNTA(F10:L10)=0,"— não preenchido",IF(COUNTIF(F10:I10,"X")<>1,"FALTA/DUPLA: CONDIÇÃO DA PLATAFORMA",IF(COUNTIF(J10:L10,"X")<>1,"FALTA/DUPLA: DRENAGEM SUPERFICIAL","OK"))) -> OK
A11: 010ETO0560 | B11: C | C11: 2 | D11: 3 | E11: =D11-C11 -> 1 | G11: X | L11: X | N11: =IF(COUNTA(F11:L11)=0,"— não preenchido",IF(COUNTIF(F11:I11,"X")<>1,"FALTA/DUPLA: CONDIÇÃO DA PLATAFORMA",IF(COUNTIF(J11:L11,"X")<>1,"FALTA/DUPLA: DRENAGEM SUPERFICIAL","OK"))) -> OK
A12: 010ETO0560 | B12: C | C12: 3 | D12: 4 | E12: =D12-C12 -> 1 | G12: X | L12: X | N12: =IF(COUNTA(F12:L12)=0,"— não preenchido",IF(COUNTIF(F12:I12,"X")<>1,"FALTA/DUPLA: CONDIÇÃO DA PLATAFORMA",IF(COUNTIF(J12:L12,"X")<>1,"FALTA/DUPLA: DRENAGEM SUPERFICIAL","OK"))) -> OK
A13: 010ETO0560 | B13: C | C13: 4 | D13: 5 | E13: =D13-C13 -> 1 | G13: X | L13: X | N13: =IF(COUNTA(F13:L13)=0,"— não preenchido",IF(COUNTIF(F13:I13,"X")<>1,"FALTA/DUPLA: CONDIÇÃO DA PLATAFORMA",IF(COUNTIF(J13:L13,"X")<>1,"FALTA/DUPLA: DRENAGEM SUPERFICIAL","OK"))) -> OK
A14: 010ETO0560 | B14: C | C14: 5 | D14: 6 | E14: =D14-C14 -> 1 | G14: X | L14: X | N14: =IF(COUNTA(F14:L14)=0,"— não preenchido",IF(COUNTIF(F14:I14,"X")<>1,"FALTA/DUPLA: CONDIÇÃO DA PLATAFORMA",IF(COUNTIF(J14:L14,"X")<>1,"FALTA/DUPLA: DRENAGEM SUPERFICIAL","OK"))) -> OK
A15: 010ETO0560 | B15: C | C15: 6 | D15: 7 | E15: =D15-C15 -> 1 | G15: X | J15: X | N15: =IF(COUNTA(F15:L15)=0,"— não preenchido",IF(COUNTIF(F15:I15,"X")<>1,"FALTA/DUPLA: CONDIÇÃO DA PLATAFORMA",IF(COUNTIF(J15:L15,"X")<>1,"FALTA/DUPLA: DRENAGEM SUPERFICIAL","OK"))) -> OK
A16: 010ETO0560 | B16: C | C16: 7 | D16: 8 | E16: =D16-C16 -> 1 | G16: X | J16: X | N16: =IF(COUNTA(F16:L16)=0,"— não preenchido",IF(COUNTIF(F16:I16,"X")<>1,"FALTA/DUPLA: CONDIÇÃO DA PLATAFORMA",IF(COUNTIF(J16:L16,"X")<>1,"FALTA/DUPLA: DRENAGEM SUPERFICIAL","OK"))) -> OK
A17: 010ETO0560 | B17: C | C17: 8 | D17: 9 | E17: =D17-C17 -> 1 | G17: X | J17: X | N17: =IF(COUNTA(F17:L17)=0,"— não preenchido",IF(COUNTIF(F17:I17,"X")<>1,"FALTA/DUPLA: CONDIÇÃO DA PLATAFORMA",IF(COUNTIF(J17:L17,"X")<>1,"FALTA/DUPLA: DRENAGEM SUPERFICIAL","OK"))) -> OK
A18: 010ETO0560 | B18: C | C18: 9 | D18: 10 | E18: =D18-C18 -> 1 | G18: X | J18: X | N18: =IF(COUNTA(F18:L18)=0,"— não preenchido",IF(COUNTIF(F18:I18,"X")<>1,"FALTA/DUPLA: CONDIÇÃO DA PLATAFORMA",IF(COUNTIF(J18:L18,"X")<>1,"FALTA/DUPLA: DRENAGEM SUPERFICIAL","OK"))) -> OK
A19: 010ETO0560 | B19: C | C19: 10 | D19: 11 | E19: =D19-C19 -> 1 | G19: X | J19: X | N19: =IF(COUNTA(F19:L19)=0,"— não preenchido",IF(COUNTIF(F19:I19,"X")<>1,"FALTA/DUPLA: CONDIÇÃO DA PLATAFORMA",IF(COUNTIF(J19:L19,"X")<>1,"FALTA/DUPLA: DRENAGEM SUPERFICIAL","OK"))) -> OK
A20: 010ETO0560 | B20: C | C20: 11 | D20: 12 | E20: =D20-C20 -> 1 | G20: X | J20: X | N20: =IF(COUNTA(F20:L20)=0,"— não preenchido",IF(COUNTIF(F20:I20,"X")<>1,"FALTA/DUPLA: CONDIÇÃO DA PLATAFORMA",IF(COUNTIF(J20:L20,"X")<>1,"FALTA/DUPLA: DRENAGEM SUPERFICIAL","OK"))) -> OK
A21: 010ETO0560 | B21: C | C21: 12 | D21: 13 | E21: =D21-C21 -> 1 | G21: X | J21: X | N21: =IF(COUNTA(F21:L21)=0,"— não preenchido",IF(COUNTIF(F21:I21,"X")<>1,"FALTA/DUPLA: CONDIÇÃO DA PLATAFORMA",IF(COUNTIF(J21:L21,"X")<>1,"FALTA/DUPLA: DRENAGEM SUPERFICIAL","OK"))) -> OK
A22: 010ETO0560 | B22: C | C22: 13 | D22: 14 | E22: =D22-C22 -> 1 | G22: X | J22: X | N22: =IF(COUNTA(F22:L22)=0,"— não preenchido",IF(COUNTIF(F22:I22,"X")<>1,"FALTA/DUPLA: CONDIÇÃO DA PLATAFORMA",IF(COUNTIF(J22:L22,"X")<>1,"FALTA/DUPLA: DRENAGEM SUPERFICIAL","OK"))) -> OK
A23: 010ETO0560 | B23: C | C23: 14 | D23: 15 | E23: =D23-C23 -> 1 | G23: X | J23: X | N23: =IF(COUNTA(F23:L23)=0,"— não preenchido",IF(COUNTIF(F23:I23,"X")<>1,"FALTA/DUPLA: CONDIÇÃO DA PLATAFORMA",IF(COUNTIF(J23:L23,"X")<>1,"FALTA/DUPLA: DRENAGEM SUPERFICIAL","OK"))) -> OK
A24: 010ETO0560 | B24: C | C24: 15 | D24: 16 | E24: =D24-C24 -> 1 | G24: X | J24: X | N24: =IF(COUNTA(F24:L24)=0,"— não preenchido",IF(COUNTIF(F24:I24,"X")<>1,"FALTA/DUPLA: CONDIÇÃO DA PLATAFORMA",IF(COUNTIF(J24:L24,"X")<>1,"FALTA/DUPLA: DRENAGEM SUPERFICIAL","OK"))) -> OK
A25: 010ETO0560 | B25: C | C25: 16 | D25: 17 | E25: =D25-C25 -> 1 | G25: X | J25: X | N25: =IF(COUNTA(F25:L25)=0,"— não preenchido",IF(COUNTIF(F25:I25,"X")<>1,"FALTA/DUPLA: CONDIÇÃO DA PLATAFORMA",IF(COUNTIF(J25:L25,"X")<>1,"FALTA/DUPLA: DRENAGEM SUPERFICIAL","OK"))) -> OK
A26: 010ETO0560 | B26: C | C26: 17 | D26: 18 | E26: =D26-C26 -> 1 | G26: X | J26: X | N26: =IF(COUNTA(F26:L26)=0,"— não preenchido",IF(COUNTIF(F26:I26,"X")<>1,"FALTA/DUPLA: CONDIÇÃO DA PLATAFORMA",IF(COUNTIF(J26:L26,"X")<>1,"FALTA/DUPLA: DRENAGEM SUPERFICIAL","OK"))) -> OK
... A41: 010ETO0560 | B41: C | C41: 32 | D41: 32.187522 | E41: =D41-C41 -> 0.18752219 | G41: X | J41: X | N41: =IF(COUNTA(F41:L41)=0,"— não preenchido",IF(COUNTIF(F41:I41,"X")<>1,"FALTA/DUPLA: CONDIÇÃO DA PLATAFORMA",IF(COUNTIF(J41:L41,"X")<>1,"FALTA/DUPLA: DRENAGEM SUPERFICIAL","OK"))) -> OK
A42: S.R.E. 010ETO0570 | ENTR. TO-205 - RONCA | EOP · Estadual · 5.380 km · início: -6.058179, -48.123409
A43: 010ETO0570 | B43: C | C43: 0 | D43: 1 | E43: =D43-C43 -> 1 | F43: X | J43: X | N43: =IF(COUNTA(F43:L43)=0,"— não preenchido",IF(COUNTIF(F43:I43,"X")<>1,"FALTA/DUPLA: CONDIÇÃO DA PLATAFORMA",IF(COUNTIF(J43:L43,"X")<>1,"FALTA/DUPLA: DRENAGEM SUPERFICIAL","OK"))) -> OK
A44: 010ETO0570 | B44: C | C44: 1 | D44: 2 | E44: =D44-C44 -> 1 | F44: X | J44: X | N44: =IF(COUNTA(F44:L44)=0,"— não preenchido",IF(COUNTIF(F44:I44,"X")<>1,"FALTA/DUPLA: CONDIÇÃO DA PLATAFORMA",IF(COUNTIF(J44:L44,"X")<>1,"FALTA/DUPLA: DRENAGEM SUPERFICIAL","OK"))) -> OK
A45: 010ETO0570 | B45: C | C45: 2 | D45: 3 | E45: =D45-C45 -> 1 | F45: X | J45: X | N45: =IF(COUNTA(F45:L45)=0,"— não preenchido",IF(COUNTIF(F45:I45,"X")<>1,"FALTA/DUPLA: CONDIÇÃO DA PLATAFORMA",IF(COUNTIF(J45:L45,"X")<>1,"FALTA/DUPLA: DRENAGEM SUPERFICIAL","OK"))) -> OK
A46: 010ETO0570 | B46: C | C46: 3 | D46: 4 | E46: =D46-C46 -> 1 | F46: X | J46: X | N46: =IF(COUNTA(F46:L46)=0,"— não preenchido",IF(COUNTIF(F46:I46,"X")<>1,"FALTA/DUPLA: CONDIÇÃO DA PLATAFORMA",IF(COUNTIF(J46:L46,"X")<>1,"FALTA/DUPLA: DRENAGEM SUPERFICIAL","OK"))) -> OK
A47: 010ETO0570 | B47: C | C47: 4 | D47: 5 | E47: =D47-C47 -> 1 | F47: X | J47: X | N47: =IF(COUNTA(F47:L47)=0,"— não preenchido",IF(COUNTIF(F47:I47,"X")<>1,"FALTA/DUPLA: CONDIÇÃO DA PLATAFORMA",IF(COUNTIF(J47:L47,"X")<>1,"FALTA/DUPLA: DRENAGEM SUPERFICIAL","OK"))) -> OK
A48: 010ETO0570 | B48: C | C48: 5 | D48: 5.3799354 | E48: =D48-C48 -> 0.37993539 | F48: X | J48: X | N48: =IF(COUNTA(F48:L48)=0,"— não preenchido",IF(COUNTIF(F48:I48,"X")<>1,"FALTA/DUPLA: CONDIÇÃO DA PLATAFORMA",IF(COUNTIF(J48:L48,"X")<>1,"FALTA/DUPLA: DRENAGEM SUPERFICIAL","OK"))) -> OK
A49: S.R.E. 010ETO0580 | RONCA - NATAL | EOP · Estadual · 16.210 km · início: -6.023745, -48.14829
A50: 010ETO0580 | B50: C | C50: 0 | D50: 1 | E50: =D50-C50 -> 1 | G50: X | J50: X | N50: =IF(COUNTA(F50:L50)=0,"— não preenchido",IF(COUNTIF(F50:I50,"X")<>1,"FALTA/DUPLA: CONDIÇÃO DA PLATAFORMA",IF(COUNTIF(J50:L50,"X")<>1,"FALTA/DUPLA: DRENAGEM SUPERFICIAL","OK"))) -> OK
A51: 010ETO0580 | B51: C | C51: 1 | D51: 2 | E51: =D51-C51 -> 1 | G51: X | J51: X | N51: =IF(COUNTA(F51:L51)=0,"— não preenchido",IF(COUNTIF(F51:I51,"X")<>1,"FALTA/DUPLA: CONDIÇÃO DA PLATAFORMA",IF(COUNTIF(J51:L51,"X")<>1,"FALTA/DUPLA: DRENAGEM SUPERFICIAL","OK"))) -> OK
A52: 010ETO0580 | B52: C | C52: 2 | D52: 3 | E52: =D52-C52 -> 1 | G52: X | J52: X | N52: =IF(COUNTA(F52:L52)=0,"— não preenchido",IF(COUNTIF(F52:I52,"X")<>1,"FALTA/DUPLA: CONDIÇÃO DA PLATAFORMA",IF(COUNTIF(J52:L52,"X")<>1,"FALTA/DUPLA: DRENAGEM SUPERFICIAL","OK"))) -> OK
A53: 010ETO0580 | B53: C | C53: 3 | D53: 4 | E53: =D53-C53 -> 1 | G53: X | J53: X | N53: =IF(COUNTA(F53:L53)=0,"— não preenchido",IF(COUNTIF(F53:I53,"X")<>1,"FALTA/DUPLA: CONDIÇÃO DA PLATAFORMA",IF(COUNTIF(J53:L53,"X")<>1,"FALTA/DUPLA: DRENAGEM SUPERFICIAL","OK"))) -> OK
A54: 010ETO0580 | B54: C | C54: 4 | D54: 5 | E54: =D54-C54 -> 1 | G54: X | J54: X | N54: =IF(COUNTA(F54:L54)=0,"— não preenchido",IF(COUNTIF(F54:I54,"X")<>1,"FALTA/DUPLA: CONDIÇÃO DA PLATAFORMA",IF(COUNTIF(J54:L54,"X")<>1,"FALTA/DUPLA: DRENAGEM SUPERFICIAL","OK"))) -> OK
A55: 010ETO0580 | B55: C | C55: 5 | D55: 6 | E55: =D55-C55 -> 1 | G55: X | J55: X | N55: =IF(COUNTA(F55:L55)=0,"— não preenchido",IF(COUNTIF(F55:I55,"X")<>1,"FALTA/DUPLA: CONDIÇÃO DA PLATAFORMA",IF(COUNTIF(J55:L55,"X")<>1,"FALTA/DUPLA: DRENAGEM SUPERFICIAL","OK"))) -> OK
...

Sheet 6
A1: PROGRAMA DE MANUTENÇÃO RODOVIÁRIA — FICHA DE INSPEÇÃO — RODOVIAS NÃO PAVIMENTADAS | P1: Valores dos gráficos — troca 0 por N/D para a fatia não aparecer. Não editar.
A2: REGIÃO: 1 — TOCANTINÓPOLIS | D2: MÊS / ANO: | G2: DATA: | J2: TÉCNICO: | P2: =IF(F50=0,NA(),F50) -> 22 | Q2: =IF(G50=0,NA(),G50) -> 13.479669 | R2: =IF(H50=0,NA(),H50) -> #N/A | S2: =IF(I50=0,NA(),I50) -> #N/A | T2: =IF(J50=0,NA(),J50) -> 29.479669 | U2: =IF(K50=0,NA(),K50) -> #N/A | V2: =IF(L50=0,NA(),L50) -> 6
A3: TRECHO 6 — RODOVIA TO-126 - TRECHO MAURILÂNDIA - TOCANTINÓPOLIS | K3: EXTENSÃO: 35,480 km · 1 S.R.E.
A4: COMO PREENCHER: uma X em UMA coluna de cada grupo, por linha. Se houver mais de um defeito no mesmo km, marque o PREDOMINANTE e escreva o resto em OBSERVAÇÕES. A quilometragem é contada de 0 até o fim de CADA S.R.E. (não é o marco da rodovia).
A6: S.R.E. | B6: SENT. | C6: INÍCIO (KM) | D6: FIM (KM) | E6: EXT. (KM) | F6: CONDIÇÃO DA PLATAFORMA | J6: DRENAGEM SUPERFICIAL | M6: OBSERVAÇÕES | N6: CONFERÊNCIA (só na tela)
F7: BOM | G7: REGULAR | H7: RUIM | I7: PÉSSIMA | J7: LIMPA | K7: OBSTRUÍDA | L7: AUSENTE
A8: S.R.E. 126ETO0130 | MAURILÃNDIA DO TOCANTINS *TRECHO URBANO* - RIBEIRÃO GRANDE | LEN · Estadual · 35.480 km · início: -6.251085, -47.463245
A9: 126ETO0130 | B9: C | C9: 0 | D9: 1 | E9: =D9-C9 -> 1 | G9: X | L9: X | N9: =IF(COUNTA(F9:L9)=0,"— não preenchido",IF(COUNTIF(F9:I9,"X")<>1,"FALTA/DUPLA: CONDIÇÃO DA PLATAFORMA",IF(COUNTIF(J9:L9,"X")<>1,"FALTA/DUPLA: DRENAGEM SUPERFICIAL","OK"))) -> OK
A10: 126ETO0130 | B10: C | C10: 1 | D10: 2 | E10: =D10-C10 -> 1 | G10: X | L10: X | N10: =IF(COUNTA(F10:L10)=0,"— não preenchido",IF(COUNTIF(F10:I10,"X")<>1,"FALTA/DUPLA: CONDIÇÃO DA PLATAFORMA",IF(COUNTIF(J10:L10,"X")<>1,"FALTA/DUPLA: DRENAGEM SUPERFICIAL","OK"))) -> OK
A11: 126ETO0130 | B11: C | C11: 2 | D11: 3 | E11: =D11-C11 -> 1 | G11: X | L11: X | N11: =IF(COUNTA(F11:L11)=0,"— não preenchido",IF(COUNTIF(F11:I11,"X")<>1,"FALTA/DUPLA: CONDIÇÃO DA PLATAFORMA",IF(COUNTIF(J11:L11,"X")<>1,"FALTA/DUPLA: DRENAGEM SUPERFICIAL","OK"))) -> OK
A12: 126ETO0130 | B12: C | C12: 3 | D12: 4 | E12: =D12-C12 -> 1 | G12: X | L12: X | N12: =IF(COUNTA(F12:L12)=0,"— não preenchido",IF(COUNTIF(F12:I12,"X")<>1,"FALTA/DUPLA: CONDIÇÃO DA PLATAFORMA",IF(COUNTIF(J12:L12,"X")<>1,"FALTA/DUPLA: DRENAGEM SUPERFICIAL","OK"))) -> OK
A13: 126ETO0130 | B13: C | C13: 4 | D13: 5 | E13: =D13-C13 -> 1 | G13: X | J13: X | M13: ALTO INDICE DE BURACOS E VALETAS | N13: =IF(COUNTA(F13:L13)=0,"— não preenchido",IF(COUNTIF(F13:I13,"X")<>1,"FALTA/DUPLA: CONDIÇÃO DA PLATAFORMA",IF(COUNTIF(J13:L13,"X")<>1,"FALTA/DUPLA: DRENAGEM SUPERFICIAL","OK"))) -> OK
A14: 126ETO0130 | B14: C | C14: 5 | D14: 6 | E14: =D14-C14 -> 1 | G14: X | J14: X | M14: ALTO INDICE DE BURACOS E VALETAS | N14: =IF(COUNTA(F14:L14)=0,"— não preenchido",IF(COUNTIF(F14:I14,"X")<>1,"FALTA/DUPLA: CONDIÇÃO DA PLATAFORMA",IF(COUNTIF(J14:L14,"X")<>1,"FALTA/DUPLA: DRENAGEM SUPERFICIAL","OK"))) -> OK
A15: 126ETO0130 | B15: C | C15: 6 | D15: 7 | E15: =D15-C15 -> 1 | G15: X | J15: X | M15: ALTO INDICE DE BURACOS E VALETAS | N15: =IF(COUNTA(F15:L15)=0,"— não preenchido",IF(COUNTIF(F15:I15,"X")<>1,"FALTA/DUPLA: CONDIÇÃO DA PLATAFORMA",IF(COUNTIF(J15:L15,"X")<>1,"FALTA/DUPLA: DRENAGEM SUPERFICIAL","OK"))) -> OK
A16: 126ETO0130 | B16: C | C16: 7 | D16: 8 | E16: =D16-C16 -> 1 | G16: X | J16: X | M16: ALTO INDICE DE BURACOS E VALETAS | N16: =IF(COUNTA(F16:L16)=0,"— não preenchido",IF(COUNTIF(F16:I16,"X")<>1,"FALTA/DUPLA: CONDIÇÃO DA PLATAFORMA",IF(COUNTIF(J16:L16,"X")<>1,"FALTA/DUPLA: DRENAGEM SUPERFICIAL","OK"))) -> OK
A17: 126ETO0130 | B17: C | C17: 8 | D17: 9 | E17: =D17-C17 -> 1 | F17: X | L17: X | N17: =IF(COUNTA(F17:L17)=0,"— não preenchido",IF(COUNTIF(F17:I17,"X")<>1,"FALTA/DUPLA: CONDIÇÃO DA PLATAFORMA",IF(COUNTIF(J17:L17,"X")<>1,"FALTA/DUPLA: DRENAGEM SUPERFICIAL","OK"))) -> OK
A18: 126ETO0130 | B18: C | C18: 9 | D18: 10 | E18: =D18-C18 -> 1 | F18: X | L18: X | N18: =IF(COUNTA(F18:L18)=0,"— não preenchido",IF(COUNTIF(F18:I18,"X")<>1,"FALTA/DUPLA: CONDIÇÃO DA PLATAFORMA",IF(COUNTIF(J18:L18,"X")<>1,"FALTA/DUPLA: DRENAGEM SUPERFICIAL","OK"))) -> OK
A19: 126ETO0130 | B19: C | C19: 10 | D19: 11 | E19: =D19-C19 -> 1 | F19: X | J19: X | N19: =IF(COUNTA(F19:L19)=0,"— não preenchido",IF(COUNTIF(F19:I19,"X")<>1,"FALTA/DUPLA: CONDIÇÃO DA PLATAFORMA",IF(COUNTIF(J19:L19,"X")<>1,"FALTA/DUPLA: DRENAGEM SUPERFICIAL","OK"))) -> OK
A20: 126ETO0130 | B20: C | C20: 11 | D20: 12 | E20: =D20-C20 -> 1 | F20: X | J20: X | N20: =IF(COUNTA(F20:L20)=0,"— não preenchido",IF(COUNTIF(F20:I20,"X")<>1,"FALTA/DUPLA: CONDIÇÃO DA PLATAFORMA",IF(COUNTIF(J20:L20,"X")<>1,"FALTA/DUPLA: DRENAGEM SUPERFICIAL","OK"))) -> OK
A21: 126ETO0130 | B21: C | C21: 12 | D21: 13 | E21: =D21-C21 -> 1 | F21: X | J21: X | N21: =IF(COUNTA(F21:L21)=0,"— não preenchido",IF(COUNTIF(F21:I21,"X")<>1,"FALTA/DUPLA: CONDIÇÃO DA PLATAFORMA",IF(COUNTIF(J21:L21,"X")<>1,"FALTA/DUPLA: DRENAGEM SUPERFICIAL","OK"))) -> OK
A22: 126ETO0130 | B22: C | C22: 13 | D22: 14 | E22: =D22-C22 -> 1 | F22: X | J22: X | N22: =IF(COUNTA(F22:L22)=0,"— não preenchido",IF(COUNTIF(F22:I22,"X")<>1,"FALTA/DUPLA: CONDIÇÃO DA PLATAFORMA",IF(COUNTIF(J22:L22,"X")<>1,"FALTA/DUPLA: DRENAGEM SUPERFICIAL","OK"))) -> OK
A23: 126ETO0130 | B23: C | C23: 14 | D23: 15 | E23: =D23-C23 -> 1 | F23: X | J23: X | N23: =IF(COUNTA(F23:L23)=0,"— não preenchido",IF(COUNTIF(F23:I23,"X")<>1,"FALTA/DUPLA: CONDIÇÃO DA PLATAFORMA",IF(COUNTIF(J23:L23,"X")<>1,"FALTA/DUPLA: DRENAGEM SUPERFICIAL","OK"))) -> OK
A24: 126ETO0130 | B24: C | C24: 15 | D24: 16 | E24: =D24-C24 -> 1 | F24: X | J24: X | N24: =IF(COUNTA(F24:L24)=0,"— não preenchido",IF(COUNTIF(F24:I24,"X")<>1,"FALTA/DUPLA: CONDIÇÃO DA PLATAFORMA",IF(COUNTIF(J24:L24,"X")<>1,"FALTA/DUPLA: DRENAGEM SUPERFICIAL","OK"))) -> OK
A25: 126ETO0130 | B25: C | C25: 16 | D25: 17 | E25: =D25-C25 -> 1 | F25: X | J25: X | M25: GREIDE REBAIXADO | N25: =IF(COUNTA(F25:L25)=0,"— não preenchido",IF(COUNTIF(F25:I25,"X")<>1,"FALTA/DUPLA: CONDIÇÃO DA PLATAFORMA",IF(COUNTIF(J25:L25,"X")<>1,"FALTA/DUPLA: DRENAGEM SUPERFICIAL","OK"))) -> OK
A26: 126ETO0130 | B26: C | C26: 17 | D26: 18 | E26: =D26-C26 -> 1 | F26: X | J26: X | M26: GREIDE REBAIXADO | N26: =IF(COUNTA(F26:L26)=0,"— não preenchido",IF(COUNTIF(F26:I26,"X")<>1,"FALTA/DUPLA: CONDIÇÃO DA PLATAFORMA",IF(COUNTIF(J26:L26,"X")<>1,"FALTA/DUPLA: DRENAGEM SUPERFICIAL","OK"))) -> OK
A27: 126ETO0130 | B27: C | C27: 18 | D27: 19 | E27: =D27-C27 -> 1 | F27: X | J27: X | M27: GREIDE REBAIXADO | N27: =IF(COUNTA(F27:L27)=0,"— não preenchido",IF(COUNTIF(F27:I27,"X")<>1,"FALTA/DUPLA: CONDIÇÃO DA PLATAFORMA",IF(COUNTIF(J27:L27,"X")<>1,"FALTA/DUPLA: DRENAGEM SUPERFICIAL","OK"))) -> OK
A28: 126ETO0130 | B28: C | C28: 19 | D28: 20 | E28: =D28-C28 -> 1 | F28: X | J28: X | M28: GREIDE REBAIXADO | N28: =IF(COUNTA(F28:L28)=0,"— não preenchido",IF(COUNTIF(F28:I28,"X")<>1,"FALTA/DUPLA: CONDIÇÃO DA PLATAFORMA",IF(COUNTIF(J28:L28,"X")<>1,"FALTA/DUPLA: DRENAGEM SUPERFICIAL","OK"))) -> OK
A29: 126ETO0130 | B29: C | C29: 20 | D29: 21 | E29: =D29-C29 -> 1 | F29: X | J29: X | M29: GREIDE REBAIXADO | N29: =IF(COUNTA(F29:L29)=0,"— não preenchido",IF(COUNTIF(F29:I29,"X")<>1,"FALTA/DUPLA: CONDIÇÃO DA PLATAFORMA",IF(COUNTIF(J29:L29,"X")<>1,"FALTA/DUPLA: DRENAGEM SUPERFICIAL","OK"))) -> OK
A30: 126ETO0130 | B30: C | C30: 21 | D30: 22 | E30: =D30-C30 -> 1 | F30: X | J30: X | M30: GREIDE REBAIXADO | N30: =IF(COUNTA(F30:L30)=0,"— não preenchido",IF(COUNTIF(F30:I30,"X")<>1,"FALTA/DUPLA: CONDIÇÃO DA PLATAFORMA",IF(COUNTIF(J30:L30,"X")<>1,"FALTA/DUPLA: DRENAGEM SUPERFICIAL","OK"))) -> OK
A31: 126ETO0130 | B31: C | C31: 22 | D31: 23 | E31: =D31-C31 -> 1 | F31: X | J31: X | M31: GREIDE REBAIXADO | N31: =IF(COUNTA(F31:L31)=0,"— não preenchido",IF(COUNTIF(F31:I31,"X")<>1,"FALTA/DUPLA: CONDIÇÃO DA PLATAFORMA",IF(COUNTIF(J31:L31,"X")<>1,"FALTA/DUPLA: DRENAGEM SUPERFICIAL","OK"))) -> OK
A32: 126ETO0130 | B32: C | C32: 23 | D32: 24 | E32: =D32-C32 -> 1 | F32: X | J32: X | M32: GREIDE REBAIXADO | N32: =IF(COUNTA(F32:L32)=0,"— não preenchido",IF(COUNTIF(F32:I32,"X")<>1,"FALTA/DUPLA: CONDIÇÃO DA PLATAFORMA",IF(COUNTIF(J32:L32,"X")<>1,"FALTA/DUPLA: DRENAGEM SUPERFICIAL","OK"))) -> OK
A33: 126ETO0130 | B33: C | C33: 24 | D33: 25 | E33: =D33-C33 -> 1 | F33: X | J33: X | M33: GREIDE REBAIXADO | N33: =IF(COUNTA(F33:L33)=0,"— não preenchido",IF(COUNTIF(F33:I33,"X")<>1,"FALTA/DUPLA: CONDIÇÃO DA PLATAFORMA",IF(COUNTIF(J33:L33,"X")<>1,"FALTA/DUPLA: DRENAGEM SUPERFICIAL","OK"))) -> OK
A34: 126ETO0130 | B34: C | C34: 25 | D34: 26 | E34: =D34-C34 -> 1 | F34: X | J34: X | M34: GREIDE REBAIXADO | N34: =IF(COUNTA(F34:L34)=0,"— não preenchido",IF(COUNTIF(F34:I34,"X")<>1,"FALTA/DUPLA: CONDIÇÃO DA PLATAFORMA",IF(COUNTIF(J34:L34,"X")<>1,"FALTA/DUPLA: DRENAGEM SUPERFICIAL","OK"))) -> OK
A35: 126ETO0130 | B35: C | C35: 26 | D35: 27 | E35: =D35-C35 -> 1 | F35: X | J35: X | M35: GREIDE REBAIXADO | N35: =IF(COUNTA(F35:L35)=0,"— não preenchido",IF(COUNTIF(F35:I35,"X")<>1,"FALTA/DUPLA: CONDIÇÃO DA PLATAFORMA",IF(COUNTIF(J35:L35,"X")<>1,"FALTA/DUPLA: DRENAGEM SUPERFICIAL","OK"))) -> OK
A36: 126ETO0130 | B36: C | C36: 27 | D36: 28 | E36: =D36-C36 -> 1 | F36: X | J36: X | M36: GREIDE REBAIXADO | N36: =IF(COUNTA(F36:L36)=0,"— não preenchido",IF(COUNTIF(F36:I36,"X")<>1,"FALTA/DUPLA: CONDIÇÃO DA PLATAFORMA",IF(COUNTIF(J36:L36,"X")<>1,"FALTA/DUPLA: DRENAGEM SUPERFICIAL","OK"))) -> OK
... A38: 126ETO0130 | B38: C | C38: 29 | D38: 30 | E38: =D38-C38 -> 1 | F38: X | J38: X | M38: GREIDE REBAIXADO | N38: =IF(COUNTA(F38:L38)=0,"— não preenchido",IF(COUNTIF(F38:I38,"X")<>1,"FALTA/DUPLA: CONDIÇÃO DA PLATAFORMA",IF(COUNTIF(J38:L38,"X")<>1,"FALTA/DUPLA: DRENAGEM SUPERFICIAL","OK"))) -> OK
A39: 126ETO0130 | B39: C | C39: 30 | D39: 31 | E39: =D39-C39 -> 1 | G39: X | J39: X | M39: GREIDE REBAIXADO | N39: =IF(COUNTA(F39:L39)=0,"— não preenchido",IF(COUNTIF(F39:I39,"X")<>1,"FALTA/DUPLA: CONDIÇÃO DA PLATAFORMA",IF(COUNTIF(J39:L39,"X")<>1,"FALTA/DUPLA: DRENAGEM SUPERFICIAL","OK"))) -> OK
A40: 126ETO0130 | B40: C | C40: 31 | D40: 32 | E40: =D40-C40 -> 1 | G40: X | J40: X | M40: GREIDE REBAIXADO | N40: =IF(COUNTA(F40:L40)=0,"— não preenchido",IF(COUNTIF(F40:I40,"X")<>1,"FALTA/DUPLA: CONDIÇÃO DA PLATAFORMA",IF(COUNTIF(J40:L40,"X")<>1,"FALTA/DUPLA: DRENAGEM SUPERFICIAL","OK"))) -> OK
A41: 126ETO0130 | B41: C | C41: 32 | D41: 33 | E41: =D41-C41 -> 1 | G41: X | J41: X | M41: GREIDE REBAIXADO | N41: =IF(COUNTA(F41:L41)=0,"— não preenchido",IF(COUNTIF(F41:I41,"X")<>1,"FALTA/DUPLA: CONDIÇÃO DA PLATAFORMA",IF(COUNTIF(J41:L41,"X")<>1,"FALTA/DUPLA: DRENAGEM SUPERFICIAL","OK"))) -> OK
A42: 126ETO0130 | B42: C | C42: 33 | D42: 34 | E42: =D42-C42 -> 1 | G42: X | J42: X | M42: GREIDE REBAIXADO | N42: =IF(COUNTA(F42:L42)=0,"— não preenchido",IF(COUNTIF(F42:I42,"X")<>1,"FALTA/DUPLA: CONDIÇÃO DA PLATAFORMA",IF(COUNTIF(J42:L42,"X")<>1,"FALTA/DUPLA: DRENAGEM SUPERFICIAL","OK"))) -> OK
...

Sheet 12
A1: PROGRAMA DE MANUTENÇÃO RODOVIÁRIA — FICHA DE INSPEÇÃO — RODOVIAS NÃO PAVIMENTADAS | P1: Valores dos gráficos — troca 0 por N/D para a fatia não aparecer. Não editar.
A2: REGIÃO: 1 — TOCANTINÓPOLIS | D2: MÊS / ANO: | G2: DATA: | J2: TÉCNICO: | P2: =IF(F49=0,NA(),F49) -> #N/A | Q2: =IF(G49=0,NA(),G49) -> #N/A | R2: =IF(H49=0,NA(),H49) -> 26.301108 | S2: =IF(I49=0,NA(),I49) -> #N/A | T2: =IF(J49=0,NA(),J49) -> #N/A | U2: =IF(K49=0,NA(),K49) -> 26.301108 | V2: =IF(L49=0,NA(),L49) -> #N/A
A3: TRECHO 12 — RODOVIA TO-134 - TRECHO RIO TOCANTINS (JATOBAL) - AXIXÁ DO TOCANTINS | K3: EXTENSÃO: 26,301 km · 6 S.R.E.
A4: COMO PREENCHER: uma X em UMA coluna de cada grupo, por linha. Se houver mais de um defeito no mesmo km, marque o PREDOMINANTE e escreva o resto em OBSERVAÇÕES. A quilometragem é contada de 0 até o fim de CADA S.R.E. (não é o marco da rodovia).
A6: S.R.E. | B6: SENT. | C6: INÍCIO (KM) | D6: FIM (KM) | E6: EXT. (KM) | F6: CONDIÇÃO DA PLATAFORMA | J6: DRENAGEM SUPERFICIAL | M6: OBSERVAÇÕES | N6: CONFERÊNCIA (só na tela)
F7: BOM | G7: REGULAR | H7: RUIM | I7: PÉSSIMA | J7: LIMPA | K7: OBSTRUÍDA | L7: AUSENTE
A8: S.R.E. 134ETO0020 | JATOBAL *TRECHO URBANO* - FOLHA SECA | LEN · Estadual · 12.569 km · início: -5.447931, -47.645828
A9: 134ETO0020 | B9: C | C9: 0 | D9: 1 | E9: =D9-C9 -> 1 | H9: X | K9: X | M9: PISTA PATROLADA MAS COM IRREGULARIDADES E MAT. FINO SOBRE A PISTA | N9: =IF(COUNTA(F9:L9)=0,"— não preenchido",IF(COUNTIF(F9:I9,"X")<>1,"FALTA/DUPLA: CONDIÇÃO DA PLATAFORMA",IF(COUNTIF(J9:L9,"X")<>1,"FALTA/DUPLA: DRENAGEM SUPERFICIAL","OK"))) -> OK
A10: 134ETO0020 | B10: C | C10: 1 | D10: 2 | E10: =D10-C10 -> 1 | H10: X | K10: X | M10: PISTA PATROLADA MAS COM IRREGULARIDADES E MAT. FINO SOBRE A PISTA | N10: =IF(COUNTA(F10:L10)=0,"— não preenchido",IF(COUNTIF(F10:I10,"X")<>1,"FALTA/DUPLA: CONDIÇÃO DA PLATAFORMA",IF(COUNTIF(J10:L10,"X")<>1,"FALTA/DUPLA: DRENAGEM SUPERFICIAL","OK"))) -> OK
A11: 134ETO0020 | B11: C | C11: 2 | D11: 3 | E11: =D11-C11 -> 1 | H11: X | K11: X | M11: PISTA PATROLADA MAS COM IRREGULARIDADES E MAT. FINO SOBRE A PISTA | N11: =IF(COUNTA(F11:L11)=0,"— não preenchido",IF(COUNTIF(F11:I11,"X")<>1,"FALTA/DUPLA: CONDIÇÃO DA PLATAFORMA",IF(COUNTIF(J11:L11,"X")<>1,"FALTA/DUPLA: DRENAGEM SUPERFICIAL","OK"))) -> OK
A12: 134ETO0020 | B12: C | C12: 3 | D12: 4 | E12: =D12-C12 -> 1 | H12: X | K12: X | M12: PISTA PATROLADA MAS COM IRREGULARIDADES E MAT. FINO SOBRE A PISTA | N12: =IF(COUNTA(F12:L12)=0,"— não preenchido",IF(COUNTIF(F12:I12,"X")<>1,"FALTA/DUPLA: CONDIÇÃO DA PLATAFORMA",IF(COUNTIF(J12:L12,"X")<>1,"FALTA/DUPLA: DRENAGEM SUPERFICIAL","OK"))) -> OK
A13: 134ETO0020 | B13: C | C13: 4 | D13: 5 | E13: =D13-C13 -> 1 | H13: X | K13: X | M13: PISTA PATROLADA MAS COM IRREGULARIDADES E MAT. FINO SOBRE A PISTA | N13: =IF(COUNTA(F13:L13)=0,"— não preenchido",IF(COUNTIF(F13:I13,"X")<>1,"FALTA/DUPLA: CONDIÇÃO DA PLATAFORMA",IF(COUNTIF(J13:L13,"X")<>1,"FALTA/DUPLA: DRENAGEM SUPERFICIAL","OK"))) -> OK
A14: 134ETO0020 | B14: C | C14: 5 | D14: 6 | E14: =D14-C14 -> 1 | H14: X | K14: X | M14: PISTA PATROLADA MAS COM IRREGULARIDADES E MAT. FINO SOBRE A PISTA | N14: =IF(COUNTA(F14:L14)=0,"— não preenchido",IF(COUNTIF(F14:I14,"X")<>1,"FALTA/DUPLA: CONDIÇÃO DA PLATAFORMA",IF(COUNTIF(J14:L14,"X")<>1,"FALTA/DUPLA: DRENAGEM SUPERFICIAL","OK"))) -> OK
A15: 134ETO0020 | B15: C | C15: 6 | D15: 7 | E15: =D15-C15 -> 1 | H15: X | K15: X | M15: PISTA PATROLADA MAS COM IRREGULARIDADES E MAT. FINO SOBRE A PISTA | N15: =IF(COUNTA(F15:L15)=0,"— não preenchido",IF(COUNTIF(F15:I15,"X")<>1,"FALTA/DUPLA: CONDIÇÃO DA PLATAFORMA",IF(COUNTIF(J15:L15,"X")<>1,"FALTA/DUPLA: DRENAGEM SUPERFICIAL","OK"))) -> OK
A16: 134ETO0020 | B16: C | C16: 7 | D16: 8 | E16: =D16-C16 -> 1 | H16: X | K16: X | M16: PISTA PATROLADA MAS COM IRREGULARIDADES E MAT. FINO SOBRE A PISTA | N16: =IF(COUNTA(F16:L16)=0,"— não preenchido",IF(COUNTIF(F16:I16,"X")<>1,"FALTA/DUPLA: CONDIÇÃO DA PLATAFORMA",IF(COUNTIF(J16:L16,"X")<>1,"FALTA/DUPLA: DRENAGEM SUPERFICIAL","OK"))) -> OK
A17: 134ETO0020 | B17: C | C17: 8 | D17: 9 | E17: =D17-C17 -> 1 | H17: X | K17: X | M17: PISTA PATROLADA MAS COM IRREGULARIDADES E MAT. FINO SOBRE A PISTA | N17: =IF(COUNTA(F17:L17)=0,"— não preenchido",IF(COUNTIF(F17:I17,"X")<>1,"FALTA/DUPLA: CONDIÇÃO DA PLATAFORMA",IF(COUNTIF(J17:L17,"X")<>1,"FALTA/DUPLA: DRENAGEM SUPERFICIAL","OK"))) -> OK
A18: 134ETO0020 | B18: C | C18: 9 | D18: 10 | E18: =D18-C18 -> 1 | H18: X | K18: X | M18: PISTA PATROLADA MAS COM IRREGULARIDADES E MAT. FINO SOBRE A PISTA | N18: =IF(COUNTA(F18:L18)=0,"— não preenchido",IF(COUNTIF(F18:I18,"X")<>1,"FALTA/DUPLA: CONDIÇÃO DA PLATAFORMA",IF(COUNTIF(J18:L18,"X")<>1,"FALTA/DUPLA: DRENAGEM SUPERFICIAL","OK"))) -> OK
A19: 134ETO0020 | B19: C | C19: 10 | D19: 11 | E19: =D19-C19 -> 1 | H19: X | K19: X | N19: =IF(COUNTA(F19:L19)=0,"— não preenchido",IF(COUNTIF(F19:I19,"X")<>1,"FALTA/DUPLA: CONDIÇÃO DA PLATAFORMA",IF(COUNTIF(J19:L19,"X")<>1,"FALTA/DUPLA: DRENAGEM SUPERFICIAL","OK"))) -> OK
A20: 134ETO0020 | B20: C | C20: 11 | D20: 12 | E20: =D20-C20 -> 1 | H20: X | K20: X | N20: =IF(COUNTA(F20:L20)=0,"— não preenchido",IF(COUNTIF(F20:I20,"X")<>1,"FALTA/DUPLA: CONDIÇÃO DA PLATAFORMA",IF(COUNTIF(J20:L20,"X")<>1,"FALTA/DUPLA: DRENAGEM SUPERFICIAL","OK"))) -> OK
A21: 134ETO0020 | B21: C | C21: 12 | D21: 12.568883 | E21: =D21-C21 -> 0.56888336 | H21: X | K21: X | M21: KM 12,2 AO 14,2 - PAV. TSD (VILA FOLHA SECA) | N21: =IF(COUNTA(F21:L21)=0,"— não preenchido",IF(COUNTIF(F21:I21,"X")<>1,"FALTA/DUPLA: CONDIÇÃO DA PLATAFORMA",IF(COUNTIF(J21:L21,"X")<>1,"FALTA/DUPLA: DRENAGEM SUPERFICIAL","OK"))) -> OK
A22: S.R.E. 134ETO0030 | FOLHA SECA - JUVELÃNDIA | LEN · Estadual · 1.147 km · início: -5.503344, -47.732567
A23: 134ETO0030 | B23: C | C23: 0 | D23: 1 | E23: =D23-C23 -> 1 | H23: X | K23: X | M23: KM 12,2 AO 14,2 - PAV. TSD (VILA FOLHA SECA) | N23: =IF(COUNTA(F23:L23)=0,"— não preenchido",IF(COUNTIF(F23:I23,"X")<>1,"FALTA/DUPLA: CONDIÇÃO DA PLATAFORMA",IF(COUNTIF(J23:L23,"X")<>1,"FALTA/DUPLA: DRENAGEM SUPERFICIAL","OK"))) -> OK
A24: 134ETO0030 | B24: C | C24: 1 | D24: 1.1473217 | E24: =D24-C24 -> 0.14732173 | H24: X | K24: X | M24: KM 12,2 AO 14,2 - PAV. TSD (VILA FOLHA SECA) | N24: =IF(COUNTA(F24:L24)=0,"— não preenchido",IF(COUNTIF(F24:I24,"X")<>1,"FALTA/DUPLA: CONDIÇÃO DA PLATAFORMA",IF(COUNTIF(J24:L24,"X")<>1,"FALTA/DUPLA: DRENAGEM SUPERFICIAL","OK"))) -> OK
A25: S.R.E. 134ETO0040 | JUVELÃNDIA - VILA SÃO FRANCISCO | LEN · Estadual · 3.559 km · início: -5.507993, -47.737653
A26: 134ETO0040 | B26: C | C26: 0 | D26: 1 | E26: =D26-C26 -> 1 | H26: X | K26: X | M26: MATERIAL FINO SOBRE A PISTA | N26: =IF(COUNTA(F26:L26)=0,"— não preenchido",IF(COUNTIF(F26:I26,"X")<>1,"FALTA/DUPLA: CONDIÇÃO DA PLATAFORMA",IF(COUNTIF(J26:L26,"X")<>1,"FALTA/DUPLA: DRENAGEM SUPERFICIAL","OK"))) -> OK
A27: 134ETO0040 | B27: C | C27: 1 | D27: 2 | E27: =D27-C27 -> 1 | H27: X | K27: X | M27: MATERIAL FINO SOBRE A PISTA | N27: =IF(COUNTA(F27:L27)=0,"— não preenchido",IF(COUNTIF(F27:I27,"X")<>1,"FALTA/DUPLA: CONDIÇÃO DA PLATAFORMA",IF(COUNTIF(J27:L27,"X")<>1,"FALTA/DUPLA: DRENAGEM SUPERFICIAL","OK"))) -> OK
A28: 134ETO0040 | B28: C | C28: 2 | D28: 3 | E28: =D28-C28 -> 1 | H28: X | K28: X | M28: MATERIAL FINO SOBRE A PISTA | N28: =IF(COUNTA(F28:L28)=0,"— não preenchido",IF(COUNTIF(F28:I28,"X")<>1,"FALTA/DUPLA: CONDIÇÃO DA PLATAFORMA",IF(COUNTIF(J28:L28,"X")<>1,"FALTA/DUPLA: DRENAGEM SUPERFICIAL","OK"))) -> OK
A29: 134ETO0040 | B29: C | C29: 3 | D29: 3.558762 | E29: =D29-C29 -> 0.55876202 | H29: X | K29: X | M29: MATERIAL FINO SOBRE A PISTA | N29: =IF(COUNTA(F29:L29)=0,"— não preenchido",IF(COUNTIF(F29:I29,"X")<>1,"FALTA/DUPLA: CONDIÇÃO DA PLATAFORMA",IF(COUNTIF(J29:L29,"X")<>1,"FALTA/DUPLA: DRENAGEM SUPERFICIAL","OK"))) -> OK
A30: S.R.E. 134ETO0050 | VILA SÃO FRANCISCO - SANTA LUZIA | LEN · Estadual · 4.310 km · início: -5.538609, -47.753094
A31: 134ETO0050 | B31: C | C31: 0 | D31: 1 | E31: =D31-C31 -> 1 | H31: X | K31: X | M31: MATERIAL FINO SOBRE A PISTA | N31: =IF(COUNTA(F31:L31)=0,"— não preenchido",IF(COUNTIF(F31:I31,"X")<>1,"FALTA/DUPLA: CONDIÇÃO DA PLATAFORMA",IF(COUNTIF(J31:L31,"X")<>1,"FALTA/DUPLA: DRENAGEM SUPERFICIAL","OK"))) -> OK
A32: 134ETO0050 | B32: C | C32: 1 | D32: 2 | E32: =D32-C32 -> 1 | H32: X | K32: X | M32: MATERIAL FINO SOBRE A PISTA | N32: =IF(COUNTA(F32:L32)=0,"— não preenchido",IF(COUNTIF(F32:I32,"X")<>1,"FALTA/DUPLA: CONDIÇÃO DA PLATAFORMA",IF(COUNTIF(J32:L32,"X")<>1,"FALTA/DUPLA: DRENAGEM SUPERFICIAL","OK"))) -> OK
A33: 134ETO0050 | B33: C | C33: 2 | D33: 3 | E33: =D33-C33 -> 1 | H33: X | K33: X | M33: MATERIAL FINO SOBRE A PISTA | N33: =IF(COUNTA(F33:L33)=0,"— não preenchido",IF(COUNTIF(F33:I33,"X")<>1,"FALTA/DUPLA: CONDIÇÃO DA PLATAFORMA",IF(COUNTIF(J33:L33,"X")<>1,"FALTA/DUPLA: DRENAGEM SUPERFICIAL","OK"))) -> OK
A34: 134ETO0050 | B34: C | C34: 3 | D34: 4 | E34: =D34-C34 -> 1 | H34: X | K34: X | M34: MATERIAL FINO SOBRE A PISTA | N34: =IF(COUNTA(F34:L34)=0,"— não preenchido",IF(COUNTIF(F34:I34,"X")<>1,"FALTA/DUPLA: CONDIÇÃO DA PLATAFORMA",IF(COUNTIF(J34:L34,"X")<>1,"FALTA/DUPLA: DRENAGEM SUPERFICIAL","OK"))) -> OK
A35: 134ETO0050 | B35: C | C35: 4 | D35: 4.3098893 | E35: =D35-C35 -> 0.3098893 | H35: X | K35: X | M35: MATERIAL FINO SOBRE A PISTA | N35: =IF(COUNTA(F35:L35)=0,"— não preenchido",IF(COUNTIF(F35:I35,"X")<>1,"FALTA/DUPLA: CONDIÇÃO DA PLATAFORMA",IF(COUNTIF(J35:L35,"X")<>1,"FALTA/DUPLA: DRENAGEM SUPERFICIAL","OK"))) -> OK
A36: S.R.E. 134ETO0060 | SANTA LUZIA - MORADA NOVA | LEN · Estadual · 1.062 km · início: -5.574848, -47.757213
A37: 134ETO0060 | B37: C | C37: 0 | D37: 1 | E37: =D37-C37 -> 1 | H37: X | K37: X | N37: =IF(COUNTA(F37:L37)=0,"— não preenchido",IF(COUNTIF(F37:I37,"X")<>1,"FALTA/DUPLA: CONDIÇÃO DA PLATAFORMA",IF(COUNTIF(J37:L37,"X")<>1,"FALTA/DUPLA: DRENAGEM SUPERFICIAL","OK"))) -> OK
A38: 134ETO0060 | B38: C | C38: 1 | D38: 1.0618146 | E38: =D38-C38 -> 0.06181458 | H38: X | K38: X | N38: =IF(COUNTA(F38:L38)=0,"— não preenchido",IF(COUNTIF(F38:I38,"X")<>1,"FALTA/DUPLA: CONDIÇÃO DA PLATAFORMA",IF(COUNTIF(J38:L38,"X")<>1,"FALTA/DUPLA: DRENAGEM SUPERFICIAL","OK"))) -> OK
A39: S.R.E. 134ETO0070 | MORADA NOVA - AXIXÁ DO TOCANTINS *TRECHO URBANO* | LEN · Estadual · 3.654 km · início: -5.579928, -47.762447
A40: 134ETO0070 | B40: C | C40: 0 | D40: 1 | E40: =D40-C40 -> 1 | H40: X | K40: X | N40: =IF(COUNTA(F40:L40)=0,"— não preenchido",IF(COUNTIF(F40:I40,"X")<>1,"FALTA/DUPLA: CONDIÇÃO DA PLATAFORMA",IF(COUNTIF(J40:L40,"X")<>1,"FALTA/DUPLA: DRENAGEM SUPERFICIAL","OK"))) -> OK
A41: 134ETO0070 | B41: C | C41: 1 | D41: 2 | E41: =D41-C41 -> 1 | H41: X | K41: X | N41: =IF(COUNTA(F41:L41)=0,"— não preenchido",IF(COUNTIF(F41:I41,"X")<>1,"FALTA/DUPLA: CONDIÇÃO DA PLATAFORMA",IF(COUNTIF(J41:L41,"X")<>1,"FALTA/DUPLA: DRENAGEM SUPERFICIAL","OK"))) -> OK
...

Sheet 20
A1: PROGRAMA DE MANUTENÇÃO RODOVIÁRIA — FICHA DE INSPEÇÃO — RODOVIAS NÃO PAVIMENTADAS | P1: Valores dos gráficos — troca 0 por N/D para a fatia não aparecer. Não editar.
A2: REGIÃO: 1 — TOCANTINÓPOLIS | D2: MÊS / ANO: | G2: DATA: | J2: TÉCNICO: | P2: =IF(F40=0,NA(),F40) -> 8 | Q2: =IF(G40=0,NA(),G40) -> 13.209234 | R2: =IF(H40=0,NA(),H40) -> #N/A | S2: =IF(I40=0,NA(),I40) -> #N/A | T2: =IF(J40=0,NA(),J40) -> 3.6392069 | U2: =IF(K40=0,NA(),K40) -> 17.570027 | V2: =IF(L40=0,NA(),L40) -> #N/A
A3: TRECHO 20 — RODOVIA TO-201 - TRECHO ESPERANTINA - DIVISA TO-MA | K3: EXTENSÃO: 22,698 km · 3 S.R.E.
A4: COMO PREENCHER: uma X em UMA coluna de cada grupo, por linha. Se houver mais de um defeito no mesmo km, marque o PREDOMINANTE e escreva o resto em OBSERVAÇÕES. A quilometragem é contada de 0 até o fim de CADA S.R.E. (não é o marco da rodovia).
A6: S.R.E. | B6: SENT. | C6: INÍCIO (KM) | D6: FIM (KM) | E6: EXT. (KM) | F6: CONDIÇÃO DA PLATAFORMA | J6: DRENAGEM SUPERFICIAL | M6: OBSERVAÇÕES | N6: CONFERÊNCIA (só na tela)
F7: BOM | G7: REGULAR | H7: RUIM | I7: PÉSSIMA | J7: LIMPA | K7: OBSTRUÍDA | L7: AUSENTE
A8: S.R.E. 201ETO0250 | ESPERANTINA *TRECHO URBANO* - ENTR. ACESSO DIV. TO-PA (PEDRA GRANDE) | LEN · Estadual · 1.489 km · início: -5.370541, -48.544992
A9: 201ETO0250 | B9: C | C9: 0 | D9: 1 | E9: =D9-C9 -> 1 | N9: =IF(COUNTA(F9:L9)=0,"— não preenchido",IF(COUNTIF(F9:I9,"X")<>1,"FALTA/DUPLA: CONDIÇÃO DA PLATAFORMA",IF(COUNTIF(J9:L9,"X")<>1,"FALTA/DUPLA: DRENAGEM SUPERFICIAL","OK"))) -> — não preenchido
A10: 201ETO0250 | B10: C | C10: 1 | D10: 1.4887814 | E10: =D10-C10 -> 0.48878136 | N10: =IF(COUNTA(F10:L10)=0,"— não preenchido",IF(COUNTIF(F10:I10,"X")<>1,"FALTA/DUPLA: CONDIÇÃO DA PLATAFORMA",IF(COUNTIF(J10:L10,"X")<>1,"FALTA/DUPLA: DRENAGEM SUPERFICIAL","OK"))) -> — não preenchido
A11: S.R.E. 201ETO0260 | ENTR. ACESSO DIV. TO-PA (PEDRA GRANDE) - PEDRA DE AMOLAR | LEN · Estadual · 8.639 km · início: -5.373241, -48.55809
A12: 201ETO0260 | B12: C | C12: 0 | D12: 1 | E12: =D12-C12 -> 1 | F12: X | J12: X | N12: =IF(COUNTA(F12:L12)=0,"— não preenchido",IF(COUNTIF(F12:I12,"X")<>1,"FALTA/DUPLA: CONDIÇÃO DA PLATAFORMA",IF(COUNTIF(J12:L12,"X")<>1,"FALTA/DUPLA: DRENAGEM SUPERFICIAL","OK"))) -> OK
A13: 201ETO0260 | B13: C | C13: 1 | D13: 2 | E13: =D13-C13 -> 1 | F13: X | J13: X | N13: =IF(COUNTA(F13:L13)=0,"— não preenchido",IF(COUNTIF(F13:I13,"X")<>1,"FALTA/DUPLA: CONDIÇÃO DA PLATAFORMA",IF(COUNTIF(J13:L13,"X")<>1,"FALTA/DUPLA: DRENAGEM SUPERFICIAL","OK"))) -> OK
A14: 201ETO0260 | B14: C | C14: 2 | D14: 3 | E14: =D14-C14 -> 1 | G14: X | J14: X | N14: =IF(COUNTA(F14:L14)=0,"— não preenchido",IF(COUNTIF(F14:I14,"X")<>1,"FALTA/DUPLA: CONDIÇÃO DA PLATAFORMA",IF(COUNTIF(J14:L14,"X")<>1,"FALTA/DUPLA: DRENAGEM SUPERFICIAL","OK"))) -> OK
A15: 201ETO0260 | B15: C | C15: 3 | D15: 4 | E15: =D15-C15 -> 1 | G15: X | K15: X | N15: =IF(COUNTA(F15:L15)=0,"— não preenchido",IF(COUNTIF(F15:I15,"X")<>1,"FALTA/DUPLA: CONDIÇÃO DA PLATAFORMA",IF(COUNTIF(J15:L15,"X")<>1,"FALTA/DUPLA: DRENAGEM SUPERFICIAL","OK"))) -> OK
A16: 201ETO0260 | B16: C | C16: 4 | D16: 5 | E16: =D16-C16 -> 1 | G16: X | K16: X | N16: =IF(COUNTA(F16:L16)=0,"— não preenchido",IF(COUNTIF(F16:I16,"X")<>1,"FALTA/DUPLA: CONDIÇÃO DA PLATAFORMA",IF(COUNTIF(J16:L16,"X")<>1,"FALTA/DUPLA: DRENAGEM SUPERFICIAL","OK"))) -> OK
A17: 201ETO0260 | B17: C | C17: 5 | D17: 6 | E17: =D17-C17 -> 1 | G17: X | K17: X | N17: =IF(COUNTA(F17:L17)=0,"— não preenchido",IF(COUNTIF(F17:I17,"X")<>1,"FALTA/DUPLA: CONDIÇÃO DA PLATAFORMA",IF(COUNTIF(J17:L17,"X")<>1,"FALTA/DUPLA: DRENAGEM SUPERFICIAL","OK"))) -> OK
A18: 201ETO0260 | B18: C | C18: 6 | D18: 7 | E18: =D18-C18 -> 1 | G18: X | K18: X | N18: =IF(COUNTA(F18:L18)=0,"— não preenchido",IF(COUNTIF(F18:I18,"X")<>1,"FALTA/DUPLA: CONDIÇÃO DA PLATAFORMA",IF(COUNTIF(J18:L18,"X")<>1,"FALTA/DUPLA: DRENAGEM SUPERFICIAL","OK"))) -> OK
A19: 201ETO0260 | B19: C | C19: 7 | D19: 8 | E19: =D19-C19 -> 1 | G19: X | K19: X | N19: =IF(COUNTA(F19:L19)=0,"— não preenchido",IF(COUNTIF(F19:I19,"X")<>1,"FALTA/DUPLA: CONDIÇÃO DA PLATAFORMA",IF(COUNTIF(J19:L19,"X")<>1,"FALTA/DUPLA: DRENAGEM SUPERFICIAL","OK"))) -> OK
A20: 201ETO0260 | B20: C | C20: 8 | D20: 8.6392069 | E20: =D20-C20 -> 0.63920691 | G20: X | J20: X | N20: =IF(COUNTA(F20:L20)=0,"— não preenchido",IF(COUNTIF(F20:I20,"X")<>1,"FALTA/DUPLA: CONDIÇÃO DA PLATAFORMA",IF(COUNTIF(J20:L20,"X")<>1,"FALTA/DUPLA: DRENAGEM SUPERFICIAL","OK"))) -> OK
A21: S.R.E. 201ETO0270 | PEDRA DE AMOLAR - DIV TO-PA-MA | LEN · Estadual · 12.570 km · início: -5.345945, -48.626757
A22: 201ETO0270 | B22: C | C22: 0 | D22: 1 | E22: =D22-C22 -> 1 | G22: X | K22: X | N22: =IF(COUNTA(F22:L22)=0,"— não preenchido",IF(COUNTIF(F22:I22,"X")<>1,"FALTA/DUPLA: CONDIÇÃO DA PLATAFORMA",IF(COUNTIF(J22:L22,"X")<>1,"FALTA/DUPLA: DRENAGEM SUPERFICIAL","OK"))) -> OK
A23: 201ETO0270 | B23: C | C23: 1 | D23: 2 | E23: =D23-C23 -> 1 | G23: X | K23: X | N23: =IF(COUNTA(F23:L23)=0,"— não preenchido",IF(COUNTIF(F23:I23,"X")<>1,"FALTA/DUPLA: CONDIÇÃO DA PLATAFORMA",IF(COUNTIF(J23:L23,"X")<>1,"FALTA/DUPLA: DRENAGEM SUPERFICIAL","OK"))) -> OK
A24: 201ETO0270 | B24: C | C24: 2 | D24: 3 | E24: =D24-C24 -> 1 | G24: X | K24: X | N24: =IF(COUNTA(F24:L24)=0,"— não preenchido",IF(COUNTIF(F24:I24,"X")<>1,"FALTA/DUPLA: CONDIÇÃO DA PLATAFORMA",IF(COUNTIF(J24:L24,"X")<>1,"FALTA/DUPLA: DRENAGEM SUPERFICIAL","OK"))) -> OK
A25: 201ETO0270 | B25: C | C25: 3 | D25: 4 | E25: =D25-C25 -> 1 | G25: X | K25: X | N25: =IF(COUNTA(F25:L25)=0,"— não preenchido",IF(COUNTIF(F25:I25,"X")<>1,"FALTA/DUPLA: CONDIÇÃO DA PLATAFORMA",IF(COUNTIF(J25:L25,"X")<>1,"FALTA/DUPLA: DRENAGEM SUPERFICIAL","OK"))) -> OK
A26: 201ETO0270 | B26: C | C26: 4 | D26: 5 | E26: =D26-C26 -> 1 | F26: X | K26: X | N26: =IF(COUNTA(F26:L26)=0,"— não preenchido",IF(COUNTIF(F26:I26,"X")<>1,"FALTA/DUPLA: CONDIÇÃO DA PLATAFORMA",IF(COUNTIF(J26:L26,"X")<>1,"FALTA/DUPLA: DRENAGEM SUPERFICIAL","OK"))) -> OK
A27: 201ETO0270 | B27: C | C27: 5 | D27: 6 | E27: =D27-C27 -> 1 | F27: X | K27: X | N27: =IF(COUNTA(F27:L27)=0,"— não preenchido",IF(COUNTIF(F27:I27,"X")<>1,"FALTA/DUPLA: CONDIÇÃO DA PLATAFORMA",IF(COUNTIF(J27:L27,"X")<>1,"FALTA/DUPLA: DRENAGEM SUPERFICIAL","OK"))) -> OK
A28: 201ETO0270 | B28: C | C28: 6 | D28: 7 | E28: =D28-C28 -> 1 | F28: X | K28: X | N28: =IF(COUNTA(F28:L28)=0,"— não preenchido",IF(COUNTIF(F28:I28,"X")<>1,"FALTA/DUPLA: CONDIÇÃO DA PLATAFORMA",IF(COUNTIF(J28:L28,"X")<>1,"FALTA/DUPLA: DRENAGEM SUPERFICIAL","OK"))) -> OK
A29: 201ETO0270 | B29: C | C29: 7 | D29: 8 | E29: =D29-C29 -> 1 | F29: X | K29: X | N29: =IF(COUNTA(F29:L29)=0,"— não preenchido",IF(COUNTIF(F29:I29,"X")<>1,"FALTA/DUPLA: CONDIÇÃO DA PLATAFORMA",IF(COUNTIF(J29:L29,"X")<>1,"FALTA/DUPLA: DRENAGEM SUPERFICIAL","OK"))) -> OK
A30: 201ETO0270 | B30: C | C30: 8 | D30: 9 | E30: =D30-C30 -> 1 | F30: X | K30: X | N30: =IF(COUNTA(F30:L30)=0,"— não preenchido",IF(COUNTIF(F30:I30,"X")<>1,"FALTA/DUPLA: CONDIÇÃO DA PLATAFORMA",IF(COUNTIF(J30:L30,"X")<>1,"FALTA/DUPLA: DRENAGEM SUPERFICIAL","OK"))) -> OK
A31: 201ETO0270 | B31: C | C31: 9 | D31: 10 | E31: =D31-C31 -> 1 | F31: X | K31: X | N31: =IF(COUNTA(F31:L31)=0,"— não preenchido",IF(COUNTIF(F31:I31,"X")<>1,"FALTA/DUPLA: CONDIÇÃO DA PLATAFORMA",IF(COUNTIF(J31:L31,"X")<>1,"FALTA/DUPLA: DRENAGEM SUPERFICIAL","OK"))) -> OK
A32: 201ETO0270 | B32: C | C32: 10 | D32: 11 | E32: =D32-C32 -> 1 | G32: X | K32: X | N32: =IF(COUNTA(F32:L32)=0,"— não preenchido",IF(COUNTIF(F32:I32,"X")<>1,"FALTA/DUPLA: CONDIÇÃO DA PLATAFORMA",IF(COUNTIF(J32:L32,"X")<>1,"FALTA/DUPLA: DRENAGEM SUPERFICIAL","OK"))) -> OK
A33: 201ETO0270 | B33: C | C33: 11 | D33: 12 | E33: =D33-C33 -> 1 | G33: X | K33: X | N33: =IF(COUNTA(F33:L33)=0,"— não preenchido",IF(COUNTIF(F33:I33,"X")<>1,"FALTA/DUPLA: CONDIÇÃO DA PLATAFORMA",IF(COUNTIF(J33:L33,"X")<>1,"FALTA/DUPLA: DRENAGEM SUPERFICIAL","OK"))) -> OK
A34: 201ETO0270 | B34: C | C34: 12 | D34: 12.570027 | E34: =D34-C34 -> 0.57002706 | G34: X | K34: X | N34: =IF(COUNTA(F34:L34)=0,"— não preenchido",IF(COUNTIF(F34:I34,"X")<>1,"FALTA/DUPLA: CONDIÇÃO DA PLATAFORMA",IF(COUNTIF(J34:L34,"X")<>1,"FALTA/DUPLA: DRENAGEM SUPERFICIAL","OK"))) -> OK
A36: ____________________________________________ | G36: ____________________________________________
A37: TÉCNICO RESPONSÁVEL PELA INSPEÇÃO | G37: VISTO DA SUPERVISÃO
A39: RESUMO DO TRECHO — KM LANÇADO POR ITEM
A40: KM LANÇADO | F40: =SUMIF(F$9:F$34,"X",$E$9:$E$34) -> 8 | G40: =SUMIF(G$9:G$34,"X",$E$9:$E$34) -> 13.209234 | H40: =SUMIF(H$9:H$34,"X",$E$9:$E$34) -> 0 | I40: =SUMIF(I$9:I$34,"X",$E$9:$E$34) -> 0 | J40: =SUMIF(J$9:J$34,"X",$E$9:$E$34) -> 3.6392069 | K40: =SUMIF(K$9:K$34,"X",$E$9:$E$34) -> 17.570027 | L40: =SUMIF(L$9:L$34,"X",$E$9:$E$34) -> 0
A41: % DA EXTENSÃO | F41: =IF($I43=0,0,F40/$I43) -> 0.35245372 | G41: =IF($I43=0,0,G40/$I43) -> 0.58195546 | H41: =IF($I43=0,0,H40/$I43) -> 0 | I41: =IF($I43=0,0,I40/$I43) -> 0 | J41: =IF($I43=0,0,J40/$I43) -> 0.1603315 | K41: =IF($I43=0,0,K40/$I43) -> 0.77407768 | L41: =IF($I43=0,0,L40/$I43) -> 0
A42: CONFERÊNCIA POR GRUPO | F42: =IF(SUM(F40:I40)=0,"— não preenchido",IF(ROUND(SUM(F40:I40)-$I43,3)=0,"OK — "&ROUND(SUM(F40:I40),3)&" km","ERRO — dif. de "&ROUND(SUM(F40:I40)-$I43,3)&" km")) -> ERRO — dif. de -1,489 km | J42: =IF(SUM(J40:L40)=0,"— não preenchido",IF(ROUND(SUM(J40:L40)-$I43,3)=0,"OK — "&ROUND(SUM(J40:L40),3)&" km","ERRO — dif. de "&ROUND(SUM(J40:L40)-$I43,3)&" km")) -> ERRO — dif. de -1,489 km
A43: EXTENSÃO TOTAL DO TRECHO | I43: =SUM(E9:E34) -> 22.698015 | M43: =COUNTIF(N9:N34,"OK")&" de "&COUNT($E$9:$E$34)&" linhas conferidas" -> 22 de 24 linhas conferidas
...

Sheet 21
A1: PROGRAMA DE MANUTENÇÃO RODOVIÁRIA — FICHA DE INSPEÇÃO — RODOVIAS NÃO PAVIMENTADAS | P1: Valores dos gráficos — troca 0 por N/D para a fatia não aparecer. Não editar.
A2: REGIÃO: 1 — TOCANTINÓPOLIS | D2: MÊS / ANO: | G2: DATA: | J2: TÉCNICO: | P2: =IF(F40=0,NA(),F40) -> 16.673932 | Q2: =IF(G40=0,NA(),G40) -> 9 | R2: =IF(H40=0,NA(),H40) -> #N/A | S2: =IF(I40=0,NA(),I40) -> #N/A | T2: =IF(J40=0,NA(),J40) -> 14.673932 | U2: =IF(K40=0,NA(),K40) -> 11 | V2: =IF(L40=0,NA(),L40) -> #N/A
A3: TRECHO 21 — RODOVIA TO-205 - TRECHO SÃO BENTO DO TOCANTINS - ENTR. TO-010 | K3: EXTENSÃO: 25,674 km · 1 S.R.E.
A4: COMO PREENCHER: uma X em UMA coluna de cada grupo, por linha. Se houver mais de um defeito no mesmo km, marque o PREDOMINANTE e escreva o resto em OBSERVAÇÕES. A quilometragem é contada de 0 até o fim de CADA S.R.E. (não é o marco da rodovia).
A6: S.R.E. | B6: SENT. | C6: INÍCIO (KM) | D6: FIM (KM) | E6: EXT. (KM) | F6: CONDIÇÃO DA PLATAFORMA | J6: DRENAGEM SUPERFICIAL | M6: OBSERVAÇÕES | N6: CONFERÊNCIA (só na tela)
F7: BOM | G7: REGULAR | H7: RUIM | I7: PÉSSIMA | J7: LIMPA | K7: OBSTRUÍDA | L7: AUSENTE
A8: S.R.E. 205ETO0010 | SÃO BENTO DO TO * TRECHO URBANO* - ENTR. TO-010 (CAMPO ALEGRE) | LEN · Estadual · 25.674 km · início: -6.027173, -47.92714
A9: 205ETO0010 | B9: C | C9: 0 | D9: 1 | E9: =D9-C9 -> 1 | F9: X | K9: X | N9: =IF(COUNTA(F9:L9)=0,"— não preenchido",IF(COUNTIF(F9:I9,"X")<>1,"FALTA/DUPLA: CONDIÇÃO DA PLATAFORMA",IF(COUNTIF(J9:L9,"X")<>1,"FALTA/DUPLA: DRENAGEM SUPERFICIAL","OK"))) -> OK
A10: 205ETO0010 | B10: C | C10: 1 | D10: 2 | E10: =D10-C10 -> 1 | F10: X | K10: X | N10: =IF(COUNTA(F10:L10)=0,"— não preenchido",IF(COUNTIF(F10:I10,"X")<>1,"FALTA/DUPLA: CONDIÇÃO DA PLATAFORMA",IF(COUNTIF(J10:L10,"X")<>1,"FALTA/DUPLA: DRENAGEM SUPERFICIAL","OK"))) -> OK
A11: 205ETO0010 | B11: C | C11: 2 | D11: 3 | E11: =D11-C11 -> 1 | F11: X | K11: X | N11: =IF(COUNTA(F11:L11)=0,"— não preenchido",IF(COUNTIF(F11:I11,"X")<>1,"FALTA/DUPLA: CONDIÇÃO DA PLATAFORMA",IF(COUNTIF(J11:L11,"X")<>1,"FALTA/DUPLA: DRENAGEM SUPERFICIAL","OK"))) -> OK
A12: 205ETO0010 | B12: C | C12: 3 | D12: 4 | E12: =D12-C12 -> 1 | F12: X | K12: X | M12: AUSENCIA DE DRENAGEM E MATERIAL FINO SOBRE A PISTA | N12: =IF(COUNTA(F12:L12)=0,"— não preenchido",IF(COUNTIF(F12:I12,"X")<>1,"FALTA/DUPLA: CONDIÇÃO DA PLATAFORMA",IF(COUNTIF(J12:L12,"X")<>1,"FALTA/DUPLA: DRENAGEM SUPERFICIAL","OK"))) -> OK
A13: 205ETO0010 | B13: C | C13: 4 | D13: 5 | E13: =D13-C13 -> 1 | G13: X | K13: X | N13: =IF(COUNTA(F13:L13)=0,"— não preenchido",IF(COUNTIF(F13:I13,"X")<>1,"FALTA/DUPLA: CONDIÇÃO DA PLATAFORMA",IF(COUNTIF(J13:L13,"X")<>1,"FALTA/DUPLA: DRENAGEM SUPERFICIAL","OK"))) -> OK
A14: 205ETO0010 | B14: C | C14: 5 | D14: 6 | E14: =D14-C14 -> 1 | F14: X | K14: X | N14: =IF(COUNTA(F14:L14)=0,"— não preenchido",IF(COUNTIF(F14:I14,"X")<>1,"FALTA/DUPLA: CONDIÇÃO DA PLATAFORMA",IF(COUNTIF(J14:L14,"X")<>1,"FALTA/DUPLA: DRENAGEM SUPERFICIAL","OK"))) -> OK
A15: 205ETO0010 | B15: C | C15: 6 | D15: 7 | E15: =D15-C15 -> 1 | G15: X | J15: X | N15: =IF(COUNTA(F15:L15)=0,"— não preenchido",IF(COUNTIF(F15:I15,"X")<>1,"FALTA/DUPLA: CONDIÇÃO DA PLATAFORMA",IF(COUNTIF(J15:L15,"X")<>1,"FALTA/DUPLA: DRENAGEM SUPERFICIAL","OK"))) -> OK
A16: 205ETO0010 | B16: C | C16: 7 | D16: 8 | E16: =D16-C16 -> 1 | G16: X | J16: X | M16: GREIDE REBAIXADO | N16: =IF(COUNTA(F16:L16)=0,"— não preenchido",IF(COUNTIF(F16:I16,"X")<>1,"FALTA/DUPLA: CONDIÇÃO DA PLATAFORMA",IF(COUNTIF(J16:L16,"X")<>1,"FALTA/DUPLA: DRENAGEM SUPERFICIAL","OK"))) -> OK
A17: 205ETO0010 | B17: C | C17: 8 | D17: 9 | E17: =D17-C17 -> 1 | F17: X | J17: X | M17: GREIDE REBAIXADO | N17: =IF(COUNTA(F17:L17)=0,"— não preenchido",IF(COUNTIF(F17:I17,"X")<>1,"FALTA/DUPLA: CONDIÇÃO DA PLATAFORMA",IF(COUNTIF(J17:L17,"X")<>1,"FALTA/DUPLA: DRENAGEM SUPERFICIAL","OK"))) -> OK
A18: 205ETO0010 | B18: C | C18: 9 | D18: 10 | E18: =D18-C18 -> 1 | F18: X | J18: X | N18: =IF(COUNTA(F18:L18)=0,"— não preenchido",IF(COUNTIF(F18:I18,"X")<>1,"FALTA/DUPLA: CONDIÇÃO DA PLATAFORMA",IF(COUNTIF(J18:L18,"X")<>1,"FALTA/DUPLA: DRENAGEM SUPERFICIAL","OK"))) -> OK
A19: 205ETO0010 | B19: C | C19: 10 | D19: 11 | E19: =D19-C19 -> 1 | F19: X | K19: X | N19: =IF(COUNTA(F19:L19)=0,"— não preenchido",IF(COUNTIF(F19:I19,"X")<>1,"FALTA/DUPLA: CONDIÇÃO DA PLATAFORMA",IF(COUNTIF(J19:L19,"X")<>1,"FALTA/DUPLA: DRENAGEM SUPERFICIAL","OK"))) -> OK
A20: 205ETO0010 | B20: C | C20: 11 | D20: 12 | E20: =D20-C20 -> 1 | F20: X | K20: X | N20: =IF(COUNTA(F20:L20)=0,"— não preenchido",IF(COUNTIF(F20:I20,"X")<>1,"FALTA/DUPLA: CONDIÇÃO DA PLATAFORMA",IF(COUNTIF(J20:L20,"X")<>1,"FALTA/DUPLA: DRENAGEM SUPERFICIAL","OK"))) -> OK
A21: 205ETO0010 | B21: C | C21: 12 | D21: 13 | E21: =D21-C21 -> 1 | G21: X | K21: X | N21: =IF(COUNTA(F21:L21)=0,"— não preenchido",IF(COUNTIF(F21:I21,"X")<>1,"FALTA/DUPLA: CONDIÇÃO DA PLATAFORMA",IF(COUNTIF(J21:L21,"X")<>1,"FALTA/DUPLA: DRENAGEM SUPERFICIAL","OK"))) -> OK
A22: 205ETO0010 | B22: C | C22: 13 | D22: 14 | E22: =D22-C22 -> 1 | G22: X | J22: X | N22: =IF(COUNTA(F22:L22)=0,"— não preenchido",IF(COUNTIF(F22:I22,"X")<>1,"FALTA/DUPLA: CONDIÇÃO DA PLATAFORMA",IF(COUNTIF(J22:L22,"X")<>1,"FALTA/DUPLA: DRENAGEM SUPERFICIAL","OK"))) -> OK
A23: 205ETO0010 | B23: C | C23: 14 | D23: 15 | E23: =D23-C23 -> 1 | G23: X | J23: X | N23: =IF(COUNTA(F23:L23)=0,"— não preenchido",IF(COUNTIF(F23:I23,"X")<>1,"FALTA/DUPLA: CONDIÇÃO DA PLATAFORMA",IF(COUNTIF(J23:L23,"X")<>1,"FALTA/DUPLA: DRENAGEM SUPERFICIAL","OK"))) -> OK
A24: 205ETO0010 | B24: C | C24: 15 | D24: 16 | E24: =D24-C24 -> 1 | G24: X | J24: X | N24: =IF(COUNTA(F24:L24)=0,"— não preenchido",IF(COUNTIF(F24:I24,"X")<>1,"FALTA/DUPLA: CONDIÇÃO DA PLATAFORMA",IF(COUNTIF(J24:L24,"X")<>1,"FALTA/DUPLA: DRENAGEM SUPERFICIAL","OK"))) -> OK
A25: 205ETO0010 | B25: C | C25: 16 | D25: 17 | E25: =D25-C25 -> 1 | G25: X | K25: X | N25: =IF(COUNTA(F25:L25)=0,"— não preenchido",IF(COUNTIF(F25:I25,"X")<>1,"FALTA/DUPLA: CONDIÇÃO DA PLATAFORMA",IF(COUNTIF(J25:L25,"X")<>1,"FALTA/DUPLA: DRENAGEM SUPERFICIAL","OK"))) -> OK
A26: 205ETO0010 | B26: C | C26: 17 | D26: 18 | E26: =D26-C26 -> 1 | G26: X | J26: X | N26: =IF(COUNTA(F26:L26)=0,"— não preenchido",IF(COUNTIF(F26:I26,"X")<>1,"FALTA/DUPLA: CONDIÇÃO DA PLATAFORMA",IF(COUNTIF(J26:L26,"X")<>1,"FALTA/DUPLA: DRENAGEM SUPERFICIAL","OK"))) -> OK
A27: 205ETO0010 | B27: C | C27: 18 | D27: 19 | E27: =D27-C27 -> 1 | F27: X | J27: X | N27: =IF(COUNTA(F27:L27)=0,"— não preenchido",IF(COUNTIF(F27:I27,"X")<>1,"FALTA/DUPLA: CONDIÇÃO DA PLATAFORMA",IF(COUNTIF(J27:L27,"X")<>1,"FALTA/DUPLA: DRENAGEM SUPERFICIAL","OK"))) -> OK
A28: 205ETO0010 | B28: C | C28: 19 | D28: 20 | E28: =D28-C28 -> 1 | F28: X | J28: X | N28: =IF(COUNTA(F28:L28)=0,"— não preenchido",IF(COUNTIF(F28:I28,"X")<>1,"FALTA/DUPLA: CONDIÇÃO DA PLATAFORMA",IF(COUNTIF(J28:L28,"X")<>1,"FALTA/DUPLA: DRENAGEM SUPERFICIAL","OK"))) -> OK
A29: 205ETO0010 | B29: C | C29: 20 | D29: 21 | E29: =D29-C29 -> 1 | F29: X | J29: X | N29: =IF(COUNTA(F29:L29)=0,"— não preenchido",IF(COUNTIF(F29:I29,"X")<>1,"FALTA/DUPLA: CONDIÇÃO DA PLATAFORMA",IF(COUNTIF(J29:L29,"X")<>1,"FALTA/DUPLA: DRENAGEM SUPERFICIAL","OK"))) -> OK
A30: 205ETO0010 | B30: C | C30: 21 | D30: 22 | E30: =D30-C30 -> 1 | F30: X | K30: X | N30: =IF(COUNTA(F30:L30)=0,"— não preenchido",IF(COUNTIF(F30:I30,"X")<>1,"FALTA/DUPLA: CONDIÇÃO DA PLATAFORMA",IF(COUNTIF(J30:L30,"X")<>1,"FALTA/DUPLA: DRENAGEM SUPERFICIAL","OK"))) -> OK
A31: 205ETO0010 | B31: C | C31: 22 | D31: 23 | E31: =D31-C31 -> 1 | F31: X | J31: X | N31: =IF(COUNTA(F31:L31)=0,"— não preenchido",IF(COUNTIF(F31:I31,"X")<>1,"FALTA/DUPLA: CONDIÇÃO DA PLATAFORMA",IF(COUNTIF(J31:L31,"X")<>1,"FALTA/DUPLA: DRENAGEM SUPERFICIAL","OK"))) -> OK
A32: 205ETO0010 | B32: C | C32: 23 | D32: 24 | E32: =D32-C32 -> 1 | F32: X | J32: X | N32: =IF(COUNTA(F32:L32)=0,"— não preenchido",IF(COUNTIF(F32:I32,"X")<>1,"FALTA/DUPLA: CONDIÇÃO DA PLATAFORMA",IF(COUNTIF(J32:L32,"X")<>1,"FALTA/DUPLA: DRENAGEM SUPERFICIAL","OK"))) -> OK
A33: 205ETO0010 | B33: C | C33: 24 | D33: 25 | E33: =D33-C33 -> 1 | F33: X | J33: X | N33: =IF(COUNTA(F33:L33)=0,"— não preenchido",IF(COUNTIF(F33:I33,"X")<>1,"FALTA/DUPLA: CONDIÇÃO DA PLATAFORMA",IF(COUNTIF(J33:L33,"X")<>1,"FALTA/DUPLA: DRENAGEM SUPERFICIAL","OK"))) -> OK
A34: 205ETO0010 | B34: C | C34: 25 | D34: 25.673932 | E34: =D34-C34 -> 0.67393223 | F34: X | J34: X | N34: =IF(COUNTA(F34:L34)=0,"— não preenchido",IF(COUNTIF(F34:I34,"X")<>1,"FALTA/DUPLA: CONDIÇÃO DA PLATAFORMA",IF(COUNTIF(J34:L34,"X")<>1,"FALTA/DUPLA: DRENAGEM SUPERFICIAL","OK"))) -> OK
A36: ____________________________________________ | G36: ____________________________________________
A37: TÉCNICO RESPONSÁVEL PELA INSPEÇÃO | G37: VISTO DA SUPERVISÃO
A39: RESUMO DO TRECHO — KM LANÇADO POR ITEM
A40: KM LANÇADO | F40: =SUMIF(F$9:F$34,"X",$E$9:$E$34) -> 16.673932 | G40: =SUMIF(G$9:G$34,"X",$E$9:$E$34) -> 9 | H40: =SUMIF(H$9:H$34,"X",$E$9:$E$34) -> 0 | I40: =SUMIF(I$9:I$34,"X",$E$9:$E$34) -> 0 | J40: =SUMIF(J$9:J$34,"X",$E$9:$E$34) -> 14.673932 | K40: =SUMIF(K$9:K$34,"X",$E$9:$E$34) -> 11 | L40: =SUMIF(L$9:L$34,"X",$E$9:$E$34) -> 0
A41: % DA EXTENSÃO | F41: =IF($I43=0,0,F40/$I43) -> 0.64944988 | G41: =IF($I43=0,0,G40/$I43) -> 0.35055012 | H41: =IF($I43=0,0,H40/$I43) -> 0 | I41: =IF($I43=0,0,I40/$I43) -> 0 | J41: =IF($I43=0,0,J40/$I43) -> 0.57154985 | K41: =IF($I43=0,0,K40/$I43) -> 0.42845015 | L41: =IF($I43=0,0,L40/$I43) -> 0
A42: CONFERÊNCIA POR GRUPO | F42: =IF(SUM(F40:I40)=0,"— não preenchido",IF(ROUND(SUM(F40:I40)-$I43,3)=0,"OK — "&ROUND(SUM(F40:I40),3)&" km","ERRO — dif. de "&ROUND(SUM(F40:I40)-$I43,3)&" km")) -> OK — 25,674 km | J42: =IF(SUM(J40:L40)=0,"— não preenchido",IF(ROUND(SUM(J40:L40)-$I43,3)=0,"OK — "&ROUND(SUM(J40:L40),3)&" km","ERRO — dif. de "&ROUND(SUM(J40:L40)-$I43,3)&" km")) -> OK — 25,674 km
A43: EXTENSÃO TOTAL DO TRECHO | I43: =SUM(E9:E34) -> 25.673932 | M43: =COUNTIF(N9:N34,"OK")&" de "&COUNT($E$9:$E$34)&" linhas conferidas" -> 26 de 26 linhas conferidas
...

Sheet 22
A1: PROGRAMA DE MANUTENÇÃO RODOVIÁRIA — FICHA DE INSPEÇÃO — RODOVIAS NÃO PAVIMENTADAS | P1: Valores dos gráficos — troca 0 por N/D para a fatia não aparecer. Não editar.
A2: REGIÃO: 1 — TOCANTINÓPOLIS | D2: MÊS / ANO: | G2: DATA: | J2: TÉCNICO: | P2: =IF(F53=0,NA(),F53) -> 10.250855 | Q2: =IF(G53=0,NA(),G53) -> 28 | R2: =IF(H53=0,NA(),H53) -> #N/A | S2: =IF(I53=0,NA(),I53) -> #N/A | T2: =IF(J53=0,NA(),J53) -> 33 | U2: =IF(K53=0,NA(),K53) -> 3.2508546 | V2: =IF(L53=0,NA(),L53) -> 2
A3: TRECHO 22 — RODOVIA TO-210 - TRECHO ENTR. TO-010 - DIVISA TO-PA (VILA ANTONINA) | K3: EXTENSÃO: 38,251 km · 1 S.R.E.
A4: COMO PREENCHER: uma X em UMA coluna de cada grupo, por linha. Se houver mais de um defeito no mesmo km, marque o PREDOMINANTE e escreva o resto em OBSERVAÇÕES. A quilometragem é contada de 0 até o fim de CADA S.R.E. (não é o marco da rodovia).
A6: S.R.E. | B6: SENT. | C6: INÍCIO (KM) | D6: FIM (KM) | E6: EXT. (KM) | F6: CONDIÇÃO DA PLATAFORMA | J6: DRENAGEM SUPERFICIAL | M6: OBSERVAÇÕES | N6: CONFERÊNCIA (só na tela)
F7: BOM | G7: REGULAR | H7: RUIM | I7: PÉSSIMA | J7: LIMPA | K7: OBSTRUÍDA | L7: AUSENTE
A8: S.R.E. 210ETO0290 | ENTR. TO-010 - VILA ANTONINA | LEN · Estadual · 38.251 km · início: -6.123077, -48.304689
A9: 210ETO0290 | B9: C | C9: 0 | D9: 1 | E9: =D9-C9 -> 1 | F9: X | J9: X | M9: BUEIRO SIMPLES KM-0,2 ( 0,70 / 0,70 ) | N9: =IF(COUNTA(F9:L9)=0,"— não preenchido",IF(COUNTIF(F9:I9,"X")<>1,"FALTA/DUPLA: CONDIÇÃO DA PLATAFORMA",IF(COUNTIF(J9:L9,"X")<>1,"FALTA/DUPLA: DRENAGEM SUPERFICIAL","OK"))) -> OK
A10: 210ETO0290 | B10: C | C10: 1 | D10: 2 | E10: =D10-C10 -> 1 | F10: X | J10: X | M10: BUEIRO SIMPLES KM-0,2 ( 0,70 / 0,70 ) | N10: =IF(COUNTA(F10:L10)=0,"— não preenchido",IF(COUNTIF(F10:I10,"X")<>1,"FALTA/DUPLA: CONDIÇÃO DA PLATAFORMA",IF(COUNTIF(J10:L10,"X")<>1,"FALTA/DUPLA: DRENAGEM SUPERFICIAL","OK"))) -> OK
A11: 210ETO0290 | B11: C | C11: 2 | D11: 3 | E11: =D11-C11 -> 1 | G11: X | L11: X | M11: BUEIRO SIMPLES KM-4,70 ( 1,10 / 1,10 ) ESTAR SEM CABECA | N11: =IF(COUNTA(F11:L11)=0,"— não preenchido",IF(COUNTIF(F11:I11,"X")<>1,"FALTA/DUPLA: CONDIÇÃO DA PLATAFORMA",IF(COUNTIF(J11:L11,"X")<>1,"FALTA/DUPLA: DRENAGEM SUPERFICIAL","OK"))) -> OK
