Workbook

Sheet RESUMO
A1: RESUMO CONSOLIDADO — REGIÃO 1 — RODOVIAS NÃO PAVIMENTADAS | M1: Valores dos gráficos — troca 0 por N/D para a fatia não aparecer. Não editar.
A2: Todos os números vêm das abas dos trechos por referência direta. Não digite nada aqui. A coluna CONFERÊNCIA acusa qualquer trecho em que a soma das marcações não fecha com a extensão. | M2: =IF(D20=0,NA(),D20) -> 410.0688 | N2: =IF(E20=0,NA(),E20) -> 191.48836 | O2: =IF(F20=0,NA(),F20) -> #N/A | P2: =IF(G20=0,NA(),G20) -> 3 | Q2: =IF(H20=0,NA(),H20) -> 282.67376 | R2: =IF(I20=0,NA(),I20) -> 216.3254 | S2: =IF(J20=0,NA(),J20) -> 92.558004
A4: Nº TRECHO | B4: TRECHO | C4: EXTENSÃO (KM) | D4: CONDIÇÃO DA PLATAFORMA | H4: DRENAGEM SUPERFICIAL | K4: CONFERÊNCIA
D5: BOM | E5: REGULAR | F5: RUIM | G5: PÉSSIMA | H5: LIMPA | I5: OBSTRUÍDA | J5: AUSENTE
A6: 245 | B6: RODOVIA TO-040 - TRECHO ENTR. TO-369 - ENTR. TO-280 (ALMAS) | C6: ='245'!I74 -> 56.716372 | D6: ='245'!F71 -> 0 | E6: ='245'!G71 -> 0 | F6: ='245'!H71 -> 0 | G6: ='245'!I71 -> 0 | H6: ='245'!J71 -> 0 | I6: ='245'!K71 -> 0 | J6: ='245'!L71 -> 0 | K6: =IF(SUM(D6:G6)=0,"— não preenchido",IF(ROUND(SUM(D6:G6)-C6,3)=0,"OK","ERRO — dif. de "&ROUND(SUM(D6:G6)-C6,3)&" km")) -> — não preenchido
A7: 260 | B7: RODOVIA TO-296 - TRECHO ENTR. TO-050 - ENTR. TO-110 (COMBINADO) | C7: ='260'!I71 -> 52.135569 | D7: ='260'!F68 -> 15.279582 | E7: ='260'!G68 -> 33 | F7: ='260'!H68 -> 0 | G7: ='260'!I68 -> 3 | H7: ='260'!J68 -> 0 | I7: ='260'!K68 -> 30.279582 | J7: ='260'!L68 -> 8 | K7: =IF(SUM(D7:G7)=0,"— não preenchido",IF(ROUND(SUM(D7:G7)-C7,3)=0,"OK","ERRO — dif. de "&ROUND(SUM(D7:G7)-C7,3)&" km")) -> ERRO — dif. de -0,856 km
A8: 261 | B8: RODOVIA TO-296 - TRECHO ENTR. BR-242 (POVOADO SÃO BOM JESUS DAS PALMAS) - ENTR. TO-050 | C8: ='261'!I68 -> 50.619704 | D8: ='261'!F65 -> 0 | E8: ='261'!G65 -> 50.619704 | F8: ='261'!H65 -> 0 | G8: ='261'!I65 -> 0 | H8: ='261'!J65 -> 22 | I8: ='261'!K65 -> 28.619704 | J8: ='261'!L65 -> 0 | K8: =IF(SUM(D8:G8)=0,"— não preenchido",IF(ROUND(SUM(D8:G8)-C8,3)=0,"OK","ERRO — dif. de "&ROUND(SUM(D8:G8)-C8,3)&" km")) -> OK
A9: 262 | B9: RODOVIA TO-369 - TRECHO ENTR. TO-040 - ENTR. TO-476 (FUNIL - RIO SONINHO) | C9: ='262'!I41 -> 23.951037 | D9: ='262'!F38 -> 0 | E9: ='262'!G38 -> 23.951037 | F9: ='262'!H38 -> 0 | G9: ='262'!I38 -> 0 | H9: ='262'!J38 -> 17 | I9: ='262'!K38 -> 6.9510366 | J9: ='262'!L38 -> 0 | K9: =IF(SUM(D9:G9)=0,"— não preenchido",IF(ROUND(SUM(D9:G9)-C9,3)=0,"OK","ERRO — dif. de "&ROUND(SUM(D9:G9)-C9,3)&" km")) -> OK
A10: 263 | B10: RODOVIA TO-387 - TRECHO CONCEIÇÃO DO TOCANTINS - TAIPAS DO TOCANTINS | C10: ='263'!I57 -> 39.5018 | D10: ='263'!F54 -> 39.5018 | E10: ='263'!G54 -> 0 | F10: ='263'!H54 -> 0 | G10: ='263'!I54 -> 0 | H10: ='263'!J54 -> 32.5018 | I10: ='263'!K54 -> 7 | J10: ='263'!L54 -> 0 | K10: =IF(SUM(D10:G10)=0,"— não preenchido",IF(ROUND(SUM(D10:G10)-C10,3)=0,"OK","ERRO — dif. de "&ROUND(SUM(D10:G10)-C10,3)&" km")) -> OK
A11: 264 | B11: RODOVIA TO-387 - TRECHO ENTR. BR-010 - ENTR. TO-050 (CONCEIÇÃO DO TOCANTINS) | C11: ='264'!I60 -> 42.464393 | D11: ='264'!F57 -> 25 | E11: ='264'!G57 -> 17.464393 | F11: ='264'!H57 -> 0 | G11: ='264'!I57 -> 0 | H11: ='264'!J57 -> 0 | I11: ='264'!K57 -> 42.464393 | J11: ='264'!L57 -> 0 | K11: =IF(SUM(D11:G11)=0,"— não preenchido",IF(ROUND(SUM(D11:G11)-C11,3)=0,"OK","ERRO — dif. de "&ROUND(SUM(D11:G11)-C11,3)&" km")) -> OK
A12: 265 | B12: RODOVIA TO-387 - TRECHO ENTR. TO-040 - TAIPAS DO TOCANTINS | C12: ='265'!I85 -> 67.817857 | D12: ='265'!F82 -> 67.817857 | E12: ='265'!G82 -> 0 | F12: ='265'!H82 -> 0 | G12: ='265'!I82 -> 0 | H12: ='265'!J82 -> 67.817857 | I12: ='265'!K82 -> 0 | J12: ='265'!L82 -> 0 | K12: =IF(SUM(D12:G12)=0,"— não preenchido",IF(ROUND(SUM(D12:G12)-C12,3)=0,"OK","ERRO — dif. de "&ROUND(SUM(D12:G12)-C12,3)&" km")) -> OK
A13: 267 | B13: RODOVIA TO-476 - TRECHO RIO DA CONCEIÇÃO - ENTR. TO-477 | C13: ='267'!I32 -> 14.476203 | D13: ='267'!F29 -> 5 | E13: ='267'!G29 -> 9.4762034 | F13: ='267'!H29 -> 0 | G13: ='267'!I29 -> 0 | H13: ='267'!J29 -> 0 | I13: ='267'!K29 -> 14.476203 | J13: ='267'!L29 -> 0 | K13: =IF(SUM(D13:G13)=0,"— não preenchido",IF(ROUND(SUM(D13:G13)-C13,3)=0,"OK","ERRO — dif. de "&ROUND(SUM(D13:G13)-C13,3)&" km")) -> OK
A14: 268 | B14: RODOVIA TO-477 - TRECHO ALMAS - ENTR. TO-476 | C14: ='268'!I52 -> 34.769106 | D14: ='268'!F49 -> 0 | E14: ='268'!G49 -> 34.769106 | F14: ='268'!H49 -> 0 | G14: ='268'!I49 -> 0 | H14: ='268'!J49 -> 34.769106 | I14: ='268'!K49 -> 0 | J14: ='268'!L49 -> 0 | K14: =IF(SUM(D14:G14)=0,"— não preenchido",IF(ROUND(SUM(D14:G14)-C14,3)=0,"OK","ERRO — dif. de "&ROUND(SUM(D14:G14)-C14,3)&" km")) -> OK
A15: 269 | B15: RODOVIA TO-477 - TRECHO ENTR. BR-010 (POVOADO BONFIM) - ALMAS | C15: ='269'!I92 -> 73.039576 | D15: ='269'!F89 -> 73.039576 | E15: ='269'!G89 -> 0 | F15: ='269'!H89 -> 0 | G15: ='269'!I89 -> 0 | H15: ='269'!J89 -> 11 | I15: ='269'!K89 -> 62.039576 | J15: ='269'!L89 -> 0 | K15: =IF(SUM(D15:G15)=0,"— não preenchido",IF(ROUND(SUM(D15:G15)-C15,3)=0,"OK","ERRO — dif. de "&ROUND(SUM(D15:G15)-C15,3)&" km")) -> OK
A16: 270 | B16: RODOVIA TO-485 - TRECHO TAIPAS DO TOCANTINS - ENTR. TO-110 | C16: ='270'!I123 -> 98.762685 | D16: ='270'!F120 -> 87.643029 | E16: ='270'!G120 -> 11 | F16: ='270'!H120 -> 0 | G16: ='270'!I120 -> 0 | H16: ='270'!J120 -> 60.438444 | I16: ='270'!K120 -> 10.4949 | J16: ='270'!L120 -> 27.709685 | K16: =IF(SUM(D16:G16)=0,"— não preenchido",IF(ROUND(SUM(D16:G16)-C16,3)=0,"OK","ERRO — dif. de "&ROUND(SUM(D16:G16)-C16,3)&" km")) -> ERRO — dif. de -0,12 km
A17: 271 | B17: RODOVIA TO-487 - TRECHO ENTR. TO-485 (MIMOSA DOS MARINS) - ENTR. BR-242 | C17: ='271'!I39 -> 21.62153 | D17: ='271'!F36 -> 21 | E17: ='271'!G36 -> 0 | F17: ='271'!H36 -> 0 | G17: ='271'!I36 -> 0 | H17: ='271'!J36 -> 0 | I17: ='271'!K36 -> 14 | J17: ='271'!L36 -> 7 | K17: =IF(SUM(D17:G17)=0,"— não preenchido",IF(ROUND(SUM(D17:G17)-C17,3)=0,"OK","ERRO — dif. de "&ROUND(SUM(D17:G17)-C17,3)&" km")) -> ERRO — dif. de -0,622 km
A18: 272 | B18: RODOVIA TO-497 - TRECHO ENTR. BR-242 - ENTR. TO-296 (POVOADO JACARÉ) | C18: ='272'!I98 -> 75.786951 | D18: ='272'!F95 -> 75.786951 | E18: ='272'!G95 -> 0 | F18: ='272'!H95 -> 0 | G18: ='272'!I95 -> 0 | H18: ='272'!J95 -> 25.938632 | I18: ='272'!K95 -> 0 | J18: ='272'!L95 -> 49.848319 | K18: =IF(SUM(D18:G18)=0,"— não preenchido",IF(ROUND(SUM(D18:G18)-C18,3)=0,"OK","ERRO — dif. de "&ROUND(SUM(D18:G18)-C18,3)&" km")) -> OK
A19: 273 | B19: RODOVIA TO-499 - TRECHO ENTR. TO-050 - DIVISA TO-GO | C19: ='273'!I29 -> 11.207917 | D19: ='273'!F26 -> 0 | E19: ='273'!G26 -> 11.207917 | F19: ='273'!H26 -> 0 | G19: ='273'!I26 -> 0 | H19: ='273'!J26 -> 11.207917 | I19: ='273'!K26 -> 0 | J19: ='273'!L26 -> 0 | K19: =IF(SUM(D19:G19)=0,"— não preenchido",IF(ROUND(SUM(D19:G19)-C19,3)=0,"OK","ERRO — dif. de "&ROUND(SUM(D19:G19)-C19,3)&" km")) -> OK
B20: TOTAL PERCORRIDO NO MÊS | C20: =SUM(C6:C19) -> 662.8707 | D20: =SUM(D6:D19) -> 410.0688 | E20: =SUM(E6:E19) -> 191.48836 | F20: =SUM(F6:F19) -> 0 | G20: =SUM(G6:G19) -> 3 | H20: =SUM(H6:H19) -> 282.67376 | I20: =SUM(I6:I19) -> 216.3254 | J20: =SUM(J6:J19) -> 92.558004
B21: % DA EXTENSÃO DA MALHA (662.87 km) | D21: =SUM(D20:G20)/662.87 -> 0.91202974 | H21: (soma do grupo 'CONDIÇÃO DA PLATAFORMA' dividida pela malha)

Sheet 245
A1: PROGRAMA DE MANUTENÇÃO RODOVIÁRIA — FICHA DE INSPEÇÃO — RODOVIAS NÃO PAVIMENTADAS | P1: Valores dos gráficos — troca 0 por N/D para a fatia não aparecer. Não editar.
A2: REGIÃO: 13 — DIANÓPOLIS | D2: MÊS / ANO: | G2: DATA: | J2: TÉCNICO: | P2: =IF(F71=0,NA(),F71) -> #N/A | Q2: =IF(G71=0,NA(),G71) -> #N/A | R2: =IF(H71=0,NA(),H71) -> #N/A | S2: =IF(I71=0,NA(),I71) -> #N/A | T2: =IF(J71=0,NA(),J71) -> #N/A | U2: =IF(K71=0,NA(),K71) -> #N/A | V2: =IF(L71=0,NA(),L71) -> #N/A
A3: TRECHO 245 — RODOVIA TO-040 - TRECHO ENTR. TO-369 - ENTR. TO-280 (ALMAS) | K3: EXTENSÃO: 56,716 km · 1 S.R.E.
A4: COMO PREENCHER: uma X em UMA coluna de cada grupo, por linha. Se houver mais de um defeito no mesmo km, marque o PREDOMINANTE e escreva o resto em OBSERVAÇÕES. A quilometragem é contada de 0 até o fim de CADA S.R.E. (não é o marco da rodovia).
A6: S.R.E. | B6: SENT. | C6: INÍCIO (KM) | D6: FIM (KM) | E6: EXT. (KM) | F6: CONDIÇÃO DA PLATAFORMA | J6: DRENAGEM SUPERFICIAL | M6: OBSERVAÇÕES | N6: CONFERÊNCIA (só na tela)
F7: BOM | G7: REGULAR | H7: RUIM | I7: PÉSSIMA | J7: LIMPA | K7: OBSTRUÍDA | L7: AUSENTE
A8: S.R.E. 040ETO0140 | ENTR. TO-369 - ENTR. TO-280 (ALMAS) | EOP · Estadual · 56.716 km · início: -11.163844, -47.299488
A9: 040ETO0140 | B9: C | C9: 0 | D9: 1 | E9: =D9-C9 -> 1 | N9: =IF(COUNTA(F9:L9)=0,"— não preenchido",IF(COUNTIF(F9:I9,"X")<>1,"FALTA/DUPLA: CONDIÇÃO DA PLATAFORMA",IF(COUNTIF(J9:L9,"X")<>1,"FALTA/DUPLA: DRENAGEM SUPERFICIAL","OK"))) -> — não preenchido
A10: 040ETO0140 | B10: C | C10: 1 | D10: 2 | E10: =D10-C10 -> 1 | N10: =IF(COUNTA(F10:L10)=0,"— não preenchido",IF(COUNTIF(F10:I10,"X")<>1,"FALTA/DUPLA: CONDIÇÃO DA PLATAFORMA",IF(COUNTIF(J10:L10,"X")<>1,"FALTA/DUPLA: DRENAGEM SUPERFICIAL","OK"))) -> — não preenchido
A11: 040ETO0140 | B11: C | C11: 2 | D11: 3 | E11: =D11-C11 -> 1 | N11: =IF(COUNTA(F11:L11)=0,"— não preenchido",IF(COUNTIF(F11:I11,"X")<>1,"FALTA/DUPLA: CONDIÇÃO DA PLATAFORMA",IF(COUNTIF(J11:L11,"X")<>1,"FALTA/DUPLA: DRENAGEM SUPERFICIAL","OK"))) -> — não preenchido
A12: 040ETO0140 | B12: C | C12: 3 | D12: 4 | E12: =D12-C12 -> 1 | N12: =IF(COUNTA(F12:L12)=0,"— não preenchido",IF(COUNTIF(F12:I12,"X")<>1,"FALTA/DUPLA: CONDIÇÃO DA PLATAFORMA",IF(COUNTIF(J12:L12,"X")<>1,"FALTA/DUPLA: DRENAGEM SUPERFICIAL","OK"))) -> — não preenchido
A13: 040ETO0140 | B13: C | C13: 4 | D13: 5 | E13: =D13-C13 -> 1 | N13: =IF(COUNTA(F13:L13)=0,"— não preenchido",IF(COUNTIF(F13:I13,"X")<>1,"FALTA/DUPLA: CONDIÇÃO DA PLATAFORMA",IF(COUNTIF(J13:L13,"X")<>1,"FALTA/DUPLA: DRENAGEM SUPERFICIAL","OK"))) -> — não preenchido
A14: 040ETO0140 | B14: C | C14: 5 | D14: 6 | E14: =D14-C14 -> 1 | N14: =IF(COUNTA(F14:L14)=0,"— não preenchido",IF(COUNTIF(F14:I14,"X")<>1,"FALTA/DUPLA: CONDIÇÃO DA PLATAFORMA",IF(COUNTIF(J14:L14,"X")<>1,"FALTA/DUPLA: DRENAGEM SUPERFICIAL","OK"))) -> — não preenchido
A15: 040ETO0140 | B15: C | C15: 6 | D15: 7 | E15: =D15-C15 -> 1 | N15: =IF(COUNTA(F15:L15)=0,"— não preenchido",IF(COUNTIF(F15:I15,"X")<>1,"FALTA/DUPLA: CONDIÇÃO DA PLATAFORMA",IF(COUNTIF(J15:L15,"X")<>1,"FALTA/DUPLA: DRENAGEM SUPERFICIAL","OK"))) -> — não preenchido
A16: 040ETO0140 | B16: C | C16: 7 | D16: 8 | E16: =D16-C16 -> 1 | N16: =IF(COUNTA(F16:L16)=0,"— não preenchido",IF(COUNTIF(F16:I16,"X")<>1,"FALTA/DUPLA: CONDIÇÃO DA PLATAFORMA",IF(COUNTIF(J16:L16,"X")<>1,"FALTA/DUPLA: DRENAGEM SUPERFICIAL","OK"))) -> — não preenchido
A17: 040ETO0140 | B17: C | C17: 8 | D17: 9 | E17: =D17-C17 -> 1 | N17: =IF(COUNTA(F17:L17)=0,"— não preenchido",IF(COUNTIF(F17:I17,"X")<>1,"FALTA/DUPLA: CONDIÇÃO DA PLATAFORMA",IF(COUNTIF(J17:L17,"X")<>1,"FALTA/DUPLA: DRENAGEM SUPERFICIAL","OK"))) -> — não preenchido
A18: 040ETO0140 | B18: C | C18: 9 | D18: 10 | E18: =D18-C18 -> 1 | N18: =IF(COUNTA(F18:L18)=0,"— não preenchido",IF(COUNTIF(F18:I18,"X")<>1,"FALTA/DUPLA: CONDIÇÃO DA PLATAFORMA",IF(COUNTIF(J18:L18,"X")<>1,"FALTA/DUPLA: DRENAGEM SUPERFICIAL","OK"))) -> — não preenchido
A19: 040ETO0140 | B19: C | C19: 10 | D19: 11 | E19: =D19-C19 -> 1 | N19: =IF(COUNTA(F19:L19)=0,"— não preenchido",IF(COUNTIF(F19:I19,"X")<>1,"FALTA/DUPLA: CONDIÇÃO DA PLATAFORMA",IF(COUNTIF(J19:L19,"X")<>1,"FALTA/DUPLA: DRENAGEM SUPERFICIAL","OK"))) -> — não preenchido
A20: 040ETO0140 | B20: C | C20: 11 | D20: 12 | E20: =D20-C20 -> 1 | N20: =IF(COUNTA(F20:L20)=0,"— não preenchido",IF(COUNTIF(F20:I20,"X")<>1,"FALTA/DUPLA: CONDIÇÃO DA PLATAFORMA",IF(COUNTIF(J20:L20,"X")<>1,"FALTA/DUPLA: DRENAGEM SUPERFICIAL","OK"))) -> — não preenchido
... A65: 040ETO0140 | B65: C | C65: 56 | D65: 56.716372 | E65: =D65-C65 -> 0.71637192 | N65: =IF(COUNTA(F65:L65)=0,"— não preenchido",IF(COUNTIF(F65:I65,"X")<>1,"FALTA/DUPLA: CONDIÇÃO DA PLATAFORMA",IF(COUNTIF(J65:L65,"X")<>1,"FALTA/DUPLA: DRENAGEM SUPERFICIAL","OK"))) -> — não preenchido
A67: ____________________________________________ | G67: ____________________________________________
A68: TÉCNICO RESPONSÁVEL PELA INSPEÇÃO | G68: VISTO DA SUPERVISÃO
A70: RESUMO DO TRECHO — KM LANÇADO POR ITEM
A71: KM LANÇADO | F71: =SUMIF(F$9:F$65,"X",$E$9:$E$65) -> 0 | G71: =SUMIF(G$9:G$65,"X",$E$9:$E$65) -> 0 | H71: =SUMIF(H$9:H$65,"X",$E$9:$E$65) -> 0 | I71: =SUMIF(I$9:I$65,"X",$E$9:$E$65) -> 0 | J71: =SUMIF(J$9:J$65,"X",$E$9:$E$65) -> 0 | K71: =SUMIF(K$9:K$65,"X",$E$9:$E$65) -> 0 | L71: =SUMIF(L$9:L$65,"X",$E$9:$E$65) -> 0
A72: % DA EXTENSÃO | F72: =IF($I74=0,0,F71/$I74) -> 0 | G72: =IF($I74=0,0,G71/$I74) -> 0 | H72: =IF($I74=0,0,H71/$I74) -> 0 | I72: =IF($I74=0,0,I71/$I74) -> 0 | J72: =IF($I74=0,0,J71/$I74) -> 0 | K72: =IF($I74=0,0,K71/$I74) -> 0 | L72: =IF($I74=0,0,L71/$I74) -> 0
A73: CONFERÊNCIA POR GRUPO | F73: =IF(SUM(F71:I71)=0,"— não preenchido",IF(ROUND(SUM(F71:I71)-$I74,3)=0,"OK — "&ROUND(SUM(F71:I71),3)&" km","ERRO — dif. de "&ROUND(SUM(F71:I71)-$I74,3)&" km")) -> — não preenchido | J73: =IF(SUM(J71:L71)=0,"— não preenchido",IF(ROUND(SUM(J71:L71)-$I74,3)=0,"OK — "&ROUND(SUM(J71:L71),3)&" km","ERRO — dif. de "&ROUND(SUM(J71:L71)-$I74,3)&" km")) -> — não preenchido
A74: EXTENSÃO TOTAL DO TRECHO | I74: =SUM(E9:E65) -> 56.716372 | M74: =COUNTIF(N9:N65,"OK")&" de "&COUNT($E$9:$E$65)&" linhas conferidas" -> 0 de 57 linhas conferidas
A76: LEGENDA
A77: REGULAR | E77: Até 10 irregularidades por km
A78: RUIM | E78: Mais de 10 irregularidades por km
A79: PÉSSIMA | E79: Atoleiro ou ponto crítico
A80: SIT. | E80: LEN = leito natural · EOP = em obras de pavimentação
A81: FAIXA AZUL | E81: Cabeçalho de cada S.R.E.: descrição, situação, jurisdição, extensão e coordenada de início.
A82: INÍCIO / FIM (KM) | E82: Contados de 0 até o fim de CADA S.R.E. Não é o marco quilométrico da rodovia.
A83: SENT. | E83: C = crescente · D = decrescente
A84: FAIXA CINZA | E84: Segmento fora do escopo do contrato: você passa por ele, mas não preenche.
A85: CÉLULA VERMELHA | E85: Mais de uma X no mesmo grupo. Apague uma delas.
A86: CONFERÊNCIA | E86: Só na tela, não sai impresso. Fica OK com uma X em cada grupo.

Sheet 260
A1: PROGRAMA DE MANUTENÇÃO RODOVIÁRIA — FICHA DE INSPEÇÃO — RODOVIAS NÃO PAVIMENTADAS | P1: Valores dos gráficos — troca 0 por N/D para a fatia não aparecer. Não editar.
A2: REGIÃO: 13 — DIANÓPOLIS | D2: MÊS / ANO: | G2: DATA: | J2: TÉCNICO: | P2: =IF(F68=0,NA(),F68) -> 15.279582 | Q2: =IF(G68=0,NA(),G68) -> 33 | R2: =IF(H68=0,NA(),H68) -> #N/A | S2: =IF(I68=0,NA(),I68) -> 3 | T2: =IF(J68=0,NA(),J68) -> #N/A | U2: =IF(K68=0,NA(),K68) -> 30.279582 | V2: =IF(L68=0,NA(),L68) -> 8
A3: TRECHO 260 — RODOVIA TO-296 - TRECHO ENTR. TO-050 - ENTR. TO-110 (COMBINADO) | K3: EXTENSÃO: 52,136 km · 2 S.R.E.
A4: COMO PREENCHER: uma X em UMA coluna de cada grupo, por linha. Se houver mais de um defeito no mesmo km, marque o PREDOMINANTE e escreva o resto em OBSERVAÇÕES. A quilometragem é contada de 0 até o fim de CADA S.R.E. (não é o marco da rodovia).
A6: S.R.E. | B6: SENT. | C6: INÍCIO (KM) | D6: FIM (KM) | E6: EXT. (KM) | F6: CONDIÇÃO DA PLATAFORMA | J6: DRENAGEM SUPERFICIAL | M6: OBSERVAÇÕES | N6: CONFERÊNCIA (só na tela)
F7: BOM | G7: REGULAR | H7: RUIM | I7: PÉSSIMA | J7: LIMPA | K7: OBSTRUÍDA | L7: AUSENTE
A8: S.R.E. 296ETO0110 | COMBINADO *TRECHO URBANO* - ENTR. TO-497 | LEN · Estadual · 30.280 km · início: -12.81329, -46.554648
A9: 296ETO0110 | B9: C | C9: 0 | D9: 1 | E9: =D9-C9 -> 1 | G9: X | K9: X | N9: =IF(COUNTA(F9:L9)=0,"— não preenchido",IF(COUNTIF(F9:I9,"X")<>1,"FALTA/DUPLA: CONDIÇÃO DA PLATAFORMA",IF(COUNTIF(J9:L9,"X")<>1,"FALTA/DUPLA: DRENAGEM SUPERFICIAL","OK"))) -> OK
A10: 296ETO0110 | B10: C | C10: 1 | D10: 2 | E10: =D10-C10 -> 1 | G10: X | K10: X | N10: =IF(COUNTA(F10:L10)=0,"— não preenchido",IF(COUNTIF(F10:I10,"X")<>1,"FALTA/DUPLA: CONDIÇÃO DA PLATAFORMA",IF(COUNTIF(J10:L10,"X")<>1,"FALTA/DUPLA: DRENAGEM SUPERFICIAL","OK"))) -> OK
A11: 296ETO0110 | B11: C | C11: 2 | D11: 3 | E11: =D11-C11 -> 1 | G11: X | K11: X | N11: =IF(COUNTA(F11:L11)=0,"— não preenchido",IF(COUNTIF(F11:I11,"X")<>1,"FALTA/DUPLA: CONDIÇÃO DA PLATAFORMA",IF(COUNTIF(J11:L11,"X")<>1,"FALTA/DUPLA: DRENAGEM SUPERFICIAL","OK"))) -> OK
A12: 296ETO0110 | B12: C | C12: 3 | D12: 4 | E12: =D12-C12 -> 1 | G12: X | K12: X | N12: =IF(COUNTA(F12:L12)=0,"— não preenchido",IF(COUNTIF(F12:I12,"X")<>1,"FALTA/DUPLA: CONDIÇÃO DA PLATAFORMA",IF(COUNTIF(J12:L12,"X")<>1,"FALTA/DUPLA: DRENAGEM SUPERFICIAL","OK"))) -> OK
A13: 296ETO0110 | B13: C | C13: 4 | D13: 5 | E13: =D13-C13 -> 1 | G13: X | K13: X | N13: =IF(COUNTA(F13:L13)=0,"— não preenchido",IF(COUNTIF(F13:I13,"X")<>1,"FALTA/DUPLA: CONDIÇÃO DA PLATAFORMA",IF(COUNTIF(J13:L13,"X")<>1,"FALTA/DUPLA: DRENAGEM SUPERFICIAL","OK"))) -> OK
A14: 296ETO0110 | B14: C | C14: 5 | D14: 6 | E14: =D14-C14 -> 1 | G14: X | K14: X | N14: =IF(COUNTA(F14:L14)=0,"— não preenchido",IF(COUNTIF(F14:I14,"X")<>1,"FALTA/DUPLA: CONDIÇÃO DA PLATAFORMA",IF(COUNTIF(J14:L14,"X")<>1,"FALTA/DUPLA: DRENAGEM SUPERFICIAL","OK"))) -> OK
A15: 296ETO0110 | B15: C | C15: 6 | D15: 7 | E15: =D15-C15 -> 1 | G15: X | K15: X | N15: =IF(COUNTA(F15:L15)=0,"— não preenchido",IF(COUNTIF(F15:I15,"X")<>1,"FALTA/DUPLA: CONDIÇÃO DA PLATAFORMA",IF(COUNTIF(J15:L15,"X")<>1,"FALTA/DUPLA: DRENAGEM SUPERFICIAL","OK"))) -> OK
A16: 296ETO0110 | B16: C | C16: 7 | D16: 8 | E16: =D16-C16 -> 1 | G16: X | K16: X | N16: =IF(COUNTA(F16:L16)=0,"— não preenchido",IF(COUNTIF(F16:I16,"X")<>1,"FALTA/DUPLA: CONDIÇÃO DA PLATAFORMA",IF(COUNTIF(J16:L16,"X")<>1,"FALTA/DUPLA: DRENAGEM SUPERFICIAL","OK"))) -> OK
A17: 296ETO0110 | B17: C | C17: 8 | D17: 9 | E17: =D17-C17 -> 1 | G17: X | K17: X | N17: =IF(COUNTA(F17:L17)=0,"— não preenchido",IF(COUNTIF(F17:I17,"X")<>1,"FALTA/DUPLA: CONDIÇÃO DA PLATAFORMA",IF(COUNTIF(J17:L17,"X")<>1,"FALTA/DUPLA: DRENAGEM SUPERFICIAL","OK"))) -> OK
A18: 296ETO0110 | B18: C | C18: 9 | D18: 10 | E18: =D18-C18 -> 1 | G18: X | K18: X | N18: =IF(COUNTA(F18:L18)=0,"— não preenchido",IF(COUNTIF(F18:I18,"X")<>1,"FALTA/DUPLA: CONDIÇÃO DA PLATAFORMA",IF(COUNTIF(J18:L18,"X")<>1,"FALTA/DUPLA: DRENAGEM SUPERFICIAL","OK"))) -> OK
A19: 296ETO0110 | B19: C | C19: 10 | D19: 11 | E19: =D19-C19 -> 1 | G19: X | K19: X | N19: =IF(COUNTA(F19:L19)=0,"— não preenchido",IF(COUNTIF(F19:I19,"X")<>1,"FALTA/DUPLA: CONDIÇÃO DA PLATAFORMA",IF(COUNTIF(J19:L19,"X")<>1,"FALTA/DUPLA: DRENAGEM SUPERFICIAL","OK"))) -> OK
A20: 296ETO0110 | B20: C | C20: 11 | D20: 12 | E20: =D20-C20 -> 1 | G20: X | K20: X | N20: =IF(COUNTA(F20:L20)=0,"— não preenchido",IF(COUNTIF(F20:I20,"X")<>1,"FALTA/DUPLA: CONDIÇÃO DA PLATAFORMA",IF(COUNTIF(J20:L20,"X")<>1,"FALTA/DUPLA: DRENAGEM SUPERFICIAL","OK"))) -> OK
... A23: 296ETO0110 | B23: C | C23: 14 | D23: 15 | E23: =D23-C23 -> 1 | G23: X | K23: X | N23: =IF(COUNTA(F23:L23)=0,"— não preenchido",IF(COUNTIF(F23:I23,"X")<>1,"FALTA/DUPLA: CONDIÇÃO DA PLATAFORMA",IF(COUNTIF(J23:L23,"X")<>1,"FALTA/DUPLA: DRENAGEM SUPERFICIAL","OK"))) -> OK
A24: 296ETO0110 | B24: C | C24: 15 | D24: 16 | E24: =D24-C24 -> 1 | F24: X | K24: X | N24: =IF(COUNTA(F24:L24)=0,"— não preenchido",IF(COUNTIF(F24:I24,"X")<>1,"FALTA/DUPLA: CONDIÇÃO DA PLATAFORMA",IF(COUNTIF(J24:L24,"X")<>1,"FALTA/DUPLA: DRENAGEM SUPERFICIAL","OK"))) -> OK
A25: 296ETO0110 | B25: C | C25: 16 | D25: 17 | E25: =D25-C25 -> 1 | F25: X | K25: X | N25: =IF(COUNTA(F25:L25)=0,"— não preenchido",IF(COUNTIF(F25:I25,"X")<>1,"FALTA/DUPLA: CONDIÇÃO DA PLATAFORMA",IF(COUNTIF(J25:L25,"X")<>1,"FALTA/DUPLA: DRENAGEM SUPERFICIAL","OK"))) -> OK
A26: 296ETO0110 | B26: C | C26: 17 | D26: 18 | E26: =D26-C26 -> 1 | F26: X | K26: X | N26: =IF(COUNTA(F26:L26)=0,"— não preenchido",IF(COUNTIF(F26:I26,"X")<>1,"FALTA/DUPLA: CONDIÇÃO DA PLATAFORMA",IF(COUNTIF(J26:L26,"X")<>1,"FALTA/DUPLA: DRENAGEM SUPERFICIAL","OK"))) -> OK
A27: 296ETO0110 | B27: C | C27: 18 | D27: 19 | E27: =D27-C27 -> 1 | F27: X | K27: X | N27: =IF(COUNTA(F27:L27)=0,"— não preenchido",IF(COUNTIF(F27:I27,"X")<>1,"FALTA/DUPLA: CONDIÇÃO DA PLATAFORMA",IF(COUNTIF(J27:L27,"X")<>1,"FALTA/DUPLA: DRENAGEM SUPERFICIAL","OK"))) -> OK
A28: 296ETO0110 | B28: C | C28: 19 | D28: 20 | E28: =D28-C28 -> 1 | F28: X | K28: X | N28: =IF(COUNTA(F28:L28)=0,"— não preenchido",IF(COUNTIF(F28:I28,"X")<>1,"FALTA/DUPLA: CONDIÇÃO DA PLATAFORMA",IF(COUNTIF(J28:L28,"X")<>1,"FALTA/DUPLA: DRENAGEM SUPERFICIAL","OK"))) -> OK
A29: 296ETO0110 | B29: C | C29: 20 | D29: 21 | E29: =D29-C29 -> 1 | F29: X | K29: X | N29: =IF(COUNTA(F29:L29)=0,"— não preenchido",IF(COUNTIF(F29:I29,"X")<>1,"FALTA/DUPLA: CONDIÇÃO DA PLATAFORMA",IF(COUNTIF(J29:L29,"X")<>1,"FALTA/DUPLA: DRENAGEM SUPERFICIAL","OK"))) -> OK
A30: 296ETO0110 | B30: C | C30: 21 | D30: 22 | E30: =D30-C30 -> 1 | F30: X | K30: X | N30: =IF(COUNTA(F30:L30)=0,"— não preenchido",IF(COUNTIF(F30:I30,"X")<>1,"FALTA/DUPLA: CONDIÇÃO DA PLATAFORMA",IF(COUNTIF(J30:L30,"X")<>1,"FALTA/DUPLA: DRENAGEM SUPERFICIAL","OK"))) -> OK
A31: 296ETO0110 | B31: C | C31: 22 | D31: 23 | E31: =D31-C31 -> 1 | F31: X | K31: X | N31: =IF(COUNTA(F31:L31)=0,"— não preenchido",IF(COUNTIF(F31:I31,"X")<>1,"FALTA/DUPLA: CONDIÇÃO DA PLATAFORMA",IF(COUNTIF(J31:L31,"X")<>1,"FALTA/DUPLA: DRENAGEM SUPERFICIAL","OK"))) -> OK
A32: 296ETO0110 | B32: C | C32: 23 | D32: 24 | E32: =D32-C32 -> 1 | F32: X | K32: X | N32: =IF(COUNTA(F32:L32)=0,"— não preenchido",IF(COUNTIF(F32:I32,"X")<>1,"FALTA/DUPLA: CONDIÇÃO DA PLATAFORMA",IF(COUNTIF(J32:L32,"X")<>1,"FALTA/DUPLA: DRENAGEM SUPERFICIAL","OK"))) -> OK
A33: 296ETO0110 | B33: C | C33: 24 | D33: 25 | E33: =D33-C33 -> 1 | F33: X | K33: X | N33: =IF(COUNTA(F33:L33)=0,"— não preenchido",IF(COUNTIF(F33:I33,"X")<>1,"FALTA/DUPLA: CONDIÇÃO DA PLATAFORMA",IF(COUNTIF(J33:L33,"X")<>1,"FALTA/DUPLA: DRENAGEM SUPERFICIAL","OK"))) -> OK
A34: 296ETO0110 | B34: C | C34: 25 | D34: 26 | E34: =D34-C34 -> 1 | F34: X | K34: X | N34: =IF(COUNTA(F34:L34)=0,"— não preenchido",IF(COUNTIF(F34:I34,"X")<>1,"FALTA/DUPLA: CONDIÇÃO DA PLATAFORMA",IF(COUNTIF(J34:L34,"X")<>1,"FALTA/DUPLA: DRENAGEM SUPERFICIAL","OK"))) -> OK
A35: 296ETO0110 | B35: C | C35: 26 | D35: 27 | E35: =D35-C35 -> 1 | F35: X | K35: X | N35: =IF(COUNTA(F35:L35)=0,"— não preenchido",IF(COUNTIF(F35:I35,"X")<>1,"FALTA/DUPLA: CONDIÇÃO DA PLATAFORMA",IF(COUNTIF(J35:L35,"X")<>1,"FALTA/DUPLA: DRENAGEM SUPERFICIAL","OK"))) -> OK
... A39: 296ETO0110 | B39: C | C39: 30 | D39: 30.279582 | E39: =D39-C39 -> 0.27958236 | F39: X | K39: X | N39: =IF(COUNTA(F39:L39)=0,"— não preenchido",IF(COUNTIF(F39:I39,"X")<>1,"FALTA/DUPLA: CONDIÇÃO DA PLATAFORMA",IF(COUNTIF(J39:L39,"X")<>1,"FALTA/DUPLA: DRENAGEM SUPERFICIAL","OK"))) -> OK
A40: S.R.E. 296ETO0120 | ENTR. TO-497 - ENTR. TO-050 | LEN · Estadual · 21.856 km · início: -12.847586, -46.789522
A41: 296ETO0120 | B41: C | C41: 0 | D41: 1 | E41: =D41-C41 -> 1 | I41: X | L41: X | M41: * (21,86 Km) TRECHO CRÍTICO COM MUITAS PEDRAS AFLORADAS - 07 FOTOS | N41: =IF(COUNTA(F41:L41)=0,"— não preenchido",IF(COUNTIF(F41:I41,"X")<>1,"FALTA/DUPLA: CONDIÇÃO DA PLATAFORMA",IF(COUNTIF(J41:L41,"X")<>1,"FALTA/DUPLA: DRENAGEM SUPERFICIAL","OK"))) -> OK
A42: 296ETO0120 | B42: C | C42: 1 | D42: 2 | E42: =D42-C42 -> 1 | I42: X | L42: X | M42: * (21,86 Km) TRECHO CRÍTICO COM MUITAS PEDRAS AFLORADAS - 07 FOTOS | N42: =IF(COUNTA(F42:L42)=0,"— não preenchido",IF(COUNTIF(F42:I42,"X")<>1,"FALTA/DUPLA: CONDIÇÃO DA PLATAFORMA",IF(COUNTIF(J42:L42,"X")<>1,"FALTA/DUPLA: DRENAGEM SUPERFICIAL","OK"))) -> OK
A43: 296ETO0120 | B43: C | C43: 2 | D43: 3 | E43: =D43-C43 -> 1 | I43: X | L43: X | M43: * (21,86 Km) TRECHO CRÍTICO COM MUITAS PEDRAS AFLORADAS - 07 FOTOS | N43: =IF(COUNTA(F43:L43)=0,"— não preenchido",IF(COUNTIF(F43:I43,"X")<>1,"FALTA/DUPLA: CONDIÇÃO DA PLATAFORMA",IF(COUNTIF(J43:L43,"X")<>1,"FALTA/DUPLA: DRENAGEM SUPERFICIAL","OK"))) -> OK
A44: 296ETO0120 | B44: C | C44: 3 | D44: 4 | E44: =D44-C44 -> 1 | G44: X | L44: X | M44: 01 FOTO | N44: =IF(COUNTA(F44:L44)=0,"— não preenchido",IF(COUNTIF(F44:I44,"X")<>1,"FALTA/DUPLA: CONDIÇÃO DA PLATAFORMA",IF(COUNTIF(J44:L44,"X")<>1,"FALTA/DUPLA: DRENAGEM SUPERFICIAL","OK"))) -> OK
A45: 296ETO0120 | B45: C | C45: 4 | D45: 5 | E45: =D45-C45 -> 1 | G45: X | L45: X | M45: AMPLIAÇÃO DE UM BUEIRO CELULAR | N45: =IF(COUNTA(F45:L45)=0,"— não preenchido",IF(COUNTIF(F45:I45,"X")<>1,"FALTA/DUPLA: CONDIÇÃO DA PLATAFORMA",IF(COUNTIF(J45:L45,"X")<>1,"FALTA/DUPLA: DRENAGEM SUPERFICIAL","OK"))) -> OK
A46: 296ETO0120 | B46: C | C46: 5 | D46: 6 | E46: =D46-C46 -> 1 | G46: X | L46: X | M46: AMPLIAÇÃO DE UM BUEIRO CELULAR | N46: =IF(COUNTA(F46:L46)=0,"— não preenchido",IF(COUNTIF(F46:I46,"X")<>1,"FALTA/DUPLA: CONDIÇÃO DA PLATAFORMA",IF(COUNTIF(J46:L46,"X")<>1,"FALTA/DUPLA: DRENAGEM SUPERFICIAL","OK"))) -> OK
...

Sheet 261
A1: PROGRAMA DE MANUTENÇÃO RODOVIÁRIA — FICHA DE INSPEÇÃO — RODOVIAS NÃO PAVIMENTADAS | P1: Valores dos gráficos — troca 0 por N/D para a fatia não aparecer. Não editar.
A2: REGIÃO: 13 — DIANÓPOLIS | D2: MÊS / ANO: | G2: DATA: | J2: TÉCNICO: | P2: =IF(F65=0,NA(),F65) -> #N/A | Q2: =IF(G65=0,NA(),G65) -> 50.619704 | R2: =IF(H65=0,NA(),H65) -> #N/A | S2: =IF(I65=0,NA(),I65) -> #N/A | T2: =IF(J65=0,NA(),J65) -> 22 | U2: =IF(K65=0,NA(),K65) -> 28.619704 | V2: =IF(L65=0,NA(),L65) -> #N/A
A3: TRECHO 261 — RODOVIA TO-296 - TRECHO ENTR. BR-242 (POVOADO SÃO BOM JESUS DAS PALMAS) - ENTR. TO-050 | K3: EXTENSÃO: 50,620 km · 1 S.R.E.
A4: COMO PREENCHER: uma X em UMA coluna de cada grupo, por linha. Se houver mais de um defeito no mesmo km, marque o PREDOMINANTE e escreva o resto em OBSERVAÇÕES. A quilometragem é contada de 0 até o fim de CADA S.R.E. (não é o marco da rodovia).
A6: S.R.E. | B6: SENT. | C6: INÍCIO (KM) | D6: FIM (KM) | E6: EXT. (KM) | F6: CONDIÇÃO DA PLATAFORMA | J6: DRENAGEM SUPERFICIAL | M6: OBSERVAÇÕES | N6: CONFERÊNCIA (só na tela)
F7: BOM | G7: REGULAR | H7: RUIM | I7: PÉSSIMA | J7: LIMPA | K7: OBSTRUÍDA | L7: AUSENTE
A8: S.R.E. 296ETO0170 | ENTR. TO-050 - ENTR. BR-242 | LEN · Estadual · 50.620 km · início: -12.843804, -47.088265
A9: 296ETO0170 | B9: C | C9: 0 | D9: 1 | E9: =D9-C9 -> 1 | G9: X | J9: X | N9: =IF(COUNTA(F9:L9)=0,"— não preenchido",IF(COUNTIF(F9:I9,"X")<>1,"FALTA/DUPLA: CONDIÇÃO DA PLATAFORMA",IF(COUNTIF(J9:L9,"X")<>1,"FALTA/DUPLA: DRENAGEM SUPERFICIAL","OK"))) -> OK
A10: 296ETO0170 | B10: C | C10: 1 | D10: 2 | E10: =D10-C10 -> 1 | G10: X | J10: X | N10: =IF(COUNTA(F10:L10)=0,"— não preenchido",IF(COUNTIF(F10:I10,"X")<>1,"FALTA/DUPLA: CONDIÇÃO DA PLATAFORMA",IF(COUNTIF(J10:L10,"X")<>1,"FALTA/DUPLA: DRENAGEM SUPERFICIAL","OK"))) -> OK
A11: 296ETO0170 | B11: C | C11: 2 | D11: 3 | E11: =D11-C11 -> 1 | G11: X | J11: X | N11: =IF(COUNTA(F11:L11)=0,"— não preenchido",IF(COUNTIF(F11:I11,"X")<>1,"FALTA/DUPLA: CONDIÇÃO DA PLATAFORMA",IF(COUNTIF(J11:L11,"X")<>1,"FALTA/DUPLA: DRENAGEM SUPERFICIAL","OK"))) -> OK
A12: 296ETO0170 | B12: C | C12: 3 | D12: 4 | E12: =D12-C12 -> 1 | G12: X | J12: X | N12: =IF(COUNTA(F12:L12)=0,"— não preenchido",IF(COUNTIF(F12:I12,"X")<>1,"FALTA/DUPLA: CONDIÇÃO DA PLATAFORMA",IF(COUNTIF(J12:L12,"X")<>1,"FALTA/DUPLA: DRENAGEM SUPERFICIAL","OK"))) -> OK
A13: 296ETO0170 | B13: C | C13: 4 | D13: 5 | E13: =D13-C13 -> 1 | G13: X | J13: X | N13: =IF(COUNTA(F13:L13)=0,"— não preenchido",IF(COUNTIF(F13:I13,"X")<>1,"FALTA/DUPLA: CONDIÇÃO DA PLATAFORMA",IF(COUNTIF(J13:L13,"X")<>1,"FALTA/DUPLA: DRENAGEM SUPERFICIAL","OK"))) -> OK
A14: 296ETO0170 | B14: C | C14: 5 | D14: 6 | E14: =D14-C14 -> 1 | G14: X | J14: X | N14: =IF(COUNTA(F14:L14)=0,"— não preenchido",IF(COUNTIF(F14:I14,"X")<>1,"FALTA/DUPLA: CONDIÇÃO DA PLATAFORMA",IF(COUNTIF(J14:L14,"X")<>1,"FALTA/DUPLA: DRENAGEM SUPERFICIAL","OK"))) -> OK
A15: 296ETO0170 | B15: C | C15: 6 | D15: 7 | E15: =D15-C15 -> 1 | G15: X | J15: X | N15: =IF(COUNTA(F15:L15)=0,"— não preenchido",IF(COUNTIF(F15:I15,"X")<>1,"FALTA/DUPLA: CONDIÇÃO DA PLATAFORMA",IF(COUNTIF(J15:L15,"X")<>1,"FALTA/DUPLA: DRENAGEM SUPERFICIAL","OK"))) -> OK
A16: 296ETO0170 | B16: C | C16: 7 | D16: 8 | E16: =D16-C16 -> 1 | G16: X | J16: X | N16: =IF(COUNTA(F16:L16)=0,"— não preenchido",IF(COUNTIF(F16:I16,"X")<>1,"FALTA/DUPLA: CONDIÇÃO DA PLATAFORMA",IF(COUNTIF(J16:L16,"X")<>1,"FALTA/DUPLA: DRENAGEM SUPERFICIAL","OK"))) -> OK
A17: 296ETO0170 | B17: C | C17: 8 | D17: 9 | E17: =D17-C17 -> 1 | G17: X | J17: X | N17: =IF(COUNTA(F17:L17)=0,"— não preenchido",IF(COUNTIF(F17:I17,"X")<>1,"FALTA/DUPLA: CONDIÇÃO DA PLATAFORMA",IF(COUNTIF(J17:L17,"X")<>1,"FALTA/DUPLA: DRENAGEM SUPERFICIAL","OK"))) -> OK
A18: 296ETO0170 | B18: C | C18: 9 | D18: 10 | E18: =D18-C18 -> 1 | G18: X | J18: X | N18: =IF(COUNTA(F18:L18)=0,"— não preenchido",IF(COUNTIF(F18:I18,"X")<>1,"FALTA/DUPLA: CONDIÇÃO DA PLATAFORMA",IF(COUNTIF(J18:L18,"X")<>1,"FALTA/DUPLA: DRENAGEM SUPERFICIAL","OK"))) -> OK
A19: 296ETO0170 | B19: C | C19: 10 | D19: 11 | E19: =D19-C19 -> 1 | G19: X | J19: X | N19: =IF(COUNTA(F19:L19)=0,"— não preenchido",IF(COUNTIF(F19:I19,"X")<>1,"FALTA/DUPLA: CONDIÇÃO DA PLATAFORMA",IF(COUNTIF(J19:L19,"X")<>1,"FALTA/DUPLA: DRENAGEM SUPERFICIAL","OK"))) -> OK
A20: 296ETO0170 | B20: C | C20: 11 | D20: 12 | E20: =D20-C20 -> 1 | G20: X | J20: X | N20: =IF(COUNTA(F20:L20)=0,"— não preenchido",IF(COUNTIF(F20:I20,"X")<>1,"FALTA/DUPLA: CONDIÇÃO DA PLATAFORMA",IF(COUNTIF(J20:L20,"X")<>1,"FALTA/DUPLA: DRENAGEM SUPERFICIAL","OK"))) -> OK
... A30: 296ETO0170 | B30: C | C30: 21 | D30: 22 | E30: =D30-C30 -> 1 | G30: X | J30: X | N30: =IF(COUNTA(F30:L30)=0,"— não preenchido",IF(COUNTIF(F30:I30,"X")<>1,"FALTA/DUPLA: CONDIÇÃO DA PLATAFORMA",IF(COUNTIF(J30:L30,"X")<>1,"FALTA/DUPLA: DRENAGEM SUPERFICIAL","OK"))) -> OK
A31: 296ETO0170 | B31: C | C31: 22 | D31: 23 | E31: =D31-C31 -> 1 | G31: X | K31: X | N31: =IF(COUNTA(F31:L31)=0,"— não preenchido",IF(COUNTIF(F31:I31,"X")<>1,"FALTA/DUPLA: CONDIÇÃO DA PLATAFORMA",IF(COUNTIF(J31:L31,"X")<>1,"FALTA/DUPLA: DRENAGEM SUPERFICIAL","OK"))) -> OK
A32: 296ETO0170 | B32: C | C32: 23 | D32: 24 | E32: =D32-C32 -> 1 | G32: X | K32: X | N32: =IF(COUNTA(F32:L32)=0,"— não preenchido",IF(COUNTIF(F32:I32,"X")<>1,"FALTA/DUPLA: CONDIÇÃO DA PLATAFORMA",IF(COUNTIF(J32:L32,"X")<>1,"FALTA/DUPLA: DRENAGEM SUPERFICIAL","OK"))) -> OK
A33: 296ETO0170 | B33: C | C33: 24 | D33: 25 | E33: =D33-C33 -> 1 | G33: X | K33: X | N33: =IF(COUNTA(F33:L33)=0,"— não preenchido",IF(COUNTIF(F33:I33,"X")<>1,"FALTA/DUPLA: CONDIÇÃO DA PLATAFORMA",IF(COUNTIF(J33:L33,"X")<>1,"FALTA/DUPLA: DRENAGEM SUPERFICIAL","OK"))) -> OK
A34: 296ETO0170 | B34: C | C34: 25 | D34: 26 | E34: =D34-C34 -> 1 | G34: X | K34: X | N34: =IF(COUNTA(F34:L34)=0,"— não preenchido",IF(COUNTIF(F34:I34,"X")<>1,"FALTA/DUPLA: CONDIÇÃO DA PLATAFORMA",IF(COUNTIF(J34:L34,"X")<>1,"FALTA/DUPLA: DRENAGEM SUPERFICIAL","OK"))) -> OK
A35: 296ETO0170 | B35: C | C35: 26 | D35: 27 | E35: =D35-C35 -> 1 | G35: X | K35: X | N35: =IF(COUNTA(F35:L35)=0,"— não preenchido",IF(COUNTIF(F35:I35,"X")<>1,"FALTA/DUPLA: CONDIÇÃO DA PLATAFORMA",IF(COUNTIF(J35:L35,"X")<>1,"FALTA/DUPLA: DRENAGEM SUPERFICIAL","OK"))) -> OK
A36: 296ETO0170 | B36: C | C36: 27 | D36: 28 | E36: =D36-C36 -> 1 | G36: X | K36: X | N36: =IF(COUNTA(F36:L36)=0,"— não preenchido",IF(COUNTIF(F36:I36,"X")<>1,"FALTA/DUPLA: CONDIÇÃO DA PLATAFORMA",IF(COUNTIF(J36:L36,"X")<>1,"FALTA/DUPLA: DRENAGEM SUPERFICIAL","OK"))) -> OK
A37: 296ETO0170 | B37: C | C37: 28 | D37: 29 | E37: =D37-C37 -> 1 | G37: X | K37: X | N37: =IF(COUNTA(F37:L37)=0,"— não preenchido",IF(COUNTIF(F37:I37,"X")<>1,"FALTA/DUPLA: CONDIÇÃO DA PLATAFORMA",IF(COUNTIF(J37:L37,"X")<>1,"FALTA/DUPLA: DRENAGEM SUPERFICIAL","OK"))) -> OK
A38: 296ETO0170 | B38: C | C38: 29 | D38: 30 | E38: =D38-C38 -> 1 | G38: X | K38: X | N38: =IF(COUNTA(F38:L38)=0,"— não preenchido",IF(COUNTIF(F38:I38,"X")<>1,"FALTA/DUPLA: CONDIÇÃO DA PLATAFORMA",IF(COUNTIF(J38:L38,"X")<>1,"FALTA/DUPLA: DRENAGEM SUPERFICIAL","OK"))) -> OK
A39: 296ETO0170 | B39: C | C39: 30 | D39: 31 | E39: =D39-C39 -> 1 | G39: X | K39: X | N39: =IF(COUNTA(F39:L39)=0,"— não preenchido",IF(COUNTIF(F39:I39,"X")<>1,"FALTA/DUPLA: CONDIÇÃO DA PLATAFORMA",IF(COUNTIF(J39:L39,"X")<>1,"FALTA/DUPLA: DRENAGEM SUPERFICIAL","OK"))) -> OK
A40: 296ETO0170 | B40: C | C40: 31 | D40: 32 | E40: =D40-C40 -> 1 | G40: X | K40: X | N40: =IF(COUNTA(F40:L40)=0,"— não preenchido",IF(COUNTIF(F40:I40,"X")<>1,"FALTA/DUPLA: CONDIÇÃO DA PLATAFORMA",IF(COUNTIF(J40:L40,"X")<>1,"FALTA/DUPLA: DRENAGEM SUPERFICIAL","OK"))) -> OK
A41: 296ETO0170 | B41: C | C41: 32 | D41: 33 | E41: =D41-C41 -> 1 | G41: X | K41: X | N41: =IF(COUNTA(F41:L41)=0,"— não preenchido",IF(COUNTIF(F41:I41,"X")<>1,"FALTA/DUPLA: CONDIÇÃO DA PLATAFORMA",IF(COUNTIF(J41:L41,"X")<>1,"FALTA/DUPLA: DRENAGEM SUPERFICIAL","OK"))) -> OK
A42: 296ETO0170 | B42: C | C42: 33 | D42: 34 | E42: =D42-C42 -> 1 | G42: X | K42: X | N42: =IF(COUNTA(F42:L42)=0,"— não preenchido",IF(COUNTIF(F42:I42,"X")<>1,"FALTA/DUPLA: CONDIÇÃO DA PLATAFORMA",IF(COUNTIF(J42:L42,"X")<>1,"FALTA/DUPLA: DRENAGEM SUPERFICIAL","OK"))) -> OK
... A59: 296ETO0170 | B59: C | C59: 50 | D59: 50.619704 | E59: =D59-C59 -> 0.61970428 | G59: X | K59: X | N59: =IF(COUNTA(F59:L59)=0,"— não preenchido",IF(COUNTIF(F59:I59,"X")<>1,"FALTA/DUPLA: CONDIÇÃO DA PLATAFORMA",IF(COUNTIF(J59:L59,"X")<>1,"FALTA/DUPLA: DRENAGEM SUPERFICIAL","OK"))) -> OK
A61: ____________________________________________ | G61: ____________________________________________
A62: TÉCNICO RESPONSÁVEL PELA INSPEÇÃO | G62: VISTO DA SUPERVISÃO
A64: RESUMO DO TRECHO — KM LANÇADO POR ITEM
A65: KM LANÇADO | F65: =SUMIF(F$9:F$59,"X",$E$9:$E$59) -> 0 | G65: =SUMIF(G$9:G$59,"X",$E$9:$E$59) -> 50.619704 | H65: =SUMIF(H$9:H$59,"X",$E$9:$E$59) -> 0 | I65: =SUMIF(I$9:I$59,"X",$E$9:$E$59) -> 0 | J65: =SUMIF(J$9:J$59,"X",$E$9:$E$59) -> 22 | K65: =SUMIF(K$9:K$59,"X",$E$9:$E$59) -> 28.619704 | L65: =SUMIF(L$9:L$59,"X",$E$9:$E$59) -> 0
A66: % DA EXTENSÃO | F66: =IF($I68=0,0,F65/$I68) -> 0 | G66: =IF($I68=0,0,G65/$I68) -> 1 | H66: =IF($I68=0,0,H65/$I68) -> 0 | I66: =IF($I68=0,0,I65/$I68) -> 0 | J66: =IF($I68=0,0,J65/$I68) -> 0.43461336 | K66: =IF($I68=0,0,K65/$I68) -> 0.56538664 | L66: =IF($I68=0,0,L65/$I68) -> 0
A67: CONFERÊNCIA POR GRUPO | F67: =IF(SUM(F65:I65)=0,"— não preenchido",IF(ROUND(SUM(F65:I65)-$I68,3)=0,"OK — "&ROUND(SUM(F65:I65),3)&" km","ERRO — dif. de "&ROUND(SUM(F65:I65)-$I68,3)&" km")) -> OK — 50,62 km | J67: =IF(SUM(J65:L65)=0,"— não preenchido",IF(ROUND(SUM(J65:L65)-$I68,3)=0,"OK — "&ROUND(SUM(J65:L65),3)&" km","ERRO — dif. de "&ROUND(SUM(J65:L65)-$I68,3)&" km")) -> OK — 50,62 km
A68: EXTENSÃO TOTAL DO TRECHO | I68: =SUM(E9:E59) -> 50.619704 | M68: =COUNTIF(N9:N59,"OK")&" de "&COUNT($E$9:$E$59)&" linhas conferidas" -> 51 de 51 linhas conferidas
...

Sheet 262
A1: PROGRAMA DE MANUTENÇÃO RODOVIÁRIA — FICHA DE INSPEÇÃO — RODOVIAS NÃO PAVIMENTADAS | P1: Valores dos gráficos — troca 0 por N/D para a fatia não aparecer. Não editar.
A2: REGIÃO: 13 — DIANÓPOLIS | D2: MÊS / ANO: | G2: DATA: | J2: TÉCNICO: | P2: =IF(F38=0,NA(),F38) -> #N/A | Q2: =IF(G38=0,NA(),G38) -> 23.951037 | R2: =IF(H38=0,NA(),H38) -> #N/A | S2: =IF(I38=0,NA(),I38) -> #N/A | T2: =IF(J38=0,NA(),J38) -> 17 | U2: =IF(K38=0,NA(),K38) -> 6.9510366 | V2: =IF(L38=0,NA(),L38) -> #N/A
A3: TRECHO 262 — RODOVIA TO-369 - TRECHO ENTR. TO-040 - ENTR. TO-476 (FUNIL - RIO SONINHO) | K3: EXTENSÃO: 23,951 km · 1 S.R.E.
A4: COMO PREENCHER: uma X em UMA coluna de cada grupo, por linha. Se houver mais de um defeito no mesmo km, marque o PREDOMINANTE e escreva o resto em OBSERVAÇÕES. A quilometragem é contada de 0 até o fim de CADA S.R.E. (não é o marco da rodovia).
A6: S.R.E. | B6: SENT. | C6: INÍCIO (KM) | D6: FIM (KM) | E6: EXT. (KM) | F6: CONDIÇÃO DA PLATAFORMA | J6: DRENAGEM SUPERFICIAL | M6: OBSERVAÇÕES | N6: CONFERÊNCIA (só na tela)
F7: BOM | G7: REGULAR | H7: RUIM | I7: PÉSSIMA | J7: LIMPA | K7: OBSTRUÍDA | L7: AUSENTE
A8: S.R.E. 369ETO0100 | ENTR. TO-476 - ENTR. TO-040 | LEN · Estadual · 23.951 km · início: -10.98981, -47.228897
A9: 369ETO0100 | B9: C | C9: 0 | D9: 1 | E9: =D9-C9 -> 1 | G9: X | J9: X | N9: =IF(COUNTA(F9:L9)=0,"— não preenchido",IF(COUNTIF(F9:I9,"X")<>1,"FALTA/DUPLA: CONDIÇÃO DA PLATAFORMA",IF(COUNTIF(J9:L9,"X")<>1,"FALTA/DUPLA: DRENAGEM SUPERFICIAL","OK"))) -> OK
A10: 369ETO0100 | B10: C | C10: 1 | D10: 2 | E10: =D10-C10 -> 1 | G10: X | J10: X | N10: =IF(COUNTA(F10:L10)=0,"— não preenchido",IF(COUNTIF(F10:I10,"X")<>1,"FALTA/DUPLA: CONDIÇÃO DA PLATAFORMA",IF(COUNTIF(J10:L10,"X")<>1,"FALTA/DUPLA: DRENAGEM SUPERFICIAL","OK"))) -> OK
A11: 369ETO0100 | B11: C | C11: 2 | D11: 3 | E11: =D11-C11 -> 1 | G11: X | J11: X | N11: =IF(COUNTA(F11:L11)=0,"— não preenchido",IF(COUNTIF(F11:I11,"X")<>1,"FALTA/DUPLA: CONDIÇÃO DA PLATAFORMA",IF(COUNTIF(J11:L11,"X")<>1,"FALTA/DUPLA: DRENAGEM SUPERFICIAL","OK"))) -> OK
A12: 369ETO0100 | B12: C | C12: 3 | D12: 4 | E12: =D12-C12 -> 1 | G12: X | J12: X | N12: =IF(COUNTA(F12:L12)=0,"— não preenchido",IF(COUNTIF(F12:I12,"X")<>1,"FALTA/DUPLA: CONDIÇÃO DA PLATAFORMA",IF(COUNTIF(J12:L12,"X")<>1,"FALTA/DUPLA: DRENAGEM SUPERFICIAL","OK"))) -> OK
A13: 369ETO0100 | B13: C | C13: 4 | D13: 5 | E13: =D13-C13 -> 1 | G13: X | J13: X | N13: =IF(COUNTA(F13:L13)=0,"— não preenchido",IF(COUNTIF(F13:I13,"X")<>1,"FALTA/DUPLA: CONDIÇÃO DA PLATAFORMA",IF(COUNTIF(J13:L13,"X")<>1,"FALTA/DUPLA: DRENAGEM SUPERFICIAL","OK"))) -> OK
A14: 369ETO0100 | B14: C | C14: 5 | D14: 6 | E14: =D14-C14 -> 1 | G14: X | J14: X | N14: =IF(COUNTA(F14:L14)=0,"— não preenchido",IF(COUNTIF(F14:I14,"X")<>1,"FALTA/DUPLA: CONDIÇÃO DA PLATAFORMA",IF(COUNTIF(J14:L14,"X")<>1,"FALTA/DUPLA: DRENAGEM SUPERFICIAL","OK"))) -> OK
A15: 369ETO0100 | B15: C | C15: 6 | D15: 7 | E15: =D15-C15 -> 1 | G15: X | J15: X | N15: =IF(COUNTA(F15:L15)=0,"— não preenchido",IF(COUNTIF(F15:I15,"X")<>1,"FALTA/DUPLA: CONDIÇÃO DA PLATAFORMA",IF(COUNTIF(J15:L15,"X")<>1,"FALTA/DUPLA: DRENAGEM SUPERFICIAL","OK"))) -> OK
A16: 369ETO0100 | B16: C | C16: 7 | D16: 8 | E16: =D16-C16 -> 1 | G16: X | J16: X | N16: =IF(COUNTA(F16:L16)=0,"— não preenchido",IF(COUNTIF(F16:I16,"X")<>1,"FALTA/DUPLA: CONDIÇÃO DA PLATAFORMA",IF(COUNTIF(J16:L16,"X")<>1,"FALTA/DUPLA: DRENAGEM SUPERFICIAL","OK"))) -> OK
A17: 369ETO0100 | B17: C | C17: 8 | D17: 9 | E17: =D17-C17 -> 1 | G17: X | J17: X | N17: =IF(COUNTA(F17:L17)=0,"— não preenchido",IF(COUNTIF(F17:I17,"X")<>1,"FALTA/DUPLA: CONDIÇÃO DA PLATAFORMA",IF(COUNTIF(J17:L17,"X")<>1,"FALTA/DUPLA: DRENAGEM SUPERFICIAL","OK"))) -> OK
A18: 369ETO0100 | B18: C | C18: 9 | D18: 10 | E18: =D18-C18 -> 1 | G18: X | J18: X | N18: =IF(COUNTA(F18:L18)=0,"— não preenchido",IF(COUNTIF(F18:I18,"X")<>1,"FALTA/DUPLA: CONDIÇÃO DA PLATAFORMA",IF(COUNTIF(J18:L18,"X")<>1,"FALTA/DUPLA: DRENAGEM SUPERFICIAL","OK"))) -> OK
A19: 369ETO0100 | B19: C | C19: 10 | D19: 11 | E19: =D19-C19 -> 1 | G19: X | J19: X | N19: =IF(COUNTA(F19:L19)=0,"— não preenchido",IF(COUNTIF(F19:I19,"X")<>1,"FALTA/DUPLA: CONDIÇÃO DA PLATAFORMA",IF(COUNTIF(J19:L19,"X")<>1,"FALTA/DUPLA: DRENAGEM SUPERFICIAL","OK"))) -> OK
A20: 369ETO0100 | B20: C | C20: 11 | D20: 12 | E20: =D20-C20 -> 1 | G20: X | J20: X | N20: =IF(COUNTA(F20:L20)=0,"— não preenchido",IF(COUNTIF(F20:I20,"X")<>1,"FALTA/DUPLA: CONDIÇÃO DA PLATAFORMA",IF(COUNTIF(J20:L20,"X")<>1,"FALTA/DUPLA: DRENAGEM SUPERFICIAL","OK"))) -> OK
... A25: 369ETO0100 | B25: C | C25: 16 | D25: 17 | E25: =D25-C25 -> 1 | G25: X | J25: X | N25: =IF(COUNTA(F25:L25)=0,"— não preenchido",IF(COUNTIF(F25:I25,"X")<>1,"FALTA/DUPLA: CONDIÇÃO DA PLATAFORMA",IF(COUNTIF(J25:L25,"X")<>1,"FALTA/DUPLA: DRENAGEM SUPERFICIAL","OK"))) -> OK
A26: 369ETO0100 | B26: C | C26: 17 | D26: 18 | E26: =D26-C26 -> 1 | G26: X | K26: X | N26: =IF(COUNTA(F26:L26)=0,"— não preenchido",IF(COUNTIF(F26:I26,"X")<>1,"FALTA/DUPLA: CONDIÇÃO DA PLATAFORMA",IF(COUNTIF(J26:L26,"X")<>1,"FALTA/DUPLA: DRENAGEM SUPERFICIAL","OK"))) -> OK
A27: 369ETO0100 | B27: C | C27: 18 | D27: 19 | E27: =D27-C27 -> 1 | G27: X | K27: X | N27: =IF(COUNTA(F27:L27)=0,"— não preenchido",IF(COUNTIF(F27:I27,"X")<>1,"FALTA/DUPLA: CONDIÇÃO DA PLATAFORMA",IF(COUNTIF(J27:L27,"X")<>1,"FALTA/DUPLA: DRENAGEM SUPERFICIAL","OK"))) -> OK
A28: 369ETO0100 | B28: C | C28: 19 | D28: 20 | E28: =D28-C28 -> 1 | G28: X | K28: X | N28: =IF(COUNTA(F28:L28)=0,"— não preenchido",IF(COUNTIF(F28:I28,"X")<>1,"FALTA/DUPLA: CONDIÇÃO DA PLATAFORMA",IF(COUNTIF(J28:L28,"X")<>1,"FALTA/DUPLA: DRENAGEM SUPERFICIAL","OK"))) -> OK
A29: 369ETO0100 | B29: C | C29: 20 | D29: 21 | E29: =D29-C29 -> 1 | G29: X | K29: X | N29: =IF(COUNTA(F29:L29)=0,"— não preenchido",IF(COUNTIF(F29:I29,"X")<>1,"FALTA/DUPLA: CONDIÇÃO DA PLATAFORMA",IF(COUNTIF(J29:L29,"X")<>1,"FALTA/DUPLA: DRENAGEM SUPERFICIAL","OK"))) -> OK
A30: 369ETO0100 | B30: C | C30: 21 | D30: 22 | E30: =D30-C30 -> 1 | G30: X | K30: X | N30: =IF(COUNTA(F30:L30)=0,"— não preenchido",IF(COUNTIF(F30:I30,"X")<>1,"FALTA/DUPLA: CONDIÇÃO DA PLATAFORMA",IF(COUNTIF(J30:L30,"X")<>1,"FALTA/DUPLA: DRENAGEM SUPERFICIAL","OK"))) -> OK
A31: 369ETO0100 | B31: C | C31: 22 | D31: 23 | E31: =D31-C31 -> 1 | G31: X | K31: X | N31: =IF(COUNTA(F31:L31)=0,"— não preenchido",IF(COUNTIF(F31:I31,"X")<>1,"FALTA/DUPLA: CONDIÇÃO DA PLATAFORMA",IF(COUNTIF(J31:L31,"X")<>1,"FALTA/DUPLA: DRENAGEM SUPERFICIAL","OK"))) -> OK
A32: 369ETO0100 | B32: C | C32: 23 | D32: 23.951037 | E32: =D32-C32 -> 0.95103656 | G32: X | K32: X | N32: =IF(COUNTA(F32:L32)=0,"— não preenchido",IF(COUNTIF(F32:I32,"X")<>1,"FALTA/DUPLA: CONDIÇÃO DA PLATAFORMA",IF(COUNTIF(J32:L32,"X")<>1,"FALTA/DUPLA: DRENAGEM SUPERFICIAL","OK"))) -> OK
A34: ____________________________________________ | G34: ____________________________________________
A35: TÉCNICO RESPONSÁVEL PELA INSPEÇÃO | G35: VISTO DA SUPERVISÃO
A37: RESUMO DO TRECHO — KM LANÇADO POR ITEM
A38: KM LANÇADO | F38: =SUMIF(F$9:F$32,"X",$E$9:$E$32) -> 0 | G38: =SUMIF(G$9:G$32,"X",$E$9:$E$32) -> 23.951037 | H38: =SUMIF(H$9:H$32,"X",$E$9:$E$32) -> 0 | I38: =SUMIF(I$9:I$32,"X",$E$9:$E$32) -> 0 | J38: =SUMIF(J$9:J$32,"X",$E$9:$E$32) -> 17 | K38: =SUMIF(K$9:K$32,"X",$E$9:$E$32) -> 6.9510366 | L38: =SUMIF(L$9:L$32,"X",$E$9:$E$32) -> 0
A39: % DA EXTENSÃO | F39: =IF($I41=0,0,F38/$I41) -> 0 | G39: =IF($I41=0,0,G38/$I41) -> 1 | H39: =IF($I41=0,0,H38/$I41) -> 0 | I39: =IF($I41=0,0,I38/$I41) -> 0 | J39: =IF($I41=0,0,J38/$I41) -> 0.70978139 | K39: =IF($I41=0,0,K38/$I41) -> 0.29021861 | L39: =IF($I41=0,0,L38/$I41) -> 0
A40: CONFERÊNCIA POR GRUPO | F40: =IF(SUM(F38:I38)=0,"— não preenchido",IF(ROUND(SUM(F38:I38)-$I41,3)=0,"OK — "&ROUND(SUM(F38:I38),3)&" km","ERRO — dif. de "&ROUND(SUM(F38:I38)-$I41,3)&" km")) -> OK — 23,951 km | J40: =IF(SUM(J38:L38)=0,"— não preenchido",IF(ROUND(SUM(J38:L38)-$I41,3)=0,"OK — "&ROUND(SUM(J38:L38),3)&" km","ERRO — dif. de "&ROUND(SUM(J38:L38)-$I41,3)&" km")) -> OK — 23,951 km
A41: EXTENSÃO TOTAL DO TRECHO | I41: =SUM(E9:E32) -> 23.951037 | M41: =COUNTIF(N9:N32,"OK")&" de "&COUNT($E$9:$E$32)&" linhas conferidas" -> 24 de 24 linhas conferidas
A43: LEGENDA
A44: REGULAR | E44: Até 10 irregularidades por km
A45: RUIM | E45: Mais de 10 irregularidades por km
A46: PÉSSIMA | E46: Atoleiro ou ponto crítico
A47: SIT. | E47: LEN = leito natural · EOP = em obras de pavimentação
A48: FAIXA AZUL | E48: Cabeçalho de cada S.R.E.: descrição, situação, jurisdição, extensão e coordenada de início.
...

Sheet 263
A1: PROGRAMA DE MANUTENÇÃO RODOVIÁRIA — FICHA DE INSPEÇÃO — RODOVIAS NÃO PAVIMENTADAS | P1: Valores dos gráficos — troca 0 por N/D para a fatia não aparecer. Não editar.
A2: REGIÃO: 13 — DIANÓPOLIS | D2: MÊS / ANO: | G2: DATA: | J2: TÉCNICO: | P2: =IF(F54=0,NA(),F54) -> 39.5018 | Q2: =IF(G54=0,NA(),G54) -> #N/A | R2: =IF(H54=0,NA(),H54) -> #N/A | S2: =IF(I54=0,NA(),I54) -> #N/A | T2: =IF(J54=0,NA(),J54) -> 32.5018 | U2: =IF(K54=0,NA(),K54) -> 7 | V2: =IF(L54=0,NA(),L54) -> #N/A
A3: TRECHO 263 — RODOVIA TO-387 - TRECHO CONCEIÇÃO DO TOCANTINS - TAIPAS DO TOCANTINS | K3: EXTENSÃO: 39,502 km · 1 S.R.E.
A4: COMO PREENCHER: uma X em UMA coluna de cada grupo, por linha. Se houver mais de um defeito no mesmo km, marque o PREDOMINANTE e escreva o resto em OBSERVAÇÕES. A quilometragem é contada de 0 até o fim de CADA S.R.E. (não é o marco da rodovia).
A6: S.R.E. | B6: SENT. | C6: INÍCIO (KM) | D6: FIM (KM) | E6: EXT. (KM) | F6: CONDIÇÃO DA PLATAFORMA | J6: DRENAGEM SUPERFICIAL | M6: OBSERVAÇÕES | N6: CONFERÊNCIA (só na tela)
F7: BOM | G7: REGULAR | H7: RUIM | I7: PÉSSIMA | J7: LIMPA | K7: OBSTRUÍDA | L7: AUSENTE
A8: S.R.E. 387ETO0070 | ENTR. TO-485 (TAIPAS) - CONCEIÇÃO DO TOCANTINS *TRECHO URBANO* | LEN · Estadual · 39.502 km · início: -12.205354, -46.990971
A9: 387ETO0070 | B9: C | C9: 0 | D9: 1 | E9: =D9-C9 -> 1 | F9: X | J9: X | N9: =IF(COUNTA(F9:L9)=0,"— não preenchido",IF(COUNTIF(F9:I9,"X")<>1,"FALTA/DUPLA: CONDIÇÃO DA PLATAFORMA",IF(COUNTIF(J9:L9,"X")<>1,"FALTA/DUPLA: DRENAGEM SUPERFICIAL","OK"))) -> OK
A10: 387ETO0070 | B10: C | C10: 1 | D10: 2 | E10: =D10-C10 -> 1 | F10: X | J10: X | N10: =IF(COUNTA(F10:L10)=0,"— não preenchido",IF(COUNTIF(F10:I10,"X")<>1,"FALTA/DUPLA: CONDIÇÃO DA PLATAFORMA",IF(COUNTIF(J10:L10,"X")<>1,"FALTA/DUPLA: DRENAGEM SUPERFICIAL","OK"))) -> OK
A11: 387ETO0070 | B11: C | C11: 2 | D11: 3 | E11: =D11-C11 -> 1 | F11: X | J11: X | N11: =IF(COUNTA(F11:L11)=0,"— não preenchido",IF(COUNTIF(F11:I11,"X")<>1,"FALTA/DUPLA: CONDIÇÃO DA PLATAFORMA",IF(COUNTIF(J11:L11,"X")<>1,"FALTA/DUPLA: DRENAGEM SUPERFICIAL","OK"))) -> OK
A12: 387ETO0070 | B12: C | C12: 3 | D12: 4 | E12: =D12-C12 -> 1 | F12: X | J12: X | N12: =IF(COUNTA(F12:L12)=0,"— não preenchido",IF(COUNTIF(F12:I12,"X")<>1,"FALTA/DUPLA: CONDIÇÃO DA PLATAFORMA",IF(COUNTIF(J12:L12,"X")<>1,"FALTA/DUPLA: DRENAGEM SUPERFICIAL","OK"))) -> OK
A13: 387ETO0070 | B13: C | C13: 4 | D13: 5 | E13: =D13-C13 -> 1 | F13: X | J13: X | N13: =IF(COUNTA(F13:L13)=0,"— não preenchido",IF(COUNTIF(F13:I13,"X")<>1,"FALTA/DUPLA: CONDIÇÃO DA PLATAFORMA",IF(COUNTIF(J13:L13,"X")<>1,"FALTA/DUPLA: DRENAGEM SUPERFICIAL","OK"))) -> OK
A14: 387ETO0070 | B14: C | C14: 5 | D14: 6 | E14: =D14-C14 -> 1 | F14: X | J14: X | N14: =IF(COUNTA(F14:L14)=0,"— não preenchido",IF(COUNTIF(F14:I14,"X")<>1,"FALTA/DUPLA: CONDIÇÃO DA PLATAFORMA",IF(COUNTIF(J14:L14,"X")<>1,"FALTA/DUPLA: DRENAGEM SUPERFICIAL","OK"))) -> OK
A15: 387ETO0070 | B15: C | C15: 6 | D15: 7 | E15: =D15-C15 -> 1 | F15: X | J15: X | N15: =IF(COUNTA(F15:L15)=0,"— não preenchido",IF(COUNTIF(F15:I15,"X")<>1,"FALTA/DUPLA: CONDIÇÃO DA PLATAFORMA",IF(COUNTIF(J15:L15,"X")<>1,"FALTA/DUPLA: DRENAGEM SUPERFICIAL","OK"))) -> OK
A16: 387ETO0070 | B16: C | C16: 7 | D16: 8 | E16: =D16-C16 -> 1 | F16: X | J16: X | N16: =IF(COUNTA(F16:L16)=0,"— não preenchido",IF(COUNTIF(F16:I16,"X")<>1,"FALTA/DUPLA: CONDIÇÃO DA PLATAFORMA",IF(COUNTIF(J16:L16,"X")<>1,"FALTA/DUPLA: DRENAGEM SUPERFICIAL","OK"))) -> OK
A17: 387ETO0070 | B17: C | C17: 8 | D17: 9 | E17: =D17-C17 -> 1 | F17: X | J17: X | N17: =IF(COUNTA(F17:L17)=0,"— não preenchido",IF(COUNTIF(F17:I17,"X")<>1,"FALTA/DUPLA: CONDIÇÃO DA PLATAFORMA",IF(COUNTIF(J17:L17,"X")<>1,"FALTA/DUPLA: DRENAGEM SUPERFICIAL","OK"))) -> OK
A18: 387ETO0070 | B18: C | C18: 9 | D18: 10 | E18: =D18-C18 -> 1 | F18: X | J18: X | N18: =IF(COUNTA(F18:L18)=0,"— não preenchido",IF(COUNTIF(F18:I18,"X")<>1,"FALTA/DUPLA: CONDIÇÃO DA PLATAFORMA",IF(COUNTIF(J18:L18,"X")<>1,"FALTA/DUPLA: DRENAGEM SUPERFICIAL","OK"))) -> OK
A19: 387ETO0070 | B19: C | C19: 10 | D19: 11 | E19: =D19-C19 -> 1 | F19: X | J19: X | N19: =IF(COUNTA(F19:L19)=0,"— não preenchido",IF(COUNTIF(F19:I19,"X")<>1,"FALTA/DUPLA: CONDIÇÃO DA PLATAFORMA",IF(COUNTIF(J19:L19,"X")<>1,"FALTA/DUPLA: DRENAGEM SUPERFICIAL","OK"))) -> OK
A20: 387ETO0070 | B20: C | C20: 11 | D20: 12 | E20: =D20-C20 -> 1 | F20: X | J20: X | N20: =IF(COUNTA(F20:L20)=0,"— não preenchido",IF(COUNTIF(F20:I20,"X")<>1,"FALTA/DUPLA: CONDIÇÃO DA PLATAFORMA",IF(COUNTIF(J20:L20,"X")<>1,"FALTA/DUPLA: DRENAGEM SUPERFICIAL","OK"))) -> OK
... A23: 387ETO0070 | B23: C | C23: 14 | D23: 15 | E23: =D23-C23 -> 1 | F23: X | J23: X | N23: =IF(COUNTA(F23:L23)=0,"— não preenchido",IF(COUNTIF(F23:I23,"X")<>1,"FALTA/DUPLA: CONDIÇÃO DA PLATAFORMA",IF(COUNTIF(J23:L23,"X")<>1,"FALTA/DUPLA: DRENAGEM SUPERFICIAL","OK"))) -> OK
A24: 387ETO0070 | B24: C | C24: 15 | D24: 16 | E24: =D24-C24 -> 1 | F24: X | K24: X | N24: =IF(COUNTA(F24:L24)=0,"— não preenchido",IF(COUNTIF(F24:I24,"X")<>1,"FALTA/DUPLA: CONDIÇÃO DA PLATAFORMA",IF(COUNTIF(J24:L24,"X")<>1,"FALTA/DUPLA: DRENAGEM SUPERFICIAL","OK"))) -> OK
A25: 387ETO0070 | B25: C | C25: 16 | D25: 17 | E25: =D25-C25 -> 1 | F25: X | K25: X | N25: =IF(COUNTA(F25:L25)=0,"— não preenchido",IF(COUNTIF(F25:I25,"X")<>1,"FALTA/DUPLA: CONDIÇÃO DA PLATAFORMA",IF(COUNTIF(J25:L25,"X")<>1,"FALTA/DUPLA: DRENAGEM SUPERFICIAL","OK"))) -> OK
A26: 387ETO0070 | B26: C | C26: 17 | D26: 18 | E26: =D26-C26 -> 1 | F26: X | K26: X | N26: =IF(COUNTA(F26:L26)=0,"— não preenchido",IF(COUNTIF(F26:I26,"X")<>1,"FALTA/DUPLA: CONDIÇÃO DA PLATAFORMA",IF(COUNTIF(J26:L26,"X")<>1,"FALTA/DUPLA: DRENAGEM SUPERFICIAL","OK"))) -> OK
A27: 387ETO0070 | B27: C | C27: 18 | D27: 19 | E27: =D27-C27 -> 1 | F27: X | K27: X | N27: =IF(COUNTA(F27:L27)=0,"— não preenchido",IF(COUNTIF(F27:I27,"X")<>1,"FALTA/DUPLA: CONDIÇÃO DA PLATAFORMA",IF(COUNTIF(J27:L27,"X")<>1,"FALTA/DUPLA: DRENAGEM SUPERFICIAL","OK"))) -> OK
A28: 387ETO0070 | B28: C | C28: 19 | D28: 20 | E28: =D28-C28 -> 1 | F28: X | K28: X | N28: =IF(COUNTA(F28:L28)=0,"— não preenchido",IF(COUNTIF(F28:I28,"X")<>1,"FALTA/DUPLA: CONDIÇÃO DA PLATAFORMA",IF(COUNTIF(J28:L28,"X")<>1,"FALTA/DUPLA: DRENAGEM SUPERFICIAL","OK"))) -> OK
A29: 387ETO0070 | B29: C | C29: 20 | D29: 21 | E29: =D29-C29 -> 1 | F29: X | K29: X | N29: =IF(COUNTA(F29:L29)=0,"— não preenchido",IF(COUNTIF(F29:I29,"X")<>1,"FALTA/DUPLA: CONDIÇÃO DA PLATAFORMA",IF(COUNTIF(J29:L29,"X")<>1,"FALTA/DUPLA: DRENAGEM SUPERFICIAL","OK"))) -> OK
A30: 387ETO0070 | B30: C | C30: 21 | D30: 22 | E30: =D30-C30 -> 1 | F30: X | K30: X | N30: =IF(COUNTA(F30:L30)=0,"— não preenchido",IF(COUNTIF(F30:I30,"X")<>1,"FALTA/DUPLA: CONDIÇÃO DA PLATAFORMA",IF(COUNTIF(J30:L30,"X")<>1,"FALTA/DUPLA: DRENAGEM SUPERFICIAL","OK"))) -> OK
A31: 387ETO0070 | B31: C | C31: 22 | D31: 23 | E31: =D31-C31 -> 1 | F31: X | J31: X | N31: =IF(COUNTA(F31:L31)=0,"— não preenchido",IF(COUNTIF(F31:I31,"X")<>1,"FALTA/DUPLA: CONDIÇÃO DA PLATAFORMA",IF(COUNTIF(J31:L31,"X")<>1,"FALTA/DUPLA: DRENAGEM SUPERFICIAL","OK"))) -> OK
A32: 387ETO0070 | B32: C | C32: 23 | D32: 24 | E32: =D32-C32 -> 1 | F32: X | J32: X | N32: =IF(COUNTA(F32:L32)=0,"— não preenchido",IF(COUNTIF(F32:I32,"X")<>1,"FALTA/DUPLA: CONDIÇÃO DA PLATAFORMA",IF(COUNTIF(J32:L32,"X")<>1,"FALTA/DUPLA: DRENAGEM SUPERFICIAL","OK"))) -> OK
A33: 387ETO0070 | B33: C | C33: 24 | D33: 25 | E33: =D33-C33 -> 1 | F33: X | J33: X | N33: =IF(COUNTA(F33:L33)=0,"— não preenchido",IF(COUNTIF(F33:I33,"X")<>1,"FALTA/DUPLA: CONDIÇÃO DA PLATAFORMA",IF(COUNTIF(J33:L33,"X")<>1,"FALTA/DUPLA: DRENAGEM SUPERFICIAL","OK"))) -> OK
A34: 387ETO0070 | B34: C | C34: 25 | D34: 26 | E34: =D34-C34 -> 1 | F34: X | J34: X | N34: =IF(COUNTA(F34:L34)=0,"— não preenchido",IF(COUNTIF(F34:I34,"X")<>1,"FALTA/DUPLA: CONDIÇÃO DA PLATAFORMA",IF(COUNTIF(J34:L34,"X")<>1,"FALTA/DUPLA: DRENAGEM SUPERFICIAL","OK"))) -> OK
A35: 387ETO0070 | B35: C | C35: 26 | D35: 27 | E35: =D35-C35 -> 1 | F35: X | J35: X | N35: =IF(COUNTA(F35:L35)=0,"— não preenchido",IF(COUNTIF(F35:I35,"X")<>1,"FALTA/DUPLA: CONDIÇÃO DA PLATAFORMA",IF(COUNTIF(J35:L35,"X")<>1,"FALTA/DUPLA: DRENAGEM SUPERFICIAL","OK"))) -> OK
A36: 387ETO0070 | B36: C | C36: 27 | D36: 28 | E36: =D36-C36 -> 1 | F36: X | J36: X | N36: =IF(COUNTA(F36:L36)=0,"— não preenchido",IF(COUNTIF(F36:I36,"X")<>1,"FALTA/DUPLA: CONDIÇÃO DA PLATAFORMA",IF(COUNTIF(J36:L36,"X")<>1,"FALTA/DUPLA: DRENAGEM SUPERFICIAL","OK"))) -> OK
A37: 387ETO0070 | B37: C | C37: 28 | D37: 29 | E37: =D37-C37 -> 1 | F37: X | J37: X | N37: =IF(COUNTA(F37:L37)=0,"— não preenchido",IF(COUNTIF(F37:I37,"X")<>1,"FALTA/DUPLA: CONDIÇÃO DA PLATAFORMA",IF(COUNTIF(J37:L37,"X")<>1,"FALTA/DUPLA: DRENAGEM SUPERFICIAL","OK"))) -> OK
A38: 387ETO0070 | B38: C | C38: 29 | D38: 30 | E38: =D38-C38 -> 1 | F38: X | J38: X | N38: =IF(COUNTA(F38:L38)=0,"— não preenchido",IF(COUNTIF(F38:I38,"X")<>1,"FALTA/DUPLA: CONDIÇÃO DA PLATAFORMA",IF(COUNTIF(J38:L38,"X")<>1,"FALTA/DUPLA: DRENAGEM SUPERFICIAL","OK"))) -> OK
A39: 387ETO0070 | B39: C | C39: 30 | D39: 31 | E39: =D39-C39 -> 1 | F39: X | J39: X | N39: =IF(COUNTA(F39:L39)=0,"— não preenchido",IF(COUNTIF(F39:I39,"X")<>1,"FALTA/DUPLA: CONDIÇÃO DA PLATAFORMA",IF(COUNTIF(J39:L39,"X")<>1,"FALTA/DUPLA: DRENAGEM SUPERFICIAL","OK"))) -> OK
A40: 387ETO0070 | B40: C | C40: 31 | D40: 32 | E40: =D40-C40 -> 1 | F40: X | J40: X | N40: =IF(COUNTA(F40:L40)=0,"— não preenchido",IF(COUNTIF(F40:I40,"X")<>1,"FALTA/DUPLA: CONDIÇÃO DA PLATAFORMA",IF(COUNTIF(J40:L40,"X")<>1,"FALTA/DUPLA: DRENAGEM SUPERFICIAL","OK"))) -> OK
A41: 387ETO0070 | B41: C | C41: 32 | D41: 33 | E41: =D41-C41 -> 1 | F41: X | J41: X | N41: =IF(COUNTA(F41:L41)=0,"— não preenchido",IF(COUNTIF(F41:I41,"X")<>1,"FALTA/DUPLA: CONDIÇÃO DA PLATAFORMA",IF(COUNTIF(J41:L41,"X")<>1,"FALTA/DUPLA: DRENAGEM SUPERFICIAL","OK"))) -> OK
A42: 387ETO0070 | B42: C | C42: 33 | D42: 34 | E42: =D42-C42 -> 1 | F42: X | J42: X | N42: =IF(COUNTA(F42:L42)=0,"— não preenchido",IF(COUNTIF(F42:I42,"X")<>1,"FALTA/DUPLA: CONDIÇÃO DA PLATAFORMA",IF(COUNTIF(J42:L42,"X")<>1,"FALTA/DUPLA: DRENAGEM SUPERFICIAL","OK"))) -> OK
... A48: 387ETO0070 | B48: C | C48: 39 | D48: 39.5018 | E48: =D48-C48 -> 0.50180008 | F48: X | J48: X | N48: =IF(COUNTA(F48:L48)=0,"— não preenchido",IF(COUNTIF(F48:I48,"X")<>1,"FALTA/DUPLA: CONDIÇÃO DA PLATAFORMA",IF(COUNTIF(J48:L48,"X")<>1,"FALTA/DUPLA: DRENAGEM SUPERFICIAL","OK"))) -> OK
...

Sheet 264
A1: PROGRAMA DE MANUTENÇÃO RODOVIÁRIA — FICHA DE INSPEÇÃO — RODOVIAS NÃO PAVIMENTADAS | P1: Valores dos gráficos — troca 0 por N/D para a fatia não aparecer. Não editar.
A2: REGIÃO: 13 — DIANÓPOLIS | D2: MÊS / ANO: | G2: DATA: | J2: TÉCNICO: | P2: =IF(F57=0,NA(),F57) -> 25 | Q2: =IF(G57=0,NA(),G57) -> 17.464393 | R2: =IF(H57=0,NA(),H57) -> #N/A | S2: =IF(I57=0,NA(),I57) -> #N/A | T2: =IF(J57=0,NA(),J57) -> #N/A | U2: =IF(K57=0,NA(),K57) -> 42.464393 | V2: =IF(L57=0,NA(),L57) -> #N/A
A3: TRECHO 264 — RODOVIA TO-387 - TRECHO ENTR. BR-010 - ENTR. TO-050 (CONCEIÇÃO DO TOCANTINS) | K3: EXTENSÃO: 42,464 km · 1 S.R.E.
A4: COMO PREENCHER: uma X em UMA coluna de cada grupo, por linha. Se houver mais de um defeito no mesmo km, marque o PREDOMINANTE e escreva o resto em OBSERVAÇÕES. A quilometragem é contada de 0 até o fim de CADA S.R.E. (não é o marco da rodovia).
A6: S.R.E. | B6: SENT. | C6: INÍCIO (KM) | D6: FIM (KM) | E6: EXT. (KM) | F6: CONDIÇÃO DA PLATAFORMA | J6: DRENAGEM SUPERFICIAL | M6: OBSERVAÇÕES | N6: CONFERÊNCIA (só na tela)
F7: BOM | G7: REGULAR | H7: RUIM | I7: PÉSSIMA | J7: LIMPA | K7: OBSTRUÍDA | L7: AUSENTE
A8: S.R.E. 387ETO0100 | ENTR. TO-050 - ENTR. TO-130-BR-010 | LEN · Estadual · 42.464 km · início: -12.230213, -47.348306
A9: 387ETO0100 | B9: C | C9: 0 | D9: 1 | E9: =D9-C9 -> 1 | F9: X | K9: X | N9: =IF(COUNTA(F9:L9)=0,"— não preenchido",IF(COUNTIF(F9:I9,"X")<>1,"FALTA/DUPLA: CONDIÇÃO DA PLATAFORMA",IF(COUNTIF(J9:L9,"X")<>1,"FALTA/DUPLA: DRENAGEM SUPERFICIAL","OK"))) -> OK
A10: 387ETO0100 | B10: C | C10: 1 | D10: 2 | E10: =D10-C10 -> 1 | F10: X | K10: X | N10: =IF(COUNTA(F10:L10)=0,"— não preenchido",IF(COUNTIF(F10:I10,"X")<>1,"FALTA/DUPLA: CONDIÇÃO DA PLATAFORMA",IF(COUNTIF(J10:L10,"X")<>1,"FALTA/DUPLA: DRENAGEM SUPERFICIAL","OK"))) -> OK
A11: 387ETO0100 | B11: C | C11: 2 | D11: 3 | E11: =D11-C11 -> 1 | F11: X | K11: X | N11: =IF(COUNTA(F11:L11)=0,"— não preenchido",IF(COUNTIF(F11:I11,"X")<>1,"FALTA/DUPLA: CONDIÇÃO DA PLATAFORMA",IF(COUNTIF(J11:L11,"X")<>1,"FALTA/DUPLA: DRENAGEM SUPERFICIAL","OK"))) -> OK
A12: 387ETO0100 | B12: C | C12: 3 | D12: 4 | E12: =D12-C12 -> 1 | F12: X | K12: X | N12: =IF(COUNTA(F12:L12)=0,"— não preenchido",IF(COUNTIF(F12:I12,"X")<>1,"FALTA/DUPLA: CONDIÇÃO DA PLATAFORMA",IF(COUNTIF(J12:L12,"X")<>1,"FALTA/DUPLA: DRENAGEM SUPERFICIAL","OK"))) -> OK
A13: 387ETO0100 | B13: C | C13: 4 | D13: 5 | E13: =D13-C13 -> 1 | F13: X | K13: X | N13: =IF(COUNTA(F13:L13)=0,"— não preenchido",IF(COUNTIF(F13:I13,"X")<>1,"FALTA/DUPLA: CONDIÇÃO DA PLATAFORMA",IF(COUNTIF(J13:L13,"X")<>1,"FALTA/DUPLA: DRENAGEM SUPERFICIAL","OK"))) -> OK
A14: 387ETO0100 | B14: C | C14: 5 | D14: 6 | E14: =D14-C14 -> 1 | F14: X | K14: X | N14: =IF(COUNTA(F14:L14)=0,"— não preenchido",IF(COUNTIF(F14:I14,"X")<>1,"FALTA/DUPLA: CONDIÇÃO DA PLATAFORMA",IF(COUNTIF(J14:L14,"X")<>1,"FALTA/DUPLA: DRENAGEM SUPERFICIAL","OK"))) -> OK
A15: 387ETO0100 | B15: C | C15: 6 | D15: 7 | E15: =D15-C15 -> 1 | F15: X | K15: X | N15: =IF(COUNTA(F15:L15)=0,"— não preenchido",IF(COUNTIF(F15:I15,"X")<>1,"FALTA/DUPLA: CONDIÇÃO DA PLATAFORMA",IF(COUNTIF(J15:L15,"X")<>1,"FALTA/DUPLA: DRENAGEM SUPERFICIAL","OK"))) -> OK
A16: 387ETO0100 | B16: C | C16: 7 | D16: 8 | E16: =D16-C16 -> 1 | F16: X | K16: X | N16: =IF(COUNTA(F16:L16)=0,"— não preenchido",IF(COUNTIF(F16:I16,"X")<>1,"FALTA/DUPLA: CONDIÇÃO DA PLATAFORMA",IF(COUNTIF(J16:L16,"X")<>1,"FALTA/DUPLA: DRENAGEM SUPERFICIAL","OK"))) -> OK
A17: 387ETO0100 | B17: C | C17: 8 | D17: 9 | E17: =D17-C17 -> 1 | F17: X | K17: X | N17: =IF(COUNTA(F17:L17)=0,"— não preenchido",IF(COUNTIF(F17:I17,"X")<>1,"FALTA/DUPLA: CONDIÇÃO DA PLATAFORMA",IF(COUNTIF(J17:L17,"X")<>1,"FALTA/DUPLA: DRENAGEM SUPERFICIAL","OK"))) -> OK
A18: 387ETO0100 | B18: C | C18: 9 | D18: 10 | E18: =D18-C18 -> 1 | F18: X | K18: X | N18: =IF(COUNTA(F18:L18)=0,"— não preenchido",IF(COUNTIF(F18:I18,"X")<>1,"FALTA/DUPLA: CONDIÇÃO DA PLATAFORMA",IF(COUNTIF(J18:L18,"X")<>1,"FALTA/DUPLA: DRENAGEM SUPERFICIAL","OK"))) -> OK
A19: 387ETO0100 | B19: C | C19: 10 | D19: 11 | E19: =D19-C19 -> 1 | F19: X | K19: X | N19: =IF(COUNTA(F19:L19)=0,"— não preenchido",IF(COUNTIF(F19:I19,"X")<>1,"FALTA/DUPLA: CONDIÇÃO DA PLATAFORMA",IF(COUNTIF(J19:L19,"X")<>1,"FALTA/DUPLA: DRENAGEM SUPERFICIAL","OK"))) -> OK
A20: 387ETO0100 | B20: C | C20: 11 | D20: 12 | E20: =D20-C20 -> 1 | F20: X | K20: X | N20: =IF(COUNTA(F20:L20)=0,"— não preenchido",IF(COUNTIF(F20:I20,"X")<>1,"FALTA/DUPLA: CONDIÇÃO DA PLATAFORMA",IF(COUNTIF(J20:L20,"X")<>1,"FALTA/DUPLA: DRENAGEM SUPERFICIAL","OK"))) -> OK
... A33: 387ETO0100 | B33: C | C33: 24 | D33: 25 | E33: =D33-C33 -> 1 | F33: X | K33: X | N33: =IF(COUNTA(F33:L33)=0,"— não preenchido",IF(COUNTIF(F33:I33,"X")<>1,"FALTA/DUPLA: CONDIÇÃO DA PLATAFORMA",IF(COUNTIF(J33:L33,"X")<>1,"FALTA/DUPLA: DRENAGEM SUPERFICIAL","OK"))) -> OK
A34: 387ETO0100 | B34: C | C34: 25 | D34: 26 | E34: =D34-C34 -> 1 | G34: X | K34: X | N34: =IF(COUNTA(F34:L34)=0,"— não preenchido",IF(COUNTIF(F34:I34,"X")<>1,"FALTA/DUPLA: CONDIÇÃO DA PLATAFORMA",IF(COUNTIF(J34:L34,"X")<>1,"FALTA/DUPLA: DRENAGEM SUPERFICIAL","OK"))) -> OK
A35: 387ETO0100 | B35: C | C35: 26 | D35: 27 | E35: =D35-C35 -> 1 | G35: X | K35: X | N35: =IF(COUNTA(F35:L35)=0,"— não preenchido",IF(COUNTIF(F35:I35,"X")<>1,"FALTA/DUPLA: CONDIÇÃO DA PLATAFORMA",IF(COUNTIF(J35:L35,"X")<>1,"FALTA/DUPLA: DRENAGEM SUPERFICIAL","OK"))) -> OK
A36: 387ETO0100 | B36: C | C36: 27 | D36: 28 | E36: =D36-C36 -> 1 | G36: X | K36: X | N36: =IF(COUNTA(F36:L36)=0,"— não preenchido",IF(COUNTIF(F36:I36,"X")<>1,"FALTA/DUPLA: CONDIÇÃO DA PLATAFORMA",IF(COUNTIF(J36:L36,"X")<>1,"FALTA/DUPLA: DRENAGEM SUPERFICIAL","OK"))) -> OK
A37: 387ETO0100 | B37: C | C37: 28 | D37: 29 | E37: =D37-C37 -> 1 | G37: X | K37: X | N37: =IF(COUNTA(F37:L37)=0,"— não preenchido",IF(COUNTIF(F37:I37,"X")<>1,"FALTA/DUPLA: CONDIÇÃO DA PLATAFORMA",IF(COUNTIF(J37:L37,"X")<>1,"FALTA/DUPLA: DRENAGEM SUPERFICIAL","OK"))) -> OK
A38: 387ETO0100 | B38: C | C38: 29 | D38: 30 | E38: =D38-C38 -> 1 | G38: X | K38: X | N38: =IF(COUNTA(F38:L38)=0,"— não preenchido",IF(COUNTIF(F38:I38,"X")<>1,"FALTA/DUPLA: CONDIÇÃO DA PLATAFORMA",IF(COUNTIF(J38:L38,"X")<>1,"FALTA/DUPLA: DRENAGEM SUPERFICIAL","OK"))) -> OK
A39: 387ETO0100 | B39: C | C39: 30 | D39: 31 | E39: =D39-C39 -> 1 | G39: X | K39: X | N39: =IF(COUNTA(F39:L39)=0,"— não preenchido",IF(COUNTIF(F39:I39,"X")<>1,"FALTA/DUPLA: CONDIÇÃO DA PLATAFORMA",IF(COUNTIF(J39:L39,"X")<>1,"FALTA/DUPLA: DRENAGEM SUPERFICIAL","OK"))) -> OK
A40: 387ETO0100 | B40: C | C40: 31 | D40: 32 | E40: =D40-C40 -> 1 | G40: X | K40: X | N40: =IF(COUNTA(F40:L40)=0,"— não preenchido",IF(COUNTIF(F40:I40,"X")<>1,"FALTA/DUPLA: CONDIÇÃO DA PLATAFORMA",IF(COUNTIF(J40:L40,"X")<>1,"FALTA/DUPLA: DRENAGEM SUPERFICIAL","OK"))) -> OK
